Workbook

Sheet RESUMEN AL 24-8-2026
C2: PERU FROST
C3: AVANCE COMERCIAL AL 24-8-2026
F5: RENTABILIDAD DEL INVENTARIO | X5: 46235 | AA5: 46245 | AD5: 46250 | AG5: 46259 | AJ5: TOTAL PROYECTADO AGOSTO 2026 | AX5: UNITARIOS POR TM
B6: Código | C6: Producto | D6: TM en Stock Libre | E6: CU | F6: Costo Ventas | G6: Gasto Ventas | H6: Gasto ADM | I6: Gasto Fin | J6: Depreciación | K6: Utilidad Neta | L6: Margen Neto | M6: Venta Equilibrio a Utd Neta | N6: Precio Equilibrio x TM a Utd Neta | O6: Venta Equilibro a EBITDA | P6: Precio Equilibrio x TM a EBITDA | Q6: Precio Mercado | R6: Venta total | S6: Utilidad | T6: Mg Neto | U6: EBITDA | V6: Mg EBITDA | X6: TM | Y6: Venta | Z6: Precio x TM | AA6: TM | AB6: Venta | AC6: Precio x TM | AD6: TM | AE6: Venta | AF6: Precio x TM | AG6: TM | AH6: Venta | AI6: Precio x TM | AJ6: TM | AK6: Venta | AL6: Precio x TM | AM6: Costo Ventas | AN6: Gasto Ventas | AO6: Gasto Adm | AP6: Gasto Fin | AQ6: Depreciación | AR6: Drawback | AS6: Utilidad Neta | AT6: Mg Neto % | AU6: EBITDA | AV6: MG EBITDA | AX6: Precio x TM | AY6: Costo Ventas | AZ6: Gasto Ventas | BA6: Gasto Adm | BB6: Gasto Fin | BC6: Depreciación | BD6: Drawback | BE6: Utilidad Neta | BF6: EBITDA
B7: 10005721 | C7: POTA FILETE CONGELADO | D7: =TD!F4 -> 66.96 | E7: =IFERROR(F7/D7,0) -> 1834.431 | F7: =TD!G4 -> 122833.5 | G7: =TD!H4 -> 13916.966 | H7: =TD!I4 -> 3440.3135 | I7: =TD!J4 -> 6763.0734 | J7: =TD!K4 -> 5406.3411 | K7: 0 | L7: 0 | M7: =F7+G7+H7+I7 -> 146953.85 | N7: =IFERROR(M7/D7,0) -> 2194.6513 | O7: =F7+G7+H7-J7 -> 134784.44 | P7: =IFERROR(O7/D7,0) -> 2012.9098 | Q7: 1800 | R7: =Q7*D7 -> 120528 | S7: =R7-M7 -> -26425.853 | T7: =IFERROR(S7/R7,0) -> -0.21925074 | U7: =R7-(M7-J7-I7) -> -14256.439 | V7: =IFERROR(U7/R7,0) -> -0.11828321 | X7: {=SUM([1]Hoja5!$H$6:$H$12*([1]Hoja5!$E$6:$E$12=X$5)*($C7=[1]Hoja5!$J$6:$J$12))} -> 0 | Y7: {=SUM([1]Hoja5!$I$6:$I$12*([1]Hoja5!$E$6:$E$12=X$5)*($C7=[1]Hoja5!$J$6:$J$12))} -> 0 | Z7: =IFERROR(Y7/X7,0) -> 0 | AA7: {=SUM([1]Hoja5!$H$6:$H$12*([1]Hoja5!$E$6:$E$12=AA$5)*($C7=[1]Hoja5!$J$6:$J$12))} -> 0 | AB7: {=SUM([1]Hoja5!$I$6:$I$12*([1]Hoja5!$E$6:$E$12=AA$5)*($C7=[1]Hoja5!$J$6:$J$12))} -> 0 | AC7: =IFERROR(AB7/AA7,0) -> 0 | AD7: {=SUM([1]Hoja5!$H$6:$H$12*([1]Hoja5!$E$6:$E$12=AD$5)*($C7=[1]Hoja5!$J$6:$J$12))} -> 0 | AE7: {=SUM([1]Hoja5!$I$6:$I$12*([1]Hoja5!$E$6:$E$12=AD$5)*($C7=[1]Hoja5!$J$6:$J$12))} -> 0 | AF7: =IFERROR(AE7/AD7,0) -> 0 | AG7: {=SUM([1]Hoja5!$H$6:$H$12*([1]Hoja5!$E$6:$E$12=AG$5)*($C7=[1]Hoja5!$J$6:$J$12))} -> 0 | AH7: {=SUM([1]Hoja5!$I$6:$I$12*([1]Hoja5!$E$6:$E$12=AG$5)*($C7=[1]Hoja5!$J$6:$J$12))} -> 0 | AI7: =IFERROR(AH7/AG7,0) -> 0 | AJ7: =X7+AA7+AD7+AG7 -> 0 | AK7: =Y7+AB7+AE7+AH7 -> 0 | AL7: =IFERROR(AK7/AJ7,0) -> 0 | AM7: =-IFERROR(F7/D7*AJ7,0) -> 0 | AN7: =-207.84*AJ7 -> 0 | AO7: =$AO$20/$AJ$20*$AJ7 -> 0 | AP7: =$AP$20/$AJ$20*$AJ7 -> 0 | AQ7: =$AQ$20/$AJ$20*$AJ7 -> 0 | AR7: =(AK7-AJ7*$AO$21)*0.03 -> 0 | AS7: =AK7+SUM(AM7:AP7,AR7) -> 0 | AT7: =IFERROR(AS7/AK7,0) -> 0 | AU7: =AK7+AM7+AN7+AO7+AR7-AQ7 -> 0 | AV7: =IFERROR(AU7/AK7,0) -> 0 | AX7: =AL7 -> 0 | AY7: =IFERROR(AM7/$AJ7,0) -> 0 | AZ7: =IFERROR(AN7/$AJ7,0) -> 0 | BA7: =IFERROR(AO7/$AJ7,0) -> 0 | BB7: =IFERROR(AP7/$AJ7,0) -> 0 | BC7: =IFERROR(AQ7/$AJ7,0) -> 0 | BD7: =IFERROR(AR7/$AJ7,0) -> 0 | BE7: =IFERROR(AS7/$AJ7,0) -> 0 | BF7: =IFERROR(AU7/$AJ7,0) -> 0
B8: 10005779 | C8: POTA NUCAS CONGELADAS | D8: =TD!F5 -> 379.14 | E8: =IFERROR(F8/D8,0) -> 1483.423 | F8: =TD!G5 -> 562424.98 | G8: =TD!H5 -> 78800.458 | H8: =TD!I5 -> 19479.696 | I8: =TD!J5 -> 38293.782 | J8: =TD!K5 -> 30611.711 | K8: 0 | L8: 0 | M8: =F8+G8+H8+I8 -> 698998.92 | N8: =IFERROR(M8/D8,0) -> 1843.6433 | O8: =F8+G8+H8-J8 -> 630093.43 | P8: =IFERROR(O8/D8,0) -> 1661.9017 | Q8: 1400 | R8: =Q8*D8 -> 530796 | S8: =R8-M8 -> -168202.92 | T8: =IFERROR(S8/R8,0) -> -0.31688807 | U8: =R8-(M8-J8-I8) -> -99297.427 | V8: =IFERROR(U8/R8,0) -> -0.18707267 | X8: {=SUM([1]Hoja5!$H$6:$H$12*([1]Hoja5!$E$6:$E$12=X$5)*($C8=[1]Hoja5!$J$6:$J$12))} -> 0 | Y8: {=SUM([1]Hoja5!$I$6:$I$12*([1]Hoja5!$E$6:$E$12=X$5)*($C8=[1]Hoja5!$J$6:$J$12))} -> 0 | Z8: =IFERROR(Y8/X8,0) -> 0 | AA8: {=SUM([1]Hoja5!$H$6:$H$12*([1]Hoja5!$E$6:$E$12=AA$5)*($C8=[1]Hoja5!$J$6:$J$12))} -> 0 | AB8: {=SUM([1]Hoja5!$I$6:$I$12*([1]Hoja5!$E$6:$E$12=AA$5)*($C8=[1]Hoja5!$J$6:$J$12))} -> 0 | AC8: =IFERROR(AB8/AA8,0) -> 0 | AD8: {=SUM([1]Hoja5!$H$6:$H$12*([1]Hoja5!$E$6:$E$12=AD$5)*($C8=[1]Hoja5!$J$6:$J$12))} -> 0 | AE8: {=SUM([1]Hoja5!$I$6:$I$12*([1]Hoja5!$E$6:$E$12=AD$5)*($C8=[1]Hoja5!$J$6:$J$12))} -> 0 | AF8: =IFERROR(AE8/AD8,0) -> 0 | AG8: {=SUM([1]Hoja5!$H$6:$H$12*([1]Hoja5!$E$6:$E$12=AG$5)*($C8=[1]Hoja5!$J$6:$J$12))} -> 78 | AH8: {=SUM([1]Hoja5!$I$6:$I$12*([1]Hoja5!$E$6:$E$12=AG$5)*($C8=[1]Hoja5!$J$6:$J$12))} -> 103740 | AI8: =IFERROR(AH8/AG8,0) -> 1330 | AJ8: =X8+AA8+AD8+AG8 -> 78 | AK8: =Y8+AB8+AE8+AH8 -> 103740 | AL8: =IFERROR(AK8/AJ8,0) -> 1330 | AM8: =-IFERROR(F8/D8*AJ8,0) -> -115706.99 | AN8: =-207.84*AJ8 -> -16211.52 | AO8: =$AO$20/$AJ$20*$AJ8 -> -21557.266 | AP8: =$AP$20/$AJ$20*$AJ8 -> -42377.933 | AQ8: =$AQ$20/$AJ$20*$AJ8 -> -33876.545 | AR8: =(AK8-AJ8*$AO$21)*0.03 -> 2845.0244 | AS8: =AK8+SUM(AM8:AP8,AR8) -> -89268.687 | AT8: =IFERROR(AS8/AK8,0) -> -0.86050402 | AU8: =AK8+AM8+AN8+AO8+AR8-AQ8 -> -13014.209 | AV8: =IFERROR(AU8/AK8,0) -> -0.12545025 | AX8: =AL8 -> 1330 | AY8: =IFERROR(AM8/$AJ8,0) -> -1483.423 | AZ8: =IFERROR(AN8/$AJ8,0) -> -207.84 | BA8: =IFERROR(AO8/$AJ8,0) -> -276.37521 | BB8: =IFERROR(AP8/$AJ8,0) -> -543.30684 | BC8: =IFERROR(AQ8/$AJ8,0) -> -434.31468 | BD8: =IFERROR(AR8/$AJ8,0) -> 36.474672 | BE8: =IFERROR(AS8/$AJ8,0) -> -1144.4703 | BF8: =IFERROR(AU8/$AJ8,0) -> -166.84883
B9: 10006719 | C9: POTA ALAS CONGELADAS | D9: =TD!F6 -> 17.9 | E9: =IFERROR(F9/D9,0) -> 1731.9701 | F9: =TD!G6 -> 31002.265 | G9: =TD!H6 -> 3720.336 | H9: =TD!I6 -> 919.67759 | I9: =TD!J6 -> 1807.9303 | J9: =TD!K6 -> 1445.2435 | K9: 0 | L9: 0 | M9: =F9+G9+H9+I9 -> 37450.209 | N9: =IFERROR(M9/D9,0) -> 2092.1905 | O9: =F9+G9+H9-J9 -> 34197.035 | P9: =IFERROR(O9/D9,0) -> 1910.4489 | Q9: 1950 | R9: =Q9*D9 -> 34905 | S9: =R9-M9 -> -2545.2092 | T9: =IFERROR(S9/R9,0) -> -0.072918183 | U9: =R9-(M9-J9-I9) -> 707.96464 | V9: =IFERROR(U9/R9,0) -> 0.020282614 | X9: {=SUM([1]Hoja5!$H$6:$H$12*([1]Hoja5!$E$6:$E$12=X$5)*($C9=[1]Hoja5!$J$6:$J$12))} -> 0 | Y9: {=SUM([1]Hoja5!$I$6:$I$12*([1]Hoja5!$E$6:$E$12=X$5)*($C9=[1]Hoja5!$J$6:$J$12))} -> 0 | Z9: =IFERROR(Y9/X9,0) -> 0 | AA9: {=SUM([1]Hoja5!$H$6:$H$12*([1]Hoja5!$E$6:$E$12=AA$5)*($C9=[1]Hoja5!$J$6:$J$12))} -> 27 | AB9: {=SUM([1]Hoja5!$I$6:$I$12*([1]Hoja5!$E$6:$E$12=AA$5)*($C9=[1]Hoja5!$J$6:$J$12))} -> 48600 | AC9: =IFERROR(AB9/AA9,0) -> 1800 | AD9: {=SUM([1]Hoja5!$H$6:$H$12*([1]Hoja5!$E$6:$E$12=AD$5)*($C9=[1]Hoja5!$J$6:$J$12))} -> 0 | AE9: {=SUM([1]Hoja5!$I$6:$I$12*([1]Hoja5!$E$6:$E$12=AD$5)*($C9=[1]Hoja5!$J$6:$J$12))} -> 0 | AF9: =IFERROR(AE9/AD9,0) -> 0 | AG9: {=SUM([1]Hoja5!$H$6:$H$12*([1]Hoja5!$E$6:$E$12=AG$5)*($C9=[1]Hoja5!$J$6:$J$12))} -> 0 | AH9: {=SUM([1]Hoja5!$I$6:$I$12*([1]Hoja5!$E$6:$E$12=AG$5)*($C9=[1]Hoja5!$J$6:$J$12))} -> 0 | AI9: =IFERROR(AH9/AG9,0) -> 0 | AJ9: =X9+AA9+AD9+AG9 -> 27 | AK9: =Y9+AB9+AE9+AH9 -> 48600 | AL9: =IFERROR(AK9/AJ9,0) -> 1800 | AM9: =-IFERROR(F9/D9*AJ9,0) -> -46763.193 | AN9: =-207.84*AJ9 -> -5611.68 | AO9: =$AO$20/$AJ$20*$AJ9 -> -7462.1307 | AP9: =$AP$20/$AJ$20*$AJ9 -> -14669.285 | AQ9: =$AQ$20/$AJ$20*$AJ9 -> -11726.496 | AR9: =(AK9-AJ9*$AO$21)*0.03 -> 1365.5161 | AS9: =AK9+SUM(AM9:AP9,AR9) -> -24540.773 | AT9: =IFERROR(AS9/AK9,0) -> -0.50495417 | AU9: =AK9+AM9+AN9+AO9+AR9-AQ9 -> 1855.0084 | AV9: =IFERROR(AU9/AK9,0) -> 0.038168897 | AX9: =AL9 -> 1800 | AY9: =IFERROR(AM9/$AJ9,0) -> -1731.9701 | AZ9: =IFERROR(AN9/$AJ9,0) -> -207.84 | BA9: =IFERROR(AO9/$AJ9,0) -> -276.37521 | BB9: =IFERROR(AP9/$AJ9,0) -> -543.30684 | BC9: =IFERROR(AQ9/$AJ9,0) -> -434.31468 | BD9: =IFERROR(AR9/$AJ9,0) -> 50.574672 | BE9: =IFERROR(AS9/$AJ9,0) -> -908.9175 | BF9: =IFERROR(AU9/$AJ9,0) -> 68.704014
B10: 10007050 | C10: POTA RECORTES COCIDOS | D10: =TD!F7 -> 124.54 | E10: =IFERROR(F10/D10,0) -> 1308.2098 | F10: =TD!G7 -> 162924.45 | G10: =TD!H7 -> 25884.394 | H10: =TD!I7 -> 6398.6954 | I10: =TD!J7 -> 12578.751 | J10: =TD!K7 -> 10055.342 | K10: 0 | L10: 0 | M10: =F10+G10+H10+I10 -> 207786.29 | N10: =IFERROR(M10/D10,0) -> 1668.4302 | O10: =F10+G10+H10-J10 -> 185152.2 | P10: =IFERROR(O10/D10,0) -> 1486.6886 | Q10: 1700 | R10: =Q10*D10 -> 211718 | S10: =R10-M10 -> 3931.7088 | T10: =IFERROR(S10/R10,0) -> 0.018570498 | U10: =R10-(M10-J10-I10) -> 26565.802 | V10: =IFERROR(U10/R10,0) -> 0.12547729 | X10: {=SUM([1]Hoja5!$H$6:$H$12*([1]Hoja5!$E$6:$E$12=X$5)*($C10=[1]Hoja5!$J$6:$J$12))} -> 0 | Y10: {=SUM([1]Hoja5!$I$6:$I$12*([1]Hoja5!$E$6:$E$12=X$5)*($C10=[1]Hoja5!$J$6:$J$12))} -> 0 | Z10: =IFERROR(Y10/X10,0) -> 0 | AA10: {=SUM([1]Hoja5!$H$6:$H$12*([1]Hoja5!$E$6:$E$12=AA$5)*($C10=[1]Hoja5!$J$6:$J$12))} -> 0 | AB10: {=SUM([1]Hoja5!$I$6:$I$12*([1]Hoja5!$E$6:$E$12=AA$5)*($C10=[1]Hoja5!$J$6:$J$12))} -> 0 | AC10: =IFERROR(AB10/AA10,0) -> 0 | AD10: {=SUM([1]Hoja5!$H$6:$H$12*([1]Hoja5!$E$6:$E$12=AD$5)*($C10=[1]Hoja5!$J$6:$J$12))} -> 0 | AE10: {=SUM([1]Hoja5!$I$6:$I$12*([1]Hoja5!$E$6:$E$12=AD$5)*($C10=[1]Hoja5!$J$6:$J$12))} -> 0 | AF10: =IFERROR(AE10/AD10,0) -> 0 | AG10: {=SUM([1]Hoja5!$H$6:$H$12*([1]Hoja5!$E$6:$E$12=AG$5)*($C10=[1]Hoja5!$J$6:$J$12))} -> 0 | AH10: {=SUM([1]Hoja5!$I$6:$I$12*([1]Hoja5!$E$6:$E$12=AG$5)*($C10=[1]Hoja5!$J$6:$J$12))} -> 0 | AI10: =IFERROR(AH10/AG10,0) -> 0 | AJ10: =X10+AA10+AD10+AG10 -> 0 | AK10: =Y10+AB10+AE10+AH10 -> 0 | AL10: =IFERROR(AK10/AJ10,0) -> 0 | AM10: =-IFERROR(F10/D10*AJ10,0) -> 0 | AN10: =-207.84*AJ10 -> 0 | AO10: =$AO$20/$AJ$20*$AJ10 -> 0 | AP10: =$AP$20/$AJ$20*$AJ10 -> 0 | AQ10: =$AQ$20/$AJ$20*$AJ10 -> 0 | AR10: =(AK10-AJ10*$AO$21)*0.03 -> 0 | AS10: =AK10+SUM(AM10:AP10,AR10) -> 0 | AT10: =IFERROR(AS10/AK10,0) -> 0 | AU10: =AK10+AM10+AN10+AO10+AR10-AQ10 -> 0 | AV10: =IFERROR(AU10/AK10,0) -> 0 | AX10: =AL10 -> 0 | AY10: =IFERROR(AM10/$AJ10,0) -> 0 | AZ10: =IFERROR(AN10/$AJ10,0) -> 0 | BA10: =IFERROR(AO10/$AJ10,0) -> 0 | BB10: =IFERROR(AP10/$AJ10,0) -> 0 | BC10: =IFERROR(AQ10/$AJ10,0) -> 0 | BD10: =IFERROR(AR10/$AJ10,0) -> 0 | BE10: =IFERROR(AS10/$AJ10,0) -> 0 | BF10: =IFERROR(AU10/$AJ10,0) -> 0
B11: 10007162 | C11: POTA REJOS CONGELADOS | D11: =TD!F8 -> 270.4 | E11: =IFERROR(F11/D11,0) -> 1596.5588 | F11: =TD!G8 -> 431709.5 | G11: =TD!H8 -> 56199.936 | H11: =TD!I8 -> 13892.783 | I11: =TD!J8 -> 27310.858 | J11: =TD!K8 -> 21832.058 | K11: 0 | L11: 0 | M11: =F11+G11+H11+I11 -> 529113.08 | N11: =IFERROR(M11/D11,0) -> 1956.7791 | O11: =F11+G11+H11-J11 -> 479970.16 | P11: =IFERROR(O11/D11,0) -> 1775.0376 | Q11: 2700 | R11: =Q11*D11 -> 730080 | S11: =R11-M11 -> 200966.92 | T11: =IFERROR(S11/R11,0) -> 0.27526698 | U11: =R11-(M11-J11-I11) -> 250109.84 | V11: =IFERROR(U11/R11,0) -> 0.34257867 | X11: {=SUM([1]Hoja5!$H$6:$H$12*([1]Hoja5!$E$6:$E$12=X$5)*($C11=[1]Hoja5!$J$6:$J$12))} -> 81 | Y11: {=SUM([1]Hoja5!$I$6:$I$12*([1]Hoja5!$E$6:$E$12=X$5)*($C11=[1]Hoja5!$J$6:$J$12))} -> 213300 | Z11: =IFERROR(Y11/X11,0) -> 2633.3333 | AA11: {=SUM([1]Hoja5!$H$6:$H$12*([1]Hoja5!$E$6:$E$12=AA$5)*($C11=[1]Hoja5!$J$6:$J$12))} -> 0 | AB11: {=SUM([1]Hoja5!$I$6:$I$12*([1]Hoja5!$E$6:$E$12=AA$5)*($C11=[1]Hoja5!$J$6:$J$12))} -> 0 | AC11: =IFERROR(AB11/AA11,0) -> 0 | AD11: {=SUM([1]Hoja5!$H$6:$H$12*([1]Hoja5!$E$6:$E$12=AD$5)*($C11=[1]Hoja5!$J$6:$J$12))} -> 0 | AE11: {=SUM([1]Hoja5!$I$6:$I$12*([1]Hoja5!$E$6:$E$12=AD$5)*($C11=[1]Hoja5!$J$6:$J$12))} -> 0 | AF11: =IFERROR(AE11/AD11,0) -> 0 | AG11: {=SUM([1]Hoja5!$H$6:$H$12*([1]Hoja5!$E$6:$E$12=AG$5)*($C11=[1]Hoja5!$J$6:$J$12))} -> 0 | AH11: {=SUM([1]Hoja5!$I$6:$I$12*([1]Hoja5!$E$6:$E$12=AG$5)*($C11=[1]Hoja5!$J$6:$J$12))} -> 0 | AI11: =IFERROR(AH11/AG11,0) -> 0 | AJ11: =X11+AA11+AD11+AG11 -> 81 | AK11: =Y11+AB11+AE11+AH11 -> 213300 | AL11: =IFERROR(AK11/AJ11,0) -> 2633.3333 | AM11: =-IFERROR(F11/D11*AJ11,0) -> -129321.26 | AN11: =-207.84*AJ11 -> -16835.04 | AO11: =$AO$20/$AJ$20*$AJ11 -> -22386.392 | AP11: =$AP$20/$AJ$20*$AJ11 -> -44007.854 | AQ11: =$AQ$20/$AJ$20*$AJ11 -> -35179.489 | AR11: =(AK11-AJ11*$AO$21)*0.03 -> 6121.5484 | AS11: =AK11+SUM(AM11:AP11,AR11) -> 6870.9985 | AT11: =IFERROR(AS11/AK11,0) -> 0.032212839 | AU11: =AK11+AM11+AN11+AO11+AR11-AQ11 -> 86058.342 | AV11: =IFERROR(AU11/AK11,0) -> 0.40346152 | AX11: =AL11 -> 2633.3333 | AY11: =IFERROR(AM11/$AJ11,0) -> -1596.5588 | AZ11: =IFERROR(AN11/$AJ11,0) -> -207.84 | BA11: =IFERROR(AO11/$AJ11,0) -> -276.37521 | BB11: =IFERROR(AP11/$AJ11,0) -> -543.30684 | BC11: =IFERROR(AQ11/$AJ11,0) -> -434.31468 | BD11: =IFERROR(AR11/$AJ11,0) -> 75.574672 | BE11: =IFERROR(AS11/$AJ11,0) -> 84.827142 | BF11: =IFERROR(AU11/$AJ11,0) -> 1062.4487
B12: 10007567 | C12: POTA REPRODUCTORES | D12: =TD!F9 -> 132.38 | E12: =IFERROR(F12/D12,0) -> 1540.1637 | F12: =TD!G9 -> 203886.87 | G12: =TD!H9 -> 27513.859 | H12: =TD!I9 -> 6801.5039 | I12: =TD!J9 -> 13370.604 | J12: =TD!K9 -> 10688.343 | K12: 0 | L12: 0 | M12: =F12+G12+H12+I12 -> 251572.83 | N12: =IFERROR(M12/D12,0) -> 1900.384 | O12: =F12+G12+H12-J12 -> 227513.89 | P12: =IFERROR(O12/D12,0) -> 1718.6424 | Q12: 2800 | R12: =Q12*D12 -> 370664 | S12: =R12-M12 -> 119091.17 | T12: =IFERROR(S12/R12,0) -> 0.32129143 | U12: =R12-(M12-J12-I12) -> 143150.11 | V12: =IFERROR(U12/R12,0) -> 0.38619913 | X12: {=SUM([1]Hoja5!$H$6:$H$12*([1]Hoja5!$E$6:$E$12=X$5)*($C12=[1]Hoja5!$J$6:$J$12))} -> 0 | Y12: {=SUM([1]Hoja5!$I$6:$I$12*([1]Hoja5!$E$6:$E$12=X$5)*($C12=[1]Hoja5!$J$6:$J$12))} -> 0 | Z12: =IFERROR(Y12/X12,0) -> 0 | AA12: {=SUM([1]Hoja5!$H$6:$H$12*([1]Hoja5!$E$6:$E$12=AA$5)*($C12=[1]Hoja5!$J$6:$J$12))} -> 0 | AB12: {=SUM([1]Hoja5!$I$6:$I$12*([1]Hoja5!$E$6:$E$12=AA$5)*($C12=[1]Hoja5!$J$6:$J$12))} -> 0 | AC12: =IFERROR(AB12/AA12,0) -> 0 | AD12: {=SUM([1]Hoja5!$H$6:$H$12*([1]Hoja5!$E$6:$E$12=AD$5)*($C12=[1]Hoja5!$J$6:$J$12))} -> 0 | AE12: {=SUM([1]Hoja5!$I$6:$I$12*([1]Hoja5!$E$6:$E$12=AD$5)*($C12=[1]Hoja5!$J$6:$J$12))} -> 0 | AF12: =IFERROR(AE12/AD12,0) -> 0 | AG12: {=SUM([1]Hoja5!$H$6:$H$12*([1]Hoja5!$E$6:$E$12=AG$5)*($C12=[1]Hoja5!$J$6:$J$12))} -> 0 | AH12: {=SUM([1]Hoja5!$I$6:$I$12*([1]Hoja5!$E$6:$E$12=AG$5)*($C12=[1]Hoja5!$J$6:$J$12))} -> 0 | AI12: =IFERROR(AH12/AG12,0) -> 0 | AJ12: =X12+AA12+AD12+AG12 -> 0 | AK12: =Y12+AB12+AE12+AH12 -> 0 | AL12: =IFERROR(AK12/AJ12,0) -> 0 | AM12: =-IFERROR(F12/D12*AJ12,0) -> 0 | AN12: =-207.84*AJ12 -> 0 | AO12: =$AO$20/$AJ$20*$AJ12 -> 0 | AP12: =$AP$20/$AJ$20*$AJ12 -> 0 | AQ12: =$AQ$20/$AJ$20*$AJ12 -> 0 | AR12: =(AK12-AJ12*$AO$21)*0.03 -> 0 | AS12: =AK12+SUM(AM12:AP12,AR12) -> 0 | AT12: =IFERROR(AS12/AK12,0) -> 0 | AU12: =AK12+AM12+AN12+AO12+AR12-AQ12 -> 0 | AV12: =IFERROR(AU12/AK12,0) -> 0 | AX12: =AL12 -> 0 | AY12: =IFERROR(AM12/$AJ12,0) -> 0 | AZ12: =IFERROR(AN12/$AJ12,0) -> 0 | BA12: =IFERROR(AO12/$AJ12,0) -> 0 | BB12: =IFERROR(AP12/$AJ12,0) -> 0 | BC12: =IFERROR(AQ12/$AJ12,0) -> 0 | BD12: =IFERROR(AR12/$AJ12,0) -> 0 | BE12: =IFERROR(AS12/$AJ12,0) -> 0 | BF12: =IFERROR(AU12/$AJ12,0) -> 0
B13: 10007969 | C13: POTA CONOS | D13: =TD!F10 -> 0 | E13: =IFERROR(F13/D13,0) -> 0 | F13: =TD!G10 -> 0 | G13: =TD!H10 -> 0 | H13: =TD!I10 -> 0 | I13: =TD!J10 -> 0 | J13: =TD!K10 -> 0 | K13: 0 | L13: 0 | M13: =F13+G13+H13+I13 -> 0 | N13: =IFERROR(M13/D13,0) -> 0 | O13: =F13+G13+H13-J13 -> 0 | P13: =IFERROR(O13/D13,0) -> 0 | Q13: 1700 | R13: =Q13*D13 -> 0 | S13: =R13-M13 -> 0 | T13: =IFERROR(S13/R13,0) -> 0 | U13: =R13-(M13-J13-I13) -> 0 | V13: =IFERROR(U13/R13,0) -> 0 | X13: {=SUM([1]Hoja5!$H$6:$H$12*([1]Hoja5!$E$6:$E$12=X$5)*($C13=[1]Hoja5!$J$6:$J$12))} -> 26.4 | Y13: {=SUM([1]Hoja5!$I$6:$I$12*([1]Hoja5!$E$6:$E$12=X$5)*($C13=[1]Hoja5!$J$6:$J$12))} -> 42240 | Z13: =IFERROR(Y13/X13,0) -> 1600 | AA13: {=SUM([1]Hoja5!$H$6:$H$12*([1]Hoja5!$E$6:$E$12=AA$5)*($C13=[1]Hoja5!$J$6:$J$12))} -> 0 | AB13: {=SUM([1]Hoja5!$I$6:$I$12*([1]Hoja5!$E$6:$E$12=AA$5)*($C13=[1]Hoja5!$J$6:$J$12))} -> 0 | AC13: =IFERROR(AB13/AA13,0) -> 0 | AD13: {=SUM([1]Hoja5!$H$6:$H$12*([1]Hoja5!$E$6:$E$12=AD$5)*($C13=[1]Hoja5!$J$6:$J$12))} -> 0 | AE13: {=SUM([1]Hoja5!$I$6:$I$12*([1]Hoja5!$E$6:$E$12=AD$5)*($C13=[1]Hoja5!$J$6:$J$12))} -> 0 | AF13: =IFERROR(AE13/AD13,0) -> 0 | AG13: {=SUM([1]Hoja5!$H$6:$H$12*([1]Hoja5!$E$6:$E$12=AG$5)*($C13=[1]Hoja5!$J$6:$J$12))} -> 20.38 | AH13: {=SUM([1]Hoja5!$I$6:$I$12*([1]Hoja5!$E$6:$E$12=AG$5)*($C13=[1]Hoja5!$J$6:$J$12))} -> 36684 | AI13: =IFERROR(AH13/AG13,0) -> 1800 | AJ13: =X13+AA13+AD13+AG13 -> 46.78 | AK13: =Y13+AB13+AE13+AH13 -> 78924 | AL13: =IFERROR(AK13/AJ13,0) -> 1687.1313 | AM13: =-AJ13*'Stock Libre'!H10*1000 -> -57681.457 | AN13: =-207.84*AJ13 -> -9722.7552 | AO13: =$AO$20/$AJ$20*$AJ13 -> -12928.832 | AP13: =$AP$20/$AJ$20*$AJ13 -> -25415.894 | AQ13: =$AQ$20/$AJ$20*$AJ13 -> -20317.241 | AR13: =(AK13-AJ13*$AO$21)*0.03 -> 2207.4831 | AS13: =AK13+SUM(AM13:AP13,AR13) -> -24617.455 | AT13: =IFERROR(AS13/AK13,0) -> -0.31191342 | AU13: =AK13+AM13+AN13+AO13+AR13-AQ13 -> 21115.679 | AV13: =IFERROR(AU13/AK13,0) -> 0.26754447 | AX13: =AL13 -> 1687.1313 | AY13: =IFERROR(AM13/$AJ13,0) -> -1233.0367 | AZ13: =IFERROR(AN13/$AJ13,0) -> -207.84 | BA13: =IFERROR(AO13/$AJ13,0) -> -276.37521 | BB13: =IFERROR(AP13/$AJ13,0) -> -543.30684 | BC13: =IFERROR(AQ13/$AJ13,0) -> -434.31468 | BD13: =IFERROR(AR13/$AJ13,0) -> 47.188609 | BE13: =IFERROR(AS13/$AJ13,0) -> -526.23889 | BF13: =IFERROR(AU13/$AJ13,0) -> 451.38263
B14: 10009239 | C14: POTA FILETE DARUMA | D14: =TD!F11 -> 16.48 | E14: =IFERROR(F14/D14,0) -> 3085.0611 | F14: =TD!G11 -> 50841.807 | G14: =TD!H11 -> 3425.2032 | H14: =TD!I11 -> 846.71992 | I14: =TD!J11 -> 1664.5079 | J14: =TD!K11 -> 1330.5929 | K14: 0 | L14: 0 | M14: =F14+G14+H14+I14 -> 56778.238 | N14: =IFERROR(M14/D14,0) -> 3445.2815 | O14: =F14+G14+H14-J14 -> 53783.138 | P14: =IFERROR(O14/D14,0) -> 3263.5399 | Q14: 3500 | R14: =Q14*D14 -> 57680 | S14: =R14-M14 -> 901.76165 | T14: =IFERROR(S14/R14,0) -> 0.01563387 | U14: =R14-(M14-J14-I14) -> 3896.8625 | V14: =IFERROR(U14/R14,0) -> 0.067560029 | X14: {=SUM([1]Hoja5!$H$6:$H$12*([1]Hoja5!$E$6:$E$12=X$5)*($C14=[1]Hoja5!$J$6:$J$12))} -> 0 | Y14: {=SUM([1]Hoja5!$I$6:$I$12*([1]Hoja5!$E$6:$E$12=X$5)*($C14=[1]Hoja5!$J$6:$J$12))} -> 0 | Z14: =IFERROR(Y14/X14,0) -> 0 | AA14: {=SUM([1]Hoja5!$H$6:$H$12*([1]Hoja5!$E$6:$E$12=AA$5)*($C14=[1]Hoja5!$J$6:$J$12))} -> 0 | AB14: {=SUM([1]Hoja5!$I$6:$I$12*([1]Hoja5!$E$6:$E$12=AA$5)*($C14=[1]Hoja5!$J$6:$J$12))} -> 0 | AC14: =IFERROR(AB14/AA14,0) -> 0 | AD14: {=SUM([1]Hoja5!$H$6:$H$12*([1]Hoja5!$E$6:$E$12=AD$5)*($C14=[1]Hoja5!$J$6:$J$12))} -> 0 | AE14: {=SUM([1]Hoja5!$I$6:$I$12*([1]Hoja5!$E$6:$E$12=AD$5)*($C14=[1]Hoja5!$J$6:$J$12))} -> 0 | AF14: =IFERROR(AE14/AD14,0) -> 0 | AG14: {=SUM([1]Hoja5!$H$6:$H$12*([1]Hoja5!$E$6:$E$12=AG$5)*($C14=[1]Hoja5!$J$6:$J$12))} -> 0 | AH14: {=SUM([1]Hoja5!$I$6:$I$12*([1]Hoja5!$E$6:$E$12=AG$5)*($C14=[1]Hoja5!$J$6:$J$12))} -> 0 | AI14: =IFERROR(AH14/AG14,0) -> 0 | AJ14: =X14+AA14+AD14+AG14 -> 0 | AK14: =Y14+AB14+AE14+AH14 -> 0 | AL14: =IFERROR(AK14/AJ14,0) -> 0 | AM14: =-IFERROR(F14/D14*AJ14,0) -> 0 | AN14: =-207.84*AJ14 -> 0 | AO14: =$AO$20/$AJ$20*$AJ14 -> 0 | AP14: =$AP$20/$AJ$20*$AJ14 -> 0 | AQ14: =$AQ$20/$AJ$20*$AJ14 -> 0 | AR14: =(AK14-AJ14*$AO$21)*0.03 -> 0 | AS14: =AK14+SUM(AM14:AP14,AR14) -> 0 | AT14: =IFERROR(AS14/AK14,0) -> 0 | AU14: =AK14+AM14+AN14+AO14+AR14-AQ14 -> 0 | AV14: =IFERROR(AU14/AK14,0) -> 0 | AX14: =AL14 -> 0 | AY14: =IFERROR(AM14/$AJ14,0) -> 0 | AZ14: =IFERROR(AN14/$AJ14,0) -> 0 | BA14: =IFERROR(AO14/$AJ14,0) -> 0 | BB14: =IFERROR(AP14/$AJ14,0) -> 0 | BC14: =IFERROR(AQ14/$AJ14,0) -> 0 | BD14: =IFERROR(AR14/$AJ14,0) -> 0 | BE14: =IFERROR(AS14/$AJ14,0) -> 0 | BF14: =IFERROR(AU14/$AJ14,0) -> 0
B15: 10009334 | C15: POTA ALAS COCIDAS | D15: =TD!F12 -> 137.83 | E15: =IFERROR(F15/D15,0) -> 2649.6026 | F15: =TD!G12 -> 365194.73 | G15: =TD!H12 -> 28646.587 | H15: =TD!I12 -> 7081.5174 | I15: =TD!J12 -> 13921.063 | J15: =TD!K12 -> 11128.375 | K15: 0 | L15: 0 | M15: =F15+G15+H15+I15 -> 414843.9 | N15: =IFERROR(M15/D15,0) -> 3009.8229 | O15: =F15+G15+H15-J15 -> 389794.46 | P15: =IFERROR(O15/D15,0) -> 2828.0814 | Q15: 3500 | R15: =Q15*D15 -> 482405 | S15: =R15-M15 -> 67561.105 | T15: =IFERROR(S15/R15,0) -> 0.14005059 | U15: =R15-(M15-J15-I15) -> 92610.543 | V15: =IFERROR(U15/R15,0) -> 0.19197675 | X15: {=SUM([1]Hoja5!$H$6:$H$12*([1]Hoja5!$E$6:$E$12=X$5)*($C15=[1]Hoja5!$J$6:$J$12))} -> 0 | Y15: {=SUM([1]Hoja5!$I$6:$I$12*([1]Hoja5!$E$6:$E$12=X$5)*($C15=[1]Hoja5!$J$6:$J$12))} -> 0 | Z15: =IFERROR(Y15/X15,0) -> 0 | AA15: {=SUM([1]Hoja5!$H$6:$H$12*([1]Hoja5!$E$6:$E$12=AA$5)*($C15=[1]Hoja5!$J$6:$J$12))} -> 0 | AB15: {=SUM([1]Hoja5!$I$6:$I$12*([1]Hoja5!$E$6:$E$12=AA$5)*($C15=[1]Hoja5!$J$6:$J$12))} -> 0 | AC15: =IFERROR(AB15/AA15,0) -> 0 | AD15: {=SUM([1]Hoja5!$H$6:$H$12*([1]Hoja5!$E$6:$E$12=AD$5)*($C15=[1]Hoja5!$J$6:$J$12))} -> 0 | AE15: {=SUM([1]Hoja5!$I$6:$I$12*([1]Hoja5!$E$6:$E$12=AD$5)*($C15=[1]Hoja5!$J$6:$J$12))} -> 0 | AF15: =IFERROR(AE15/AD15,0) -> 0 | AG15: {=SUM([1]Hoja5!$H$6:$H$12*([1]Hoja5!$E$6:$E$12=AG$5)*($C15=[1]Hoja5!$J$6:$J$12))} -> 0 | AH15: {=SUM([1]Hoja5!$I$6:$I$12*([1]Hoja5!$E$6:$E$12=AG$5)*($C15=[1]Hoja5!$J$6:$J$12))} -> 0 | AI15: =IFERROR(AH15/AG15,0) -> 0 | AJ15: =X15+AA15+AD15+AG15 -> 0 | AK15: =Y15+AB15+AE15+AH15 -> 0 | AL15: =IFERROR(AK15/AJ15,0) -> 0 | AM15: =-IFERROR(F15/D15*AJ15,0) -> 0 | AN15: =-207.84*AJ15 -> 0 | AO15: =$AO$20/$AJ$20*$AJ15 -> 0 | AP15: =$AP$20/$AJ$20*$AJ15 -> 0 | AQ15: =$AQ$20/$AJ$20*$AJ15 -> 0 | AR15: =(AK15-AJ15*$AO$21)*0.03 -> 0 | AS15: =AK15+SUM(AM15:AP15,AR15) -> 0 | AT15: =IFERROR(AS15/AK15,0) -> 0 | AU15: =AK15+AM15+AN15+AO15+AR15-AQ15 -> 0 | AV15: =IFERROR(AU15/AK15,0) -> 0 | AX15: =AL15 -> 0 | AY15: =IFERROR(AM15/$AJ15,0) -> 0 | AZ15: =IFERROR(AN15/$AJ15,0) -> 0 | BA15: =IFERROR(AO15/$AJ15,0) -> 0 | BB15: =IFERROR(AP15/$AJ15,0) -> 0 | BC15: =IFERROR(AQ15/$AJ15,0) -> 0 | BD15: =IFERROR(AR15/$AJ15,0) -> 0 | BE15: =IFERROR(AS15/$AJ15,0) -> 0 | BF15: =IFERROR(AU15/$AJ15,0) -> 0
B16: 10009386 | C16: VENTOSAS | D16: =TD!F13 -> 21.28 | E16: =IFERROR(F16/D16,0) -> 1597.9903 | F16: =TD!G13 -> 34005.233 | G16: =TD!H13 -> 4422.8352 | H16: =TD!I13 -> 1093.3374 | I16: =TD!J13 -> 2149.316 | J16: =TD!K13 -> 1718.1442 | K16: 0 | L16: 0 | M16: =F16+G16+H16+I16 -> 41670.721 | N16: =IFERROR(M16/D16,0) -> 1958.2106 | O16: =F16+G16+H16-J16 -> 37803.261 | P16: =IFERROR(O16/D16,0) -> 1776.469 | Q16: 2000 | R16: =Q16*D16 -> 42560 | S16: =R16-M16 -> 889.27879 | T16: =IFERROR(S16/R16,0) -> 0.020894708 | U16: =R16-(M16-J16-I16) -> 4756.7391 | V16: =IFERROR(U16/R16,0) -> 0.11176549 | X16: {=SUM([1]Hoja5!$H$6:$H$12*([1]Hoja5!$E$6:$E$12=X$5)*($C16=[1]Hoja5!$J$6:$J$12))} -> 0 | Y16: {=SUM([1]Hoja5!$I$6:$I$12*([1]Hoja5!$E$6:$E$12=X$5)*($C16=[1]Hoja5!$J$6:$J$12))} -> 0 | Z16: =IFERROR(Y16/X16,0) -> 0 | AA16: {=SUM([1]Hoja5!$H$6:$H$12*([1]Hoja5!$E$6:$E$12=AA$5)*($C16=[1]Hoja5!$J$6:$J$12))} -> 0 | AB16: {=SUM([1]Hoja5!$I$6:$I$12*([1]Hoja5!$E$6:$E$12=AA$5)*($C16=[1]Hoja5!$J$6:$J$12))} -> 0 | AC16: =IFERROR(AB16/AA16,0) -> 0 | AD16: {=SUM([1]Hoja5!$H$6:$H$12*([1]Hoja5!$E$6:$E$12=AD$5)*($C16=[1]Hoja5!$J$6:$J$12))} -> 0 | AE16: {=SUM([1]Hoja5!$I$6:$I$12*([1]Hoja5!$E$6:$E$12=AD$5)*($C16=[1]Hoja5!$J$6:$J$12))} -> 0 | AF16: =IFERROR(AE16/AD16,0) -> 0 | AG16: {=SUM([1]Hoja5!$H$6:$H$12*([1]Hoja5!$E$6:$E$12=AG$5)*($C16=[1]Hoja5!$J$6:$J$12))} -> 0 | AH16: {=SUM([1]Hoja5!$I$6:$I$12*([1]Hoja5!$E$6:$E$12=AG$5)*($C16=[1]Hoja5!$J$6:$J$12))} -> 0 | AI16: =IFERROR(AH16/AG16,0) -> 0 | AJ16: =X16+AA16+AD16+AG16 -> 0 | AK16: =Y16+AB16+AE16+AH16 -> 0 | AL16: =IFERROR(AK16/AJ16,0) -> 0 | AM16: =-IFERROR(F16/D16*AJ16,0) -> 0 | AN16: =-207.84*AJ16 -> 0 | AO16: =$AO$20/$AJ$20*$AJ16 -> 0 | AP16: =$AP$20/$AJ$20*$AJ16 -> 0 | AQ16: =$AQ$20/$AJ$20*$AJ16 -> 0 | AR16: =(AK16-AJ16*$AO$21)*0.03 -> 0 | AS16: =AK16+SUM(AM16:AP16,AR16) -> 0 | AT16: =IFERROR(AS16/AK16,0) -> 0 | AU16: =AK16+AM16+AN16+AO16+AR16-AQ16 -> 0 | AV16: =IFERROR(AU16/AK16,0) -> 0 | AX16: =AL16 -> 0 | AY16: =IFERROR(AM16/$AJ16,0) -> 0 | AZ16: =IFERROR(AN16/$AJ16,0) -> 0 | BA16: =IFERROR(AO16/$AJ16,0) -> 0 | BB16: =IFERROR(AP16/$AJ16,0) -> 0 | BC16: =IFERROR(AQ16/$AJ16,0) -> 0 | BD16: =IFERROR(AR16/$AJ16,0) -> 0 | BE16: =IFERROR(AS16/$AJ16,0) -> 0 | BF16: =IFERROR(AU16/$AJ16,0) -> 0
B17: 10009386 | C17: OTROS | D17: =TD!F14 -> 30.94 | E17: =IFERROR(F17/D17,0) -> 1279.9703 | F17: =TD!G14 -> 39602.28 | G17: =TD!H14 -> 6430.5696 | H17: =TD!I14 -> 1589.655 | I17: =TD!J14 -> 3124.9924 | J17: =TD!K14 -> 2498.0913 | K17: 0 | L17: 0 | M17: =F17+G17+H17+I17 -> 50747.497 | N17: =IFERROR(M17/D17,0) -> 1640.1906 | O17: =F17+G17+H17-J17 -> 45124.413 | P17: =IFERROR(O17/D17,0) -> 1458.449 | Q17: 1700 | R17: =Q17*D17 -> 52598 | S17: =R17-M17 -> 1850.5034 | T17: =IFERROR(S17/R17,0) -> 0.035182011 | U17: =R17-(M17-J17-I17) -> 7473.5871 | V17: =IFERROR(U17/R17,0) -> 0.14208881 | X17: {=SUM([1]Hoja5!$H$6:$H$12*([1]Hoja5!$E$6:$E$12=X$5)*($C17=[1]Hoja5!$J$6:$J$12))} -> 25.875 | Y17: {=SUM([1]Hoja5!$I$6:$I$12*([1]Hoja5!$E$6:$E$12=X$5)*($C17=[1]Hoja5!$J$6:$J$12))} -> 41400 | Z17: =IFERROR(Y17/X17,0) -> 1600 | AA17: {=SUM([1]Hoja5!$H$6:$H$12*([1]Hoja5!$E$6:$E$12=AA$5)*($C17=[1]Hoja5!$J$6:$J$12))} -> 0 | AB17: {=SUM([1]Hoja5!$I$6:$I$12*([1]Hoja5!$E$6:$E$12=AA$5)*($C17=[1]Hoja5!$J$6:$J$12))} -> 0 | AC17: =IFERROR(AB17/AA17,0) -> 0 | AD17: {=SUM([1]Hoja5!$H$6:$H$12*([1]Hoja5!$E$6:$E$12=AD$5)*($C17=[1]Hoja5!$J$6:$J$12))} -> 25.665 | AE17: {=SUM([1]Hoja5!$I$6:$I$12*([1]Hoja5!$E$6:$E$12=AD$5)*($C17=[1]Hoja5!$J$6:$J$12))} -> 41064 | AF17: =IFERROR(AE17/AD17,0) -> 1600 | AG17: {=SUM([1]Hoja5!$H$6:$H$12*([1]Hoja5!$E$6:$E$12=AG$5)*($C17=[1]Hoja5!$J$6:$J$12))} -> 0 | AH17: {=SUM([1]Hoja5!$I$6:$I$12*([1]Hoja5!$E$6:$E$12=AG$5)*($C17=[1]Hoja5!$J$6:$J$12))} -> 0 | AI17: =IFERROR(AH17/AG17,0) -> 0 | AJ17: =X17+AA17+AD17+AG17 -> 51.54 | AK17: =Y17+AB17+AE17+AH17 -> 82464 | AL17: =IFERROR(AK17/AJ17,0) -> 1600 | AM17: =-IFERROR(F17/D17*AJ17,0) -> -65969.667 | AN17: =-207.84*AJ17 -> -10712.074 | AO17: =$AO$20/$AJ$20*$AJ17 -> -14244.378 | AP17: =$AP$20/$AJ$20*$AJ17 -> -28002.034 | AQ17: =$AQ$20/$AJ$20*$AJ17 -> -22384.579 | AR17: =(AK17-AJ17*$AO$21)*0.03 -> 2297.3786 | AS17: =AK17+SUM(AM17:AP17,AR17) -> -34166.775 | AT17: =IFERROR(AS17/AK17,0) -> -0.41432352 | AU17: =AK17+AM17+AN17+AO17+AR17-AQ17 -> 16219.838 | AV17: =IFERROR(AU17/AK17,0) -> 0.19668993 | AX17: =AL17 -> 1600 | AY17: =IFERROR(AM17/$AJ17,0) -> -1279.9703 | AZ17: =IFERROR(AN17/$AJ17,0) -> -207.84 | BA17: =IFERROR(AO17/$AJ17,0) -> -276.37521 | BB17: =IFERROR(AP17/$AJ17,0) -> -543.30684 | BC17: =IFERROR(AQ17/$AJ17,0) -> -434.31468 | BD17: =IFERROR(AR17/$AJ17,0) -> 44.574672 | BE17: =IFERROR(AS17/$AJ17,0) -> -662.91763 | BF17: =IFERROR(AU17/$AJ17,0) -> 314.70389
C18: FILETE PARA REPROCESO | D18: =TD!F15 -> 0 | E18: =IFERROR(F18/D18,0) -> 0 | F18: =TD!G15 -> 0 | G18: =TD!H15 -> 0 | H18: =TD!I15 -> 0 | I18: =TD!J15 -> 0 | J18: =TD!K15 -> 0 | K18: 0 | L18: 0 | M18: =F18+G18+H18+I18 -> 0 | N18: =IFERROR(M18/D18,0) -> 0 | O18: =F18+G18+H18-J18 -> 0 | P18: =IFERROR(O18/D18,0) -> 0 | Q18: 1800 | R18: =Q18*D18 -> 0 | S18: =R18-M18 -> 0 | T18: =IFERROR(S18/R18,0) -> 0 | U18: =R18-(M18-J18-I18) -> 0 | V18: =IFERROR(U18/R18,0) -> 0 | X18: {=SUM([1]Hoja5!$H$6:$H$12*([1]Hoja5!$E$6:$E$12=X$5)*($C18=[1]Hoja5!$J$6:$J$12))} -> 0 | Y18: {=SUM([1]Hoja5!$I$6:$I$12*([1]Hoja5!$E$6:$E$12=X$5)*($C18=[1]Hoja5!$J$6:$J$12))} -> 0 | Z18: =IFERROR(Y18/X18,0) -> 0 | AA18: {=SUM([1]Hoja5!$H$6:$H$12*([1]Hoja5!$E$6:$E$12=AA$5)*($C18=[1]Hoja5!$J$6:$J$12))} -> 0 | AB18: {=SUM([1]Hoja5!$I$6:$I$12*([1]Hoja5!$E$6:$E$12=AA$5)*($C18=[1]Hoja5!$J$6:$J$12))} -> 0 | AC18: =IFERROR(AB18/AA18,0) -> 0 | AD18: {=SUM([1]Hoja5!$H$6:$H$12*([1]Hoja5!$E$6:$E$12=AD$5)*($C18=[1]Hoja5!$J$6:$J$12))} -> 0 | AE18: {=SUM([1]Hoja5!$I$6:$I$12*([1]Hoja5!$E$6:$E$12=AD$5)*($C18=[1]Hoja5!$J$6:$J$12))} -> 0 | AF18: =IFERROR(AE18/AD18,0) -> 0 | AG18: {=SUM([1]Hoja5!$H$6:$H$12*([1]Hoja5!$E$6:$E$12=AG$5)*($C18=[1]Hoja5!$J$6:$J$12))} -> 0 | AH18: {=SUM([1]Hoja5!$I$6:$I$12*([1]Hoja5!$E$6:$E$12=AG$5)*($C18=[1]Hoja5!$J$6:$J$12))} -> 0 | AI18: =IFERROR(AH18/AG18,0) -> 0 | AJ18: =X18+AA18+AD18+AG18 -> 0 | AK18: =Y18+AB18+AE18+AH18 -> 0 | AL18: =IFERROR(AK18/AJ18,0) -> 0 | AM18: =-IFERROR(F18/D18*AJ18,0) -> 0 | AN18: =-207.84*AJ18 -> 0 | AO18: =$AO$20/$AJ$20*$AJ18 -> 0 | AP18: =$AP$20/$AJ$20*$AJ18 -> 0 | AQ18: =$AQ$20/$AJ$20*$AJ18 -> 0 | AR18: =(AK18-AJ18*$AO$21)*0.03 -> 0 | AS18: =AK18+SUM(AM18:AP18,AR18) -> 0 | AT18: =IFERROR(AS18/AK18,0) -> 0 | AU18: =AK18+AM18+AN18+AO18+AR18-AQ18 -> 0 | AV18: =IFERROR(AU18/AK18,0) -> 0 | AX18: =AL18 -> 0 | AY18: =IFERROR(AM18/$AJ18,0) -> 0 | AZ18: =IFERROR(AN18/$AJ18,0) -> 0 | BA18: =IFERROR(AO18/$AJ18,0) -> 0 | BB18: =IFERROR(AP18/$AJ18,0) -> 0 | BC18: =IFERROR(AQ18/$AJ18,0) -> 0 | BD18: =IFERROR(AR18/$AJ18,0) -> 0 | BE18: =IFERROR(AS18/$AJ18,0) -> 0 | BF18: =IFERROR(AU18/$AJ18,0) -> 0
C19: ALAS PARA REPROCESO | D19: =TD!F16 -> 331.56 | E19: =IFERROR(F19/D19,0) -> 1731.9701 | F19: =TD!G16 -> 574252.02 | G19: =TD!H16 -> 68911.43 | H19: =TD!I16 -> 17035.101 | I19: =TD!J16 -> 33488.121 | J19: =TD!K16 -> 26770.108 | K19: 0 | L19: 0 | M19: =F19+G19+H19+I19 -> 693686.67 | N19: =IFERROR(M19/D19,0) -> 2092.1905 | O19: =F19+G19+H19-J19 -> 633428.44 | P19: =IFERROR(O19/D19,0) -> 1910.4489 | Q19: 1950 | R19: =Q19*D19 -> 646542 | S19: =R19-M19 -> -47144.668 | T19: =IFERROR(S19/R19,0) -> -0.072918183 | U19: =R19-(M19-J19-I19) -> 13113.562 | V19: =IFERROR(U19/R19,0) -> 0.020282614 | X19: {=SUM([1]Hoja5!$H$6:$H$12*([1]Hoja5!$E$6:$E$12=X$5)*($C19=[1]Hoja5!$J$6:$J$12))} -> 0 | Y19: {=SUM([1]Hoja5!$I$6:$I$12*([1]Hoja5!$E$6:$E$12=X$5)*($C19=[1]Hoja5!$J$6:$J$12))} -> 0 | Z19: =IFERROR(Y19/X19,0) -> 0 | AA19: {=SUM([1]Hoja5!$H$6:$H$12*([1]Hoja5!$E$6:$E$12=AA$5)*($C19=[1]Hoja5!$J$6:$J$12))} -> 0 | AB19: {=SUM([1]Hoja5!$I$6:$I$12*([1]Hoja5!$E$6:$E$12=AA$5)*($C19=[1]Hoja5!$J$6:$J$12))} -> 0 | AC19: =IFERROR(AB19/AA19,0) -> 0 | AD19: {=SUM([1]Hoja5!$H$6:$H$12*([1]Hoja5!$E$6:$E$12=AD$5)*($C19=[1]Hoja5!$J$6:$J$12))} -> 0 | AE19: {=SUM([1]Hoja5!$I$6:$I$12*([1]Hoja5!$E$6:$E$12=AD$5)*($C19=[1]Hoja5!$J$6:$J$12))} -> 0 | AF19: =IFERROR(AE19/AD19,0) -> 0 | AG19: {=SUM([1]Hoja5!$H$6:$H$12*([1]Hoja5!$E$6:$E$12=AG$5)*($C19=[1]Hoja5!$J$6:$J$12))} -> 0 | AH19: {=SUM([1]Hoja5!$I$6:$I$12*([1]Hoja5!$E$6:$E$12=AG$5)*($C19=[1]Hoja5!$J$6:$J$12))} -> 0 | AI19: =IFERROR(AH19/AG19,0) -> 0 | AJ19: =X19+AA19+AD19+AG19 -> 0 | AK19: =Y19+AB19+AE19+AH19 -> 0 | AL19: =IFERROR(AK19/AJ19,0) -> 0 | AM19: =-IFERROR(F19/D19*AJ19,0) -> 0 | AN19: =-207.84*AJ19 -> 0 | AO19: =$AO$20/$AJ$20*$AJ19 -> 0 | AP19: =$AP$20/$AJ$20*$AJ19 -> 0 | AQ19: =$AQ$20/$AJ$20*$AJ19 -> 0 | AR19: =(AK19-AJ19*$AO$21)*0.03 -> 0 | AS19: =AK19+SUM(AM19:AP19,AR19) -> 0 | AT19: =IFERROR(AS19/AK19,0) -> 0 | AU19: =AK19+AM19+AN19+AO19+AR19-AQ19 -> 0 | AV19: =IFERROR(AU19/AK19,0) -> 0 | AX19: =AL19 -> 0 | AY19: =IFERROR(AM19/$AJ19,0) -> 0 | AZ19: =IFERROR(AN19/$AJ19,0) -> 0 | BA19: =IFERROR(AO19/$AJ19,0) -> 0 | BB19: =IFERROR(AP19/$AJ19,0) -> 0 | BC19: =IFERROR(AQ19/$AJ19,0) -> 0 | BD19: =IFERROR(AR19/$AJ19,0) -> 0 | BE19: =IFERROR(AS19/$AJ19,0) -> 0 | BF19: =IFERROR(AU19/$AJ19,0) -> 0
C20: TOTAL | D20: =SUM(D7:D19) -> 1529.41 | E20: =IFERROR(F20/D20,0) -> 1686.0604 | F20: =SUM(F7:F19) -> 2578677.6 | G20: =SUM(G7:G19) -> 317872.57 | H20: =SUM(H7:H19) -> 78579 | I20: =SUM(I7:I19) -> 154473 | J20: =SUM(J7:J19) -> 123484.35 | K20: =SUM(K7:K19) -> 0 | L20: 0 | M20: =SUM(M7:M19) -> 3129602.2 | N20: =IFERROR(M20/D20,0) -> 2046.2807 | O20: =SUM(O7:O19) -> 2851644.9 | P20: =IFERROR(O20/D20,0) -> 1864.5392 | Q20: =R20/D20 -> 2144.9291 | R20: =SUM(R7:R19) -> 3280476 | S20: =SUM(S7:S19) -> 150873.79 | T20: =S20/R20 -> 0.045991433 | U20: =SUM(U7:U19) -> 428831.14 | V20: =IFERROR(U20/R20,0) -> 0.13072223 | X20: =SUM(X7:X19) -> 133.275 | Y20: =SUM(Y7:Y19) -> 296940 | Z20: =IFERROR(Y20/X20,0) -> 2228.0248 | AA20: =SUM(AA7:AA19) -> 27 | AB20: =SUM(AB7:AB19) -> 48600 | AC20: =IFERROR(AB20/AA20,0) -> 1800 | AD20: =SUM(AD7:AD19) -> 25.665 | AE20: =SUM(AE7:AE19) -> 41064 | AF20: =IFERROR(AE20/AD20,0) -> 1600 | AG20: =SUM(AG7:AG19) -> 98.38 | AH20: =SUM(AH7:AH19) -> 140424 | AI20: =IFERROR(AH20/AG20,0) -> 1427.3633 | AJ20: =SUM(AJ7:AJ19) -> 284.32 | AK20: =SUM(AK7:AK19) -> 527028 | AL20: =IFERROR(AK20/AJ20,0) -> 1853.6438 | AM20: =SUM(AM7:AM19) -> -415442.57 | AN20: =SUM(AN7:AN19) -> -59093.069 | AO20: =-'[2]Stock Libre'!O54 -> -78579 | AP20: =-'[2]Stock Libre'!P54 -> -154473 | AQ20: =-'[2]Stock Libre'!Q54 -> -123484.35 | AR20: =SUM(AR7:AR19) -> 14836.951 | AS20: =SUM(AS7:AS19) -> -165722.69 | AT20: =IFERROR(AS20/AK20,0) -> -0.3144476 | AU20: =SUM(AU7:AU19) -> 112234.66 | AV20: =IFERROR(AU20/AK20,0) -> 0.21295768 | AX20: =AL20 -> 1853.6438 | AY20: =IFERROR(AM20/$AJ20,0) -> -1461.1796 | AZ20: =IFERROR(AN20/$AJ20,0) -> -207.84 | BA20: =IFERROR(AO20/$AJ20,0) -> -276.37521 | BB20: =IFERROR(AP20/$AJ20,0) -> -543.30684 | BC20: =IFERROR(AQ20/$AJ20,0) -> -434.31468 | BD20: =IFERROR(AR20/$AJ20,0) -> 52.183985 | BE20: =IFERROR(AS20/$AJ20,0) -> -582.87384 | BF20: =IFERROR(AU20/$AJ20,0) -> 394.74768
N21: =M20-R20 -> -150873.79 | AN21: flete x tm | AO21: 114.17761
C22: TM en Almacén de Yantai Jiahong | R22: =7%/12 -> 0.0058333333 | AY22: =SUM(AY7:BB7) -> 0
R23: =R22*M31 -> 22283.591 | S23: =R23*7 -> 155985.14 | T23: =S23/D31 -> 111.17179 | AJ23: =286 -> 286
C24: Producto | D24: TM en Stock Libre | E24: CU | F24: Costo Ventas | G24: Gasto Ventas | H24: Gasto ADM | I24: Gasto Fin | J24: Depreciación | K24: Utilidad Neta | L24: Margen Neto | M24: Venta Equilibrio a Utd Neta | N24: Precio Equilibrio x TM a Utd Neta | O24: Venta Equilibro a EBITDA | P24: Precio Equilibrio x TM a EBITDA | Q24: Precio Mercado | R24: Venta total | S24: Utilidad | T24: Mg Neto | U24: EBITDA | V24: Mg EBITDA | AJ24: =AK20/AJ20*AJ23 -> 530142.12 | AM24: =AK20+AM20+AN20 -> 52492.359 | AY24: =AY7/0.5 -> 0
C25: POTA FILETE CONGELADO | D25: 567 | E25: =E7 -> 1834.431 | F25: =E25*D25 -> 1040122.4 | G25: =D25*207.84 -> 117845.28 | H25: =H$20/$D$20*$D25 -> 29131.687 | I25: =I$20/$D$20*$D25 -> 57267.96 | J25: =J$20/$D$20*$D25 -> 45779.501 | K25: 0 | L25: 0 | M25: =F25+G25+H25+I25 -> 1244367.3 | N25: =IFERROR(M25/D25,0) -> 2194.6513 | O25: =F25+G25+H25-J25 -> 1141319.8 | P25: =IFERROR(O25/D25,0) -> 2012.9098 | Q25: 1500 | R25: =Q25*D25 -> 850500 | S25: =R25-M25 -> -393867.31 | T25: =IFERROR(S25/R25,0) -> -0.46310089 | U25: =R25-(M25-J25-I25) -> -290819.85 | V25: =IFERROR(U25/R25,0) -> -0.34193985
C26: POTA ALAS CONGELADAS | D26: 54 | E26: =E9 -> 1731.9701 | F26: =E26*D26 -> 93526.387 | G26: =D26*207.84 -> 11223.36 | H26: =H$20/$D$20*$D26 -> 2774.4464 | I26: =I$20/$D$20*$D26 -> 5454.0914 | J26: =J$20/$D$20*$D26 -> 4359.9525 | K26: 0 | L26: 0 | M26: =F26+G26+H26+I26 -> 112978.28 | N26: =IFERROR(M26/D26,0) -> 2092.1905 | O26: =F26+G26+H26-J26 -> 103164.24 | P26: =IFERROR(O26/D26,0) -> 1910.4489 | Q26: 1700 | R26: =Q26*D26 -> 91800 | S26: =R26-M26 -> -21178.285 | T26: =IFERROR(S26/R26,0) -> -0.23070027 | U26: =R26-(M26-J26-I26) -> -11364.241 | AK26: 386604
C27: POTA REJOS CONGELADOS | D27: 108 | E27: =E11 -> 1596.5588 | F27: =E27*D27 -> 172428.35 | G27: =D27*207.84 -> 22446.72 | H27: =H$20/$D$20*$D27 -> 5548.8927 | I27: =I$20/$D$20*$D27 -> 10908.183 | J27: =J$20/$D$20*$D27 -> 8719.9049 | K27: 0 | L27: 0 | M27: =F27+G27+H27+I27 -> 211332.15 | N27: =IFERROR(M27/D27,0) -> 1956.7791 | O27: =F27+G27+H27-J27 -> 191704.06 | P27: =IFERROR(O27/D27,0) -> 1775.0376 | Q27: 2275 | R27: =Q27*D27 -> 245700 | S27: =R27-M27 -> 34367.852 | T27: =IFERROR(S27/R27,0) -> 0.1398773 | U27: =R27-(M27-J27-I27) -> 53995.94 | V27: =IFERROR(U27/R27,0) -> 0.2197637 | AK27: =AK20-AK26 -> 140424
C28: POTA FILETE DARUMA | D28: 594 | E28: =E14 -> 3085.0611 | F28: =E28*D28 -> 1832526.3 | G28: =D28*207.84 -> 123456.96 | H28: =H$20/$D$20*$D28 -> 30518.91 | I28: =I$20/$D$20*$D28 -> 59995.006 | J28: =J$20/$D$20*$D28 -> 47959.477 | K28: 0 | L28: 0 | M28: =F28+G28+H28+I28 -> 2046497.2 | N28: =IFERROR(M28/D28,0) -> 3445.2815 | O28: =F28+G28+H28-J28 -> 1938542.7 | P28: =IFERROR(O28/D28,0) -> 3263.5399 | Q28: 3400 | R28: =Q28*D28 -> 2019600 | S28: =R28-M28 -> -26897.183 | T28: =IFERROR(S28/R28,0) -> -0.013318075 | U28: =R28-(M28-J28-I28) -> 81057.3 | V28: =IFERROR(U28/R28,0) -> 0.040135324
C29: POTA ALAS COCIDAS | D29: 53.1 | E29: =E15 -> 2649.6026 | F29: =E29*D29 -> 140693.9 | G29: =D29*207.84 -> 11036.304 | H29: =H$20/$D$20*$D29 -> 2728.2056 | I29: =I$20/$D$20*$D29 -> 5363.1899 | J29: =J$20/$D$20*$D29 -> 4287.2866 | K29: 0 | L29: 0 | M29: =F29+G29+H29+I29 -> 159821.6 | N29: =IFERROR(M29/D29,0) -> 3009.8229 | O29: =F29+G29+H29-J29 -> 150171.12 | P29: =IFERROR(O29/D29,0) -> 2828.0814 | Q29: 3400 | R29: =Q29*D29 -> 180540 | S29: =R29-M29 -> 20718.402 | T29: =IFERROR(S29/R29,0) -> 0.11475796 | U29: =R29-(M29-J29-I29) -> 30368.879
C30: POTA RECORTES COCIDOS | D30: 27 | E30: =E10 -> 1308.2098 | F30: =E30*D30 -> 35321.665 | G30: =D30*207.84 -> 5611.68 | H30: =H$20/$D$20*$D30 -> 1387.2232 | I30: =I$20/$D$20*$D30 -> 2727.0457 | J30: =J$20/$D$20*$D30 -> 2179.9762 | K30: 0 | L30: 0 | M30: =F30+G30+H30+I30 -> 45047.614 | N30: =IFERROR(M30/D30,0) -> 1668.4302 | O30: =F30+G30+H30-J30 -> 40140.592 | P30: =IFERROR(O30/D30,0) -> 1486.6886 | Q30: 1800 | R30: =Q30*D30 -> 48600 | S30: =R30-M30 -> 3552.3859 | T30: =IFERROR(S30/R30,0) -> 0.07309436 | U30: =R30-(M30-J30-I30) -> 8459.4078
C31: TOTAL | D31: =SUM(D25:D30) -> 1403.1 | E31: =F31/D31 -> 2362.3541 | F31: =SUM(F25:F30) -> 3314619 | G31: =SUM(G25:G30) -> 291620.3 | H31: =SUM(H25:H30) -> 72089.364 | I31: =SUM(I25:I30) -> 141715.48 | J31: =SUM(J25:J30) -> 113286.1 | K31: =SUM(K25:K30) -> 0 | L31: 0 | M31: =SUM(M25:M30) -> 3820044.1 | N31: =IFERROR(M31/D31,0) -> 2722.5744 | O31: =SUM(O25:O30) -> 3565042.6 | P31: =IFERROR(O31/D31,0) -> 2540.8328 | Q31: =R31/D31 -> 2449.3906 | R31: =SUM(R25:R30) -> 3436740 | S31: =SUM(S25:S30) -> -383304.13 | T31: =S31/R31 -> -0.11153132 | U31: =SUM(U25:U30) -> -128302.56 | V31: =IFERROR(U31/R31,0) -> -0.037332635
C33: TOTAL | D33: =D20+D31 -> 2932.51 | E33: =F33/D33 -> 2009.6425 | F33: =F20+F31 -> 5893296.6 | G33: =G20+G31 -> 609492.88 | H33: =H20+H31 -> 150668.36 | I33: =I20+I31 -> 296188.48 | J33: =J20+J31 -> 236770.45 | K33: =K20+K31 -> 0 | L33: =L20+L31 -> 0 | M33: =M20+M31 -> 6949646.3 | N33: =IFERROR(M33/D33,0) -> 2369.8628 | O33: =O20+O31 -> 6416687.4 | P33: =IFERROR(O33/D33,0) -> 2188.1212 | Q33: =R33/D33 -> 2290.6029 | R33: =R20+R31 -> 6717216 | S33: =S20+S31 -> -232430.34 | T33: =S33/R33 -> -0.034602184 | U33: =U20+U31 -> 300528.58 | V33: =IFERROR(U33/R33,0) -> 0.04474005
C36: INVENTARIO TOTAL VALORIZADO
C38: Producto | D38: TM en Stock Libre | E38: CU | F38: Costo Ventas | G38: Gasto Ventas | H38: Gasto ADM | I38: Gasto Fin | J38: Depreciación | K38: Utilidad Neta | L38: Margen Neto | M38: Venta Equilibrio a Utd Neta | N38: Precio Equilibrio x TM a Utd Neta | O38: Precio Venta | P38: Venta Esperada | Q38: Utilidad Neta | R38: Margen Neto | S38: Precio actual | T38: venta con precio actual | U38: P/L | V38: variación | X38: ebitda con nuevos precios
C39: POTA FILETE CONGELADO | D39: =D7+D25 -> 633.96 | E39: =IFERROR(F39/D39,0) -> 1834.431 | F39: =F7+F25 -> 1162955.9 | G39: =G7+G25 -> 131762.25 | H39: =H7+H25 -> 32572 | I39: =I7+I25 -> 64031.034 | J39: =J7+J25 -> 51185.842 | K39: 0 | L39: 0 | M39: =F39+G39+H39+I39 -> 1391321.2 | N39: =IFERROR(M39/D39,0) -> 2194.6513 | O39: 2200 | P39: =O39*D39 -> 1394712 | Q39: =P39-M39 -> 3390.8392 | R39: =Q39/P39 -> 0.002431211 | S39: =Q25 -> 1500 | T39: =S39*D39 -> 950940 | U39: =T39-M39 -> -440381.16 | V39: =Q39-U39 -> 443772 | X39: =Q39+I39+J39 -> 118607.71
C40: POTA NUCAS CONGELADAS | D40: =D8 -> 379.14 | E40: =IFERROR(F40/D40,0) -> 1483.423 | F40: =F8 -> 562424.98 | G40: =G8 -> 78800.458 | H40: =H8 -> 19479.696 | I40: =I8 -> 38293.782 | J40: =J8 -> 30611.711 | K40: 0 | L40: 0 | M40: =F40+G40+H40+I40 -> 698998.92 | N40: =IFERROR(M40/D40,0) -> 1843.6433 | O40: 1400 | P40: =O40*D40 -> 530796 | Q40: =P40-M40 -> -168202.92 | R40: =Q40/P40 -> -0.31688807 | S40: =Q8 -> 1400 | T40: =S40*D40 -> 530796 | U40: =T40-M40 -> -168202.92 | V40: =Q40-U40 -> 0 | X40: =Q40+I40+J40 -> -99297.427
C41: POTA ALAS CONGELADAS | D41: =D9+D26 -> 71.9 | E41: =IFERROR(F41/D41,0) -> 1731.9701 | F41: =F9+F26 -> 124528.65 | G41: =G9+G26 -> 14943.696 | H41: =H9+H26 -> 3694.1239 | I41: =I9+I26 -> 7262.0218 | J41: =J9+J26 -> 5805.196 | K41: 0 | L41: 0 | M41: =F41+G41+H41+I41 -> 150428.49 | N41: =IFERROR(M41/D41,0) -> 2092.1905 | O41: 2400 | P41: =O41*D41 -> 172560 | Q41: =P41-M41 -> 22131.506 | R41: =Q41/P41 -> 0.12825398 | S41: =Q9 -> 1950 | T41: =S41*D41 -> 140205 | U41: =T41-M41 -> -10223.494 | V41: =Q41-U41 -> 32355 | X41: =Q41+I41+J41 -> 35198.724
C42: POTA RECORTES COCIDOS | D42: =D10+D30 -> 151.54 | E42: =IFERROR(F42/D42,0) -> 1308.2098 | F42: =F10+F30 -> 198246.12 | G42: =G10+G30 -> 31496.074 | H42: =H10+H30 -> 7785.9185 | I42: =I10+I30 -> 15305.797 | J42: =J10+J30 -> 12235.318 | K42: 0 | L42: 0 | M42: =F42+G42+H42+I42 -> 252833.91 | N42: =IFERROR(M42/D42,0) -> 1668.4302 | O42: 2500 | P42: =O42*D42 -> 378850 | Q42: =P42-M42 -> 126016.09 | R42: =Q42/P42 -> 0.33262794 | S42: =Q10 -> 1700 | T42: =S42*D42 -> 257618 | U42: =T42-M42 -> 4784.0946 | V42: =Q42-U42 -> 121232 | X42: =Q42+I42+J42 -> 153557.21
C43: POTA REJOS CONGELADOS | D43: =D11+D27 -> 378.4 | E43: =IFERROR(F43/D43,0) -> 1596.5588 | F43: =F11+F27 -> 604137.86 | G43: =G11+G27 -> 78646.656 | H43: =H11+H27 -> 19441.676 | I43: =I11+I27 -> 38219.041 | J43: =J11+J27 -> 30551.963 | K43: 0 | L43: 0 | M43: =F43+G43+H43+I43 -> 740445.23 | N43: =IFERROR(M43/D43,0) -> 1956.7791 | O43: 2800 | P43: =O43*D43 -> 1059520 | Q43: =P43-M43 -> 319074.77 | R43: =Q43/P43 -> 0.30115031 | S43: =Q11 -> 2700 | T43: =S43*D43 -> 1021680 | U43: =T43-M43 -> 281234.77 | V43: =Q43-U43 -> 37840 | X43: =Q43+I43+J43 -> 387845.78
C44: POTA REPRODUCTORES | D44: =D12 -> 132.38 | E44: =IFERROR(F44/D44,0) -> 1540.1637 | F44: =F12 -> 203886.87 | G44: =G12 -> 27513.859 | H44: =H12 -> 6801.5039 | I44: =I12 -> 13370.604 | J44: =J12 -> 10688.343 | K44: 0 | L44: 0 | M44: =F44+G44+H44+I44 -> 251572.83 | N44: =IFERROR(M44/D44,0) -> 1900.384 | O44: 2800 | P44: =O44*D44 -> 370664 | Q44: =P44-M44 -> 119091.17 | R44: =Q44/P44 -> 0.32129143 | S44: =Q12 -> 2800 | T44: =S44*D44 -> 370664 | U44: =T44-M44 -> 119091.17 | V44: =Q44-U44 -> 0 | X44: =Q44+I44+J44 -> 143150.11
C45: POTA CONOS | D45: =D13 -> 0 | E45: =IFERROR(F45/D45,0) -> 0 | F45: =F13 -> 0 | G45: =G13 -> 0 | H45: =H13 -> 0 | I45: =I13 -> 0 | J45: =J13 -> 0 | K45: 0 | L45: 0 | M45: =F45+G45+H45+I45 -> 0 | N45: =IFERROR(M45/D45,0) -> 0 | O45: 1800 | P45: =O45*D45 -> 0 | Q45: =P45-M45 -> 0 | R45: =Q45/P45 -> #DIV/0! | S45: =Q13 -> 1700 | T45: =S45*D45 -> 0 | U45: =T45-M45 -> 0 | V45: =Q45-U45 -> 0 | X45: =Q45+I45+J45 -> 0
C46: POTA FILETE DARUMA | D46: =D14+D28+D18*0.5 -> 610.48 | E46: =IFERROR(F46/D46,0) -> 3085.0611 | F46: =F14+F28+F18 -> 1883368.1 | G46: =G14+G28+G18 -> 126882.16 | H46: =H14+H28+H18 -> 31365.63 | I46: =I14+I28+I18 -> 61659.514 | J46: =J14+J28+J18 -> 49290.07 | K46: 0 | L46: 0 | M46: =F46+G46+H46+I46 -> 2103275.4 | N46: =IFERROR(M46/D46,0) -> 3445.2815 | O46: 4000 | P46: =O46*D46 -> 2441920 | Q46: =P46-M46 -> 338644.58 | R46: =Q46/P46 -> 0.13867964 | S46: =Q14 -> 3500 | T46: =S46*D46 -> 2136680 | U46: =T46-M46 -> 33404.578 | V46: =Q46-U46 -> 305240 | X46: =Q46+I46+J46 -> 449594.16
...

Sheet TD
E3: CÓDIGO | F3: Suma de TM en Stock Total | G3: Suma de Costo Ventas | H3: Suma de Gasto Ventas | I3: Suma de Gasto ADM | J3: Suma de Gasto Fin | K3: Suma de Depreciación
B4: =C4=E4 -> TRUE | C4: 10005721 | D4: POTA FILETE CONGELADO | E4: 10005721 | F4: 66.96 | G4: 122833.5 | H4: 13916.966 | I4: 3440.3135 | J4: 6763.0734 | K4: 5406.3411
B5: =C5=E5 -> TRUE | C5: 10005779 | D5: POTA NUCAS CONGELADAS | E5: 10005779 | F5: 379.14 | G5: 562424.98 | H5: 78800.458 | I5: 19479.696 | J5: 38293.782 | K5: 30611.711
B6: =C6=E6 -> TRUE | C6: 10006719 | D6: POTA ALAS CONGELADAS | E6: 10006719 | F6: 17.9 | G6: 31002.265 | H6: 3720.336 | I6: 919.67759 | J6: 1807.9303 | K6: 1445.2435
B7: =C7=E7 -> TRUE | C7: 10007050 | D7: POTA RECORTES COCIDOS | E7: 10007050 | F7: 124.54 | G7: 162924.45 | H7: 25884.394 | I7: 6398.6954 | J7: 12578.751 | K7: 10055.342
B8: =C8=E8 -> TRUE | C8: 10007162 | D8: POTA REJOS CONGELADOS | E8: 10007162 | F8: 270.4 | G8: 431709.5 | H8: 56199.936 | I8: 13892.783 | J8: 27310.858 | K8: 21832.058
B9: =C9=E9 -> TRUE | C9: 10007567 | D9: POTA REPRODUCTORES | E9: 10007567 | F9: 132.38 | G9: 203886.87 | H9: 27513.859 | I9: 6801.5039 | J9: 13370.604 | K9: 10688.343
B10: =C10=E10 -> TRUE | C10: 10007969 | D10: POTA CONOS | E10: 10007969 | F10: 0 | G10: 0 | H10: 0 | I10: 0 | J10: 0 | K10: 0
B11: =C11=E11 -> TRUE | C11: 10009239 | D11: POTA FILETE DARUMA | E11: 10009239 | F11: 16.48 | G11: 50841.807 | H11: 3425.2032 | I11: 846.71992 | J11: 1664.5079 | K11: 1330.5929
B12: =C12=E12 -> TRUE | C12: 10009334 | D12: POTA ALAS COCIDAS | E12: 10009334 | F12: 137.83 | G12: 365194.73 | H12: 28646.587 | I12: 7081.5174 | J12: 13921.063 | K12: 11128.375
B13: =C13=E13 -> TRUE | C13: 10009386 | D13: VENTOSAS | E13: 10009386 | F13: 21.28 | G13: 34005.233 | H13: 4422.8352 | I13: 1093.3374 | J13: 2149.316 | K13: 1718.1442
B14: =C14=E14 -> FALSE | D14: OTROS | E14: 10009207 | F14: 30.94 | G14: 39602.28 | H14: 6430.5696 | I14: 1589.655 | J14: 3124.9924 | K14: 2498.0913
D15: FILETE PARA REPROCESO | E15: 10009650 | F15: 0 | G15: 0 | H15: 0 | I15: 0 | J15: 0 | K15: 0
D16: ALAS PARA REPROCESO | E16: 10009649 | F16: 331.56 | G16: 574252.02 | H16: 68911.43 | I16: 17035.101 | J16: 33488.121 | K16: 26770.108
E17: Total Resultado | F17: 1529.41 | G17: 2578677.6 | H17: 317872.57 | I17: 78579 | J17: 154473 | K17: 123484.35

Sheet Stock Libre
B1: PRODUCTO | C1: TOTAL STOCK | D1: POR EMBARCAR | E1: STOCK LIBRE | G1: CÓDIGO | H1: CU X TM | I1: % MP | J1: incremento MP | K1: TM en Stock Total | L1: TM en Stock | M1: Costo Ventas | N1: Gasto Ventas | O1: Gasto ADM | P1: Gasto Fin | Q1: Depreciación | R1: Utilidad Neta | S1: Margen Neto | T1: Venta Equilibrio | U1: Precio Equilibrio x TM
B2: POTA ALAS FR C/P C/C < 0.5 BL10 S20 | C2: 680 | G2: 10006719 | H2: =IFERROR(INDEX([3]Resumen!$K$3:$K$63,MATCH(G2,[3]Resumen!$C$3:$C$63,0)),0)*(1+I2*J2)/1000-51.89/1000-93.38/1000 -> 1.7319701 | I2: 0.71 | J2: =$H$59 -> -0.10965909 | K2: =C2/1000 -> 0.68 | L2: =IF(C2<0,0,C2)/1000 -> 0.68 | M2: =IFERROR(H2*L2,0)*1000 -> 1177.7397 | N2: =207.84*L2 -> 141.3312 | O2: =$O$54/$L$52*L2 -> 45.401203 | P2: =$P$54/$L$52*L2 -> 89.251073 | Q2: =$Q$54/$L$52*L2 -> 71.346518 | R2: 0 | S2: 0 | T2: =M2+N2+O2+P2 -> 1453.7232 | U2: =IFERROR(T2/L2,0) -> 2137.8282
B3: POTA ALAS FR C/P C/C AA S/COD BL10 S20 | C3: 14840 | G3: 10006719 | H3: =IFERROR(INDEX([3]Resumen!$K$3:$K$63,MATCH(G3,[3]Resumen!$C$3:$C$63,0)),0)*(1+I3*J3)/1000-51.89/1000-93.38/1000 -> 1.7319701 | I3: 0.71 | J3: =$H$59 -> -0.10965909 | K3: =C3/1000 -> 14.84 | L3: =IF(C3<0,0,C3)/1000 -> 14.84 | M3: =IFERROR(H3*L3,0)*1000 -> 25702.437 | N3: =207.84*L3 -> 3084.3456 | O3: =$O$54/$L$52*L3 -> 990.81449 | P3: =$P$54/$L$52*L3 -> 1947.7734 | Q3: =$Q$54/$L$52*L3 -> 1557.0328 | R3: 0 | S3: 0 | T3: =M3+N3+O3+P3 -> 31725.37 | U3: =IFERROR(T3/L3,0) -> 2137.8282
B4: POTA ALAS FR C/P C/C 1.0-2.0 BL10 S20 | C4: 40 | G4: 10006719 | H4: =IFERROR(INDEX([3]Resumen!$K$3:$K$63,MATCH(G4,[3]Resumen!$C$3:$C$63,0)),0)*(1+I4*J4)/1000-51.89/1000-93.38/1000 -> 1.7319701 | I4: 0.71 | J4: =$H$59 -> -0.10965909 | K4: =C4/1000 -> 0.04 | L4: =IF(C4<0,0,C4)/1000 -> 0.04 | M4: =IFERROR(H4*L4,0)*1000 -> 69.278805 | N4: =207.84*L4 -> 8.3136 | O4: =$O$54/$L$52*L4 -> 2.670659 | P4: =$P$54/$L$52*L4 -> 5.2500631 | Q4: =$Q$54/$L$52*L4 -> 4.196854 | R4: 0 | S4: 0 | T4: =M4+N4+O4+P4 -> 85.513127 | U4: =IFERROR(T4/L4,0) -> 2137.8282
B5: POTA ALAS FR C/P C/C 1.0-2.0 ENT BL10 S20 | C5: 2340 | G5: 10006719 | H5: =IFERROR(INDEX([3]Resumen!$K$3:$K$63,MATCH(G5,[3]Resumen!$C$3:$C$63,0)),0)*(1+I5*J5)/1000-51.89/1000-93.38/1000 -> 1.7319701 | I5: 0.71 | J5: =$H$59 -> -0.10965909 | K5: =C5/1000 -> 2.34 | L5: =IF(C5<0,0,C5)/1000 -> 2.34 | M5: =IFERROR(H5*L5,0)*1000 -> 4052.8101 | N5: =207.84*L5 -> 486.3456 | O5: =$O$54/$L$52*L5 -> 156.23355 | P5: =$P$54/$L$52*L5 -> 307.12869 | Q5: =$Q$54/$L$52*L5 -> 245.51596 | R5: 0 | S5: 0 | T5: =M5+N5+O5+P5 -> 5002.5179 | U5: =IFERROR(T5/L5,0) -> 2137.8282
B6: POTA ALAS FR C/P C/C 2.0-UP BL10 S20 | C6: 120 | G6: 10006719 | H6: =IFERROR(INDEX([3]Resumen!$K$3:$K$63,MATCH(G6,[3]Resumen!$C$3:$C$63,0)),0)*(1+I6*J6)/1000-51.89/1000-93.38/1000 -> 1.7319701 | I6: 0.71 | J6: =$H$59 -> -0.10965909 | K6: =C6/1000 -> 0.12 | L6: =IF(C6<0,0,C6)/1000 -> 0.12 | M6: =IFERROR(H6*L6,0)*1000 -> 207.83642 | N6: =207.84*L6 -> 24.9408 | O6: =$O$54/$L$52*L6 -> 8.011977 | P6: =$P$54/$L$52*L6 -> 15.750189 | Q6: =$Q$54/$L$52*L6 -> 12.590562 | R6: 0 | S6: 0 | T6: =M6+N6+O6+P6 -> 256.53938 | U6: =IFERROR(T6/L6,0) -> 2137.8282
B7: POTA ALAS PRE COC S/COD BL10 S20 | C7: 260 | G7: 10006719 | H7: =IFERROR(INDEX([3]Resumen!$K$3:$K$63,MATCH(G7,[3]Resumen!$C$3:$C$63,0)),0)*(1+I7*J7)/1000-51.89/1000-93.38/1000 -> 1.7319701 | I7: 0.71 | J7: =$H$59 -> -0.10965909 | K7: =C7/1000 -> 0.26 | L7: =IF(C7<0,0,C7)/1000 -> 0.26 | M7: =IFERROR(H7*L7,0)*1000 -> 450.31223 | N7: =207.84*L7 -> 54.0384 | O7: =$O$54/$L$52*L7 -> 17.359283 | P7: =$P$54/$L$52*L7 -> 34.12541 | Q7: =$Q$54/$L$52*L7 -> 27.279551 | R7: 0 | S7: 0 | T7: =M7+N7+O7+P7 -> 555.83533 | U7: =IFERROR(T7/L7,0) -> 2137.8282
B8: POTA ALAS PRE COC 0.3 - UP BL9 S18 | C8: =163764+108000+50000/2 -> 296764 | G8: 10006719 | H8: =IFERROR(INDEX([3]Resumen!$K$3:$K$63,MATCH(G8,[3]Resumen!$C$3:$C$63,0)),0)*(1+I8*J8)/1000-51.89/1000-93.38/1000 -> 1.7319701 | I8: 0.71 | J8: =$H$59 -> -0.10965909 | K8: =C8/1000 -> 296.764 | L8: =IF(C8<0,0,C8)/1000 -> 296.764 | M8: =IFERROR(H8*L8,0)*1000 -> 513986.38 | N8: =207.84*L8 -> 61679.43 | O8: =$O$54/$L$52*L8 -> 19813.886 | P8: =$P$54/$L$52*L8 -> 38950.743 | Q8: =$Q$54/$L$52*L8 -> 31136.88 | R8: 0 | S8: 0 | T8: =M8+N8+O8+P8 -> 634430.44 | U8: =IFERROR(T8/L8,0) -> 2137.8282
B9: POTA ALAS PRE COC AA BL9 S18 | C9: 14744 | G9: 10009207 | H9: =IFERROR(INDEX([3]Resumen!$K$3:$K$63,MATCH(G9,[3]Resumen!$C$3:$C$63,0)),0)*(1+I9*J9)/1000-51.89/1000-93.38/1000 -> 1.2799703 | I9: 0.71 | J9: =$H$59 -> -0.10965909 | K9: =C9/1000 -> 14.744 | L9: =IF(C9<0,0,C9)/1000 -> 14.744 | M9: =IFERROR(H9*L9,0)*1000 -> 18871.881 | N9: =207.84*L9 -> 3064.393 | O9: =$O$54/$L$52*L9 -> 984.40491 | P9: =$P$54/$L$52*L9 -> 1935.1733 | Q9: =$Q$54/$L$52*L9 -> 1546.9604 | R9: 0 | S9: 0 | T9: =M9+N9+O9+P9 -> 24855.853 | U9: =IFERROR(T9/L9,0) -> 1685.8283
B10: POTA FILETE C/M C/T FR 1.0 - 2.0 BL10 S20 | C10: 1760 | G10: 10007969 | H10: =IFERROR(INDEX([3]Resumen!$K$3:$K$63,MATCH(G10,[3]Resumen!$C$3:$C$63,0)),0)*(1+I10*J10)/1000-51.89/1000-93.38/1000 -> 1.2330367 | I10: 0.71 | J10: =$H$59 -> -0.10965909 | K10: =C10/1000 -> 1.76 | L10: =IF(C10<0,0,C10)/1000 -> 1.76 | M10: =IFERROR(H10*L10,0)*1000 -> 2170.1446 | N10: =207.84*L10 -> 365.7984 | O10: =$O$54/$L$52*L10 -> 117.509 | P10: =$P$54/$L$52*L10 -> 231.00278 | Q10: =$Q$54/$L$52*L10 -> 184.66158 | R10: 0 | S10: 0 | T10: =M10+N10+O10+P10 -> 2884.4548 | U10: =IFERROR(T10/L10,0) -> 1638.8948
B11: POTA FILETE C/M C/T FR < 0.5 AA BL10 S20 | C11: 1080 | G11: 10005721 | H11: =IFERROR(INDEX([3]Resumen!$K$3:$K$63,MATCH(G11,[3]Resumen!$C$3:$C$63,0)),0)*(1+I11*J11)/1000-51.89/1000-93.38/1000 -> 1.834431 | I11: 0.67 | J11: =$H$59 -> -0.10965909 | K11: =C11/1000 -> 1.08 | L11: =IF(C11<0,0,C11)/1000 -> 1.08 | M11: =IFERROR(H11*L11,0)*1000 -> 1981.1855 | N11: =207.84*L11 -> 224.4672 | O11: =$O$54/$L$52*L11 -> 72.107793 | P11: =$P$54/$L$52*L11 -> 141.7517 | Q11: =$Q$54/$L$52*L11 -> 113.31506 | R11: 0 | S11: 0 | T11: =M11+N11+O11+P11 -> 2419.5122 | U11: =IFERROR(T11/L11,0) -> 2240.2891
B12: POTA FILETE C/M C/T FR 1.0 - 2.0 AA BL10 S20 | C12: 20240 | G12: 10005721 | H12: =IFERROR(INDEX([3]Resumen!$K$3:$K$63,MATCH(G12,[3]Resumen!$C$3:$C$63,0)),0)*(1+I12*J12)/1000-51.89/1000-93.38/1000 -> 1.834431 | I12: 0.67 | J12: =$H$59 -> -0.10965909 | K12: =C12/1000 -> 20.24 | L12: =IF(C12<0,0,C12)/1000 -> 20.24 | M12: =IFERROR(H12*L12,0)*1000 -> 37128.884 | N12: =207.84*L12 -> 4206.6816 | O12: =$O$54/$L$52*L12 -> 1351.3535 | P12: =$P$54/$L$52*L12 -> 2656.5319 | Q12: =$Q$54/$L$52*L12 -> 2123.6081 | R12: 0 | S12: 0 | T12: =M12+N12+O12+P12 -> 45343.451 | U12: =IFERROR(T12/L12,0) -> 2240.2891
B13: POTA FILETE C/M C/T FR 1.0 - 3.0 AA BL10 S20 | C13: 5280 | G13: 10005721 | H13: =IFERROR(INDEX([3]Resumen!$K$3:$K$63,MATCH(G13,[3]Resumen!$C$3:$C$63,0)),0)*(1+I13*J13)/1000-51.89/1000-93.38/1000 -> 1.834431 | I13: 0.67 | J13: =$H$59 -> -0.10965909 | K13: =C13/1000 -> 5.28 | L13: =IF(C13<0,0,C13)/1000 -> 5.28 | M13: =IFERROR(H13*L13,0)*1000 -> 9685.7957 | N13: =207.84*L13 -> 1097.3952 | O13: =$O$54/$L$52*L13 -> 352.52699 | P13: =$P$54/$L$52*L13 -> 693.00833 | Q13: =$Q$54/$L$52*L13 -> 553.98473 | R13: 0 | S13: 0 | T13: =M13+N13+O13+P13 -> 11828.726 | U13: =IFERROR(T13/L13,0) -> 2240.2891
B14: POTA FILETE C/M C/T FR 2.0 - 4.0 AA BL10 S20 | C14: 3100 | G14: 10005721 | H14: =IFERROR(INDEX([3]Resumen!$K$3:$K$63,MATCH(G14,[3]Resumen!$C$3:$C$63,0)),0)*(1+I14*J14)/1000-51.89/1000-93.38/1000 -> 1.834431 | I14: 0.67 | J14: =$H$59 -> -0.10965909 | K14: =C14/1000 -> 3.1 | L14: =IF(C14<0,0,C14)/1000 -> 3.1 | M14: =IFERROR(H14*L14,0)*1000 -> 5686.7361 | N14: =207.84*L14 -> 644.304 | O14: =$O$54/$L$52*L14 -> 206.97607 | P14: =$P$54/$L$52*L14 -> 406.87989 | Q14: =$Q$54/$L$52*L14 -> 325.25618 | R14: 0 | S14: 0 | T14: =M14+N14+O14+P14 -> 6944.8961 | U14: =IFERROR(T14/L14,0) -> 2240.2891
B15: POTA FILETE S/M S/T FR 1.0-2.0 CM/ESP BL10 S20 | C15: 3200 | G15: 10005721 | H15: =IFERROR(INDEX([3]Resumen!$K$3:$K$63,MATCH(G15,[3]Resumen!$C$3:$C$63,0)),0)*(1+I15*J15)/1000-51.89/1000-93.38/1000 -> 1.834431 | I15: 0.67 | J15: =$H$59 -> -0.10965909 | K15: =C15/1000 -> 3.2 | L15: =IF(C15<0,0,C15)/1000 -> 3.2 | M15: =IFERROR(H15*L15,0)*1000 -> 5870.1792 | N15: =207.84*L15 -> 665.088 | O15: =$O$54/$L$52*L15 -> 213.65272 | P15: =$P$54/$L$52*L15 -> 420.00505 | Q15: =$Q$54/$L$52*L15 -> 335.74832 | R15: 0 | S15: 0 | T15: =M15+N15+O15+P15 -> 7168.925 | U15: =IFERROR(T15/L15,0) -> 2240.2891
B16: POTA FILETE PRE COCIDO S/M S/T C/P S/COD BL10 S20 | C16: 16480 | G16: 10005721 | H16: =IFERROR(INDEX([3]Resumen!$K$3:$K$63,MATCH(G16,[3]Resumen!$C$3:$C$63,0)),0)*(1+I16*J16)/1000-51.89/1000-93.38/1000 -> 1.834431 | I16: 0.67 | J16: =$H$59 -> -0.10965909 | K16: =C16/1000 -> 16.48 | L16: =IF(C16<0,0,C16)/1000 -> 16.48 | M16: =IFERROR(H16*L16,0)*1000 -> 30231.423 | N16: =207.84*L16 -> 3425.2032 | O16: =$O$54/$L$52*L16 -> 1100.3115 | P16: =$P$54/$L$52*L16 -> 2163.026 | Q16: =$Q$54/$L$52*L16 -> 1729.1038 | R16: 0 | S16: 0 | T16: =M16+N16+O16+P16 -> 36919.964 | U16: =IFERROR(T16/L16,0) -> 2240.2891
B17: POTA FILETE PRE COCIDO S/M S/T 0.6 - 1.0 BL10 S20 | C17: 20 | G17: 10005721 | H17: =IFERROR(INDEX([3]Resumen!$K$3:$K$63,MATCH(G17,[3]Resumen!$C$3:$C$63,0)),0)*(1+I17*J17)/1000-51.89/1000-93.38/1000 -> 1.834431 | I17: 0.67 | J17: =$H$59 -> -0.10965909 | K17: =C17/1000 -> 0.02 | L17: =IF(C17<0,0,C17)/1000 -> 0.02 | M17: =IFERROR(H17*L17,0)*1000 -> 36.68862 | N17: =207.84*L17 -> 4.1568 | O17: =$O$54/$L$52*L17 -> 1.3353295 | P17: =$P$54/$L$52*L17 -> 2.6250315 | Q17: =$Q$54/$L$52*L17 -> 2.098427 | R17: 0 | S17: 0 | T17: =M17+N17+O17+P17 -> 44.805781 | U17: =IFERROR(T17/L17,0) -> 2240.2891
B18: POTA CONOS | G18: 10005721 | H18: =IFERROR(INDEX([3]Resumen!$K$3:$K$63,MATCH(G18,[3]Resumen!$C$3:$C$63,0)),0)*(1+I18*J18)/1000-51.89/1000-93.38/1000 -> 1.834431 | I18: 0.67 | J18: =$H$59 -> -0.10965909 | K18: =C18/1000 -> 0 | L18: =IF(C18<0,0,C18)/1000 -> 0 | M18: =IFERROR(H18*L18,0)*1000 -> 0 | N18: =207.84*L18 -> 0 | O18: =$O$54/$L$52*L18 -> 0 | P18: =$P$54/$L$52*L18 -> 0 | Q18: =$Q$54/$L$52*L18 -> 0 | R18: 0 | S18: 0 | T18: =M18+N18+O18+P18 -> 0 | U18: =IFERROR(T18/L18,0) -> 0
B19: POTA NUCAS CERRADAS < 0.1 BL10 S20 | C19: 1040 | G19: 10005721 | H19: =IFERROR(INDEX([3]Resumen!$K$3:$K$63,MATCH(G19,[3]Resumen!$C$3:$C$63,0)),0)*(1+I19*J19)/1000-51.89/1000-93.38/1000 -> 1.834431 | I19: 0.67 | J19: =$H$59 -> -0.10965909 | K19: =C19/1000 -> 1.04 | L19: =IF(C19<0,0,C19)/1000 -> 1.04 | M19: =IFERROR(H19*L19,0)*1000 -> 1907.8082 | N19: =207.84*L19 -> 216.1536 | O19: =$O$54/$L$52*L19 -> 69.437134 | P19: =$P$54/$L$52*L19 -> 136.50164 | Q19: =$Q$54/$L$52*L19 -> 109.1182 | R19: 0 | S19: 0 | T19: =M19+N19+O19+P19 -> 2329.9006 | U19: =IFERROR(T19/L19,0) -> 2240.2891
B20: POTA NUCAS CERRADAS 0.1 - 0.3 BL10 S20 | C20: 41820 | G20: 10005721 | H20: =IFERROR(INDEX([3]Resumen!$K$3:$K$63,MATCH(G20,[3]Resumen!$C$3:$C$63,0)),0)*(1+I20*J20)/1000-51.89/1000-93.38/1000 -> 1.834431 | I20: 0.67 | J20: =$H$59 -> -0.10965909 | K20: =C20/1000 -> 41.82 | L20: =IF(C20<0,0,C20)/1000 -> 41.82 | M20: =IFERROR(H20*L20,0)*1000 -> 76715.905 | N20: =207.84*L20 -> 8691.8688 | O20: =$O$54/$L$52*L20 -> 2792.174 | P20: =$P$54/$L$52*L20 -> 5488.941 | Q20: =$Q$54/$L$52*L20 -> 4387.8109 | R20: 0 | S20: 0 | T20: =M20+N20+O20+P20 -> 93688.888 | U20: =IFERROR(T20/L20,0) -> 2240.2891
B21: POTA NUCAS FR ABIERTAS 0.1 - 0.3 BL10 S20 | C21: 138020 | G21: 10005721 | H21: =IFERROR(INDEX([3]Resumen!$K$3:$K$63,MATCH(G21,[3]Resumen!$C$3:$C$63,0)),0)*(1+I21*J21)/1000-51.89/1000-93.38/1000 -> 1.834431 | I21: 0.67 | J21: =$H$59 -> -0.10965909 | K21: =C21/1000 -> 138.02 | L21: =IF(C21<0,0,C21)/1000 -> 138.02 | M21: =IFERROR(H21*L21,0)*1000 -> 253188.17 | N21: =207.84*L21 -> 28686.077 | O21: =$O$54/$L$52*L21 -> 9215.1089 | P21: =$P$54/$L$52*L21 -> 18115.343 | Q21: =$Q$54/$L$52*L21 -> 14481.245 | R21: 0 | S21: 0 | T21: =M21+N21+O21+P21 -> 309204.7 | U21: =IFERROR(T21/L21,0) -> 2240.2891
B22: POTA NUCAS FR ABIERTAS 0.3 - 0.5 BL10 S20 | C22: 174240 | G22: 10005721 | H22: =IFERROR(INDEX([3]Resumen!$K$3:$K$63,MATCH(G22,[3]Resumen!$C$3:$C$63,0)),0)*(1+I22*J22)/1000-51.89/1000-93.38/1000 -> 1.834431 | I22: 0.67 | J22: =$H$59 -> -0.10965909 | K22: =C22/1000 -> 174.24 | L22: =IF(C22<0,0,C22)/1000 -> 174.24 | M22: =IFERROR(H22*L22,0)*1000 -> 319631.26 | N22: =207.84*L22 -> 36214.042 | O22: =$O$54/$L$52*L22 -> 11633.391 | P22: =$P$54/$L$52*L22 -> 22869.275 | Q22: =$Q$54/$L$52*L22 -> 18281.496 | R22: 0 | S22: 0 | T22: =M22+N22+O22+P22 -> 390347.97 | U22: =IFERROR(T22/L22,0) -> 2240.2891
B23: POTA NUCAS FR ABIERTAS 0.5 - 1.0 BL10 S20 | C23: 0 | G23: 10005721 | H23: =IFERROR(INDEX([3]Resumen!$K$3:$K$63,MATCH(G23,[3]Resumen!$C$3:$C$63,0)),0)*(1+I23*J23)/1000-51.89/1000-93.38/1000 -> 1.834431 | I23: 0.67 | J23: =$H$59 -> -0.10965909 | K23: =C23/1000 -> 0 | L23: =IF(C23<0,0,C23)/1000 -> 0 | M23: =IFERROR(H23*L23,0)*1000 -> 0 | N23: =207.84*L23 -> 0 | O23: =$O$54/$L$52*L23 -> 0 | P23: =$P$54/$L$52*L23 -> 0 | Q23: =$Q$54/$L$52*L23 -> 0 | R23: 0 | S23: 0 | T23: =M23+N23+O23+P23 -> 0 | U23: =IFERROR(T23/L23,0) -> 0
B24: POTA NUCAS FR ABIERTAS 1.0 - 2.0 BL10 S20 | C24: 0 | G24: 10005779 | H24: =IFERROR(INDEX([3]Resumen!$K$3:$K$63,MATCH(G24,[3]Resumen!$C$3:$C$63,0)),0)*(1+I24*J24)/1000-51.89/1000-93.38/1000 -> 1.483423 | I24: 0.65 | J24: =$H$59 -> -0.10965909 | K24: =C24/1000 -> 0 | L24: =IF(C24<0,0,C24)/1000 -> 0 | M24: =IFERROR(H24*L24,0)*1000 -> 0 | N24: =207.84*L24 -> 0 | O24: =$O$54/$L$52*L24 -> 0 | P24: =$P$54/$L$52*L24 -> 0 | Q24: =$Q$54/$L$52*L24 -> 0 | R24: 0 | S24: 0 | T24: =M24+N24+O24+P24 -> 0 | U24: =IFERROR(T24/L24,0) -> 0
B25: POTA REJOS FR S-S/POR C/UV 0.1 - 0.3 BL10 S20 | C25: 40 | G25: 10005779 | H25: =IFERROR(INDEX([3]Resumen!$K$3:$K$63,MATCH(G25,[3]Resumen!$C$3:$C$63,0)),0)*(1+I25*J25)/1000-51.89/1000-93.38/1000 -> 1.483423 | I25: 0.65 | J25: =$H$59 -> -0.10965909 | K25: =C25/1000 -> 0.04 | L25: =IF(C25<0,0,C25)/1000 -> 0.04 | M25: =IFERROR(H25*L25,0)*1000 -> 59.336919 | N25: =207.84*L25 -> 8.3136 | O25: =$O$54/$L$52*L25 -> 2.670659 | P25: =$P$54/$L$52*L25 -> 5.2500631 | Q25: =$Q$54/$L$52*L25 -> 4.196854 | R25: 0 | S25: 0 | T25: =M25+N25+O25+P25 -> 75.571241 | U25: =IFERROR(T25/L25,0) -> 1889.281
