Workbook

Sheet RESUMEN AL 15-6-2026
C2: PERU FROST
C3: AVANCE COMERCIAL AL 15-6-2026
F5: RENTABILIDAD DEL INVENTARIO | X5: 46174 | AA5: 46182 | AD5: 46185 | AG5: 46188 | AJ5: 46192 | AM5: 46195 | AP5: POR DEFINIR | AS5: TOTAL PROYECTADO JUNIO 2026 | BG5: UNITARIOS POR TM
B6: Código | C6: Producto | D6: TM en Stock Libre | E6: CU | F6: Costo Ventas | G6: Gasto Ventas | H6: Gasto ADM | I6: Gasto Fin | J6: Depreciación | K6: Utilidad Neta | L6: Margen Neto | M6: Venta Equilibrio a Utd Neta | N6: Precio Equilibrio x TM a Utd Neta | O6: Venta Equilibro a EBITDA | P6: Precio Equilibrio x TM a EBITDA | Q6: Precio Mercado | R6: Venta total | S6: Utilidad | T6: Mg Neto | U6: EBITDA | V6: Mg EBITDA | X6: TM | Y6: Venta | Z6: Precio x TM | AA6: TM | AB6: Venta | AC6: Precio x TM | AD6: TM | AE6: Venta | AF6: Precio x TM | AG6: TM | AH6: Venta | AI6: Precio x TM | AJ6: TM | AK6: Venta | AL6: Precio x TM | AM6: TM | AN6: Venta | AO6: Precio x TM | AP6: TM | AQ6: Venta | AR6: Precio x TM | AS6: TM | AT6: Venta | AU6: Precio x TM | AV6: Costo Ventas | AW6: Gasto Ventas | AX6: Gasto Adm | AY6: Gasto Fin | AZ6: Depreciación | BA6: Drawback | BB6: Utilidad Neta | BC6: Mg Neto % | BD6: EBITDA | BE6: MG EBITDA | BG6: Precio x TM | BH6: Costo Ventas | BI6: Gasto Ventas | BJ6: Gasto Adm | BK6: Gasto Fin | BL6: Depreciación | BM6: Drawback | BN6: Utilidad Neta | BO6: EBITDA
B7: 10005721 | C7: POTA FILETE CONGELADO | D7: =TD!F4 -> 561.84 | E7: =IFERROR(F7/D7,0) -> 1984.5862 | F7: =TD!G4 -> 1115019.9 | G7: =TD!H4 -> 116772.83 | H7: =TD!I4 -> 35439.697 | I7: =TD!J4 -> 69668.44 | J7: =TD!K4 -> 55692.334 | K7: 0 | L7: 0 | M7: =F7+G7+H7+I7 -> 1336900.9 | N7: =IFERROR(M7/D7,0) -> 2379.5046 | O7: =F7+G7+H7-J7 -> 1211540.1 | P7: =IFERROR(O7/D7,0) -> 2156.3792 | Q7: 2000 | R7: =Q7*D7 -> 1123680 | S7: =R7-M7+(Q7-$AX$22)*D7*0.03 -> -181434.94 | T7: =IFERROR(S7/R7,0) -> -0.16146496 | U7: =R7-(M7-J7-I7)+(Q7-$AX$22)*D7*0.03 -> -56074.17 | V7: =IFERROR(U7/R7,0) -> -0.049902259 | X7: {=SUM([1]Hoja2!$I$5:$I$27*([1]Hoja2!$F$5:$F$27=X$5)*([1]Hoja2!$K$5:$K$27=$C7))} -> 0 | Y7: {=SUM([1]Hoja2!$J$5:$J$27*([1]Hoja2!$F$5:$F$27=X$5)*([1]Hoja2!$K$5:$K$27=$C7))} -> 0 | Z7: =IFERROR(Y7/X7,0) -> 0 | AA7: {=SUM([1]Hoja2!$I$5:$I$27*([1]Hoja2!$F$5:$F$27=AA$5)*([1]Hoja2!$K$5:$K$27=$C7))} -> 0 | AB7: {=SUM([1]Hoja2!$J$5:$J$27*([1]Hoja2!$F$5:$F$27=AA$5)*([1]Hoja2!$K$5:$K$27=$C7))} -> 0 | AC7: =IFERROR(AB7/AA7,0) -> 0 | AD7: {=SUM([1]Hoja2!$I$5:$I$27*([1]Hoja2!$F$5:$F$27=AD$5)*([1]Hoja2!$K$5:$K$27=$C7))} -> 0 | AE7: {=SUM([1]Hoja2!$J$5:$J$27*([1]Hoja2!$F$5:$F$27=AD$5)*([1]Hoja2!$K$5:$K$27=$C7))} -> 0 | AF7: =IFERROR(AE7/AD7,0) -> 0 | AG7: {=SUM([1]Hoja2!$I$5:$I$27*([1]Hoja2!$F$5:$F$27=AG$5)*([1]Hoja2!$K$5:$K$27=$C7))} -> 0 | AH7: {=SUM([1]Hoja2!$J$5:$J$27*([1]Hoja2!$F$5:$F$27=AG$5)*([1]Hoja2!$K$5:$K$27=$C7))} -> 0 | AI7: =IFERROR(AH7/AG7,0) -> 0 | AJ7: {=SUM([1]Hoja2!$I$5:$I$27*([1]Hoja2!$F$5:$F$27=AJ$5)*([1]Hoja2!$K$5:$K$27=$C7))} -> 78 | AK7: {=SUM([1]Hoja2!$J$5:$J$27*([1]Hoja2!$F$5:$F$27=AJ$5)*([1]Hoja2!$K$5:$K$27=$C7))} -> 164280 | AL7: =IFERROR(AK7/AJ7,0) -> 2106.1538 | AM7: {=SUM([1]Hoja2!$I$5:$I$27*([1]Hoja2!$F$5:$F$27=AM$5)*([1]Hoja2!$K$5:$K$27=$C7))} -> 0 | AN7: {=SUM([1]Hoja2!$J$5:$J$27*([1]Hoja2!$F$5:$F$27=AM$5)*([1]Hoja2!$K$5:$K$27=$C7))} -> 0 | AO7: =IFERROR(AN7/AM7,0) -> 0 | AP7: {=SUM([1]Hoja2!$I$5:$I$27*([1]Hoja2!$F$5:$F$27=AP$5)*([1]Hoja2!$K$5:$K$27=$C7))} -> 89 | AQ7: {=SUM([1]Hoja2!$J$5:$J$27*([1]Hoja2!$F$5:$F$27=AP$5)*([1]Hoja2!$K$5:$K$27=$C7))} -> 166940 | AR7: =IFERROR(AQ7/AP7,0) -> 1875.7303 | AS7: =X7+AA7+AD7+AG7+AJ7+AM7+AP7 -> 167 | AT7: =Y7+AB7+AE7+AH7+AK7+AN7+AQ7 -> 331220 | AU7: =IFERROR(AT7/AS7,0) -> 1983.3533 | AV7: =-IFERROR(F7/D7*AS7,0) -> -331425.89 | AW7: =-207.84*AS7 -> -34709.28 | AX7: =$AX$18/$AS$18*$AS7 -> -9393.481 | AY7: =$AY$18/$AS$18*$AS7 -> -18465.992 | AZ7: =$AZ$18/$AS$18*$AS7 -> -14761.551 | BA7: =(AT7-AS7*$AX$22)*0.03 -> 9364.5702 | BB7: =AT7+SUM(AV7:AY7,BA7) -> -53410.074 | BC7: =IFERROR(BB7/AT7,0) -> -0.16125256 | BD7: =AT7+AV7+AW7+AX7+BA7-AZ7 -> -20182.531 | BE7: =IFERROR(BD7/AT7,0) -> -0.060933914 | BG7: =AU7 -> 1983.3533 | BH7: =IFERROR(AV7/$AS7,0) -> -1984.5862 | BI7: =IFERROR(AW7/$AS7,0) -> -207.84 | BJ7: =IFERROR(AX7/$AS7,0) -> -56.248389 | BK7: =IFERROR(AY7/$AS7,0) -> -110.5748 | BL7: =IFERROR(AZ7/$AS7,0) -> -88.39252 | BM7: =IFERROR(BA7/$AS7,0) -> 56.07527 | BN7: =IFERROR(BB7/$AS7,0) -> -319.8208 | BO7: =IFERROR(BD7/$AS7,0) -> -120.85348 | BP7: =BO7-BN7 -> 198.96732
B8: 10005779 | C8: POTA NUCAS CONGELADAS | D8: =TD!F5 -> 235.92 | E8: =IFERROR(F8/D8,0) -> 1622.0104 | F8: =TD!G5 -> 382664.69 | G8: =TD!H5 -> 49033.613 | H8: =TD!I5 -> 14881.342 | I8: =TD!J5 -> 29254.197 | J8: =TD!K5 -> 23385.547 | K8: 0 | L8: 0 | M8: =F8+G8+H8+I8 -> 475833.84 | N8: =IFERROR(M8/D8,0) -> 2016.9288 | O8: =F8+G8+H8-J8 -> 423194.1 | P8: =IFERROR(O8/D8,0) -> 1793.8034 | Q8: 1350 | R8: =Q8*D8 -> 318492 | S8: =R8-M8+(Q8-$AX$22)*D8*0.03 -> -148595.19 | T8: =IFERROR(S8/R8,0) -> -0.46655862 | U8: =R8-(M8-J8-I8)+(Q8-$AX$22)*D8*0.03 -> -95955.444 | V8: =IFERROR(U8/R8,0) -> -0.30128055 | X8: {=SUM([1]Hoja2!$I$5:$I$27*([1]Hoja2!$F$5:$F$27=X$5)*([1]Hoja2!$K$5:$K$27=$C8))} -> 0 | Y8: {=SUM([1]Hoja2!$J$5:$J$27*([1]Hoja2!$F$5:$F$27=X$5)*([1]Hoja2!$K$5:$K$27=$C8))} -> 0 | Z8: =IFERROR(Y8/X8,0) -> 0 | AA8: {=SUM([1]Hoja2!$I$5:$I$27*([1]Hoja2!$F$5:$F$27=AA$5)*([1]Hoja2!$K$5:$K$27=$C8))} -> 26 | AB8: {=SUM([1]Hoja2!$J$5:$J$27*([1]Hoja2!$F$5:$F$27=AA$5)*([1]Hoja2!$K$5:$K$27=$C8))} -> 33800 | AC8: =IFERROR(AB8/AA8,0) -> 1300 | AD8: {=SUM([1]Hoja2!$I$5:$I$27*([1]Hoja2!$F$5:$F$27=AD$5)*([1]Hoja2!$K$5:$K$27=$C8))} -> 0 | AE8: {=SUM([1]Hoja2!$J$5:$J$27*([1]Hoja2!$F$5:$F$27=AD$5)*([1]Hoja2!$K$5:$K$27=$C8))} -> 0 | AF8: =IFERROR(AE8/AD8,0) -> 0 | AG8: {=SUM([1]Hoja2!$I$5:$I$27*([1]Hoja2!$F$5:$F$27=AG$5)*([1]Hoja2!$K$5:$K$27=$C8))} -> 0 | AH8: {=SUM([1]Hoja2!$J$5:$J$27*([1]Hoja2!$F$5:$F$27=AG$5)*([1]Hoja2!$K$5:$K$27=$C8))} -> 0 | AI8: =IFERROR(AH8/AG8,0) -> 0 | AJ8: {=SUM([1]Hoja2!$I$5:$I$27*([1]Hoja2!$F$5:$F$27=AJ$5)*([1]Hoja2!$K$5:$K$27=$C8))} -> 0 | AK8: {=SUM([1]Hoja2!$J$5:$J$27*([1]Hoja2!$F$5:$F$27=AJ$5)*([1]Hoja2!$K$5:$K$27=$C8))} -> 0 | AL8: =IFERROR(AK8/AJ8,0) -> 0 | AM8: {=SUM([1]Hoja2!$I$5:$I$27*([1]Hoja2!$F$5:$F$27=AM$5)*([1]Hoja2!$K$5:$K$27=$C8))} -> 0 | AN8: {=SUM([1]Hoja2!$J$5:$J$27*([1]Hoja2!$F$5:$F$27=AM$5)*([1]Hoja2!$K$5:$K$27=$C8))} -> 0 | AO8: =IFERROR(AN8/AM8,0) -> 0 | AP8: {=SUM([1]Hoja2!$I$5:$I$27*([1]Hoja2!$F$5:$F$27=AP$5)*([1]Hoja2!$K$5:$K$27=$C8))} -> 192 | AQ8: {=SUM([1]Hoja2!$J$5:$J$27*([1]Hoja2!$F$5:$F$27=AP$5)*([1]Hoja2!$K$5:$K$27=$C8))} -> 255020 | AR8: =IFERROR(AQ8/AP8,0) -> 1328.2292 | AS8: =X8+AA8+AD8+AG8+AJ8+AM8+AP8 -> 218 | AT8: =Y8+AB8+AE8+AH8+AK8+AN8+AQ8 -> 288820 | AU8: =IFERROR(AT8/AS8,0) -> 1324.8624 | AV8: =-IFERROR(F8/D8*AS8,0) -> -353598.27 | AW8: =-207.84*AS8 -> -45309.12 | AX8: =$AX$18/$AS$18*$AS8 -> -12262.149 | AY8: =$AY$18/$AS$18*$AS8 -> -24105.307 | AZ8: =$AZ$18/$AS$18*$AS8 -> -19269.569 | BA8: =(AT8-AS8*$AX$22)*0.03 -> 7917.8784 | BB8: =AT8+SUM(AV8:AY8,BA8) -> -138536.96 | BC8: =IFERROR(BB8/AT8,0) -> -0.47966541 | BD8: =AT8+AV8+AW8+AX8+BA8-AZ8 -> -95162.087 | BE8: =IFERROR(BD8/AT8,0) -> -0.3294858 | BG8: =AU8 -> 1324.8624 | BH8: =IFERROR(AV8/$AS8,0) -> -1622.0104 | BI8: =IFERROR(AW8/$AS8,0) -> -207.84 | BJ8: =IFERROR(AX8/$AS8,0) -> -56.248389 | BK8: =IFERROR(AY8/$AS8,0) -> -110.5748 | BL8: =IFERROR(AZ8/$AS8,0) -> -88.39252 | BM8: =IFERROR(BA8/$AS8,0) -> 36.320543 | BN8: =IFERROR(BB8/$AS8,0) -> -635.49066 | BO8: =IFERROR(BD8/$AS8,0) -> -436.52334 | BP8: =BO8-BN8 -> 198.96732
B9: 10006719 | C9: POTA ALAS CONGELADAS | D9: =TD!F6 -> 63.32 | E9: =IFERROR(F9/D9,0) -> 1882.6724 | F9: =TD!G6 -> 119210.81 | G9: =TD!H6 -> 13160.429 | H9: =TD!I6 -> 3994.0937 | I9: =TD!J6 -> 7851.7115 | J9: =TD!K6 -> 6276.5887 | K9: 0 | L9: 0 | M9: =F9+G9+H9+I9 -> 144217.05 | N9: =IFERROR(M9/D9,0) -> 2277.5908 | O9: =F9+G9+H9-J9 -> 130088.75 | P9: =IFERROR(O9/D9,0) -> 2054.4654 | Q9: 2300 | R9: =Q9*D9 -> 145636 | S9: =R9-M9+(Q9-$AX$22)*D9*0.03 -> 5571.1403 | T9: =IFERROR(S9/R9,0) -> 0.038253868 | U9: =R9-(M9-J9-I9)+(Q9-$AX$22)*D9*0.03 -> 19699.441 | V9: =IFERROR(U9/R9,0) -> 0.13526491 | X9: {=SUM([1]Hoja2!$I$5:$I$27*([1]Hoja2!$F$5:$F$27=X$5)*([1]Hoja2!$K$5:$K$27=$C9))} -> 0 | Y9: {=SUM([1]Hoja2!$J$5:$J$27*([1]Hoja2!$F$5:$F$27=X$5)*([1]Hoja2!$K$5:$K$27=$C9))} -> 0 | Z9: =IFERROR(Y9/X9,0) -> 0 | AA9: {=SUM([1]Hoja2!$I$5:$I$27*([1]Hoja2!$F$5:$F$27=AA$5)*([1]Hoja2!$K$5:$K$27=$C9))} -> 0 | AB9: {=SUM([1]Hoja2!$J$5:$J$27*([1]Hoja2!$F$5:$F$27=AA$5)*([1]Hoja2!$K$5:$K$27=$C9))} -> 0 | AC9: =IFERROR(AB9/AA9,0) -> 0 | AD9: {=SUM([1]Hoja2!$I$5:$I$27*([1]Hoja2!$F$5:$F$27=AD$5)*([1]Hoja2!$K$5:$K$27=$C9))} -> 72 | AE9: {=SUM([1]Hoja2!$J$5:$J$27*([1]Hoja2!$F$5:$F$27=AD$5)*([1]Hoja2!$K$5:$K$27=$C9))} -> 151200 | AF9: =IFERROR(AE9/AD9,0) -> 2100 | AG9: {=SUM([1]Hoja2!$I$5:$I$27*([1]Hoja2!$F$5:$F$27=AG$5)*([1]Hoja2!$K$5:$K$27=$C9))} -> 0 | AH9: {=SUM([1]Hoja2!$J$5:$J$27*([1]Hoja2!$F$5:$F$27=AG$5)*([1]Hoja2!$K$5:$K$27=$C9))} -> 0 | AI9: =IFERROR(AH9/AG9,0) -> 0 | AJ9: {=SUM([1]Hoja2!$I$5:$I$27*([1]Hoja2!$F$5:$F$27=AJ$5)*([1]Hoja2!$K$5:$K$27=$C9))} -> 27 | AK9: {=SUM([1]Hoja2!$J$5:$J$27*([1]Hoja2!$F$5:$F$27=AJ$5)*([1]Hoja2!$K$5:$K$27=$C9))} -> 59400 | AL9: =IFERROR(AK9/AJ9,0) -> 2200 | AM9: {=SUM([1]Hoja2!$I$5:$I$27*([1]Hoja2!$F$5:$F$27=AM$5)*([1]Hoja2!$K$5:$K$27=$C9))} -> 0 | AN9: {=SUM([1]Hoja2!$J$5:$J$27*([1]Hoja2!$F$5:$F$27=AM$5)*([1]Hoja2!$K$5:$K$27=$C9))} -> 0 | AO9: =IFERROR(AN9/AM9,0) -> 0 | AP9: {=SUM([1]Hoja2!$I$5:$I$27*([1]Hoja2!$F$5:$F$27=AP$5)*([1]Hoja2!$K$5:$K$27=$C9))} -> 0 | AQ9: {=SUM([1]Hoja2!$J$5:$J$27*([1]Hoja2!$F$5:$F$27=AP$5)*([1]Hoja2!$K$5:$K$27=$C9))} -> 0 | AR9: =IFERROR(AQ9/AP9,0) -> 0 | AS9: =X9+AA9+AD9+AG9+AJ9+AM9+AP9 -> 99 | AT9: =Y9+AB9+AE9+AH9+AK9+AN9+AQ9 -> 210600 | AU9: =IFERROR(AT9/AS9,0) -> 2127.2727 | AV9: =-IFERROR(F9/D9*AS9,0) -> -186384.56 | AW9: =-207.84*AS9 -> -20576.16 | AX9: =$AX$18/$AS$18*$AS9 -> -5568.5906 | AY9: =$AY$18/$AS$18*$AS9 -> -10946.906 | AZ9: =$AZ$18/$AS$18*$AS9 -> -8750.8594 | BA9: =(AT9-AS9*$AX$22)*0.03 -> 5978.8925 | BB9: =AT9+SUM(AV9:AY9,BA9) -> -6897.3273 | BC9: =IFERROR(BB9/AT9,0) -> -0.032750842 | BD9: =AT9+AV9+AW9+AX9+BA9-AZ9 -> 12800.438 | BE9: =IFERROR(BD9/AT9,0) -> 0.060780805 | BG9: =AU9 -> 2127.2727 | BH9: =IFERROR(AV9/$AS9,0) -> -1882.6724 | BI9: =IFERROR(AW9/$AS9,0) -> -207.84 | BJ9: =IFERROR(AX9/$AS9,0) -> -56.248389 | BK9: =IFERROR(AY9/$AS9,0) -> -110.5748 | BL9: =IFERROR(AZ9/$AS9,0) -> -88.39252 | BM9: =IFERROR(BA9/$AS9,0) -> 60.392853 | BN9: =IFERROR(BB9/$AS9,0) -> -69.669973 | BO9: =IFERROR(BD9/$AS9,0) -> 129.29735 | BP9: =BO9-BN9 -> 198.96732
B10: 10007050 | C10: POTA RECORTES COCIDOS | D10: =TD!F7 -> 103.325 | E10: =IFERROR(F10/D10,0) -> 1443.946 | F10: =TD!G7 -> 149195.72 | G10: =TD!H7 -> 21475.068 | H10: =TD!I7 -> 6517.5258 | I10: =TD!J7 -> 12812.351 | J10: =TD!K7 -> 10242.08 | K10: 0 | L10: 0 | M10: =F10+G10+H10+I10 -> 190000.66 | N10: =IFERROR(M10/D10,0) -> 1838.8644 | O10: =F10+G10+H10-J10 -> 166946.23 | P10: =IFERROR(O10/D10,0) -> 1615.739 | Q10: 2300 | R10: =Q10*D10 -> 237647.5 | S10: =R10-M10+(Q10-$AX$22)*D10*0.03 -> 54422.342 | T10: =IFERROR(S10/R10,0) -> 0.22900448 | U10: =R10-(M10-J10-I10)+(Q10-$AX$22)*D10*0.03 -> 77476.774 | V10: =IFERROR(U10/R10,0) -> 0.32601552 | X10: {=SUM([1]Hoja2!$I$5:$I$27*([1]Hoja2!$F$5:$F$27=X$5)*([1]Hoja2!$K$5:$K$27=$C10))} -> 0 | Y10: {=SUM([1]Hoja2!$J$5:$J$27*([1]Hoja2!$F$5:$F$27=X$5)*([1]Hoja2!$K$5:$K$27=$C10))} -> 0 | Z10: =IFERROR(Y10/X10,0) -> 0 | AA10: {=SUM([1]Hoja2!$I$5:$I$27*([1]Hoja2!$F$5:$F$27=AA$5)*([1]Hoja2!$K$5:$K$27=$C10))} -> 0 | AB10: {=SUM([1]Hoja2!$J$5:$J$27*([1]Hoja2!$F$5:$F$27=AA$5)*([1]Hoja2!$K$5:$K$27=$C10))} -> 0 | AC10: =IFERROR(AB10/AA10,0) -> 0 | AD10: {=SUM([1]Hoja2!$I$5:$I$27*([1]Hoja2!$F$5:$F$27=AD$5)*([1]Hoja2!$K$5:$K$27=$C10))} -> 0 | AE10: {=SUM([1]Hoja2!$J$5:$J$27*([1]Hoja2!$F$5:$F$27=AD$5)*([1]Hoja2!$K$5:$K$27=$C10))} -> 0 | AF10: =IFERROR(AE10/AD10,0) -> 0 | AG10: {=SUM([1]Hoja2!$I$5:$I$27*([1]Hoja2!$F$5:$F$27=AG$5)*([1]Hoja2!$K$5:$K$27=$C10))} -> 0 | AH10: {=SUM([1]Hoja2!$J$5:$J$27*([1]Hoja2!$F$5:$F$27=AG$5)*([1]Hoja2!$K$5:$K$27=$C10))} -> 0 | AI10: =IFERROR(AH10/AG10,0) -> 0 | AJ10: {=SUM([1]Hoja2!$I$5:$I$27*([1]Hoja2!$F$5:$F$27=AJ$5)*([1]Hoja2!$K$5:$K$27=$C10))} -> 0 | AK10: {=SUM([1]Hoja2!$J$5:$J$27*([1]Hoja2!$F$5:$F$27=AJ$5)*([1]Hoja2!$K$5:$K$27=$C10))} -> 0 | AL10: =IFERROR(AK10/AJ10,0) -> 0 | AM10: {=SUM([1]Hoja2!$I$5:$I$27*([1]Hoja2!$F$5:$F$27=AM$5)*([1]Hoja2!$K$5:$K$27=$C10))} -> 0 | AN10: {=SUM([1]Hoja2!$J$5:$J$27*([1]Hoja2!$F$5:$F$27=AM$5)*([1]Hoja2!$K$5:$K$27=$C10))} -> 0 | AO10: =IFERROR(AN10/AM10,0) -> 0 | AP10: {=SUM([1]Hoja2!$I$5:$I$27*([1]Hoja2!$F$5:$F$27=AP$5)*([1]Hoja2!$K$5:$K$27=$C10))} -> 54 | AQ10: {=SUM([1]Hoja2!$J$5:$J$27*([1]Hoja2!$F$5:$F$27=AP$5)*([1]Hoja2!$K$5:$K$27=$C10))} -> 136350 | AR10: =IFERROR(AQ10/AP10,0) -> 2525 | AS10: =X10+AA10+AD10+AG10+AJ10+AM10+AP10 -> 54 | AT10: =Y10+AB10+AE10+AH10+AK10+AN10+AQ10 -> 136350 | AU10: =IFERROR(AT10/AS10,0) -> 2525 | AV10: =-IFERROR(F10/D10*AS10,0) -> -77973.081 | AW10: =-207.84*AS10 -> -11223.36 | AX10: =$AX$18/$AS$18*$AS10 -> -3037.413 | AY10: =$AY$18/$AS$18*$AS10 -> -5971.0394 | AZ10: =$AZ$18/$AS$18*$AS10 -> -4773.1961 | BA10: =(AT10-AS10*$AX$22)*0.03 -> 3905.5323 | BB10: =AT10+SUM(AV10:AY10,BA10) -> 42050.639 | BC10: =IFERROR(BB10/AT10,0) -> 0.30840219 | BD10: =AT10+AV10+AW10+AX10+BA10-AZ10 -> 52794.874 | BE10: =IFERROR(BD10/AT10,0) -> 0.38720113 | BG10: =AU10 -> 2525 | BH10: =IFERROR(AV10/$AS10,0) -> -1443.946 | BI10: =IFERROR(AW10/$AS10,0) -> -207.84 | BJ10: =IFERROR(AX10/$AS10,0) -> -56.248389 | BK10: =IFERROR(AY10/$AS10,0) -> -110.5748 | BL10: =IFERROR(AZ10/$AS10,0) -> -88.39252 | BM10: =IFERROR(BA10/$AS10,0) -> 72.324672 | BN10: =IFERROR(BB10/$AS10,0) -> 778.71553 | BO10: =IFERROR(BD10/$AS10,0) -> 977.68285 | BP10: =BO10-BN10 -> 198.96732
B11: 10007162 | C11: POTA REJOS CONGELADOS | D11: =TD!F8 -> 171.96 | E11: =IFERROR(F11/D11,0) -> 1740.6978 | F11: =TD!G8 -> 299330.39 | G11: =TD!H8 -> 35740.166 | H11: =TD!I8 -> 10846.879 | I11: =TD!J8 -> 21323.126 | J11: =TD!K8 -> 17045.518 | K11: 0 | L11: 0 | M11: =F11+G11+H11+I11 -> 367240.56 | N11: =IFERROR(M11/D11,0) -> 2135.6162 | O11: =F11+G11+H11-J11 -> 328871.92 | P11: =IFERROR(O11/D11,0) -> 1912.4908 | Q11: 2300 | R11: =Q11*D11 -> 395508 | S11: =R11-M11+(Q11-$AX$22)*D11*0.03 -> 39543.661 | T11: =IFERROR(S11/R11,0) -> 0.099981949 | U11: =R11-(M11-J11-I11)+(Q11-$AX$22)*D11*0.03 -> 77912.304 | V11: =IFERROR(U11/R11,0) -> 0.19699299 | X11: {=SUM([1]Hoja2!$I$5:$I$27*([1]Hoja2!$F$5:$F$27=X$5)*([1]Hoja2!$K$5:$K$27=$C11))} -> 0 | Y11: {=SUM([1]Hoja2!$J$5:$J$27*([1]Hoja2!$F$5:$F$27=X$5)*([1]Hoja2!$K$5:$K$27=$C11))} -> 0 | Z11: =IFERROR(Y11/X11,0) -> 0 | AA11: {=SUM([1]Hoja2!$I$5:$I$27*([1]Hoja2!$F$5:$F$27=AA$5)*([1]Hoja2!$K$5:$K$27=$C11))} -> 0 | AB11: {=SUM([1]Hoja2!$J$5:$J$27*([1]Hoja2!$F$5:$F$27=AA$5)*([1]Hoja2!$K$5:$K$27=$C11))} -> 0 | AC11: =IFERROR(AB11/AA11,0) -> 0 | AD11: {=SUM([1]Hoja2!$I$5:$I$27*([1]Hoja2!$F$5:$F$27=AD$5)*([1]Hoja2!$K$5:$K$27=$C11))} -> 27 | AE11: {=SUM([1]Hoja2!$J$5:$J$27*([1]Hoja2!$F$5:$F$27=AD$5)*([1]Hoja2!$K$5:$K$27=$C11))} -> 82350 | AF11: =IFERROR(AE11/AD11,0) -> 3050 | AG11: {=SUM([1]Hoja2!$I$5:$I$27*([1]Hoja2!$F$5:$F$27=AG$5)*([1]Hoja2!$K$5:$K$27=$C11))} -> 26 | AH11: {=SUM([1]Hoja2!$J$5:$J$27*([1]Hoja2!$F$5:$F$27=AG$5)*([1]Hoja2!$K$5:$K$27=$C11))} -> 67600 | AI11: =IFERROR(AH11/AG11,0) -> 2600 | AJ11: {=SUM([1]Hoja2!$I$5:$I$27*([1]Hoja2!$F$5:$F$27=AJ$5)*([1]Hoja2!$K$5:$K$27=$C11))} -> 0 | AK11: {=SUM([1]Hoja2!$J$5:$J$27*([1]Hoja2!$F$5:$F$27=AJ$5)*([1]Hoja2!$K$5:$K$27=$C11))} -> 0 | AL11: =IFERROR(AK11/AJ11,0) -> 0 | AM11: {=SUM([1]Hoja2!$I$5:$I$27*([1]Hoja2!$F$5:$F$27=AM$5)*([1]Hoja2!$K$5:$K$27=$C11))} -> 0 | AN11: {=SUM([1]Hoja2!$J$5:$J$27*([1]Hoja2!$F$5:$F$27=AM$5)*([1]Hoja2!$K$5:$K$27=$C11))} -> 0 | AO11: =IFERROR(AN11/AM11,0) -> 0 | AP11: {=SUM([1]Hoja2!$I$5:$I$27*([1]Hoja2!$F$5:$F$27=AP$5)*([1]Hoja2!$K$5:$K$27=$C11))} -> 106 | AQ11: {=SUM([1]Hoja2!$J$5:$J$27*([1]Hoja2!$F$5:$F$27=AP$5)*([1]Hoja2!$K$5:$K$27=$C11))} -> 302600 | AR11: =IFERROR(AQ11/AP11,0) -> 2854.717 | AS11: =X11+AA11+AD11+AG11+AJ11+AM11+AP11 -> 159 | AT11: =Y11+AB11+AE11+AH11+AK11+AN11+AQ11 -> 452550 | AU11: =IFERROR(AT11/AS11,0) -> 2846.2264 | AV11: =-IFERROR(F11/D11*AS11,0) -> -276770.95 | AW11: =-207.84*AS11 -> -33046.56 | AX11: =$AX$18/$AS$18*$AS11 -> -8943.4939 | AY11: =$AY$18/$AS$18*$AS11 -> -17581.394 | AZ11: =$AZ$18/$AS$18*$AS11 -> -14054.411 | BA11: =(AT11-AS11*$AX$22)*0.03 -> 13031.873 | BB11: =AT11+SUM(AV11:AY11,BA11) -> 129239.48 | BC11: =IFERROR(BB11/AT11,0) -> 0.28558055 | BD11: =AT11+AV11+AW11+AX11+BA11-AZ11 -> 160875.28 | BE11: =IFERROR(BD11/AT11,0) -> 0.35548621 | BG11: =AU11 -> 2846.2264 | BH11: =IFERROR(AV11/$AS11,0) -> -1740.6978 | BI11: =IFERROR(AW11/$AS11,0) -> -207.84 | BJ11: =IFERROR(AX11/$AS11,0) -> -56.248389 | BK11: =IFERROR(AY11/$AS11,0) -> -110.5748 | BL11: =IFERROR(AZ11/$AS11,0) -> -88.39252 | BM11: =IFERROR(BA11/$AS11,0) -> 81.961464 | BN11: =IFERROR(BB11/$AS11,0) -> 812.82691 | BO11: =IFERROR(BD11/$AS11,0) -> 1011.7942 | BP11: =BO11-BN11 -> 198.96732
B12: 10007567 | C12: POTA REPRODUCTORES | D12: =TD!F9 -> 61.46 | E12: =IFERROR(F12/D12,0) -> 1682.6592 | F12: =TD!G9 -> 103416.23 | G12: =TD!H9 -> 12773.846 | H12: =TD!I9 -> 3876.7688 | I12: =TD!J9 -> 7621.0706 | J12: =TD!K9 -> 6092.2164 | K12: 0 | L12: 0 | M12: =F12+G12+H12+I12 -> 127687.92 | N12: =IFERROR(M12/D12,0) -> 2077.5776 | O12: =F12+G12+H12-J12 -> 113974.63 | P12: =IFERROR(O12/D12,0) -> 1854.4522 | Q12: 2700 | R12: =Q12*D12 -> 165942 | S12: =R12-M12+(Q12-$AX$22)*D12*0.03 -> 43021.819 | T12: =IFERROR(S12/R12,0) -> 0.25925817 | U12: =R12-(M12-J12-I12)+(Q12-$AX$22)*D12*0.03 -> 56735.106 | V12: =IFERROR(U12/R12,0) -> 0.3418972 | X12: {=SUM([1]Hoja2!$I$5:$I$27*([1]Hoja2!$F$5:$F$27=X$5)*([1]Hoja2!$K$5:$K$27=$C12))} -> 0 | Y12: {=SUM([1]Hoja2!$J$5:$J$27*([1]Hoja2!$F$5:$F$27=X$5)*([1]Hoja2!$K$5:$K$27=$C12))} -> 0 | Z12: =IFERROR(Y12/X12,0) -> 0 | AA12: {=SUM([1]Hoja2!$I$5:$I$27*([1]Hoja2!$F$5:$F$27=AA$5)*([1]Hoja2!$K$5:$K$27=$C12))} -> 0 | AB12: {=SUM([1]Hoja2!$J$5:$J$27*([1]Hoja2!$F$5:$F$27=AA$5)*([1]Hoja2!$K$5:$K$27=$C12))} -> 0 | AC12: =IFERROR(AB12/AA12,0) -> 0 | AD12: {=SUM([1]Hoja2!$I$5:$I$27*([1]Hoja2!$F$5:$F$27=AD$5)*([1]Hoja2!$K$5:$K$27=$C12))} -> 0 | AE12: {=SUM([1]Hoja2!$J$5:$J$27*([1]Hoja2!$F$5:$F$27=AD$5)*([1]Hoja2!$K$5:$K$27=$C12))} -> 0 | AF12: =IFERROR(AE12/AD12,0) -> 0 | AG12: {=SUM([1]Hoja2!$I$5:$I$27*([1]Hoja2!$F$5:$F$27=AG$5)*([1]Hoja2!$K$5:$K$27=$C12))} -> 0 | AH12: {=SUM([1]Hoja2!$J$5:$J$27*([1]Hoja2!$F$5:$F$27=AG$5)*([1]Hoja2!$K$5:$K$27=$C12))} -> 0 | AI12: =IFERROR(AH12/AG12,0) -> 0 | AJ12: {=SUM([1]Hoja2!$I$5:$I$27*([1]Hoja2!$F$5:$F$27=AJ$5)*([1]Hoja2!$K$5:$K$27=$C12))} -> 0 | AK12: {=SUM([1]Hoja2!$J$5:$J$27*([1]Hoja2!$F$5:$F$27=AJ$5)*([1]Hoja2!$K$5:$K$27=$C12))} -> 0 | AL12: =IFERROR(AK12/AJ12,0) -> 0 | AM12: {=SUM([1]Hoja2!$I$5:$I$27*([1]Hoja2!$F$5:$F$27=AM$5)*([1]Hoja2!$K$5:$K$27=$C12))} -> 53 | AN12: {=SUM([1]Hoja2!$J$5:$J$27*([1]Hoja2!$F$5:$F$27=AM$5)*([1]Hoja2!$K$5:$K$27=$C12))} -> 147810 | AO12: =IFERROR(AN12/AM12,0) -> 2788.8679 | AP12: {=SUM([1]Hoja2!$I$5:$I$27*([1]Hoja2!$F$5:$F$27=AP$5)*([1]Hoja2!$K$5:$K$27=$C12))} -> 0 | AQ12: {=SUM([1]Hoja2!$J$5:$J$27*([1]Hoja2!$F$5:$F$27=AP$5)*([1]Hoja2!$K$5:$K$27=$C12))} -> 0 | AR12: =IFERROR(AQ12/AP12,0) -> 0 | AS12: =X12+AA12+AD12+AG12+AJ12+AM12+AP12 -> 53 | AT12: =Y12+AB12+AE12+AH12+AK12+AN12+AQ12 -> 147810 | AU12: =IFERROR(AT12/AS12,0) -> 2788.8679 | AV12: =-IFERROR(F12/D12*AS12,0) -> -89180.938 | AW12: =-207.84*AS12 -> -11015.52 | AX12: =$AX$18/$AS$18*$AS12 -> -2981.1646 | AY12: =$AY$18/$AS$18*$AS12 -> -5860.4646 | AZ12: =$AZ$18/$AS$18*$AS12 -> -4684.8035 | BA12: =(AT12-AS12*$AX$22)*0.03 -> 4252.7576 | BB12: =AT12+SUM(AV12:AY12,BA12) -> 43024.67 | BC12: =IFERROR(BB12/AT12,0) -> 0.29108092 | BD12: =AT12+AV12+AW12+AX12+BA12-AZ12 -> 53569.939 | BE12: =IFERROR(BD12/AT12,0) -> 0.36242432 | BG12: =AU12 -> 2788.8679 | BH12: =IFERROR(AV12/$AS12,0) -> -1682.6592 | BI12: =IFERROR(AW12/$AS12,0) -> -207.84 | BJ12: =IFERROR(AX12/$AS12,0) -> -56.248389 | BK12: =IFERROR(AY12/$AS12,0) -> -110.5748 | BL12: =IFERROR(AZ12/$AS12,0) -> -88.39252 | BM12: =IFERROR(BA12/$AS12,0) -> 80.240709 | BN12: =IFERROR(BB12/$AS12,0) -> 811.78623 | BO12: =IFERROR(BD12/$AS12,0) -> 1010.7536 | BP12: =BO12-BN12 -> 198.96732
B13: 10007969 | C13: POTA CONOS | D13: =TD!F10 -> 22.74 | E13: =IFERROR(F13/D13,0) -> 1368.5038 | F13: =TD!G10 -> 31119.777 | G13: =TD!H10 -> 4726.2816 | H13: =TD!I10 -> 1434.3918 | I13: =TD!J10 -> 2819.7713 | J13: =TD!K10 -> 2254.1003 | K13: 0 | L13: 0 | M13: =F13+G13+H13+I13 -> 40100.221 | N13: =IFERROR(M13/D13,0) -> 1763.4222 | O13: =F13+G13+H13-J13 -> 35026.35 | P13: =IFERROR(O13/D13,0) -> 1540.2968 | Q13: 2900 | R13: =Q13*D13 -> 65946 | S13: =R13-M13+(Q13-$AX$22)*D13*0.03 -> 27746.267 | T13: =IFERROR(S13/R13,0) -> 0.42074222 | U13: =R13-(M13-J13-I13)+(Q13-$AX$22)*D13*0.03 -> 32820.138 | V13: =IFERROR(U13/R13,0) -> 0.49768201 | X13: {=SUM([1]Hoja2!$I$5:$I$27*([1]Hoja2!$F$5:$F$27=X$5)*([1]Hoja2!$K$5:$K$27=$C13))} -> 0 | Y13: {=SUM([1]Hoja2!$J$5:$J$27*([1]Hoja2!$F$5:$F$27=X$5)*([1]Hoja2!$K$5:$K$27=$C13))} -> 0 | Z13: =IFERROR(Y13/X13,0) -> 0 | AA13: {=SUM([1]Hoja2!$I$5:$I$27*([1]Hoja2!$F$5:$F$27=AA$5)*([1]Hoja2!$K$5:$K$27=$C13))} -> 0 | AB13: {=SUM([1]Hoja2!$J$5:$J$27*([1]Hoja2!$F$5:$F$27=AA$5)*([1]Hoja2!$K$5:$K$27=$C13))} -> 0 | AC13: =IFERROR(AB13/AA13,0) -> 0 | AD13: {=SUM([1]Hoja2!$I$5:$I$27*([1]Hoja2!$F$5:$F$27=AD$5)*([1]Hoja2!$K$5:$K$27=$C13))} -> 0 | AE13: {=SUM([1]Hoja2!$J$5:$J$27*([1]Hoja2!$F$5:$F$27=AD$5)*([1]Hoja2!$K$5:$K$27=$C13))} -> 0 | AF13: =IFERROR(AE13/AD13,0) -> 0 | AG13: {=SUM([1]Hoja2!$I$5:$I$27*([1]Hoja2!$F$5:$F$27=AG$5)*([1]Hoja2!$K$5:$K$27=$C13))} -> 0 | AH13: {=SUM([1]Hoja2!$J$5:$J$27*([1]Hoja2!$F$5:$F$27=AG$5)*([1]Hoja2!$K$5:$K$27=$C13))} -> 0 | AI13: =IFERROR(AH13/AG13,0) -> 0 | AJ13: {=SUM([1]Hoja2!$I$5:$I$27*([1]Hoja2!$F$5:$F$27=AJ$5)*([1]Hoja2!$K$5:$K$27=$C13))} -> 27 | AK13: {=SUM([1]Hoja2!$J$5:$J$27*([1]Hoja2!$F$5:$F$27=AJ$5)*([1]Hoja2!$K$5:$K$27=$C13))} -> 46710 | AL13: =IFERROR(AK13/AJ13,0) -> 1730 | AM13: {=SUM([1]Hoja2!$I$5:$I$27*([1]Hoja2!$F$5:$F$27=AM$5)*([1]Hoja2!$K$5:$K$27=$C13))} -> 0 | AN13: {=SUM([1]Hoja2!$J$5:$J$27*([1]Hoja2!$F$5:$F$27=AM$5)*([1]Hoja2!$K$5:$K$27=$C13))} -> 0 | AO13: =IFERROR(AN13/AM13,0) -> 0 | AP13: {=SUM([1]Hoja2!$I$5:$I$27*([1]Hoja2!$F$5:$F$27=AP$5)*([1]Hoja2!$K$5:$K$27=$C13))} -> 0 | AQ13: {=SUM([1]Hoja2!$J$5:$J$27*([1]Hoja2!$F$5:$F$27=AP$5)*([1]Hoja2!$K$5:$K$27=$C13))} -> 0 | AR13: =IFERROR(AQ13/AP13,0) -> 0 | AS13: =X13+AA13+AD13+AG13+AJ13+AM13+AP13 -> 27 | AT13: =Y13+AB13+AE13+AH13+AK13+AN13+AQ13 -> 46710 | AU13: =IFERROR(AT13/AS13,0) -> 1730 | AV13: =-IFERROR(F13/D13*AS13,0) -> -36949.603 | AW13: =-207.84*AS13 -> -5611.68 | AX13: =$AX$18/$AS$18*$AS13 -> -1518.7065 | AY13: =$AY$18/$AS$18*$AS13 -> -2985.5197 | AZ13: =$AZ$18/$AS$18*$AS13 -> -2386.598 | BA13: =(AT13-AS13*$AX$22)*0.03 -> 1308.8161 | BB13: =AT13+SUM(AV13:AY13,BA13) -> 953.30695 | BC13: =IFERROR(BB13/AT13,0) -> 0.020409055 | BD13: =AT13+AV13+AW13+AX13+BA13-AZ13 -> 6325.4247 | BE13: =IFERROR(BD13/AT13,0) -> 0.13541907 | BG13: =AU13 -> 1730 | BH13: =IFERROR(AV13/$AS13,0) -> -1368.5038 | BI13: =IFERROR(AW13/$AS13,0) -> -207.84 | BJ13: =IFERROR(AX13/$AS13,0) -> -56.248389 | BK13: =IFERROR(AY13/$AS13,0) -> -110.5748 | BL13: =IFERROR(AZ13/$AS13,0) -> -88.39252 | BM13: =IFERROR(BA13/$AS13,0) -> 48.474672 | BN13: =IFERROR(BB13/$AS13,0) -> 35.307665 | BO13: =IFERROR(BD13/$AS13,0) -> 234.27499 | BP13: =BO13-BN13 -> 198.96732
B14: 10009239 | C14: POTA FILETE DARUMA | D14: =TD!F11 -> 0 | E14: =IFERROR(F14/D14,0) -> 0 | F14: =TD!G11 -> 0 | G14: =TD!H11 -> 0 | H14: =TD!I11 -> 0 | I14: =TD!J11 -> 0 | J14: =TD!K11 -> 0 | K14: 0 | L14: 0 | M14: =F14+G14+H14+I14 -> 0 | N14: =IFERROR(M14/D14,0) -> 0 | O14: =F14+G14+H14-J14 -> 0 | P14: =IFERROR(O14/D14,0) -> 0 | Q14: 1730 | R14: =Q14*D14 -> 0 | S14: =R14-M14+(Q14-$AX$22)*D14*0.03 -> 0 | T14: =IFERROR(S14/R14,0) -> 0 | U14: =R14-(M14-J14-I14)+(Q14-$AX$22)*D14*0.03 -> 0 | V14: =IFERROR(U14/R14,0) -> 0 | X14: {=SUM([1]Hoja2!$I$5:$I$27*([1]Hoja2!$F$5:$F$27=X$5)*([1]Hoja2!$K$5:$K$27=$C14))} -> 0 | Y14: {=SUM([1]Hoja2!$J$5:$J$27*([1]Hoja2!$F$5:$F$27=X$5)*([1]Hoja2!$K$5:$K$27=$C14))} -> 0 | Z14: =IFERROR(Y14/X14,0) -> 0 | AA14: {=SUM([1]Hoja2!$I$5:$I$27*([1]Hoja2!$F$5:$F$27=AA$5)*([1]Hoja2!$K$5:$K$27=$C14))} -> 0 | AB14: {=SUM([1]Hoja2!$J$5:$J$27*([1]Hoja2!$F$5:$F$27=AA$5)*([1]Hoja2!$K$5:$K$27=$C14))} -> 0 | AC14: =IFERROR(AB14/AA14,0) -> 0 | AD14: {=SUM([1]Hoja2!$I$5:$I$27*([1]Hoja2!$F$5:$F$27=AD$5)*([1]Hoja2!$K$5:$K$27=$C14))} -> 108 | AE14: {=SUM([1]Hoja2!$J$5:$J$27*([1]Hoja2!$F$5:$F$27=AD$5)*([1]Hoja2!$K$5:$K$27=$C14))} -> 421200 | AF14: =IFERROR(AE14/AD14,0) -> 3900 | AG14: {=SUM([1]Hoja2!$I$5:$I$27*([1]Hoja2!$F$5:$F$27=AG$5)*([1]Hoja2!$K$5:$K$27=$C14))} -> 0 | AH14: {=SUM([1]Hoja2!$J$5:$J$27*([1]Hoja2!$F$5:$F$27=AG$5)*([1]Hoja2!$K$5:$K$27=$C14))} -> 0 | AI14: =IFERROR(AH14/AG14,0) -> 0 | AJ14: {=SUM([1]Hoja2!$I$5:$I$27*([1]Hoja2!$F$5:$F$27=AJ$5)*([1]Hoja2!$K$5:$K$27=$C14))} -> 0 | AK14: {=SUM([1]Hoja2!$J$5:$J$27*([1]Hoja2!$F$5:$F$27=AJ$5)*([1]Hoja2!$K$5:$K$27=$C14))} -> 0 | AL14: =IFERROR(AK14/AJ14,0) -> 0 | AM14: {=SUM([1]Hoja2!$I$5:$I$27*([1]Hoja2!$F$5:$F$27=AM$5)*([1]Hoja2!$K$5:$K$27=$C14))} -> 0 | AN14: {=SUM([1]Hoja2!$J$5:$J$27*([1]Hoja2!$F$5:$F$27=AM$5)*([1]Hoja2!$K$5:$K$27=$C14))} -> 0 | AO14: =IFERROR(AN14/AM14,0) -> 0 | AP14: {=SUM([1]Hoja2!$I$5:$I$27*([1]Hoja2!$F$5:$F$27=AP$5)*([1]Hoja2!$K$5:$K$27=$C14))} -> 297 | AQ14: {=SUM([1]Hoja2!$J$5:$J$27*([1]Hoja2!$F$5:$F$27=AP$5)*([1]Hoja2!$K$5:$K$27=$C14))} -> 1171800 | AR14: =IFERROR(AQ14/AP14,0) -> 3945.4545 | AS14: =X14+AA14+AD14+AG14+AJ14+AM14+AP14 -> 405 | AT14: =Y14+AB14+AE14+AH14+AK14+AN14+AQ14 -> 1593000 | AU14: =IFERROR(AT14/AS14,0) -> 3933.3333 | AV14: =-AS14*'Stock Libre'!H45*1000 -> -1318225.5 | AW14: =-207.84*AS14 -> -84175.2 | AX14: =$AX$18/$AS$18*$AS14 -> -22780.598 | AY14: =$AY$18/$AS$18*$AS14 -> -44782.795 | AZ14: =$AZ$18/$AS$18*$AS14 -> -35798.97 | BA14: =(AT14-AS14*$AX$22)*0.03 -> 46402.742 | BB14: =AT14+SUM(AV14:AY14,BA14) -> 169438.66 | BC14: =IFERROR(BB14/AT14,0) -> 0.10636451 | BD14: =AT14+AV14+AW14+AX14+BA14-AZ14 -> 250020.43 | BE14: =IFERROR(BD14/AT14,0) -> 0.15694942 | BG14: =AU14 -> 3933.3333 | BH14: =IFERROR(AV14/$AS14,0) -> -3254.8777 | BI14: =IFERROR(AW14/$AS14,0) -> -207.84 | BJ14: =IFERROR(AX14/$AS14,0) -> -56.248389 | BK14: =IFERROR(AY14/$AS14,0) -> -110.5748 | BL14: =IFERROR(AZ14/$AS14,0) -> -88.39252 | BM14: =IFERROR(BA14/$AS14,0) -> 114.57467 | BN14: =IFERROR(BB14/$AS14,0) -> 418.36707 | BO14: =IFERROR(BD14/$AS14,0) -> 617.33439 | BP14: =BO14-BN14 -> 198.96732
B15: 10009334 | C15: POTA ALAS COCIDAS | D15: =TD!F12 -> 0 | E15: =IFERROR(F15/D15,0) -> 0 | F15: =TD!G12 -> 0 | G15: =TD!H12 -> 0 | H15: =TD!I12 -> 0 | I15: =TD!J12 -> 0 | J15: =TD!K12 -> 0 | K15: 0 | L15: 0 | M15: =F15+G15+H15+I15 -> 0 | N15: =IFERROR(M15/D15,0) -> 0 | O15: =F15+G15+H15-J15 -> 0 | P15: =IFERROR(O15/D15,0) -> 0 | Q15: 3900 | R15: =Q15*D15 -> 0 | S15: =R15-M15+(Q15-$AX$22)*D15*0.03 -> 0 | T15: =IFERROR(S15/R15,0) -> 0 | U15: =R15-(M15-J15-I15)+(Q15-$AX$22)*D15*0.03 -> 0 | V15: =IFERROR(U15/R15,0) -> 0 | X15: {=SUM([1]Hoja2!$I$5:$I$27*([1]Hoja2!$F$5:$F$27=X$5)*([1]Hoja2!$K$5:$K$27=$C15))} -> 0 | Y15: {=SUM([1]Hoja2!$J$5:$J$27*([1]Hoja2!$F$5:$F$27=X$5)*([1]Hoja2!$K$5:$K$27=$C15))} -> 0 | Z15: =IFERROR(Y15/X15,0) -> 0 | AA15: {=SUM([1]Hoja2!$I$5:$I$27*([1]Hoja2!$F$5:$F$27=AA$5)*([1]Hoja2!$K$5:$K$27=$C15))} -> 27 | AB15: {=SUM([1]Hoja2!$J$5:$J$27*([1]Hoja2!$F$5:$F$27=AA$5)*([1]Hoja2!$K$5:$K$27=$C15))} -> 116100 | AC15: =IFERROR(AB15/AA15,0) -> 4300 | AD15: {=SUM([1]Hoja2!$I$5:$I$27*([1]Hoja2!$F$5:$F$27=AD$5)*([1]Hoja2!$K$5:$K$27=$C15))} -> 0 | AE15: {=SUM([1]Hoja2!$J$5:$J$27*([1]Hoja2!$F$5:$F$27=AD$5)*([1]Hoja2!$K$5:$K$27=$C15))} -> 0 | AF15: =IFERROR(AE15/AD15,0) -> 0 | AG15: {=SUM([1]Hoja2!$I$5:$I$27*([1]Hoja2!$F$5:$F$27=AG$5)*([1]Hoja2!$K$5:$K$27=$C15))} -> 0 | AH15: {=SUM([1]Hoja2!$J$5:$J$27*([1]Hoja2!$F$5:$F$27=AG$5)*([1]Hoja2!$K$5:$K$27=$C15))} -> 0 | AI15: =IFERROR(AH15/AG15,0) -> 0 | AJ15: {=SUM([1]Hoja2!$I$5:$I$27*([1]Hoja2!$F$5:$F$27=AJ$5)*([1]Hoja2!$K$5:$K$27=$C15))} -> 54 | AK15: {=SUM([1]Hoja2!$J$5:$J$27*([1]Hoja2!$F$5:$F$27=AJ$5)*([1]Hoja2!$K$5:$K$27=$C15))} -> 232200 | AL15: =IFERROR(AK15/AJ15,0) -> 4300 | AM15: {=SUM([1]Hoja2!$I$5:$I$27*([1]Hoja2!$F$5:$F$27=AM$5)*([1]Hoja2!$K$5:$K$27=$C15))} -> 0 | AN15: {=SUM([1]Hoja2!$J$5:$J$27*([1]Hoja2!$F$5:$F$27=AM$5)*([1]Hoja2!$K$5:$K$27=$C15))} -> 0 | AO15: =IFERROR(AN15/AM15,0) -> 0 | AP15: {=SUM([1]Hoja2!$I$5:$I$27*([1]Hoja2!$F$5:$F$27=AP$5)*([1]Hoja2!$K$5:$K$27=$C15))} -> 81 | AQ15: {=SUM([1]Hoja2!$J$5:$J$27*([1]Hoja2!$F$5:$F$27=AP$5)*([1]Hoja2!$K$5:$K$27=$C15))} -> 329400 | AR15: =IFERROR(AQ15/AP15,0) -> 4066.6667 | AS15: =X15+AA15+AD15+AG15+AJ15+AM15+AP15 -> 162 | AT15: =Y15+AB15+AE15+AH15+AK15+AN15+AQ15 -> 677700 | AU15: =IFERROR(AT15/AS15,0) -> 4183.3333 | AV15: =-AS15*'Stock Libre'!H47*1000 -> -457557.42 | AW15: =-207.84*AS15 -> -33670.08 | AX15: =$AX$18/$AS$18*$AS15 -> -9112.2391 | AY15: =$AY$18/$AS$18*$AS15 -> -17913.118 | AZ15: =$AZ$18/$AS$18*$AS15 -> -14319.588 | BA15: =(AT15-AS15*$AX$22)*0.03 -> 19776.097 | BB15: =AT15+SUM(AV15:AY15,BA15) -> 179223.24 | BC15: =IFERROR(BB15/AT15,0) -> 0.26445808 | BD15: =AT15+AV15+AW15+AX15+BA15-AZ15 -> 211455.95 | BE15: =IFERROR(BD15/AT15,0) -> 0.31201999 | BG15: =AU15 -> 4183.3333 | BH15: =IFERROR(AV15/$AS15,0) -> -2824.4285 | BI15: =IFERROR(AW15/$AS15,0) -> -207.84 | BJ15: =IFERROR(AX15/$AS15,0) -> -56.248389 | BK15: =IFERROR(AY15/$AS15,0) -> -110.5748 | BL15: =IFERROR(AZ15/$AS15,0) -> -88.39252 | BM15: =IFERROR(BA15/$AS15,0) -> 122.07467 | BN15: =IFERROR(BB15/$AS15,0) -> 1106.3163 | BO15: =IFERROR(BD15/$AS15,0) -> 1305.2836 | BP15: =BO15-BN15 -> 198.96732
B16: 10009386 | C16: VENTOSAS | D16: =TD!F13 -> 16.4 | E16: =IFERROR(F16/D16,0) -> 1742.1709 | F16: =TD!G13 -> 28571.603 | G16: =TD!H13 -> 3408.576 | H16: =TD!I13 -> 1034.4778 | I16: =TD!J13 -> 2033.6082 | J16: =TD!K13 -> 1625.6484 | K16: 0 | L16: 0 | M16: =F16+G16+H16+I16 -> 35048.265 | N16: =IFERROR(M16/D16,0) -> 2137.0893 | O16: =F16+G16+H16-J16 -> 31389.009 | P16: =IFERROR(O16/D16,0) -> 1913.9639 | R16: =Q16*D16 -> 0 | S16: =R16-M16+(Q16-$AX$22)*D16*0.03 -> -35104.441 | T16: =IFERROR(S16/R16,0) -> 0 | U16: =R16-(M16-J16-I16)+(Q16-$AX$22)*D16*0.03 -> -31445.184 | V16: =IFERROR(U16/R16,0) -> 0 | X16: {=SUM([1]Hoja2!$I$5:$I$27*([1]Hoja2!$F$5:$F$27=X$5)*([1]Hoja2!$K$5:$K$27=$C16))} -> 0 | Y16: {=SUM([1]Hoja2!$J$5:$J$27*([1]Hoja2!$F$5:$F$27=X$5)*([1]Hoja2!$K$5:$K$27=$C16))} -> 0 | Z16: =IFERROR(Y16/X16,0) -> 0 | AA16: {=SUM([1]Hoja2!$I$5:$I$27*([1]Hoja2!$F$5:$F$27=AA$5)*([1]Hoja2!$K$5:$K$27=$C16))} -> 0 | AB16: {=SUM([1]Hoja2!$J$5:$J$27*([1]Hoja2!$F$5:$F$27=AA$5)*([1]Hoja2!$K$5:$K$27=$C16))} -> 0 | AC16: =IFERROR(AB16/AA16,0) -> 0 | AD16: {=SUM([1]Hoja2!$I$5:$I$27*([1]Hoja2!$F$5:$F$27=AD$5)*([1]Hoja2!$K$5:$K$27=$C16))} -> 0 | AE16: {=SUM([1]Hoja2!$J$5:$J$27*([1]Hoja2!$F$5:$F$27=AD$5)*([1]Hoja2!$K$5:$K$27=$C16))} -> 0 | AF16: =IFERROR(AE16/AD16,0) -> 0 | AG16: {=SUM([1]Hoja2!$I$5:$I$27*([1]Hoja2!$F$5:$F$27=AG$5)*([1]Hoja2!$K$5:$K$27=$C16))} -> 0 | AH16: {=SUM([1]Hoja2!$J$5:$J$27*([1]Hoja2!$F$5:$F$27=AG$5)*([1]Hoja2!$K$5:$K$27=$C16))} -> 0 | AI16: =IFERROR(AH16/AG16,0) -> 0 | AJ16: {=SUM([1]Hoja2!$I$5:$I$27*([1]Hoja2!$F$5:$F$27=AJ$5)*([1]Hoja2!$K$5:$K$27=$C16))} -> 0 | AK16: {=SUM([1]Hoja2!$J$5:$J$27*([1]Hoja2!$F$5:$F$27=AJ$5)*([1]Hoja2!$K$5:$K$27=$C16))} -> 0 | AL16: =IFERROR(AK16/AJ16,0) -> 0 | AM16: {=SUM([1]Hoja2!$I$5:$I$27*([1]Hoja2!$F$5:$F$27=AM$5)*([1]Hoja2!$K$5:$K$27=$C16))} -> 0 | AN16: {=SUM([1]Hoja2!$J$5:$J$27*([1]Hoja2!$F$5:$F$27=AM$5)*([1]Hoja2!$K$5:$K$27=$C16))} -> 0 | AO16: =IFERROR(AN16/AM16,0) -> 0 | AP16: {=SUM([1]Hoja2!$I$5:$I$27*([1]Hoja2!$F$5:$F$27=AP$5)*([1]Hoja2!$K$5:$K$27=$C16))} -> 0 | AQ16: {=SUM([1]Hoja2!$J$5:$J$27*([1]Hoja2!$F$5:$F$27=AP$5)*([1]Hoja2!$K$5:$K$27=$C16))} -> 0 | AR16: =IFERROR(AQ16/AP16,0) -> 0 | AS16: =X16+AA16+AD16+AG16+AJ16+AM16+AP16 -> 0 | AT16: =Y16+AB16+AE16+AH16+AK16+AN16+AQ16 -> 0 | AU16: =IFERROR(AT16/AS16,0) -> 0 | AV16: =-IFERROR(F16/D16*AS16,0) -> 0 | AW16: =-207.84*AS16 -> 0 | AX16: =$AX$18/$AS$18*$AS16 -> 0 | AY16: =$AY$18/$AS$18*$AS16 -> 0 | AZ16: =$AZ$18/$AS$18*$AS16 -> 0 | BA16: =(AT16-AS16*$AX$22)*0.03 -> 0 | BB16: =AT16+SUM(AV16:AY16,BA16) -> 0 | BC16: =IFERROR(BB16/AT16,0) -> 0 | BD16: =AT16+AV16+AW16+AX16+BA16-AZ16 -> 0 | BE16: =IFERROR(BD16/AT16,0) -> 0 | BG16: =AU16 -> 0 | BH16: =IFERROR(AV16/$AS16,0) -> 0 | BI16: =IFERROR(AW16/$AS16,0) -> 0 | BJ16: =IFERROR(AX16/$AS16,0) -> 0 | BK16: =IFERROR(AY16/$AS16,0) -> 0 | BL16: =IFERROR(AZ16/$AS16,0) -> 0 | BM16: =IFERROR(BA16/$AS16,0) -> 0 | BN16: =IFERROR(BB16/$AS16,0) -> 0 | BO16: =IFERROR(BD16/$AS16,0) -> 0 | BP16: =BO16-BN16 -> 0
B17: 10009386 | C17: OTROS | D17: =TD!F14 -> 8.78 | E17: =IFERROR(F17/D17,0) -> 1416.8705 | F17: =TD!G14 -> 12440.123 | G17: =TD!H14 -> 1824.8352 | H17: =TD!I14 -> 553.82411 | I17: =TD!J14 -> 1088.7244 | J17: =TD!K14 -> 870.31663 | K17: 0 | L17: 0 | M17: =F17+G17+H17+I17 -> 15907.507 | N17: =IFERROR(M17/D17,0) -> 1811.7889 | O17: =F17+G17+H17-J17 -> 13948.466 | P17: =IFERROR(O17/D17,0) -> 1588.6635 | R17: =Q17*D17 -> 0 | S17: =R17-M17+(Q17-$AX$22)*D17*0.03 -> -15937.581 | T17: =IFERROR(S17/R17,0) -> 0 | U17: =R17-(M17-J17-I17)+(Q17-$AX$22)*D17*0.03 -> -13978.54 | V17: =IFERROR(U17/R17,0) -> 0 | X17: {=SUM([1]Hoja2!$I$5:$I$27*([1]Hoja2!$F$5:$F$27=X$5)*([1]Hoja2!$K$5:$K$27=$C17))} -> 26 | Y17: {=SUM([1]Hoja2!$J$5:$J$27*([1]Hoja2!$F$5:$F$27=X$5)*([1]Hoja2!$K$5:$K$27=$C17))} -> 36400 | Z17: =IFERROR(Y17/X17,0) -> 1400 | AA17: {=SUM([1]Hoja2!$I$5:$I$27*([1]Hoja2!$F$5:$F$27=AA$5)*([1]Hoja2!$K$5:$K$27=$C17))} -> 0 | AB17: {=SUM([1]Hoja2!$J$5:$J$27*([1]Hoja2!$F$5:$F$27=AA$5)*([1]Hoja2!$K$5:$K$27=$C17))} -> 0 | AC17: =IFERROR(AB17/AA17,0) -> 0 | AD17: {=SUM([1]Hoja2!$I$5:$I$27*([1]Hoja2!$F$5:$F$27=AD$5)*([1]Hoja2!$K$5:$K$27=$C17))} -> 0 | AE17: {=SUM([1]Hoja2!$J$5:$J$27*([1]Hoja2!$F$5:$F$27=AD$5)*([1]Hoja2!$K$5:$K$27=$C17))} -> 0 | AF17: =IFERROR(AE17/AD17,0) -> 0 | AG17: {=SUM([1]Hoja2!$I$5:$I$27*([1]Hoja2!$F$5:$F$27=AG$5)*([1]Hoja2!$K$5:$K$27=$C17))} -> 0 | AH17: {=SUM([1]Hoja2!$J$5:$J$27*([1]Hoja2!$F$5:$F$27=AG$5)*([1]Hoja2!$K$5:$K$27=$C17))} -> 0 | AI17: =IFERROR(AH17/AG17,0) -> 0 | AJ17: {=SUM([1]Hoja2!$I$5:$I$27*([1]Hoja2!$F$5:$F$27=AJ$5)*([1]Hoja2!$K$5:$K$27=$C17))} -> 0 | AK17: {=SUM([1]Hoja2!$J$5:$J$27*([1]Hoja2!$F$5:$F$27=AJ$5)*([1]Hoja2!$K$5:$K$27=$C17))} -> 0 | AL17: =IFERROR(AK17/AJ17,0) -> 0 | AM17: {=SUM([1]Hoja2!$I$5:$I$27*([1]Hoja2!$F$5:$F$27=AM$5)*([1]Hoja2!$K$5:$K$27=$C17))} -> 0 | AN17: {=SUM([1]Hoja2!$J$5:$J$27*([1]Hoja2!$F$5:$F$27=AM$5)*([1]Hoja2!$K$5:$K$27=$C17))} -> 0 | AO17: =IFERROR(AN17/AM17,0) -> 0 | AP17: {=SUM([1]Hoja2!$I$5:$I$27*([1]Hoja2!$F$5:$F$27=AP$5)*([1]Hoja2!$K$5:$K$27=$C17))} -> 27 | AQ17: {=SUM([1]Hoja2!$J$5:$J$27*([1]Hoja2!$F$5:$F$27=AP$5)*([1]Hoja2!$K$5:$K$27=$C17))} -> 67500 | AR17: =IFERROR(AQ17/AP17,0) -> 2500 | AS17: =X17+AA17+AD17+AG17+AJ17+AM17+AP17 -> 53 | AT17: =Y17+AB17+AE17+AH17+AK17+AN17+AQ17 -> 103900 | AU17: =IFERROR(AT17/AS17,0) -> 1960.3774 | AV17: =-IFERROR(F17/D17*AS17,0) -> -75094.136 | AW17: =-207.84*AS17 -> -11015.52 | AX17: =$AX$18/$AS$18*$AS17 -> -2981.1646 | AY17: =$AY$18/$AS$18*$AS17 -> -5860.4646 | AZ17: =$AZ$18/$AS$18*$AS17 -> -4684.8035 | BA17: =(AT17-AS17*$AX$22)*0.03 -> 2935.4576 | BB17: =AT17+SUM(AV17:AY17,BA17) -> 11884.172 | BC17: =IFERROR(BB17/AT17,0) -> 0.11438087 | BD17: =AT17+AV17+AW17+AX17+BA17-AZ17 -> 22429.44 | BE17: =IFERROR(BD17/AT17,0) -> 0.21587527 | BG17: =AU17 -> 1960.3774 | BH17: =IFERROR(AV17/$AS17,0) -> -1416.8705 | BI17: =IFERROR(AW17/$AS17,0) -> -207.84 | BJ17: =IFERROR(AX17/$AS17,0) -> -56.248389 | BK17: =IFERROR(AY17/$AS17,0) -> -110.5748 | BL17: =IFERROR(AZ17/$AS17,0) -> -88.39252 | BM17: =IFERROR(BA17/$AS17,0) -> 55.385992 | BN17: =IFERROR(BB17/$AS17,0) -> 224.22966 | BO17: =IFERROR(BD17/$AS17,0) -> 423.19698 | BP17: =BO17-BN17 -> 198.96732
C18: TOTAL | D18: =SUM(D7:D17) -> 1245.745 | E18: =IFERROR(F18/D18,0) -> 1798.8988 | F18: =SUM(F7:F17) -> 2240969.2 | G18: =SUM(G7:G17) -> 258915.64 | H18: =SUM(H7:H17) -> 78579 | I18: =SUM(I7:I17) -> 154473 | J18: =SUM(J7:J17) -> 123484.35 | K18: =SUM(K7:K17) -> 0 | L18: 0 | M18: =SUM(M7:M17) -> 2732936.9 | N18: =IFERROR(M18/D18,0) -> 2193.8173 | O18: =SUM(O7:O17) -> 2454979.5 | P18: =IFERROR(O18/D18,0) -> 1970.6919 | Q18: =R18/D18 -> 1968.9836 | R18: =SUM(R7:R17) -> 2452851.5 | S18: =SUM(S7:S17) -> -210766.93 | T18: =S18/R18 -> -0.085927308 | U18: =SUM(U7:U17) -> 67190.424 | V18: =IFERROR(U18/R18,0) -> 0.027392781 | X18: =SUM(X7:X17) -> 26 | Y18: =SUM(Y7:Y17) -> 36400 | Z18: =IFERROR(Y18/X18,0) -> 1400 | AA18: =SUM(AA7:AA17) -> 53 | AB18: =SUM(AB7:AB17) -> 149900 | AC18: =IFERROR(AB18/AA18,0) -> 2828.3019 | AD18: =SUM(AD7:AD17) -> 207 | AE18: =SUM(AE7:AE17) -> 654750 | AF18: =IFERROR(AE18/AD18,0) -> 3163.0435 | AG18: =SUM(AG7:AG17) -> 26 | AH18: =SUM(AH7:AH17) -> 67600 | AI18: =IFERROR(AH18/AG18,0) -> 2600 | AJ18: =SUM(AJ7:AJ17) -> 186 | AK18: =SUM(AK7:AK17) -> 502590 | AL18: =IFERROR(AK18/AJ18,0) -> 2702.0968 | AM18: =SUM(AM7:AM17) -> 53 | AN18: =SUM(AN7:AN17) -> 147810 | AO18: =IFERROR(AN18/AM18,0) -> 2788.8679 | AP18: =SUM(AP7:AP17) -> 846 | AQ18: =SUM(AQ7:AQ17) -> 2429610 | AR18: =IFERROR(AQ18/AP18,0) -> 2871.8794 | AS18: =SUM(AS7:AS17) -> 1397 | AT18: =SUM(AT7:AT17) -> 3988660 | AU18: =IFERROR(AT18/AS18,0) -> 2855.1611 | AV18: =SUM(AV7:AV17) -> -3203160.3 | AW18: =SUM(AW7:AW17) -> -290352.48 | AX18: =-'Stock Libre'!N61 -> -78579 | AY18: =-'Stock Libre'!O61 -> -154473 | AZ18: =-'Stock Libre'!P61 -> -123484.35 | BA18: =SUM(BA7:BA17) -> 114874.62 | BB18: =SUM(BB7:BB17) -> 376969.81 | BC18: =IFERROR(BB18/AT18,0) -> 0.094510388 | BD18: =SUM(BD7:BD17) -> 654927.16 | BE18: =IFERROR(BD18/AT18,0) -> 0.16419729 | BG18: =AU18 -> 2855.1611 | BH18: =IFERROR(AV18/$AS18,0) -> -2292.885 | BI18: =IFERROR(AW18/$AS18,0) -> -207.84 | BJ18: =IFERROR(AX18/$AS18,0) -> -56.248389 | BK18: =IFERROR(AY18/$AS18,0) -> -110.5748 | BL18: =IFERROR(AZ18/$AS18,0) -> -88.39252 | BM18: =IFERROR(BA18/$AS18,0) -> 82.229503 | BN18: =IFERROR(BB18/$AS18,0) -> 269.84238 | BO18: =IFERROR(BD18/$AS18,0) -> 468.8097 | BP18: =BO18-BN18 -> 198.96732
N19: =N18-P18 -> 223.1254
AW22: flete x tm | AX22: 114.17761

Sheet TD
E3: CÓDIGO | F3: Suma de TM en Stock | G3: Suma de Costo Ventas | H3: Suma de Gasto Ventas | I3: Suma de Gasto ADM | J3: Suma de Gasto Fin | K3: Suma de Depreciación
A4: 10005721 | B4: =C4=E4 -> TRUE | C4: 10005721 | D4: POTA FILETE CONGELADO | E4: 10005721 | F4: 561.84 | G4: 1115019.9 | H4: 116772.83 | I4: 35439.697 | J4: 69668.44 | K4: 55692.334
A5: 10005779 | B5: =C5=E5 -> TRUE | C5: 10005779 | D5: POTA NUCAS CONGELADAS | E5: 10005779 | F5: 235.92 | G5: 382664.69 | H5: 49033.613 | I5: 14881.342 | J5: 29254.197 | K5: 23385.547
A6: 10006719 | B6: =C6=E6 -> TRUE | C6: 10006719 | D6: POTA ALAS CONGELADAS | E6: 10006719 | F6: 63.32 | G6: 119210.81 | H6: 13160.429 | I6: 3994.0937 | J6: 7851.7115 | K6: 6276.5887
A7: 10007050 | B7: =C7=E7 -> TRUE | C7: 10007050 | D7: POTA RECORTES COCIDOS | E7: 10007050 | F7: 103.325 | G7: 149195.72 | H7: 21475.068 | I7: 6517.5258 | J7: 12812.351 | K7: 10242.08
A8: 10007162 | B8: =C8=E8 -> TRUE | C8: 10007162 | D8: POTA REJOS CONGELADOS | E8: 10007162 | F8: 171.96 | G8: 299330.39 | H8: 35740.166 | I8: 10846.879 | J8: 21323.126 | K8: 17045.518
A9: 10007567 | B9: =C9=E9 -> TRUE | C9: 10007567 | D9: POTA REPRODUCTORES | E9: 10007567 | F9: 61.46 | G9: 103416.23 | H9: 12773.846 | I9: 3876.7688 | J9: 7621.0706 | K9: 6092.2164
A10: 10007969 | B10: =C10=E10 -> TRUE | C10: 10007969 | D10: POTA CONOS | E10: 10007969 | F10: 22.74 | G10: 31119.777 | H10: 4726.2816 | I10: 1434.3918 | J10: 2819.7713 | K10: 2254.1003
A11: 10009207 | B11: =C11=E11 -> TRUE | C11: 10009239 | D11: POTA FILETE DARUMA | E11: 10009239 | F11: 0 | G11: 0 | H11: 0 | I11: 0 | J11: 0 | K11: 0
A12: 10009239 | B12: =C12=E12 -> TRUE | C12: 10009334 | D12: POTA ALAS COCIDAS | E12: 10009334 | F12: 0 | G12: 0 | H12: 0 | I12: 0 | J12: 0 | K12: 0
A13: 10009334 | B13: =C13=E13 -> TRUE | C13: 10009386 | D13: VENTOSAS | E13: 10009386 | F13: 16.4 | G13: 28571.603 | H13: 3408.576 | I13: 1034.4778 | J13: 2033.6082 | K13: 1625.6484
A14: 10009386 | B14: =C14=E14 -> FALSE | D14: OTROS | E14: 10009207 | F14: 8.78 | G14: 12440.123 | H14: 1824.8352 | I14: 553.82411 | J14: 1088.7244 | K14: 870.31663
E15: (vacío) | F15: 0 | G15: 0 | H15: 0 | I15: 0 | J15: 0 | K15: 0
E16: Total Resultado | F16: 1245.745 | G16: 2240969.2 | H16: 258915.64 | I16: 78579 | J16: 154473 | K16: 123484.35

Sheet Stock Libre
A1: CODIGO | B1: PRODUCTO | C1: TOTAL STOCK | D1: POR EMBARCAR | E1: STOCK LIBRE | G1: CÓDIGO | H1: CU X TM | I1: % MP | J1: incremento MP | K1: TM en Stock | L1: Costo Ventas | M1: Gasto Ventas | N1: Gasto ADM | O1: Gasto Fin | P1: Depreciación | Q1: Utilidad Neta | R1: Margen Neto | S1: Venta Equilibrio | T1: Precio Equilibrio x TM
A2: 10009178 | B2: POTA ALAS FR C/P C/C (B) S/COD BL10 S20 | C2: 14280 | D2: 2000 | E2: 12280 | G2: 10006719 | H2: =IFERROR(INDEX([2]Resumen!$K$3:$K$63,MATCH(G2,[2]Resumen!$C$3:$C$63,0)),0)*(1+I2*J2)/1000-51.89/1000 -> 1.8826724 | I2: 0.71 | J2: -0.07 | K2: =IF(E2<0,0,E2)/1000 -> 12.28 | L2: =IFERROR(H2*K2,0)*1000 -> 23119.217 | M2: =207.84*K2 -> 2552.2752 | N2: =$N$61/$K$59*K2 -> 774.59682 | O2: =$O$61/$K$59*K2 -> 1522.7261 | P2: =$P$61/$K$59*K2 -> 1217.2538 | Q2: 0 | R2: 0 | S2: =L2+M2+N2+O2 -> 27968.815 | T2: =IFERROR(S2/K2,0) -> 2277.5908
A3: 10006668 | B3: POTA ALAS FR C/P C/C <0.5 BL10 S20 | C3: 3020 | D3: 0 | E3: 3020 | G3: 10006719 | H3: =IFERROR(INDEX([2]Resumen!$K$3:$K$63,MATCH(G3,[2]Resumen!$C$3:$C$63,0)),0)*(1+I3*J3)/1000-51.89/1000 -> 1.8826724 | I3: 0.71 | J3: -0.07 | K3: =IF(E3<0,0,E3)/1000 -> 3.02 | L3: =IFERROR(H3*K3,0)*1000 -> 5685.6705 | M3: =207.84*K3 -> 627.6768 | N3: =$N$61/$K$59*K3 -> 190.49531 | O3: =$O$61/$K$59*K3 -> 374.4815 | P3: =$P$61/$K$59*K3 -> 299.3572 | Q3: 0 | R3: 0 | S3: =L3+M3+N3+O3 -> 6878.3241 | T3: =IFERROR(S3/K3,0) -> 2277.5908
A4: 10006719 | B4: POTA ALAS FR C/P C/C 0.5-1 BL10 S20 | C4: 37900 | D4: 25000 | E4: 12900 | G4: 10006719 | H4: =IFERROR(INDEX([2]Resumen!$K$3:$K$63,MATCH(G4,[2]Resumen!$C$3:$C$63,0)),0)*(1+I4*J4)/1000-51.89/1000 -> 1.8826724 | I4: 0.71 | J4: -0.07 | K4: =IF(E4<0,0,E4)/1000 -> 12.9 | L4: =IFERROR(H4*K4,0)*1000 -> 24286.473 | M4: =207.84*K4 -> 2681.136 | N4: =$N$61/$K$59*K4 -> 813.70513 | O4: =$O$61/$K$59*K4 -> 1599.6064 | P4: =$P$61/$K$59*K4 -> 1278.7112 | Q4: 0 | R4: 0 | S4: =L4+M4+N4+O4 -> 29380.921 | T4: =IFERROR(S4/K4,0) -> 2277.5908
A5: 10009265 | B5: POTA ALAS FR C/P C/C 0.3 - 0.5 BL10 S20 | C5: 0 | E5: 0 | G5: 10006719 | H5: =IFERROR(INDEX([2]Resumen!$K$3:$K$63,MATCH(G5,[2]Resumen!$C$3:$C$63,0)),0)*(1+I5*J5)/1000-51.89/1000 -> 1.8826724 | I5: 0.71 | J5: -0.07 | K5: =IF(E5<0,0,E5)/1000 -> 0 | L5: =IFERROR(H5*K5,0)*1000 -> 0 | M5: =207.84*K5 -> 0 | N5: =$N$61/$K$59*K5 -> 0 | O5: =$O$61/$K$59*K5 -> 0 | P5: =$P$61/$K$59*K5 -> 0 | Q5: 0 | R5: 0 | S5: =L5+M5+N5+O5 -> 0 | T5: =IFERROR(S5/K5,0) -> 0
A6: 10006720 | B6: POTA ALAS FR C/P C/C 1-2 BL10 S20 | C6: 1900 | D6: 1900 | E6: 0 | G6: 10006719 | H6: =IFERROR(INDEX([2]Resumen!$K$3:$K$63,MATCH(G6,[2]Resumen!$C$3:$C$63,0)),0)*(1+I6*J6)/1000-51.89/1000 -> 1.8826724 | I6: 0.71 | J6: -0.07 | K6: =IF(E6<0,0,E6)/1000 -> 0 | L6: =IFERROR(H6*K6,0)*1000 -> 0 | M6: =207.84*K6 -> 0 | N6: =$N$61/$K$59*K6 -> 0 | O6: =$O$61/$K$59*K6 -> 0 | P6: =$P$61/$K$59*K6 -> 0 | Q6: 0 | R6: 0 | S6: =L6+M6+N6+O6 -> 0 | T6: =IFERROR(S6/K6,0) -> 0
A7: 10010005 | B7: POTA ALAS FR C/P C/C 1-2 BL10 S20 ENTERA | C7: 35120 | E7: 35120 | G7: 10006719 | H7: =IFERROR(INDEX([2]Resumen!$K$3:$K$63,MATCH(G7,[2]Resumen!$C$3:$C$63,0)),0)*(1+I7*J7)/1000-51.89/1000 -> 1.8826724 | I7: 0.71 | J7: -0.07 | K7: =IF(E7<0,0,E7)/1000 -> 35.12 | L7: =IFERROR(H7*K7,0)*1000 -> 66119.453 | M7: =207.84*K7 -> 7299.3408 | N7: =$N$61/$K$59*K7 -> 2215.2965 | O7: =$O$61/$K$59*K7 -> 4354.8975 | P7: =$P$61/$K$59*K7 -> 3481.2665 | Q7: 0 | R7: 0 | S7: =L7+M7+N7+O7 -> 79988.988 | T7: =IFERROR(S7/K7,0) -> 2277.5908
A8: 10006722 | B8: POTA ALAS FR C/P C/C 2up | C8: 120 | D8: 120 | E8: 0 | G8: 10006719 | H8: =IFERROR(INDEX([2]Resumen!$K$3:$K$63,MATCH(G8,[2]Resumen!$C$3:$C$63,0)),0)*(1+I8*J8)/1000-51.89/1000 -> 1.8826724 | I8: 0.71 | J8: -0.07 | K8: =IF(E8<0,0,E8)/1000 -> 0 | L8: =IFERROR(H8*K8,0)*1000 -> 0 | M8: =207.84*K8 -> 0 | N8: =$N$61/$K$59*K8 -> 0 | O8: =$O$61/$K$59*K8 -> 0 | P8: =$P$61/$K$59*K8 -> 0 | Q8: 0 | R8: 0 | S8: =L8+M8+N8+O8 -> 0 | T8: =IFERROR(S8/K8,0) -> 0
A9: 10009207 | B9: POTA LABIOS FR S/COD BL10 S20 | C9: 8780 | E9: 8780 | G9: 10009207 | H9: =IFERROR(INDEX([2]Resumen!$K$3:$K$63,MATCH(G9,[2]Resumen!$C$3:$C$63,0)),0)*(1+I9*J9)/1000-51.89/1000 -> 1.4168705 | I9: 0.71 | J9: -0.07 | K9: =IF(E9<0,0,E9)/1000 -> 8.78 | L9: =IFERROR(H9*K9,0)*1000 -> 12440.123 | M9: =207.84*K9 -> 1824.8352 | N9: =$N$61/$K$59*K9 -> 553.82411 | O9: =$O$61/$K$59*K9 -> 1088.7244 | P9: =$P$61/$K$59*K9 -> 870.31663 | Q9: 0 | R9: 0 | S9: =L9+M9+N9+O9 -> 15907.507 | T9: =IFERROR(S9/K9,0) -> 1811.7889
A10: 10007969 | B10: POTA CONOS | C10: 49740 | D10: 27000 | E10: 22740 | G10: 10007969 | H10: =IFERROR(INDEX([2]Resumen!$K$3:$K$63,MATCH(G10,[2]Resumen!$C$3:$C$63,0)),0)*(1+I10*J10)/1000-51.89/1000 -> 1.3685038 | I10: 0.71 | J10: -0.07 | K10: =IF(E10<0,0,E10)/1000 -> 22.74 | L10: =IFERROR(H10*K10,0)*1000 -> 31119.777 | M10: =207.84*K10 -> 4726.2816 | N10: =$N$61/$K$59*K10 -> 1434.3918 | O10: =$O$61/$K$59*K10 -> 2819.7713 | P10: =$P$61/$K$59*K10 -> 2254.1003 | Q10: 0 | R10: 0 | S10: =L10+M10+N10+O10 -> 40100.221 | T10: =IFERROR(S10/K10,0) -> 1763.4222
A11: 10009174 | B11: POTA ENTERA < 1KG | C11: 0 | E11: 0 | J11: -0.07 | K11: =IF(E11<0,0,E11)/1000 -> 0 | L11: =IFERROR(H11*K11,0)*1000 -> 0 | M11: =207.84*K11 -> 0 | N11: =$N$61/$K$59*K11 -> 0 | O11: =$O$61/$K$59*K11 -> 0 | P11: =$P$61/$K$59*K11 -> 0 | Q11: 0 | R11: 0 | S11: =L11+M11+N11+O11 -> 0 | T11: =IFERROR(S11/K11,0) -> 0
A12: 10009175 | B12: TUBO ALETA 0.1-0.5 KG | C12: 0 | E12: 0 | J12: -0.07 | K12: =IF(E12<0,0,E12)/1000 -> 0 | L12: =IFERROR(H12*K12,0)*1000 -> 0 | M12: =207.84*K12 -> 0 | N12: =$N$61/$K$59*K12 -> 0 | O12: =$O$61/$K$59*K12 -> 0 | P12: =$P$61/$K$59*K12 -> 0 | Q12: 0 | R12: 0 | S12: =L12+M12+N12+O12 -> 0 | T12: =IFERROR(S12/K12,0) -> 0
A13: 10009176 | B13: TUBO ALETA 0.5-1.0 KG | C13: 0 | E13: 0 | J13: -0.07 | K13: =IF(E13<0,0,E13)/1000 -> 0 | L13: =IFERROR(H13*K13,0)*1000 -> 0 | M13: =207.84*K13 -> 0 | N13: =$N$61/$K$59*K13 -> 0 | O13: =$O$61/$K$59*K13 -> 0 | P13: =$P$61/$K$59*K13 -> 0 | Q13: 0 | R13: 0 | S13: =L13+M13+N13+O13 -> 0 | T13: =IFERROR(S13/K13,0) -> 0
A14: 10010003 | B14: TUBO ALETA 1.0-1.5 kg | C14: 0 | E14: 0 | J14: -0.07 | K14: =IF(E14<0,0,E14)/1000 -> 0 | L14: =IFERROR(H14*K14,0)*1000 -> 0 | M14: =207.84*K14 -> 0 | N14: =$N$61/$K$59*K14 -> 0 | O14: =$O$61/$K$59*K14 -> 0 | P14: =$P$61/$K$59*K14 -> 0 | Q14: 0 | R14: 0 | S14: =L14+M14+N14+O14 -> 0 | T14: =IFERROR(S14/K14,0) -> 0
A15: 10009177 | B15: TUBO ALETA 1.0-2.0 KG | C15: 0 | E15: 0 | J15: -0.07 | K15: =IF(E15<0,0,E15)/1000 -> 0 | L15: =IFERROR(H15*K15,0)*1000 -> 0 | M15: =207.84*K15 -> 0 | N15: =$N$61/$K$59*K15 -> 0 | O15: =$O$61/$K$59*K15 -> 0 | P15: =$P$61/$K$59*K15 -> 0 | Q15: 0 | R15: 0 | S15: =L15+M15+N15+O15 -> 0 | T15: =IFERROR(S15/K15,0) -> 0
A16: 10004433 | B16: POTA FILETE C/M C/T FR 0.5-1.0 BL10 S20 | C16: 1400 | E16: 1400 | G16: 10005721 | H16: =IFERROR(INDEX([2]Resumen!$K$3:$K$63,MATCH(G16,[2]Resumen!$C$3:$C$63,0)),0)*(1+I16*J16)/1000-51.89/1000 -> 1.9845862 | I16: 0.67 | J16: -0.07 | K16: =IF(E16<0,0,E16)/1000 -> 1.4 | L16: =IFERROR(H16*K16,0)*1000 -> 2778.4206 | M16: =207.84*K16 -> 290.976 | N16: =$N$61/$K$59*K16 -> 88.309084 | O16: =$O$61/$K$59*K16 -> 173.6007 | P16: =$P$61/$K$59*K16 -> 138.77486 | Q16: 0 | R16: 0 | S16: =L16+M16+N16+O16 -> 3331.3064 | T16: =IFERROR(S16/K16,0) -> 2379.5046
A17: 10004434 | B17: POTA FILETE C/M C/T FR 1-2 BL10 S20 | C17: 1940 | D17: 1940 | E17: 0 | G17: 10005721 | H17: =IFERROR(INDEX([2]Resumen!$K$3:$K$63,MATCH(G17,[2]Resumen!$C$3:$C$63,0)),0)*(1+I17*J17)/1000-51.89/1000 -> 1.9845862 | I17: 0.67 | J17: -0.07 | K17: =IF(E17<0,0,E17)/1000 -> 0 | L17: =IFERROR(H17*K17,0)*1000 -> 0 | M17: =207.84*K17 -> 0 | N17: =$N$61/$K$59*K17 -> 0 | O17: =$O$61/$K$59*K17 -> 0 | P17: =$P$61/$K$59*K17 -> 0 | Q17: 0 | R17: 0 | S17: =L17+M17+N17+O17 -> 0 | T17: =IFERROR(S17/K17,0) -> 0
A18: 10004435 | B18: POTA FILETE C/M C/T FR 2-4 S20 | C18: 14400 | E18: 14400 | G18: 10005721 | H18: =IFERROR(INDEX([2]Resumen!$K$3:$K$63,MATCH(G18,[2]Resumen!$C$3:$C$63,0)),0)*(1+I18*J18)/1000-51.89/1000 -> 1.9845862 | I18: 0.67 | J18: -0.07 | K18: =IF(E18<0,0,E18)/1000 -> 14.4 | L18: =IFERROR(H18*K18,0)*1000 -> 28578.041 | M18: =207.84*K18 -> 2992.896 | N18: =$N$61/$K$59*K18 -> 908.32201 | O18: =$O$61/$K$59*K18 -> 1785.6072 | P18: =$P$61/$K$59*K18 -> 1427.3986 | Q18: 0 | R18: 0 | S18: =L18+M18+N18+O18 -> 34264.866 | T18: =IFERROR(S18/K18,0) -> 2379.5046
A19: 10005708 | B19: POTA FILETE C/M C/T FR <0.5 Kg AA BL10 S20 | C19: 1080 | E19: 1080 | G19: 10005721 | H19: =IFERROR(INDEX([2]Resumen!$K$3:$K$63,MATCH(G19,[2]Resumen!$C$3:$C$63,0)),0)*(1+I19*J19)/1000-51.89/1000 -> 1.9845862 | I19: 0.67 | J19: -0.07 | K19: =IF(E19<0,0,E19)/1000 -> 1.08 | L19: =IFERROR(H19*K19,0)*1000 -> 2143.3531 | M19: =207.84*K19 -> 224.4672 | N19: =$N$61/$K$59*K19 -> 68.124151 | O19: =$O$61/$K$59*K19 -> 133.92054 | P19: =$P$61/$K$59*K19 -> 107.05489 | Q19: 0 | R19: 0 | S19: =L19+M19+N19+O19 -> 2569.865 | T19: =IFERROR(S19/K19,0) -> 2379.5046
A20: 10005721 | B20: POTA FILETE C/M C/T FR 2-4 (AA) BL10 S20 | C20: 530420 | E20: 530420 | G20: 10005721 | H20: =IFERROR(INDEX([2]Resumen!$K$3:$K$63,MATCH(G20,[2]Resumen!$C$3:$C$63,0)),0)*(1+I20*J20)/1000-51.89/1000 -> 1.9845862 | I20: 0.67 | J20: -0.07 | K20: =IF(E20<0,0,E20)/1000 -> 530.42 | L20: =IFERROR(H20*K20,0)*1000 -> 1052664.2 | M20: =207.84*K20 -> 110242.49 | N20: =$N$61/$K$59*K20 -> 33457.789 | O20: =$O$61/$K$59*K20 -> 65772.344 | P20: =$P$61/$K$59*K20 -> 52577.83 | Q20: 0 | R20: 0 | S20: =L20+M20+N20+O20 -> 1262136.8 | T20: =IFERROR(S20/K20,0) -> 2379.5046
A21: 10005711 | B21: POTA FILETE C/M C/T FR 0.5-1.0 AA BL10 S20 | C21: 11340 | E21: 11340 | G21: 10005721 | H21: =IFERROR(INDEX([2]Resumen!$K$3:$K$63,MATCH(G21,[2]Resumen!$C$3:$C$63,0)),0)*(1+I21*J21)/1000-51.89/1000 -> 1.9845862 | I21: 0.67 | J21: -0.07 | K21: =IF(E21<0,0,E21)/1000 -> 11.34 | L21: =IFERROR(H21*K21,0)*1000 -> 22505.207 | M21: =207.84*K21 -> 2356.9056 | N21: =$N$61/$K$59*K21 -> 715.30358 | O21: =$O$61/$K$59*K21 -> 1406.1656 | P21: =$P$61/$K$59*K21 -> 1124.0764 | Q21: 0 | R21: 0 | S21: =L21+M21+N21+O21 -> 26983.582 | T21: =IFERROR(S21/K21,0) -> 2379.5046
A22: 10005718 | B22: POTA FILETE C/M C/T FR 1-2 AA BL10 S20 | C22: 90580 | D22: 96840 | E22: -6260 | G22: 10005721 | H22: =IFERROR(INDEX([2]Resumen!$K$3:$K$63,MATCH(G22,[2]Resumen!$C$3:$C$63,0)),0)*(1+I22*J22)/1000-51.89/1000 -> 1.9845862 | I22: 0.67 | J22: -0.07 | K22: =IF(E22<0,0,E22)/1000 -> 0 | L22: =IFERROR(H22*K22,0)*1000 -> 0 | M22: =207.84*K22 -> 0 | N22: =$N$61/$K$59*K22 -> 0 | O22: =$O$61/$K$59*K22 -> 0 | P22: =$P$61/$K$59*K22 -> 0 | Q22: 0 | R22: 0 | S22: =L22+M22+N22+O22 -> 0 | T22: =IFERROR(S22/K22,0) -> 0
A23: 10009971 | B23: POTA FILETE C/M C/T FR 0.5-1.0 AAA BL10 S20 | C23: 0 | E23: 0 | G23: 10005721 | H23: =IFERROR(INDEX([2]Resumen!$K$3:$K$63,MATCH(G23,[2]Resumen!$C$3:$C$63,0)),0)*(1+I23*J23)/1000-51.89/1000 -> 1.9845862 | I23: 0.67 | J23: -0.07 | K23: =IF(E23<0,0,E23)/1000 -> 0 | L23: =IFERROR(H23*K23,0)*1000 -> 0 | M23: =207.84*K23 -> 0 | N23: =$N$61/$K$59*K23 -> 0 | O23: =$O$61/$K$59*K23 -> 0 | P23: =$P$61/$K$59*K23 -> 0 | Q23: 0 | R23: 0 | S23: =L23+M23+N23+O23 -> 0 | T23: =IFERROR(S23/K23,0) -> 0
A24: 10009972 | B24: POTA FILETE C/M C/T FR 1-2 AAA BL10 S20 | C24: 20220 | D24: 20220 | E24: 0 | G24: 10005721 | H24: =IFERROR(INDEX([2]Resumen!$K$3:$K$63,MATCH(G24,[2]Resumen!$C$3:$C$63,0)),0)*(1+I24*J24)/1000-51.89/1000 -> 1.9845862 | I24: 0.67 | J24: -0.07 | K24: =IF(E24<0,0,E24)/1000 -> 0 | L24: =IFERROR(H24*K24,0)*1000 -> 0 | M24: =207.84*K24 -> 0 | N24: =$N$61/$K$59*K24 -> 0 | O24: =$O$61/$K$59*K24 -> 0 | P24: =$P$61/$K$59*K24 -> 0 | Q24: 0 | R24: 0 | S24: =L24+M24+N24+O24 -> 0 | T24: =IFERROR(S24/K24,0) -> 0
A25: 10010063 | B25: POTA FILETE C/M C/T FR 2-4 AAA BL10 S20 | C25: 0 | D25: 0 | E25: 0 | G25: 10005721 | H25: =IFERROR(INDEX([2]Resumen!$K$3:$K$63,MATCH(G25,[2]Resumen!$C$3:$C$63,0)),0)*(1+I25*J25)/1000-51.89/1000 -> 1.9845862 | I25: 0.67 | J25: -0.07 | K25: =IF(E25<0,0,E25)/1000 -> 0 | L25: =IFERROR(H25*K25,0)*1000 -> 0 | M25: =207.84*K25 -> 0 | N25: =$N$61/$K$59*K25 -> 0 | O25: =$O$61/$K$59*K25 -> 0 | P25: =$P$61/$K$59*K25 -> 0 | Q25: 0 | R25: 0 | S25: =L25+M25+N25+O25 -> 0 | T25: =IFERROR(S25/K25,0) -> 0
A26: 10009298 | B26: POTA FILETE SM ST 1-2 CM/ESP | C26: 3200 | E26: 3200 | G26: 10005721 | H26: =IFERROR(INDEX([2]Resumen!$K$3:$K$63,MATCH(G26,[2]Resumen!$C$3:$C$63,0)),0)*(1+I26*J26)/1000-51.89/1000 -> 1.9845862 | I26: 0.67 | J26: -0.07 | K26: =IF(E26<0,0,E26)/1000 -> 3.2 | L26: =IFERROR(H26*K26,0)*1000 -> 6350.6758 | M26: =207.84*K26 -> 665.088 | N26: =$N$61/$K$59*K26 -> 201.84934 | O26: =$O$61/$K$59*K26 -> 396.80159 | P26: =$P$61/$K$59*K26 -> 317.19968 | Q26: 0 | R26: 0 | S26: =L26+M26+N26+O26 -> 7614.4147 | T26: =IFERROR(S26/K26,0) -> 2379.5046
A27: 10009184 | B27: POTA NUCAS FR ABIERTAS 0.1 - 0.3 BL10 S2 | C27: 93080 | E27: 93080 | G27: 10005779 | H27: =IFERROR(INDEX([2]Resumen!$K$3:$K$63,MATCH(G27,[2]Resumen!$C$3:$C$63,0)),0)*(1+I27*J27)/1000-51.89/1000 -> 1.6220104 | I27: 0.65 | J27: -0.07 | K27: =IF(E27<0,0,E27)/1000 -> 93.08 | L27: =IFERROR(H27*K27,0)*1000 -> 150976.73 | M27: =207.84*K27 -> 19345.747 | N27: =$N$61/$K$59*K27 -> 5871.2925 | O27: =$O$61/$K$59*K27 -> 11541.966 | P27: =$P$61/$K$59*K27 -> 9226.5458 | Q27: 0 | R27: 0 | S27: =L27+M27+N27+O27 -> 187735.73 | T27: =IFERROR(S27/K27,0) -> 2016.9288
A28: 10009271 | B28: POTA NUCAS FR CERRADA 0.1 - 0.3 BL10 S2 | C28: 40100 | E28: 40100 | G28: 10005779 | H28: =IFERROR(INDEX([2]Resumen!$K$3:$K$63,MATCH(G28,[2]Resumen!$C$3:$C$63,0)),0)*(1+I28*J28)/1000-51.89/1000 -> 1.6220104 | I28: 0.65 | J28: -0.07 | K28: =IF(E28<0,0,E28)/1000 -> 40.1 | L28: =IFERROR(H28*K28,0)*1000 -> 65042.617 | M28: =207.84*K28 -> 8334.384 | N28: =$N$61/$K$59*K28 -> 2529.4245 | O28: =$O$61/$K$59*K28 -> 4972.42 | P28: =$P$61/$K$59*K28 -> 3974.9085 | Q28: 0 | R28: 0 | S28: =L28+M28+N28+O28 -> 80878.845 | T28: =IFERROR(S28/K28,0) -> 2016.9288
A29: 10009183 | B29: POTA NUCAS FR CERRADA <0.1 BL10 S2 | C29: 1040 | E29: 1040 | G29: 10005779 | H29: =IFERROR(INDEX([2]Resumen!$K$3:$K$63,MATCH(G29,[2]Resumen!$C$3:$C$63,0)),0)*(1+I29*J29)/1000-51.89/1000 -> 1.6220104 | I29: 0.65 | J29: -0.07 | K29: =IF(E29<0,0,E29)/1000 -> 1.04 | L29: =IFERROR(H29*K29,0)*1000 -> 1686.8908 | M29: =207.84*K29 -> 216.1536 | N29: =$N$61/$K$59*K29 -> 65.601034 | O29: =$O$61/$K$59*K29 -> 128.96052 | P29: =$P$61/$K$59*K29 -> 103.0899 | Q29: 0 | R29: 0 | S29: =L29+M29+N29+O29 -> 2097.606 | T29: =IFERROR(S29/K29,0) -> 2016.9288
A30: 10005779 | B30: POTA NUCAS FR ABIERTAS 0.5-1 BL10 S20 | C30: 53520 | D30: 24000 | E30: 29520 | G30: 10005779 | H30: =IFERROR(INDEX([2]Resumen!$K$3:$K$63,MATCH(G30,[2]Resumen!$C$3:$C$63,0)),0)*(1+I30*J30)/1000-51.89/1000 -> 1.6220104 | I30: 0.65 | J30: -0.07 | K30: =IF(E30<0,0,E30)/1000 -> 29.52 | L30: =IFERROR(H30*K30,0)*1000 -> 47881.747 | M30: =207.84*K30 -> 6135.4368 | N30: =$N$61/$K$59*K30 -> 1862.0601 | O30: =$O$61/$K$59*K30 -> 3660.4947 | P30: =$P$61/$K$59*K30 -> 2926.1671 | Q30: 0 | R30: 0 | S30: =L30+M30+N30+O30 -> 59539.738 | T30: =IFERROR(S30/K30,0) -> 2016.9288
A31: 10005776 | B31: POTA NUCAS FR ABIERTAS 0.3-0.5 BL10 S20 | C31: 130180 | D31: 58000 | E31: 72180 | G31: 10005779 | H31: =IFERROR(INDEX([2]Resumen!$K$3:$K$63,MATCH(G31,[2]Resumen!$C$3:$C$63,0)),0)*(1+I31*J31)/1000-51.89/1000 -> 1.6220104 | I31: 0.65 | J31: -0.07 | K31: =IF(E31<0,0,E31)/1000 -> 72.18 | L31: =IFERROR(H31*K31,0)*1000 -> 117076.71 | M31: =207.84*K31 -> 15001.891 | N31: =$N$61/$K$59*K31 -> 4552.9641 | O31: =$O$61/$K$59*K31 -> 8950.3559 | P31: =$P$61/$K$59*K31 -> 7154.8354 | Q31: 0 | R31: 0 | S31: =L31+M31+N31+O31 -> 145581.92 | T31: =IFERROR(S31/K31,0) -> 2016.9288
A32: 10005781 | B32: POTA NUCAS FR ABIERTAS 1-2 BL10 S20 | C32: 4400 | D32: 104000 | E32: -99600 | G32: 10005779 | H32: =IFERROR(INDEX([2]Resumen!$K$3:$K$63,MATCH(G32,[2]Resumen!$C$3:$C$63,0)),0)*(1+I32*J32)/1000-51.89/1000 -> 1.6220104 | I32: 0.65 | J32: -0.07 | K32: =IF(E32<0,0,E32)/1000 -> 0 | L32: =IFERROR(H32*K32,0)*1000 -> 0 | M32: =207.84*K32 -> 0 | N32: =$N$61/$K$59*K32 -> 0 | O32: =$O$61/$K$59*K32 -> 0 | P32: =$P$61/$K$59*K32 -> 0 | Q32: 0 | R32: 0 | S32: =L32+M32+N32+O32 -> 0 | T32: =IFERROR(S32/K32,0) -> 0
A33: 10007567 | B33: POTA REJOS OR FR LIMPIOS S/COD BL10 S20 | C33: 81600 | D33: 53000 | E33: 28600 | G33: 10007567 | H33: =IFERROR(INDEX([2]Resumen!$K$3:$K$63,MATCH(G33,[2]Resumen!$C$3:$C$63,0)),0)*(1+I33*J33)/1000-51.89/1000 -> 1.6826592 | I33: 0.68 | J33: -0.07 | K33: =IF(E33<0,0,E33)/1000 -> 28.6 | L33: =IFERROR(H33*K33,0)*1000 -> 48124.053 | M33: =207.84*K33 -> 5944.224 | N33: =$N$61/$K$59*K33 -> 1804.0284 | O33: =$O$61/$K$59*K33 -> 3546.4142 | P33: =$P$61/$K$59*K33 -> 2834.9722 | Q33: 0 | R33: 0 | S33: =L33+M33+N33+O33 -> 59418.72 | T33: =IFERROR(S33/K33,0) -> 2077.5776
A34: 10009975 | B34: POTA REJOS OR FR LIMPIOS <60 cm BL10 S20 | C34: 32860 | E34: 32860 | G34: 10007567 | H34: =IFERROR(INDEX([2]Resumen!$K$3:$K$63,MATCH(G34,[2]Resumen!$C$3:$C$63,0)),0)*(1+I34*J34)/1000-51.89/1000 -> 1.6826592 | I34: 0.68 | J34: -0.07 | K34: =IF(E34<0,0,E34)/1000 -> 32.86 | L34: =IFERROR(H34*K34,0)*1000 -> 55292.182 | M34: =207.84*K34 -> 6829.6224 | N34: =$N$61/$K$59*K34 -> 2072.7404 | O34: =$O$61/$K$59*K34 -> 4074.6564 | P34: =$P$61/$K$59*K34 -> 3257.2443 | Q34: 0 | R34: 0 | S34: =L34+M34+N34+O34 -> 68269.201 | T34: =IFERROR(S34/K34,0) -> 2077.5776
A35: 10009185 | B35: POTA REJOS FR C/U C/V S/OR <0.1 BL10 | C35: 0 | E35: 0 | G35: 10007162 | H35: =IFERROR(INDEX([2]Resumen!$K$3:$K$63,MATCH(G35,[2]Resumen!$C$3:$C$63,0)),0)*(1+I35*J35)/1000-51.89/1000 -> 1.7406978 | I35: 0.68 | J35: -0.07 | K35: =IF(E35<0,0,E35)/1000 -> 0 | L35: =IFERROR(H35*K35,0)*1000 -> 0 | M35: =207.84*K35 -> 0 | N35: =$N$61/$K$59*K35 -> 0 | O35: =$O$61/$K$59*K35 -> 0 | P35: =$P$61/$K$59*K35 -> 0 | Q35: 0 | R35: 0 | S35: =L35+M35+N35+O35 -> 0 | T35: =IFERROR(S35/K35,0) -> 0
A36: 10009186 | B36: POTA REJOS FR C/U C/V S/OR 0.1-0.3 BL10 | C36: 1220 | E36: 1220 | G36: 10007162 | H36: =IFERROR(INDEX([2]Resumen!$K$3:$K$63,MATCH(G36,[2]Resumen!$C$3:$C$63,0)),0)*(1+I36*J36)/1000-51.89/1000 -> 1.7406978 | I36: 0.68 | J36: -0.07 | K36: =IF(E36<0,0,E36)/1000 -> 1.22 | L36: =IFERROR(H36*K36,0)*1000 -> 2123.6513 | M36: =207.84*K36 -> 253.5648 | N36: =$N$61/$K$59*K36 -> 76.955059 | O36: =$O$61/$K$59*K36 -> 151.28061 | P36: =$P$61/$K$59*K36 -> 120.93238 | Q36: 0 | R36: 0 | S36: =L36+M36+N36+O36 -> 2605.4517 | T36: =IFERROR(S36/K36,0) -> 2135.6162
A37: 10009777 | B37: POTA REJOS FR C/U C/V S/OR 0.3-0.5BL10 | C37: 13240 | D37: 54000 | E37: -40760 | G37: 10007162 | H37: =IFERROR(INDEX([2]Resumen!$K$3:$K$63,MATCH(G37,[2]Resumen!$C$3:$C$63,0)),0)*(1+I37*J37)/1000-51.89/1000 -> 1.7406978 | I37: 0.68 | J37: -0.07 | K37: =IF(E37<0,0,E37)/1000 -> 0 | L37: =IFERROR(H37*K37,0)*1000 -> 0 | M37: =207.84*K37 -> 0 | N37: =$N$61/$K$59*K37 -> 0 | O37: =$O$61/$K$59*K37 -> 0 | P37: =$P$61/$K$59*K37 -> 0 | Q37: 0 | R37: 0 | S37: =L37+M37+N37+O37 -> 0 | T37: =IFERROR(S37/K37,0) -> 0
A38: 10009989 | B38: POTA REJOS FR C/U C/V S/OR 0.5-1.0 BL10 | C38: 123740 | E38: 123740 | G38: 10007162 | H38: =IFERROR(INDEX([2]Resumen!$K$3:$K$63,MATCH(G38,[2]Resumen!$C$3:$C$63,0)),0)*(1+I38*J38)/1000-51.89/1000 -> 1.7406978 | I38: 0.68 | J38: -0.07 | K38: =IF(E38<0,0,E38)/1000 -> 123.74 | L38: =IFERROR(H38*K38,0)*1000 -> 215393.94 | M38: =207.84*K38 -> 25718.122 | N38: =$N$61/$K$59*K38 -> 7805.2615 | O38: =$O$61/$K$59*K38 -> 15343.822 | P38: =$P$61/$K$59*K38 -> 12265.715 | Q38: 0 | R38: 0 | S38: =L38+M38+N38+O38 -> 264261.15 | T38: =IFERROR(S38/K38,0) -> 2135.6162
