Workbook

Sheet RESUMEN AL 20-7-2026
C2: PERU FROST
C3: AVANCE COMERCIAL AL 20-7-2026
F5: RENTABILIDAD DEL INVENTARIO | X5: 46206 | AA5: 46209 | AD5: 46215 | AG5: 46216 | AJ5: 46222 | AM5: 46224 | AP5: 46225 | AS5: 46229 | AV5: 46232 | AY5: TBN | BT5: TOTAL PROYECTADO JULIO 2026 | CH5: UNITARIOS POR TM
B6: Código | C6: Producto | D6: TM en Stock Libre | E6: CU | F6: Costo Ventas | G6: Gasto Ventas | H6: Gasto ADM | I6: Gasto Fin | J6: Depreciación | K6: Utilidad Neta | L6: Margen Neto | M6: Venta Equilibrio a Utd Neta | N6: Precio Equilibrio x TM a Utd Neta | O6: Venta Equilibro a EBITDA | P6: Precio Equilibrio x TM a EBITDA | Q6: Precio Mercado | R6: Venta total | S6: Utilidad | T6: Mg Neto | U6: EBITDA | V6: Mg EBITDA | X6: TM | Y6: Venta | Z6: Precio x TM | AA6: TM | AB6: Venta | AC6: Precio x TM | AD6: TM | AE6: Venta | AF6: Precio x TM | AG6: TM | AH6: Venta | AI6: Precio x TM | AJ6: TM | AK6: Venta | AL6: Precio x TM | AM6: TM | AN6: Venta | AO6: Precio x TM | AP6: TM | AQ6: Venta | AR6: Precio x TM | AS6: TM | AT6: Venta | AU6: Precio x TM | AV6: TM | AW6: Venta | AX6: Precio x TM | AY6: TM | AZ6: Venta | BA6: Precio x TM | BB6: TM | BC6: Venta | BD6: Precio x TM | BE6: TM | BF6: Venta | BG6: Precio x TM | BH6: TM | BI6: Venta | BJ6: Precio x TM | BK6: TM | BL6: Venta | BM6: Precio x TM | BN6: TM | BO6: Venta | BP6: Precio x TM | BQ6: TM | BR6: Venta | BS6: Precio x TM | BT6: TM | BU6: Venta | BV6: Precio x TM | BW6: Costo Ventas | BX6: Gasto Ventas | BY6: Gasto Adm | BZ6: Gasto Fin | CA6: Depreciación | CB6: Drawback | CC6: Utilidad Neta | CD6: Mg Neto % | CE6: EBITDA | CF6: MG EBITDA | CH6: Precio x TM | CI6: Costo Ventas | CJ6: Gasto Ventas | CK6: Gasto Adm | CL6: Gasto Fin | CM6: Depreciación | CN6: Drawback | CO6: Utilidad Neta | CP6: EBITDA
B7: 10005721 | C7: POTA FILETE CONGELADO | D7: =TD!F4 -> 462.666 | E7: =IFERROR(F7/D7,0) -> 1937.5523 | F7: =TD!G4 -> 896439.56 | G7: =TD!H4 -> 96160.501 | H7: =TD!I4 -> 20871.593 | I7: =TD!J4 -> 41030.016 | J7: =TD!K4 -> 32799.032 | K7: 0 | L7: 0 | M7: =F7+G7+H7+I7 -> 1054501.7 | N7: =IFERROR(M7/D7,0) -> 2279.1856 | O7: =F7+G7+H7-J7 -> 980672.62 | P7: =IFERROR(O7/D7,0) -> 2119.6125 | Q7: 1400 | R7: =Q7*D7 -> 647732.4 | S7: =R7-M7+(Q7-$BY$19)*D7*0.03 -> -388922.08 | T7: =IFERROR(S7/R7,0) -> -0.60043635 | U7: =R7-(M7-J7-I7)+(Q7-$BY$19)*D7*0.03 -> -315093.03 | V7: =IFERROR(U7/R7,0) -> -0.48645557 | X7: {=SUM([5]Hoja3!$I$6:$I$25*([5]Hoja3!$F$6:$F$25=X$5)*([5]Hoja3!$K$6:$K$25=$C7))} -> 0 | Y7: {=SUM([5]Hoja3!$J$6:$J$25*([5]Hoja3!$F$6:$F$25=X$5)*([5]Hoja3!$K$6:$K$25=$C7))} -> 0 | Z7: =IFERROR(Y7/X7,0) -> 0 | AA7: {=SUM([5]Hoja3!$I$6:$I$25*([5]Hoja3!$F$6:$F$25=AA$5)*([5]Hoja3!$K$6:$K$25=$C7))} -> 0 | AB7: {=SUM([5]Hoja3!$J$6:$J$25*([5]Hoja3!$F$6:$F$25=AA$5)*([5]Hoja3!$K$6:$K$25=$C7))} -> 0 | AC7: =IFERROR(AB7/AA7,0) -> 0 | AD7: {=SUM([5]Hoja3!$I$6:$I$25*([5]Hoja3!$F$6:$F$25=AD$5)*([5]Hoja3!$K$6:$K$25=$C7))} -> 0 | AE7: {=SUM([5]Hoja3!$J$6:$J$25*([5]Hoja3!$F$6:$F$25=AD$5)*([5]Hoja3!$K$6:$K$25=$C7))} -> 0 | AF7: =IFERROR(AE7/AD7,0) -> 0 | AG7: {=SUM([5]Hoja3!$I$6:$I$25*([5]Hoja3!$F$6:$F$25=AG$5)*([5]Hoja3!$K$6:$K$25=$C7))} -> 0 | AH7: {=SUM([5]Hoja3!$J$6:$J$25*([5]Hoja3!$F$6:$F$25=AG$5)*([5]Hoja3!$K$6:$K$25=$C7))} -> 0 | AI7: =IFERROR(AH7/AG7,0) -> 0 | AJ7: {=SUM([5]Hoja3!$I$6:$I$25*([5]Hoja3!$F$6:$F$25=AJ$5)*([5]Hoja3!$K$6:$K$25=$C7))} -> 0 | AK7: {=SUM([5]Hoja3!$J$6:$J$25*([5]Hoja3!$F$6:$F$25=AJ$5)*([5]Hoja3!$K$6:$K$25=$C7))} -> 0 | AL7: =IFERROR(AK7/AJ7,0) -> 0 | AM7: {=SUM([5]Hoja3!$I$6:$I$25*([5]Hoja3!$F$6:$F$25=AM$5)*([5]Hoja3!$K$6:$K$25=$C7))} -> 24 | AN7: {=SUM([5]Hoja3!$J$6:$J$25*([5]Hoja3!$F$6:$F$25=AM$5)*([5]Hoja3!$K$6:$K$25=$C7))} -> 48000 | AO7: =IFERROR(AN7/AM7,0) -> 2000 | AP7: {=SUM([5]Hoja3!$I$6:$I$25*([5]Hoja3!$F$6:$F$25=AP$5)*([5]Hoja3!$K$6:$K$25=$C7))} -> 0 | AQ7: {=SUM([5]Hoja3!$J$6:$J$25*([5]Hoja3!$F$6:$F$25=AP$5)*([5]Hoja3!$K$6:$K$25=$C7))} -> 0 | AR7: =IFERROR(AQ7/AP7,0) -> 0 | AS7: {=SUM([5]Hoja3!$I$6:$I$25*([5]Hoja3!$F$6:$F$25=AS$5)*([5]Hoja3!$K$6:$K$25=$C7))} -> 0 | AT7: {=SUM([5]Hoja3!$J$6:$J$25*([5]Hoja3!$F$6:$F$25=AS$5)*([5]Hoja3!$K$6:$K$25=$C7))} -> 0 | AU7: =IFERROR(AT7/AS7,0) -> 0 | AV7: {=SUM([5]Hoja3!$I$6:$I$25*([5]Hoja3!$F$6:$F$25=AV$5)*([5]Hoja3!$K$6:$K$25=$C7))} -> 0 | AW7: {=SUM([5]Hoja3!$J$6:$J$25*([5]Hoja3!$F$6:$F$25=AV$5)*([5]Hoja3!$K$6:$K$25=$C7))} -> 0 | AX7: =IFERROR(AW7/AV7,0) -> 0 | AY7: {=SUM([5]Hoja3!$I$6:$I$25*([5]Hoja3!$F$6:$F$25=AY$5)*([5]Hoja3!$K$6:$K$25=$C7))} -> 0 | AZ7: {=SUM([5]Hoja3!$J$6:$J$25*([5]Hoja3!$F$6:$F$25=AY$5)*([5]Hoja3!$K$6:$K$25=$C7))} -> 0 | BA7: =IFERROR(AZ7/AY7,0) -> 0 | BB7: {=SUM([2]Hoja2!$I$6:$I$26*([2]Hoja2!$F$6:$F$26=BB$5)*([2]Hoja2!$K$6:$K$26=$C7))} -> 0 | BC7: {=SUM([2]Hoja2!$J$6:$J$26*([2]Hoja2!$F$6:$F$26=BB$5)*([2]Hoja2!$K$6:$K$26=$C7))} -> 0 | BD7: =IFERROR(BC7/BB7,0) -> 0 | BE7: {=SUM([2]Hoja2!$I$6:$I$26*([2]Hoja2!$F$6:$F$26=BE$5)*([2]Hoja2!$K$6:$K$26=$C7))} -> 0 | BF7: {=SUM([2]Hoja2!$J$6:$J$26*([2]Hoja2!$F$6:$F$26=BE$5)*([2]Hoja2!$K$6:$K$26=$C7))} -> 0 | BG7: =IFERROR(BF7/BE7,0) -> 0 | BH7: {=SUM([2]Hoja2!$I$6:$I$26*([2]Hoja2!$F$6:$F$26=BH$5)*([2]Hoja2!$K$6:$K$26=$C7))} -> 0 | BI7: {=SUM([2]Hoja2!$J$6:$J$26*([2]Hoja2!$F$6:$F$26=BH$5)*([2]Hoja2!$K$6:$K$26=$C7))} -> 0 | BJ7: =IFERROR(BI7/BH7,0) -> 0 | BK7: {=SUM([2]Hoja2!$I$6:$I$26*([2]Hoja2!$F$6:$F$26=BK$5)*([2]Hoja2!$K$6:$K$26=$C7))} -> 0 | BL7: {=SUM([2]Hoja2!$J$6:$J$26*([2]Hoja2!$F$6:$F$26=BK$5)*([2]Hoja2!$K$6:$K$26=$C7))} -> 0 | BM7: =IFERROR(BL7/BK7,0) -> 0 | BN7: {=SUM([2]Hoja2!$I$6:$I$26*([2]Hoja2!$F$6:$F$26=BN$5)*([2]Hoja2!$K$6:$K$26=$C7))} -> 0 | BO7: {=SUM([2]Hoja2!$J$6:$J$26*([2]Hoja2!$F$6:$F$26=BN$5)*([2]Hoja2!$K$6:$K$26=$C7))} -> 0 | BP7: =IFERROR(BO7/BN7,0) -> 0 | BQ7: {=SUM([2]Hoja2!$I$6:$I$26*([2]Hoja2!$F$6:$F$26=BQ$5)*([2]Hoja2!$K$6:$K$26=$C7))} -> 0 | BR7: {=SUM([2]Hoja2!$J$6:$J$26*([2]Hoja2!$F$6:$F$26=BQ$5)*([2]Hoja2!$K$6:$K$26=$C7))} -> 0 | BS7: =IFERROR(BR7/BQ7,0) -> 0 | BT7: =X7+AA7+AD7+AG7+AJ7+AM7+AP7+AY7+AS7+AV7 -> 24 | BU7: =Y7+AB7+AE7+AH7+AK7+AN7+AQ7+AZ7+AT7+AW7 -> 48000 | BV7: =IFERROR(BU7/BT7,0) -> 2000 | BW7: =-IFERROR(F7/D7*BT7,0) -> -46501.254 | BX7: =-207.84*BT7 -> -4988.16 | BY7: =$BY$18/$BT$18*$BT7 -> -2143.0636 | BZ7: =$BZ$18/$BT$18*$BT7 -> -4212.9 | CA7: =$CA$18/$BT$18*$BT7 -> -3367.755 | CB7: =(BU7-BT7*$BY$19)*0.03 -> 1357.7921 | CC7: =BU7+SUM(BW7:BZ7,CB7) -> -8487.586 | CD7: =IFERROR(CC7/BU7,0) -> -0.17682471 | CE7: =BU7+BW7+BX7+BY7+CB7-CA7 -> -906.93099 | CF7: =IFERROR(CE7/BU7,0) -> -0.018894396 | CH7: =BV7 -> 2000 | CI7: =IFERROR(BW7/$BT7,0) -> -1937.5523 | CJ7: =IFERROR(BX7/$BT7,0) -> -207.84 | CK7: =IFERROR(BY7/$BT7,0) -> -89.294318 | CL7: =IFERROR(BZ7/$BT7,0) -> -175.5375 | CM7: =IFERROR(CA7/$BT7,0) -> -140.32313 | CN7: =IFERROR(CB7/$BT7,0) -> 56.574672 | CO7: =IFERROR(CC7/$BT7,0) -> -353.64942 | CP7: =IFERROR(CE7/$BT7,0) -> -37.788791 | CQ7: =CP7-CO7 -> 315.86063
B8: 10005779 | C8: POTA NUCAS CONGELADAS | D8: =TD!F5 -> 380.02 | E8: =IFERROR(F8/D8,0) -> 1584.5595 | F8: =TD!G5 -> 602164.3 | G8: =TD!H5 -> 78983.357 | H8: =TD!I5 -> 17143.302 | I8: =TD!J5 -> 33700.827 | J8: =TD!K5 -> 26940.143 | K8: 0 | L8: 0 | M8: =F8+G8+H8+I8 -> 731991.78 | N8: =IFERROR(M8/D8,0) -> 1926.1928 | O8: =F8+G8+H8-J8 -> 671350.81 | P8: =IFERROR(O8/D8,0) -> 1766.6197 | Q8: 1350 | R8: =Q8*D8 -> 513027 | S8: =R8-M8+(Q8-$BY$19)*D8*0.03 -> -204875.66 | T8: =IFERROR(S8/R8,0) -> -0.39934675 | U8: =R8-(M8-J8-I8)+(Q8-$BY$19)*D8*0.03 -> -144234.69 | V8: =IFERROR(U8/R8,0) -> -0.28114445 | X8: {=SUM([5]Hoja3!$I$6:$I$25*([5]Hoja3!$F$6:$F$25=X$5)*([5]Hoja3!$K$6:$K$25=$C8))} -> 0 | Y8: {=SUM([5]Hoja3!$J$6:$J$25*([5]Hoja3!$F$6:$F$25=X$5)*([5]Hoja3!$K$6:$K$25=$C8))} -> 0 | Z8: =IFERROR(Y8/X8,0) -> 0 | AA8: {=SUM([5]Hoja3!$I$6:$I$25*([5]Hoja3!$F$6:$F$25=AA$5)*([5]Hoja3!$K$6:$K$25=$C8))} -> 0 | AB8: {=SUM([5]Hoja3!$J$6:$J$25*([5]Hoja3!$F$6:$F$25=AA$5)*([5]Hoja3!$K$6:$K$25=$C8))} -> 0 | AC8: =IFERROR(AB8/AA8,0) -> 0 | AD8: {=SUM([5]Hoja3!$I$6:$I$25*([5]Hoja3!$F$6:$F$25=AD$5)*([5]Hoja3!$K$6:$K$25=$C8))} -> 0 | AE8: {=SUM([5]Hoja3!$J$6:$J$25*([5]Hoja3!$F$6:$F$25=AD$5)*([5]Hoja3!$K$6:$K$25=$C8))} -> 0 | AF8: =IFERROR(AE8/AD8,0) -> 0 | AG8: {=SUM([5]Hoja3!$I$6:$I$25*([5]Hoja3!$F$6:$F$25=AG$5)*([5]Hoja3!$K$6:$K$25=$C8))} -> 0 | AH8: {=SUM([5]Hoja3!$J$6:$J$25*([5]Hoja3!$F$6:$F$25=AG$5)*([5]Hoja3!$K$6:$K$25=$C8))} -> 0 | AI8: =IFERROR(AH8/AG8,0) -> 0 | AJ8: {=SUM([5]Hoja3!$I$6:$I$25*([5]Hoja3!$F$6:$F$25=AJ$5)*([5]Hoja3!$K$6:$K$25=$C8))} -> 78 | AK8: {=SUM([5]Hoja3!$J$6:$J$25*([5]Hoja3!$F$6:$F$25=AJ$5)*([5]Hoja3!$K$6:$K$25=$C8))} -> 103740 | AL8: =IFERROR(AK8/AJ8,0) -> 1330 | AM8: {=SUM([5]Hoja3!$I$6:$I$25*([5]Hoja3!$F$6:$F$25=AM$5)*([5]Hoja3!$K$6:$K$25=$C8))} -> 0 | AN8: {=SUM([5]Hoja3!$J$6:$J$25*([5]Hoja3!$F$6:$F$25=AM$5)*([5]Hoja3!$K$6:$K$25=$C8))} -> 0 | AO8: =IFERROR(AN8/AM8,0) -> 0 | AP8: {=SUM([5]Hoja3!$I$6:$I$25*([5]Hoja3!$F$6:$F$25=AP$5)*([5]Hoja3!$K$6:$K$25=$C8))} -> 52 | AQ8: {=SUM([5]Hoja3!$J$6:$J$25*([5]Hoja3!$F$6:$F$25=AP$5)*([5]Hoja3!$K$6:$K$25=$C8))} -> 67600 | AR8: =IFERROR(AQ8/AP8,0) -> 1300 | AS8: {=SUM([5]Hoja3!$I$6:$I$25*([5]Hoja3!$F$6:$F$25=AS$5)*([5]Hoja3!$K$6:$K$25=$C8))} -> 0 | AT8: {=SUM([5]Hoja3!$J$6:$J$25*([5]Hoja3!$F$6:$F$25=AS$5)*([5]Hoja3!$K$6:$K$25=$C8))} -> 0 | AU8: =IFERROR(AT8/AS8,0) -> 0 | AV8: {=SUM([5]Hoja3!$I$6:$I$25*([5]Hoja3!$F$6:$F$25=AV$5)*([5]Hoja3!$K$6:$K$25=$C8))} -> 26 | AW8: {=SUM([5]Hoja3!$J$6:$J$25*([5]Hoja3!$F$6:$F$25=AV$5)*([5]Hoja3!$K$6:$K$25=$C8))} -> 34580 | AX8: =IFERROR(AW8/AV8,0) -> 1330 | AY8: {=SUM([5]Hoja3!$I$6:$I$25*([5]Hoja3!$F$6:$F$25=AY$5)*([5]Hoja3!$K$6:$K$25=$C8))} -> 0 | AZ8: {=SUM([5]Hoja3!$J$6:$J$25*([5]Hoja3!$F$6:$F$25=AY$5)*([5]Hoja3!$K$6:$K$25=$C8))} -> 0 | BA8: =IFERROR(AZ8/AY8,0) -> 0 | BB8: {=SUM([2]Hoja2!$I$6:$I$26*([2]Hoja2!$F$6:$F$26=BB$5)*([2]Hoja2!$K$6:$K$26=$C8))} -> 0 | BC8: {=SUM([2]Hoja2!$J$6:$J$26*([2]Hoja2!$F$6:$F$26=BB$5)*([2]Hoja2!$K$6:$K$26=$C8))} -> 0 | BD8: =IFERROR(BC8/BB8,0) -> 0 | BE8: {=SUM([2]Hoja2!$I$6:$I$26*([2]Hoja2!$F$6:$F$26=BE$5)*([2]Hoja2!$K$6:$K$26=$C8))} -> 0 | BF8: {=SUM([2]Hoja2!$J$6:$J$26*([2]Hoja2!$F$6:$F$26=BE$5)*([2]Hoja2!$K$6:$K$26=$C8))} -> 0 | BG8: =IFERROR(BF8/BE8,0) -> 0 | BH8: {=SUM([2]Hoja2!$I$6:$I$26*([2]Hoja2!$F$6:$F$26=BH$5)*([2]Hoja2!$K$6:$K$26=$C8))} -> 0 | BI8: {=SUM([2]Hoja2!$J$6:$J$26*([2]Hoja2!$F$6:$F$26=BH$5)*([2]Hoja2!$K$6:$K$26=$C8))} -> 0 | BJ8: =IFERROR(BI8/BH8,0) -> 0 | BK8: {=SUM([2]Hoja2!$I$6:$I$26*([2]Hoja2!$F$6:$F$26=BK$5)*([2]Hoja2!$K$6:$K$26=$C8))} -> 0 | BL8: {=SUM([2]Hoja2!$J$6:$J$26*([2]Hoja2!$F$6:$F$26=BK$5)*([2]Hoja2!$K$6:$K$26=$C8))} -> 0 | BM8: =IFERROR(BL8/BK8,0) -> 0 | BN8: {=SUM([2]Hoja2!$I$6:$I$26*([2]Hoja2!$F$6:$F$26=BN$5)*([2]Hoja2!$K$6:$K$26=$C8))} -> 0 | BO8: {=SUM([2]Hoja2!$J$6:$J$26*([2]Hoja2!$F$6:$F$26=BN$5)*([2]Hoja2!$K$6:$K$26=$C8))} -> 0 | BP8: =IFERROR(BO8/BN8,0) -> 0 | BQ8: {=SUM([2]Hoja2!$I$6:$I$26*([2]Hoja2!$F$6:$F$26=BQ$5)*([2]Hoja2!$K$6:$K$26=$C8))} -> 0 | BR8: {=SUM([2]Hoja2!$J$6:$J$26*([2]Hoja2!$F$6:$F$26=BQ$5)*([2]Hoja2!$K$6:$K$26=$C8))} -> 0 | BS8: =IFERROR(BR8/BQ8,0) -> 0 | BT8: =X8+AA8+AD8+AG8+AJ8+AM8+AP8+AY8+AS8+AV8 -> 156 | BU8: =Y8+AB8+AE8+AH8+AK8+AN8+AQ8+AZ8+AT8+AW8 -> 205920 | BV8: =IFERROR(BU8/BT8,0) -> 1320 | BW8: =-IFERROR(F8/D8*BT8,0) -> -247191.28 | BX8: =-207.84*BT8 -> -32423.04 | BY8: =$BY$18/$BT$18*$BT8 -> -13929.914 | BZ8: =$BZ$18/$BT$18*$BT8 -> -27383.85 | CA8: =$CA$18/$BT$18*$BT8 -> -21890.408 | CB8: =(BU8-BT8*$BY$19)*0.03 -> 5643.2488 | CC8: =BU8+SUM(BW8:BZ8,CB8) -> -109364.83 | CD8: =IFERROR(CC8/BU8,0) -> -0.53110351 | CE8: =BU8+BW8+BX8+BY8+CB8-CA8 -> -60090.577 | CF8: =IFERROR(CE8/BU8,0) -> -0.29181516 | CH8: =BV8 -> 1320 | CI8: =IFERROR(BW8/$BT8,0) -> -1584.5595 | CJ8: =IFERROR(BX8/$BT8,0) -> -207.84 | CK8: =IFERROR(BY8/$BT8,0) -> -89.294318 | CL8: =IFERROR(BZ8/$BT8,0) -> -175.5375 | CM8: =IFERROR(CA8/$BT8,0) -> -140.32313 | CN8: =IFERROR(CB8/$BT8,0) -> 36.174672 | CO8: =IFERROR(CC8/$BT8,0) -> -701.05663 | CP8: =IFERROR(CE8/$BT8,0) -> -385.19601 | CQ8: =CP8-CO8 -> 315.86062
B9: 10006719 | C9: POTA ALAS CONGELADAS | D9: =TD!F6 -> 539.694 | E9: =IFERROR(F9/D9,0) -> 1835.1853 | F9: =TD!G6 -> 990438.47 | G9: =TD!H6 -> 112170 | H9: =TD!I6 -> 24346.448 | I9: =TD!J6 -> 47860.991 | J9: =TD!K6 -> 38259.653 | K9: 0 | L9: 0 | M9: =F9+G9+H9+I9 -> 1174815.9 | N9: =IFERROR(M9/D9,0) -> 2176.8186 | O9: =F9+G9+H9-J9 -> 1088695.3 | P9: =IFERROR(O9/D9,0) -> 2017.2455 | Q9: 1500 | R9: =Q9*D9 -> 809541 | S9: =R9-M9+(Q9-$BY$19)*D9*0.03 -> -342837.31 | T9: =IFERROR(S9/R9,0) -> -0.42349592 | U9: =R9-(M9-J9-I9)+(Q9-$BY$19)*D9*0.03 -> -256716.67 | V9: =IFERROR(U9/R9,0) -> -0.31711385 | X9: {=SUM([5]Hoja3!$I$6:$I$25*([5]Hoja3!$F$6:$F$25=X$5)*([5]Hoja3!$K$6:$K$25=$C9))} -> 0 | Y9: {=SUM([5]Hoja3!$J$6:$J$25*([5]Hoja3!$F$6:$F$25=X$5)*([5]Hoja3!$K$6:$K$25=$C9))} -> 0 | Z9: =IFERROR(Y9/X9,0) -> 0 | AA9: {=SUM([5]Hoja3!$I$6:$I$25*([5]Hoja3!$F$6:$F$25=AA$5)*([5]Hoja3!$K$6:$K$25=$C9))} -> 0 | AB9: {=SUM([5]Hoja3!$J$6:$J$25*([5]Hoja3!$F$6:$F$25=AA$5)*([5]Hoja3!$K$6:$K$25=$C9))} -> 0 | AC9: =IFERROR(AB9/AA9,0) -> 0 | AD9: {=SUM([5]Hoja3!$I$6:$I$25*([5]Hoja3!$F$6:$F$25=AD$5)*([5]Hoja3!$K$6:$K$25=$C9))} -> 54 | AE9: {=SUM([5]Hoja3!$J$6:$J$25*([5]Hoja3!$F$6:$F$25=AD$5)*([5]Hoja3!$K$6:$K$25=$C9))} -> 94500 | AF9: =IFERROR(AE9/AD9,0) -> 1750 | AG9: {=SUM([5]Hoja3!$I$6:$I$25*([5]Hoja3!$F$6:$F$25=AG$5)*([5]Hoja3!$K$6:$K$25=$C9))} -> 0 | AH9: {=SUM([5]Hoja3!$J$6:$J$25*([5]Hoja3!$F$6:$F$25=AG$5)*([5]Hoja3!$K$6:$K$25=$C9))} -> 0 | AI9: =IFERROR(AH9/AG9,0) -> 0 | AJ9: {=SUM([5]Hoja3!$I$6:$I$25*([5]Hoja3!$F$6:$F$25=AJ$5)*([5]Hoja3!$K$6:$K$25=$C9))} -> 0 | AK9: {=SUM([5]Hoja3!$J$6:$J$25*([5]Hoja3!$F$6:$F$25=AJ$5)*([5]Hoja3!$K$6:$K$25=$C9))} -> 0 | AL9: =IFERROR(AK9/AJ9,0) -> 0 | AM9: {=SUM([5]Hoja3!$I$6:$I$25*([5]Hoja3!$F$6:$F$25=AM$5)*([5]Hoja3!$K$6:$K$25=$C9))} -> 0 | AN9: {=SUM([5]Hoja3!$J$6:$J$25*([5]Hoja3!$F$6:$F$25=AM$5)*([5]Hoja3!$K$6:$K$25=$C9))} -> 0 | AO9: =IFERROR(AN9/AM9,0) -> 0 | AP9: {=SUM([5]Hoja3!$I$6:$I$25*([5]Hoja3!$F$6:$F$25=AP$5)*([5]Hoja3!$K$6:$K$25=$C9))} -> 0 | AQ9: {=SUM([5]Hoja3!$J$6:$J$25*([5]Hoja3!$F$6:$F$25=AP$5)*([5]Hoja3!$K$6:$K$25=$C9))} -> 0 | AR9: =IFERROR(AQ9/AP9,0) -> 0 | AS9: {=SUM([5]Hoja3!$I$6:$I$25*([5]Hoja3!$F$6:$F$25=AS$5)*([5]Hoja3!$K$6:$K$25=$C9))} -> 0 | AT9: {=SUM([5]Hoja3!$J$6:$J$25*([5]Hoja3!$F$6:$F$25=AS$5)*([5]Hoja3!$K$6:$K$25=$C9))} -> 0 | AU9: =IFERROR(AT9/AS9,0) -> 0 | AV9: {=SUM([5]Hoja3!$I$6:$I$25*([5]Hoja3!$F$6:$F$25=AV$5)*([5]Hoja3!$K$6:$K$25=$C9))} -> 0 | AW9: {=SUM([5]Hoja3!$J$6:$J$25*([5]Hoja3!$F$6:$F$25=AV$5)*([5]Hoja3!$K$6:$K$25=$C9))} -> 0 | AX9: =IFERROR(AW9/AV9,0) -> 0 | AY9: {=SUM([5]Hoja3!$I$6:$I$25*([5]Hoja3!$F$6:$F$25=AY$5)*([5]Hoja3!$K$6:$K$25=$C9))} -> 27 | AZ9: {=SUM([5]Hoja3!$J$6:$J$25*([5]Hoja3!$F$6:$F$25=AY$5)*([5]Hoja3!$K$6:$K$25=$C9))} -> 48600 | BA9: =IFERROR(AZ9/AY9,0) -> 1800 | BB9: {=SUM([2]Hoja2!$I$6:$I$26*([2]Hoja2!$F$6:$F$26=BB$5)*([2]Hoja2!$K$6:$K$26=$C9))} -> 0 | BC9: {=SUM([2]Hoja2!$J$6:$J$26*([2]Hoja2!$F$6:$F$26=BB$5)*([2]Hoja2!$K$6:$K$26=$C9))} -> 0 | BD9: =IFERROR(BC9/BB9,0) -> 0 | BE9: {=SUM([2]Hoja2!$I$6:$I$26*([2]Hoja2!$F$6:$F$26=BE$5)*([2]Hoja2!$K$6:$K$26=$C9))} -> 0 | BF9: {=SUM([2]Hoja2!$J$6:$J$26*([2]Hoja2!$F$6:$F$26=BE$5)*([2]Hoja2!$K$6:$K$26=$C9))} -> 0 | BG9: =IFERROR(BF9/BE9,0) -> 0 | BH9: {=SUM([2]Hoja2!$I$6:$I$26*([2]Hoja2!$F$6:$F$26=BH$5)*([2]Hoja2!$K$6:$K$26=$C9))} -> 0 | BI9: {=SUM([2]Hoja2!$J$6:$J$26*([2]Hoja2!$F$6:$F$26=BH$5)*([2]Hoja2!$K$6:$K$26=$C9))} -> 0 | BJ9: =IFERROR(BI9/BH9,0) -> 0 | BK9: {=SUM([2]Hoja2!$I$6:$I$26*([2]Hoja2!$F$6:$F$26=BK$5)*([2]Hoja2!$K$6:$K$26=$C9))} -> 0 | BL9: {=SUM([2]Hoja2!$J$6:$J$26*([2]Hoja2!$F$6:$F$26=BK$5)*([2]Hoja2!$K$6:$K$26=$C9))} -> 0 | BM9: =IFERROR(BL9/BK9,0) -> 0 | BN9: {=SUM([2]Hoja2!$I$6:$I$26*([2]Hoja2!$F$6:$F$26=BN$5)*([2]Hoja2!$K$6:$K$26=$C9))} -> 0 | BO9: {=SUM([2]Hoja2!$J$6:$J$26*([2]Hoja2!$F$6:$F$26=BN$5)*([2]Hoja2!$K$6:$K$26=$C9))} -> 0 | BP9: =IFERROR(BO9/BN9,0) -> 0 | BQ9: {=SUM([2]Hoja2!$I$6:$I$26*([2]Hoja2!$F$6:$F$26=BQ$5)*([2]Hoja2!$K$6:$K$26=$C9))} -> 0 | BR9: {=SUM([2]Hoja2!$J$6:$J$26*([2]Hoja2!$F$6:$F$26=BQ$5)*([2]Hoja2!$K$6:$K$26=$C9))} -> 0 | BS9: =IFERROR(BR9/BQ9,0) -> 0 | BT9: =X9+AA9+AD9+AG9+AJ9+AM9+AP9+AY9+AS9+AV9 -> 81 | BU9: =Y9+AB9+AE9+AH9+AK9+AN9+AQ9+AZ9+AT9+AW9 -> 143100 | BV9: =IFERROR(BU9/BT9,0) -> 1766.6667 | BW9: =-IFERROR(F9/D9*BT9,0) -> -148650.01 | BX9: =-207.84*BT9 -> -16835.04 | BY9: =$BY$18/$BT$18*$BT9 -> -7232.8398 | BZ9: =$BZ$18/$BT$18*$BT9 -> -14218.538 | CA9: =$CA$18/$BT$18*$BT9 -> -11366.173 | CB9: =(BU9-BT9*$BY$19)*0.03 -> 4015.5484 | CC9: =BU9+SUM(BW9:BZ9,CB9) -> -39820.874 | CD9: =IFERROR(CC9/BU9,0) -> -0.27827306 | CE9: =BU9+BW9+BX9+BY9+CB9-CA9 -> -14236.164 | CF9: =IFERROR(CE9/BU9,0) -> -0.099484024 | CH9: =BV9 -> 1766.6667 | CI9: =IFERROR(BW9/$BT9,0) -> -1835.1853 | CJ9: =IFERROR(BX9/$BT9,0) -> -207.84 | CK9: =IFERROR(BY9/$BT9,0) -> -89.294318 | CL9: =IFERROR(BZ9/$BT9,0) -> -175.5375 | CM9: =IFERROR(CA9/$BT9,0) -> -140.32313 | CN9: =IFERROR(CB9/$BT9,0) -> 49.574672 | CO9: =IFERROR(CC9/$BT9,0) -> -491.61573 | CP9: =IFERROR(CE9/$BT9,0) -> -175.75511 | CQ9: =CP9-CO9 -> 315.86063
B10: 10007050 | C10: POTA RECORTES COCIDOS | D10: =TD!F7 -> 11.695 | E10: =IFERROR(F10/D10,0) -> 1408.8571 | F10: =TD!G7 -> 16476.584 | G10: =TD!H7 -> 2430.6888 | H10: =TD!I7 -> 527.5799 | I10: =TD!J7 -> 1037.1327 | J10: =TD!K7 -> 829.0747 | K10: 0 | L10: 0 | M10: =F10+G10+H10+I10 -> 20471.985 | N10: =IFERROR(M10/D10,0) -> 1750.4904 | O10: =F10+G10+H10-J10 -> 18605.778 | P10: =IFERROR(O10/D10,0) -> 1590.9173 | Q10: 1700 | R10: =Q10*D10 -> 19881.5 | S10: =R10-M10+(Q10-$BY$19)*D10*0.03 -> -34.099673 | T10: =IFERROR(S10/R10,0) -> -0.0017151459 | U10: =R10-(M10-J10-I10)+(Q10-$BY$19)*D10*0.03 -> 1832.1077 | V10: =IFERROR(U10/R10,0) -> 0.092151383 | X10: {=SUM([5]Hoja3!$I$6:$I$25*([5]Hoja3!$F$6:$F$25=X$5)*([5]Hoja3!$K$6:$K$25=$C10))} -> 27 | Y10: {=SUM([5]Hoja3!$J$6:$J$25*([5]Hoja3!$F$6:$F$25=X$5)*([5]Hoja3!$K$6:$K$25=$C10))} -> 68850 | Z10: =IFERROR(Y10/X10,0) -> 2550 | AA10: {=SUM([5]Hoja3!$I$6:$I$25*([5]Hoja3!$F$6:$F$25=AA$5)*([5]Hoja3!$K$6:$K$25=$C10))} -> 0 | AB10: {=SUM([5]Hoja3!$J$6:$J$25*([5]Hoja3!$F$6:$F$25=AA$5)*([5]Hoja3!$K$6:$K$25=$C10))} -> 0 | AC10: =IFERROR(AB10/AA10,0) -> 0 | AD10: {=SUM([5]Hoja3!$I$6:$I$25*([5]Hoja3!$F$6:$F$25=AD$5)*([5]Hoja3!$K$6:$K$25=$C10))} -> 0 | AE10: {=SUM([5]Hoja3!$J$6:$J$25*([5]Hoja3!$F$6:$F$25=AD$5)*([5]Hoja3!$K$6:$K$25=$C10))} -> 0 | AF10: =IFERROR(AE10/AD10,0) -> 0 | AG10: {=SUM([5]Hoja3!$I$6:$I$25*([5]Hoja3!$F$6:$F$25=AG$5)*([5]Hoja3!$K$6:$K$25=$C10))} -> 0 | AH10: {=SUM([5]Hoja3!$J$6:$J$25*([5]Hoja3!$F$6:$F$25=AG$5)*([5]Hoja3!$K$6:$K$25=$C10))} -> 0 | AI10: =IFERROR(AH10/AG10,0) -> 0 | AJ10: {=SUM([5]Hoja3!$I$6:$I$25*([5]Hoja3!$F$6:$F$25=AJ$5)*([5]Hoja3!$K$6:$K$25=$C10))} -> 0 | AK10: {=SUM([5]Hoja3!$J$6:$J$25*([5]Hoja3!$F$6:$F$25=AJ$5)*([5]Hoja3!$K$6:$K$25=$C10))} -> 0 | AL10: =IFERROR(AK10/AJ10,0) -> 0 | AM10: {=SUM([5]Hoja3!$I$6:$I$25*([5]Hoja3!$F$6:$F$25=AM$5)*([5]Hoja3!$K$6:$K$25=$C10))} -> 0 | AN10: {=SUM([5]Hoja3!$J$6:$J$25*([5]Hoja3!$F$6:$F$25=AM$5)*([5]Hoja3!$K$6:$K$25=$C10))} -> 0 | AO10: =IFERROR(AN10/AM10,0) -> 0 | AP10: {=SUM([5]Hoja3!$I$6:$I$25*([5]Hoja3!$F$6:$F$25=AP$5)*([5]Hoja3!$K$6:$K$25=$C10))} -> 0 | AQ10: {=SUM([5]Hoja3!$J$6:$J$25*([5]Hoja3!$F$6:$F$25=AP$5)*([5]Hoja3!$K$6:$K$25=$C10))} -> 0 | AR10: =IFERROR(AQ10/AP10,0) -> 0 | AS10: {=SUM([5]Hoja3!$I$6:$I$25*([5]Hoja3!$F$6:$F$25=AS$5)*([5]Hoja3!$K$6:$K$25=$C10))} -> 0 | AT10: {=SUM([5]Hoja3!$J$6:$J$25*([5]Hoja3!$F$6:$F$25=AS$5)*([5]Hoja3!$K$6:$K$25=$C10))} -> 0 | AU10: =IFERROR(AT10/AS10,0) -> 0 | AV10: {=SUM([5]Hoja3!$I$6:$I$25*([5]Hoja3!$F$6:$F$25=AV$5)*([5]Hoja3!$K$6:$K$25=$C10))} -> 0 | AW10: {=SUM([5]Hoja3!$J$6:$J$25*([5]Hoja3!$F$6:$F$25=AV$5)*([5]Hoja3!$K$6:$K$25=$C10))} -> 0 | AX10: =IFERROR(AW10/AV10,0) -> 0 | AY10: {=SUM([5]Hoja3!$I$6:$I$25*([5]Hoja3!$F$6:$F$25=AY$5)*([5]Hoja3!$K$6:$K$25=$C10))} -> 0 | AZ10: {=SUM([5]Hoja3!$J$6:$J$25*([5]Hoja3!$F$6:$F$25=AY$5)*([5]Hoja3!$K$6:$K$25=$C10))} -> 0 | BA10: =IFERROR(AZ10/AY10,0) -> 0 | BB10: {=SUM([2]Hoja2!$I$6:$I$26*([2]Hoja2!$F$6:$F$26=BB$5)*([2]Hoja2!$K$6:$K$26=$C10))} -> 0 | BC10: {=SUM([2]Hoja2!$J$6:$J$26*([2]Hoja2!$F$6:$F$26=BB$5)*([2]Hoja2!$K$6:$K$26=$C10))} -> 0 | BD10: =IFERROR(BC10/BB10,0) -> 0 | BE10: {=SUM([2]Hoja2!$I$6:$I$26*([2]Hoja2!$F$6:$F$26=BE$5)*([2]Hoja2!$K$6:$K$26=$C10))} -> 0 | BF10: {=SUM([2]Hoja2!$J$6:$J$26*([2]Hoja2!$F$6:$F$26=BE$5)*([2]Hoja2!$K$6:$K$26=$C10))} -> 0 | BG10: =IFERROR(BF10/BE10,0) -> 0 | BH10: {=SUM([2]Hoja2!$I$6:$I$26*([2]Hoja2!$F$6:$F$26=BH$5)*([2]Hoja2!$K$6:$K$26=$C10))} -> 0 | BI10: {=SUM([2]Hoja2!$J$6:$J$26*([2]Hoja2!$F$6:$F$26=BH$5)*([2]Hoja2!$K$6:$K$26=$C10))} -> 0 | BJ10: =IFERROR(BI10/BH10,0) -> 0 | BK10: {=SUM([2]Hoja2!$I$6:$I$26*([2]Hoja2!$F$6:$F$26=BK$5)*([2]Hoja2!$K$6:$K$26=$C10))} -> 0 | BL10: {=SUM([2]Hoja2!$J$6:$J$26*([2]Hoja2!$F$6:$F$26=BK$5)*([2]Hoja2!$K$6:$K$26=$C10))} -> 0 | BM10: =IFERROR(BL10/BK10,0) -> 0 | BN10: {=SUM([2]Hoja2!$I$6:$I$26*([2]Hoja2!$F$6:$F$26=BN$5)*([2]Hoja2!$K$6:$K$26=$C10))} -> 0 | BO10: {=SUM([2]Hoja2!$J$6:$J$26*([2]Hoja2!$F$6:$F$26=BN$5)*([2]Hoja2!$K$6:$K$26=$C10))} -> 0 | BP10: =IFERROR(BO10/BN10,0) -> 0 | BQ10: {=SUM([2]Hoja2!$I$6:$I$26*([2]Hoja2!$F$6:$F$26=BQ$5)*([2]Hoja2!$K$6:$K$26=$C10))} -> 0 | BR10: {=SUM([2]Hoja2!$J$6:$J$26*([2]Hoja2!$F$6:$F$26=BQ$5)*([2]Hoja2!$K$6:$K$26=$C10))} -> 0 | BS10: =IFERROR(BR10/BQ10,0) -> 0 | BT10: =X10+AA10+AD10+AG10+AJ10+AM10+AP10+AY10+AS10+AV10 -> 27 | BU10: =Y10+AB10+AE10+AH10+AK10+AN10+AQ10+AZ10+AT10+AW10 -> 68850 | BV10: =IFERROR(BU10/BT10,0) -> 2550 | BW10: =-IFERROR(F10/D10*BT10,0) -> -38039.142 | BX10: =-207.84*BT10 -> -5611.68 | BY10: =$BY$18/$BT$18*$BT10 -> -2410.9466 | BZ10: =$BZ$18/$BT$18*$BT10 -> -4739.5125 | CA10: =$CA$18/$BT$18*$BT10 -> -3788.7244 | CB10: =(BU10-BT10*$BY$19)*0.03 -> 1973.0161 | CC10: =BU10+SUM(BW10:BZ10,CB10) -> 20021.735 | CD10: =IFERROR(CC10/BU10,0) -> 0.29080225 | CE10: =BU10+BW10+BX10+BY10+CB10-CA10 -> 28549.972 | CF10: =IFERROR(CE10/BU10,0) -> 0.41466916 | CH10: =BV10 -> 2550 | CI10: =IFERROR(BW10/$BT10,0) -> -1408.8571 | CJ10: =IFERROR(BX10/$BT10,0) -> -207.84 | CK10: =IFERROR(BY10/$BT10,0) -> -89.294318 | CL10: =IFERROR(BZ10/$BT10,0) -> -175.5375 | CM10: =IFERROR(CA10/$BT10,0) -> -140.32313 | CN10: =IFERROR(CB10/$BT10,0) -> 73.074672 | CO10: =IFERROR(CC10/$BT10,0) -> 741.54573 | CP10: =IFERROR(CE10/$BT10,0) -> 1057.4064 | CQ10: =CP10-CO10 -> 315.86063
B11: 10007162 | C11: POTA REJOS CONGELADOS | D11: =TD!F8 -> 171 | E11: =IFERROR(F11/D11,0) -> 1698.6478 | F11: =TD!G8 -> 290468.78 | G11: =TD!H8 -> 35540.64 | H11: =TD!I8 -> 7714.0798 | I11: =TD!J8 -> 15164.574 | J11: =TD!K8 -> 12122.426 | K11: 0 | L11: 0 | M11: =F11+G11+H11+I11 -> 348888.07 | N11: =IFERROR(M11/D11,0) -> 2040.2811 | O11: =F11+G11+H11-J11 -> 321601.07 | P11: =IFERROR(O11/D11,0) -> 1880.708 | Q11: 2700 | R11: =Q11*D11 -> 461700 | S11: =R11-M11+(Q11-$BY$19)*D11*0.03 -> 126077.19 | T11: =IFERROR(S11/R11,0) -> 0.27307168 | U11: =R11-(M11-J11-I11)+(Q11-$BY$19)*D11*0.03 -> 153364.19 | V11: =IFERROR(U11/R11,0) -> 0.33217283 | X11: {=SUM([5]Hoja3!$I$6:$I$25*([5]Hoja3!$F$6:$F$25=X$5)*([5]Hoja3!$K$6:$K$25=$C11))} -> 0 | Y11: {=SUM([5]Hoja3!$J$6:$J$25*([5]Hoja3!$F$6:$F$25=X$5)*([5]Hoja3!$K$6:$K$25=$C11))} -> 0 | Z11: =IFERROR(Y11/X11,0) -> 0 | AA11: {=SUM([5]Hoja3!$I$6:$I$25*([5]Hoja3!$F$6:$F$25=AA$5)*([5]Hoja3!$K$6:$K$25=$C11))} -> 0 | AB11: {=SUM([5]Hoja3!$J$6:$J$25*([5]Hoja3!$F$6:$F$25=AA$5)*([5]Hoja3!$K$6:$K$25=$C11))} -> 0 | AC11: =IFERROR(AB11/AA11,0) -> 0 | AD11: {=SUM([5]Hoja3!$I$6:$I$25*([5]Hoja3!$F$6:$F$25=AD$5)*([5]Hoja3!$K$6:$K$25=$C11))} -> 108 | AE11: {=SUM([5]Hoja3!$J$6:$J$25*([5]Hoja3!$F$6:$F$25=AD$5)*([5]Hoja3!$K$6:$K$25=$C11))} -> 275400 | AF11: =IFERROR(AE11/AD11,0) -> 2550 | AG11: {=SUM([5]Hoja3!$I$6:$I$25*([5]Hoja3!$F$6:$F$25=AG$5)*([5]Hoja3!$K$6:$K$25=$C11))} -> 0 | AH11: {=SUM([5]Hoja3!$J$6:$J$25*([5]Hoja3!$F$6:$F$25=AG$5)*([5]Hoja3!$K$6:$K$25=$C11))} -> 0 | AI11: =IFERROR(AH11/AG11,0) -> 0 | AJ11: {=SUM([5]Hoja3!$I$6:$I$25*([5]Hoja3!$F$6:$F$25=AJ$5)*([5]Hoja3!$K$6:$K$25=$C11))} -> 0 | AK11: {=SUM([5]Hoja3!$J$6:$J$25*([5]Hoja3!$F$6:$F$25=AJ$5)*([5]Hoja3!$K$6:$K$25=$C11))} -> 0 | AL11: =IFERROR(AK11/AJ11,0) -> 0 | AM11: {=SUM([5]Hoja3!$I$6:$I$25*([5]Hoja3!$F$6:$F$25=AM$5)*([5]Hoja3!$K$6:$K$25=$C11))} -> 0 | AN11: {=SUM([5]Hoja3!$J$6:$J$25*([5]Hoja3!$F$6:$F$25=AM$5)*([5]Hoja3!$K$6:$K$25=$C11))} -> 0 | AO11: =IFERROR(AN11/AM11,0) -> 0 | AP11: {=SUM([5]Hoja3!$I$6:$I$25*([5]Hoja3!$F$6:$F$25=AP$5)*([5]Hoja3!$K$6:$K$25=$C11))} -> 0 | AQ11: {=SUM([5]Hoja3!$J$6:$J$25*([5]Hoja3!$F$6:$F$25=AP$5)*([5]Hoja3!$K$6:$K$25=$C11))} -> 0 | AR11: =IFERROR(AQ11/AP11,0) -> 0 | AS11: {=SUM([5]Hoja3!$I$6:$I$25*([5]Hoja3!$F$6:$F$25=AS$5)*([5]Hoja3!$K$6:$K$25=$C11))} -> 27 | AT11: {=SUM([5]Hoja3!$J$6:$J$25*([5]Hoja3!$F$6:$F$25=AS$5)*([5]Hoja3!$K$6:$K$25=$C11))} -> 81000 | AU11: =IFERROR(AT11/AS11,0) -> 3000 | AV11: {=SUM([5]Hoja3!$I$6:$I$25*([5]Hoja3!$F$6:$F$25=AV$5)*([5]Hoja3!$K$6:$K$25=$C11))} -> 0 | AW11: {=SUM([5]Hoja3!$J$6:$J$25*([5]Hoja3!$F$6:$F$25=AV$5)*([5]Hoja3!$K$6:$K$25=$C11))} -> 0 | AX11: =IFERROR(AW11/AV11,0) -> 0 | AY11: {=SUM([5]Hoja3!$I$6:$I$25*([5]Hoja3!$F$6:$F$25=AY$5)*([5]Hoja3!$K$6:$K$25=$C11))} -> 108 | AZ11: {=SUM([5]Hoja3!$J$6:$J$25*([5]Hoja3!$F$6:$F$25=AY$5)*([5]Hoja3!$K$6:$K$25=$C11))} -> 293910 | BA11: =IFERROR(AZ11/AY11,0) -> 2721.3889 | BB11: {=SUM([2]Hoja2!$I$6:$I$26*([2]Hoja2!$F$6:$F$26=BB$5)*([2]Hoja2!$K$6:$K$26=$C11))} -> 0 | BC11: {=SUM([2]Hoja2!$J$6:$J$26*([2]Hoja2!$F$6:$F$26=BB$5)*([2]Hoja2!$K$6:$K$26=$C11))} -> 0 | BD11: =IFERROR(BC11/BB11,0) -> 0 | BE11: {=SUM([2]Hoja2!$I$6:$I$26*([2]Hoja2!$F$6:$F$26=BE$5)*([2]Hoja2!$K$6:$K$26=$C11))} -> 0 | BF11: {=SUM([2]Hoja2!$J$6:$J$26*([2]Hoja2!$F$6:$F$26=BE$5)*([2]Hoja2!$K$6:$K$26=$C11))} -> 0 | BG11: =IFERROR(BF11/BE11,0) -> 0 | BH11: {=SUM([2]Hoja2!$I$6:$I$26*([2]Hoja2!$F$6:$F$26=BH$5)*([2]Hoja2!$K$6:$K$26=$C11))} -> 0 | BI11: {=SUM([2]Hoja2!$J$6:$J$26*([2]Hoja2!$F$6:$F$26=BH$5)*([2]Hoja2!$K$6:$K$26=$C11))} -> 0 | BJ11: =IFERROR(BI11/BH11,0) -> 0 | BK11: {=SUM([2]Hoja2!$I$6:$I$26*([2]Hoja2!$F$6:$F$26=BK$5)*([2]Hoja2!$K$6:$K$26=$C11))} -> 0 | BL11: {=SUM([2]Hoja2!$J$6:$J$26*([2]Hoja2!$F$6:$F$26=BK$5)*([2]Hoja2!$K$6:$K$26=$C11))} -> 0 | BM11: =IFERROR(BL11/BK11,0) -> 0 | BN11: {=SUM([2]Hoja2!$I$6:$I$26*([2]Hoja2!$F$6:$F$26=BN$5)*([2]Hoja2!$K$6:$K$26=$C11))} -> 0 | BO11: {=SUM([2]Hoja2!$J$6:$J$26*([2]Hoja2!$F$6:$F$26=BN$5)*([2]Hoja2!$K$6:$K$26=$C11))} -> 0 | BP11: =IFERROR(BO11/BN11,0) -> 0 | BQ11: {=SUM([2]Hoja2!$I$6:$I$26*([2]Hoja2!$F$6:$F$26=BQ$5)*([2]Hoja2!$K$6:$K$26=$C11))} -> 0 | BR11: {=SUM([2]Hoja2!$J$6:$J$26*([2]Hoja2!$F$6:$F$26=BQ$5)*([2]Hoja2!$K$6:$K$26=$C11))} -> 0 | BS11: =IFERROR(BR11/BQ11,0) -> 0 | BT11: =X11+AA11+AD11+AG11+AJ11+AM11+AP11+AY11+AS11+AV11 -> 243 | BU11: =Y11+AB11+AE11+AH11+AK11+AN11+AQ11+AZ11+AT11+AW11 -> 650310 | BV11: =IFERROR(BU11/BT11,0) -> 2676.1728 | BW11: =-IFERROR(F11/D11*BT11,0) -> -412771.43 | BX11: =-207.84*BT11 -> -50505.12 | BY11: =$BY$18/$BT$18*$BT11 -> -21698.519 | BZ11: =$BZ$18/$BT$18*$BT11 -> -42655.612 | CA11: =$CA$18/$BT$18*$BT11 -> -34098.519 | CB11: =(BU11-BT11*$BY$19)*0.03 -> 18676.945 | CC11: =BU11+SUM(BW11:BZ11,CB11) -> 141356.27 | CD11: =IFERROR(CC11/BU11,0) -> 0.21736751 | CE11: =BU11+BW11+BX11+BY11+CB11-CA11 -> 218110.4 | CF11: =IFERROR(CE11/BU11,0) -> 0.3353945 | CH11: =BV11 -> 2676.1728 | CI11: =IFERROR(BW11/$BT11,0) -> -1698.6478 | CJ11: =IFERROR(BX11/$BT11,0) -> -207.84 | CK11: =IFERROR(BY11/$BT11,0) -> -89.294318 | CL11: =IFERROR(BZ11/$BT11,0) -> -175.5375 | CM11: =IFERROR(CA11/$BT11,0) -> -140.32313 | CN11: =IFERROR(CB11/$BT11,0) -> 76.859857 | CO11: =IFERROR(CC11/$BT11,0) -> 581.71304 | CP11: =IFERROR(CE11/$BT11,0) -> 897.57366 | CQ11: =CP11-CO11 -> 315.86063
B12: 10007567 | C12: POTA REPRODUCTORES | D12: =TD!F9 -> 108.54 | E12: =IFERROR(F12/D12,0) -> 1641.9707 | F12: =TD!G9 -> 178219.5 | G12: =TD!H9 -> 22558.954 | H12: =TD!I9 -> 4896.4106 | I12: =TD!J9 -> 9625.5137 | J12: =TD!K9 -> 7694.5505 | K12: 0 | L12: 0 | M12: =F12+G12+H12+I12 -> 215300.38 | N12: =IFERROR(M12/D12,0) -> 1983.604 | O12: =F12+G12+H12-J12 -> 197980.32 | P12: =IFERROR(O12/D12,0) -> 1824.0309 | Q12: 2730 | R12: =Q12*D12 -> 296314.2 | S12: =R12-M12+(Q12-$BY$19)*D12*0.03 -> 89531.461 | T12: =IFERROR(S12/R12,0) -> 0.30215042 | U12: =R12-(M12-J12-I12)+(Q12-$BY$19)*D12*0.03 -> 106851.52 | V12: =IFERROR(U12/R12,0) -> 0.36060211 | X12: {=SUM([5]Hoja3!$I$6:$I$25*([5]Hoja3!$F$6:$F$25=X$5)*([5]Hoja3!$K$6:$K$25=$C12))} -> 0 | Y12: {=SUM([5]Hoja3!$J$6:$J$25*([5]Hoja3!$F$6:$F$25=X$5)*([5]Hoja3!$K$6:$K$25=$C12))} -> 0 | Z12: =IFERROR(Y12/X12,0) -> 0 | AA12: {=SUM([5]Hoja3!$I$6:$I$25*([5]Hoja3!$F$6:$F$25=AA$5)*([5]Hoja3!$K$6:$K$25=$C12))} -> 26 | AB12: {=SUM([5]Hoja3!$J$6:$J$25*([5]Hoja3!$F$6:$F$25=AA$5)*([5]Hoja3!$K$6:$K$25=$C12))} -> 74100 | AC12: =IFERROR(AB12/AA12,0) -> 2850 | AD12: {=SUM([5]Hoja3!$I$6:$I$25*([5]Hoja3!$F$6:$F$25=AD$5)*([5]Hoja3!$K$6:$K$25=$C12))} -> 0 | AE12: {=SUM([5]Hoja3!$J$6:$J$25*([5]Hoja3!$F$6:$F$25=AD$5)*([5]Hoja3!$K$6:$K$25=$C12))} -> 0 | AF12: =IFERROR(AE12/AD12,0) -> 0 | AG12: {=SUM([5]Hoja3!$I$6:$I$25*([5]Hoja3!$F$6:$F$25=AG$5)*([5]Hoja3!$K$6:$K$25=$C12))} -> 26 | AH12: {=SUM([5]Hoja3!$J$6:$J$25*([5]Hoja3!$F$6:$F$25=AG$5)*([5]Hoja3!$K$6:$K$25=$C12))} -> 70980 | AI12: =IFERROR(AH12/AG12,0) -> 2730 | AJ12: {=SUM([5]Hoja3!$I$6:$I$25*([5]Hoja3!$F$6:$F$25=AJ$5)*([5]Hoja3!$K$6:$K$25=$C12))} -> 0 | AK12: {=SUM([5]Hoja3!$J$6:$J$25*([5]Hoja3!$F$6:$F$25=AJ$5)*([5]Hoja3!$K$6:$K$25=$C12))} -> 0 | AL12: =IFERROR(AK12/AJ12,0) -> 0 | AM12: {=SUM([5]Hoja3!$I$6:$I$25*([5]Hoja3!$F$6:$F$25=AM$5)*([5]Hoja3!$K$6:$K$25=$C12))} -> 0 | AN12: {=SUM([5]Hoja3!$J$6:$J$25*([5]Hoja3!$F$6:$F$25=AM$5)*([5]Hoja3!$K$6:$K$25=$C12))} -> 0 | AO12: =IFERROR(AN12/AM12,0) -> 0 | AP12: {=SUM([5]Hoja3!$I$6:$I$25*([5]Hoja3!$F$6:$F$25=AP$5)*([5]Hoja3!$K$6:$K$25=$C12))} -> 27 | AQ12: {=SUM([5]Hoja3!$J$6:$J$25*([5]Hoja3!$F$6:$F$25=AP$5)*([5]Hoja3!$K$6:$K$25=$C12))} -> 72360 | AR12: =IFERROR(AQ12/AP12,0) -> 2680 | AS12: {=SUM([5]Hoja3!$I$6:$I$25*([5]Hoja3!$F$6:$F$25=AS$5)*([5]Hoja3!$K$6:$K$25=$C12))} -> 0 | AT12: {=SUM([5]Hoja3!$J$6:$J$25*([5]Hoja3!$F$6:$F$25=AS$5)*([5]Hoja3!$K$6:$K$25=$C12))} -> 0 | AU12: =IFERROR(AT12/AS12,0) -> 0 | AV12: {=SUM([5]Hoja3!$I$6:$I$25*([5]Hoja3!$F$6:$F$25=AV$5)*([5]Hoja3!$K$6:$K$25=$C12))} -> 0 | AW12: {=SUM([5]Hoja3!$J$6:$J$25*([5]Hoja3!$F$6:$F$25=AV$5)*([5]Hoja3!$K$6:$K$25=$C12))} -> 0 | AX12: =IFERROR(AW12/AV12,0) -> 0 | AY12: {=SUM([5]Hoja3!$I$6:$I$25*([5]Hoja3!$F$6:$F$25=AY$5)*([5]Hoja3!$K$6:$K$25=$C12))} -> 0 | AZ12: {=SUM([5]Hoja3!$J$6:$J$25*([5]Hoja3!$F$6:$F$25=AY$5)*([5]Hoja3!$K$6:$K$25=$C12))} -> 0 | BA12: =IFERROR(AZ12/AY12,0) -> 0 | BB12: {=SUM([2]Hoja2!$I$6:$I$26*([2]Hoja2!$F$6:$F$26=BB$5)*([2]Hoja2!$K$6:$K$26=$C12))} -> 0 | BC12: {=SUM([2]Hoja2!$J$6:$J$26*([2]Hoja2!$F$6:$F$26=BB$5)*([2]Hoja2!$K$6:$K$26=$C12))} -> 0 | BD12: =IFERROR(BC12/BB12,0) -> 0 | BE12: {=SUM([2]Hoja2!$I$6:$I$26*([2]Hoja2!$F$6:$F$26=BE$5)*([2]Hoja2!$K$6:$K$26=$C12))} -> 0 | BF12: {=SUM([2]Hoja2!$J$6:$J$26*([2]Hoja2!$F$6:$F$26=BE$5)*([2]Hoja2!$K$6:$K$26=$C12))} -> 0 | BG12: =IFERROR(BF12/BE12,0) -> 0 | BH12: {=SUM([2]Hoja2!$I$6:$I$26*([2]Hoja2!$F$6:$F$26=BH$5)*([2]Hoja2!$K$6:$K$26=$C12))} -> 0 | BI12: {=SUM([2]Hoja2!$J$6:$J$26*([2]Hoja2!$F$6:$F$26=BH$5)*([2]Hoja2!$K$6:$K$26=$C12))} -> 0 | BJ12: =IFERROR(BI12/BH12,0) -> 0 | BK12: {=SUM([2]Hoja2!$I$6:$I$26*([2]Hoja2!$F$6:$F$26=BK$5)*([2]Hoja2!$K$6:$K$26=$C12))} -> 0 | BL12: {=SUM([2]Hoja2!$J$6:$J$26*([2]Hoja2!$F$6:$F$26=BK$5)*([2]Hoja2!$K$6:$K$26=$C12))} -> 0 | BM12: =IFERROR(BL12/BK12,0) -> 0 | BN12: {=SUM([2]Hoja2!$I$6:$I$26*([2]Hoja2!$F$6:$F$26=BN$5)*([2]Hoja2!$K$6:$K$26=$C12))} -> 0 | BO12: {=SUM([2]Hoja2!$J$6:$J$26*([2]Hoja2!$F$6:$F$26=BN$5)*([2]Hoja2!$K$6:$K$26=$C12))} -> 0 | BP12: =IFERROR(BO12/BN12,0) -> 0 | BQ12: {=SUM([2]Hoja2!$I$6:$I$26*([2]Hoja2!$F$6:$F$26=BQ$5)*([2]Hoja2!$K$6:$K$26=$C12))} -> 0 | BR12: {=SUM([2]Hoja2!$J$6:$J$26*([2]Hoja2!$F$6:$F$26=BQ$5)*([2]Hoja2!$K$6:$K$26=$C12))} -> 0 | BS12: =IFERROR(BR12/BQ12,0) -> 0 | BT12: =X12+AA12+AD12+AG12+AJ12+AM12+AP12+AY12+AS12+AV12 -> 79 | BU12: =Y12+AB12+AE12+AH12+AK12+AN12+AQ12+AZ12+AT12+AW12 -> 217440 | BV12: =IFERROR(BU12/BT12,0) -> 2752.4051 | BW12: =-IFERROR(F12/D12*BT12,0) -> -129715.69 | BX12: =-207.84*BT12 -> -16419.36 | BY12: =$BY$18/$BT$18*$BT12 -> -7054.2511 | BZ12: =$BZ$18/$BT$18*$BT12 -> -13867.462 | CA12: =$CA$18/$BT$18*$BT12 -> -11085.527 | CB12: =(BU12-BT12*$BY$19)*0.03 -> 6252.5991 | CC12: =BU12+SUM(BW12:BZ12,CB12) -> 56635.838 | CD12: =IFERROR(CC12/BU12,0) -> 0.26046651 | CE12: =BU12+BW12+BX12+BY12+CB12-CA12 -> 81588.828 | CF12: =IFERROR(CE12/BU12,0) -> 0.37522456 | CH12: =BV12 -> 2752.4051 | CI12: =IFERROR(BW12/$BT12,0) -> -1641.9707 | CJ12: =IFERROR(BX12/$BT12,0) -> -207.84 | CK12: =IFERROR(BY12/$BT12,0) -> -89.294318 | CL12: =IFERROR(BZ12/$BT12,0) -> -175.5375 | CM12: =IFERROR(CA12/$BT12,0) -> -140.32313 | CN12: =IFERROR(CB12/$BT12,0) -> 79.146823 | CO12: =IFERROR(CC12/$BT12,0) -> 716.90935 | CP12: =IFERROR(CE12/$BT12,0) -> 1032.77 | CQ12: =CP12-CO12 -> 315.86063
B13: 10007969 | C13: POTA CONOS | D13: =TD!F10 -> 4.02 | E13: =IFERROR(F13/D13,0) -> 1333.6378 | F13: =TD!G10 -> 5361.2241 | G13: =TD!H10 -> 835.5168 | H13: =TD!I10 -> 181.34854 | I13: =TD!J10 -> 356.50051 | J13: =TD!K10 -> 284.98335 | K13: 0 | L13: 0 | M13: =F13+G13+H13+I13 -> 6734.59 | N13: =IFERROR(M13/D13,0) -> 1675.2711 | O13: =F13+G13+H13-J13 -> 6093.1061 | P13: =IFERROR(O13/D13,0) -> 1515.698 | Q13: 1600 | R13: =Q13*D13 -> 6432 | S13: =R13-M13+(Q13-$BY$19)*D13*0.03 -> -123.3998 | T13: =IFERROR(S13/R13,0) -> -0.019185293 | U13: =R13-(M13-J13-I13)+(Q13-$BY$19)*D13*0.03 -> 518.08405 | V13: =IFERROR(U13/R13,0) -> 0.080547894 | X13: {=SUM([5]Hoja3!$I$6:$I$25*([5]Hoja3!$F$6:$F$25=X$5)*([5]Hoja3!$K$6:$K$25=$C13))} -> 0 | Y13: {=SUM([5]Hoja3!$J$6:$J$25*([5]Hoja3!$F$6:$F$25=X$5)*([5]Hoja3!$K$6:$K$25=$C13))} -> 0 | Z13: =IFERROR(Y13/X13,0) -> 0 | AA13: {=SUM([5]Hoja3!$I$6:$I$25*([5]Hoja3!$F$6:$F$25=AA$5)*([5]Hoja3!$K$6:$K$25=$C13))} -> 0 | AB13: {=SUM([5]Hoja3!$J$6:$J$25*([5]Hoja3!$F$6:$F$25=AA$5)*([5]Hoja3!$K$6:$K$25=$C13))} -> 0 | AC13: =IFERROR(AB13/AA13,0) -> 0 | AD13: {=SUM([5]Hoja3!$I$6:$I$25*([5]Hoja3!$F$6:$F$25=AD$5)*([5]Hoja3!$K$6:$K$25=$C13))} -> 54 | AE13: {=SUM([5]Hoja3!$J$6:$J$25*([5]Hoja3!$F$6:$F$25=AD$5)*([5]Hoja3!$K$6:$K$25=$C13))} -> 86400 | AF13: =IFERROR(AE13/AD13,0) -> 1600 | AG13: {=SUM([5]Hoja3!$I$6:$I$25*([5]Hoja3!$F$6:$F$25=AG$5)*([5]Hoja3!$K$6:$K$25=$C13))} -> 0 | AH13: {=SUM([5]Hoja3!$J$6:$J$25*([5]Hoja3!$F$6:$F$25=AG$5)*([5]Hoja3!$K$6:$K$25=$C13))} -> 0 | AI13: =IFERROR(AH13/AG13,0) -> 0 | AJ13: {=SUM([5]Hoja3!$I$6:$I$25*([5]Hoja3!$F$6:$F$25=AJ$5)*([5]Hoja3!$K$6:$K$25=$C13))} -> 0 | AK13: {=SUM([5]Hoja3!$J$6:$J$25*([5]Hoja3!$F$6:$F$25=AJ$5)*([5]Hoja3!$K$6:$K$25=$C13))} -> 0 | AL13: =IFERROR(AK13/AJ13,0) -> 0 | AM13: {=SUM([5]Hoja3!$I$6:$I$25*([5]Hoja3!$F$6:$F$25=AM$5)*([5]Hoja3!$K$6:$K$25=$C13))} -> 0 | AN13: {=SUM([5]Hoja3!$J$6:$J$25*([5]Hoja3!$F$6:$F$25=AM$5)*([5]Hoja3!$K$6:$K$25=$C13))} -> 0 | AO13: =IFERROR(AN13/AM13,0) -> 0 | AP13: {=SUM([5]Hoja3!$I$6:$I$25*([5]Hoja3!$F$6:$F$25=AP$5)*([5]Hoja3!$K$6:$K$25=$C13))} -> 0 | AQ13: {=SUM([5]Hoja3!$J$6:$J$25*([5]Hoja3!$F$6:$F$25=AP$5)*([5]Hoja3!$K$6:$K$25=$C13))} -> 0 | AR13: =IFERROR(AQ13/AP13,0) -> 0 | AS13: {=SUM([5]Hoja3!$I$6:$I$25*([5]Hoja3!$F$6:$F$25=AS$5)*([5]Hoja3!$K$6:$K$25=$C13))} -> 0 | AT13: {=SUM([5]Hoja3!$J$6:$J$25*([5]Hoja3!$F$6:$F$25=AS$5)*([5]Hoja3!$K$6:$K$25=$C13))} -> 0 | AU13: =IFERROR(AT13/AS13,0) -> 0 | AV13: {=SUM([5]Hoja3!$I$6:$I$25*([5]Hoja3!$F$6:$F$25=AV$5)*([5]Hoja3!$K$6:$K$25=$C13))} -> 0 | AW13: {=SUM([5]Hoja3!$J$6:$J$25*([5]Hoja3!$F$6:$F$25=AV$5)*([5]Hoja3!$K$6:$K$25=$C13))} -> 0 | AX13: =IFERROR(AW13/AV13,0) -> 0 | AY13: {=SUM([5]Hoja3!$I$6:$I$25*([5]Hoja3!$F$6:$F$25=AY$5)*([5]Hoja3!$K$6:$K$25=$C13))} -> 27 | AZ13: {=SUM([5]Hoja3!$J$6:$J$25*([5]Hoja3!$F$6:$F$25=AY$5)*([5]Hoja3!$K$6:$K$25=$C13))} -> 43200 | BA13: =IFERROR(AZ13/AY13,0) -> 1600 | BB13: {=SUM([2]Hoja2!$I$6:$I$26*([2]Hoja2!$F$6:$F$26=BB$5)*([2]Hoja2!$K$6:$K$26=$C13))} -> 0 | BC13: {=SUM([2]Hoja2!$J$6:$J$26*([2]Hoja2!$F$6:$F$26=BB$5)*([2]Hoja2!$K$6:$K$26=$C13))} -> 0 | BD13: =IFERROR(BC13/BB13,0) -> 0 | BE13: {=SUM([2]Hoja2!$I$6:$I$26*([2]Hoja2!$F$6:$F$26=BE$5)*([2]Hoja2!$K$6:$K$26=$C13))} -> 0 | BF13: {=SUM([2]Hoja2!$J$6:$J$26*([2]Hoja2!$F$6:$F$26=BE$5)*([2]Hoja2!$K$6:$K$26=$C13))} -> 0 | BG13: =IFERROR(BF13/BE13,0) -> 0 | BH13: {=SUM([2]Hoja2!$I$6:$I$26*([2]Hoja2!$F$6:$F$26=BH$5)*([2]Hoja2!$K$6:$K$26=$C13))} -> 0 | BI13: {=SUM([2]Hoja2!$J$6:$J$26*([2]Hoja2!$F$6:$F$26=BH$5)*([2]Hoja2!$K$6:$K$26=$C13))} -> 0 | BJ13: =IFERROR(BI13/BH13,0) -> 0 | BK13: {=SUM([2]Hoja2!$I$6:$I$26*([2]Hoja2!$F$6:$F$26=BK$5)*([2]Hoja2!$K$6:$K$26=$C13))} -> 0 | BL13: {=SUM([2]Hoja2!$J$6:$J$26*([2]Hoja2!$F$6:$F$26=BK$5)*([2]Hoja2!$K$6:$K$26=$C13))} -> 0 | BM13: =IFERROR(BL13/BK13,0) -> 0 | BN13: {=SUM([2]Hoja2!$I$6:$I$26*([2]Hoja2!$F$6:$F$26=BN$5)*([2]Hoja2!$K$6:$K$26=$C13))} -> 0 | BO13: {=SUM([2]Hoja2!$J$6:$J$26*([2]Hoja2!$F$6:$F$26=BN$5)*([2]Hoja2!$K$6:$K$26=$C13))} -> 0 | BP13: =IFERROR(BO13/BN13,0) -> 0 | BQ13: {=SUM([2]Hoja2!$I$6:$I$26*([2]Hoja2!$F$6:$F$26=BQ$5)*([2]Hoja2!$K$6:$K$26=$C13))} -> 0 | BR13: {=SUM([2]Hoja2!$J$6:$J$26*([2]Hoja2!$F$6:$F$26=BQ$5)*([2]Hoja2!$K$6:$K$26=$C13))} -> 0 | BS13: =IFERROR(BR13/BQ13,0) -> 0 | BT13: =X13+AA13+AD13+AG13+AJ13+AM13+AP13+AY13+AS13+AV13 -> 81 | BU13: =Y13+AB13+AE13+AH13+AK13+AN13+AQ13+AZ13+AT13+AW13 -> 129600 | BV13: =IFERROR(BU13/BT13,0) -> 1600 | BW13: =-IFERROR(F13/D13*BT13,0) -> -108024.67 | BX13: =-207.84*BT13 -> -16835.04 | BY13: =$BY$18/$BT$18*$BT13 -> -7232.8398 | BZ13: =$BZ$18/$BT$18*$BT13 -> -14218.538 | CA13: =$CA$18/$BT$18*$BT13 -> -11366.173 | CB13: =(BU13-BT13*$BY$19)*0.03 -> 3610.5484 | CC13: =BU13+SUM(BW13:BZ13,CB13) -> -13100.534 | CD13: =IFERROR(CC13/BU13,0) -> -0.10108437 | CE13: =BU13+BW13+BX13+BY13+CB13-CA13 -> 12484.176 | CF13: =IFERROR(CE13/BU13,0) -> 0.096328521 | CH13: =BV13 -> 1600 | CI13: =IFERROR(BW13/$BT13,0) -> -1333.6378 | CJ13: =IFERROR(BX13/$BT13,0) -> -207.84 | CK13: =IFERROR(BY13/$BT13,0) -> -89.294318 | CL13: =IFERROR(BZ13/$BT13,0) -> -175.5375 | CM13: =IFERROR(CA13/$BT13,0) -> -140.32313 | CN13: =IFERROR(CB13/$BT13,0) -> 44.574672 | CO13: =IFERROR(CC13/$BT13,0) -> -161.73499 | CP13: =IFERROR(CE13/$BT13,0) -> 154.12563 | CQ13: =CP13-CO13 -> 315.86063
B14: 10009239 | C14: POTA FILETE DARUMA | D14: =TD!F11 -> 2.8 | E14: =IFERROR(F14/D14,0) -> 3191.5558 | F14: =TD!G11 -> 8936.3563 | G14: =TD!H11 -> 581.952 | H14: =TD!I11 -> 126.31242 | I14: =TD!J11 -> 248.30881 | J14: =TD!K11 -> 198.49587 | K14: 0 | L14: 0 | M14: =F14+G14+H14+I14 -> 9892.9295 | N14: =IFERROR(M14/D14,0) -> 3533.1891 | O14: =F14+G14+H14-J14 -> 9446.1249 | P14: =IFERROR(O14/D14,0) -> 3373.616 | Q14: 3400 | R14: =Q14*D14 -> 9520 | S14: =R14-M14+(Q14-$BY$19)*D14*0.03 -> -96.920454 | T14: =IFERROR(S14/R14,0) -> -0.01018072 | U14: =R14-(M14-J14-I14)+(Q14-$BY$19)*D14*0.03 -> 349.88422 | V14: =IFERROR(U14/R14,0) -> 0.036752545 | X14: {=SUM([5]Hoja3!$I$6:$I$25*([5]Hoja3!$F$6:$F$25=X$5)*([5]Hoja3!$K$6:$K$25=$C14))} -> 0 | Y14: {=SUM([5]Hoja3!$J$6:$J$25*([5]Hoja3!$F$6:$F$25=X$5)*([5]Hoja3!$K$6:$K$25=$C14))} -> 0 | Z14: =IFERROR(Y14/X14,0) -> 0 | AA14: {=SUM([5]Hoja3!$I$6:$I$25*([5]Hoja3!$F$6:$F$25=AA$5)*([5]Hoja3!$K$6:$K$25=$C14))} -> 0 | AB14: {=SUM([5]Hoja3!$J$6:$J$25*([5]Hoja3!$F$6:$F$25=AA$5)*([5]Hoja3!$K$6:$K$25=$C14))} -> 0 | AC14: =IFERROR(AB14/AA14,0) -> 0 | AD14: {=SUM([5]Hoja3!$I$6:$I$25*([5]Hoja3!$F$6:$F$25=AD$5)*([5]Hoja3!$K$6:$K$25=$C14))} -> 0 | AE14: {=SUM([5]Hoja3!$J$6:$J$25*([5]Hoja3!$F$6:$F$25=AD$5)*([5]Hoja3!$K$6:$K$25=$C14))} -> 0 | AF14: =IFERROR(AE14/AD14,0) -> 0 | AG14: {=SUM([5]Hoja3!$I$6:$I$25*([5]Hoja3!$F$6:$F$25=AG$5)*([5]Hoja3!$K$6:$K$25=$C14))} -> 0 | AH14: {=SUM([5]Hoja3!$J$6:$J$25*([5]Hoja3!$F$6:$F$25=AG$5)*([5]Hoja3!$K$6:$K$25=$C14))} -> 0 | AI14: =IFERROR(AH14/AG14,0) -> 0 | AJ14: {=SUM([5]Hoja3!$I$6:$I$25*([5]Hoja3!$F$6:$F$25=AJ$5)*([5]Hoja3!$K$6:$K$25=$C14))} -> 0 | AK14: {=SUM([5]Hoja3!$J$6:$J$25*([5]Hoja3!$F$6:$F$25=AJ$5)*([5]Hoja3!$K$6:$K$25=$C14))} -> 0 | AL14: =IFERROR(AK14/AJ14,0) -> 0 | AM14: {=SUM([5]Hoja3!$I$6:$I$25*([5]Hoja3!$F$6:$F$25=AM$5)*([5]Hoja3!$K$6:$K$25=$C14))} -> 0 | AN14: {=SUM([5]Hoja3!$J$6:$J$25*([5]Hoja3!$F$6:$F$25=AM$5)*([5]Hoja3!$K$6:$K$25=$C14))} -> 0 | AO14: =IFERROR(AN14/AM14,0) -> 0 | AP14: {=SUM([5]Hoja3!$I$6:$I$25*([5]Hoja3!$F$6:$F$25=AP$5)*([5]Hoja3!$K$6:$K$25=$C14))} -> 0 | AQ14: {=SUM([5]Hoja3!$J$6:$J$25*([5]Hoja3!$F$6:$F$25=AP$5)*([5]Hoja3!$K$6:$K$25=$C14))} -> 0 | AR14: =IFERROR(AQ14/AP14,0) -> 0 | AS14: {=SUM([5]Hoja3!$I$6:$I$25*([5]Hoja3!$F$6:$F$25=AS$5)*([5]Hoja3!$K$6:$K$25=$C14))} -> 0 | AT14: {=SUM([5]Hoja3!$J$6:$J$25*([5]Hoja3!$F$6:$F$25=AS$5)*([5]Hoja3!$K$6:$K$25=$C14))} -> 0 | AU14: =IFERROR(AT14/AS14,0) -> 0 | AV14: {=SUM([5]Hoja3!$I$6:$I$25*([5]Hoja3!$F$6:$F$25=AV$5)*([5]Hoja3!$K$6:$K$25=$C14))} -> 0 | AW14: {=SUM([5]Hoja3!$J$6:$J$25*([5]Hoja3!$F$6:$F$25=AV$5)*([5]Hoja3!$K$6:$K$25=$C14))} -> 0 | AX14: =IFERROR(AW14/AV14,0) -> 0 | AY14: {=SUM([5]Hoja3!$I$6:$I$25*([5]Hoja3!$F$6:$F$25=AY$5)*([5]Hoja3!$K$6:$K$25=$C14))} -> 0 | AZ14: {=SUM([5]Hoja3!$J$6:$J$25*([5]Hoja3!$F$6:$F$25=AY$5)*([5]Hoja3!$K$6:$K$25=$C14))} -> 0 | BA14: =IFERROR(AZ14/AY14,0) -> 0 | BB14: {=SUM([2]Hoja2!$I$6:$I$26*([2]Hoja2!$F$6:$F$26=BB$5)*([2]Hoja2!$K$6:$K$26=$C14))} -> 0 | BC14: {=SUM([2]Hoja2!$J$6:$J$26*([2]Hoja2!$F$6:$F$26=BB$5)*([2]Hoja2!$K$6:$K$26=$C14))} -> 0 | BD14: =IFERROR(BC14/BB14,0) -> 0 | BE14: {=SUM([2]Hoja2!$I$6:$I$26*([2]Hoja2!$F$6:$F$26=BE$5)*([2]Hoja2!$K$6:$K$26=$C14))} -> 0 | BF14: {=SUM([2]Hoja2!$J$6:$J$26*([2]Hoja2!$F$6:$F$26=BE$5)*([2]Hoja2!$K$6:$K$26=$C14))} -> 0 | BG14: =IFERROR(BF14/BE14,0) -> 0 | BH14: {=SUM([2]Hoja2!$I$6:$I$26*([2]Hoja2!$F$6:$F$26=BH$5)*([2]Hoja2!$K$6:$K$26=$C14))} -> 0 | BI14: {=SUM([2]Hoja2!$J$6:$J$26*([2]Hoja2!$F$6:$F$26=BH$5)*([2]Hoja2!$K$6:$K$26=$C14))} -> 0 | BJ14: =IFERROR(BI14/BH14,0) -> 0 | BK14: {=SUM([2]Hoja2!$I$6:$I$26*([2]Hoja2!$F$6:$F$26=BK$5)*([2]Hoja2!$K$6:$K$26=$C14))} -> 0 | BL14: {=SUM([2]Hoja2!$J$6:$J$26*([2]Hoja2!$F$6:$F$26=BK$5)*([2]Hoja2!$K$6:$K$26=$C14))} -> 0 | BM14: =IFERROR(BL14/BK14,0) -> 0 | BN14: {=SUM([2]Hoja2!$I$6:$I$26*([2]Hoja2!$F$6:$F$26=BN$5)*([2]Hoja2!$K$6:$K$26=$C14))} -> 0 | BO14: {=SUM([2]Hoja2!$J$6:$J$26*([2]Hoja2!$F$6:$F$26=BN$5)*([2]Hoja2!$K$6:$K$26=$C14))} -> 0 | BP14: =IFERROR(BO14/BN14,0) -> 0 | BQ14: {=SUM([2]Hoja2!$I$6:$I$26*([2]Hoja2!$F$6:$F$26=BQ$5)*([2]Hoja2!$K$6:$K$26=$C14))} -> 0 | BR14: {=SUM([2]Hoja2!$J$6:$J$26*([2]Hoja2!$F$6:$F$26=BQ$5)*([2]Hoja2!$K$6:$K$26=$C14))} -> 0 | BS14: =IFERROR(BR14/BQ14,0) -> 0 | BT14: =X14+AA14+AD14+AG14+AJ14+AM14+AP14+AY14+AS14+AV14 -> 0 | BU14: =Y14+AB14+AE14+AH14+AK14+AN14+AQ14+AZ14+AT14+AW14 -> 0 | BV14: =IFERROR(BU14/BT14,0) -> 0 | BW14: =-BT14*'[3]Stock Libre'!H36*1000 -> 0 | BX14: =-207.84*BT14 -> 0 | BY14: =$BY$18/$BT$18*$BT14 -> 0 | BZ14: =$BZ$18/$BT$18*$BT14 -> 0 | CA14: =$CA$18/$BT$18*$BT14 -> 0 | CB14: =(BU14-BT14*$BY$19)*0.03 -> 0 | CC14: =BU14+SUM(BW14:BZ14,CB14) -> 0 | CD14: =IFERROR(CC14/BU14,0) -> 0 | CE14: =BU14+BW14+BX14+BY14+CB14-CA14 -> 0 | CF14: =IFERROR(CE14/BU14,0) -> 0 | CH14: =BV14 -> 0 | CI14: =IFERROR(BW14/$BT14,0) -> 0 | CJ14: =IFERROR(BX14/$BT14,0) -> 0 | CK14: =IFERROR(BY14/$BT14,0) -> 0 | CL14: =IFERROR(BZ14/$BT14,0) -> 0 | CM14: =IFERROR(CA14/$BT14,0) -> 0 | CN14: =IFERROR(CB14/$BT14,0) -> 0 | CO14: =IFERROR(CC14/$BT14,0) -> 0 | CP14: =IFERROR(CE14/$BT14,0) -> 0 | CQ14: =CP14-CO14 -> 0
B15: 10009334 | C15: POTA ALAS COCIDAS | D15: =TD!F12 -> 14.626 | E15: =IFERROR(F15/D15,0) -> 2756.9568 | F15: =TD!G12 -> 40323.25 | G15: =TD!H12 -> 3039.8678 | H15: =TD!I12 -> 659.80193 | I15: =TD!J12 -> 1297.0588 | J15: =TD!K12 -> 1036.8573 | K15: 0 | L15: 0 | M15: =F15+G15+H15+I15 -> 45319.978 | N15: =IFERROR(M15/D15,0) -> 3098.5901 | O15: =F15+G15+H15-J15 -> 42986.062 | P15: =IFERROR(O15/D15,0) -> 2939.017 | Q15: 3500 | R15: =Q15*D15 -> 51191 | S15: =R15-M15+(Q15-$BY$19)*D15*0.03 -> 7356.6527 | T15: =IFERROR(S15/R15,0) -> 0.14370988 | U15: =R15-(M15-J15-I15)+(Q15-$BY$19)*D15*0.03 -> 9690.5689 | V15: =IFERROR(U15/R15,0) -> 0.1893022 | X15: {=SUM([5]Hoja3!$I$6:$I$25*([5]Hoja3!$F$6:$F$25=X$5)*([5]Hoja3!$K$6:$K$25=$C15))} -> 0 | Y15: {=SUM([5]Hoja3!$J$6:$J$25*([5]Hoja3!$F$6:$F$25=X$5)*([5]Hoja3!$K$6:$K$25=$C15))} -> 0 | Z15: =IFERROR(Y15/X15,0) -> 0 | AA15: {=SUM([5]Hoja3!$I$6:$I$25*([5]Hoja3!$F$6:$F$25=AA$5)*([5]Hoja3!$K$6:$K$25=$C15))} -> 0 | AB15: {=SUM([5]Hoja3!$J$6:$J$25*([5]Hoja3!$F$6:$F$25=AA$5)*([5]Hoja3!$K$6:$K$25=$C15))} -> 0 | AC15: =IFERROR(AB15/AA15,0) -> 0 | AD15: {=SUM([5]Hoja3!$I$6:$I$25*([5]Hoja3!$F$6:$F$25=AD$5)*([5]Hoja3!$K$6:$K$25=$C15))} -> 0 | AE15: {=SUM([5]Hoja3!$J$6:$J$25*([5]Hoja3!$F$6:$F$25=AD$5)*([5]Hoja3!$K$6:$K$25=$C15))} -> 0 | AF15: =IFERROR(AE15/AD15,0) -> 0 | AG15: {=SUM([5]Hoja3!$I$6:$I$25*([5]Hoja3!$F$6:$F$25=AG$5)*([5]Hoja3!$K$6:$K$25=$C15))} -> 0 | AH15: {=SUM([5]Hoja3!$J$6:$J$25*([5]Hoja3!$F$6:$F$25=AG$5)*([5]Hoja3!$K$6:$K$25=$C15))} -> 0 | AI15: =IFERROR(AH15/AG15,0) -> 0 | AJ15: {=SUM([5]Hoja3!$I$6:$I$25*([5]Hoja3!$F$6:$F$25=AJ$5)*([5]Hoja3!$K$6:$K$25=$C15))} -> 0 | AK15: {=SUM([5]Hoja3!$J$6:$J$25*([5]Hoja3!$F$6:$F$25=AJ$5)*([5]Hoja3!$K$6:$K$25=$C15))} -> 0 | AL15: =IFERROR(AK15/AJ15,0) -> 0 | AM15: {=SUM([5]Hoja3!$I$6:$I$25*([5]Hoja3!$F$6:$F$25=AM$5)*([5]Hoja3!$K$6:$K$25=$C15))} -> 0 | AN15: {=SUM([5]Hoja3!$J$6:$J$25*([5]Hoja3!$F$6:$F$25=AM$5)*([5]Hoja3!$K$6:$K$25=$C15))} -> 0 | AO15: =IFERROR(AN15/AM15,0) -> 0 | AP15: {=SUM([5]Hoja3!$I$6:$I$25*([5]Hoja3!$F$6:$F$25=AP$5)*([5]Hoja3!$K$6:$K$25=$C15))} -> 0 | AQ15: {=SUM([5]Hoja3!$J$6:$J$25*([5]Hoja3!$F$6:$F$25=AP$5)*([5]Hoja3!$K$6:$K$25=$C15))} -> 0 | AR15: =IFERROR(AQ15/AP15,0) -> 0 | AS15: {=SUM([5]Hoja3!$I$6:$I$25*([5]Hoja3!$F$6:$F$25=AS$5)*([5]Hoja3!$K$6:$K$25=$C15))} -> 0 | AT15: {=SUM([5]Hoja3!$J$6:$J$25*([5]Hoja3!$F$6:$F$25=AS$5)*([5]Hoja3!$K$6:$K$25=$C15))} -> 0 | AU15: =IFERROR(AT15/AS15,0) -> 0 | AV15: {=SUM([5]Hoja3!$I$6:$I$25*([5]Hoja3!$F$6:$F$25=AV$5)*([5]Hoja3!$K$6:$K$25=$C15))} -> 0 | AW15: {=SUM([5]Hoja3!$J$6:$J$25*([5]Hoja3!$F$6:$F$25=AV$5)*([5]Hoja3!$K$6:$K$25=$C15))} -> 0 | AX15: =IFERROR(AW15/AV15,0) -> 0 | AY15: {=SUM([5]Hoja3!$I$6:$I$25*([5]Hoja3!$F$6:$F$25=AY$5)*([5]Hoja3!$K$6:$K$25=$C15))} -> 0 | AZ15: {=SUM([5]Hoja3!$J$6:$J$25*([5]Hoja3!$F$6:$F$25=AY$5)*([5]Hoja3!$K$6:$K$25=$C15))} -> 0 | BA15: =IFERROR(AZ15/AY15,0) -> 0 | BB15: {=SUM([2]Hoja2!$I$6:$I$26*([2]Hoja2!$F$6:$F$26=BB$5)*([2]Hoja2!$K$6:$K$26=$C15))} -> 0 | BC15: {=SUM([2]Hoja2!$J$6:$J$26*([2]Hoja2!$F$6:$F$26=BB$5)*([2]Hoja2!$K$6:$K$26=$C15))} -> 0 | BD15: =IFERROR(BC15/BB15,0) -> 0 | BE15: {=SUM([2]Hoja2!$I$6:$I$26*([2]Hoja2!$F$6:$F$26=BE$5)*([2]Hoja2!$K$6:$K$26=$C15))} -> 0 | BF15: {=SUM([2]Hoja2!$J$6:$J$26*([2]Hoja2!$F$6:$F$26=BE$5)*([2]Hoja2!$K$6:$K$26=$C15))} -> 0 | BG15: =IFERROR(BF15/BE15,0) -> 0 | BH15: {=SUM([2]Hoja2!$I$6:$I$26*([2]Hoja2!$F$6:$F$26=BH$5)*([2]Hoja2!$K$6:$K$26=$C15))} -> 0 | BI15: {=SUM([2]Hoja2!$J$6:$J$26*([2]Hoja2!$F$6:$F$26=BH$5)*([2]Hoja2!$K$6:$K$26=$C15))} -> 0 | BJ15: =IFERROR(BI15/BH15,0) -> 0 | BK15: {=SUM([2]Hoja2!$I$6:$I$26*([2]Hoja2!$F$6:$F$26=BK$5)*([2]Hoja2!$K$6:$K$26=$C15))} -> 0 | BL15: {=SUM([2]Hoja2!$J$6:$J$26*([2]Hoja2!$F$6:$F$26=BK$5)*([2]Hoja2!$K$6:$K$26=$C15))} -> 0 | BM15: =IFERROR(BL15/BK15,0) -> 0 | BN15: {=SUM([2]Hoja2!$I$6:$I$26*([2]Hoja2!$F$6:$F$26=BN$5)*([2]Hoja2!$K$6:$K$26=$C15))} -> 0 | BO15: {=SUM([2]Hoja2!$J$6:$J$26*([2]Hoja2!$F$6:$F$26=BN$5)*([2]Hoja2!$K$6:$K$26=$C15))} -> 0 | BP15: =IFERROR(BO15/BN15,0) -> 0 | BQ15: {=SUM([2]Hoja2!$I$6:$I$26*([2]Hoja2!$F$6:$F$26=BQ$5)*([2]Hoja2!$K$6:$K$26=$C15))} -> 0 | BR15: {=SUM([2]Hoja2!$J$6:$J$26*([2]Hoja2!$F$6:$F$26=BQ$5)*([2]Hoja2!$K$6:$K$26=$C15))} -> 0 | BS15: =IFERROR(BR15/BQ15,0) -> 0 | BT15: =X15+AA15+AD15+AG15+AJ15+AM15+AP15+AY15+AS15+AV15 -> 0 | BU15: =Y15+AB15+AE15+AH15+AK15+AN15+AQ15+AZ15+AT15+AW15 -> 0 | BV15: =IFERROR(BU15/BT15,0) -> 0 | BW15: =-BT15*'[4]Stock Libre'!H47*1000 -> 0 | BX15: =-207.84*BT15 -> 0 | BY15: =$BY$18/$BT$18*$BT15 -> 0 | BZ15: =$BZ$18/$BT$18*$BT15 -> 0 | CA15: =$CA$18/$BT$18*$BT15 -> 0 | CB15: =(BU15-BT15*$BY$19)*0.03 -> 0 | CC15: =BU15+SUM(BW15:BZ15,CB15) -> 0 | CD15: =IFERROR(CC15/BU15,0) -> 0 | CE15: =BU15+BW15+BX15+BY15+CB15-CA15 -> 0 | CF15: =IFERROR(CE15/BU15,0) -> 0 | CH15: =BV15 -> 0 | CI15: =IFERROR(BW15/$BT15,0) -> 0 | CJ15: =IFERROR(BX15/$BT15,0) -> 0 | CK15: =IFERROR(BY15/$BT15,0) -> 0 | CL15: =IFERROR(BZ15/$BT15,0) -> 0 | CM15: =IFERROR(CA15/$BT15,0) -> 0 | CN15: =IFERROR(CB15/$BT15,0) -> 0 | CO15: =IFERROR(CC15/$BT15,0) -> 0 | CP15: =IFERROR(CE15/$BT15,0) -> 0 | CQ15: =CP15-CO15 -> 0
B16: 10009386 | C16: VENTOSAS | D16: =TD!F13 -> 20.7 | E16: =IFERROR(F16/D16,0) -> 1700.0864 | F16: =TD!G13 -> 35191.789 | G16: =TD!H13 -> 4302.288 | H16: =TD!I13 -> 933.80966 | I16: =TD!J13 -> 1835.7116 | J16: =TD!K13 -> 1467.4516 | K16: 0 | L16: 0 | M16: =F16+G16+H16+I16 -> 42263.598 | N16: =IFERROR(M16/D16,0) -> 2041.7197 | O16: =F16+G16+H16-J16 -> 38960.435 | P16: =IFERROR(O16/D16,0) -> 1882.1466 | Q16: 2000 | R16: =Q16*D16 -> 41400 | S16: =R16-M16+(Q16-$BY$19)*D16*0.03 -> 307.49724 | T16: =IFERROR(S16/R16,0) -> 0.0074274695 | U16: =R16-(M16-J16-I16)+(Q16-$BY$19)*D16*0.03 -> 3610.6604 | V16: =IFERROR(U16/R16,0) -> 0.087214019 | X16: {=SUM([5]Hoja3!$I$6:$I$25*([5]Hoja3!$F$6:$F$25=X$5)*([5]Hoja3!$K$6:$K$25=$C16))} -> 0 | Y16: {=SUM([5]Hoja3!$J$6:$J$25*([5]Hoja3!$F$6:$F$25=X$5)*([5]Hoja3!$K$6:$K$25=$C16))} -> 0 | Z16: =IFERROR(Y16/X16,0) -> 0 | AA16: {=SUM([5]Hoja3!$I$6:$I$25*([5]Hoja3!$F$6:$F$25=AA$5)*([5]Hoja3!$K$6:$K$25=$C16))} -> 0 | AB16: {=SUM([5]Hoja3!$J$6:$J$25*([5]Hoja3!$F$6:$F$25=AA$5)*([5]Hoja3!$K$6:$K$25=$C16))} -> 0 | AC16: =IFERROR(AB16/AA16,0) -> 0 | AD16: {=SUM([5]Hoja3!$I$6:$I$25*([5]Hoja3!$F$6:$F$25=AD$5)*([5]Hoja3!$K$6:$K$25=$C16))} -> 0 | AE16: {=SUM([5]Hoja3!$J$6:$J$25*([5]Hoja3!$F$6:$F$25=AD$5)*([5]Hoja3!$K$6:$K$25=$C16))} -> 0 | AF16: =IFERROR(AE16/AD16,0) -> 0 | AG16: {=SUM([5]Hoja3!$I$6:$I$25*([5]Hoja3!$F$6:$F$25=AG$5)*([5]Hoja3!$K$6:$K$25=$C16))} -> 0 | AH16: {=SUM([5]Hoja3!$J$6:$J$25*([5]Hoja3!$F$6:$F$25=AG$5)*([5]Hoja3!$K$6:$K$25=$C16))} -> 0 | AI16: =IFERROR(AH16/AG16,0) -> 0 | AJ16: {=SUM([5]Hoja3!$I$6:$I$25*([5]Hoja3!$F$6:$F$25=AJ$5)*([5]Hoja3!$K$6:$K$25=$C16))} -> 0 | AK16: {=SUM([5]Hoja3!$J$6:$J$25*([5]Hoja3!$F$6:$F$25=AJ$5)*([5]Hoja3!$K$6:$K$25=$C16))} -> 0 | AL16: =IFERROR(AK16/AJ16,0) -> 0 | AM16: {=SUM([5]Hoja3!$I$6:$I$25*([5]Hoja3!$F$6:$F$25=AM$5)*([5]Hoja3!$K$6:$K$25=$C16))} -> 0 | AN16: {=SUM([5]Hoja3!$J$6:$J$25*([5]Hoja3!$F$6:$F$25=AM$5)*([5]Hoja3!$K$6:$K$25=$C16))} -> 0 | AO16: =IFERROR(AN16/AM16,0) -> 0 | AP16: {=SUM([5]Hoja3!$I$6:$I$25*([5]Hoja3!$F$6:$F$25=AP$5)*([5]Hoja3!$K$6:$K$25=$C16))} -> 0 | AQ16: {=SUM([5]Hoja3!$J$6:$J$25*([5]Hoja3!$F$6:$F$25=AP$5)*([5]Hoja3!$K$6:$K$25=$C16))} -> 0 | AR16: =IFERROR(AQ16/AP16,0) -> 0 | AS16: {=SUM([5]Hoja3!$I$6:$I$25*([5]Hoja3!$F$6:$F$25=AS$5)*([5]Hoja3!$K$6:$K$25=$C16))} -> 0 | AT16: {=SUM([5]Hoja3!$J$6:$J$25*([5]Hoja3!$F$6:$F$25=AS$5)*([5]Hoja3!$K$6:$K$25=$C16))} -> 0 | AU16: =IFERROR(AT16/AS16,0) -> 0 | AV16: {=SUM([5]Hoja3!$I$6:$I$25*([5]Hoja3!$F$6:$F$25=AV$5)*([5]Hoja3!$K$6:$K$25=$C16))} -> 0 | AW16: {=SUM([5]Hoja3!$J$6:$J$25*([5]Hoja3!$F$6:$F$25=AV$5)*([5]Hoja3!$K$6:$K$25=$C16))} -> 0 | AX16: =IFERROR(AW16/AV16,0) -> 0 | AY16: {=SUM([5]Hoja3!$I$6:$I$25*([5]Hoja3!$F$6:$F$25=AY$5)*([5]Hoja3!$K$6:$K$25=$C16))} -> 0 | AZ16: {=SUM([5]Hoja3!$J$6:$J$25*([5]Hoja3!$F$6:$F$25=AY$5)*([5]Hoja3!$K$6:$K$25=$C16))} -> 0 | BA16: =IFERROR(AZ16/AY16,0) -> 0 | BB16: {=SUM([2]Hoja2!$I$6:$I$26*([2]Hoja2!$F$6:$F$26=BB$5)*([2]Hoja2!$K$6:$K$26=$C16))} -> 0 | BC16: {=SUM([2]Hoja2!$J$6:$J$26*([2]Hoja2!$F$6:$F$26=BB$5)*([2]Hoja2!$K$6:$K$26=$C16))} -> 0 | BD16: =IFERROR(BC16/BB16,0) -> 0 | BE16: {=SUM([2]Hoja2!$I$6:$I$26*([2]Hoja2!$F$6:$F$26=BE$5)*([2]Hoja2!$K$6:$K$26=$C16))} -> 0 | BF16: {=SUM([2]Hoja2!$J$6:$J$26*([2]Hoja2!$F$6:$F$26=BE$5)*([2]Hoja2!$K$6:$K$26=$C16))} -> 0 | BG16: =IFERROR(BF16/BE16,0) -> 0 | BH16: {=SUM([2]Hoja2!$I$6:$I$26*([2]Hoja2!$F$6:$F$26=BH$5)*([2]Hoja2!$K$6:$K$26=$C16))} -> 0 | BI16: {=SUM([2]Hoja2!$J$6:$J$26*([2]Hoja2!$F$6:$F$26=BH$5)*([2]Hoja2!$K$6:$K$26=$C16))} -> 0 | BJ16: =IFERROR(BI16/BH16,0) -> 0 | BK16: {=SUM([2]Hoja2!$I$6:$I$26*([2]Hoja2!$F$6:$F$26=BK$5)*([2]Hoja2!$K$6:$K$26=$C16))} -> 0 | BL16: {=SUM([2]Hoja2!$J$6:$J$26*([2]Hoja2!$F$6:$F$26=BK$5)*([2]Hoja2!$K$6:$K$26=$C16))} -> 0 | BM16: =IFERROR(BL16/BK16,0) -> 0 | BN16: {=SUM([2]Hoja2!$I$6:$I$26*([2]Hoja2!$F$6:$F$26=BN$5)*([2]Hoja2!$K$6:$K$26=$C16))} -> 0 | BO16: {=SUM([2]Hoja2!$J$6:$J$26*([2]Hoja2!$F$6:$F$26=BN$5)*([2]Hoja2!$K$6:$K$26=$C16))} -> 0 | BP16: =IFERROR(BO16/BN16,0) -> 0 | BQ16: {=SUM([2]Hoja2!$I$6:$I$26*([2]Hoja2!$F$6:$F$26=BQ$5)*([2]Hoja2!$K$6:$K$26=$C16))} -> 0 | BR16: {=SUM([2]Hoja2!$J$6:$J$26*([2]Hoja2!$F$6:$F$26=BQ$5)*([2]Hoja2!$K$6:$K$26=$C16))} -> 0 | BS16: =IFERROR(BR16/BQ16,0) -> 0 | BT16: =X16+AA16+AD16+AG16+AJ16+AM16+AP16+AY16+AS16+AV16 -> 0 | BU16: =Y16+AB16+AE16+AH16+AK16+AN16+AQ16+AZ16+AT16+AW16 -> 0 | BV16: =IFERROR(BU16/BT16,0) -> 0 | BW16: =-IFERROR(F16/D16*BT16,0) -> 0 | BX16: =-207.84*BT16 -> 0 | BY16: =$BY$18/$BT$18*$BT16 -> 0 | BZ16: =$BZ$18/$BT$18*$BT16 -> 0 | CA16: =$CA$18/$BT$18*$BT16 -> 0 | CB16: =(BU16-BT16*$BY$19)*0.03 -> 0 | CC16: =BU16+SUM(BW16:BZ16,CB16) -> 0 | CD16: =IFERROR(CC16/BU16,0) -> 0 | CE16: =BU16+BW16+BX16+BY16+CB16-CA16 -> 0 | CF16: =IFERROR(CE16/BU16,0) -> 0 | CH16: =BV16 -> 0 | CI16: =IFERROR(BW16/$BT16,0) -> 0 | CJ16: =IFERROR(BX16/$BT16,0) -> 0 | CK16: =IFERROR(BY16/$BT16,0) -> 0 | CL16: =IFERROR(BZ16/$BT16,0) -> 0 | CM16: =IFERROR(CA16/$BT16,0) -> 0 | CN16: =IFERROR(CB16/$BT16,0) -> 0 | CO16: =IFERROR(CC16/$BT16,0) -> 0 | CP16: =IFERROR(CE16/$BT16,0) -> 0 | CQ16: =CP16-CO16 -> 0
B17: 10009386 | C17: OTROS | D17: =TD!F14 -> 26.12 | E17: =IFERROR(F17/D17,0) -> 1380.8173 | F17: =TD!G14 -> 36066.948 | G17: =TD!H14 -> 5428.7808 | H17: =TD!I14 -> 1178.3144 | I17: =TD!J14 -> 2316.3665 | J17: =TD!K14 -> 1851.6829 | K17: 0 | L17: 0 | M17: =F17+G17+H17+I17 -> 44990.409 | N17: =IFERROR(M17/D17,0) -> 1722.4506 | O17: =F17+G17+H17-J17 -> 40822.36 | P17: =IFERROR(O17/D17,0) -> 1562.8775 | Q17: 1700 | R17: =Q17*D17 -> 44404 | S17: =R17-M17+(Q17-$BY$19)*D17*0.03 -> 656.2412 | T17: =IFERROR(S17/R17,0) -> 0.014778876 | U17: =R17-(M17-J17-I17)+(Q17-$BY$19)*D17*0.03 -> 4824.2906 | V17: =IFERROR(U17/R17,0) -> 0.1086454 | X17: {=SUM([5]Hoja3!$I$6:$I$25*([5]Hoja3!$F$6:$F$25=X$5)*([5]Hoja3!$K$6:$K$25=$C17))} -> 0 | Y17: {=SUM([5]Hoja3!$J$6:$J$25*([5]Hoja3!$F$6:$F$25=X$5)*([5]Hoja3!$K$6:$K$25=$C17))} -> 0 | Z17: =IFERROR(Y17/X17,0) -> 0 | AA17: {=SUM([5]Hoja3!$I$6:$I$25*([5]Hoja3!$F$6:$F$25=AA$5)*([5]Hoja3!$K$6:$K$25=$C17))} -> 0 | AB17: {=SUM([5]Hoja3!$J$6:$J$25*([5]Hoja3!$F$6:$F$25=AA$5)*([5]Hoja3!$K$6:$K$25=$C17))} -> 0 | AC17: =IFERROR(AB17/AA17,0) -> 0 | AD17: {=SUM([5]Hoja3!$I$6:$I$25*([5]Hoja3!$F$6:$F$25=AD$5)*([5]Hoja3!$K$6:$K$25=$C17))} -> 54 | AE17: {=SUM([5]Hoja3!$J$6:$J$25*([5]Hoja3!$F$6:$F$25=AD$5)*([5]Hoja3!$K$6:$K$25=$C17))} -> 86400 | AF17: =IFERROR(AE17/AD17,0) -> 1600 | AG17: {=SUM([5]Hoja3!$I$6:$I$25*([5]Hoja3!$F$6:$F$25=AG$5)*([5]Hoja3!$K$6:$K$25=$C17))} -> 0 | AH17: {=SUM([5]Hoja3!$J$6:$J$25*([5]Hoja3!$F$6:$F$25=AG$5)*([5]Hoja3!$K$6:$K$25=$C17))} -> 0 | AI17: =IFERROR(AH17/AG17,0) -> 0 | AJ17: {=SUM([5]Hoja3!$I$6:$I$25*([5]Hoja3!$F$6:$F$25=AJ$5)*([5]Hoja3!$K$6:$K$25=$C17))} -> 54 | AK17: {=SUM([5]Hoja3!$J$6:$J$25*([5]Hoja3!$F$6:$F$25=AJ$5)*([5]Hoja3!$K$6:$K$25=$C17))} -> 86400 | AL17: =IFERROR(AK17/AJ17,0) -> 1600 | AM17: {=SUM([5]Hoja3!$I$6:$I$25*([5]Hoja3!$F$6:$F$25=AM$5)*([5]Hoja3!$K$6:$K$25=$C17))} -> 0 | AN17: {=SUM([5]Hoja3!$J$6:$J$25*([5]Hoja3!$F$6:$F$25=AM$5)*([5]Hoja3!$K$6:$K$25=$C17))} -> 0 | AO17: =IFERROR(AN17/AM17,0) -> 0 | AP17: {=SUM([5]Hoja3!$I$6:$I$25*([5]Hoja3!$F$6:$F$25=AP$5)*([5]Hoja3!$K$6:$K$25=$C17))} -> 0 | AQ17: {=SUM([5]Hoja3!$J$6:$J$25*([5]Hoja3!$F$6:$F$25=AP$5)*([5]Hoja3!$K$6:$K$25=$C17))} -> 0 | AR17: =IFERROR(AQ17/AP17,0) -> 0 | AS17: {=SUM([5]Hoja3!$I$6:$I$25*([5]Hoja3!$F$6:$F$25=AS$5)*([5]Hoja3!$K$6:$K$25=$C17))} -> 27 | AT17: {=SUM([5]Hoja3!$J$6:$J$25*([5]Hoja3!$F$6:$F$25=AS$5)*([5]Hoja3!$K$6:$K$25=$C17))} -> 43200 | AU17: =IFERROR(AT17/AS17,0) -> 1600 | AV17: {=SUM([5]Hoja3!$I$6:$I$25*([5]Hoja3!$F$6:$F$25=AV$5)*([5]Hoja3!$K$6:$K$25=$C17))} -> 0 | AW17: {=SUM([5]Hoja3!$J$6:$J$25*([5]Hoja3!$F$6:$F$25=AV$5)*([5]Hoja3!$K$6:$K$25=$C17))} -> 0 | AX17: =IFERROR(AW17/AV17,0) -> 0 | AY17: {=SUM([5]Hoja3!$I$6:$I$25*([5]Hoja3!$F$6:$F$25=AY$5)*([5]Hoja3!$K$6:$K$25=$C17))} -> 54 | AZ17: {=SUM([5]Hoja3!$J$6:$J$25*([5]Hoja3!$F$6:$F$25=AY$5)*([5]Hoja3!$K$6:$K$25=$C17))} -> 86400 | BA17: =IFERROR(AZ17/AY17,0) -> 1600 | BB17: {=SUM([2]Hoja2!$I$6:$I$26*([2]Hoja2!$F$6:$F$26=BB$5)*([2]Hoja2!$K$6:$K$26=$C17))} -> 0 | BC17: {=SUM([2]Hoja2!$J$6:$J$26*([2]Hoja2!$F$6:$F$26=BB$5)*([2]Hoja2!$K$6:$K$26=$C17))} -> 0 | BD17: =IFERROR(BC17/BB17,0) -> 0 | BE17: {=SUM([2]Hoja2!$I$6:$I$26*([2]Hoja2!$F$6:$F$26=BE$5)*([2]Hoja2!$K$6:$K$26=$C17))} -> 0 | BF17: {=SUM([2]Hoja2!$J$6:$J$26*([2]Hoja2!$F$6:$F$26=BE$5)*([2]Hoja2!$K$6:$K$26=$C17))} -> 0 | BG17: =IFERROR(BF17/BE17,0) -> 0 | BH17: {=SUM([2]Hoja2!$I$6:$I$26*([2]Hoja2!$F$6:$F$26=BH$5)*([2]Hoja2!$K$6:$K$26=$C17))} -> 0 | BI17: {=SUM([2]Hoja2!$J$6:$J$26*([2]Hoja2!$F$6:$F$26=BH$5)*([2]Hoja2!$K$6:$K$26=$C17))} -> 0 | BJ17: =IFERROR(BI17/BH17,0) -> 0 | BK17: {=SUM([2]Hoja2!$I$6:$I$26*([2]Hoja2!$F$6:$F$26=BK$5)*([2]Hoja2!$K$6:$K$26=$C17))} -> 0 | BL17: {=SUM([2]Hoja2!$J$6:$J$26*([2]Hoja2!$F$6:$F$26=BK$5)*([2]Hoja2!$K$6:$K$26=$C17))} -> 0 | BM17: =IFERROR(BL17/BK17,0) -> 0 | BN17: {=SUM([2]Hoja2!$I$6:$I$26*([2]Hoja2!$F$6:$F$26=BN$5)*([2]Hoja2!$K$6:$K$26=$C17))} -> 0 | BO17: {=SUM([2]Hoja2!$J$6:$J$26*([2]Hoja2!$F$6:$F$26=BN$5)*([2]Hoja2!$K$6:$K$26=$C17))} -> 0 | BP17: =IFERROR(BO17/BN17,0) -> 0 | BQ17: {=SUM([2]Hoja2!$I$6:$I$26*([2]Hoja2!$F$6:$F$26=BQ$5)*([2]Hoja2!$K$6:$K$26=$C17))} -> 0 | BR17: {=SUM([2]Hoja2!$J$6:$J$26*([2]Hoja2!$F$6:$F$26=BQ$5)*([2]Hoja2!$K$6:$K$26=$C17))} -> 0 | BS17: =IFERROR(BR17/BQ17,0) -> 0 | BT17: =X17+AA17+AD17+AG17+AJ17+AM17+AP17+AY17+AS17+AV17 -> 189 | BU17: =Y17+AB17+AE17+AH17+AK17+AN17+AQ17+AZ17+AT17+AW17 -> 302400 | BV17: =IFERROR(BU17/BT17,0) -> 1600 | BW17: =-IFERROR(F17/D17*BT17,0) -> -260974.47 | BX17: =-207.84*BT17 -> -39281.76 | BY17: =$BY$18/$BT$18*$BT17 -> -16876.626 | BZ17: =$BZ$18/$BT$18*$BT17 -> -33176.588 | CA17: =$CA$18/$BT$18*$BT17 -> -26521.071 | CB17: =(BU17-BT17*$BY$19)*0.03 -> 8424.6129 | CC17: =BU17+SUM(BW17:BZ17,CB17) -> -39484.828 | CD17: =IFERROR(CC17/BU17,0) -> -0.13057152 | CE17: =BU17+BW17+BX17+BY17+CB17-CA17 -> 20212.83 | CF17: =IFERROR(CE17/BU17,0) -> 0.06684137 | CH17: =BV17 -> 1600 | CI17: =IFERROR(BW17/$BT17,0) -> -1380.8173 | CJ17: =IFERROR(BX17/$BT17,0) -> -207.84 | CK17: =IFERROR(BY17/$BT17,0) -> -89.294318 | CL17: =IFERROR(BZ17/$BT17,0) -> -175.5375 | CM17: =IFERROR(CA17/$BT17,0) -> -140.32313 | CN17: =IFERROR(CB17/$BT17,0) -> 44.574672 | CO17: =IFERROR(CC17/$BT17,0) -> -208.91443 | CP17: =IFERROR(CE17/$BT17,0) -> 106.94619 | CQ17: =CP17-CO17 -> 315.86063
