Workbook

Sheet RESUMEN AL 7-9-2026 (2)
C2: PERU FROST
C3: AVANCE COMERCIAL AL 7-9-2026
F5: RENTABILIDAD DEL INVENTARIO
B6: Código | C6: Producto | D6: TM en Stock Libre | E6: CU | F6: Costo Ventas | G6: Gasto Ventas | H6: Gasto ADM | I6: Gasto Fin | J6: Depreciación | K6: Utilidad Neta | L6: Margen Neto | M6: Venta Equilibrio a Utd Neta | N6: Precio Equilibrio x TM a Utd Neta | O6: Venta Equilibro a EBITDA | P6: Precio Equilibrio x TM a EBITDA | Q6: Precio Mercado | R6: Venta total | S6: Utilidad | T6: Mg Neto | U6: EBITDA | V6: Mg EBITDA
B7: 10005721 | C7: POTA FILETE CONGELADO | D7: =TD!F4 -> 66.98 | E7: =IFERROR(F7/D7,0) -> 1831.106 | F7: =TD!G4 -> 122647.48 | G7: =TD!H4 -> 13921.123 | H7: =TD!I4 -> 3685.5951 | I7: =TD!J4 -> 7245.2555 | J7: =TD!K4 -> 5791.7931 | K7: 0 | L7: 0 | M7: =F7+G7+H7+I7 -> 147499.45 | N7: =IFERROR(M7/D7,0) -> 2202.1417 | O7: =F7+G7+H7-J7 -> 134462.41 | P7: =IFERROR(O7/D7,0) -> 2007.5008 | Q7: 1800 | R7: =Q7*D7 -> 120564 | S7: =R7-M7 -> -26935.454 | T7: =IFERROR(S7/R7,0) -> -0.22341208 | U7: =R7-(M7-J7-I7) -> -13898.405 | V7: =IFERROR(U7/R7,0) -> -0.11527823
B8: 10005779 | C8: POTA NUCAS CONGELADAS | D8: =TD!F5 -> 384.74 | E8: =IFERROR(F8/D8,0) -> 1793.326 | F8: =TD!G5 -> 689964.25 | G8: =TD!H5 -> 79964.362 | H8: =TD!I5 -> 21170.437 | I8: =TD!J5 -> 41617.492 | J8: =TD!K5 -> 33268.655 | K8: 0 | L8: 0 | M8: =F8+G8+H8+I8 -> 832716.54 | N8: =IFERROR(M8/D8,0) -> 2164.3617 | O8: =F8+G8+H8-J8 -> 757830.39 | P8: =IFERROR(O8/D8,0) -> 1969.7208 | Q8: 1400 | R8: =Q8*D8 -> 538636 | S8: =R8-M8 -> -294080.54 | T8: =IFERROR(S8/R8,0) -> -0.54597267 | U8: =R8-(M8-J8-I8) -> -219194.39 | V8: =IFERROR(U8/R8,0) -> -0.40694344
B9: 10006719 | C9: POTA ALAS CONGELADAS | D9: =TD!F6 -> 17.86 | E9: =IFERROR(F9/D9,0) -> 1652.036 | F9: =TD!G6 -> 29505.363 | G9: =TD!H6 -> 3712.0224 | H9: =TD!I6 -> 982.75199 | I9: =TD!J6 -> 1931.9239 | J9: =TD!K6 -> 1544.3629 | K9: 0 | L9: 0 | M9: =F9+G9+H9+I9 -> 36132.061 | N9: =IFERROR(M9/D9,0) -> 2023.0717 | O9: =F9+G9+H9-J9 -> 32655.774 | P9: =IFERROR(O9/D9,0) -> 1828.4308 | Q9: 1950 | R9: =Q9*D9 -> 34827 | S9: =R9-M9 -> -1305.0612 | T9: =IFERROR(S9/R9,0) -> -0.037472686 | U9: =R9-(M9-J9-I9) -> 2171.2255 | V9: =IFERROR(U9/R9,0) -> 0.062343168
B10: 10007050 | C10: POTA RECORTES COCIDOS | D10: =TD!F7 -> 138.718 | E10: =IFERROR(F10/D10,0) -> 2246.62 | F10: =TD!G7 -> 311646.63 | G10: =TD!H7 -> 28831.149 | H10: =TD!I7 -> 7633.0006 | I10: =TD!J7 -> 15005.186 | J10: =TD!K7 -> 11995.013 | K10: 0 | L10: 0 | M10: =F10+G10+H10+I10 -> 363115.97 | N10: =IFERROR(M10/D10,0) -> 2617.6557 | O10: =F10+G10+H10-J10 -> 336115.77 | P10: =IFERROR(O10/D10,0) -> 2423.0148 | Q10: 1700 | R10: =Q10*D10 -> 235820.6 | S10: =R10-M10 -> -127295.37 | T10: =IFERROR(S10/R10,0) -> -0.53979749 | U10: =R10-(M10-J10-I10) -> -100295.17 | V10: =IFERROR(U10/R10,0) -> -0.42530284
B11: 10007162 | C11: POTA REJOS CONGELADOS | D11: =TD!F8 -> 297.72 | E11: =IFERROR(F11/D11,0) -> 1783.985 | F11: =TD!G8 -> 531128.01 | G11: =TD!H8 -> 61878.125 | H11: =TD!I8 -> 16382.134 | I11: =TD!J8 -> 32204.501 | J11: =TD!K8 -> 25743.993 | K11: 0 | L11: 0 | M11: =F11+G11+H11+I11 -> 641592.77 | N11: =IFERROR(M11/D11,0) -> 2155.0207 | O11: =F11+G11+H11-J11 -> 583644.28 | P11: =IFERROR(O11/D11,0) -> 1960.3798 | Q11: 2700 | R11: =Q11*D11 -> 803844 | S11: =R11-M11 -> 162251.23 | T11: =IFERROR(S11/R11,0) -> 0.20184417 | U11: =R11-(M11-J11-I11) -> 220199.72 | V11: =IFERROR(U11/R11,0) -> 0.2739334
B12: 10007567 | C12: POTA REPRODUCTORES | D12: =TD!F9 -> 110.22 | E12: =IFERROR(F12/D12,0) -> 1712.173 | F12: =TD!G9 -> 188715.71 | G12: =TD!H9 -> 22908.125 | H12: =TD!I9 -> 6064.8894 | I12: =TD!J9 -> 11922.545 | J12: =TD!K9 -> 9530.7769 | K12: 0 | L12: 0 | M12: =F12+G12+H12+I12 -> 229611.27 | N12: =IFERROR(M12/D12,0) -> 2083.2087 | O12: =F12+G12+H12-J12 -> 208157.95 | P12: =IFERROR(O12/D12,0) -> 1888.5678 | Q12: 2800 | R12: =Q12*D12 -> 308616 | S12: =R12-M12 -> 79004.733 | T12: =IFERROR(S12/R12,0) -> 0.25599688 | U12: =R12-(M12-J12-I12) -> 100458.05 | V12: =IFERROR(U12/R12,0) -> 0.32551149
B13: 10007969 | C13: POTA CONOS | D13: =TD!F10 -> 0 | E13: =IFERROR(F13/D13,0) -> 0 | F13: =TD!G10 -> 0 | G13: =TD!H10 -> 0 | H13: =TD!I10 -> 0 | I13: =TD!J10 -> 0 | J13: =TD!K10 -> 0 | K13: 0 | L13: 0 | M13: =F13+G13+H13+I13 -> 0 | N13: =IFERROR(M13/D13,0) -> 0 | O13: =F13+G13+H13-J13 -> 0 | P13: =IFERROR(O13/D13,0) -> 0 | Q13: 1700 | R13: =Q13*D13 -> 0 | S13: =R13-M13 -> 0 | T13: =IFERROR(S13/R13,0) -> 0 | U13: =R13-(M13-J13-I13) -> 0 | V13: =IFERROR(U13/R13,0) -> 0
B14: 10009239 | C14: POTA FILETE DARUMA | D14: =TD!F11 -> 16.48 | E14: =IFERROR(F14/D14,0) -> 2846.957 | F14: =TD!G11 -> 46917.851 | G14: =TD!H11 -> 3425.2032 | H14: =TD!I11 -> 906.81706 | I14: =TD!J11 -> 1782.6487 | J14: =TD!K11 -> 1425.0336 | K14: 0 | L14: 0 | M14: =F14+G14+H14+I14 -> 53032.52 | N14: =IFERROR(M14/D14,0) -> 3217.9927 | O14: =F14+G14+H14-J14 -> 49824.838 | P14: =IFERROR(O14/D14,0) -> 3023.3518 | Q14: 3500 | R14: =Q14*D14 -> 57680 | S14: =R14-M14 -> 4647.4797 | T14: =IFERROR(S14/R14,0) -> 0.080573503 | U14: =R14-(M14-J14-I14) -> 7855.162 | V14: =IFERROR(U14/R14,0) -> 0.13618519
B15: 10009334 | C15: POTA ALAS COCIDAS | D15: =TD!F12 -> 329.458 | E15: =IFERROR(F15/D15,0) -> 2574.823 | F15: =TD!G12 -> 848296.04 | G15: =TD!H12 -> 68474.551 | H15: =TD!I12 -> 18128.528 | I15: =TD!J12 -> 35637.614 | J15: =TD!K12 -> 28488.393 | K15: 0 | L15: 0 | M15: =F15+G15+H15+I15 -> 970536.73 | N15: =IFERROR(M15/D15,0) -> 2945.8587 | O15: =F15+G15+H15-J15 -> 906410.72 | P15: =IFERROR(O15/D15,0) -> 2751.2178 | Q15: 3500 | R15: =Q15*D15 -> 1153103 | S15: =R15-M15 -> 182566.27 | T15: =IFERROR(S15/R15,0) -> 0.15832607 | U15: =R15-(M15-J15-I15) -> 246692.28 | V15: =IFERROR(U15/R15,0) -> 0.21393777
B16: 10009386 | C16: VENTOSAS | D16: =TD!F13 -> 21.28 | E16: =IFERROR(F16/D16,0) -> 3230.8044 | F16: =TD!G13 -> 68751.518 | G16: =TD!H13 -> 4422.8352 | H16: =TD!I13 -> 1170.9385 | I16: =TD!J13 -> 2301.8668 | J16: =TD!K13 -> 1840.0919 | K16: 0 | L16: 0 | M16: =F16+G16+H16+I16 -> 76647.158 | N16: =IFERROR(M16/D16,0) -> 3601.8401 | O16: =F16+G16+H16-J16 -> 72505.2 | P16: =IFERROR(O16/D16,0) -> 3407.1992 | Q16: 2000 | R16: =Q16*D16 -> 42560 | S16: =R16-M16 -> -34087.158 | T16: =IFERROR(S16/R16,0) -> -0.80092007 | U16: =R16-(M16-J16-I16) -> -29945.2 | V16: =IFERROR(U16/R16,0) -> -0.70359962
B17: 10009386 | C17: OTROS | D17: =TD!F14+TD!F17+TD!F18+TD!F19 -> 41.116 | E17: =IFERROR(F17/D17,0) -> 1588.6756 | F17: =TD!G14+TD!G17+TD!G18+TD!G19 -> 65319.987 | G17: =TD!H14+TD!H17+TD!H18+TD!H19 -> 8545.5494 | H17: =TD!I14+TD!I17+TD!I18+TD!I19 -> 2262.4205 | I17: =TD!J14+TD!J17+TD!J18+TD!J19 -> 4447.5354 | J17: =TD!K14+TD!K17+TD!K18+TD!K19 -> 3555.3205 | K17: 0 | L17: 0 | M17: =F17+G17+H17+I17 -> 80575.492 | N17: =IFERROR(M17/D17,0) -> 1959.7114 | O17: =F17+G17+H17-J17 -> 72572.636 | P17: =IFERROR(O17/D17,0) -> 1765.0704 | Q17: 1700 | R17: =Q17*D17 -> 69897.2 | S17: =R17-M17 -> -10678.292 | T17: =IFERROR(S17/R17,0) -> -0.15277139 | U17: =R17-(M17-J17-I17) -> -2675.4364 | V17: =IFERROR(U17/R17,0) -> -0.038276733
C18: FILETE PARA REPROCESO | D18: =TD!F15 -> 3.48 | E18: =IFERROR(F18/D18,0) -> 1831.106 | F18: =TD!G15 -> 6372.2489 | G18: =TD!H15 -> 723.2832 | H18: =TD!I15 -> 191.48807 | I18: =TD!J15 -> 376.4331 | J18: =TD!K15 -> 300.91729 | K18: 0 | L18: 0 | M18: =F18+G18+H18+I18 -> 7663.4532 | N18: =IFERROR(M18/D18,0) -> 2202.1417 | O18: =F18+G18+H18-J18 -> 6986.1029 | P18: =IFERROR(O18/D18,0) -> 2007.5008 | Q18: 1800 | R18: =Q18*D18 -> 6264 | S18: =R18-M18 -> -1399.4532 | T18: =IFERROR(S18/R18,0) -> -0.22341208 | U18: =R18-(M18-J18-I18) -> -722.10286 | V18: =IFERROR(U18/R18,0) -> -0.11527823
C19: ALAS PARA REPROCESO | D19: =TD!F16 -> 0 | E19: =IFERROR(F19/D19,0) -> 0 | F19: =TD!G16 -> 0 | G19: =TD!H16 -> 0 | H19: =TD!I16 -> 0 | I19: =TD!J16 -> 0 | J19: =TD!K16 -> 0 | K19: 0 | L19: 0 | M19: =F19+G19+H19+I19 -> 0 | N19: =IFERROR(M19/D19,0) -> 0 | O19: =F19+G19+H19-J19 -> 0 | P19: =IFERROR(O19/D19,0) -> 0 | Q19: 1950 | R19: =Q19*D19 -> 0 | S19: =R19-M19 -> 0 | T19: =IFERROR(S19/R19,0) -> 0 | U19: =R19-(M19-J19-I19) -> 0 | V19: =IFERROR(U19/R19,0) -> 0
C20: TOTAL | D20: =SUM(D7:D19) -> 1428.052 | E20: =IFERROR(F20/D20,0) -> 2037.2263 | F20: =SUM(F7:F19) -> 2909265.1 | G20: =SUM(G7:G19) -> 296806.33 | H20: =SUM(H7:H19) -> 78579 | I20: =SUM(I7:I19) -> 154473 | J20: =SUM(J7:J19) -> 123484.35 | K20: =SUM(K7:K19) -> 0 | L20: 0 | M20: =SUM(M7:M19) -> 3439123.4 | N20: =IFERROR(M20/D20,0) -> 2408.262 | O20: =SUM(O7:O19) -> 3161166.1 | P20: =IFERROR(O20/D20,0) -> 2213.6211 | Q20: =R20/D20 -> 2361.1268 | R20: =SUM(R7:R19) -> 3371811.8 | S20: =SUM(S7:S19) -> -67311.612 | T20: =S20/R20 -> -0.019963039 | U20: =SUM(U7:U19) -> 210645.74 | V20: =IFERROR(U20/R20,0) -> 0.062472567
C22: TM en Almacén de Yantai Jiahong | R22: =7%/12 -> 0.0058333333
R23: =R22*M31 -> 21753.62 | S23: =R23*7 -> 152275.34 | T23: =S23/D31 -> 108.52779
C24: Producto | D24: TM en Stock Libre | E24: CU | F24: Costo Ventas | G24: Gasto Ventas | H24: Gasto ADM | I24: Gasto Fin | J24: Depreciación | K24: Utilidad Neta | L24: Margen Neto | M24: Venta Equilibrio a Utd Neta | N24: Precio Equilibrio x TM a Utd Neta | O24: Venta Equilibro a EBITDA | P24: Precio Equilibrio x TM a EBITDA | Q24: Precio Mercado | R24: Venta total | S24: Utilidad | T24: Mg Neto | U24: EBITDA | V24: Mg EBITDA
C25: POTA FILETE CONGELADO | D25: 567 | E25: =E7 -> 1831.106 | F25: =E25*D25 -> 1038237.1 | G25: =D25*207.84 -> 117845.28 | H25: =H$20/$D$20*$D25 -> 31199.349 | I25: =I$20/$D$20*$D25 -> 61332.634 | J25: =J$20/$D$20*$D25 -> 49028.765 | K25: 0 | L25: 0 | M25: =F25+G25+H25+I25 -> 1248614.4 | N25: =IFERROR(M25/D25,0) -> 2202.1417 | O25: =F25+G25+H25-J25 -> 1138253 | P25: =IFERROR(O25/D25,0) -> 2007.5008 | Q25: 1500 | R25: =Q25*D25 -> 850500 | S25: =R25-M25 -> -398114.37 | T25: =IFERROR(S25/R25,0) -> -0.46809449 | U25: =R25-(M25-J25-I25) -> -287752.97 | V25: =IFERROR(U25/R25,0) -> -0.33833388
C26: POTA ALAS CONGELADAS | D26: 54 | E26: =E9 -> 1652.036 | F26: =E26*D26 -> 89209.944 | G26: =D26*207.84 -> 11223.36 | H26: =H$20/$D$20*$D26 -> 2971.3666 | I26: =I$20/$D$20*$D26 -> 5841.2033 | J26: =J$20/$D$20*$D26 -> 4669.4062 | K26: 0 | L26: 0 | M26: =F26+G26+H26+I26 -> 109245.87 | N26: =IFERROR(M26/D26,0) -> 2023.0717 | O26: =F26+G26+H26-J26 -> 98735.264 | P26: =IFERROR(O26/D26,0) -> 1828.4308 | Q26: 1700 | R26: =Q26*D26 -> 91800 | S26: =R26-M26 -> -17445.874 | T26: =IFERROR(S26/R26,0) -> -0.1900422 | U26: =R26-(M26-J26-I26) -> -6935.2644
C27: POTA REJOS CONGELADOS | D27: 108 | E27: =E11 -> 1783.985 | F27: =E27*D27 -> 192670.38 | G27: =D27*207.84 -> 22446.72 | H27: =H$20/$D$20*$D27 -> 5942.7332 | I27: =I$20/$D$20*$D27 -> 11682.407 | J27: =J$20/$D$20*$D27 -> 9338.8125 | K27: 0 | L27: 0 | M27: =F27+G27+H27+I27 -> 232742.24 | N27: =IFERROR(M27/D27,0) -> 2155.0207 | O27: =F27+G27+H27-J27 -> 211721.02 | P27: =IFERROR(O27/D27,0) -> 1960.3798 | Q27: 2275 | R27: =Q27*D27 -> 245700 | S27: =R27-M27 -> 12957.76 | T27: =IFERROR(S27/R27,0) -> 0.052738137 | U27: =R27-(M27-J27-I27) -> 33978.979 | V27: =IFERROR(U27/R27,0) -> 0.13829458
C28: POTA FILETE DARUMA | D28: 594 | E28: =E14 -> 2846.957 | F28: =E28*D28 -> 1691092.5 | G28: =D28*207.84 -> 123456.96 | H28: =H$20/$D$20*$D28 -> 32685.032 | I28: =I$20/$D$20*$D28 -> 64253.236 | J28: =J$20/$D$20*$D28 -> 51363.468 | K28: 0 | L28: 0 | M28: =F28+G28+H28+I28 -> 1911487.7 | N28: =IFERROR(M28/D28,0) -> 3217.9927 | O28: =F28+G28+H28-J28 -> 1795871 | P28: =IFERROR(O28/D28,0) -> 3023.3518 | Q28: 3400 | R28: =Q28*D28 -> 2019600 | S28: =R28-M28 -> 108112.31 | T28: =IFERROR(S28/R28,0) -> 0.053531548 | U28: =R28-(M28-J28-I28) -> 223729.02 | V28: =IFERROR(U28/R28,0) -> 0.11077888
C29: POTA ALAS COCIDAS | D29: 53.1 | E29: =E15 -> 2574.823 | F29: =E29*D29 -> 136723.1 | G29: =D29*207.84 -> 11036.304 | H29: =H$20/$D$20*$D29 -> 2921.8438 | I29: =I$20/$D$20*$D29 -> 5743.8499 | J29: =J$20/$D$20*$D29 -> 4591.5828 | K29: 0 | L29: 0 | M29: =F29+G29+H29+I29 -> 156425.1 | N29: =IFERROR(M29/D29,0) -> 2945.8587 | O29: =F29+G29+H29-J29 -> 146089.67 | P29: =IFERROR(O29/D29,0) -> 2751.2178 | Q29: 3400 | R29: =Q29*D29 -> 180540 | S29: =R29-M29 -> 24114.901 | T29: =IFERROR(S29/R29,0) -> 0.13357096 | U29: =R29-(M29-J29-I29) -> 34450.334
C30: POTA RECORTES COCIDOS | D30: 27 | E30: =E10 -> 2246.62 | F30: =E30*D30 -> 60658.74 | G30: =D30*207.84 -> 5611.68 | H30: =H$20/$D$20*$D30 -> 1485.6833 | I30: =I$20/$D$20*$D30 -> 2920.6016 | J30: =J$20/$D$20*$D30 -> 2334.7031 | K30: 0 | L30: 0 | M30: =F30+G30+H30+I30 -> 70676.705 | N30: =IFERROR(M30/D30,0) -> 2617.6557 | O30: =F30+G30+H30-J30 -> 65421.4 | P30: =IFERROR(O30/D30,0) -> 2423.0148 | Q30: 1800 | R30: =Q30*D30 -> 48600 | S30: =R30-M30 -> -22076.705 | T30: =IFERROR(S30/R30,0) -> -0.45425319 | U30: =R30-(M30-J30-I30) -> -16821.4
C31: TOTAL | D31: =SUM(D25:D30) -> 1403.1 | E31: =F31/D31 -> 2286.7876 | F31: =SUM(F25:F30) -> 3208591.7 | G31: =SUM(G25:G30) -> 291620.3 | H31: =SUM(H25:H30) -> 77206.009 | I31: =SUM(I25:I30) -> 151773.93 | J31: =SUM(J25:J30) -> 121326.74 | K31: =SUM(K25:K30) -> 0 | L31: 0 | M31: =SUM(M25:M30) -> 3729192 | N31: =IFERROR(M31/D31,0) -> 2657.8234 | O31: =SUM(O25:O30) -> 3456091.3 | P31: =IFERROR(O31/D31,0) -> 2463.1825 | Q31: =R31/D31 -> 2449.3906 | R31: =SUM(R25:R30) -> 3436740 | S31: =SUM(S25:S30) -> -292451.97 | T31: =S31/R31 -> -0.08509575 | U31: =SUM(U25:U30) -> -19351.299 | V31: =IFERROR(U31/R31,0) -> -0.0056307138
C33: TOTAL | D33: =D20+D31 -> 2831.152 | E33: =F33/D33 -> 2160.9072 | F33: =F20+F31 -> 6117856.8 | G33: =G20+G31 -> 588426.63 | H33: =H20+H31 -> 155785.01 | I33: =I20+I31 -> 306246.93 | J33: =J20+J31 -> 244811.09 | K33: =K20+K31 -> 0 | L33: =L20+L31 -> 0 | M33: =M20+M31 -> 7168315.4 | N33: =IFERROR(M33/D33,0) -> 2531.943 | O33: =O20+O31 -> 6617257.4 | P33: =IFERROR(O33/D33,0) -> 2337.302 | Q33: =R33/D33 -> 2404.8697 | R33: =R20+R31 -> 6808551.8 | S33: =S20+S31 -> -359763.58 | T33: =S33/R33 -> -0.052839957 | U33: =U20+U31 -> 191294.44 | V33: =IFERROR(U33/R33,0) -> 0.028096201
C36: INVENTARIO TOTAL VALORIZADO
C38: Producto | D38: TM en Stock Libre | E38: CU | F38: Costo Ventas | G38: Gasto Ventas | H38: Gasto ADM | I38: Gasto Fin | J38: Depreciación | K38: Utilidad Neta | L38: Margen Neto | M38: Venta Equilibrio a Utd Neta | N38: Precio Equilibrio x TM a Utd Neta | O38: Precio Venta | P38: Venta Esperada | Q38: Utilidad Neta | R38: Margen Neto | S38: Precio actual | T38: venta con precio actual | U38: P/L | V38: variación | W38: ebtida
C39: POTA FILETE CONGELADO | D39: =D7+D25 -> 633.98 | E39: =IFERROR(F39/D39,0) -> 1831.106 | F39: =F7+F25 -> 1160884.6 | G39: =G7+G25 -> 131766.4 | H39: =H7+H25 -> 34884.944 | I39: =I7+I25 -> 68577.89 | J39: =J7+J25 -> 54820.559 | K39: 0 | L39: 0 | M39: =F39+G39+H39+I39 -> 1396113.8 | N39: =IFERROR(M39/D39,0) -> 2202.1417 | O39: 1670 | P39: =O39*D39 -> 1058746.6 | Q39: =P39-M39 -> -337367.22 | R39: =Q39/P39 -> -0.31864775 | S39: =Q25 -> 1500 | T39: =S39*D39 -> 950970 | U39: =T39-M39 -> -445143.82 | V39: =Q39-U39 -> 107776.6 | W39: =Q39+I39+J39 -> -213968.77
C40: POTA NUCAS CONGELADAS | D40: =D8 -> 384.74 | E40: =IFERROR(F40/D40,0) -> 1793.326 | F40: =F8 -> 689964.25 | G40: =G8 -> 79964.362 | H40: =H8 -> 21170.437 | I40: =I8 -> 41617.492 | J40: =J8 -> 33268.655 | K40: 0 | L40: 0 | M40: =F40+G40+H40+I40 -> 832716.54 | N40: =IFERROR(M40/D40,0) -> 2164.3617 | O40: 1370 | P40: =O40*D40 -> 527093.8 | Q40: =P40-M40 -> -305622.74 | R40: =Q40/P40 -> -0.57982609 | S40: =Q8 -> 1400 | T40: =S40*D40 -> 538636 | U40: =T40-M40 -> -294080.54 | V40: =Q40-U40 -> -11542.2 | W40: =Q40+I40+J40 -> -230736.59
C41: POTA ALAS CONGELADAS | D41: =D9+D26 -> 71.86 | E41: =IFERROR(F41/D41,0) -> 1652.036 | F41: =F9+F26 -> 118715.31 | G41: =G9+G26 -> 14935.382 | H41: =H9+H26 -> 3954.1186 | I41: =I9+I26 -> 7773.1272 | J41: =J9+J26 -> 6213.7691 | K41: 0 | L41: 0 | M41: =F41+G41+H41+I41 -> 145377.94 | N41: =IFERROR(M41/D41,0) -> 2023.0717 | O41: 1900 | P41: =O41*D41 -> 136534 | Q41: =P41-M41 -> -8843.9351 | R41: =Q41/P41 -> -0.064774599 | S41: =Q9 -> 1950 | T41: =S41*D41 -> 140127 | U41: =T41-M41 -> -5250.9351 | V41: =Q41-U41 -> -3593 | W41: =Q41+I41+J41 -> 5142.9612
C42: POTA RECORTES COCIDOS | D42: =D10+D30 -> 165.718 | E42: =IFERROR(F42/D42,0) -> 2246.62 | F42: =F10+F30 -> 372305.37 | G42: =G10+G30 -> 34442.829 | H42: =H10+H30 -> 9118.6839 | I42: =I10+I30 -> 17925.787 | J42: =J10+J30 -> 14329.716 | K42: 0 | L42: 0 | M42: =F42+G42+H42+I42 -> 433792.67 | N42: =IFERROR(M42/D42,0) -> 2617.6557 | O42: 1500 | P42: =O42*D42 -> 248577 | Q42: =P42-M42 -> -185215.67 | R42: =Q42/P42 -> -0.74510383 | S42: =Q10 -> 1700 | T42: =S42*D42 -> 281720.6 | U42: =T42-M42 -> -152072.07 | V42: =Q42-U42 -> -33143.6 | W42: =Q42+I42+J42 -> -152960.17
C43: POTA REJOS CONGELADOS | D43: =D11+D27 -> 405.72 | E43: =IFERROR(F43/D43,0) -> 1783.985 | F43: =F11+F27 -> 723798.39 | G43: =G11+G27 -> 84324.845 | H43: =H11+H27 -> 22324.868 | I43: =I11+I27 -> 43886.907 | J43: =J11+J27 -> 35082.805 | K43: 0 | L43: 0 | M43: =F43+G43+H43+I43 -> 874335.01 | N43: =IFERROR(M43/D43,0) -> 2155.0207 | O43: 2580 | P43: =O43*D43 -> 1046757.6 | Q43: =P43-M43 -> 172422.59 | R43: =Q43/P43 -> 0.16472064 | S43: =Q11 -> 2700 | T43: =S43*D43 -> 1095444 | U43: =T43-M43 -> 221108.99 | V43: =Q43-U43 -> -48686.4 | W43: =Q43+I43+J43 -> 251392.3
C44: POTA REPRODUCTORES | D44: =D12 -> 110.22 | E44: =IFERROR(F44/D44,0) -> 1712.173 | F44: =F12 -> 188715.71 | G44: =G12 -> 22908.125 | H44: =H12 -> 6064.8894 | I44: =I12 -> 11922.545 | J44: =J12 -> 9530.7769 | K44: 0 | L44: 0 | M44: =F44+G44+H44+I44 -> 229611.27 | N44: =IFERROR(M44/D44,0) -> 2083.2087 | O44: 2580 | P44: =O44*D44 -> 284367.6 | Q44: =P44-M44 -> 54756.333 | R44: =Q44/P44 -> 0.19255475 | S44: =Q12 -> 2800 | T44: =S44*D44 -> 308616 | U44: =T44-M44 -> 79004.733 | V44: =Q44-U44 -> -24248.4 | W44: =Q44+I44+J44 -> 76209.655
C45: POTA CONOS | D45: =D13 -> 0 | E45: =IFERROR(F45/D45,0) -> 0 | F45: =F13 -> 0 | G45: =G13 -> 0 | H45: =H13 -> 0 | I45: =I13 -> 0 | J45: =J13 -> 0 | K45: 0 | L45: 0 | M45: =F45+G45+H45+I45 -> 0 | N45: =IFERROR(M45/D45,0) -> 0 | O45: 1750 | P45: =O45*D45 -> 0 | Q45: =P45-M45 -> 0 | R45: =Q45/P45 -> #DIV/0! | S45: =Q13 -> 1700 | T45: =S45*D45 -> 0 | U45: =T45-M45 -> 0 | V45: =Q45-U45 -> 0 | W45: =Q45+I45+J45 -> 0
C46: POTA FILETE DARUMA | D46: =D14+D28+D18 -> 613.96 | E46: =IFERROR(F46/D46,0) -> 2841.199 | F46: =F14+F28+F18 -> 1744382.6 | G46: =G14+G28+G18 -> 127605.45 | H46: =H14+H28+H18 -> 33783.338 | I46: =I14+I28+I18 -> 66412.318 | J46: =J14+J28+J18 -> 53089.419 | K46: 0 | L46: 0 | M46: =F46+G46+H46+I46 -> 1972183.7 | N46: =IFERROR(M46/D46,0) -> 3212.2348 | O46: 3300 | P46: =O46*D46 -> 2026068 | Q46: =P46-M46 -> 53884.34 | R46: =Q46/P46 -> 0.026595524 | S46: =Q14 -> 3500 | T46: =S46*D46 -> 2148860 | U46: =T46-M46 -> 176676.34 | V46: =Q46-U46 -> -122792 | W46: =Q46+I46+J46 -> 173386.08
C47: POTA ALAS COCIDAS | D47: =D15+D29+D19 -> 382.558 | E47: =IFERROR(F47/D47,0) -> 2574.823 | F47: =F15+F29+F19 -> 985019.14 | G47: =G15+G29+G19 -> 79510.855 | H47: =H15+H29+H19 -> 21050.371 | I47: =I15+I29+I19 -> 41381.464 | J47: =J15+J29+J19 -> 33079.976 | K47: 0 | L47: 0 | M47: =F47+G47+H47+I47 -> 1126961.8 | N47: =IFERROR(M47/D47,0) -> 2945.8587 | O47: 3300 | P47: =O47*D47 -> 1262441.4 | Q47: =P47-M47 -> 135479.57 | R47: =Q47/P47 -> 0.10731553 | S47: =Q15 -> 3500 | T47: =S47*D47 -> 1338953 | U47: =T47-M47 -> 211991.17 | V47: =Q47-U47 -> -76511.6 | W47: =Q47+I47+J47 -> 209941.01
...

Sheet RESUMEN AL 7-9-2026
C2: PERU FROST
C3: AVANCE COMERCIAL AL 7-9-2026
F5: RENTABILIDAD DEL INVENTARIO
B6: Código | C6: Producto | D6: TM en Stock Libre | E6: CU | F6: Costo Ventas | G6: Gasto Ventas | H6: Gasto ADM | I6: Gasto Fin | J6: Depreciación | K6: Utilidad Neta | L6: Margen Neto | M6: Venta Equilibrio a Utd Neta | N6: Precio Equilibrio x TM a Utd Neta | O6: Venta Equilibro a EBITDA | P6: Precio Equilibrio x TM a EBITDA | Q6: Precio Mercado | R6: Venta total | S6: Utilidad | T6: Mg Neto | U6: EBITDA | V6: Mg EBITDA
B7: 10005721 | C7: POTA FILETE CONGELADO | D7: =TD!F4 -> 66.98 | E7: =IFERROR(F7/D7,0) -> 1831.106 | F7: =TD!G4 -> 122647.48 | G7: =TD!H4 -> 13921.123 | H7: =TD!I4 -> 3685.5951 | I7: =TD!J4 -> 7245.2555 | J7: =TD!K4 -> 5791.7931 | K7: 0 | L7: 0 | M7: =F7+G7+H7+I7 -> 147499.45 | N7: =IFERROR(M7/D7,0) -> 2202.1417 | O7: =F7+G7+H7-J7 -> 134462.41 | P7: =IFERROR(O7/D7,0) -> 2007.5008 | Q7: 1800 | R7: =Q7*D7 -> 120564 | S7: =R7-M7 -> -26935.454 | T7: =IFERROR(S7/R7,0) -> -0.22341208 | U7: =R7-(M7-J7-I7) -> -13898.405 | V7: =IFERROR(U7/R7,0) -> -0.11527823
B8: 10005779 | C8: POTA NUCAS CONGELADAS | D8: =TD!F5 -> 384.74 | E8: =IFERROR(F8/D8,0) -> 1793.326 | F8: =TD!G5 -> 689964.25 | G8: =TD!H5 -> 79964.362 | H8: =TD!I5 -> 21170.437 | I8: =TD!J5 -> 41617.492 | J8: =TD!K5 -> 33268.655 | K8: 0 | L8: 0 | M8: =F8+G8+H8+I8 -> 832716.54 | N8: =IFERROR(M8/D8,0) -> 2164.3617 | O8: =F8+G8+H8-J8 -> 757830.39 | P8: =IFERROR(O8/D8,0) -> 1969.7208 | Q8: 1400 | R8: =Q8*D8 -> 538636 | S8: =R8-M8 -> -294080.54 | T8: =IFERROR(S8/R8,0) -> -0.54597267 | U8: =R8-(M8-J8-I8) -> -219194.39 | V8: =IFERROR(U8/R8,0) -> -0.40694344
B9: 10006719 | C9: POTA ALAS CONGELADAS | D9: =TD!F6 -> 17.86 | E9: =IFERROR(F9/D9,0) -> 1652.036 | F9: =TD!G6 -> 29505.363 | G9: =TD!H6 -> 3712.0224 | H9: =TD!I6 -> 982.75199 | I9: =TD!J6 -> 1931.9239 | J9: =TD!K6 -> 1544.3629 | K9: 0 | L9: 0 | M9: =F9+G9+H9+I9 -> 36132.061 | N9: =IFERROR(M9/D9,0) -> 2023.0717 | O9: =F9+G9+H9-J9 -> 32655.774 | P9: =IFERROR(O9/D9,0) -> 1828.4308 | Q9: 1950 | R9: =Q9*D9 -> 34827 | S9: =R9-M9 -> -1305.0612 | T9: =IFERROR(S9/R9,0) -> -0.037472686 | U9: =R9-(M9-J9-I9) -> 2171.2255 | V9: =IFERROR(U9/R9,0) -> 0.062343168
B10: 10007050 | C10: POTA RECORTES COCIDOS | D10: =TD!F7 -> 138.718 | E10: =IFERROR(F10/D10,0) -> 2246.62 | F10: =TD!G7 -> 311646.63 | G10: =TD!H7 -> 28831.149 | H10: =TD!I7 -> 7633.0006 | I10: =TD!J7 -> 15005.186 | J10: =TD!K7 -> 11995.013 | K10: 0 | L10: 0 | M10: =F10+G10+H10+I10 -> 363115.97 | N10: =IFERROR(M10/D10,0) -> 2617.6557 | O10: =F10+G10+H10-J10 -> 336115.77 | P10: =IFERROR(O10/D10,0) -> 2423.0148 | Q10: 1700 | R10: =Q10*D10 -> 235820.6 | S10: =R10-M10 -> -127295.37 | T10: =IFERROR(S10/R10,0) -> -0.53979749 | U10: =R10-(M10-J10-I10) -> -100295.17 | V10: =IFERROR(U10/R10,0) -> -0.42530284
B11: 10007162 | C11: POTA REJOS CONGELADOS | D11: =TD!F8 -> 297.72 | E11: =IFERROR(F11/D11,0) -> 1783.985 | F11: =TD!G8 -> 531128.01 | G11: =TD!H8 -> 61878.125 | H11: =TD!I8 -> 16382.134 | I11: =TD!J8 -> 32204.501 | J11: =TD!K8 -> 25743.993 | K11: 0 | L11: 0 | M11: =F11+G11+H11+I11 -> 641592.77 | N11: =IFERROR(M11/D11,0) -> 2155.0207 | O11: =F11+G11+H11-J11 -> 583644.28 | P11: =IFERROR(O11/D11,0) -> 1960.3798 | Q11: 2700 | R11: =Q11*D11 -> 803844 | S11: =R11-M11 -> 162251.23 | T11: =IFERROR(S11/R11,0) -> 0.20184417 | U11: =R11-(M11-J11-I11) -> 220199.72 | V11: =IFERROR(U11/R11,0) -> 0.2739334
B12: 10007567 | C12: POTA REPRODUCTORES | D12: =TD!F9 -> 110.22 | E12: =IFERROR(F12/D12,0) -> 1712.173 | F12: =TD!G9 -> 188715.71 | G12: =TD!H9 -> 22908.125 | H12: =TD!I9 -> 6064.8894 | I12: =TD!J9 -> 11922.545 | J12: =TD!K9 -> 9530.7769 | K12: 0 | L12: 0 | M12: =F12+G12+H12+I12 -> 229611.27 | N12: =IFERROR(M12/D12,0) -> 2083.2087 | O12: =F12+G12+H12-J12 -> 208157.95 | P12: =IFERROR(O12/D12,0) -> 1888.5678 | Q12: 2800 | R12: =Q12*D12 -> 308616 | S12: =R12-M12 -> 79004.733 | T12: =IFERROR(S12/R12,0) -> 0.25599688 | U12: =R12-(M12-J12-I12) -> 100458.05 | V12: =IFERROR(U12/R12,0) -> 0.32551149
B13: 10007969 | C13: POTA CONOS | D13: =TD!F10 -> 0 | E13: =IFERROR(F13/D13,0) -> 0 | F13: =TD!G10 -> 0 | G13: =TD!H10 -> 0 | H13: =TD!I10 -> 0 | I13: =TD!J10 -> 0 | J13: =TD!K10 -> 0 | K13: 0 | L13: 0 | M13: =F13+G13+H13+I13 -> 0 | N13: =IFERROR(M13/D13,0) -> 0 | O13: =F13+G13+H13-J13 -> 0 | P13: =IFERROR(O13/D13,0) -> 0 | Q13: 1700 | R13: =Q13*D13 -> 0 | S13: =R13-M13 -> 0 | T13: =IFERROR(S13/R13,0) -> 0 | U13: =R13-(M13-J13-I13) -> 0 | V13: =IFERROR(U13/R13,0) -> 0
B14: 10009239 | C14: POTA FILETE DARUMA | D14: =TD!F11 -> 16.48 | E14: =IFERROR(F14/D14,0) -> 2846.957 | F14: =TD!G11 -> 46917.851 | G14: =TD!H11 -> 3425.2032 | H14: =TD!I11 -> 906.81706 | I14: =TD!J11 -> 1782.6487 | J14: =TD!K11 -> 1425.0336 | K14: 0 | L14: 0 | M14: =F14+G14+H14+I14 -> 53032.52 | N14: =IFERROR(M14/D14,0) -> 3217.9927 | O14: =F14+G14+H14-J14 -> 49824.838 | P14: =IFERROR(O14/D14,0) -> 3023.3518 | Q14: 3500 | R14: =Q14*D14 -> 57680 | S14: =R14-M14 -> 4647.4797 | T14: =IFERROR(S14/R14,0) -> 0.080573503 | U14: =R14-(M14-J14-I14) -> 7855.162 | V14: =IFERROR(U14/R14,0) -> 0.13618519
B15: 10009334 | C15: POTA ALAS COCIDAS | D15: =TD!F12 -> 329.458 | E15: =IFERROR(F15/D15,0) -> 2574.823 | F15: =TD!G12 -> 848296.04 | G15: =TD!H12 -> 68474.551 | H15: =TD!I12 -> 18128.528 | I15: =TD!J12 -> 35637.614 | J15: =TD!K12 -> 28488.393 | K15: 0 | L15: 0 | M15: =F15+G15+H15+I15 -> 970536.73 | N15: =IFERROR(M15/D15,0) -> 2945.8587 | O15: =F15+G15+H15-J15 -> 906410.72 | P15: =IFERROR(O15/D15,0) -> 2751.2178 | Q15: 3500 | R15: =Q15*D15 -> 1153103 | S15: =R15-M15 -> 182566.27 | T15: =IFERROR(S15/R15,0) -> 0.15832607 | U15: =R15-(M15-J15-I15) -> 246692.28 | V15: =IFERROR(U15/R15,0) -> 0.21393777
B16: 10009386 | C16: VENTOSAS | D16: =TD!F13 -> 21.28 | E16: =IFERROR(F16/D16,0) -> 3230.8044 | F16: =TD!G13 -> 68751.518 | G16: =TD!H13 -> 4422.8352 | H16: =TD!I13 -> 1170.9385 | I16: =TD!J13 -> 2301.8668 | J16: =TD!K13 -> 1840.0919 | K16: 0 | L16: 0 | M16: =F16+G16+H16+I16 -> 76647.158 | N16: =IFERROR(M16/D16,0) -> 3601.8401 | O16: =F16+G16+H16-J16 -> 72505.2 | P16: =IFERROR(O16/D16,0) -> 3407.1992 | Q16: 2000 | R16: =Q16*D16 -> 42560 | S16: =R16-M16 -> -34087.158 | T16: =IFERROR(S16/R16,0) -> -0.80092007 | U16: =R16-(M16-J16-I16) -> -29945.2 | V16: =IFERROR(U16/R16,0) -> -0.70359962
B17: 10009386 | C17: OTROS | D17: =TD!F14+TD!F17+TD!F18+TD!F19 -> 41.116 | E17: =IFERROR(F17/D17,0) -> 1588.6756 | F17: =TD!G14+TD!G17+TD!G18+TD!G19 -> 65319.987 | G17: =TD!H14+TD!H17+TD!H18+TD!H19 -> 8545.5494 | H17: =TD!I14+TD!I17+TD!I18+TD!I19 -> 2262.4205 | I17: =TD!J14+TD!J17+TD!J18+TD!J19 -> 4447.5354 | J17: =TD!K14+TD!K17+TD!K18+TD!K19 -> 3555.3205 | K17: 0 | L17: 0 | M17: =F17+G17+H17+I17 -> 80575.492 | N17: =IFERROR(M17/D17,0) -> 1959.7114 | O17: =F17+G17+H17-J17 -> 72572.636 | P17: =IFERROR(O17/D17,0) -> 1765.0704 | Q17: 1700 | R17: =Q17*D17 -> 69897.2 | S17: =R17-M17 -> -10678.292 | T17: =IFERROR(S17/R17,0) -> -0.15277139 | U17: =R17-(M17-J17-I17) -> -2675.4364 | V17: =IFERROR(U17/R17,0) -> -0.038276733
C18: FILETE PARA REPROCESO | D18: =TD!F15 -> 3.48 | E18: =IFERROR(F18/D18,0) -> 1831.106 | F18: =TD!G15 -> 6372.2489 | G18: =TD!H15 -> 723.2832 | H18: =TD!I15 -> 191.48807 | I18: =TD!J15 -> 376.4331 | J18: =TD!K15 -> 300.91729 | K18: 0 | L18: 0 | M18: =F18+G18+H18+I18 -> 7663.4532 | N18: =IFERROR(M18/D18,0) -> 2202.1417 | O18: =F18+G18+H18-J18 -> 6986.1029 | P18: =IFERROR(O18/D18,0) -> 2007.5008 | Q18: 1800 | R18: =Q18*D18 -> 6264 | S18: =R18-M18 -> -1399.4532 | T18: =IFERROR(S18/R18,0) -> -0.22341208 | U18: =R18-(M18-J18-I18) -> -722.10286 | V18: =IFERROR(U18/R18,0) -> -0.11527823
C19: ALAS PARA REPROCESO | D19: =TD!F16 -> 0 | E19: =IFERROR(F19/D19,0) -> 0 | F19: =TD!G16 -> 0 | G19: =TD!H16 -> 0 | H19: =TD!I16 -> 0 | I19: =TD!J16 -> 0 | J19: =TD!K16 -> 0 | K19: 0 | L19: 0 | M19: =F19+G19+H19+I19 -> 0 | N19: =IFERROR(M19/D19,0) -> 0 | O19: =F19+G19+H19-J19 -> 0 | P19: =IFERROR(O19/D19,0) -> 0 | Q19: 1950 | R19: =Q19*D19 -> 0 | S19: =R19-M19 -> 0 | T19: =IFERROR(S19/R19,0) -> 0 | U19: =R19-(M19-J19-I19) -> 0 | V19: =IFERROR(U19/R19,0) -> 0
C20: TOTAL | D20: =SUM(D7:D19) -> 1428.052 | E20: =IFERROR(F20/D20,0) -> 2037.2263 | F20: =SUM(F7:F19) -> 2909265.1 | G20: =SUM(G7:G19) -> 296806.33 | H20: =SUM(H7:H19) -> 78579 | I20: =SUM(I7:I19) -> 154473 | J20: =SUM(J7:J19) -> 123484.35 | K20: =SUM(K7:K19) -> 0 | L20: 0 | M20: =SUM(M7:M19) -> 3439123.4 | N20: =IFERROR(M20/D20,0) -> 2408.262 | O20: =SUM(O7:O19) -> 3161166.1 | P20: =IFERROR(O20/D20,0) -> 2213.6211 | Q20: =R20/D20 -> 2361.1268 | R20: =SUM(R7:R19) -> 3371811.8 | S20: =SUM(S7:S19) -> -67311.612 | T20: =S20/R20 -> -0.019963039 | U20: =SUM(U7:U19) -> 210645.74 | V20: =IFERROR(U20/R20,0) -> 0.062472567
C22: TM en Almacén de Yantai Jiahong | R22: =7%/12 -> 0.0058333333
R23: =R22*M31 -> 21753.62 | S23: =R23*7 -> 152275.34 | T23: =S23/D31 -> 108.52779
C24: Producto | D24: TM en Stock Libre | E24: CU | F24: Costo Ventas | G24: Gasto Ventas | H24: Gasto ADM | I24: Gasto Fin | J24: Depreciación | K24: Utilidad Neta | L24: Margen Neto | M24: Venta Equilibrio a Utd Neta | N24: Precio Equilibrio x TM a Utd Neta | O24: Venta Equilibro a EBITDA | P24: Precio Equilibrio x TM a EBITDA | Q24: Precio Mercado | R24: Venta total | S24: Utilidad | T24: Mg Neto | U24: EBITDA | V24: Mg EBITDA
C25: POTA FILETE CONGELADO | D25: 567 | E25: =E7 -> 1831.106 | F25: =E25*D25 -> 1038237.1 | G25: =D25*207.84 -> 117845.28 | H25: =H$20/$D$20*$D25 -> 31199.349 | I25: =I$20/$D$20*$D25 -> 61332.634 | J25: =J$20/$D$20*$D25 -> 49028.765 | K25: 0 | L25: 0 | M25: =F25+G25+H25+I25 -> 1248614.4 | N25: =IFERROR(M25/D25,0) -> 2202.1417 | O25: =F25+G25+H25-J25 -> 1138253 | P25: =IFERROR(O25/D25,0) -> 2007.5008 | Q25: 1500 | R25: =Q25*D25 -> 850500 | S25: =R25-M25 -> -398114.37 | T25: =IFERROR(S25/R25,0) -> -0.46809449 | U25: =R25-(M25-J25-I25) -> -287752.97 | V25: =IFERROR(U25/R25,0) -> -0.33833388
C26: POTA ALAS CONGELADAS | D26: 54 | E26: =E9 -> 1652.036 | F26: =E26*D26 -> 89209.944 | G26: =D26*207.84 -> 11223.36 | H26: =H$20/$D$20*$D26 -> 2971.3666 | I26: =I$20/$D$20*$D26 -> 5841.2033 | J26: =J$20/$D$20*$D26 -> 4669.4062 | K26: 0 | L26: 0 | M26: =F26+G26+H26+I26 -> 109245.87 | N26: =IFERROR(M26/D26,0) -> 2023.0717 | O26: =F26+G26+H26-J26 -> 98735.264 | P26: =IFERROR(O26/D26,0) -> 1828.4308 | Q26: 1700 | R26: =Q26*D26 -> 91800 | S26: =R26-M26 -> -17445.874 | T26: =IFERROR(S26/R26,0) -> -0.1900422 | U26: =R26-(M26-J26-I26) -> -6935.2644
C27: POTA REJOS CONGELADOS | D27: 108 | E27: =E11 -> 1783.985 | F27: =E27*D27 -> 192670.38 | G27: =D27*207.84 -> 22446.72 | H27: =H$20/$D$20*$D27 -> 5942.7332 | I27: =I$20/$D$20*$D27 -> 11682.407 | J27: =J$20/$D$20*$D27 -> 9338.8125 | K27: 0 | L27: 0 | M27: =F27+G27+H27+I27 -> 232742.24 | N27: =IFERROR(M27/D27,0) -> 2155.0207 | O27: =F27+G27+H27-J27 -> 211721.02 | P27: =IFERROR(O27/D27,0) -> 1960.3798 | Q27: 2275 | R27: =Q27*D27 -> 245700 | S27: =R27-M27 -> 12957.76 | T27: =IFERROR(S27/R27,0) -> 0.052738137 | U27: =R27-(M27-J27-I27) -> 33978.979 | V27: =IFERROR(U27/R27,0) -> 0.13829458
C28: POTA FILETE DARUMA | D28: 594 | E28: =E14 -> 2846.957 | F28: =E28*D28 -> 1691092.5 | G28: =D28*207.84 -> 123456.96 | H28: =H$20/$D$20*$D28 -> 32685.032 | I28: =I$20/$D$20*$D28 -> 64253.236 | J28: =J$20/$D$20*$D28 -> 51363.468 | K28: 0 | L28: 0 | M28: =F28+G28+H28+I28 -> 1911487.7 | N28: =IFERROR(M28/D28,0) -> 3217.9927 | O28: =F28+G28+H28-J28 -> 1795871 | P28: =IFERROR(O28/D28,0) -> 3023.3518 | Q28: 3400 | R28: =Q28*D28 -> 2019600 | S28: =R28-M28 -> 108112.31 | T28: =IFERROR(S28/R28,0) -> 0.053531548 | U28: =R28-(M28-J28-I28) -> 223729.02 | V28: =IFERROR(U28/R28,0) -> 0.11077888
C29: POTA ALAS COCIDAS | D29: 53.1 | E29: =E15 -> 2574.823 | F29: =E29*D29 -> 136723.1 | G29: =D29*207.84 -> 11036.304 | H29: =H$20/$D$20*$D29 -> 2921.8438 | I29: =I$20/$D$20*$D29 -> 5743.8499 | J29: =J$20/$D$20*$D29 -> 4591.5828 | K29: 0 | L29: 0 | M29: =F29+G29+H29+I29 -> 156425.1 | N29: =IFERROR(M29/D29,0) -> 2945.8587 | O29: =F29+G29+H29-J29 -> 146089.67 | P29: =IFERROR(O29/D29,0) -> 2751.2178 | Q29: 3400 | R29: =Q29*D29 -> 180540 | S29: =R29-M29 -> 24114.901 | T29: =IFERROR(S29/R29,0) -> 0.13357096 | U29: =R29-(M29-J29-I29) -> 34450.334
C30: POTA RECORTES COCIDOS | D30: 27 | E30: =E10 -> 2246.62 | F30: =E30*D30 -> 60658.74 | G30: =D30*207.84 -> 5611.68 | H30: =H$20/$D$20*$D30 -> 1485.6833 | I30: =I$20/$D$20*$D30 -> 2920.6016 | J30: =J$20/$D$20*$D30 -> 2334.7031 | K30: 0 | L30: 0 | M30: =F30+G30+H30+I30 -> 70676.705 | N30: =IFERROR(M30/D30,0) -> 2617.6557 | O30: =F30+G30+H30-J30 -> 65421.4 | P30: =IFERROR(O30/D30,0) -> 2423.0148 | Q30: 1800 | R30: =Q30*D30 -> 48600 | S30: =R30-M30 -> -22076.705 | T30: =IFERROR(S30/R30,0) -> -0.45425319 | U30: =R30-(M30-J30-I30) -> -16821.4
C31: TOTAL | D31: =SUM(D25:D30) -> 1403.1 | E31: =F31/D31 -> 2286.7876 | F31: =SUM(F25:F30) -> 3208591.7 | G31: =SUM(G25:G30) -> 291620.3 | H31: =SUM(H25:H30) -> 77206.009 | I31: =SUM(I25:I30) -> 151773.93 | J31: =SUM(J25:J30) -> 121326.74 | K31: =SUM(K25:K30) -> 0 | L31: 0 | M31: =SUM(M25:M30) -> 3729192 | N31: =IFERROR(M31/D31,0) -> 2657.8234 | O31: =SUM(O25:O30) -> 3456091.3 | P31: =IFERROR(O31/D31,0) -> 2463.1825 | Q31: =R31/D31 -> 2449.3906 | R31: =SUM(R25:R30) -> 3436740 | S31: =SUM(S25:S30) -> -292451.97 | T31: =S31/R31 -> -0.08509575 | U31: =SUM(U25:U30) -> -19351.299 | V31: =IFERROR(U31/R31,0) -> -0.0056307138
C33: TOTAL | D33: =D20+D31 -> 2831.152 | E33: =F33/D33 -> 2160.9072 | F33: =F20+F31 -> 6117856.8 | G33: =G20+G31 -> 588426.63 | H33: =H20+H31 -> 155785.01 | I33: =I20+I31 -> 306246.93 | J33: =J20+J31 -> 244811.09 | K33: =K20+K31 -> 0 | L33: =L20+L31 -> 0 | M33: =M20+M31 -> 7168315.4 | N33: =IFERROR(M33/D33,0) -> 2531.943 | O33: =O20+O31 -> 6617257.4 | P33: =IFERROR(O33/D33,0) -> 2337.302 | Q33: =R33/D33 -> 2404.8697 | R33: =R20+R31 -> 6808551.8 | S33: =S20+S31 -> -359763.58 | T33: =S33/R33 -> -0.052839957 | U33: =U20+U31 -> 191294.44 | V33: =IFERROR(U33/R33,0) -> 0.028096201
C36: INVENTARIO TOTAL VALORIZADO
C38: Producto | D38: TM en Stock Libre | E38: CU | F38: Costo Ventas | G38: Gasto Ventas | H38: Gasto ADM | I38: Gasto Fin | J38: Depreciación | K38: Utilidad Neta | L38: Margen Neto | M38: Venta Equilibrio a Utd Neta | N38: Precio Equilibrio x TM a Utd Neta | O38: Precio Venta | P38: Venta Esperada | Q38: Utilidad Neta | R38: Margen Neto | S38: Precio actual | T38: venta con precio actual | U38: P/L | V38: variación | W38: ebtida
C39: POTA FILETE CONGELADO | D39: =D7+D25 -> 633.98 | E39: =IFERROR(F39/D39,0) -> 1831.106 | F39: =F7+F25 -> 1160884.6 | G39: =G7+G25 -> 131766.4 | H39: =H7+H25 -> 34884.944 | I39: =I7+I25 -> 68577.89 | J39: =J7+J25 -> 54820.559 | K39: 0 | L39: 0 | M39: =F39+G39+H39+I39 -> 1396113.8 | N39: =IFERROR(M39/D39,0) -> 2202.1417 | O39: 2500 | P39: =O39*D39 -> 1584950 | Q39: =P39-M39 -> 188836.18 | R39: =Q39/P39 -> 0.1191433 | S39: =Q25 -> 1500 | T39: =S39*D39 -> 950970 | U39: =T39-M39 -> -445143.82 | V39: =Q39-U39 -> 633980 | W39: =Q39+I39+J39 -> 312234.63
C40: POTA NUCAS CONGELADAS | D40: =D8 -> 384.74 | E40: =IFERROR(F40/D40,0) -> 1793.326 | F40: =F8 -> 689964.25 | G40: =G8 -> 79964.362 | H40: =H8 -> 21170.437 | I40: =I8 -> 41617.492 | J40: =J8 -> 33268.655 | K40: 0 | L40: 0 | M40: =F40+G40+H40+I40 -> 832716.54 | N40: =IFERROR(M40/D40,0) -> 2164.3617 | O40: 1400 | P40: =O40*D40 -> 538636 | Q40: =P40-M40 -> -294080.54 | R40: =Q40/P40 -> -0.54597267 | S40: =Q8 -> 1400 | T40: =S40*D40 -> 538636 | U40: =T40-M40 -> -294080.54 | V40: =Q40-U40 -> 0 | W40: =Q40+I40+J40 -> -219194.39
C41: POTA ALAS CONGELADAS | D41: =D9+D26 -> 71.86 | E41: =IFERROR(F41/D41,0) -> 1652.036 | F41: =F9+F26 -> 118715.31 | G41: =G9+G26 -> 14935.382 | H41: =H9+H26 -> 3954.1186 | I41: =I9+I26 -> 7773.1272 | J41: =J9+J26 -> 6213.7691 | K41: 0 | L41: 0 | M41: =F41+G41+H41+I41 -> 145377.94 | N41: =IFERROR(M41/D41,0) -> 2023.0717 | O41: 2400 | P41: =O41*D41 -> 172464 | Q41: =P41-M41 -> 27086.065 | R41: =Q41/P41 -> 0.15705344 | S41: =Q9 -> 1950 | T41: =S41*D41 -> 140127 | U41: =T41-M41 -> -5250.9351 | V41: =Q41-U41 -> 32337 | W41: =Q41+I41+J41 -> 41072.961
C42: POTA RECORTES COCIDOS | D42: =D10+D30 -> 165.718 | E42: =IFERROR(F42/D42,0) -> 2246.62 | F42: =F10+F30 -> 372305.37 | G42: =G10+G30 -> 34442.829 | H42: =H10+H30 -> 9118.6839 | I42: =I10+I30 -> 17925.787 | J42: =J10+J30 -> 14329.716 | K42: 0 | L42: 0 | M42: =F42+G42+H42+I42 -> 433792.67 | N42: =IFERROR(M42/D42,0) -> 2617.6557 | O42: 2500 | P42: =O42*D42 -> 414295 | Q42: =P42-M42 -> -19497.674 | R42: =Q42/P42 -> -0.047062295 | S42: =Q10 -> 1700 | T42: =S42*D42 -> 281720.6 | U42: =T42-M42 -> -152072.07 | V42: =Q42-U42 -> 132574.4 | W42: =Q42+I42+J42 -> 12757.83
C43: POTA REJOS CONGELADOS | D43: =D11+D27 -> 405.72 | E43: =IFERROR(F43/D43,0) -> 1783.985 | F43: =F11+F27 -> 723798.39 | G43: =G11+G27 -> 84324.845 | H43: =H11+H27 -> 22324.868 | I43: =I11+I27 -> 43886.907 | J43: =J11+J27 -> 35082.805 | K43: 0 | L43: 0 | M43: =F43+G43+H43+I43 -> 874335.01 | N43: =IFERROR(M43/D43,0) -> 2155.0207 | O43: 2800 | P43: =O43*D43 -> 1136016 | Q43: =P43-M43 -> 261680.99 | R43: =Q43/P43 -> 0.23034974 | S43: =Q11 -> 2700 | T43: =S43*D43 -> 1095444 | U43: =T43-M43 -> 221108.99 | V43: =Q43-U43 -> 40572 | W43: =Q43+I43+J43 -> 340650.7
C44: POTA REPRODUCTORES | D44: =D12 -> 110.22 | E44: =IFERROR(F44/D44,0) -> 1712.173 | F44: =F12 -> 188715.71 | G44: =G12 -> 22908.125 | H44: =H12 -> 6064.8894 | I44: =I12 -> 11922.545 | J44: =J12 -> 9530.7769 | K44: 0 | L44: 0 | M44: =F44+G44+H44+I44 -> 229611.27 | N44: =IFERROR(M44/D44,0) -> 2083.2087 | O44: 2800 | P44: =O44*D44 -> 308616 | Q44: =P44-M44 -> 79004.733 | R44: =Q44/P44 -> 0.25599688 | S44: =Q12 -> 2800 | T44: =S44*D44 -> 308616 | U44: =T44-M44 -> 79004.733 | V44: =Q44-U44 -> 0 | W44: =Q44+I44+J44 -> 100458.05
C45: POTA CONOS | D45: =D13 -> 0 | E45: =IFERROR(F45/D45,0) -> 0 | F45: =F13 -> 0 | G45: =G13 -> 0 | H45: =H13 -> 0 | I45: =I13 -> 0 | J45: =J13 -> 0 | K45: 0 | L45: 0 | M45: =F45+G45+H45+I45 -> 0 | N45: =IFERROR(M45/D45,0) -> 0 | O45: 1800 | P45: =O45*D45 -> 0 | Q45: =P45-M45 -> 0 | R45: =Q45/P45 -> #DIV/0! | S45: =Q13 -> 1700 | T45: =S45*D45 -> 0 | U45: =T45-M45 -> 0 | V45: =Q45-U45 -> 0 | W45: =Q45+I45+J45 -> 0
C46: POTA FILETE DARUMA | D46: =D14+D28+D18 -> 613.96 | E46: =IFERROR(F46/D46,0) -> 2841.199 | F46: =F14+F28+F18 -> 1744382.6 | G46: =G14+G28+G18 -> 127605.45 | H46: =H14+H28+H18 -> 33783.338 | I46: =I14+I28+I18 -> 66412.318 | J46: =J14+J28+J18 -> 53089.419 | K46: 0 | L46: 0 | M46: =F46+G46+H46+I46 -> 1972183.7 | N46: =IFERROR(M46/D46,0) -> 3212.2348 | O46: 4000 | P46: =O46*D46 -> 2455840 | Q46: =P46-M46 -> 483656.34 | R46: =Q46/P46 -> 0.19694131 | S46: =Q14 -> 3500 | T46: =S46*D46 -> 2148860 | U46: =T46-M46 -> 176676.34 | V46: =Q46-U46 -> 306980 | W46: =Q46+I46+J46 -> 603158.08
C47: POTA ALAS COCIDAS | D47: =D15+D29+D19 -> 382.558 | E47: =IFERROR(F47/D47,0) -> 2574.823 | F47: =F15+F29+F19 -> 985019.14 | G47: =G15+G29+G19 -> 79510.855 | H47: =H15+H29+H19 -> 21050.371 | I47: =I15+I29+I19 -> 41381.464 | J47: =J15+J29+J19 -> 33079.976 | K47: 0 | L47: 0 | M47: =F47+G47+H47+I47 -> 1126961.8 | N47: =IFERROR(M47/D47,0) -> 2945.8587 | O47: 4000 | P47: =O47*D47 -> 1530232 | Q47: =P47-M47 -> 403270.17 | R47: =Q47/P47 -> 0.26353532 | S47: =Q15 -> 3500 | T47: =S47*D47 -> 1338953 | U47: =T47-M47 -> 211991.17 | V47: =Q47-U47 -> 191279 | W47: =Q47+I47+J47 -> 477731.61
...

Sheet TD
E3: Etiquetas de fila | F3: Suma de TM en Stock | G3: Suma de Costo Ventas | H3: Suma de Gasto Ventas | I3: Suma de Gasto ADM | J3: Suma de Gasto Fin | K3: Suma de Depreciación
B4: =C4=E4 -> TRUE | C4: 10005721 | D4: POTA FILETE CONGELADO | E4: 10005721 | F4: 66.98 | G4: 122647.48 | H4: 13921.123 | I4: 3685.5951 | J4: 7245.2555 | K4: 5791.7931
B5: =C5=E5 -> TRUE | C5: 10005779 | D5: POTA NUCAS CONGELADAS | E5: 10005779 | F5: 384.74 | G5: 689964.25 | H5: 79964.362 | I5: 21170.437 | J5: 41617.492 | K5: 33268.655
B6: =C6=E6 -> TRUE | C6: 10006719 | D6: POTA ALAS CONGELADAS | E6: 10006719 | F6: 17.86 | G6: 29505.363 | H6: 3712.0224 | I6: 982.75199 | J6: 1931.9239 | K6: 1544.3629
B7: =C7=E7 -> TRUE | C7: 10007050 | D7: POTA RECORTES COCIDOS | E7: 10007050 | F7: 138.718 | G7: 311646.63 | H7: 28831.149 | I7: 7633.0006 | J7: 15005.186 | K7: 11995.013
B8: =C8=E8 -> TRUE | C8: 10007162 | D8: POTA REJOS CONGELADOS | E8: 10007162 | F8: 297.72 | G8: 531128.01 | H8: 61878.125 | I8: 16382.134 | J8: 32204.501 | K8: 25743.993
B9: =C9=E9 -> TRUE | C9: 10007567 | D9: POTA REPRODUCTORES | E9: 10007567 | F9: 110.22 | G9: 188715.71 | H9: 22908.125 | I9: 6064.8894 | J9: 11922.545 | K9: 9530.7769
B10: =C10=E10 -> TRUE | C10: 10007969 | D10: POTA CONOS | E10: 10007969 | F10: 0 | G10: 0 | H10: 0 | I10: 0 | J10: 0 | K10: 0
B11: =C11=E11 -> TRUE | C11: 10009239 | D11: POTA FILETE DARUMA | E11: 10009239 | F11: 16.48 | G11: 46917.851 | H11: 3425.2032 | I11: 906.81706 | J11: 1782.6487 | K11: 1425.0336
B12: =C12=E12 -> TRUE | C12: 10009334 | D12: POTA ALAS COCIDAS | E12: 10009334 | F12: 329.458 | G12: 848296.04 | H12: 68474.551 | I12: 18128.528 | J12: 35637.614 | K12: 28488.393
B13: =C13=E13 -> TRUE | C13: 10009386 | D13: VENTOSAS | E13: 10009386 | F13: 21.28 | G13: 68751.518 | H13: 4422.8352 | I13: 1170.9385 | J13: 2301.8668 | K13: 1840.0919
B14: =C14=E14 -> FALSE | D14: OTROS | E14: 10009207 | F14: 32.28 | G14: 45468.853 | H14: 6709.0752 | I14: 1776.2169 | J14: 3491.7415 | K14: 2791.2673
D15: FILETE PARA REPROCESO | E15: 10009650 | F15: 3.48 | G15: 6372.2489 | H15: 723.2832 | I15: 191.48807 | J15: 376.4331 | K15: 300.91729
D16: ALAS PARA REPROCESO | E16: 10009649 | F16: 0 | G16: 0 | H16: 0 | I16: 0 | J16: 0 | K16: 0
E17: 10007051 | F17: 4.35 | G17: 9772.797 | H17: 904.104 | I17: 239.36009 | J17: 470.54137 | K17: 376.14661
E18: 10007151 | F18: 3.64 | G18: 8177.6968 | H18: 756.5376 | I18: 200.29212 | J18: 393.74037 | K18: 314.75257
E19: 10007152 | F19: 0.846 | G19: 1900.6405 | H19: 175.83264 | I19: 46.55141 | J19: 91.512184 | K19: 73.154031
E20: Total general | F20: 1428.052 | G20: 2909265.1 | H20: 296806.33 | I20: 78579 | J20: 154473 | K20: 123484.35

Sheet STOCK LIBRE
A1: CODIGO | B1: PRODUCTO | C1: TOTAL STOCK | D1: POR EMBARCAR | E1: STOCK LIBRE | G1: CÓDIGO | H1: CU X TM | I1: % MP | J1: incremento MP | K1: TM en Stock Total | L1: TM en Stock | M1: Costo Ventas | N1: Gasto Ventas | O1: Gasto ADM | P1: Gasto Fin | Q1: Depreciación | R1: Utilidad Neta | S1: Margen Neto | T1: Venta Equilibrio | U1: Precio Equilibrio x TM
A2: 10009178 | B2: POTA ALAS FR C/P C/C (B) S/COD BL10 S20 | C2: 14840 | E2: 14840 | G2: 10006719 | H2: =1652.036/1000 -> 1.652036 | I2: 0.71 | J2: =$H$62 -> -0.10965909 | K2: =C2/1000 -> 14.84 | L2: =IF(E2<0,0,E2)/1000 -> 14.84 | M2: =IFERROR(H2*L2,0)*1000 -> 24516.214 | N2: =207.84*L2 -> 3084.3456 | O2: =$O$57/$L$55*L2 -> 816.57556 | P2: =$P$57/$L$55*L2 -> 1605.2492 | Q2: =$Q$57/$L$55*L2 -> 1283.222 | R2: 0 | S2: 0 | T2: =M2+N2+O2+P2 -> 30022.385 | U2: =IFERROR(T2/L2,0) -> 2023.0717
A3: 10006668 | B3: POTA ALAS FR C/P C/C <0.5 BL10 S20 | C3: 680 | E3: 680 | G3: 10006719 | H3: =1652.036/1000 -> 1.652036 | I3: 0.71 | J3: =$H$62 -> -0.10965909 | K3: =C3/1000 -> 0.68 | L3: =IF(E3<0,0,E3)/1000 -> 0.68 | M3: =IFERROR(H3*L3,0)*1000 -> 1123.3845 | N3: =207.84*L3 -> 141.3312 | O3: =$O$57/$L$55*L3 -> 37.417209 | P3: =$P$57/$L$55*L3 -> 73.555893 | Q3: =$Q$57/$L$55*L3 -> 58.79993 | R3: 0 | S3: 0 | T3: =M3+N3+O3+P3 -> 1375.6888 | U3: =IFERROR(T3/L3,0) -> 2023.0717
A4: 10006719 | B4: POTA ALAS FR C/P C/C 0.5-1 BL10 S20 | C4: 0 | E4: 0 | G4: 10006719 | H4: =1652.036/1000 -> 1.652036 | I4: 0.71 | J4: =$H$62 -> -0.10965909 | K4: =C4/1000 -> 0 | L4: =IF(E4<0,0,E4)/1000 -> 0 | M4: =IFERROR(H4*L4,0)*1000 -> 0 | N4: =207.84*L4 -> 0 | O4: =$O$57/$L$55*L4 -> 0 | P4: =$P$57/$L$55*L4 -> 0 | Q4: =$Q$57/$L$55*L4 -> 0 | R4: 0 | S4: 0 | T4: =M4+N4+O4+P4 -> 0 | U4: =IFERROR(T4/L4,0) -> 0
A5: 10009265 | B5: POTA ALAS FR C/P C/C 0.3 - 0.5 BL10 S20 | C5: 0 | E5: 0 | G5: 10006719 | H5: =1652.036/1000 -> 1.652036 | I5: 0.71 | J5: =$H$62 -> -0.10965909 | K5: =C5/1000 -> 0 | L5: =IF(E5<0,0,E5)/1000 -> 0 | M5: =IFERROR(H5*L5,0)*1000 -> 0 | N5: =207.84*L5 -> 0 | O5: =$O$57/$L$55*L5 -> 0 | P5: =$P$57/$L$55*L5 -> 0 | Q5: =$Q$57/$L$55*L5 -> 0 | R5: 0 | S5: 0 | T5: =M5+N5+O5+P5 -> 0 | U5: =IFERROR(T5/L5,0) -> 0
A6: 10006720 | B6: POTA ALAS FR C/P C/C 1-2 BL10 S20 | C6: 40 | E6: 0 | G6: 10006719 | H6: =1652.036/1000 -> 1.652036 | I6: 0.71 | J6: =$H$62 -> -0.10965909 | K6: =C6/1000 -> 0.04 | L6: =IF(E6<0,0,E6)/1000 -> 0 | M6: =IFERROR(H6*L6,0)*1000 -> 0 | N6: =207.84*L6 -> 0 | O6: =$O$57/$L$55*L6 -> 0 | P6: =$P$57/$L$55*L6 -> 0 | Q6: =$Q$57/$L$55*L6 -> 0 | R6: 0 | S6: 0 | T6: =M6+N6+O6+P6 -> 0 | U6: =IFERROR(T6/L6,0) -> 0
A7: 10010005 | B7: POTA ALAS FR C/P C/C 1-2 BL10 S20 ENTERA | C7: 2340 | E7: 2340 | G7: 10006719 | H7: =1652.036/1000 -> 1.652036 | I7: 0.71 | J7: =$H$62 -> -0.10965909 | K7: =C7/1000 -> 2.34 | L7: =IF(E7<0,0,E7)/1000 -> 2.34 | M7: =IFERROR(H7*L7,0)*1000 -> 3865.7642 | N7: =207.84*L7 -> 486.3456 | O7: =$O$57/$L$55*L7 -> 128.75922 | P7: =$P$57/$L$55*L7 -> 253.11881 | Q7: =$Q$57/$L$55*L7 -> 202.34094 | R7: 0 | S7: 0 | T7: =M7+N7+O7+P7 -> 4733.9879 | U7: =IFERROR(T7/L7,0) -> 2023.0717
A8: 10006722 | B8: POTA ALAS FR C/P C/C 2up | C8: 0 | E8: 0 | G8: 10006719 | H8: =1652.036/1000 -> 1.652036 | I8: 0.71 | J8: =$H$62 -> -0.10965909 | K8: =C8/1000 -> 0 | L8: =IF(E8<0,0,E8)/1000 -> 0 | M8: =IFERROR(H8*L8,0)*1000 -> 0 | N8: =207.84*L8 -> 0 | O8: =$O$57/$L$55*L8 -> 0 | P8: =$P$57/$L$55*L8 -> 0 | Q8: =$Q$57/$L$55*L8 -> 0 | R8: 0 | S8: 0 | T8: =M8+N8+O8+P8 -> 0 | U8: =IFERROR(T8/L8,0) -> 0
A9: 10009207 | B9: POTA LABIOS FR S/COD BL10 S20 | C9: 32280 | E9: 32280 | G9: 10009207 | H9: =1408.57659987072/1000 -> 1.4085766 | I9: 0.71 | J9: =$H$62 -> -0.10965909 | K9: =C9/1000 -> 32.28 | L9: =IF(E9<0,0,E9)/1000 -> 32.28 | M9: =IFERROR(H9*L9,0)*1000 -> 45468.853 | N9: =207.84*L9 -> 6709.0752 | O9: =$O$57/$L$55*L9 -> 1776.2169 | P9: =$P$57/$L$55*L9 -> 3491.7415 | Q9: =$Q$57/$L$55*L9 -> 2791.2673 | R9: 0 | S9: 0 | T9: =M9+N9+O9+P9 -> 57445.886 | U9: =IFERROR(T9/L9,0) -> 1779.6123
A10: 10007969 | B10: POTA CONOS | C10: 5580 | D10: 50000 | E10: -44420 | G10: 10007969 | H10: =1226.35851472471/1000 -> 1.2263585 | I10: 0.71 | J10: =$H$62 -> -0.10965909 | K10: =C10/1000 -> 5.58 | L10: =IF(E10<0,0,E10)/1000 -> 0 | M10: =IFERROR(H10*L10,0)*1000 -> 0 | N10: =207.84*L10 -> 0 | O10: =$O$57/$L$55*L10 -> 0 | P10: =$P$57/$L$55*L10 -> 0 | Q10: =$Q$57/$L$55*L10 -> 0 | R10: 0 | S10: 0 | T10: =M10+N10+O10+P10 -> 0 | U10: =IFERROR(T10/L10,0) -> 0
A11: 10004433 | B11: POTA FILETE C/M C/T FR 0.5-1.0 BL10 S20 | C11: 0 | E11: 0 | G11: 10005721 | H11: =1831.106/1000 -> 1.831106 | I11: 0.67 | J11: =$H$62 -> -0.10965909 | K11: =C11/1000 -> 0 | L11: =IF(E11<0,0,E11)/1000 -> 0 | M11: =IFERROR(H11*L11,0)*1000 -> 0 | N11: =207.84*L11 -> 0 | O11: =$O$57/$L$55*L11 -> 0 | P11: =$P$57/$L$55*L11 -> 0 | Q11: =$Q$57/$L$55*L11 -> 0 | R11: 0 | S11: 0 | T11: =M11+N11+O11+P11 -> 0 | U11: =IFERROR(T11/L11,0) -> 0
A12: 10004434 | B12: POTA FILETE C/M C/T FR 1-2 BL10 S20 | C12: 1780 | E12: 1780 | G12: 10005721 | H12: =1831.106/1000 -> 1.831106 | I12: 0.67 | J12: =$H$62 -> -0.10965909 | K12: =C12/1000 -> 1.78 | L12: =IF(E12<0,0,E12)/1000 -> 1.78 | M12: =IFERROR(H12*L12,0)*1000 -> 3259.3687 | N12: =207.84*L12 -> 369.9552 | O12: =$O$57/$L$55*L12 -> 97.945047 | P12: =$P$57/$L$55*L12 -> 192.54337 | Q12: =$Q$57/$L$55*L12 -> 153.91746 | R12: 0 | S12: 0 | T12: =M12+N12+O12+P12 -> 3919.8123 | U12: =IFERROR(T12/L12,0) -> 2202.1417
A13: 10010125 | B13: POTA FILETE C/M C/T FR 1.0 - 3.0 BL10 S20 | C13: 0 | E13: 0 | G13: 10005721 | H13: =1831.106/1000 -> 1.831106 | I13: 0.67 | J13: =$H$62 -> -0.10965909 | K13: =C13/1000 -> 0 | L13: =IF(E13<0,0,E13)/1000 -> 0 | M13: =IFERROR(H13*L13,0)*1000 -> 0 | N13: =207.84*L13 -> 0 | O13: =$O$57/$L$55*L13 -> 0 | P13: =$P$57/$L$55*L13 -> 0 | Q13: =$Q$57/$L$55*L13 -> 0 | R13: 0 | S13: 0 | T13: =M13+N13+O13+P13 -> 0 | U13: =IFERROR(T13/L13,0) -> 0
A14: 10004435 | B14: POTA FILETE C/M C/T FR 2-4 S20 | C14: 32180 | E14: 32180 | G14: 10005721 | H14: =1831.106/1000 -> 1.831106 | I14: 0.67 | J14: =$H$62 -> -0.10965909 | K14: =C14/1000 -> 32.18 | L14: =IF(E14<0,0,E14)/1000 -> 32.18 | M14: =IFERROR(H14*L14,0)*1000 -> 58924.991 | N14: =207.84*L14 -> 6688.2912 | O14: =$O$57/$L$55*L14 -> 1770.7144 | P14: =$P$57/$L$55*L14 -> 3480.9245 | Q14: =$Q$57/$L$55*L14 -> 2782.6202 | R14: 0 | S14: 0 | T14: =M14+N14+O14+P14 -> 70864.921 | U14: =IFERROR(T14/L14,0) -> 2202.1417
A15: 10005708 | B15: POTA FILETE C/M C/T FR <0.5 Kg AA BL10 S20 | C15: 1080 | E15: 1080 | G15: 10005721 | H15: =1831.106/1000 -> 1.831106 | I15: 0.67 | J15: =$H$62 -> -0.10965909 | K15: =C15/1000 -> 1.08 | L15: =IF(E15<0,0,E15)/1000 -> 1.08 | M15: =IFERROR(H15*L15,0)*1000 -> 1977.5945 | N15: =207.84*L15 -> 224.4672 | O15: =$O$57/$L$55*L15 -> 59.427332 | P15: =$P$57/$L$55*L15 -> 116.82407 | Q15: =$Q$57/$L$55*L15 -> 93.388125 | R15: 0 | S15: 0 | T15: =M15+N15+O15+P15 -> 2378.3131 | U15: =IFERROR(T15/L15,0) -> 2202.1417
A16: 10005721 | B16: POTA FILETE C/M C/T FR 2-4 (AA) BL10 S20 | C16: 3100 | E16: 3100 | G16: 10005721 | H16: =1831.106/1000 -> 1.831106 | I16: 0.67 | J16: =$H$62 -> -0.10965909 | K16: =C16/1000 -> 3.1 | L16: =IF(E16<0,0,E16)/1000 -> 3.1 | M16: =IFERROR(H16*L16,0)*1000 -> 5676.4286 | N16: =207.84*L16 -> 644.304 | O16: =$O$57/$L$55*L16 -> 170.57845 | P16: =$P$57/$L$55*L16 -> 335.32834 | Q16: =$Q$57/$L$55*L16 -> 268.05851 | R16: 0 | S16: 0 | T16: =M16+N16+O16+P16 -> 6826.6394 | U16: =IFERROR(T16/L16,0) -> 2202.1417
A17: 10005711 | B17: POTA FILETE C/M C/T FR 0.5-1.0 AA BL10 S20 | C17: 0 | E17: 0 | G17: 10005721 | H17: =1831.106/1000 -> 1.831106 | I17: 0.67 | J17: =$H$62 -> -0.10965909 | K17: =C17/1000 -> 0 | L17: =IF(E17<0,0,E17)/1000 -> 0 | M17: =IFERROR(H17*L17,0)*1000 -> 0 | N17: =207.84*L17 -> 0 | O17: =$O$57/$L$55*L17 -> 0 | P17: =$P$57/$L$55*L17 -> 0 | Q17: =$Q$57/$L$55*L17 -> 0 | R17: 0 | S17: 0 | T17: =M17+N17+O17+P17 -> 0 | U17: =IFERROR(T17/L17,0) -> 0
A18: 10010126 | B18: POTA FILETE C/M C/T FR 1.0 - 3.0 AA BL10 S20 | C18: 5280 | E18: 5280 | G18: 10005721 | H18: =1831.106/1000 -> 1.831106 | I18: 0.67 | J18: =$H$62 -> -0.10965909 | K18: =C18/1000 -> 5.28 | L18: =IF(E18<0,0,E18)/1000 -> 5.28 | M18: =IFERROR(H18*L18,0)*1000 -> 9668.2397 | N18: =207.84*L18 -> 1097.3952 | O18: =$O$57/$L$55*L18 -> 290.53362 | P18: =$P$57/$L$55*L18 -> 571.13987 | Q18: =$Q$57/$L$55*L18 -> 456.56416 | R18: 0 | S18: 0 | T18: =M18+N18+O18+P18 -> 11627.308 | U18: =IFERROR(T18/L18,0) -> 2202.1417
A19: 10005718 | B19: POTA FILETE C/M C/T FR 1-2 AA BL10 S20 JAPON | C19: 17640 | E19: 17640 | G19: 10005721 | H19: =1831.106/1000 -> 1.831106 | I19: 0.67 | J19: =$H$62 -> -0.10965909 | K19: =C19/1000 -> 17.64 | L19: =IF(E19<0,0,E19)/1000 -> 17.64 | M19: =IFERROR(H19*L19,0)*1000 -> 32300.71 | N19: =207.84*L19 -> 3666.2976 | O19: =$O$57/$L$55*L19 -> 970.64642 | P19: =$P$57/$L$55*L19 -> 1908.1264 | Q19: =$Q$57/$L$55*L19 -> 1525.3394 | R19: 0 | S19: 0 | T19: =M19+N19+O19+P19 -> 38845.78 | U19: =IFERROR(T19/L19,0) -> 2202.1417
A20: 10009971 | B20: POTA FILETE C/M C/T FR 0.5-1.0 AAA BL10 S20 | C20: 0 | E20: 0 | G20: 10005721 | H20: =1831.106/1000 -> 1.831106 | I20: 0.67 | J20: =$H$62 -> -0.10965909 | K20: =C20/1000 -> 0 | L20: =IF(E20<0,0,E20)/1000 -> 0 | M20: =IFERROR(H20*L20,0)*1000 -> 0 | N20: =207.84*L20 -> 0 | O20: =$O$57/$L$55*L20 -> 0 | P20: =$P$57/$L$55*L20 -> 0 | Q20: =$Q$57/$L$55*L20 -> 0 | R20: 0 | S20: 0 | T20: =M20+N20+O20+P20 -> 0 | U20: =IFERROR(T20/L20,0) -> 0
A21: 10009972 | B21: POTA FILETE C/M C/T FR 1-2 AA BL10 S20 50% ROSADO | C21: 2720 | E21: 2720 | G21: 10005721 | H21: =1831.106/1000 -> 1.831106 | I21: 0.67 | J21: =$H$62 -> -0.10965909 | K21: =C21/1000 -> 2.72 | L21: =IF(E21<0,0,E21)/1000 -> 2.72 | M21: =IFERROR(H21*L21,0)*1000 -> 4980.6083 | N21: =207.84*L21 -> 565.3248 | O21: =$O$57/$L$55*L21 -> 149.66884 | P21: =$P$57/$L$55*L21 -> 294.22357 | Q21: =$Q$57/$L$55*L21 -> 235.19972 | R21: 0 | S21: 0 | T21: =M21+N21+O21+P21 -> 5989.8255 | U21: =IFERROR(T21/L21,0) -> 2202.1417
A22: 10010063 | B22: POTA FILETE C/M C/T FR 2-4 AAA BL10 S20 | C22: 0 | E22: 0 | G22: 10005721 | H22: =1831.106/1000 -> 1.831106 | I22: 0.67 | J22: =$H$62 -> -0.10965909 | K22: =C22/1000 -> 0 | L22: =IF(E22<0,0,E22)/1000 -> 0 | M22: =IFERROR(H22*L22,0)*1000 -> 0 | N22: =207.84*L22 -> 0 | O22: =$O$57/$L$55*L22 -> 0 | P22: =$P$57/$L$55*L22 -> 0 | Q22: =$Q$57/$L$55*L22 -> 0 | R22: 0 | S22: 0 | T22: =M22+N22+O22+P22 -> 0 | U22: =IFERROR(T22/L22,0) -> 0
A23: 10009298 | B23: POTA FILETE SM ST 1-2 CM/ESP | C23: 3200 | E23: 3200 | G23: 10005721 | H23: =1831.106/1000 -> 1.831106 | I23: 0.67 | J23: =$H$62 -> -0.10965909 | K23: =C23/1000 -> 3.2 | L23: =IF(E23<0,0,E23)/1000 -> 3.2 | M23: =IFERROR(H23*L23,0)*1000 -> 5859.5392 | N23: =207.84*L23 -> 665.088 | O23: =$O$57/$L$55*L23 -> 176.08098 | P23: =$P$57/$L$55*L23 -> 346.14538 | Q23: =$Q$57/$L$55*L23 -> 276.70555 | R23: 0 | S23: 0 | T23: =M23+N23+O23+P23 -> 7046.8536 | U23: =IFERROR(T23/L23,0) -> 2202.1417
A24: 10009184 | B24: POTA NUCAS FR ABIERTAS 0.1 - 0.3 BL10 S2 | C24: 147120 | E24: 147120 | G24: 10005779 | H24: =1793.326/1000 -> 1.793326 | I24: 0.65 | J24: =$H$62 -> -0.10965909 | K24: =C24/1000 -> 147.12 | L24: =IF(E24<0,0,E24)/1000 -> 147.12 | M24: =IFERROR(H24*L24,0)*1000 -> 263834.12 | N24: =207.84*L24 -> 30577.421 | O24: =$O$57/$L$55*L24 -> 8095.3232 | P24: =$P$57/$L$55*L24 -> 15914.034 | Q24: =$Q$57/$L$55*L24 -> 12721.538 | R24: 0 | S24: 0 | T24: =M24+N24+O24+P24 -> 318420.9 | U24: =IFERROR(T24/L24,0) -> 2164.3617
A25: 10009271 | B25: POTA NUCAS FR CERRADA 0.1 - 0.3 BL10 S2 | C25: 49520 | E25: 49520 | G25: 10005779 | H25: =1793.326/1000 -> 1.793326 | I25: 0.65 | J25: =$H$62 -> -0.10965909 | K25: =C25/1000 -> 49.52 | L25: =IF(E25<0,0,E25)/1000 -> 49.52 | M25: =IFERROR(H25*L25,0)*1000 -> 88805.504 | N25: =207.84*L25 -> 10292.237 | O25: =$O$57/$L$55*L25 -> 2724.8532 | P25: =$P$57/$L$55*L25 -> 5356.5997 | Q25: =$Q$57/$L$55*L25 -> 4282.0185 | R25: 0 | S25: 0 | T25: =M25+N25+O25+P25 -> 107179.19 | U25: =IFERROR(T25/L25,0) -> 2164.3617
A26: 10009183 | B26: POTA NUCAS FR CERRADA <0.1 BL10 S2 | C26: 1260 | E26: 1260 | G26: 10005779 | H26: =1793.326/1000 -> 1.793326 | I26: 0.65 | J26: =$H$62 -> -0.10965909 | K26: =C26/1000 -> 1.26 | L26: =IF(E26<0,0,E26)/1000 -> 1.26 | M26: =IFERROR(H26*L26,0)*1000 -> 2259.5908 | N26: =207.84*L26 -> 261.8784 | O26: =$O$57/$L$55*L26 -> 69.331887 | P26: =$P$57/$L$55*L26 -> 136.29474 | Q26: =$Q$57/$L$55*L26 -> 108.95281 | R26: 0 | S26: 0 | T26: =M26+N26+O26+P26 -> 2727.0958 | U26: =IFERROR(T26/L26,0) -> 2164.3617
A27: 10005779 | B27: POTA NUCAS FR ABIERTAS 0.5-1 BL10 S20 | C27: 16180 | D27: 16180 | E27: 0 | G27: 10005779 | H27: =1793.326/1000 -> 1.793326 | I27: 0.65 | J27: =$H$62 -> -0.10965909 | K27: =C27/1000 -> 16.18 | L27: =IF(E27<0,0,E27)/1000 -> 0 | M27: =IFERROR(H27*L27,0)*1000 -> 0 | N27: =207.84*L27 -> 0 | O27: =$O$57/$L$55*L27 -> 0 | P27: =$P$57/$L$55*L27 -> 0 | Q27: =$Q$57/$L$55*L27 -> 0 | R27: 0 | S27: 0 | T27: =M27+N27+O27+P27 -> 0 | U27: =IFERROR(T27/L27,0) -> 0
A28: 10005776 | B28: POTA NUCAS FR ABIERTAS 0.3-0.5 BL10 S20 | C28: 174240 | E28: 174240 | G28: 10005779 | H28: =1793.326/1000 -> 1.793326 | I28: 0.65 | J28: =$H$62 -> -0.10965909 | K28: =C28/1000 -> 174.24 | L28: =IF(E28<0,0,E28)/1000 -> 174.24 | M28: =IFERROR(H28*L28,0)*1000 -> 312469.12 | N28: =207.84*L28 -> 36214.042 | O28: =$O$57/$L$55*L28 -> 9587.6095 | P28: =$P$57/$L$55*L28 -> 18847.616 | Q28: =$Q$57/$L$55*L28 -> 15066.617 | R28: 0 | S28: 0 | T28: =M28+N28+O28+P28 -> 377118.39 | U28: =IFERROR(T28/L28,0) -> 2164.3617
A29: 10005781 | B29: POTA NUCAS FR ABIERTAS 1-2 BL10 S20 | C29: 20440 | D29: 7840 | E29: 12600 | G29: 10005779 | H29: =1793.326/1000 -> 1.793326 | I29: 0.65 | J29: =$H$62 -> -0.10965909 | K29: =C29/1000 -> 20.44 | L29: =IF(E29<0,0,E29)/1000 -> 12.6 | M29: =IFERROR(H29*L29,0)*1000 -> 22595.908 | N29: =207.84*L29 -> 2618.784 | O29: =$O$57/$L$55*L29 -> 693.31887 | P29: =$P$57/$L$55*L29 -> 1362.9474 | Q29: =$Q$57/$L$55*L29 -> 1089.5281 | R29: 0 | S29: 0 | T29: =M29+N29+O29+P29 -> 27270.958 | U29: =IFERROR(T29/L29,0) -> 2164.3617
A30: 10007567 | B30: POTA REJOS OR FR LIMPIOS S/COD BL10 S20 | C30: 73900 | E30: 73900 | G30: 10007567 | H30: =1712.173/1000 -> 1.712173 | I30: 0.68 | J30: =$H$62 -> -0.10965909 | K30: =C30/1000 -> 73.9 | L30: =IF(E30<0,0,E30)/1000 -> 73.9 | M30: =IFERROR(H30*L30,0)*1000 -> 126529.58 | N30: =207.84*L30 -> 15359.376 | O30: =$O$57/$L$55*L30 -> 4066.3702 | P30: =$P$57/$L$55*L30 -> 7993.7948 | Q30: =$Q$57/$L$55*L30 -> 6390.1689 | R30: 0 | S30: 0 | T30: =M30+N30+O30+P30 -> 153949.13 | U30: =IFERROR(T30/L30,0) -> 2083.2087
A31: 10010107 | B31: POTA REJOS OR FR LIMPIOS <60 cm BL10 S20 | C31: 36320 | E31: 36320 | G31: 10007567 | H31: =1712.173/1000 -> 1.712173 | I31: 0.68 | J31: =$H$62 -> -0.10965909 | K31: =C31/1000 -> 36.32 | L31: =IF(E31<0,0,E31)/1000 -> 36.32 | M31: =IFERROR(H31*L31,0)*1000 -> 62186.123 | N31: =207.84*L31 -> 7548.7488 | O31: =$O$57/$L$55*L31 -> 1998.5192 | P31: =$P$57/$L$55*L31 -> 3928.75 | Q31: =$Q$57/$L$55*L31 -> 3140.608 | R31: 0 | S31: 0 | T31: =M31+N31+O31+P31 -> 75662.141 | U31: =IFERROR(T31/L31,0) -> 2083.2087
A32: 10009185 | B32: POTA REJOS FR C/U C/V S/OR <0.1 BL10 | C32: 7300 | E32: 7300 | G32: 10007162 | H32: =1783.985/1000 -> 1.783985 | I32: 0.68 | J32: =$H$62 -> -0.10965909 | K32: =C32/1000 -> 7.3 | L32: =IF(E32<0,0,E32)/1000 -> 7.3 | M32: =IFERROR(H32*L32,0)*1000 -> 13023.09 | N32: =207.84*L32 -> 1517.232 | O32: =$O$57/$L$55*L32 -> 401.68474 | P32: =$P$57/$L$55*L32 -> 789.64414 | Q32: =$Q$57/$L$55*L32 -> 631.23455 | R32: 0 | S32: 0 | T32: =M32+N32+O32+P32 -> 15731.651 | U32: =IFERROR(T32/L32,0) -> 2155.0207
A33: 10009186 | B33: POTA REJOS FR C/U C/V S/OR 0.1-0.3 BL10 | C33: 60 | E33: 60 | G33: 10007162 | H33: =1783.985/1000 -> 1.783985 | I33: 0.68 | J33: =$H$62 -> -0.10965909 | K33: =C33/1000 -> 0.06 | L33: =IF(E33<0,0,E33)/1000 -> 0.06 | M33: =IFERROR(H33*L33,0)*1000 -> 107.0391 | N33: =207.84*L33 -> 12.4704 | O33: =$O$57/$L$55*L33 -> 3.3015184 | P33: =$P$57/$L$55*L33 -> 6.4902258 | Q33: =$Q$57/$L$55*L33 -> 5.1882291 | R33: 0 | S33: 0 | T33: =M33+N33+O33+P33 -> 129.30124 | U33: =IFERROR(T33/L33,0) -> 2155.0207
A34: 10009777 | B34: POTA REJOS FR C/U C/V S/OR 0.3-0.5BL10 | C34: 12840 | E34: 12840 | G34: 10007162 | H34: =1783.985/1000 -> 1.783985 | I34: 0.68 | J34: =$H$62 -> -0.10965909 | K34: =C34/1000 -> 12.84 | L34: =IF(E34<0,0,E34)/1000 -> 12.84 | M34: =IFERROR(H34*L34,0)*1000 -> 22906.367 | N34: =207.84*L34 -> 2668.6656 | O34: =$O$57/$L$55*L34 -> 706.52494 | P34: =$P$57/$L$55*L34 -> 1388.9083 | Q34: =$Q$57/$L$55*L34 -> 1110.281 | R34: 0 | S34: 0 | T34: =M34+N34+O34+P34 -> 27670.466 | U34: =IFERROR(T34/L34,0) -> 2155.0207
A35: 10010108 | B35: POTA REJOS FR C/U C/V S/OR 0.5-1.0 BL10 | C35: 41080 | E35: 41080 | G35: 10007162 | H35: =1783.985/1000 -> 1.783985 | I35: 0.68 | J35: =$H$62 -> -0.10965909 | K35: =C35/1000 -> 41.08 | L35: =IF(E35<0,0,E35)/1000 -> 41.08 | M35: =IFERROR(H35*L35,0)*1000 -> 73286.104 | N35: =207.84*L35 -> 8538.0672 | O35: =$O$57/$L$55*L35 -> 2260.4396 | P35: =$P$57/$L$55*L35 -> 4443.6413 | Q35: =$Q$57/$L$55*L35 -> 3552.2076 | R35: 0 | S35: 0 | T35: =M35+N35+O35+P35 -> 88528.252 | U35: =IFERROR(T35/L35,0) -> 2155.0207
A36: 10009187 | B36: POTA REJOS FR C/B S/U S/V S/OR 0.3-0.5 BL10 | C36: 120 | E36: 120 | G36: 10007162 | H36: =1783.985/1000 -> 1.783985 | I36: 0.68 | J36: =$H$62 -> -0.10965909 | K36: =C36/1000 -> 0.12 | L36: =IF(E36<0,0,E36)/1000 -> 0.12 | M36: =IFERROR(H36*L36,0)*1000 -> 214.0782 | N36: =207.84*L36 -> 24.9408 | O36: =$O$57/$L$55*L36 -> 6.6030369 | P36: =$P$57/$L$55*L36 -> 12.980452 | Q36: =$Q$57/$L$55*L36 -> 10.376458 | R36: 0 | S36: 0 | T36: =M36+N36+O36+P36 -> 258.60249 | U36: =IFERROR(T36/L36,0) -> 2155.0207
A37: 10007161 | B37: POTA REJOS FR C/B S/U S/V S/OR 0.5-1 BL1 0 | C37: 23580 | E37: 23580 | G37: 10007162 | H37: =1783.985/1000 -> 1.783985 | I37: 0.68 | J37: =$H$62 -> -0.10965909 | K37: =C37/1000 -> 23.58 | L37: =IF(E37<0,0,E37)/1000 -> 23.58 | M37: =IFERROR(H37*L37,0)*1000 -> 42066.366 | N37: =207.84*L37 -> 4900.8672 | O37: =$O$57/$L$55*L37 -> 1297.4967 | P37: =$P$57/$L$55*L37 -> 2550.6588 | Q37: =$Q$57/$L$55*L37 -> 2038.9741 | R37: 0 | S37: 0 | T37: =M37+N37+O37+P37 -> 50815.389 | U37: =IFERROR(T37/L37,0) -> 2155.0207
A38: 10009658 | B38: POTA REJOS FR C/B C/U C/V S/OR 1.0 up BL 10S20 | C38: 2780 | E38: 2780 | G38: 10007162 | H38: =1783.985/1000 -> 1.783985 | I38: 0.68 | J38: =$H$62 -> -0.10965909 | K38: =C38/1000 -> 2.78 | L38: =IF(E38<0,0,E38)/1000 -> 2.78 | M38: =IFERROR(H38*L38,0)*1000 -> 4959.4783 | N38: =207.84*L38 -> 577.7952 | O38: =$O$57/$L$55*L38 -> 152.97035 | P38: =$P$57/$L$55*L38 -> 300.7138 | Q38: =$Q$57/$L$55*L38 -> 240.38795 | R38: 0 | S38: 0 | T38: =M38+N38+O38+P38 -> 5990.9577 | U38: =IFERROR(T38/L38,0) -> 2155.0207
