Workbook

Sheet RESUMEN AL 17-8-2026
C2: PERU FROST
C3: AVANCE COMERCIAL AL 17-8-2026
F5: RENTABILIDAD DEL INVENTARIO | X5: 46235 | AA5: 46245 | AD5: 46250 | AG5: POR DEFINIR | AJ5: TOTAL PROYECTADO JULIO 2026 | AX5: UNITARIOS POR TM
B6: Código | C6: Producto | D6: TM en Stock Libre | E6: CU | F6: Costo Ventas | G6: Gasto Ventas | H6: Gasto ADM | I6: Gasto Fin | J6: Depreciación | K6: Utilidad Neta | L6: Margen Neto | M6: Venta Equilibrio a Utd Neta | N6: Precio Equilibrio x TM a Utd Neta | O6: Venta Equilibro a EBITDA | P6: Precio Equilibrio x TM a EBITDA | Q6: Precio Mercado | R6: Venta total | S6: Utilidad | T6: Mg Neto | U6: EBITDA | V6: Mg EBITDA | X6: TM | Y6: Venta | Z6: Precio x TM | AA6: TM | AB6: Venta | AC6: Precio x TM | AD6: TM | AE6: Venta | AF6: Precio x TM | AG6: TM | AH6: Venta | AI6: Precio x TM | AJ6: TM | AK6: Venta | AL6: Precio x TM | AM6: Costo Ventas | AN6: Gasto Ventas | AO6: Gasto Adm | AP6: Gasto Fin | AQ6: Depreciación | AR6: Drawback | AS6: Utilidad Neta | AT6: Mg Neto % | AU6: EBITDA | AV6: MG EBITDA | AX6: Precio x TM | AY6: Costo Ventas | AZ6: Gasto Ventas | BA6: Gasto Adm | BB6: Gasto Fin | BC6: Depreciación | BD6: Drawback | BE6: Utilidad Neta | BF6: EBITDA
B7: 10005721 | C7: POTA FILETE CONGELADO | D7: =TD!F4 -> 66.96 | E7: =IFERROR(F7/D7,0) -> 1834.431 | F7: =TD!G4 -> 122833.5 | G7: =TD!H4 -> 13916.966 | H7: =TD!I4 -> 3177.8717 | I7: =TD!J4 -> 6247.1573 | J7: =TD!K4 -> 4993.9223 | K7: 0 | L7: 0 | M7: =F7+G7+H7+I7 -> 146175.5 | N7: =IFERROR(M7/D7,0) -> 2183.0271 | O7: =F7+G7+H7-J7 -> 134934.42 | P7: =IFERROR(O7/D7,0) -> 2015.1496 | Q7: 1800 | R7: =Q7*D7 -> 120528 | S7: =R7-M7 -> -25647.496 | T7: =IFERROR(S7/R7,0) -> -0.21279284 | U7: =R7-(M7-J7-I7) -> -14406.416 | V7: =IFERROR(U7/R7,0) -> -0.11952755 | X7: {=SUM([2]Hoja6!$H$24:$H$28*([2]Hoja6!$E$24:$E$28=X$5)*($C7=[2]Hoja6!$J$24:$J$28))} -> 0 | Y7: {=SUM([2]Hoja6!$I$24:$I$28*([2]Hoja6!$E$24:$E$28=X$5)*($C7=[2]Hoja6!$J$24:$J$28))} -> 0 | Z7: =IFERROR(Y7/X7,0) -> 0 | AA7: {=SUM([2]Hoja6!$H$24:$H$28*([2]Hoja6!$E$24:$E$28=AA$5)*($C7=[2]Hoja6!$J$24:$J$28))} -> 0 | AB7: {=SUM([2]Hoja6!$I$24:$I$28*([2]Hoja6!$E$24:$E$28=AA$5)*($C7=[2]Hoja6!$J$24:$J$28))} -> 0 | AC7: =IFERROR(AB7/AA7,0) -> 0 | AD7: {=SUM([2]Hoja6!$H$24:$H$28*([2]Hoja6!$E$24:$E$28=AD$5)*($C7=[2]Hoja6!$J$24:$J$28))} -> 0 | AE7: {=SUM([2]Hoja6!$I$24:$I$28*([2]Hoja6!$E$24:$E$28=AD$5)*($C7=[2]Hoja6!$J$24:$J$28))} -> 0 | AF7: =IFERROR(AE7/AD7,0) -> 0 | AG7: {=SUM([2]Hoja6!$H$24:$H$28*([2]Hoja6!$E$24:$E$28=AG$5)*($C7=[2]Hoja6!$J$24:$J$28))} -> 0 | AH7: {=SUM([2]Hoja6!$I$24:$I$28*([2]Hoja6!$E$24:$E$28=AG$5)*($C7=[2]Hoja6!$J$24:$J$28))} -> 0 | AI7: =IFERROR(AH7/AG7,0) -> 0 | AJ7: =X7+AA7+AD7+AG7 -> 0 | AK7: =Y7+AB7+AE7+AH7 -> 0 | AL7: =IFERROR(AK7/AJ7,0) -> 0 | AM7: =-IFERROR(F7/D7*AJ7,0) -> 0 | AN7: =-207.84*AJ7 -> 0 | AO7: =$AO$20/$AJ$20*$AJ7 -> 0 | AP7: =$AP$20/$AJ$20*$AJ7 -> 0 | AQ7: =$AQ$20/$AJ$20*$AJ7 -> 0 | AR7: =(AK7-AJ7*$AO$21)*0.03 -> 0 | AS7: =AK7+SUM(AM7:AP7,AR7) -> 0 | AT7: =IFERROR(AS7/AK7,0) -> 0 | AU7: =AK7+AM7+AN7+AO7+AR7-AQ7 -> 0 | AV7: =IFERROR(AU7/AK7,0) -> 0 | AX7: =AL7 -> 0 | AY7: =IFERROR(AM7/$AJ7,0) -> 0 | AZ7: =IFERROR(AN7/$AJ7,0) -> 0 | BA7: =IFERROR(AO7/$AJ7,0) -> 0 | BB7: =IFERROR(AP7/$AJ7,0) -> 0 | BC7: =IFERROR(AQ7/$AJ7,0) -> 0 | BD7: =IFERROR(AR7/$AJ7,0) -> 0 | BE7: =IFERROR(AS7/$AJ7,0) -> 0 | BF7: =IFERROR(AU7/$AJ7,0) -> 0
B8: 10005779 | C8: POTA NUCAS CONGELADAS | D8: =TD!F5 -> 368.64 | E8: =IFERROR(F8/D8,0) -> 1483.423 | F8: =TD!G5 -> 546849.04 | G8: =TD!H5 -> 76618.138 | H8: =TD!I5 -> 17495.38 | I8: =TD!J5 -> 34392.952 | J8: =TD!K5 -> 27493.422 | K8: 0 | L8: 0 | M8: =F8+G8+H8+I8 -> 675355.51 | N8: =IFERROR(M8/D8,0) -> 1832.0191 | O8: =F8+G8+H8-J8 -> 613469.14 | P8: =IFERROR(O8/D8,0) -> 1664.1415 | Q8: 1400 | R8: =Q8*D8 -> 516096 | S8: =R8-M8 -> -159259.51 | T8: =IFERROR(S8/R8,0) -> -0.30858505 | U8: =R8-(M8-J8-I8) -> -97373.139 | V8: =IFERROR(U8/R8,0) -> -0.18867253 | X8: {=SUM([2]Hoja6!$H$24:$H$28*([2]Hoja6!$E$24:$E$28=X$5)*($C8=[2]Hoja6!$J$24:$J$28))} -> 0 | Y8: {=SUM([2]Hoja6!$I$24:$I$28*([2]Hoja6!$E$24:$E$28=X$5)*($C8=[2]Hoja6!$J$24:$J$28))} -> 0 | Z8: =IFERROR(Y8/X8,0) -> 0 | AA8: {=SUM([2]Hoja6!$H$24:$H$28*([2]Hoja6!$E$24:$E$28=AA$5)*($C8=[2]Hoja6!$J$24:$J$28))} -> 0 | AB8: {=SUM([2]Hoja6!$I$24:$I$28*([2]Hoja6!$E$24:$E$28=AA$5)*($C8=[2]Hoja6!$J$24:$J$28))} -> 0 | AC8: =IFERROR(AB8/AA8,0) -> 0 | AD8: {=SUM([2]Hoja6!$H$24:$H$28*([2]Hoja6!$E$24:$E$28=AD$5)*($C8=[2]Hoja6!$J$24:$J$28))} -> 0 | AE8: {=SUM([2]Hoja6!$I$24:$I$28*([2]Hoja6!$E$24:$E$28=AD$5)*($C8=[2]Hoja6!$J$24:$J$28))} -> 0 | AF8: =IFERROR(AE8/AD8,0) -> 0 | AG8: {=SUM([2]Hoja6!$H$24:$H$28*([2]Hoja6!$E$24:$E$28=AG$5)*($C8=[2]Hoja6!$J$24:$J$28))} -> 0 | AH8: {=SUM([2]Hoja6!$I$24:$I$28*([2]Hoja6!$E$24:$E$28=AG$5)*($C8=[2]Hoja6!$J$24:$J$28))} -> 0 | AI8: =IFERROR(AH8/AG8,0) -> 0 | AJ8: =X8+AA8+AD8+AG8 -> 0 | AK8: =Y8+AB8+AE8+AH8 -> 0 | AL8: =IFERROR(AK8/AJ8,0) -> 0 | AM8: =-IFERROR(F8/D8*AJ8,0) -> 0 | AN8: =-207.84*AJ8 -> 0 | AO8: =$AO$20/$AJ$20*$AJ8 -> 0 | AP8: =$AP$20/$AJ$20*$AJ8 -> 0 | AQ8: =$AQ$20/$AJ$20*$AJ8 -> 0 | AR8: =(AK8-AJ8*$AO$21)*0.03 -> 0 | AS8: =AK8+SUM(AM8:AP8,AR8) -> 0 | AT8: =IFERROR(AS8/AK8,0) -> 0 | AU8: =AK8+AM8+AN8+AO8+AR8-AQ8 -> 0 | AV8: =IFERROR(AU8/AK8,0) -> 0 | AX8: =AL8 -> 0 | AY8: =IFERROR(AM8/$AJ8,0) -> 0 | AZ8: =IFERROR(AN8/$AJ8,0) -> 0 | BA8: =IFERROR(AO8/$AJ8,0) -> 0 | BB8: =IFERROR(AP8/$AJ8,0) -> 0 | BC8: =IFERROR(AQ8/$AJ8,0) -> 0 | BD8: =IFERROR(AR8/$AJ8,0) -> 0 | BE8: =IFERROR(AS8/$AJ8,0) -> 0 | BF8: =IFERROR(AU8/$AJ8,0) -> 0
B9: 10006719 | C9: POTA ALAS CONGELADAS | D9: =TD!F6 -> 17.9 | E9: =IFERROR(F9/D9,0) -> 1731.9701 | F9: =TD!G6 -> 31002.265 | G9: =TD!H6 -> 3720.336 | H9: =TD!I6 -> 849.52066 | I9: =TD!J6 -> 1670.0137 | J9: =TD!K6 -> 1334.9942 | K9: 0 | L9: 0 | M9: =F9+G9+H9+I9 -> 37242.136 | N9: =IFERROR(M9/D9,0) -> 2080.5662 | O9: =F9+G9+H9-J9 -> 34237.128 | P9: =IFERROR(O9/D9,0) -> 1912.6887 | Q9: 1950 | R9: =Q9*D9 -> 34905 | S9: =R9-M9 -> -2337.1356 | T9: =IFERROR(S9/R9,0) -> -0.066957044 | U9: =R9-(M9-J9-I9) -> 667.87223 | V9: =IFERROR(U9/R9,0) -> 0.019133999 | X9: {=SUM([2]Hoja6!$H$24:$H$28*([2]Hoja6!$E$24:$E$28=X$5)*($C9=[2]Hoja6!$J$24:$J$28))} -> 0 | Y9: {=SUM([2]Hoja6!$I$24:$I$28*([2]Hoja6!$E$24:$E$28=X$5)*($C9=[2]Hoja6!$J$24:$J$28))} -> 0 | Z9: =IFERROR(Y9/X9,0) -> 0 | AA9: {=SUM([2]Hoja6!$H$24:$H$28*([2]Hoja6!$E$24:$E$28=AA$5)*($C9=[2]Hoja6!$J$24:$J$28))} -> 27 | AB9: {=SUM([2]Hoja6!$I$24:$I$28*([2]Hoja6!$E$24:$E$28=AA$5)*($C9=[2]Hoja6!$J$24:$J$28))} -> 48600 | AC9: =IFERROR(AB9/AA9,0) -> 1800 | AD9: {=SUM([2]Hoja6!$H$24:$H$28*([2]Hoja6!$E$24:$E$28=AD$5)*($C9=[2]Hoja6!$J$24:$J$28))} -> 0 | AE9: {=SUM([2]Hoja6!$I$24:$I$28*([2]Hoja6!$E$24:$E$28=AD$5)*($C9=[2]Hoja6!$J$24:$J$28))} -> 0 | AF9: =IFERROR(AE9/AD9,0) -> 0 | AG9: {=SUM([2]Hoja6!$H$24:$H$28*([2]Hoja6!$E$24:$E$28=AG$5)*($C9=[2]Hoja6!$J$24:$J$28))} -> 0 | AH9: {=SUM([2]Hoja6!$I$24:$I$28*([2]Hoja6!$E$24:$E$28=AG$5)*($C9=[2]Hoja6!$J$24:$J$28))} -> 0 | AI9: =IFERROR(AH9/AG9,0) -> 0 | AJ9: =X9+AA9+AD9+AG9 -> 27 | AK9: =Y9+AB9+AE9+AH9 -> 48600 | AL9: =IFERROR(AK9/AJ9,0) -> 1800 | AM9: =-IFERROR(F9/D9*AJ9,0) -> -46763.193 | AN9: =-207.84*AJ9 -> -5611.68 | AO9: =$AO$20/$AJ$20*$AJ9 -> -11410.31 | AP9: =$AP$20/$AJ$20*$AJ9 -> -22430.736 | AQ9: =$AQ$20/$AJ$20*$AJ9 -> -17930.932 | AR9: =(AK9-AJ9*$AO$21)*0.03 -> 1365.5161 | AS9: =AK9+SUM(AM9:AP9,AR9) -> -36250.403 | AT9: =IFERROR(AS9/AK9,0) -> -0.74589306 | AU9: =AK9+AM9+AN9+AO9+AR9-AQ9 -> 4111.2647 | AV9: =IFERROR(AU9/AK9,0) -> 0.084593923 | AX9: =AL9 -> 1800 | AY9: =IFERROR(AM9/$AJ9,0) -> -1731.9701 | AZ9: =IFERROR(AN9/$AJ9,0) -> -207.84 | BA9: =IFERROR(AO9/$AJ9,0) -> -422.60407 | BB9: =IFERROR(AP9/$AJ9,0) -> -830.76799 | BC9: =IFERROR(AQ9/$AJ9,0) -> -664.10858 | BD9: =IFERROR(AR9/$AJ9,0) -> 50.574672 | BE9: =IFERROR(AS9/$AJ9,0) -> -1342.6075 | BF9: =IFERROR(AU9/$AJ9,0) -> 152.26906
B10: 10007050 | C10: POTA RECORTES COCIDOS | D10: =TD!F7 -> 114.855 | E10: =IFERROR(F10/D10,0) -> 1308.2098 | F10: =TD!G7 -> 150254.44 | G10: =TD!H7 -> 23871.463 | H10: =TD!I7 -> 5450.9327 | I10: =TD!J7 -> 10715.61 | J10: =TD!K7 -> 8565.964 | K10: 0 | L10: 0 | M10: =F10+G10+H10+I10 -> 190292.45 | N10: =IFERROR(M10/D10,0) -> 1656.8059 | O10: =F10+G10+H10-J10 -> 171010.87 | P10: =IFERROR(O10/D10,0) -> 1488.9284 | Q10: 1700 | R10: =Q10*D10 -> 195253.5 | S10: =R10-M10 -> 4961.0547 | T10: =IFERROR(S10/R10,0) -> 0.025408276 | U10: =R10-(M10-J10-I10) -> 24242.629 | V10: =IFERROR(U10/R10,0) -> 0.12415977 | X10: {=SUM([2]Hoja6!$H$24:$H$28*([2]Hoja6!$E$24:$E$28=X$5)*($C10=[2]Hoja6!$J$24:$J$28))} -> 0 | Y10: {=SUM([2]Hoja6!$I$24:$I$28*([2]Hoja6!$E$24:$E$28=X$5)*($C10=[2]Hoja6!$J$24:$J$28))} -> 0 | Z10: =IFERROR(Y10/X10,0) -> 0 | AA10: {=SUM([2]Hoja6!$H$24:$H$28*([2]Hoja6!$E$24:$E$28=AA$5)*($C10=[2]Hoja6!$J$24:$J$28))} -> 0 | AB10: {=SUM([2]Hoja6!$I$24:$I$28*([2]Hoja6!$E$24:$E$28=AA$5)*($C10=[2]Hoja6!$J$24:$J$28))} -> 0 | AC10: =IFERROR(AB10/AA10,0) -> 0 | AD10: {=SUM([2]Hoja6!$H$24:$H$28*([2]Hoja6!$E$24:$E$28=AD$5)*($C10=[2]Hoja6!$J$24:$J$28))} -> 0 | AE10: {=SUM([2]Hoja6!$I$24:$I$28*([2]Hoja6!$E$24:$E$28=AD$5)*($C10=[2]Hoja6!$J$24:$J$28))} -> 0 | AF10: =IFERROR(AE10/AD10,0) -> 0 | AG10: {=SUM([2]Hoja6!$H$24:$H$28*([2]Hoja6!$E$24:$E$28=AG$5)*($C10=[2]Hoja6!$J$24:$J$28))} -> 0 | AH10: {=SUM([2]Hoja6!$I$24:$I$28*([2]Hoja6!$E$24:$E$28=AG$5)*($C10=[2]Hoja6!$J$24:$J$28))} -> 0 | AI10: =IFERROR(AH10/AG10,0) -> 0 | AJ10: =X10+AA10+AD10+AG10 -> 0 | AK10: =Y10+AB10+AE10+AH10 -> 0 | AL10: =IFERROR(AK10/AJ10,0) -> 0 | AM10: =-IFERROR(F10/D10*AJ10,0) -> 0 | AN10: =-207.84*AJ10 -> 0 | AO10: =$AO$20/$AJ$20*$AJ10 -> 0 | AP10: =$AP$20/$AJ$20*$AJ10 -> 0 | AQ10: =$AQ$20/$AJ$20*$AJ10 -> 0 | AR10: =(AK10-AJ10*$AO$21)*0.03 -> 0 | AS10: =AK10+SUM(AM10:AP10,AR10) -> 0 | AT10: =IFERROR(AS10/AK10,0) -> 0 | AU10: =AK10+AM10+AN10+AO10+AR10-AQ10 -> 0 | AV10: =IFERROR(AU10/AK10,0) -> 0 | AX10: =AL10 -> 0 | AY10: =IFERROR(AM10/$AJ10,0) -> 0 | AZ10: =IFERROR(AN10/$AJ10,0) -> 0 | BA10: =IFERROR(AO10/$AJ10,0) -> 0 | BB10: =IFERROR(AP10/$AJ10,0) -> 0 | BC10: =IFERROR(AQ10/$AJ10,0) -> 0 | BD10: =IFERROR(AR10/$AJ10,0) -> 0 | BE10: =IFERROR(AS10/$AJ10,0) -> 0 | BF10: =IFERROR(AU10/$AJ10,0) -> 0
B11: 10007162 | C11: POTA REJOS CONGELADOS | D11: =TD!F8 -> 270.4 | E11: =IFERROR(F11/D11,0) -> 1596.5588 | F11: =TD!G8 -> 431709.5 | G11: =TD!H8 -> 56199.936 | H11: =TD!I8 -> 12832.982 | I11: =TD!J8 -> 25227.469 | J11: =TD!K8 -> 20166.616 | K11: 0 | L11: 0 | M11: =F11+G11+H11+I11 -> 525969.89 | N11: =IFERROR(M11/D11,0) -> 1945.1549 | O11: =F11+G11+H11-J11 -> 480575.81 | P11: =IFERROR(O11/D11,0) -> 1777.2774 | Q11: 2700 | R11: =Q11*D11 -> 730080 | S11: =R11-M11 -> 204110.11 | T11: =IFERROR(S11/R11,0) -> 0.27957225 | U11: =R11-(M11-J11-I11) -> 249504.19 | V11: =IFERROR(U11/R11,0) -> 0.34174912 | X11: {=SUM([2]Hoja6!$H$24:$H$28*([2]Hoja6!$E$24:$E$28=X$5)*($C11=[2]Hoja6!$J$24:$J$28))} -> 81 | Y11: {=SUM([2]Hoja6!$I$24:$I$28*([2]Hoja6!$E$24:$E$28=X$5)*($C11=[2]Hoja6!$J$24:$J$28))} -> 213300 | Z11: =IFERROR(Y11/X11,0) -> 2633.3333 | AA11: {=SUM([2]Hoja6!$H$24:$H$28*([2]Hoja6!$E$24:$E$28=AA$5)*($C11=[2]Hoja6!$J$24:$J$28))} -> 0 | AB11: {=SUM([2]Hoja6!$I$24:$I$28*([2]Hoja6!$E$24:$E$28=AA$5)*($C11=[2]Hoja6!$J$24:$J$28))} -> 0 | AC11: =IFERROR(AB11/AA11,0) -> 0 | AD11: {=SUM([2]Hoja6!$H$24:$H$28*([2]Hoja6!$E$24:$E$28=AD$5)*($C11=[2]Hoja6!$J$24:$J$28))} -> 0 | AE11: {=SUM([2]Hoja6!$I$24:$I$28*([2]Hoja6!$E$24:$E$28=AD$5)*($C11=[2]Hoja6!$J$24:$J$28))} -> 0 | AF11: =IFERROR(AE11/AD11,0) -> 0 | AG11: {=SUM([2]Hoja6!$H$24:$H$28*([2]Hoja6!$E$24:$E$28=AG$5)*($C11=[2]Hoja6!$J$24:$J$28))} -> 0 | AH11: {=SUM([2]Hoja6!$I$24:$I$28*([2]Hoja6!$E$24:$E$28=AG$5)*($C11=[2]Hoja6!$J$24:$J$28))} -> 0 | AI11: =IFERROR(AH11/AG11,0) -> 0 | AJ11: =X11+AA11+AD11+AG11 -> 81 | AK11: =Y11+AB11+AE11+AH11 -> 213300 | AL11: =IFERROR(AK11/AJ11,0) -> 2633.3333 | AM11: =-IFERROR(F11/D11*AJ11,0) -> -129321.26 | AN11: =-207.84*AJ11 -> -16835.04 | AO11: =$AO$20/$AJ$20*$AJ11 -> -34230.929 | AP11: =$AP$20/$AJ$20*$AJ11 -> -67292.207 | AQ11: =$AQ$20/$AJ$20*$AJ11 -> -53792.795 | AR11: =(AK11-AJ11*$AO$21)*0.03 -> 6121.5484 | AS11: =AK11+SUM(AM11:AP11,AR11) -> -28257.892 | AT11: =IFERROR(AS11/AK11,0) -> -0.13247957 | AU11: =AK11+AM11+AN11+AO11+AR11-AQ11 -> 92827.11 | AV11: =IFERROR(AU11/AK11,0) -> 0.43519508 | AX11: =AL11 -> 2633.3333 | AY11: =IFERROR(AM11/$AJ11,0) -> -1596.5588 | AZ11: =IFERROR(AN11/$AJ11,0) -> -207.84 | BA11: =IFERROR(AO11/$AJ11,0) -> -422.60407 | BB11: =IFERROR(AP11/$AJ11,0) -> -830.76799 | BC11: =IFERROR(AQ11/$AJ11,0) -> -664.10858 | BD11: =IFERROR(AR11/$AJ11,0) -> 75.574672 | BE11: =IFERROR(AS11/$AJ11,0) -> -348.86286 | BF11: =IFERROR(AU11/$AJ11,0) -> 1146.0137
B12: 10007567 | C12: POTA REPRODUCTORES | D12: =TD!F9 -> 132.38 | E12: =IFERROR(F12/D12,0) -> 1540.1637 | F12: =TD!G9 -> 203886.87 | G12: =TD!H9 -> 27513.859 | H12: =TD!I9 -> 6282.6561 | I12: =TD!J9 -> 12350.637 | J12: =TD!K9 -> 9872.9904 | K12: 0 | L12: 0 | M12: =F12+G12+H12+I12 -> 250034.02 | N12: =IFERROR(M12/D12,0) -> 1888.7598 | O12: =F12+G12+H12-J12 -> 227810.39 | P12: =IFERROR(O12/D12,0) -> 1720.8822 | Q12: 2800 | R12: =Q12*D12 -> 370664 | S12: =R12-M12 -> 120629.98 | T12: =IFERROR(S12/R12,0) -> 0.32544294 | U12: =R12-(M12-J12-I12) -> 142853.61 | V12: =IFERROR(U12/R12,0) -> 0.3853992 | X12: {=SUM([2]Hoja6!$H$24:$H$28*([2]Hoja6!$E$24:$E$28=X$5)*($C12=[2]Hoja6!$J$24:$J$28))} -> 0 | Y12: {=SUM([2]Hoja6!$I$24:$I$28*([2]Hoja6!$E$24:$E$28=X$5)*($C12=[2]Hoja6!$J$24:$J$28))} -> 0 | Z12: =IFERROR(Y12/X12,0) -> 0 | AA12: {=SUM([2]Hoja6!$H$24:$H$28*([2]Hoja6!$E$24:$E$28=AA$5)*($C12=[2]Hoja6!$J$24:$J$28))} -> 0 | AB12: {=SUM([2]Hoja6!$I$24:$I$28*([2]Hoja6!$E$24:$E$28=AA$5)*($C12=[2]Hoja6!$J$24:$J$28))} -> 0 | AC12: =IFERROR(AB12/AA12,0) -> 0 | AD12: {=SUM([2]Hoja6!$H$24:$H$28*([2]Hoja6!$E$24:$E$28=AD$5)*($C12=[2]Hoja6!$J$24:$J$28))} -> 0 | AE12: {=SUM([2]Hoja6!$I$24:$I$28*([2]Hoja6!$E$24:$E$28=AD$5)*($C12=[2]Hoja6!$J$24:$J$28))} -> 0 | AF12: =IFERROR(AE12/AD12,0) -> 0 | AG12: {=SUM([2]Hoja6!$H$24:$H$28*([2]Hoja6!$E$24:$E$28=AG$5)*($C12=[2]Hoja6!$J$24:$J$28))} -> 0 | AH12: {=SUM([2]Hoja6!$I$24:$I$28*([2]Hoja6!$E$24:$E$28=AG$5)*($C12=[2]Hoja6!$J$24:$J$28))} -> 0 | AI12: =IFERROR(AH12/AG12,0) -> 0 | AJ12: =X12+AA12+AD12+AG12 -> 0 | AK12: =Y12+AB12+AE12+AH12 -> 0 | AL12: =IFERROR(AK12/AJ12,0) -> 0 | AM12: =-IFERROR(F12/D12*AJ12,0) -> 0 | AN12: =-207.84*AJ12 -> 0 | AO12: =$AO$20/$AJ$20*$AJ12 -> 0 | AP12: =$AP$20/$AJ$20*$AJ12 -> 0 | AQ12: =$AQ$20/$AJ$20*$AJ12 -> 0 | AR12: =(AK12-AJ12*$AO$21)*0.03 -> 0 | AS12: =AK12+SUM(AM12:AP12,AR12) -> 0 | AT12: =IFERROR(AS12/AK12,0) -> 0 | AU12: =AK12+AM12+AN12+AO12+AR12-AQ12 -> 0 | AV12: =IFERROR(AU12/AK12,0) -> 0 | AX12: =AL12 -> 0 | AY12: =IFERROR(AM12/$AJ12,0) -> 0 | AZ12: =IFERROR(AN12/$AJ12,0) -> 0 | BA12: =IFERROR(AO12/$AJ12,0) -> 0 | BB12: =IFERROR(AP12/$AJ12,0) -> 0 | BC12: =IFERROR(AQ12/$AJ12,0) -> 0 | BD12: =IFERROR(AR12/$AJ12,0) -> 0 | BE12: =IFERROR(AS12/$AJ12,0) -> 0 | BF12: =IFERROR(AU12/$AJ12,0) -> 0
B13: 10007969 | C13: POTA CONOS | D13: =TD!F10 -> 0 | E13: =IFERROR(F13/D13,0) -> 0 | F13: =TD!G10 -> 0 | G13: =TD!H10 -> 0 | H13: =TD!I10 -> 0 | I13: =TD!J10 -> 0 | J13: =TD!K10 -> 0 | K13: 0 | L13: 0 | M13: =F13+G13+H13+I13 -> 0 | N13: =IFERROR(M13/D13,0) -> 0 | O13: =F13+G13+H13-J13 -> 0 | P13: =IFERROR(O13/D13,0) -> 0 | Q13: 1700 | R13: =Q13*D13 -> 0 | S13: =R13-M13 -> 0 | T13: =IFERROR(S13/R13,0) -> 0 | U13: =R13-(M13-J13-I13) -> 0 | V13: =IFERROR(U13/R13,0) -> 0 | X13: {=SUM([2]Hoja6!$H$24:$H$28*([2]Hoja6!$E$24:$E$28=X$5)*($C13=[2]Hoja6!$J$24:$J$28))} -> 26.4 | Y13: {=SUM([2]Hoja6!$I$24:$I$28*([2]Hoja6!$E$24:$E$28=X$5)*($C13=[2]Hoja6!$J$24:$J$28))} -> 42240 | Z13: =IFERROR(Y13/X13,0) -> 1600 | AA13: {=SUM([2]Hoja6!$H$24:$H$28*([2]Hoja6!$E$24:$E$28=AA$5)*($C13=[2]Hoja6!$J$24:$J$28))} -> 0 | AB13: {=SUM([2]Hoja6!$I$24:$I$28*([2]Hoja6!$E$24:$E$28=AA$5)*($C13=[2]Hoja6!$J$24:$J$28))} -> 0 | AC13: =IFERROR(AB13/AA13,0) -> 0 | AD13: {=SUM([2]Hoja6!$H$24:$H$28*([2]Hoja6!$E$24:$E$28=AD$5)*($C13=[2]Hoja6!$J$24:$J$28))} -> 0 | AE13: {=SUM([2]Hoja6!$I$24:$I$28*([2]Hoja6!$E$24:$E$28=AD$5)*($C13=[2]Hoja6!$J$24:$J$28))} -> 0 | AF13: =IFERROR(AE13/AD13,0) -> 0 | AG13: {=SUM([2]Hoja6!$H$24:$H$28*([2]Hoja6!$E$24:$E$28=AG$5)*($C13=[2]Hoja6!$J$24:$J$28))} -> 0 | AH13: {=SUM([2]Hoja6!$I$24:$I$28*([2]Hoja6!$E$24:$E$28=AG$5)*($C13=[2]Hoja6!$J$24:$J$28))} -> 0 | AI13: =IFERROR(AH13/AG13,0) -> 0 | AJ13: =X13+AA13+AD13+AG13 -> 26.4 | AK13: =Y13+AB13+AE13+AH13 -> 42240 | AL13: =IFERROR(AK13/AJ13,0) -> 1600 | AM13: =-IFERROR(F13/D13*AJ13,0) -> 0 | AN13: =-207.84*AJ13 -> -5486.976 | AO13: =$AO$20/$AJ$20*$AJ13 -> -11156.747 | AP13: =$AP$20/$AJ$20*$AJ13 -> -21932.275 | AQ13: =$AQ$20/$AJ$20*$AJ13 -> -17532.467 | AR13: =(AK13-AJ13*$AO$21)*0.03 -> 1176.7713 | AS13: =AK13+SUM(AM13:AP13,AR13) -> 4840.7731 | AT13: =IFERROR(AS13/AK13,0) -> 0.11460164 | AU13: =AK13+AM13+AN13+AO13+AR13-AQ13 -> 44305.515 | AV13: =IFERROR(AU13/AK13,0) -> 1.0488995 | AX13: =AL13 -> 1600 | AY13: =IFERROR(AM13/$AJ13,0) -> 0 | AZ13: =IFERROR(AN13/$AJ13,0) -> -207.84 | BA13: =IFERROR(AO13/$AJ13,0) -> -422.60407 | BB13: =IFERROR(AP13/$AJ13,0) -> -830.76799 | BC13: =IFERROR(AQ13/$AJ13,0) -> -664.10858 | BD13: =IFERROR(AR13/$AJ13,0) -> 44.574672 | BE13: =IFERROR(AS13/$AJ13,0) -> 183.36262 | BF13: =IFERROR(AU13/$AJ13,0) -> 1678.2392
B14: 10009239 | C14: POTA FILETE DARUMA | D14: =TD!F11 -> 0.86 | E14: =IFERROR(F14/D14,0) -> 3085.0611 | F14: =TD!G11 -> 2653.1526 | G14: =TD!H11 -> 178.7424 | H14: =TD!I11 -> 40.814959 | I14: =TD!J11 -> 80.235294 | J14: =TD!K11 -> 64.139384 | K14: 0 | L14: 0 | M14: =F14+G14+H14+I14 -> 2952.9452 | N14: =IFERROR(M14/D14,0) -> 3433.6572 | O14: =F14+G14+H14-J14 -> 2808.5705 | P14: =IFERROR(O14/D14,0) -> 3265.7797 | Q14: 3500 | R14: =Q14*D14 -> 3010 | S14: =R14-M14 -> 57.05478 | T14: =IFERROR(S14/R14,0) -> 0.018955077 | U14: =R14-(M14-J14-I14) -> 201.42946 | V14: =IFERROR(U14/R14,0) -> 0.066920086 | X14: {=SUM([2]Hoja6!$H$24:$H$28*([2]Hoja6!$E$24:$E$28=X$5)*($C14=[2]Hoja6!$J$24:$J$28))} -> 0 | Y14: {=SUM([2]Hoja6!$I$24:$I$28*([2]Hoja6!$E$24:$E$28=X$5)*($C14=[2]Hoja6!$J$24:$J$28))} -> 0 | Z14: =IFERROR(Y14/X14,0) -> 0 | AA14: {=SUM([2]Hoja6!$H$24:$H$28*([2]Hoja6!$E$24:$E$28=AA$5)*($C14=[2]Hoja6!$J$24:$J$28))} -> 0 | AB14: {=SUM([2]Hoja6!$I$24:$I$28*([2]Hoja6!$E$24:$E$28=AA$5)*($C14=[2]Hoja6!$J$24:$J$28))} -> 0 | AC14: =IFERROR(AB14/AA14,0) -> 0 | AD14: {=SUM([2]Hoja6!$H$24:$H$28*([2]Hoja6!$E$24:$E$28=AD$5)*($C14=[2]Hoja6!$J$24:$J$28))} -> 0 | AE14: {=SUM([2]Hoja6!$I$24:$I$28*([2]Hoja6!$E$24:$E$28=AD$5)*($C14=[2]Hoja6!$J$24:$J$28))} -> 0 | AF14: =IFERROR(AE14/AD14,0) -> 0 | AG14: {=SUM([2]Hoja6!$H$24:$H$28*([2]Hoja6!$E$24:$E$28=AG$5)*($C14=[2]Hoja6!$J$24:$J$28))} -> 0 | AH14: {=SUM([2]Hoja6!$I$24:$I$28*([2]Hoja6!$E$24:$E$28=AG$5)*($C14=[2]Hoja6!$J$24:$J$28))} -> 0 | AI14: =IFERROR(AH14/AG14,0) -> 0 | AJ14: =X14+AA14+AD14+AG14 -> 0 | AK14: =Y14+AB14+AE14+AH14 -> 0 | AL14: =IFERROR(AK14/AJ14,0) -> 0 | AM14: =-IFERROR(F14/D14*AJ14,0) -> 0 | AN14: =-207.84*AJ14 -> 0 | AO14: =$AO$20/$AJ$20*$AJ14 -> 0 | AP14: =$AP$20/$AJ$20*$AJ14 -> 0 | AQ14: =$AQ$20/$AJ$20*$AJ14 -> 0 | AR14: =(AK14-AJ14*$AO$21)*0.03 -> 0 | AS14: =AK14+SUM(AM14:AP14,AR14) -> 0 | AT14: =IFERROR(AS14/AK14,0) -> 0 | AU14: =AK14+AM14+AN14+AO14+AR14-AQ14 -> 0 | AV14: =IFERROR(AU14/AK14,0) -> 0 | AX14: =AL14 -> 0 | AY14: =IFERROR(AM14/$AJ14,0) -> 0 | AZ14: =IFERROR(AN14/$AJ14,0) -> 0 | BA14: =IFERROR(AO14/$AJ14,0) -> 0 | BB14: =IFERROR(AP14/$AJ14,0) -> 0 | BC14: =IFERROR(AQ14/$AJ14,0) -> 0 | BD14: =IFERROR(AR14/$AJ14,0) -> 0 | BE14: =IFERROR(AS14/$AJ14,0) -> 0 | BF14: =IFERROR(AU14/$AJ14,0) -> 0
B15: 10009334 | C15: POTA ALAS COCIDAS | D15: =TD!F12 -> 18.92 | E15: =IFERROR(F15/D15,0) -> 2649.6026 | F15: =TD!G12 -> 50130.481 | G15: =TD!H12 -> 3932.3328 | H15: =TD!I12 -> 897.9291 | I15: =TD!J12 -> 1765.1765 | J15: =TD!K12 -> 1411.0665 | K15: 0 | L15: 0 | M15: =F15+G15+H15+I15 -> 56725.92 | N15: =IFERROR(M15/D15,0) -> 2998.1987 | O15: =F15+G15+H15-J15 -> 53549.677 | P15: =IFERROR(O15/D15,0) -> 2830.3212 | Q15: 3500 | R15: =Q15*D15 -> 66220 | S15: =R15-M15 -> 9494.0803 | T15: =IFERROR(S15/R15,0) -> 0.1433718 | U15: =R15-(M15-J15-I15) -> 12670.323 | V15: =IFERROR(U15/R15,0) -> 0.19133681 | X15: {=SUM([2]Hoja6!$H$24:$H$28*([2]Hoja6!$E$24:$E$28=X$5)*($C15=[2]Hoja6!$J$24:$J$28))} -> 0 | Y15: {=SUM([2]Hoja6!$I$24:$I$28*([2]Hoja6!$E$24:$E$28=X$5)*($C15=[2]Hoja6!$J$24:$J$28))} -> 0 | Z15: =IFERROR(Y15/X15,0) -> 0 | AA15: {=SUM([2]Hoja6!$H$24:$H$28*([2]Hoja6!$E$24:$E$28=AA$5)*($C15=[2]Hoja6!$J$24:$J$28))} -> 0 | AB15: {=SUM([2]Hoja6!$I$24:$I$28*([2]Hoja6!$E$24:$E$28=AA$5)*($C15=[2]Hoja6!$J$24:$J$28))} -> 0 | AC15: =IFERROR(AB15/AA15,0) -> 0 | AD15: {=SUM([2]Hoja6!$H$24:$H$28*([2]Hoja6!$E$24:$E$28=AD$5)*($C15=[2]Hoja6!$J$24:$J$28))} -> 0 | AE15: {=SUM([2]Hoja6!$I$24:$I$28*([2]Hoja6!$E$24:$E$28=AD$5)*($C15=[2]Hoja6!$J$24:$J$28))} -> 0 | AF15: =IFERROR(AE15/AD15,0) -> 0 | AG15: {=SUM([2]Hoja6!$H$24:$H$28*([2]Hoja6!$E$24:$E$28=AG$5)*($C15=[2]Hoja6!$J$24:$J$28))} -> 0 | AH15: {=SUM([2]Hoja6!$I$24:$I$28*([2]Hoja6!$E$24:$E$28=AG$5)*($C15=[2]Hoja6!$J$24:$J$28))} -> 0 | AI15: =IFERROR(AH15/AG15,0) -> 0 | AJ15: =X15+AA15+AD15+AG15 -> 0 | AK15: =Y15+AB15+AE15+AH15 -> 0 | AL15: =IFERROR(AK15/AJ15,0) -> 0 | AM15: =-IFERROR(F15/D15*AJ15,0) -> 0 | AN15: =-207.84*AJ15 -> 0 | AO15: =$AO$20/$AJ$20*$AJ15 -> 0 | AP15: =$AP$20/$AJ$20*$AJ15 -> 0 | AQ15: =$AQ$20/$AJ$20*$AJ15 -> 0 | AR15: =(AK15-AJ15*$AO$21)*0.03 -> 0 | AS15: =AK15+SUM(AM15:AP15,AR15) -> 0 | AT15: =IFERROR(AS15/AK15,0) -> 0 | AU15: =AK15+AM15+AN15+AO15+AR15-AQ15 -> 0 | AV15: =IFERROR(AU15/AK15,0) -> 0 | AX15: =AL15 -> 0 | AY15: =IFERROR(AM15/$AJ15,0) -> 0 | AZ15: =IFERROR(AN15/$AJ15,0) -> 0 | BA15: =IFERROR(AO15/$AJ15,0) -> 0 | BB15: =IFERROR(AP15/$AJ15,0) -> 0 | BC15: =IFERROR(AQ15/$AJ15,0) -> 0 | BD15: =IFERROR(AR15/$AJ15,0) -> 0 | BE15: =IFERROR(AS15/$AJ15,0) -> 0 | BF15: =IFERROR(AU15/$AJ15,0) -> 0
B16: 10009386 | C16: VENTOSAS | D16: =TD!F13 -> 21.28 | E16: =IFERROR(F16/D16,0) -> 1597.9903 | F16: =TD!G13 -> 34005.233 | G16: =TD!H13 -> 4422.8352 | H16: =TD!I13 -> 1009.9329 | I16: =TD!J13 -> 1985.357 | J16: =TD!K13 -> 1587.0769 | K16: 0 | L16: 0 | M16: =F16+G16+H16+I16 -> 41423.358 | N16: =IFERROR(M16/D16,0) -> 1946.5864 | O16: =F16+G16+H16-J16 -> 37850.924 | P16: =IFERROR(O16/D16,0) -> 1778.7088 | Q16: 2000 | R16: =Q16*D16 -> 42560 | S16: =R16-M16 -> 1136.6422 | T16: =IFERROR(S16/R16,0) -> 0.026706819 | U16: =R16-(M16-J16-I16) -> 4709.0761 | V16: =IFERROR(U16/R16,0) -> 0.11064559 | X16: {=SUM([2]Hoja6!$H$24:$H$28*([2]Hoja6!$E$24:$E$28=X$5)*($C16=[2]Hoja6!$J$24:$J$28))} -> 0 | Y16: {=SUM([2]Hoja6!$I$24:$I$28*([2]Hoja6!$E$24:$E$28=X$5)*($C16=[2]Hoja6!$J$24:$J$28))} -> 0 | Z16: =IFERROR(Y16/X16,0) -> 0 | AA16: {=SUM([2]Hoja6!$H$24:$H$28*([2]Hoja6!$E$24:$E$28=AA$5)*($C16=[2]Hoja6!$J$24:$J$28))} -> 0 | AB16: {=SUM([2]Hoja6!$I$24:$I$28*([2]Hoja6!$E$24:$E$28=AA$5)*($C16=[2]Hoja6!$J$24:$J$28))} -> 0 | AC16: =IFERROR(AB16/AA16,0) -> 0 | AD16: {=SUM([2]Hoja6!$H$24:$H$28*([2]Hoja6!$E$24:$E$28=AD$5)*($C16=[2]Hoja6!$J$24:$J$28))} -> 0 | AE16: {=SUM([2]Hoja6!$I$24:$I$28*([2]Hoja6!$E$24:$E$28=AD$5)*($C16=[2]Hoja6!$J$24:$J$28))} -> 0 | AF16: =IFERROR(AE16/AD16,0) -> 0 | AG16: {=SUM([2]Hoja6!$H$24:$H$28*([2]Hoja6!$E$24:$E$28=AG$5)*($C16=[2]Hoja6!$J$24:$J$28))} -> 0 | AH16: {=SUM([2]Hoja6!$I$24:$I$28*([2]Hoja6!$E$24:$E$28=AG$5)*($C16=[2]Hoja6!$J$24:$J$28))} -> 0 | AI16: =IFERROR(AH16/AG16,0) -> 0 | AJ16: =X16+AA16+AD16+AG16 -> 0 | AK16: =Y16+AB16+AE16+AH16 -> 0 | AL16: =IFERROR(AK16/AJ16,0) -> 0 | AM16: =-IFERROR(F16/D16*AJ16,0) -> 0 | AN16: =-207.84*AJ16 -> 0 | AO16: =$AO$20/$AJ$20*$AJ16 -> 0 | AP16: =$AP$20/$AJ$20*$AJ16 -> 0 | AQ16: =$AQ$20/$AJ$20*$AJ16 -> 0 | AR16: =(AK16-AJ16*$AO$21)*0.03 -> 0 | AS16: =AK16+SUM(AM16:AP16,AR16) -> 0 | AT16: =IFERROR(AS16/AK16,0) -> 0 | AU16: =AK16+AM16+AN16+AO16+AR16-AQ16 -> 0 | AV16: =IFERROR(AU16/AK16,0) -> 0 | AX16: =AL16 -> 0 | AY16: =IFERROR(AM16/$AJ16,0) -> 0 | AZ16: =IFERROR(AN16/$AJ16,0) -> 0 | BA16: =IFERROR(AO16/$AJ16,0) -> 0 | BB16: =IFERROR(AP16/$AJ16,0) -> 0 | BC16: =IFERROR(AQ16/$AJ16,0) -> 0 | BD16: =IFERROR(AR16/$AJ16,0) -> 0 | BE16: =IFERROR(AS16/$AJ16,0) -> 0 | BF16: =IFERROR(AU16/$AJ16,0) -> 0
B17: 10009386 | C17: OTROS | D17: =TD!F14 -> 30.94 | E17: =IFERROR(F17/D17,0) -> 1279.9703 | F17: =TD!G14 -> 39602.28 | G17: =TD!H14 -> 6430.5696 | H17: =TD!I14 -> 1468.3893 | I17: =TD!J14 -> 2886.6047 | J17: =TD!K14 -> 2307.5262 | K17: 0 | L17: 0 | M17: =F17+G17+H17+I17 -> 50387.843 | N17: =IFERROR(M17/D17,0) -> 1628.5664 | O17: =F17+G17+H17-J17 -> 45193.712 | P17: =IFERROR(O17/D17,0) -> 1460.6888 | Q17: 1700 | R17: =Q17*D17 -> 52598 | S17: =R17-M17 -> 2210.1568 | T17: =IFERROR(S17/R17,0) -> 0.042019789 | U17: =R17-(M17-J17-I17) -> 7404.2877 | V17: =IFERROR(U17/R17,0) -> 0.14077128 | X17: {=SUM([2]Hoja6!$H$24:$H$28*([2]Hoja6!$E$24:$E$28=X$5)*($C17=[2]Hoja6!$J$24:$J$28))} -> 25.875 | Y17: {=SUM([2]Hoja6!$I$24:$I$28*([2]Hoja6!$E$24:$E$28=X$5)*($C17=[2]Hoja6!$J$24:$J$28))} -> 41400 | Z17: =IFERROR(Y17/X17,0) -> 1600 | AA17: {=SUM([2]Hoja6!$H$24:$H$28*([2]Hoja6!$E$24:$E$28=AA$5)*($C17=[2]Hoja6!$J$24:$J$28))} -> 0 | AB17: {=SUM([2]Hoja6!$I$24:$I$28*([2]Hoja6!$E$24:$E$28=AA$5)*($C17=[2]Hoja6!$J$24:$J$28))} -> 0 | AC17: =IFERROR(AB17/AA17,0) -> 0 | AD17: {=SUM([2]Hoja6!$H$24:$H$28*([2]Hoja6!$E$24:$E$28=AD$5)*($C17=[2]Hoja6!$J$24:$J$28))} -> 25.665 | AE17: {=SUM([2]Hoja6!$I$24:$I$28*([2]Hoja6!$E$24:$E$28=AD$5)*($C17=[2]Hoja6!$J$24:$J$28))} -> 41064 | AF17: =IFERROR(AE17/AD17,0) -> 1600 | AG17: {=SUM([2]Hoja6!$H$24:$H$28*([2]Hoja6!$E$24:$E$28=AG$5)*($C17=[2]Hoja6!$J$24:$J$28))} -> 0 | AH17: {=SUM([2]Hoja6!$I$24:$I$28*([2]Hoja6!$E$24:$E$28=AG$5)*($C17=[2]Hoja6!$J$24:$J$28))} -> 0 | AI17: =IFERROR(AH17/AG17,0) -> 0 | AJ17: =X17+AA17+AD17+AG17 -> 51.54 | AK17: =Y17+AB17+AE17+AH17 -> 82464 | AL17: =IFERROR(AK17/AJ17,0) -> 1600 | AM17: =-IFERROR(F17/D17*AJ17,0) -> -65969.667 | AN17: =-207.84*AJ17 -> -10712.074 | AO17: =$AO$20/$AJ$20*$AJ17 -> -21781.014 | AP17: =$AP$20/$AJ$20*$AJ17 -> -42817.782 | AQ17: =$AQ$20/$AJ$20*$AJ17 -> -34228.156 | AR17: =(AK17-AJ17*$AO$21)*0.03 -> 2297.3786 | AS17: =AK17+SUM(AM17:AP17,AR17) -> -56519.158 | AT17: =IFERROR(AS17/AK17,0) -> -0.68537977 | AU17: =AK17+AM17+AN17+AO17+AR17-AQ17 -> 20526.781 | AV17: =IFERROR(AU17/AK17,0) -> 0.24891809 | AX17: =AL17 -> 1600 | AY17: =IFERROR(AM17/$AJ17,0) -> -1279.9703 | AZ17: =IFERROR(AN17/$AJ17,0) -> -207.84 | BA17: =IFERROR(AO17/$AJ17,0) -> -422.60407 | BB17: =IFERROR(AP17/$AJ17,0) -> -830.76799 | BC17: =IFERROR(AQ17/$AJ17,0) -> -664.10858 | BD17: =IFERROR(AR17/$AJ17,0) -> 44.574672 | BE17: =IFERROR(AS17/$AJ17,0) -> -1096.6076 | BF17: =IFERROR(AU17/$AJ17,0) -> 398.26894
C18: FILETE PARA REPROCESO | D18: =TD!F15 -> 0 | E18: =IFERROR(F18/D18,0) -> 0 | F18: =TD!G15 -> 0 | G18: =TD!H15 -> 0 | H18: =TD!I15 -> 0 | I18: =TD!J15 -> 0 | J18: =TD!K15 -> 0 | K18: 0 | L18: 0 | M18: =F18+G18+H18+I18 -> 0 | N18: =IFERROR(M18/D18,0) -> 0 | O18: =F18+G18+H18-J18 -> 0 | P18: =IFERROR(O18/D18,0) -> 0 | Q18: 1800 | R18: =Q18*D18 -> 0 | S18: =R18-M18 -> 0 | T18: =IFERROR(S18/R18,0) -> 0 | U18: =R18-(M18-J18-I18) -> 0 | V18: =IFERROR(U18/R18,0) -> 0 | X18: {=SUM([2]Hoja6!$H$24:$H$28*([2]Hoja6!$E$24:$E$28=X$5)*($C18=[2]Hoja6!$J$24:$J$28))} -> 0 | Y18: {=SUM([2]Hoja6!$I$24:$I$28*([2]Hoja6!$E$24:$E$28=X$5)*($C18=[2]Hoja6!$J$24:$J$28))} -> 0 | Z18: =IFERROR(Y18/X18,0) -> 0 | AA18: {=SUM([2]Hoja6!$H$24:$H$28*([2]Hoja6!$E$24:$E$28=AA$5)*($C18=[2]Hoja6!$J$24:$J$28))} -> 0 | AB18: {=SUM([2]Hoja6!$I$24:$I$28*([2]Hoja6!$E$24:$E$28=AA$5)*($C18=[2]Hoja6!$J$24:$J$28))} -> 0 | AC18: =IFERROR(AB18/AA18,0) -> 0 | AD18: {=SUM([2]Hoja6!$H$24:$H$28*([2]Hoja6!$E$24:$E$28=AD$5)*($C18=[2]Hoja6!$J$24:$J$28))} -> 0 | AE18: {=SUM([2]Hoja6!$I$24:$I$28*([2]Hoja6!$E$24:$E$28=AD$5)*($C18=[2]Hoja6!$J$24:$J$28))} -> 0 | AF18: =IFERROR(AE18/AD18,0) -> 0 | AG18: {=SUM([2]Hoja6!$H$24:$H$28*([2]Hoja6!$E$24:$E$28=AG$5)*($C18=[2]Hoja6!$J$24:$J$28))} -> 0 | AH18: {=SUM([2]Hoja6!$I$24:$I$28*([2]Hoja6!$E$24:$E$28=AG$5)*($C18=[2]Hoja6!$J$24:$J$28))} -> 0 | AI18: =IFERROR(AH18/AG18,0) -> 0 | AJ18: =X18+AA18+AD18+AG18 -> 0 | AK18: =Y18+AB18+AE18+AH18 -> 0 | AL18: =IFERROR(AK18/AJ18,0) -> 0 | AM18: =-IFERROR(F18/D18*AJ18,0) -> 0 | AN18: =-207.84*AJ18 -> 0 | AO18: =$AO$20/$AJ$20*$AJ18 -> 0 | AP18: =$AP$20/$AJ$20*$AJ18 -> 0 | AQ18: =$AQ$20/$AJ$20*$AJ18 -> 0 | AR18: =(AK18-AJ18*$AO$21)*0.03 -> 0 | AS18: =AK18+SUM(AM18:AP18,AR18) -> 0 | AT18: =IFERROR(AS18/AK18,0) -> 0 | AU18: =AK18+AM18+AN18+AO18+AR18-AQ18 -> 0 | AV18: =IFERROR(AU18/AK18,0) -> 0 | AX18: =AL18 -> 0 | AY18: =IFERROR(AM18/$AJ18,0) -> 0 | AZ18: =IFERROR(AN18/$AJ18,0) -> 0 | BA18: =IFERROR(AO18/$AJ18,0) -> 0 | BB18: =IFERROR(AP18/$AJ18,0) -> 0 | BC18: =IFERROR(AQ18/$AJ18,0) -> 0 | BD18: =IFERROR(AR18/$AJ18,0) -> 0 | BE18: =IFERROR(AS18/$AJ18,0) -> 0 | BF18: =IFERROR(AU18/$AJ18,0) -> 0
C19: ALAS PARA REPROCESO | D19: =TD!F16 -> 612.58 | E19: =IFERROR(F19/D19,0) -> 1731.9701 | F19: =TD!G16 -> 1060970.3 | G19: =TD!H16 -> 127318.63 | H19: =TD!I16 -> 29072.59 | I19: =TD!J16 -> 57151.787 | J19: =TD!K16 -> 45686.633 | K19: 0 | L19: 0 | M19: =F19+G19+H19+I19 -> 1274513.3 | N19: =IFERROR(M19/D19,0) -> 2080.5662 | O19: =F19+G19+H19-J19 -> 1171674.8 | P19: =IFERROR(O19/D19,0) -> 1912.6887 | Q19: 1950 | R19: =Q19*D19 -> 1194531 | S19: =R19-M19 -> -79982.264 | T19: =IFERROR(S19/R19,0) -> -0.066957044 | U19: =R19-(M19-J19-I19) -> 22856.155 | V19: =IFERROR(U19/R19,0) -> 0.019133999 | X19: {=SUM([2]Hoja6!$H$24:$H$28*([2]Hoja6!$E$24:$E$28=X$5)*($C19=[2]Hoja6!$J$24:$J$28))} -> 0 | Y19: {=SUM([2]Hoja6!$I$24:$I$28*([2]Hoja6!$E$24:$E$28=X$5)*($C19=[2]Hoja6!$J$24:$J$28))} -> 0 | Z19: =IFERROR(Y19/X19,0) -> 0 | AA19: {=SUM([2]Hoja6!$H$24:$H$28*([2]Hoja6!$E$24:$E$28=AA$5)*($C19=[2]Hoja6!$J$24:$J$28))} -> 0 | AB19: {=SUM([2]Hoja6!$I$24:$I$28*([2]Hoja6!$E$24:$E$28=AA$5)*($C19=[2]Hoja6!$J$24:$J$28))} -> 0 | AC19: =IFERROR(AB19/AA19,0) -> 0 | AD19: {=SUM([2]Hoja6!$H$24:$H$28*([2]Hoja6!$E$24:$E$28=AD$5)*($C19=[2]Hoja6!$J$24:$J$28))} -> 0 | AE19: {=SUM([2]Hoja6!$I$24:$I$28*([2]Hoja6!$E$24:$E$28=AD$5)*($C19=[2]Hoja6!$J$24:$J$28))} -> 0 | AF19: =IFERROR(AE19/AD19,0) -> 0 | AG19: {=SUM([2]Hoja6!$H$24:$H$28*([2]Hoja6!$E$24:$E$28=AG$5)*($C19=[2]Hoja6!$J$24:$J$28))} -> 0 | AH19: {=SUM([2]Hoja6!$I$24:$I$28*([2]Hoja6!$E$24:$E$28=AG$5)*($C19=[2]Hoja6!$J$24:$J$28))} -> 0 | AI19: =IFERROR(AH19/AG19,0) -> 0 | AJ19: =X19+AA19+AD19+AG19 -> 0 | AK19: =Y19+AB19+AE19+AH19 -> 0 | AL19: =IFERROR(AK19/AJ19,0) -> 0 | AM19: =-IFERROR(F19/D19*AJ19,0) -> 0 | AN19: =-207.84*AJ19 -> 0 | AO19: =$AO$20/$AJ$20*$AJ19 -> 0 | AP19: =$AP$20/$AJ$20*$AJ19 -> 0 | AQ19: =$AQ$20/$AJ$20*$AJ19 -> 0 | AR19: =(AK19-AJ19*$AO$21)*0.03 -> 0 | AS19: =AK19+SUM(AM19:AP19,AR19) -> 0 | AT19: =IFERROR(AS19/AK19,0) -> 0 | AU19: =AK19+AM19+AN19+AO19+AR19-AQ19 -> 0 | AV19: =IFERROR(AU19/AK19,0) -> 0 | AX19: =AL19 -> 0 | AY19: =IFERROR(AM19/$AJ19,0) -> 0 | AZ19: =IFERROR(AN19/$AJ19,0) -> 0 | BA19: =IFERROR(AO19/$AJ19,0) -> 0 | BB19: =IFERROR(AP19/$AJ19,0) -> 0 | BC19: =IFERROR(AQ19/$AJ19,0) -> 0 | BD19: =IFERROR(AR19/$AJ19,0) -> 0 | BE19: =IFERROR(AS19/$AJ19,0) -> 0 | BF19: =IFERROR(AU19/$AJ19,0) -> 0
C20: TOTAL | D20: =SUM(D7:D19) -> 1655.715 | E20: =IFERROR(F20/D20,0) -> 1614.9501 | F20: =SUM(F7:F19) -> 2673897 | G20: =SUM(G7:G19) -> 344123.81 | H20: =SUM(H7:H19) -> 78579 | I20: =SUM(I7:I19) -> 154473 | J20: =SUM(J7:J19) -> 123484.35 | K20: =SUM(K7:K19) -> 0 | L20: 0 | M20: =SUM(M7:M19) -> 3251072.8 | N20: =IFERROR(M20/D20,0) -> 1963.5462 | O20: =SUM(O7:O19) -> 2973115.5 | P20: =IFERROR(O20/D20,0) -> 1795.6686 | Q20: =R20/D20 -> 2009.0689 | R20: =SUM(R7:R19) -> 3326445.5 | S20: =SUM(S7:S19) -> 75372.67 | T20: =S20/R20 -> 0.022658622 | U20: =SUM(U7:U19) -> 353330.02 | V20: =IFERROR(U20/R20,0) -> 0.10621849 | X20: =SUM(X7:X19) -> 133.275 | Y20: =SUM(Y7:Y19) -> 296940 | Z20: =IFERROR(Y20/X20,0) -> 2228.0248 | AA20: =SUM(AA7:AA19) -> 27 | AB20: =SUM(AB7:AB19) -> 48600 | AC20: =IFERROR(AB20/AA20,0) -> 1800 | AD20: =SUM(AD7:AD19) -> 25.665 | AE20: =SUM(AE7:AE19) -> 41064 | AF20: =IFERROR(AE20/AD20,0) -> 1600 | AG20: =SUM(AG7:AG19) -> 0 | AH20: =SUM(AH7:AH19) -> 0 | AI20: =IFERROR(AH20/AG20,0) -> 0 | AJ20: =SUM(AJ7:AJ19) -> 185.94 | AK20: =SUM(AK7:AK19) -> 386604 | AL20: =IFERROR(AK20/AJ20,0) -> 2079.1868 | AM20: =SUM(AM7:AM19) -> -242054.12 | AN20: =SUM(AN7:AN19) -> -38645.77 | AO20: =-'Stock Libre'!O54 -> -78579 | AP20: =-'Stock Libre'!P54 -> -154473 | AQ20: =-'Stock Libre'!Q54 -> -123484.35 | AR20: =SUM(AR7:AR19) -> 10961.214 | AS20: =SUM(AS7:AS19) -> -116186.68 | AT20: =IFERROR(AS20/AK20,0) -> -0.3005315 | AU20: =SUM(AU7:AU19) -> 161770.67 | AV20: =IFERROR(AU20/AK20,0) -> 0.41844024 | AX20: =AL20 -> 2079.1868 | AY20: =IFERROR(AM20/$AJ20,0) -> -1301.7862 | AZ20: =IFERROR(AN20/$AJ20,0) -> -207.84 | BA20: =IFERROR(AO20/$AJ20,0) -> -422.60407 | BB20: =IFERROR(AP20/$AJ20,0) -> -830.76799 | BC20: =IFERROR(AQ20/$AJ20,0) -> -664.10858 | BD20: =IFERROR(AR20/$AJ20,0) -> 58.950277 | BE20: =IFERROR(AS20/$AJ20,0) -> -624.86113 | BF20: =IFERROR(AU20/$AJ20,0) -> 870.01544
N21: =M20-R20 -> -75372.67 | AN21: flete x tm | AO21: 114.17761
C22: TM en Almacén de Yantai Jiahong | R22: =7%/12 -> 0.0058333333 | AY22: =SUM(AY7:BB7) -> 0
R23: =R22*M31 -> 20040.986 | S23: =R23*7 -> 140286.9 | T23: =S23/D31 -> 108.24607
C24: Producto | D24: TM en Stock Libre | E24: CU | F24: Costo Ventas | G24: Gasto Ventas | H24: Gasto ADM | I24: Gasto Fin | J24: Depreciación | K24: Utilidad Neta | L24: Margen Neto | M24: Venta Equilibrio a Utd Neta | N24: Precio Equilibrio x TM a Utd Neta | O24: Venta Equilibro a EBITDA | P24: Precio Equilibrio x TM a EBITDA | Q24: Precio Mercado | R24: Venta total | S24: Utilidad | T24: Mg Neto | U24: EBITDA | V24: Mg EBITDA | AY24: =AY7/0.5 -> 0
C25: POTA FILETE CONGELADO | D25: 567 | E25: =E7 -> 1834.431 | F25: =E25*D25 -> 1040122.4 | G25: =D25*207.84 -> 117845.28 | H25: =H$20/$D$20*$D25 -> 26909.397 | I25: =I$20/$D$20*$D25 -> 52899.316 | J25: =J$20/$D$20*$D25 -> 42287.245 | K25: 0 | L25: 0 | M25: =F25+G25+H25+I25 -> 1237776.4 | N25: =IFERROR(M25/D25,0) -> 2183.0271 | O25: =F25+G25+H25-J25 -> 1142589.8 | P25: =IFERROR(O25/D25,0) -> 2015.1496 | Q25: 1500 | R25: =Q25*D25 -> 850500 | S25: =R25-M25 -> -387276.37 | T25: =IFERROR(S25/R25,0) -> -0.45535141 | U25: =R25-(M25-J25-I25) -> -292089.81 | V25: =IFERROR(U25/R25,0) -> -0.34343305
C26: POTA ALAS CONGELADAS | D26: 54 | E26: =E9 -> 1731.9701 | F26: =E26*D26 -> 93526.387 | G26: =D26*207.84 -> 11223.36 | H26: =H$20/$D$20*$D26 -> 2562.7998 | I26: =I$20/$D$20*$D26 -> 5038.0301 | J26: =J$20/$D$20*$D26 -> 4027.3567 | K26: 0 | L26: 0 | M26: =F26+G26+H26+I26 -> 112350.58 | N26: =IFERROR(M26/D26,0) -> 2080.5662 | O26: =F26+G26+H26-J26 -> 103285.19 | P26: =IFERROR(O26/D26,0) -> 1912.6887 | Q26: 1700 | R26: =Q26*D26 -> 91800 | S26: =R26-M26 -> -20550.577 | T26: =IFERROR(S26/R26,0) -> -0.22386249 | U26: =R26-(M26-J26-I26) -> -11485.19
C27: POTA REJOS CONGELADOS | D27: 108 | E27: =E11 -> 1596.5588 | F27: =E27*D27 -> 172428.35 | G27: =D27*207.84 -> 22446.72 | H27: =H$20/$D$20*$D27 -> 5125.5995 | I27: =I$20/$D$20*$D27 -> 10076.06 | J27: =J$20/$D$20*$D27 -> 8054.7134 | K27: 0 | L27: 0 | M27: =F27+G27+H27+I27 -> 210076.73 | N27: =IFERROR(M27/D27,0) -> 1945.1549 | O27: =F27+G27+H27-J27 -> 191945.96 | P27: =IFERROR(O27/D27,0) -> 1777.2774 | Q27: 2275 | R27: =Q27*D27 -> 245700 | S27: =R27-M27 -> 35623.268 | T27: =IFERROR(S27/R27,0) -> 0.14498685 | U27: =R27-(M27-J27-I27) -> 53754.042 | V27: =IFERROR(U27/R27,0) -> 0.21877917
C28: POTA FILETE DARUMA | D28: 486 | E28: =E14 -> 3085.0611 | F28: =E28*D28 -> 1499339.7 | G28: =D28*207.84 -> 101010.24 | H28: =H$20/$D$20*$D28 -> 23065.198 | I28: =I$20/$D$20*$D28 -> 45342.271 | J28: =J$20/$D$20*$D28 -> 36246.21 | K28: 0 | L28: 0 | M28: =F28+G28+H28+I28 -> 1668757.4 | N28: =IFERROR(M28/D28,0) -> 3433.6572 | O28: =F28+G28+H28-J28 -> 1587168.9 | P28: =IFERROR(O28/D28,0) -> 3265.7797 | Q28: 3400 | R28: =Q28*D28 -> 1652400 | S28: =R28-M28 -> -16357.415 | T28: =IFERROR(S28/R28,0) -> -0.0098991859 | U28: =R28-(M28-J28-I28) -> 65231.066 | V28: =IFERROR(U28/R28,0) -> 0.039476559
C29: POTA ALAS COCIDAS | D29: 54 | E29: =E15 -> 2649.6026 | F29: =E29*D29 -> 143078.54 | G29: =D29*207.84 -> 11223.36 | H29: =H$20/$D$20*$D29 -> 2562.7998 | I29: =I$20/$D$20*$D29 -> 5038.0301 | J29: =J$20/$D$20*$D29 -> 4027.3567 | K29: 0 | L29: 0 | M29: =F29+G29+H29+I29 -> 161902.73 | N29: =IFERROR(M29/D29,0) -> 2998.1987 | O29: =F29+G29+H29-J29 -> 152837.34 | P29: =IFERROR(O29/D29,0) -> 2830.3212 | Q29: 3400 | R29: =Q29*D29 -> 183600 | S29: =R29-M29 -> 21697.269 | T29: =IFERROR(S29/R29,0) -> 0.11817685 | U29: =R29-(M29-J29-I29) -> 30762.656
C30: POTA RECORTES COCIDOS | D30: 27 | E30: =E10 -> 1308.2098 | F30: =E30*D30 -> 35321.665 | G30: =D30*207.84 -> 5611.68 | H30: =H$20/$D$20*$D30 -> 1281.3999 | I30: =I$20/$D$20*$D30 -> 2519.015 | J30: =J$20/$D$20*$D30 -> 2013.6784 | K30: 0 | L30: 0 | M30: =F30+G30+H30+I30 -> 44733.76 | N30: =IFERROR(M30/D30,0) -> 1656.8059 | O30: =F30+G30+H30-J30 -> 40201.067 | P30: =IFERROR(O30/D30,0) -> 1488.9284 | Q30: 1800 | R30: =Q30*D30 -> 48600 | S30: =R30-M30 -> 3866.2398 | T30: =IFERROR(S30/R30,0) -> 0.07955226 | U30: =R30-(M30-J30-I30) -> 8398.9332
C31: TOTAL | D31: =SUM(D25:D30) -> 1296 | E31: =F31/D31 -> 2302.328 | F31: =SUM(F25:F30) -> 2983817 | G31: =SUM(G25:G30) -> 269360.64 | H31: =SUM(H25:H30) -> 61507.194 | I31: =SUM(I25:I30) -> 120912.72 | J31: =SUM(J25:J30) -> 96656.561 | K31: =SUM(K25:K30) -> 0 | L31: 0 | M31: =SUM(M25:M30) -> 3435597.6 | N31: =IFERROR(M31/D31,0) -> 2650.9241 | O31: =SUM(O25:O30) -> 3218028.3 | P31: =IFERROR(O31/D31,0) -> 2483.0465 | Q31: =R31/D31 -> 2370.8333 | R31: =SUM(R25:R30) -> 3072600 | S31: =SUM(S25:S30) -> -362997.59 | T31: =S31/R31 -> -0.1181402 | U31: =SUM(U25:U30) -> -145428.3 | V31: =IFERROR(U31/R31,0) -> -0.047330699
C33: TOTAL | D33: =D20+D31 -> 2951.715 | E33: =F33/D33 -> 1916.7549 | F33: =F20+F31 -> 5657714.1 | G33: =G20+G31 -> 613484.45 | H33: =H20+H31 -> 140086.19 | I33: =I20+I31 -> 275385.72 | J33: =J20+J31 -> 220140.91 | K33: =K20+K31 -> 0 | L33: =L20+L31 -> 0 | M33: =M20+M31 -> 6686670.4 | N33: =IFERROR(M33/D33,0) -> 2265.351 | O33: =O20+O31 -> 6191143.8 | P33: =IFERROR(O33/D33,0) -> 2097.4734 | Q33: =R33/D33 -> 2167.9076 | R33: =R20+R31 -> 6399045.5 | S33: =S20+S31 -> -287624.92 | T33: =S33/R33 -> -0.044948097 | U33: =U20+U31 -> 207901.72 | V33: =IFERROR(U33/R33,0) -> 0.032489489
C36: INVENTARIO TOTAL VALORIZADO
C38: Producto | D38: TM en Stock Libre | E38: CU | F38: Costo Ventas | G38: Gasto Ventas | H38: Gasto ADM | I38: Gasto Fin | J38: Depreciación | K38: Utilidad Neta | L38: Margen Neto | M38: Venta Equilibrio a Utd Neta | N38: Precio Equilibrio x TM a Utd Neta | O38: Precio Venta | P38: Venta Esperada | Q38: Utilidad Neta | R38: Margen Neto | S38: Precio actual | T38: venta con precio actual | U38: P/L | V38: variación | X38: ebitda con nuevos precios
C39: POTA FILETE CONGELADO | D39: =D7+D25 -> 633.96 | E39: =IFERROR(F39/D39,0) -> 1834.431 | F39: =F7+F25 -> 1162955.9 | G39: =G7+G25 -> 131762.25 | H39: =H7+H25 -> 30087.269 | I39: =I7+I25 -> 59146.473 | J39: =J7+J25 -> 47281.168 | K39: 0 | L39: 0 | M39: =F39+G39+H39+I39 -> 1383951.9 | N39: =IFERROR(M39/D39,0) -> 2183.0271 | O39: 2200 | P39: =O39*D39 -> 1394712 | Q39: =P39-M39 -> 10760.13 | R39: =Q39/P39 -> 0.007714948 | S39: =Q25 -> 1500 | T39: =S39*D39 -> 950940 | U39: =T39-M39 -> -433011.87 | V39: =Q39-U39 -> 443772 | X39: =Q39+I39+J39 -> 117187.77
C40: POTA NUCAS CONGELADAS | D40: =D8 -> 368.64 | E40: =IFERROR(F40/D40,0) -> 1483.423 | F40: =F8 -> 546849.04 | G40: =G8 -> 76618.138 | H40: =H8 -> 17495.38 | I40: =I8 -> 34392.952 | J40: =J8 -> 27493.422 | K40: 0 | L40: 0 | M40: =F40+G40+H40+I40 -> 675355.51 | N40: =IFERROR(M40/D40,0) -> 1832.0191 | O40: 1400 | P40: =O40*D40 -> 516096 | Q40: =P40-M40 -> -159259.51 | R40: =Q40/P40 -> -0.30858505 | S40: =Q8 -> 1400 | T40: =S40*D40 -> 516096 | U40: =T40-M40 -> -159259.51 | V40: =Q40-U40 -> 0 | X40: =Q40+I40+J40 -> -97373.139
C41: POTA ALAS CONGELADAS | D41: =D9+D26 -> 71.9 | E41: =IFERROR(F41/D41,0) -> 1731.9701 | F41: =F9+F26 -> 124528.65 | G41: =G9+G26 -> 14943.696 | H41: =H9+H26 -> 3412.3204 | I41: =I9+I26 -> 6708.0438 | J41: =J9+J26 -> 5362.3509 | K41: 0 | L41: 0 | M41: =F41+G41+H41+I41 -> 149592.71 | N41: =IFERROR(M41/D41,0) -> 2080.5662 | O41: 2700 | P41: =O41*D41 -> 194130 | Q41: =P41-M41 -> 44537.288 | R41: =Q41/P41 -> 0.22941991 | S41: =Q9 -> 1950 | T41: =S41*D41 -> 140205 | U41: =T41-M41 -> -9387.7123 | V41: =Q41-U41 -> 53925 | X41: =Q41+I41+J41 -> 56607.682
C42: POTA RECORTES COCIDOS | D42: =D10+D30 -> 141.855 | E42: =IFERROR(F42/D42,0) -> 1308.2098 | F42: =F10+F30 -> 185576.1 | G42: =G10+G30 -> 29483.143 | H42: =H10+H30 -> 6732.3326 | I42: =I10+I30 -> 13234.625 | J42: =J10+J30 -> 10579.642 | K42: 0 | L42: 0 | M42: =F42+G42+H42+I42 -> 235026.21 | N42: =IFERROR(M42/D42,0) -> 1656.8059 | O42: 2500 | P42: =O42*D42 -> 354637.5 | Q42: =P42-M42 -> 119611.29 | R42: =Q42/P42 -> 0.33727763 | S42: =Q10 -> 1700 | T42: =S42*D42 -> 241153.5 | U42: =T42-M42 -> 6127.2946 | V42: =Q42-U42 -> 113484 | X42: =Q42+I42+J42 -> 143425.56
C43: POTA REJOS CONGELADOS | D43: =D11+D27 -> 378.4 | E43: =IFERROR(F43/D43,0) -> 1596.5588 | F43: =F11+F27 -> 604137.86 | G43: =G11+G27 -> 78646.656 | H43: =H11+H27 -> 17958.582 | I43: =I11+I27 -> 35303.529 | J43: =J11+J27 -> 28221.329 | K43: 0 | L43: 0 | M43: =F43+G43+H43+I43 -> 736046.62 | N43: =IFERROR(M43/D43,0) -> 1945.1549 | O43: 2700 | P43: =O43*D43 -> 1021680 | Q43: =P43-M43 -> 285633.38 | R43: =Q43/P43 -> 0.27957225 | S43: =Q11 -> 2700 | T43: =S43*D43 -> 1021680 | U43: =T43-M43 -> 285633.38 | V43: =Q43-U43 -> 0 | X43: =Q43+I43+J43 -> 349158.24
C44: POTA REPRODUCTORES | D44: =D12 -> 132.38 | E44: =IFERROR(F44/D44,0) -> 1540.1637 | F44: =F12 -> 203886.87 | G44: =G12 -> 27513.859 | H44: =H12 -> 6282.6561 | I44: =I12 -> 12350.637 | J44: =J12 -> 9872.9904 | K44: 0 | L44: 0 | M44: =F44+G44+H44+I44 -> 250034.02 | N44: =IFERROR(M44/D44,0) -> 1888.7598 | O44: 2700 | P44: =O44*D44 -> 357426 | Q44: =P44-M44 -> 107391.98 | R44: =Q44/P44 -> 0.30045934 | S44: =Q12 -> 2800 | T44: =S44*D44 -> 370664 | U44: =T44-M44 -> 120629.98 | V44: =Q44-U44 -> -13238 | X44: =Q44+I44+J44 -> 129615.61
C45: POTA CONOS | D45: =D13 -> 0 | E45: =IFERROR(F45/D45,0) -> 0 | F45: =F13 -> 0 | G45: =G13 -> 0 | H45: =H13 -> 0 | I45: =I13 -> 0 | J45: =J13 -> 0 | K45: 0 | L45: 0 | M45: =F45+G45+H45+I45 -> 0 | N45: =IFERROR(M45/D45,0) -> 0 | O45: 1800 | P45: =O45*D45 -> 0 | Q45: =P45-M45 -> 0 | R45: =Q45/P45 -> #DIV/0! | S45: =Q13 -> 1700 | T45: =S45*D45 -> 0 | U45: =T45-M45 -> 0 | V45: =Q45-U45 -> 0 | X45: =Q45+I45+J45 -> 0
C46: POTA FILETE DARUMA | D46: =D14+D28+D18*0.5 -> 486.86 | E46: =IFERROR(F46/D46,0) -> 3085.0611 | F46: =F14+F28+F18 -> 1501992.9 | G46: =G14+G28+G18 -> 101188.98 | H46: =H14+H28+H18 -> 23106.013 | I46: =I14+I28+I18 -> 45422.506 | J46: =J14+J28+J18 -> 36310.35 | K46: 0 | L46: 0 | M46: =F46+G46+H46+I46 -> 1671710.4 | N46: =IFERROR(M46/D46,0) -> 3433.6572 | O46: 3900 | P46: =O46*D46 -> 1898754 | Q46: =P46-M46 -> 227043.64 | R46: =Q46/P46 -> 0.11957507 | S46: =Q14 -> 3500 | T46: =S46*D46 -> 1704010 | U46: =T46-M46 -> 32299.64 | V46: =Q46-U46 -> 194744 | X46: =Q46+I46+J46 -> 308776.5
...

Sheet TD
E3: Etiquetas de fila | F3: Suma de TM en Stock | G3: Suma de Costo Ventas | H3: Suma de Gasto Ventas | I3: Suma de Gasto ADM | J3: Suma de Gasto Fin | K3: Suma de Depreciación
B4: =C4=E4 -> TRUE | C4: 10005721 | D4: POTA FILETE CONGELADO | E4: 10005721 | F4: 66.96 | G4: 122833.5 | H4: 13916.966 | I4: 3177.8717 | J4: 6247.1573 | K4: 4993.9223
B5: =C5=E5 -> TRUE | C5: 10005779 | D5: POTA NUCAS CONGELADAS | E5: 10005779 | F5: 368.64 | G5: 546849.04 | H5: 76618.138 | I5: 17495.38 | J5: 34392.952 | K5: 27493.422
B6: =C6=E6 -> TRUE | C6: 10006719 | D6: POTA ALAS CONGELADAS | E6: 10006719 | F6: 17.9 | G6: 31002.265 | H6: 3720.336 | I6: 849.52066 | J6: 1670.0137 | K6: 1334.9942
B7: =C7=E7 -> TRUE | C7: 10007050 | D7: POTA RECORTES COCIDOS | E7: 10007050 | F7: 114.855 | G7: 150254.44 | H7: 23871.463 | I7: 5450.9327 | J7: 10715.61 | K7: 8565.964
B8: =C8=E8 -> TRUE | C8: 10007162 | D8: POTA REJOS CONGELADOS | E8: 10007162 | F8: 270.4 | G8: 431709.5 | H8: 56199.936 | I8: 12832.982 | J8: 25227.469 | K8: 20166.616
B9: =C9=E9 -> TRUE | C9: 10007567 | D9: POTA REPRODUCTORES | E9: 10007567 | F9: 132.38 | G9: 203886.87 | H9: 27513.859 | I9: 6282.6561 | J9: 12350.637 | K9: 9872.9904
B10: =C10=E10 -> TRUE | C10: 10007969 | D10: POTA CONOS | E10: 10007969 | F10: 0 | G10: 0 | H10: 0 | I10: 0 | J10: 0 | K10: 0
B11: =C11=E11 -> TRUE | C11: 10009239 | D11: POTA FILETE DARUMA | E11: 10009239 | F11: 0.86 | G11: 2653.1526 | H11: 178.7424 | I11: 40.814959 | J11: 80.235294 | K11: 64.139384
B12: =C12=E12 -> TRUE | C12: 10009334 | D12: POTA ALAS COCIDAS | E12: 10009334 | F12: 18.92 | G12: 50130.481 | H12: 3932.3328 | I12: 897.9291 | J12: 1765.1765 | K12: 1411.0665
B13: =C13=E13 -> TRUE | C13: 10009386 | D13: VENTOSAS | E13: 10009386 | F13: 21.28 | G13: 34005.233 | H13: 4422.8352 | I13: 1009.9329 | J13: 1985.357 | K13: 1587.0769
B14: =C14=E14 -> FALSE | D14: OTROS | E14: 10009207 | F14: 30.94 | G14: 39602.28 | H14: 6430.5696 | I14: 1468.3893 | J14: 2886.6047 | K14: 2307.5262
D15: FILETE PARA REPROCESO | E15: 10009650 | F15: 0 | G15: 0 | H15: 0 | I15: 0 | J15: 0 | K15: 0
D16: ALAS PARA REPROCESO | E16: 10009649 | F16: 612.58 | G16: 1060970.3 | H16: 127318.63 | I16: 29072.59 | J16: 57151.787 | K16: 45686.633
E17: Total general | F17: 1655.715 | G17: 2673897 | H17: 344123.81 | I17: 78579 | J17: 154473 | K17: 123484.35

Sheet Stock Libre
B1: PRODUCTO | C1: TOTAL STOCK | D1: POR EMBARCAR | E1: STOCK LIBRE | G1: CÓDIGO | H1: CU X TM | I1: % MP | J1: incremento MP | K1: TM en Stock Total | L1: TM en Stock | M1: Costo Ventas | N1: Gasto Ventas | O1: Gasto ADM | P1: Gasto Fin | Q1: Depreciación | R1: Utilidad Neta | S1: Margen Neto | T1: Venta Equilibrio | U1: Precio Equilibrio x TM
B2: POTA ALAS FR C/P C/C (B) S/COD BL10 S20 | C2: 14840 | E2: 14840 | G2: 10006719 | H2: =IFERROR(INDEX([1]Resumen!$K$3:$K$63,MATCH(G2,[1]Resumen!$C$3:$C$63,0)),0)*(1+I2*J2)/1000-51.89/1000-93.38/1000 -> 1.7319701 | I2: 0.71 | J2: =$H$59 -> -0.10965909 | K2: =C2/1000 -> 14.84 | L2: =IF(E2<0,0,E2)/1000 -> 14.84 | M2: =IFERROR(H2*L2,0)*1000 -> 25702.437 | N2: =207.84*L2 -> 3084.3456 | O2: =$O$54/$L$52*L2 -> 704.29534 | P2: =$P$54/$L$52*L2 -> 1384.5253 | Q2: =$Q$54/$L$52*L2 -> 1106.7773 | R2: 0 | S2: 0 | T2: =M2+N2+O2+P2 -> 30875.603 | U2: =IFERROR(T2/L2,0) -> 2080.5662
B3: POTA ALAS FR C/P C/C <0.5 BL10 S20 | C3: 680 | E3: 680 | G3: 10006719 | H3: =IFERROR(INDEX([1]Resumen!$K$3:$K$63,MATCH(G3,[1]Resumen!$C$3:$C$63,0)),0)*(1+I3*J3)/1000-51.89/1000-93.38/1000 -> 1.7319701 | I3: 0.71 | J3: =$H$59 -> -0.10965909 | K3: =C3/1000 -> 0.68 | L3: =IF(E3<0,0,E3)/1000 -> 0.68 | M3: =IFERROR(H3*L3,0)*1000 -> 1177.7397 | N3: =207.84*L3 -> 141.3312 | O3: =$O$54/$L$52*L3 -> 32.272293 | P3: =$P$54/$L$52*L3 -> 63.44186 | Q3: =$Q$54/$L$52*L3 -> 50.714862 | R3: 0 | S3: 0 | T3: =M3+N3+O3+P3 -> 1414.785 | U3: =IFERROR(T3/L3,0) -> 2080.5662
B4: POTA ALAS FR C/P C/C 0.5-1 BL10 S20 | C4: 0 | E4: 0 | G4: 10006719 | H4: =IFERROR(INDEX([1]Resumen!$K$3:$K$63,MATCH(G4,[1]Resumen!$C$3:$C$63,0)),0)*(1+I4*J4)/1000-51.89/1000-93.38/1000 -> 1.7319701 | I4: 0.71 | J4: =$H$59 -> -0.10965909 | K4: =C4/1000 -> 0 | L4: =IF(E4<0,0,E4)/1000 -> 0 | M4: =IFERROR(H4*L4,0)*1000 -> 0 | N4: =207.84*L4 -> 0 | O4: =$O$54/$L$52*L4 -> 0 | P4: =$P$54/$L$52*L4 -> 0 | Q4: =$Q$54/$L$52*L4 -> 0 | R4: 0 | S4: 0 | T4: =M4+N4+O4+P4 -> 0 | U4: =IFERROR(T4/L4,0) -> 0
B5: POTA ALAS FR C/P C/C 0.3 - 0.5 BL10 S20 | C5: 0 | E5: 0 | G5: 10006719 | H5: =IFERROR(INDEX([1]Resumen!$K$3:$K$63,MATCH(G5,[1]Resumen!$C$3:$C$63,0)),0)*(1+I5*J5)/1000-51.89/1000-93.38/1000 -> 1.7319701 | I5: 0.71 | J5: =$H$59 -> -0.10965909 | K5: =C5/1000 -> 0 | L5: =IF(E5<0,0,E5)/1000 -> 0 | M5: =IFERROR(H5*L5,0)*1000 -> 0 | N5: =207.84*L5 -> 0 | O5: =$O$54/$L$52*L5 -> 0 | P5: =$P$54/$L$52*L5 -> 0 | Q5: =$Q$54/$L$52*L5 -> 0 | R5: 0 | S5: 0 | T5: =M5+N5+O5+P5 -> 0 | U5: =IFERROR(T5/L5,0) -> 0
B6: POTA ALAS FR C/P C/C 1-2 BL10 S20 | C6: 40 | E6: 40 | G6: 10006719 | H6: =IFERROR(INDEX([1]Resumen!$K$3:$K$63,MATCH(G6,[1]Resumen!$C$3:$C$63,0)),0)*(1+I6*J6)/1000-51.89/1000-93.38/1000 -> 1.7319701 | I6: 0.71 | J6: =$H$59 -> -0.10965909 | K6: =C6/1000 -> 0.04 | L6: =IF(E6<0,0,E6)/1000 -> 0.04 | M6: =IFERROR(H6*L6,0)*1000 -> 69.278805 | N6: =207.84*L6 -> 8.3136 | O6: =$O$54/$L$52*L6 -> 1.8983702 | P6: =$P$54/$L$52*L6 -> 3.7318741 | Q6: =$Q$54/$L$52*L6 -> 2.9832272 | R6: 0 | S6: 0 | T6: =M6+N6+O6+P6 -> 83.222649 | U6: =IFERROR(T6/L6,0) -> 2080.5662
B7: POTA ALAS FR C/P C/C 1-2 BL10 S20 ENTERA | C7: 2340 | E7: 2340 | G7: 10006719 | H7: =IFERROR(INDEX([1]Resumen!$K$3:$K$63,MATCH(G7,[1]Resumen!$C$3:$C$63,0)),0)*(1+I7*J7)/1000-51.89/1000-93.38/1000 -> 1.7319701 | I7: 0.71 | J7: =$H$59 -> -0.10965909 | K7: =C7/1000 -> 2.34 | L7: =IF(E7<0,0,E7)/1000 -> 2.34 | M7: =IFERROR(H7*L7,0)*1000 -> 4052.8101 | N7: =207.84*L7 -> 486.3456 | O7: =$O$54/$L$52*L7 -> 111.05466 | P7: =$P$54/$L$52*L7 -> 218.31464 | Q7: =$Q$54/$L$52*L7 -> 174.51879 | R7: 0 | S7: 0 | T7: =M7+N7+O7+P7 -> 4868.525 | U7: =IFERROR(T7/L7,0) -> 2080.5662
B8: POTA ALAS FR C/P C/C 2up | C8: 0 | E8: 0 | G8: 10006719 | H8: =IFERROR(INDEX([1]Resumen!$K$3:$K$63,MATCH(G8,[1]Resumen!$C$3:$C$63,0)),0)*(1+I8*J8)/1000-51.89/1000-93.38/1000 -> 1.7319701 | I8: 0.71 | J8: =$H$59 -> -0.10965909 | K8: =C8/1000 -> 0 | L8: =IF(E8<0,0,E8)/1000 -> 0 | M8: =IFERROR(H8*L8,0)*1000 -> 0 | N8: =207.84*L8 -> 0 | O8: =$O$54/$L$52*L8 -> 0 | P8: =$P$54/$L$52*L8 -> 0 | Q8: =$Q$54/$L$52*L8 -> 0 | R8: 0 | S8: 0 | T8: =M8+N8+O8+P8 -> 0 | U8: =IFERROR(T8/L8,0) -> 0
B9: POTA LABIOS FR S/COD BL10 S20 | C9: 30940 | E9: 30940 | G9: 10009207 | H9: =IFERROR(INDEX([1]Resumen!$K$3:$K$63,MATCH(G9,[1]Resumen!$C$3:$C$63,0)),0)*(1+I9*J9)/1000-51.89/1000-93.38/1000 -> 1.2799703 | I9: 0.71 | J9: =$H$59 -> -0.10965909 | K9: =C9/1000 -> 30.94 | L9: =IF(E9<0,0,E9)/1000 -> 30.94 | M9: =IFERROR(H9*L9,0)*1000 -> 39602.28 | N9: =207.84*L9 -> 6430.5696 | O9: =$O$54/$L$52*L9 -> 1468.3893 | P9: =$P$54/$L$52*L9 -> 2886.6047 | Q9: =$Q$54/$L$52*L9 -> 2307.5262 | R9: 0 | S9: 0 | T9: =M9+N9+O9+P9 -> 50387.843 | U9: =IFERROR(T9/L9,0) -> 1628.5664
B10: POTA CONOS | C10: 20380 | D10: 20380 | E10: 0 | G10: 10007969 | H10: =IFERROR(INDEX([1]Resumen!$K$3:$K$63,MATCH(G10,[1]Resumen!$C$3:$C$63,0)),0)*(1+I10*J10)/1000-51.89/1000-93.38/1000 -> 1.2330367 | I10: 0.71 | J10: =$H$59 -> -0.10965909 | K10: =C10/1000 -> 20.38 | L10: =IF(E10<0,0,E10)/1000 -> 0 | M10: =IFERROR(H10*L10,0)*1000 -> 0 | N10: =207.84*L10 -> 0 | O10: =$O$54/$L$52*L10 -> 0 | P10: =$P$54/$L$52*L10 -> 0 | Q10: =$Q$54/$L$52*L10 -> 0 | R10: 0 | S10: 0 | T10: =M10+N10+O10+P10 -> 0 | U10: =IFERROR(T10/L10,0) -> 0
B11: POTA FILETE C/M C/T FR 0.5-1.0 BL10 S20 | C11: 0 | E11: 0 | G11: 10005721 | H11: =IFERROR(INDEX([1]Resumen!$K$3:$K$63,MATCH(G11,[1]Resumen!$C$3:$C$63,0)),0)*(1+I11*J11)/1000-51.89/1000-93.38/1000 -> 1.834431 | I11: 0.67 | J11: =$H$59 -> -0.10965909 | K11: =C11/1000 -> 0 | L11: =IF(E11<0,0,E11)/1000 -> 0 | M11: =IFERROR(H11*L11,0)*1000 -> 0 | N11: =207.84*L11 -> 0 | O11: =$O$54/$L$52*L11 -> 0 | P11: =$P$54/$L$52*L11 -> 0 | Q11: =$Q$54/$L$52*L11 -> 0 | R11: 0 | S11: 0 | T11: =M11+N11+O11+P11 -> 0 | U11: =IFERROR(T11/L11,0) -> 0
B12: POTA FILETE C/M C/T FR 1-2 BL10 S20 | C12: 1760 | E12: 1760 | G12: 10005721 | H12: =IFERROR(INDEX([1]Resumen!$K$3:$K$63,MATCH(G12,[1]Resumen!$C$3:$C$63,0)),0)*(1+I12*J12)/1000-51.89/1000-93.38/1000 -> 1.834431 | I12: 0.67 | J12: =$H$59 -> -0.10965909 | K12: =C12/1000 -> 1.76 | L12: =IF(E12<0,0,E12)/1000 -> 1.76 | M12: =IFERROR(H12*L12,0)*1000 -> 3228.5986 | N12: =207.84*L12 -> 365.7984 | O12: =$O$54/$L$52*L12 -> 83.528288 | P12: =$P$54/$L$52*L12 -> 164.20246 | Q12: =$Q$54/$L$52*L12 -> 131.262 | R12: 0 | S12: 0 | T12: =M12+N12+O12+P12 -> 3842.1277 | U12: =IFERROR(T12/L12,0) -> 2183.0271
B13: POTA FILETE C/M C/T FR 1.0 - 3.0 BL10 S20 | C13: 0 | E13: 0 | G13: 10005721 | H13: =IFERROR(INDEX([1]Resumen!$K$3:$K$63,MATCH(G13,[1]Resumen!$C$3:$C$63,0)),0)*(1+I13*J13)/1000-51.89/1000-93.38/1000 -> 1.834431 | I13: 0.67 | J13: =$H$59 -> -0.10965909 | K13: =C13/1000 -> 0 | L13: =IF(E13<0,0,E13)/1000 -> 0 | M13: =IFERROR(H13*L13,0)*1000 -> 0 | N13: =207.84*L13 -> 0 | O13: =$O$54/$L$52*L13 -> 0 | P13: =$P$54/$L$52*L13 -> 0 | Q13: =$Q$54/$L$52*L13 -> 0 | R13: 0 | S13: 0 | T13: =M13+N13+O13+P13 -> 0 | U13: =IFERROR(T13/L13,0) -> 0
B14: POTA FILETE C/M C/T FR 2-4 S20 | C14: 32180 | E14: 32180 | G14: 10005721 | H14: =IFERROR(INDEX([1]Resumen!$K$3:$K$63,MATCH(G14,[1]Resumen!$C$3:$C$63,0)),0)*(1+I14*J14)/1000-51.89/1000-93.38/1000 -> 1.834431 | I14: 0.67 | J14: =$H$59 -> -0.10965909 | K14: =C14/1000 -> 32.18 | L14: =IF(E14<0,0,E14)/1000 -> 32.18 | M14: =IFERROR(H14*L14,0)*1000 -> 59031.99 | N14: =207.84*L14 -> 6688.2912 | O14: =$O$54/$L$52*L14 -> 1527.2388 | P14: =$P$54/$L$52*L14 -> 3002.2927 | Q14: =$Q$54/$L$52*L14 -> 2400.0063 | R14: 0 | S14: 0 | T14: =M14+N14+O14+P14 -> 70249.813 | U14: =IFERROR(T14/L14,0) -> 2183.0271
B15: POTA FILETE C/M C/T FR <0.5 Kg AA BL10 S20 | C15: 1080 | E15: 1080 | G15: 10005721 | H15: =IFERROR(INDEX([1]Resumen!$K$3:$K$63,MATCH(G15,[1]Resumen!$C$3:$C$63,0)),0)*(1+I15*J15)/1000-51.89/1000-93.38/1000 -> 1.834431 | I15: 0.67 | J15: =$H$59 -> -0.10965909 | K15: =C15/1000 -> 1.08 | L15: =IF(E15<0,0,E15)/1000 -> 1.08 | M15: =IFERROR(H15*L15,0)*1000 -> 1981.1855 | N15: =207.84*L15 -> 224.4672 | O15: =$O$54/$L$52*L15 -> 51.255995 | P15: =$P$54/$L$52*L15 -> 100.7606 | Q15: =$Q$54/$L$52*L15 -> 80.547134 | R15: 0 | S15: 0 | T15: =M15+N15+O15+P15 -> 2357.6693 | U15: =IFERROR(T15/L15,0) -> 2183.0271
B16: POTA FILETE C/M C/T FR 2-4 (AA) BL10 S20 | C16: 3100 | E16: 3100 | G16: 10005721 | H16: =IFERROR(INDEX([1]Resumen!$K$3:$K$63,MATCH(G16,[1]Resumen!$C$3:$C$63,0)),0)*(1+I16*J16)/1000-51.89/1000-93.38/1000 -> 1.834431 | I16: 0.67 | J16: =$H$59 -> -0.10965909 | K16: =C16/1000 -> 3.1 | L16: =IF(E16<0,0,E16)/1000 -> 3.1 | M16: =IFERROR(H16*L16,0)*1000 -> 5686.7361 | N16: =207.84*L16 -> 644.304 | O16: =$O$54/$L$52*L16 -> 147.12369 | P16: =$P$54/$L$52*L16 -> 289.22025 | Q16: =$Q$54/$L$52*L16 -> 231.20011 | R16: 0 | S16: 0 | T16: =M16+N16+O16+P16 -> 6767.3841 | U16: =IFERROR(T16/L16,0) -> 2183.0271
B17: POTA FILETE C/M C/T FR 0.5-1.0 AA BL10 S20 | C17: 0 | E17: 0 | G17: 10005721 | H17: =IFERROR(INDEX([1]Resumen!$K$3:$K$63,MATCH(G17,[1]Resumen!$C$3:$C$63,0)),0)*(1+I17*J17)/1000-51.89/1000-93.38/1000 -> 1.834431 | I17: 0.67 | J17: =$H$59 -> -0.10965909 | K17: =C17/1000 -> 0 | L17: =IF(E17<0,0,E17)/1000 -> 0 | M17: =IFERROR(H17*L17,0)*1000 -> 0 | N17: =207.84*L17 -> 0 | O17: =$O$54/$L$52*L17 -> 0 | P17: =$P$54/$L$52*L17 -> 0 | Q17: =$Q$54/$L$52*L17 -> 0 | R17: 0 | S17: 0 | T17: =M17+N17+O17+P17 -> 0 | U17: =IFERROR(T17/L17,0) -> 0
B18: POTA FILETE C/M C/T FR 1.0 - 3.0 AA BL10 S20 | C18: 5280 | E18: 5280 | G18: 10005721 | H18: =IFERROR(INDEX([1]Resumen!$K$3:$K$63,MATCH(G18,[1]Resumen!$C$3:$C$63,0)),0)*(1+I18*J18)/1000-51.89/1000-93.38/1000 -> 1.834431 | I18: 0.67 | J18: =$H$59 -> -0.10965909 | K18: =C18/1000 -> 5.28 | L18: =IF(E18<0,0,E18)/1000 -> 5.28 | M18: =IFERROR(H18*L18,0)*1000 -> 9685.7957 | N18: =207.84*L18 -> 1097.3952 | O18: =$O$54/$L$52*L18 -> 250.58487 | P18: =$P$54/$L$52*L18 -> 492.60739 | Q18: =$Q$54/$L$52*L18 -> 393.78599 | R18: 0 | S18: 0 | T18: =M18+N18+O18+P18 -> 11526.383 | U18: =IFERROR(T18/L18,0) -> 2183.0271
B19: POTA FILETE C/M C/T FR 1-2 AA BL10 S20 JAPON | C19: 17640 | E19: 17640 | G19: 10005721 | H19: =IFERROR(INDEX([1]Resumen!$K$3:$K$63,MATCH(G19,[1]Resumen!$C$3:$C$63,0)),0)*(1+I19*J19)/1000-51.89/1000-93.38/1000 -> 1.834431 | I19: 0.67 | J19: =$H$59 -> -0.10965909 | K19: =C19/1000 -> 17.64 | L19: =IF(E19<0,0,E19)/1000 -> 17.64 | M19: =IFERROR(H19*L19,0)*1000 -> 32359.363 | N19: =207.84*L19 -> 3666.2976 | O19: =$O$54/$L$52*L19 -> 837.18125 | P19: =$P$54/$L$52*L19 -> 1645.7565 | Q19: =$Q$54/$L$52*L19 -> 1315.6032 | R19: 0 | S19: 0 | T19: =M19+N19+O19+P19 -> 38508.598 | U19: =IFERROR(T19/L19,0) -> 2183.0271
B20: POTA FILETE C/M C/T FR 0.5-1.0 AAA BL10 S20 | C20: 0 | E20: 0 | G20: 10005721 | H20: =IFERROR(INDEX([1]Resumen!$K$3:$K$63,MATCH(G20,[1]Resumen!$C$3:$C$63,0)),0)*(1+I20*J20)/1000-51.89/1000-93.38/1000 -> 1.834431 | I20: 0.67 | J20: =$H$59 -> -0.10965909 | K20: =C20/1000 -> 0 | L20: =IF(E20<0,0,E20)/1000 -> 0 | M20: =IFERROR(H20*L20,0)*1000 -> 0 | N20: =207.84*L20 -> 0 | O20: =$O$54/$L$52*L20 -> 0 | P20: =$P$54/$L$52*L20 -> 0 | Q20: =$Q$54/$L$52*L20 -> 0 | R20: 0 | S20: 0 | T20: =M20+N20+O20+P20 -> 0 | U20: =IFERROR(T20/L20,0) -> 0
B21: POTA FILETE C/M C/T FR 1-2 AA BL10 S20 50% ROSADO | C21: 2720 | E21: 2720 | G21: 10005721 | H21: =IFERROR(INDEX([1]Resumen!$K$3:$K$63,MATCH(G21,[1]Resumen!$C$3:$C$63,0)),0)*(1+I21*J21)/1000-51.89/1000-93.38/1000 -> 1.834431 | I21: 0.67 | J21: =$H$59 -> -0.10965909 | K21: =C21/1000 -> 2.72 | L21: =IF(E21<0,0,E21)/1000 -> 2.72 | M21: =IFERROR(H21*L21,0)*1000 -> 4989.6523 | N21: =207.84*L21 -> 565.3248 | O21: =$O$54/$L$52*L21 -> 129.08917 | P21: =$P$54/$L$52*L21 -> 253.76744 | Q21: =$Q$54/$L$52*L21 -> 202.85945 | R21: 0 | S21: 0 | T21: =M21+N21+O21+P21 -> 5937.8338 | U21: =IFERROR(T21/L21,0) -> 2183.0271
B22: POTA FILETE C/M C/T FR 2-4 AAA BL10 S20 | C22: 0 | E22: 0 | G22: 10005721 | H22: =IFERROR(INDEX([1]Resumen!$K$3:$K$63,MATCH(G22,[1]Resumen!$C$3:$C$63,0)),0)*(1+I22*J22)/1000-51.89/1000-93.38/1000 -> 1.834431 | I22: 0.67 | J22: =$H$59 -> -0.10965909 | K22: =C22/1000 -> 0 | L22: =IF(E22<0,0,E22)/1000 -> 0 | M22: =IFERROR(H22*L22,0)*1000 -> 0 | N22: =207.84*L22 -> 0 | O22: =$O$54/$L$52*L22 -> 0 | P22: =$P$54/$L$52*L22 -> 0 | Q22: =$Q$54/$L$52*L22 -> 0 | R22: 0 | S22: 0 | T22: =M22+N22+O22+P22 -> 0 | U22: =IFERROR(T22/L22,0) -> 0
... B26: POTA NUCAS FR CERRADA <0.1 BL10 S2 | C26: 1040 | E26: 1040 | G26: 10005779 | H26: =IFERROR(INDEX([1]Resumen!$K$3:$K$63,MATCH(G26,[1]Resumen!$C$3:$C$63,0)),0)*(1+I26*J26)/1000-51.89/1000-93.38/1000 -> 1.483423 | I26: 0.65 | J26: =$H$59 -> -0.10965909 | K26: =C26/1000 -> 1.04 | L26: =IF(E26<0,0,E26)/1000 -> 1.04 | M26: =IFERROR(H26*L26,0)*1000 -> 1542.7599 | N26: =207.84*L26 -> 216.1536 | O26: =$O$54/$L$52*L26 -> 49.357625 | P26: =$P$54/$L$52*L26 -> 97.028728 | Q26: =$Q$54/$L$52*L26 -> 77.563907 | R26: 0 | S26: 0 | T26: =M26+N26+O26+P26 -> 1905.2998 | U26: =IFERROR(T26/L26,0) -> 1832.0191
B27: POTA NUCAS FR ABIERTAS 0.5-1 BL10 S20 | C27: 83680 | D27: 78000 | E27: 5680 | G27: 10005779 | H27: =IFERROR(INDEX([1]Resumen!$K$3:$K$63,MATCH(G27,[1]Resumen!$C$3:$C$63,0)),0)*(1+I27*J27)/1000-51.89/1000-93.38/1000 -> 1.483423 | I27: 0.65 | J27: =$H$59 -> -0.10965909 | K27: =C27/1000 -> 83.68 | L27: =IF(E27<0,0,E27)/1000 -> 5.68 | M27: =IFERROR(H27*L27,0)*1000 -> 8425.8425 | N27: =207.84*L27 -> 1180.5312 | O27: =$O$54/$L$52*L27 -> 269.56857 | P27: =$P$54/$L$52*L27 -> 529.92613 | Q27: =$Q$54/$L$52*L27 -> 423.61826 | R27: 0 | S27: 0 | T27: =M27+N27+O27+P27 -> 10405.868 | U27: =IFERROR(T27/L27,0) -> 1832.0191
B28: POTA NUCAS FR ABIERTAS 0.3-0.5 BL10 S20 | C28: 174240 | E28: 174240 | G28: 10005779 | H28: =IFERROR(INDEX([1]Resumen!$K$3:$K$63,MATCH(G28,[1]Resumen!$C$3:$C$63,0)),0)*(1+I28*J28)/1000-51.89/1000-93.38/1000 -> 1.483423 | I28: 0.65 | J28: =$H$59 -> -0.10965909 | K28: =C28/1000 -> 174.24 | L28: =IF(E28<0,0,E28)/1000 -> 174.24 | M28: =IFERROR(H28*L28,0)*1000 -> 258471.62 | N28: =207.84*L28 -> 36214.042 | O28: =$O$54/$L$52*L28 -> 8269.3005 | P28: =$P$54/$L$52*L28 -> 16256.044 | Q28: =$Q$54/$L$52*L28 -> 12994.938 | R28: 0 | S28: 0 | T28: =M28+N28+O28+P28 -> 319211 | U28: =IFERROR(T28/L28,0) -> 1832.0191
B29: POTA NUCAS FR ABIERTAS 1-2 BL10 S20 | C29: 7840 | E29: 7840 | G29: 10005779 | H29: =IFERROR(INDEX([1]Resumen!$K$3:$K$63,MATCH(G29,[1]Resumen!$C$3:$C$63,0)),0)*(1+I29*J29)/1000-51.89/1000-93.38/1000 -> 1.483423 | I29: 0.65 | J29: =$H$59 -> -0.10965909 | K29: =C29/1000 -> 7.84 | L29: =IF(E29<0,0,E29)/1000 -> 7.84 | M29: =IFERROR(H29*L29,0)*1000 -> 11630.036 | N29: =207.84*L29 -> 1629.4656 | O29: =$O$54/$L$52*L29 -> 372.08056 | P29: =$P$54/$L$52*L29 -> 731.44733 | Q29: =$Q$54/$L$52*L29 -> 584.71253 | R29: 0 | S29: 0 | T29: =M29+N29+O29+P29 -> 14363.03 | U29: =IFERROR(T29/L29,0) -> 1832.0191
