Workbook

Sheet RESUMEN AL 6-7-2026
C2: PERU FROST
C3: AVANCE COMERCIAL AL 13-7-2026
F5: RENTABILIDAD DEL INVENTARIO | X5: 46206 | AA5: 46209 | AD5: 46215 | AG5: 46216 | AJ5: 46218 | AM5: 46220 | AP5: 46227 | AS5: TBN | BN5: TOTAL PROYECTADO JULIO 2026 | CB5: UNITARIOS POR TM
B6: Código | C6: Producto | D6: TM en Stock Libre | E6: CU | F6: Costo Ventas | G6: Gasto Ventas | H6: Gasto ADM | I6: Gasto Fin | J6: Depreciación | K6: Utilidad Neta | L6: Margen Neto | M6: Venta Equilibrio a Utd Neta | N6: Precio Equilibrio x TM a Utd Neta | O6: Venta Equilibro a EBITDA | P6: Precio Equilibrio x TM a EBITDA | Q6: Precio Mercado | R6: Venta total | S6: Utilidad | T6: Mg Neto | U6: EBITDA | V6: Mg EBITDA | X6: TM | Y6: Venta | Z6: Precio x TM | AA6: TM | AB6: Venta | AC6: Precio x TM | AD6: TM | AE6: Venta | AF6: Precio x TM | AG6: TM | AH6: Venta | AI6: Precio x TM | AJ6: TM | AK6: Venta | AL6: Precio x TM | AM6: TM | AN6: Venta | AO6: Precio x TM | AP6: TM | AQ6: Venta | AR6: Precio x TM | AS6: TM | AT6: Venta | AU6: Precio x TM | AV6: TM | AW6: Venta | AX6: Precio x TM | AY6: TM | AZ6: Venta | BA6: Precio x TM | BB6: TM | BC6: Venta | BD6: Precio x TM | BE6: TM | BF6: Venta | BG6: Precio x TM | BH6: TM | BI6: Venta | BJ6: Precio x TM | BK6: TM | BL6: Venta | BM6: Precio x TM | BN6: TM | BO6: Venta | BP6: Precio x TM | BQ6: Costo Ventas | BR6: Gasto Ventas | BS6: Gasto Adm | BT6: Gasto Fin | BU6: Depreciación | BV6: Drawback | BW6: Utilidad Neta | BX6: Mg Neto % | BY6: EBITDA | BZ6: MG EBITDA | CB6: Precio x TM | CC6: Costo Ventas | CD6: Gasto Ventas | CE6: Gasto Adm | CF6: Gasto Fin | CG6: Depreciación | CH6: Drawback | CI6: Utilidad Neta | CJ6: EBITDA
B7: 10005721 | C7: POTA FILETE CONGELADO | D7: =TD!F4 -> 377.674 | E7: =IFERROR(F7/D7,0) -> 1984.5862 | F7: =TD!G4 -> 749526.6 | G7: =TD!H4 -> 78495.764 | H7: =TD!I4 -> 17191.005 | I7: =TD!J4 -> 33794.604 | J7: =TD!K4 -> 27015.107 | K7: 0 | L7: 0 | M7: =F7+G7+H7+I7 -> 879007.97 | N7: =IFERROR(M7/D7,0) -> 2327.4252 | O7: =F7+G7+H7-J7 -> 818198.26 | P7: =IFERROR(O7/D7,0) -> 2166.4141 | Q7: 1800 | R7: =Q7*D7 -> 679813.2 | S7: =R7-M7+(Q7-$BS$19)*D7*0.03 -> -180094.03 | T7: =IFERROR(S7/R7,0) -> -0.26491694 | U7: =R7-(M7-J7-I7)+(Q7-$BS$19)*D7*0.03 -> -119284.32 | V7: =IFERROR(U7/R7,0) -> -0.17546632 | X7: {=SUM([6]Hoja3!$I$5:$I$19*([6]Hoja3!$F$5:$F$19=X$5)*([6]Hoja3!$K$5:$K$19=$C7))} -> 0 | Y7: {=SUM([6]Hoja3!$J$5:$J$19*([6]Hoja3!$F$5:$F$19=X$5)*([6]Hoja3!$K$5:$K$19=$C7))} -> 0 | Z7: =IFERROR(Y7/X7,0) -> 0 | AA7: {=SUM([6]Hoja3!$I$5:$I$19*([6]Hoja3!$F$5:$F$19=AA$5)*([6]Hoja3!$K$5:$K$19=$C7))} -> 0 | AB7: {=SUM([6]Hoja3!$J$5:$J$19*([6]Hoja3!$F$5:$F$19=AA$5)*([6]Hoja3!$K$5:$K$19=$C7))} -> 0 | AC7: =IFERROR(AB7/AA7,0) -> 0 | AD7: {=SUM([6]Hoja3!$I$5:$I$19*([6]Hoja3!$F$5:$F$19=AD$5)*([6]Hoja3!$K$5:$K$19=$C7))} -> 0 | AE7: {=SUM([6]Hoja3!$J$5:$J$19*([6]Hoja3!$F$5:$F$19=AD$5)*([6]Hoja3!$K$5:$K$19=$C7))} -> 0 | AF7: =IFERROR(AE7/AD7,0) -> 0 | AG7: {=SUM([6]Hoja3!$I$5:$I$19*([6]Hoja3!$F$5:$F$19=AG$5)*([6]Hoja3!$K$5:$K$19=$C7))} -> 0 | AH7: {=SUM([6]Hoja3!$J$5:$J$19*([6]Hoja3!$F$5:$F$19=AG$5)*([6]Hoja3!$K$5:$K$19=$C7))} -> 0 | AI7: =IFERROR(AH7/AG7,0) -> 0 | AJ7: {=SUM([6]Hoja3!$I$5:$I$19*([6]Hoja3!$F$5:$F$19=AJ$5)*([6]Hoja3!$K$5:$K$19=$C7))} -> 270 | AK7: {=SUM([6]Hoja3!$J$5:$J$19*([6]Hoja3!$F$5:$F$19=AJ$5)*([6]Hoja3!$K$5:$K$19=$C7))} -> 405000 | AL7: =IFERROR(AK7/AJ7,0) -> 1500 | AM7: {=SUM([6]Hoja3!$I$5:$I$19*([6]Hoja3!$F$5:$F$19=AM$5)*([6]Hoja3!$K$5:$K$19=$C7))} -> 0 | AN7: {=SUM([6]Hoja3!$J$5:$J$19*([6]Hoja3!$F$5:$F$19=AM$5)*([6]Hoja3!$K$5:$K$19=$C7))} -> 0 | AO7: =IFERROR(AN7/AM7,0) -> 0 | AP7: {=SUM([6]Hoja3!$I$5:$I$19*([6]Hoja3!$F$5:$F$19=AP$5)*([6]Hoja3!$K$5:$K$19=$C7))} -> 0 | AQ7: {=SUM([6]Hoja3!$J$5:$J$19*([6]Hoja3!$F$5:$F$19=AP$5)*([6]Hoja3!$K$5:$K$19=$C7))} -> 0 | AR7: =IFERROR(AQ7/AP7,0) -> 0 | AS7: {=SUM([6]Hoja3!$I$5:$I$19*([6]Hoja3!$F$5:$F$19=AS$5)*([6]Hoja3!$K$5:$K$19=$C7))} -> 294 | AT7: {=SUM([6]Hoja3!$J$5:$J$19*([6]Hoja3!$F$5:$F$19=AS$5)*([6]Hoja3!$K$5:$K$19=$C7))} -> 460200 | AU7: =IFERROR(AT7/AS7,0) -> 1565.3061 | AV7: {=SUM([2]Hoja2!$I$6:$I$26*([2]Hoja2!$F$6:$F$26=AV$5)*([2]Hoja2!$K$6:$K$26=$C7))} -> 0 | AW7: {=SUM([2]Hoja2!$J$6:$J$26*([2]Hoja2!$F$6:$F$26=AV$5)*([2]Hoja2!$K$6:$K$26=$C7))} -> 0 | AX7: =IFERROR(AW7/AV7,0) -> 0 | AY7: {=SUM([2]Hoja2!$I$6:$I$26*([2]Hoja2!$F$6:$F$26=AY$5)*([2]Hoja2!$K$6:$K$26=$C7))} -> 0 | AZ7: {=SUM([2]Hoja2!$J$6:$J$26*([2]Hoja2!$F$6:$F$26=AY$5)*([2]Hoja2!$K$6:$K$26=$C7))} -> 0 | BA7: =IFERROR(AZ7/AY7,0) -> 0 | BB7: {=SUM([2]Hoja2!$I$6:$I$26*([2]Hoja2!$F$6:$F$26=BB$5)*([2]Hoja2!$K$6:$K$26=$C7))} -> 0 | BC7: {=SUM([2]Hoja2!$J$6:$J$26*([2]Hoja2!$F$6:$F$26=BB$5)*([2]Hoja2!$K$6:$K$26=$C7))} -> 0 | BD7: =IFERROR(BC7/BB7,0) -> 0 | BE7: {=SUM([2]Hoja2!$I$6:$I$26*([2]Hoja2!$F$6:$F$26=BE$5)*([2]Hoja2!$K$6:$K$26=$C7))} -> 0 | BF7: {=SUM([2]Hoja2!$J$6:$J$26*([2]Hoja2!$F$6:$F$26=BE$5)*([2]Hoja2!$K$6:$K$26=$C7))} -> 0 | BG7: =IFERROR(BF7/BE7,0) -> 0 | BH7: {=SUM([2]Hoja2!$I$6:$I$26*([2]Hoja2!$F$6:$F$26=BH$5)*([2]Hoja2!$K$6:$K$26=$C7))} -> 0 | BI7: {=SUM([2]Hoja2!$J$6:$J$26*([2]Hoja2!$F$6:$F$26=BH$5)*([2]Hoja2!$K$6:$K$26=$C7))} -> 0 | BJ7: =IFERROR(BI7/BH7,0) -> 0 | BK7: {=SUM([2]Hoja2!$I$6:$I$26*([2]Hoja2!$F$6:$F$26=BK$5)*([2]Hoja2!$K$6:$K$26=$C7))} -> 0 | BL7: {=SUM([2]Hoja2!$J$6:$J$26*([2]Hoja2!$F$6:$F$26=BK$5)*([2]Hoja2!$K$6:$K$26=$C7))} -> 0 | BM7: =IFERROR(BL7/BK7,0) -> 0 | BN7: =X7+AA7+AD7+AG7+AJ7+AM7+AP7+AS7 -> 564 | BO7: =Y7+AB7+AE7+AH7+AK7+AN7+AQ7+AT7 -> 865200 | BP7: =IFERROR(BO7/BN7,0) -> 1534.0426 | BQ7: =-IFERROR(F7/D7*BN7,0) -> -1119306.6 | BR7: =-207.84*BN7 -> -117221.76 | BS7: =$BS$18/$BN$18*$BN7 -> -55398.195 | BT7: =$BT$18/$BN$18*$BN7 -> -108903.47 | BU7: =$BU$18/$BN$18*$BN7 -> -87056.467 | BV7: =(BO7-BN7*$BS$19)*0.03 -> 24024.115 | BW7: =BO7+SUM(BQ7:BT7,BV7) -> -511605.91 | BX7: =IFERROR(BW7/BO7,0) -> -0.5913152 | BY7: =BO7+BQ7+BR7+BS7+BV7-BU7 -> -315645.98 | BZ7: =IFERROR(BY7/BO7,0) -> -0.36482429 | CB7: =BP7 -> 1534.0426 | CC7: =IFERROR(BQ7/$BN7,0) -> -1984.5862 | CD7: =IFERROR(BR7/$BN7,0) -> -207.84 | CE7: =IFERROR(BS7/$BN7,0) -> -98.22375 | CF7: =IFERROR(BT7/$BN7,0) -> -193.09125 | CG7: =IFERROR(BU7/$BN7,0) -> -154.35544 | CH7: =IFERROR(BV7/$BN7,0) -> 42.595948 | CI7: =IFERROR(BW7/$BN7,0) -> -907.10267 | CJ7: =IFERROR(BY7/$BN7,0) -> -559.65598 | CK7: =CJ7-CI7 -> 347.44669
B8: 10005779 | C8: POTA NUCAS CONGELADAS | D8: =TD!F5 -> 329.24 | E8: =IFERROR(F8/D8,0) -> 1622.0104 | F8: =TD!G5 -> 534030.7 | G8: =TD!H5 -> 68429.242 | H8: =TD!I5 -> 14986.381 | I8: =TD!J5 -> 29460.687 | J8: =TD!K5 -> 23550.612 | K8: 0 | L8: 0 | M8: =F8+G8+H8+I8 -> 646907.01 | N8: =IFERROR(M8/D8,0) -> 1964.8494 | O8: =F8+G8+H8-J8 -> 593895.71 | P8: =IFERROR(O8/D8,0) -> 1803.8383 | Q8: 1300 | R8: =Q8*D8 -> 428012 | S8: =R8-M8+(Q8-$BS$19)*D8*0.03 -> -207182.41 | T8: =IFERROR(S8/R8,0) -> -0.48405747 | U8: =R8-(M8-J8-I8)+(Q8-$BS$19)*D8*0.03 -> -154171.11 | V8: =IFERROR(U8/R8,0) -> -0.36020277 | X8: {=SUM([6]Hoja3!$I$5:$I$19*([6]Hoja3!$F$5:$F$19=X$5)*([6]Hoja3!$K$5:$K$19=$C8))} -> 0 | Y8: {=SUM([6]Hoja3!$J$5:$J$19*([6]Hoja3!$F$5:$F$19=X$5)*([6]Hoja3!$K$5:$K$19=$C8))} -> 0 | Z8: =IFERROR(Y8/X8,0) -> 0 | AA8: {=SUM([6]Hoja3!$I$5:$I$19*([6]Hoja3!$F$5:$F$19=AA$5)*([6]Hoja3!$K$5:$K$19=$C8))} -> 0 | AB8: {=SUM([6]Hoja3!$J$5:$J$19*([6]Hoja3!$F$5:$F$19=AA$5)*([6]Hoja3!$K$5:$K$19=$C8))} -> 0 | AC8: =IFERROR(AB8/AA8,0) -> 0 | AD8: {=SUM([6]Hoja3!$I$5:$I$19*([6]Hoja3!$F$5:$F$19=AD$5)*([6]Hoja3!$K$5:$K$19=$C8))} -> 0 | AE8: {=SUM([6]Hoja3!$J$5:$J$19*([6]Hoja3!$F$5:$F$19=AD$5)*([6]Hoja3!$K$5:$K$19=$C8))} -> 0 | AF8: =IFERROR(AE8/AD8,0) -> 0 | AG8: {=SUM([6]Hoja3!$I$5:$I$19*([6]Hoja3!$F$5:$F$19=AG$5)*([6]Hoja3!$K$5:$K$19=$C8))} -> 0 | AH8: {=SUM([6]Hoja3!$J$5:$J$19*([6]Hoja3!$F$5:$F$19=AG$5)*([6]Hoja3!$K$5:$K$19=$C8))} -> 0 | AI8: =IFERROR(AH8/AG8,0) -> 0 | AJ8: {=SUM([6]Hoja3!$I$5:$I$19*([6]Hoja3!$F$5:$F$19=AJ$5)*([6]Hoja3!$K$5:$K$19=$C8))} -> 0 | AK8: {=SUM([6]Hoja3!$J$5:$J$19*([6]Hoja3!$F$5:$F$19=AJ$5)*([6]Hoja3!$K$5:$K$19=$C8))} -> 0 | AL8: =IFERROR(AK8/AJ8,0) -> 0 | AM8: {=SUM([6]Hoja3!$I$5:$I$19*([6]Hoja3!$F$5:$F$19=AM$5)*([6]Hoja3!$K$5:$K$19=$C8))} -> 0 | AN8: {=SUM([6]Hoja3!$J$5:$J$19*([6]Hoja3!$F$5:$F$19=AM$5)*([6]Hoja3!$K$5:$K$19=$C8))} -> 0 | AO8: =IFERROR(AN8/AM8,0) -> 0 | AP8: {=SUM([6]Hoja3!$I$5:$I$19*([6]Hoja3!$F$5:$F$19=AP$5)*([6]Hoja3!$K$5:$K$19=$C8))} -> 0 | AQ8: {=SUM([6]Hoja3!$J$5:$J$19*([6]Hoja3!$F$5:$F$19=AP$5)*([6]Hoja3!$K$5:$K$19=$C8))} -> 0 | AR8: =IFERROR(AQ8/AP8,0) -> 0 | AS8: {=SUM([6]Hoja3!$I$5:$I$19*([6]Hoja3!$F$5:$F$19=AS$5)*([6]Hoja3!$K$5:$K$19=$C8))} -> 52 | AT8: {=SUM([6]Hoja3!$J$5:$J$19*([6]Hoja3!$F$5:$F$19=AS$5)*([6]Hoja3!$K$5:$K$19=$C8))} -> 67600 | AU8: =IFERROR(AT8/AS8,0) -> 1300 | AV8: {=SUM([2]Hoja2!$I$6:$I$26*([2]Hoja2!$F$6:$F$26=AV$5)*([2]Hoja2!$K$6:$K$26=$C8))} -> 0 | AW8: {=SUM([2]Hoja2!$J$6:$J$26*([2]Hoja2!$F$6:$F$26=AV$5)*([2]Hoja2!$K$6:$K$26=$C8))} -> 0 | AX8: =IFERROR(AW8/AV8,0) -> 0 | AY8: {=SUM([2]Hoja2!$I$6:$I$26*([2]Hoja2!$F$6:$F$26=AY$5)*([2]Hoja2!$K$6:$K$26=$C8))} -> 0 | AZ8: {=SUM([2]Hoja2!$J$6:$J$26*([2]Hoja2!$F$6:$F$26=AY$5)*([2]Hoja2!$K$6:$K$26=$C8))} -> 0 | BA8: =IFERROR(AZ8/AY8,0) -> 0 | BB8: {=SUM([2]Hoja2!$I$6:$I$26*([2]Hoja2!$F$6:$F$26=BB$5)*([2]Hoja2!$K$6:$K$26=$C8))} -> 0 | BC8: {=SUM([2]Hoja2!$J$6:$J$26*([2]Hoja2!$F$6:$F$26=BB$5)*([2]Hoja2!$K$6:$K$26=$C8))} -> 0 | BD8: =IFERROR(BC8/BB8,0) -> 0 | BE8: {=SUM([2]Hoja2!$I$6:$I$26*([2]Hoja2!$F$6:$F$26=BE$5)*([2]Hoja2!$K$6:$K$26=$C8))} -> 0 | BF8: {=SUM([2]Hoja2!$J$6:$J$26*([2]Hoja2!$F$6:$F$26=BE$5)*([2]Hoja2!$K$6:$K$26=$C8))} -> 0 | BG8: =IFERROR(BF8/BE8,0) -> 0 | BH8: {=SUM([2]Hoja2!$I$6:$I$26*([2]Hoja2!$F$6:$F$26=BH$5)*([2]Hoja2!$K$6:$K$26=$C8))} -> 0 | BI8: {=SUM([2]Hoja2!$J$6:$J$26*([2]Hoja2!$F$6:$F$26=BH$5)*([2]Hoja2!$K$6:$K$26=$C8))} -> 0 | BJ8: =IFERROR(BI8/BH8,0) -> 0 | BK8: {=SUM([2]Hoja2!$I$6:$I$26*([2]Hoja2!$F$6:$F$26=BK$5)*([2]Hoja2!$K$6:$K$26=$C8))} -> 0 | BL8: {=SUM([2]Hoja2!$J$6:$J$26*([2]Hoja2!$F$6:$F$26=BK$5)*([2]Hoja2!$K$6:$K$26=$C8))} -> 0 | BM8: =IFERROR(BL8/BK8,0) -> 0 | BN8: =X8+AA8+AD8+AG8+AJ8+AM8+AP8+AS8 -> 52 | BO8: =Y8+AB8+AE8+AH8+AK8+AN8+AQ8+AT8 -> 67600 | BP8: =IFERROR(BO8/BN8,0) -> 1300 | BQ8: =-IFERROR(F8/D8*BN8,0) -> -84344.541 | BR8: =-207.84*BN8 -> -10807.68 | BS8: =$BS$18/$BN$18*$BN8 -> -5107.635 | BT8: =$BT$18/$BN$18*$BN8 -> -10040.745 | BU8: =$BU$18/$BN$18*$BN8 -> -8026.4828 | BV8: =(BO8-BN8*$BS$19)*0.03 -> 1849.8829 | BW8: =BO8+SUM(BQ8:BT8,BV8) -> -40850.718 | BX8: =IFERROR(BW8/BO8,0) -> -0.60430056 | BY8: =BO8+BQ8+BR8+BS8+BV8-BU8 -> -22783.49 | BZ8: =IFERROR(BY8/BO8,0) -> -0.33703387 | CB8: =BP8 -> 1300 | CC8: =IFERROR(BQ8/$BN8,0) -> -1622.0104 | CD8: =IFERROR(BR8/$BN8,0) -> -207.84 | CE8: =IFERROR(BS8/$BN8,0) -> -98.22375 | CF8: =IFERROR(BT8/$BN8,0) -> -193.09125 | CG8: =IFERROR(BU8/$BN8,0) -> -154.35544 | CH8: =IFERROR(BV8/$BN8,0) -> 35.574672 | CI8: =IFERROR(BW8/$BN8,0) -> -785.59072 | CJ8: =IFERROR(BY8/$BN8,0) -> -438.14404 | CK8: =CJ8-CI8 -> 347.44669
B9: 10006719 | C9: POTA ALAS CONGELADAS | D9: =TD!F6 -> 487.452 | E9: =IFERROR(F9/D9,0) -> 1882.6724 | F9: =TD!G6 -> 917712.41 | G9: =TD!H6 -> 101312.02 | H9: =TD!I6 -> 22187.892 | I9: =TD!J6 -> 43617.637 | J9: =TD!K6 -> 34867.553 | K9: 0 | L9: 0 | M9: =F9+G9+H9+I9 -> 1084830 | N9: =IFERROR(M9/D9,0) -> 2225.5114 | O9: =F9+G9+H9-J9 -> 1006344.8 | P9: =IFERROR(O9/D9,0) -> 2064.5002 | Q9: 1750 | R9: =Q9*D9 -> 853041 | S9: =R9-M9+(Q9-$BS$19)*D9*0.03 -> -207867.41 | T9: =IFERROR(S9/R9,0) -> -0.2436781 | U9: =R9-(M9-J9-I9)+(Q9-$BS$19)*D9*0.03 -> -129382.22 | V9: =IFERROR(U9/R9,0) -> -0.15167175 | X9: {=SUM([6]Hoja3!$I$5:$I$19*([6]Hoja3!$F$5:$F$19=X$5)*([6]Hoja3!$K$5:$K$19=$C9))} -> 0 | Y9: {=SUM([6]Hoja3!$J$5:$J$19*([6]Hoja3!$F$5:$F$19=X$5)*([6]Hoja3!$K$5:$K$19=$C9))} -> 0 | Z9: =IFERROR(Y9/X9,0) -> 0 | AA9: {=SUM([6]Hoja3!$I$5:$I$19*([6]Hoja3!$F$5:$F$19=AA$5)*([6]Hoja3!$K$5:$K$19=$C9))} -> 0 | AB9: {=SUM([6]Hoja3!$J$5:$J$19*([6]Hoja3!$F$5:$F$19=AA$5)*([6]Hoja3!$K$5:$K$19=$C9))} -> 0 | AC9: =IFERROR(AB9/AA9,0) -> 0 | AD9: {=SUM([6]Hoja3!$I$5:$I$19*([6]Hoja3!$F$5:$F$19=AD$5)*([6]Hoja3!$K$5:$K$19=$C9))} -> 54 | AE9: {=SUM([6]Hoja3!$J$5:$J$19*([6]Hoja3!$F$5:$F$19=AD$5)*([6]Hoja3!$K$5:$K$19=$C9))} -> 94500 | AF9: =IFERROR(AE9/AD9,0) -> 1750 | AG9: {=SUM([6]Hoja3!$I$5:$I$19*([6]Hoja3!$F$5:$F$19=AG$5)*([6]Hoja3!$K$5:$K$19=$C9))} -> 0 | AH9: {=SUM([6]Hoja3!$J$5:$J$19*([6]Hoja3!$F$5:$F$19=AG$5)*([6]Hoja3!$K$5:$K$19=$C9))} -> 0 | AI9: =IFERROR(AH9/AG9,0) -> 0 | AJ9: {=SUM([6]Hoja3!$I$5:$I$19*([6]Hoja3!$F$5:$F$19=AJ$5)*([6]Hoja3!$K$5:$K$19=$C9))} -> 0 | AK9: {=SUM([6]Hoja3!$J$5:$J$19*([6]Hoja3!$F$5:$F$19=AJ$5)*([6]Hoja3!$K$5:$K$19=$C9))} -> 0 | AL9: =IFERROR(AK9/AJ9,0) -> 0 | AM9: {=SUM([6]Hoja3!$I$5:$I$19*([6]Hoja3!$F$5:$F$19=AM$5)*([6]Hoja3!$K$5:$K$19=$C9))} -> 0 | AN9: {=SUM([6]Hoja3!$J$5:$J$19*([6]Hoja3!$F$5:$F$19=AM$5)*([6]Hoja3!$K$5:$K$19=$C9))} -> 0 | AO9: =IFERROR(AN9/AM9,0) -> 0 | AP9: {=SUM([6]Hoja3!$I$5:$I$19*([6]Hoja3!$F$5:$F$19=AP$5)*([6]Hoja3!$K$5:$K$19=$C9))} -> 0 | AQ9: {=SUM([6]Hoja3!$J$5:$J$19*([6]Hoja3!$F$5:$F$19=AP$5)*([6]Hoja3!$K$5:$K$19=$C9))} -> 0 | AR9: =IFERROR(AQ9/AP9,0) -> 0 | AS9: {=SUM([6]Hoja3!$I$5:$I$19*([6]Hoja3!$F$5:$F$19=AS$5)*([6]Hoja3!$K$5:$K$19=$C9))} -> 0 | AT9: {=SUM([6]Hoja3!$J$5:$J$19*([6]Hoja3!$F$5:$F$19=AS$5)*([6]Hoja3!$K$5:$K$19=$C9))} -> 0 | AU9: =IFERROR(AT9/AS9,0) -> 0 | AV9: {=SUM([2]Hoja2!$I$6:$I$26*([2]Hoja2!$F$6:$F$26=AV$5)*([2]Hoja2!$K$6:$K$26=$C9))} -> 0 | AW9: {=SUM([2]Hoja2!$J$6:$J$26*([2]Hoja2!$F$6:$F$26=AV$5)*([2]Hoja2!$K$6:$K$26=$C9))} -> 0 | AX9: =IFERROR(AW9/AV9,0) -> 0 | AY9: {=SUM([2]Hoja2!$I$6:$I$26*([2]Hoja2!$F$6:$F$26=AY$5)*([2]Hoja2!$K$6:$K$26=$C9))} -> 0 | AZ9: {=SUM([2]Hoja2!$J$6:$J$26*([2]Hoja2!$F$6:$F$26=AY$5)*([2]Hoja2!$K$6:$K$26=$C9))} -> 0 | BA9: =IFERROR(AZ9/AY9,0) -> 0 | BB9: {=SUM([2]Hoja2!$I$6:$I$26*([2]Hoja2!$F$6:$F$26=BB$5)*([2]Hoja2!$K$6:$K$26=$C9))} -> 0 | BC9: {=SUM([2]Hoja2!$J$6:$J$26*([2]Hoja2!$F$6:$F$26=BB$5)*([2]Hoja2!$K$6:$K$26=$C9))} -> 0 | BD9: =IFERROR(BC9/BB9,0) -> 0 | BE9: {=SUM([2]Hoja2!$I$6:$I$26*([2]Hoja2!$F$6:$F$26=BE$5)*([2]Hoja2!$K$6:$K$26=$C9))} -> 0 | BF9: {=SUM([2]Hoja2!$J$6:$J$26*([2]Hoja2!$F$6:$F$26=BE$5)*([2]Hoja2!$K$6:$K$26=$C9))} -> 0 | BG9: =IFERROR(BF9/BE9,0) -> 0 | BH9: {=SUM([2]Hoja2!$I$6:$I$26*([2]Hoja2!$F$6:$F$26=BH$5)*([2]Hoja2!$K$6:$K$26=$C9))} -> 0 | BI9: {=SUM([2]Hoja2!$J$6:$J$26*([2]Hoja2!$F$6:$F$26=BH$5)*([2]Hoja2!$K$6:$K$26=$C9))} -> 0 | BJ9: =IFERROR(BI9/BH9,0) -> 0 | BK9: {=SUM([2]Hoja2!$I$6:$I$26*([2]Hoja2!$F$6:$F$26=BK$5)*([2]Hoja2!$K$6:$K$26=$C9))} -> 0 | BL9: {=SUM([2]Hoja2!$J$6:$J$26*([2]Hoja2!$F$6:$F$26=BK$5)*([2]Hoja2!$K$6:$K$26=$C9))} -> 0 | BM9: =IFERROR(BL9/BK9,0) -> 0 | BN9: =X9+AA9+AD9+AG9+AJ9+AM9+AP9+AS9 -> 54 | BO9: =Y9+AB9+AE9+AH9+AK9+AN9+AQ9+AT9 -> 94500 | BP9: =IFERROR(BO9/BN9,0) -> 1750 | BQ9: =-IFERROR(F9/D9*BN9,0) -> -101664.31 | BR9: =-207.84*BN9 -> -11223.36 | BS9: =$BS$18/$BN$18*$BN9 -> -5304.0825 | BT9: =$BT$18/$BN$18*$BN9 -> -10426.928 | BU9: =$BU$18/$BN$18*$BN9 -> -8335.1936 | BV9: =(BO9-BN9*$BS$19)*0.03 -> 2650.0323 | BW9: =BO9+SUM(BQ9:BT9,BV9) -> -31468.645 | BX9: =IFERROR(BW9/BO9,0) -> -0.33300154 | BY9: =BO9+BQ9+BR9+BS9+BV9-BU9 -> -12706.524 | BZ9: =IFERROR(BY9/BO9,0) -> -0.13446057 | CB9: =BP9 -> 1750 | CC9: =IFERROR(BQ9/$BN9,0) -> -1882.6724 | CD9: =IFERROR(BR9/$BN9,0) -> -207.84 | CE9: =IFERROR(BS9/$BN9,0) -> -98.22375 | CF9: =IFERROR(BT9/$BN9,0) -> -193.09125 | CG9: =IFERROR(BU9/$BN9,0) -> -154.35544 | CH9: =IFERROR(BV9/$BN9,0) -> 49.074672 | CI9: =IFERROR(BW9/$BN9,0) -> -582.75269 | CJ9: =IFERROR(BY9/$BN9,0) -> -235.306 | CK9: =CJ9-CI9 -> 347.44669
B10: 10007050 | C10: POTA RECORTES COCIDOS | D10: =TD!F7 -> 59.01 | E10: =IFERROR(F10/D10,0) -> 1443.946 | F10: =TD!G7 -> 85207.251 | G10: =TD!H7 -> 12264.638 | H10: =TD!I7 -> 2686.0235 | I10: =TD!J7 -> 5280.267 | J10: =TD!K7 -> 4220.9988 | K10: 0 | L10: 0 | M10: =F10+G10+H10+I10 -> 105438.18 | N10: =IFERROR(M10/D10,0) -> 1786.7849 | O10: =F10+G10+H10-J10 -> 95936.914 | P10: =IFERROR(O10/D10,0) -> 1625.7738 | Q10: 1700 | R10: =Q10*D10 -> 100317 | S10: =R10-M10+(Q10-$BS$19)*D10*0.03 -> -2313.7981 | T10: =IFERROR(S10/R10,0) -> -0.023064865 | U10: =R10-(M10-J10-I10)+(Q10-$BS$19)*D10*0.03 -> 7187.4677 | V10: =IFERROR(U10/R10,0) -> 0.071647554 | X10: {=SUM([6]Hoja3!$I$5:$I$19*([6]Hoja3!$F$5:$F$19=X$5)*([6]Hoja3!$K$5:$K$19=$C10))} -> 27 | Y10: {=SUM([6]Hoja3!$J$5:$J$19*([6]Hoja3!$F$5:$F$19=X$5)*([6]Hoja3!$K$5:$K$19=$C10))} -> 68850 | Z10: =IFERROR(Y10/X10,0) -> 2550 | AA10: {=SUM([6]Hoja3!$I$5:$I$19*([6]Hoja3!$F$5:$F$19=AA$5)*([6]Hoja3!$K$5:$K$19=$C10))} -> 0 | AB10: {=SUM([6]Hoja3!$J$5:$J$19*([6]Hoja3!$F$5:$F$19=AA$5)*([6]Hoja3!$K$5:$K$19=$C10))} -> 0 | AC10: =IFERROR(AB10/AA10,0) -> 0 | AD10: {=SUM([6]Hoja3!$I$5:$I$19*([6]Hoja3!$F$5:$F$19=AD$5)*([6]Hoja3!$K$5:$K$19=$C10))} -> 0 | AE10: {=SUM([6]Hoja3!$J$5:$J$19*([6]Hoja3!$F$5:$F$19=AD$5)*([6]Hoja3!$K$5:$K$19=$C10))} -> 0 | AF10: =IFERROR(AE10/AD10,0) -> 0 | AG10: {=SUM([6]Hoja3!$I$5:$I$19*([6]Hoja3!$F$5:$F$19=AG$5)*([6]Hoja3!$K$5:$K$19=$C10))} -> 0 | AH10: {=SUM([6]Hoja3!$J$5:$J$19*([6]Hoja3!$F$5:$F$19=AG$5)*([6]Hoja3!$K$5:$K$19=$C10))} -> 0 | AI10: =IFERROR(AH10/AG10,0) -> 0 | AJ10: {=SUM([6]Hoja3!$I$5:$I$19*([6]Hoja3!$F$5:$F$19=AJ$5)*([6]Hoja3!$K$5:$K$19=$C10))} -> 0 | AK10: {=SUM([6]Hoja3!$J$5:$J$19*([6]Hoja3!$F$5:$F$19=AJ$5)*([6]Hoja3!$K$5:$K$19=$C10))} -> 0 | AL10: =IFERROR(AK10/AJ10,0) -> 0 | AM10: {=SUM([6]Hoja3!$I$5:$I$19*([6]Hoja3!$F$5:$F$19=AM$5)*([6]Hoja3!$K$5:$K$19=$C10))} -> 0 | AN10: {=SUM([6]Hoja3!$J$5:$J$19*([6]Hoja3!$F$5:$F$19=AM$5)*([6]Hoja3!$K$5:$K$19=$C10))} -> 0 | AO10: =IFERROR(AN10/AM10,0) -> 0 | AP10: {=SUM([6]Hoja3!$I$5:$I$19*([6]Hoja3!$F$5:$F$19=AP$5)*([6]Hoja3!$K$5:$K$19=$C10))} -> 0 | AQ10: {=SUM([6]Hoja3!$J$5:$J$19*([6]Hoja3!$F$5:$F$19=AP$5)*([6]Hoja3!$K$5:$K$19=$C10))} -> 0 | AR10: =IFERROR(AQ10/AP10,0) -> 0 | AS10: {=SUM([6]Hoja3!$I$5:$I$19*([6]Hoja3!$F$5:$F$19=AS$5)*([6]Hoja3!$K$5:$K$19=$C10))} -> 0 | AT10: {=SUM([6]Hoja3!$J$5:$J$19*([6]Hoja3!$F$5:$F$19=AS$5)*([6]Hoja3!$K$5:$K$19=$C10))} -> 0 | AU10: =IFERROR(AT10/AS10,0) -> 0 | AV10: {=SUM([2]Hoja2!$I$6:$I$26*([2]Hoja2!$F$6:$F$26=AV$5)*([2]Hoja2!$K$6:$K$26=$C10))} -> 0 | AW10: {=SUM([2]Hoja2!$J$6:$J$26*([2]Hoja2!$F$6:$F$26=AV$5)*([2]Hoja2!$K$6:$K$26=$C10))} -> 0 | AX10: =IFERROR(AW10/AV10,0) -> 0 | AY10: {=SUM([2]Hoja2!$I$6:$I$26*([2]Hoja2!$F$6:$F$26=AY$5)*([2]Hoja2!$K$6:$K$26=$C10))} -> 0 | AZ10: {=SUM([2]Hoja2!$J$6:$J$26*([2]Hoja2!$F$6:$F$26=AY$5)*([2]Hoja2!$K$6:$K$26=$C10))} -> 0 | BA10: =IFERROR(AZ10/AY10,0) -> 0 | BB10: {=SUM([2]Hoja2!$I$6:$I$26*([2]Hoja2!$F$6:$F$26=BB$5)*([2]Hoja2!$K$6:$K$26=$C10))} -> 0 | BC10: {=SUM([2]Hoja2!$J$6:$J$26*([2]Hoja2!$F$6:$F$26=BB$5)*([2]Hoja2!$K$6:$K$26=$C10))} -> 0 | BD10: =IFERROR(BC10/BB10,0) -> 0 | BE10: {=SUM([2]Hoja2!$I$6:$I$26*([2]Hoja2!$F$6:$F$26=BE$5)*([2]Hoja2!$K$6:$K$26=$C10))} -> 0 | BF10: {=SUM([2]Hoja2!$J$6:$J$26*([2]Hoja2!$F$6:$F$26=BE$5)*([2]Hoja2!$K$6:$K$26=$C10))} -> 0 | BG10: =IFERROR(BF10/BE10,0) -> 0 | BH10: {=SUM([2]Hoja2!$I$6:$I$26*([2]Hoja2!$F$6:$F$26=BH$5)*([2]Hoja2!$K$6:$K$26=$C10))} -> 0 | BI10: {=SUM([2]Hoja2!$J$6:$J$26*([2]Hoja2!$F$6:$F$26=BH$5)*([2]Hoja2!$K$6:$K$26=$C10))} -> 0 | BJ10: =IFERROR(BI10/BH10,0) -> 0 | BK10: {=SUM([2]Hoja2!$I$6:$I$26*([2]Hoja2!$F$6:$F$26=BK$5)*([2]Hoja2!$K$6:$K$26=$C10))} -> 0 | BL10: {=SUM([2]Hoja2!$J$6:$J$26*([2]Hoja2!$F$6:$F$26=BK$5)*([2]Hoja2!$K$6:$K$26=$C10))} -> 0 | BM10: =IFERROR(BL10/BK10,0) -> 0 | BN10: =X10+AA10+AD10+AG10+AJ10+AM10+AP10+AS10 -> 27 | BO10: =Y10+AB10+AE10+AH10+AK10+AN10+AQ10+AT10 -> 68850 | BP10: =IFERROR(BO10/BN10,0) -> 2550 | BQ10: =-IFERROR(F10/D10*BN10,0) -> -38986.541 | BR10: =-207.84*BN10 -> -5611.68 | BS10: =$BS$18/$BN$18*$BN10 -> -2652.0413 | BT10: =$BT$18/$BN$18*$BN10 -> -5213.4638 | BU10: =$BU$18/$BN$18*$BN10 -> -4167.5968 | BV10: =(BO10-BN10*$BS$19)*0.03 -> 1973.0161 | BW10: =BO10+SUM(BQ10:BT10,BV10) -> 18359.29 | BX10: =IFERROR(BW10/BO10,0) -> 0.26665636 | BY10: =BO10+BQ10+BR10+BS10+BV10-BU10 -> 27740.351 | BZ10: =IFERROR(BY10/BO10,0) -> 0.40290996 | CB10: =BP10 -> 2550 | CC10: =IFERROR(BQ10/$BN10,0) -> -1443.946 | CD10: =IFERROR(BR10/$BN10,0) -> -207.84 | CE10: =IFERROR(BS10/$BN10,0) -> -98.22375 | CF10: =IFERROR(BT10/$BN10,0) -> -193.09125 | CG10: =IFERROR(BU10/$BN10,0) -> -154.35544 | CH10: =IFERROR(BV10/$BN10,0) -> 73.074672 | CI10: =IFERROR(BW10/$BN10,0) -> 679.97372 | CJ10: =IFERROR(BY10/$BN10,0) -> 1027.4204 | CK10: =CJ10-CI10 -> 347.44669
B11: 10007162 | C11: POTA REJOS CONGELADOS | D11: =TD!F8 -> 235.86 | E11: =IFERROR(F11/D11,0) -> 1740.6978 | F11: =TD!G8 -> 410560.98 | G11: =TD!H8 -> 49021.142 | H11: =TD!I8 -> 10735.901 | I11: =TD!J8 -> 21104.962 | J11: =TD!K8 -> 16871.12 | K11: 0 | L11: 0 | M11: =F11+G11+H11+I11 -> 491422.98 | N11: =IFERROR(M11/D11,0) -> 2083.5368 | O11: =F11+G11+H11-J11 -> 453446.9 | P11: =IFERROR(O11/D11,0) -> 1922.5257 | Q11: 2700 | R11: =Q11*D11 -> 636822 | S11: =R11-M11+(Q11-$BS$19)*D11*0.03 -> 163695.78 | T11: =IFERROR(S11/R11,0) -> 0.25705108 | U11: =R11-(M11-J11-I11)+(Q11-$BS$19)*D11*0.03 -> 201671.86 | V11: =IFERROR(U11/R11,0) -> 0.31668482 | X11: {=SUM([6]Hoja3!$I$5:$I$19*([6]Hoja3!$F$5:$F$19=X$5)*([6]Hoja3!$K$5:$K$19=$C11))} -> 0 | Y11: {=SUM([6]Hoja3!$J$5:$J$19*([6]Hoja3!$F$5:$F$19=X$5)*([6]Hoja3!$K$5:$K$19=$C11))} -> 0 | Z11: =IFERROR(Y11/X11,0) -> 0 | AA11: {=SUM([6]Hoja3!$I$5:$I$19*([6]Hoja3!$F$5:$F$19=AA$5)*([6]Hoja3!$K$5:$K$19=$C11))} -> 0 | AB11: {=SUM([6]Hoja3!$J$5:$J$19*([6]Hoja3!$F$5:$F$19=AA$5)*([6]Hoja3!$K$5:$K$19=$C11))} -> 0 | AC11: =IFERROR(AB11/AA11,0) -> 0 | AD11: {=SUM([6]Hoja3!$I$5:$I$19*([6]Hoja3!$F$5:$F$19=AD$5)*([6]Hoja3!$K$5:$K$19=$C11))} -> 108 | AE11: {=SUM([6]Hoja3!$J$5:$J$19*([6]Hoja3!$F$5:$F$19=AD$5)*([6]Hoja3!$K$5:$K$19=$C11))} -> 275400 | AF11: =IFERROR(AE11/AD11,0) -> 2550 | AG11: {=SUM([6]Hoja3!$I$5:$I$19*([6]Hoja3!$F$5:$F$19=AG$5)*([6]Hoja3!$K$5:$K$19=$C11))} -> 0 | AH11: {=SUM([6]Hoja3!$J$5:$J$19*([6]Hoja3!$F$5:$F$19=AG$5)*([6]Hoja3!$K$5:$K$19=$C11))} -> 0 | AI11: =IFERROR(AH11/AG11,0) -> 0 | AJ11: {=SUM([6]Hoja3!$I$5:$I$19*([6]Hoja3!$F$5:$F$19=AJ$5)*([6]Hoja3!$K$5:$K$19=$C11))} -> 0 | AK11: {=SUM([6]Hoja3!$J$5:$J$19*([6]Hoja3!$F$5:$F$19=AJ$5)*([6]Hoja3!$K$5:$K$19=$C11))} -> 0 | AL11: =IFERROR(AK11/AJ11,0) -> 0 | AM11: {=SUM([6]Hoja3!$I$5:$I$19*([6]Hoja3!$F$5:$F$19=AM$5)*([6]Hoja3!$K$5:$K$19=$C11))} -> 0 | AN11: {=SUM([6]Hoja3!$J$5:$J$19*([6]Hoja3!$F$5:$F$19=AM$5)*([6]Hoja3!$K$5:$K$19=$C11))} -> 0 | AO11: =IFERROR(AN11/AM11,0) -> 0 | AP11: {=SUM([6]Hoja3!$I$5:$I$19*([6]Hoja3!$F$5:$F$19=AP$5)*([6]Hoja3!$K$5:$K$19=$C11))} -> 0 | AQ11: {=SUM([6]Hoja3!$J$5:$J$19*([6]Hoja3!$F$5:$F$19=AP$5)*([6]Hoja3!$K$5:$K$19=$C11))} -> 0 | AR11: =IFERROR(AQ11/AP11,0) -> 0 | AS11: {=SUM([6]Hoja3!$I$5:$I$19*([6]Hoja3!$F$5:$F$19=AS$5)*([6]Hoja3!$K$5:$K$19=$C11))} -> 108 | AT11: {=SUM([6]Hoja3!$J$5:$J$19*([6]Hoja3!$F$5:$F$19=AS$5)*([6]Hoja3!$K$5:$K$19=$C11))} -> 299310 | AU11: =IFERROR(AT11/AS11,0) -> 2771.3889 | AV11: {=SUM([2]Hoja2!$I$6:$I$26*([2]Hoja2!$F$6:$F$26=AV$5)*([2]Hoja2!$K$6:$K$26=$C11))} -> 0 | AW11: {=SUM([2]Hoja2!$J$6:$J$26*([2]Hoja2!$F$6:$F$26=AV$5)*([2]Hoja2!$K$6:$K$26=$C11))} -> 0 | AX11: =IFERROR(AW11/AV11,0) -> 0 | AY11: {=SUM([2]Hoja2!$I$6:$I$26*([2]Hoja2!$F$6:$F$26=AY$5)*([2]Hoja2!$K$6:$K$26=$C11))} -> 0 | AZ11: {=SUM([2]Hoja2!$J$6:$J$26*([2]Hoja2!$F$6:$F$26=AY$5)*([2]Hoja2!$K$6:$K$26=$C11))} -> 0 | BA11: =IFERROR(AZ11/AY11,0) -> 0 | BB11: {=SUM([2]Hoja2!$I$6:$I$26*([2]Hoja2!$F$6:$F$26=BB$5)*([2]Hoja2!$K$6:$K$26=$C11))} -> 0 | BC11: {=SUM([2]Hoja2!$J$6:$J$26*([2]Hoja2!$F$6:$F$26=BB$5)*([2]Hoja2!$K$6:$K$26=$C11))} -> 0 | BD11: =IFERROR(BC11/BB11,0) -> 0 | BE11: {=SUM([2]Hoja2!$I$6:$I$26*([2]Hoja2!$F$6:$F$26=BE$5)*([2]Hoja2!$K$6:$K$26=$C11))} -> 0 | BF11: {=SUM([2]Hoja2!$J$6:$J$26*([2]Hoja2!$F$6:$F$26=BE$5)*([2]Hoja2!$K$6:$K$26=$C11))} -> 0 | BG11: =IFERROR(BF11/BE11,0) -> 0 | BH11: {=SUM([2]Hoja2!$I$6:$I$26*([2]Hoja2!$F$6:$F$26=BH$5)*([2]Hoja2!$K$6:$K$26=$C11))} -> 0 | BI11: {=SUM([2]Hoja2!$J$6:$J$26*([2]Hoja2!$F$6:$F$26=BH$5)*([2]Hoja2!$K$6:$K$26=$C11))} -> 0 | BJ11: =IFERROR(BI11/BH11,0) -> 0 | BK11: {=SUM([2]Hoja2!$I$6:$I$26*([2]Hoja2!$F$6:$F$26=BK$5)*([2]Hoja2!$K$6:$K$26=$C11))} -> 0 | BL11: {=SUM([2]Hoja2!$J$6:$J$26*([2]Hoja2!$F$6:$F$26=BK$5)*([2]Hoja2!$K$6:$K$26=$C11))} -> 0 | BM11: =IFERROR(BL11/BK11,0) -> 0 | BN11: =X11+AA11+AD11+AG11+AJ11+AM11+AP11+AS11 -> 216 | BO11: =Y11+AB11+AE11+AH11+AK11+AN11+AQ11+AT11 -> 574710 | BP11: =IFERROR(BO11/BN11,0) -> 2660.6944 | BQ11: =-IFERROR(F11/D11*BN11,0) -> -375990.72 | BR11: =-207.84*BN11 -> -44893.44 | BS11: =$BS$18/$BN$18*$BN11 -> -21216.33 | BT11: =$BT$18/$BN$18*$BN11 -> -41707.71 | BU11: =$BU$18/$BN$18*$BN11 -> -33340.775 | BV11: =(BO11-BN11*$BS$19)*0.03 -> 16501.429 | BW11: =BO11+SUM(BQ11:BT11,BV11) -> 107403.23 | BX11: =IFERROR(BW11/BO11,0) -> 0.18688248 | BY11: =BO11+BQ11+BR11+BS11+BV11-BU11 -> 182451.71 | BZ11: =IFERROR(BY11/BO11,0) -> 0.31746744 | CB11: =BP11 -> 2660.6944 | CC11: =IFERROR(BQ11/$BN11,0) -> -1740.6978 | CD11: =IFERROR(BR11/$BN11,0) -> -207.84 | CE11: =IFERROR(BS11/$BN11,0) -> -98.22375 | CF11: =IFERROR(BT11/$BN11,0) -> -193.09125 | CG11: =IFERROR(BU11/$BN11,0) -> -154.35544 | CH11: =IFERROR(BV11/$BN11,0) -> 76.395505 | CI11: =IFERROR(BW11/$BN11,0) -> 497.23718 | CJ11: =IFERROR(BY11/$BN11,0) -> 844.68386 | CK11: =CJ11-CI11 -> 347.44669
B12: 10007567 | C12: POTA REPRODUCTORES | D12: =TD!F9 -> 107.14 | E12: =IFERROR(F12/D12,0) -> 1682.6592 | F12: =TD!G9 -> 180280.11 | G12: =TD!H9 -> 22267.978 | H12: =TD!I9 -> 4876.8099 | I12: =TD!J9 -> 9586.9821 | J12: =TD!K9 -> 7663.7487 | K12: 0 | L12: 0 | M12: =F12+G12+H12+I12 -> 217011.88 | N12: =IFERROR(M12/D12,0) -> 2025.4982 | O12: =F12+G12+H12-J12 -> 199761.15 | P12: =IFERROR(O12/D12,0) -> 1864.4871 | Q12: 2730 | R12: =Q12*D12 -> 292492.2 | S12: =R12-M12+(Q12-$BS$19)*D12*0.03 -> 83888.099 | T12: =IFERROR(S12/R12,0) -> 0.28680457 | U12: =R12-(M12-J12-I12)+(Q12-$BS$19)*D12*0.03 -> 101138.83 | V12: =IFERROR(U12/R12,0) -> 0.345783 | X12: {=SUM([6]Hoja3!$I$5:$I$19*([6]Hoja3!$F$5:$F$19=X$5)*([6]Hoja3!$K$5:$K$19=$C12))} -> 0 | Y12: {=SUM([6]Hoja3!$J$5:$J$19*([6]Hoja3!$F$5:$F$19=X$5)*([6]Hoja3!$K$5:$K$19=$C12))} -> 0 | Z12: =IFERROR(Y12/X12,0) -> 0 | AA12: {=SUM([6]Hoja3!$I$5:$I$19*([6]Hoja3!$F$5:$F$19=AA$5)*([6]Hoja3!$K$5:$K$19=$C12))} -> 26 | AB12: {=SUM([6]Hoja3!$J$5:$J$19*([6]Hoja3!$F$5:$F$19=AA$5)*([6]Hoja3!$K$5:$K$19=$C12))} -> 74100 | AC12: =IFERROR(AB12/AA12,0) -> 2850 | AD12: {=SUM([6]Hoja3!$I$5:$I$19*([6]Hoja3!$F$5:$F$19=AD$5)*([6]Hoja3!$K$5:$K$19=$C12))} -> 0 | AE12: {=SUM([6]Hoja3!$J$5:$J$19*([6]Hoja3!$F$5:$F$19=AD$5)*([6]Hoja3!$K$5:$K$19=$C12))} -> 0 | AF12: =IFERROR(AE12/AD12,0) -> 0 | AG12: {=SUM([6]Hoja3!$I$5:$I$19*([6]Hoja3!$F$5:$F$19=AG$5)*([6]Hoja3!$K$5:$K$19=$C12))} -> 27 | AH12: {=SUM([6]Hoja3!$J$5:$J$19*([6]Hoja3!$F$5:$F$19=AG$5)*([6]Hoja3!$K$5:$K$19=$C12))} -> 73710 | AI12: =IFERROR(AH12/AG12,0) -> 2730 | AJ12: {=SUM([6]Hoja3!$I$5:$I$19*([6]Hoja3!$F$5:$F$19=AJ$5)*([6]Hoja3!$K$5:$K$19=$C12))} -> 0 | AK12: {=SUM([6]Hoja3!$J$5:$J$19*([6]Hoja3!$F$5:$F$19=AJ$5)*([6]Hoja3!$K$5:$K$19=$C12))} -> 0 | AL12: =IFERROR(AK12/AJ12,0) -> 0 | AM12: {=SUM([6]Hoja3!$I$5:$I$19*([6]Hoja3!$F$5:$F$19=AM$5)*([6]Hoja3!$K$5:$K$19=$C12))} -> 0 | AN12: {=SUM([6]Hoja3!$J$5:$J$19*([6]Hoja3!$F$5:$F$19=AM$5)*([6]Hoja3!$K$5:$K$19=$C12))} -> 0 | AO12: =IFERROR(AN12/AM12,0) -> 0 | AP12: {=SUM([6]Hoja3!$I$5:$I$19*([6]Hoja3!$F$5:$F$19=AP$5)*([6]Hoja3!$K$5:$K$19=$C12))} -> 0 | AQ12: {=SUM([6]Hoja3!$J$5:$J$19*([6]Hoja3!$F$5:$F$19=AP$5)*([6]Hoja3!$K$5:$K$19=$C12))} -> 0 | AR12: =IFERROR(AQ12/AP12,0) -> 0 | AS12: {=SUM([6]Hoja3!$I$5:$I$19*([6]Hoja3!$F$5:$F$19=AS$5)*([6]Hoja3!$K$5:$K$19=$C12))} -> 0 | AT12: {=SUM([6]Hoja3!$J$5:$J$19*([6]Hoja3!$F$5:$F$19=AS$5)*([6]Hoja3!$K$5:$K$19=$C12))} -> 0 | AU12: =IFERROR(AT12/AS12,0) -> 0 | AV12: {=SUM([2]Hoja2!$I$6:$I$26*([2]Hoja2!$F$6:$F$26=AV$5)*([2]Hoja2!$K$6:$K$26=$C12))} -> 0 | AW12: {=SUM([2]Hoja2!$J$6:$J$26*([2]Hoja2!$F$6:$F$26=AV$5)*([2]Hoja2!$K$6:$K$26=$C12))} -> 0 | AX12: =IFERROR(AW12/AV12,0) -> 0 | AY12: {=SUM([2]Hoja2!$I$6:$I$26*([2]Hoja2!$F$6:$F$26=AY$5)*([2]Hoja2!$K$6:$K$26=$C12))} -> 0 | AZ12: {=SUM([2]Hoja2!$J$6:$J$26*([2]Hoja2!$F$6:$F$26=AY$5)*([2]Hoja2!$K$6:$K$26=$C12))} -> 0 | BA12: =IFERROR(AZ12/AY12,0) -> 0 | BB12: {=SUM([2]Hoja2!$I$6:$I$26*([2]Hoja2!$F$6:$F$26=BB$5)*([2]Hoja2!$K$6:$K$26=$C12))} -> 0 | BC12: {=SUM([2]Hoja2!$J$6:$J$26*([2]Hoja2!$F$6:$F$26=BB$5)*([2]Hoja2!$K$6:$K$26=$C12))} -> 0 | BD12: =IFERROR(BC12/BB12,0) -> 0 | BE12: {=SUM([2]Hoja2!$I$6:$I$26*([2]Hoja2!$F$6:$F$26=BE$5)*([2]Hoja2!$K$6:$K$26=$C12))} -> 0 | BF12: {=SUM([2]Hoja2!$J$6:$J$26*([2]Hoja2!$F$6:$F$26=BE$5)*([2]Hoja2!$K$6:$K$26=$C12))} -> 0 | BG12: =IFERROR(BF12/BE12,0) -> 0 | BH12: {=SUM([2]Hoja2!$I$6:$I$26*([2]Hoja2!$F$6:$F$26=BH$5)*([2]Hoja2!$K$6:$K$26=$C12))} -> 0 | BI12: {=SUM([2]Hoja2!$J$6:$J$26*([2]Hoja2!$F$6:$F$26=BH$5)*([2]Hoja2!$K$6:$K$26=$C12))} -> 0 | BJ12: =IFERROR(BI12/BH12,0) -> 0 | BK12: {=SUM([2]Hoja2!$I$6:$I$26*([2]Hoja2!$F$6:$F$26=BK$5)*([2]Hoja2!$K$6:$K$26=$C12))} -> 0 | BL12: {=SUM([2]Hoja2!$J$6:$J$26*([2]Hoja2!$F$6:$F$26=BK$5)*([2]Hoja2!$K$6:$K$26=$C12))} -> 0 | BM12: =IFERROR(BL12/BK12,0) -> 0 | BN12: =X12+AA12+AD12+AG12+AJ12+AM12+AP12+AS12 -> 53 | BO12: =Y12+AB12+AE12+AH12+AK12+AN12+AQ12+AT12 -> 147810 | BP12: =IFERROR(BO12/BN12,0) -> 2788.8679 | BQ12: =-IFERROR(F12/D12*BN12,0) -> -89180.938 | BR12: =-207.84*BN12 -> -11015.52 | BS12: =$BS$18/$BN$18*$BN12 -> -5205.8588 | BT12: =$BT$18/$BN$18*$BN12 -> -10233.836 | BU12: =$BU$18/$BN$18*$BN12 -> -8180.8382 | BV12: =(BO12-BN12*$BS$19)*0.03 -> 4252.7576 | BW12: =BO12+SUM(BQ12:BT12,BV12) -> 36426.605 | BX12: =IFERROR(BW12/BO12,0) -> 0.24644209 | BY12: =BO12+BQ12+BR12+BS12+BV12-BU12 -> 54841.279 | BZ12: =IFERROR(BY12/BO12,0) -> 0.3710255 | CB12: =BP12 -> 2788.8679 | CC12: =IFERROR(BQ12/$BN12,0) -> -1682.6592 | CD12: =IFERROR(BR12/$BN12,0) -> -207.84 | CE12: =IFERROR(BS12/$BN12,0) -> -98.22375 | CF12: =IFERROR(BT12/$BN12,0) -> -193.09125 | CG12: =IFERROR(BU12/$BN12,0) -> -154.35544 | CH12: =IFERROR(BV12/$BN12,0) -> 80.240709 | CI12: =IFERROR(BW12/$BN12,0) -> 687.29443 | CJ12: =IFERROR(BY12/$BN12,0) -> 1034.7411 | CK12: =CJ12-CI12 -> 347.44669
B13: 10007969 | C13: POTA CONOS | D13: =TD!F10 -> 15.82 | E13: =IFERROR(F13/D13,0) -> 1368.5038 | F13: =TD!G10 -> 21649.73 | G13: =TD!H10 -> 3288.0288 | H13: =TD!I10 -> 720.09645 | I13: =TD!J10 -> 1415.5876 | J13: =TD!K10 -> 1131.6082 | K13: 0 | L13: 0 | M13: =F13+G13+H13+I13 -> 27073.443 | N13: =IFERROR(M13/D13,0) -> 1711.3428 | O13: =F13+G13+H13-J13 -> 24526.247 | P13: =IFERROR(O13/D13,0) -> 1550.3317 | Q13: 1600 | R13: =Q13*D13 -> 25312 | S13: =R13-M13+(Q13-$BS$19)*D13*0.03 -> -1056.2719 | T13: =IFERROR(S13/R13,0) -> -0.041730084 | U13: =R13-(M13-J13-I13)+(Q13-$BS$19)*D13*0.03 -> 1490.9239 | V13: =IFERROR(U13/R13,0) -> 0.058901862 | X13: {=SUM([6]Hoja3!$I$5:$I$19*([6]Hoja3!$F$5:$F$19=X$5)*([6]Hoja3!$K$5:$K$19=$C13))} -> 0 | Y13: {=SUM([6]Hoja3!$J$5:$J$19*([6]Hoja3!$F$5:$F$19=X$5)*([6]Hoja3!$K$5:$K$19=$C13))} -> 0 | Z13: =IFERROR(Y13/X13,0) -> 0 | AA13: {=SUM([6]Hoja3!$I$5:$I$19*([6]Hoja3!$F$5:$F$19=AA$5)*([6]Hoja3!$K$5:$K$19=$C13))} -> 0 | AB13: {=SUM([6]Hoja3!$J$5:$J$19*([6]Hoja3!$F$5:$F$19=AA$5)*([6]Hoja3!$K$5:$K$19=$C13))} -> 0 | AC13: =IFERROR(AB13/AA13,0) -> 0 | AD13: {=SUM([6]Hoja3!$I$5:$I$19*([6]Hoja3!$F$5:$F$19=AD$5)*([6]Hoja3!$K$5:$K$19=$C13))} -> 54 | AE13: {=SUM([6]Hoja3!$J$5:$J$19*([6]Hoja3!$F$5:$F$19=AD$5)*([6]Hoja3!$K$5:$K$19=$C13))} -> 86400 | AF13: =IFERROR(AE13/AD13,0) -> 1600 | AG13: {=SUM([6]Hoja3!$I$5:$I$19*([6]Hoja3!$F$5:$F$19=AG$5)*([6]Hoja3!$K$5:$K$19=$C13))} -> 0 | AH13: {=SUM([6]Hoja3!$J$5:$J$19*([6]Hoja3!$F$5:$F$19=AG$5)*([6]Hoja3!$K$5:$K$19=$C13))} -> 0 | AI13: =IFERROR(AH13/AG13,0) -> 0 | AJ13: {=SUM([6]Hoja3!$I$5:$I$19*([6]Hoja3!$F$5:$F$19=AJ$5)*([6]Hoja3!$K$5:$K$19=$C13))} -> 0 | AK13: {=SUM([6]Hoja3!$J$5:$J$19*([6]Hoja3!$F$5:$F$19=AJ$5)*([6]Hoja3!$K$5:$K$19=$C13))} -> 0 | AL13: =IFERROR(AK13/AJ13,0) -> 0 | AM13: {=SUM([6]Hoja3!$I$5:$I$19*([6]Hoja3!$F$5:$F$19=AM$5)*([6]Hoja3!$K$5:$K$19=$C13))} -> 0 | AN13: {=SUM([6]Hoja3!$J$5:$J$19*([6]Hoja3!$F$5:$F$19=AM$5)*([6]Hoja3!$K$5:$K$19=$C13))} -> 0 | AO13: =IFERROR(AN13/AM13,0) -> 0 | AP13: {=SUM([6]Hoja3!$I$5:$I$19*([6]Hoja3!$F$5:$F$19=AP$5)*([6]Hoja3!$K$5:$K$19=$C13))} -> 0 | AQ13: {=SUM([6]Hoja3!$J$5:$J$19*([6]Hoja3!$F$5:$F$19=AP$5)*([6]Hoja3!$K$5:$K$19=$C13))} -> 0 | AR13: =IFERROR(AQ13/AP13,0) -> 0 | AS13: {=SUM([6]Hoja3!$I$5:$I$19*([6]Hoja3!$F$5:$F$19=AS$5)*([6]Hoja3!$K$5:$K$19=$C13))} -> 0 | AT13: {=SUM([6]Hoja3!$J$5:$J$19*([6]Hoja3!$F$5:$F$19=AS$5)*([6]Hoja3!$K$5:$K$19=$C13))} -> 0 | AU13: =IFERROR(AT13/AS13,0) -> 0 | AV13: {=SUM([2]Hoja2!$I$6:$I$26*([2]Hoja2!$F$6:$F$26=AV$5)*([2]Hoja2!$K$6:$K$26=$C13))} -> 0 | AW13: {=SUM([2]Hoja2!$J$6:$J$26*([2]Hoja2!$F$6:$F$26=AV$5)*([2]Hoja2!$K$6:$K$26=$C13))} -> 0 | AX13: =IFERROR(AW13/AV13,0) -> 0 | AY13: {=SUM([2]Hoja2!$I$6:$I$26*([2]Hoja2!$F$6:$F$26=AY$5)*([2]Hoja2!$K$6:$K$26=$C13))} -> 0 | AZ13: {=SUM([2]Hoja2!$J$6:$J$26*([2]Hoja2!$F$6:$F$26=AY$5)*([2]Hoja2!$K$6:$K$26=$C13))} -> 0 | BA13: =IFERROR(AZ13/AY13,0) -> 0 | BB13: {=SUM([2]Hoja2!$I$6:$I$26*([2]Hoja2!$F$6:$F$26=BB$5)*([2]Hoja2!$K$6:$K$26=$C13))} -> 0 | BC13: {=SUM([2]Hoja2!$J$6:$J$26*([2]Hoja2!$F$6:$F$26=BB$5)*([2]Hoja2!$K$6:$K$26=$C13))} -> 0 | BD13: =IFERROR(BC13/BB13,0) -> 0 | BE13: {=SUM([2]Hoja2!$I$6:$I$26*([2]Hoja2!$F$6:$F$26=BE$5)*([2]Hoja2!$K$6:$K$26=$C13))} -> 0 | BF13: {=SUM([2]Hoja2!$J$6:$J$26*([2]Hoja2!$F$6:$F$26=BE$5)*([2]Hoja2!$K$6:$K$26=$C13))} -> 0 | BG13: =IFERROR(BF13/BE13,0) -> 0 | BH13: {=SUM([2]Hoja2!$I$6:$I$26*([2]Hoja2!$F$6:$F$26=BH$5)*([2]Hoja2!$K$6:$K$26=$C13))} -> 0 | BI13: {=SUM([2]Hoja2!$J$6:$J$26*([2]Hoja2!$F$6:$F$26=BH$5)*([2]Hoja2!$K$6:$K$26=$C13))} -> 0 | BJ13: =IFERROR(BI13/BH13,0) -> 0 | BK13: {=SUM([2]Hoja2!$I$6:$I$26*([2]Hoja2!$F$6:$F$26=BK$5)*([2]Hoja2!$K$6:$K$26=$C13))} -> 0 | BL13: {=SUM([2]Hoja2!$J$6:$J$26*([2]Hoja2!$F$6:$F$26=BK$5)*([2]Hoja2!$K$6:$K$26=$C13))} -> 0 | BM13: =IFERROR(BL13/BK13,0) -> 0 | BN13: =X13+AA13+AD13+AG13+AJ13+AM13+AP13+AS13 -> 54 | BO13: =Y13+AB13+AE13+AH13+AK13+AN13+AQ13+AT13 -> 86400 | BP13: =IFERROR(BO13/BN13,0) -> 1600 | BQ13: =-IFERROR(F13/D13*BN13,0) -> -73899.206 | BR13: =-207.84*BN13 -> -11223.36 | BS13: =$BS$18/$BN$18*$BN13 -> -5304.0825 | BT13: =$BT$18/$BN$18*$BN13 -> -10426.928 | BU13: =$BU$18/$BN$18*$BN13 -> -8335.1936 | BV13: =(BO13-BN13*$BS$19)*0.03 -> 2407.0323 | BW13: =BO13+SUM(BQ13:BT13,BV13) -> -12046.544 | BX13: =IFERROR(BW13/BO13,0) -> -0.13942759 | BY13: =BO13+BQ13+BR13+BS13+BV13-BU13 -> 6715.5774 | BZ13: =IFERROR(BY13/BO13,0) -> 0.07772659 | CB13: =BP13 -> 1600 | CC13: =IFERROR(BQ13/$BN13,0) -> -1368.5038 | CD13: =IFERROR(BR13/$BN13,0) -> -207.84 | CE13: =IFERROR(BS13/$BN13,0) -> -98.22375 | CF13: =IFERROR(BT13/$BN13,0) -> -193.09125 | CG13: =IFERROR(BU13/$BN13,0) -> -154.35544 | CH13: =IFERROR(BV13/$BN13,0) -> 44.574672 | CI13: =IFERROR(BW13/$BN13,0) -> -223.08414 | CJ13: =IFERROR(BY13/$BN13,0) -> 124.36254 | CK13: =CJ13-CI13 -> 347.44669
B14: 10009239 | C14: POTA FILETE DARUMA | D14: =TD!F11 -> 40.66 | E14: =IFERROR(F14/D14,0) -> 3254.8777 | F14: =TD!G11 -> 132343.33 | G14: =TD!H11 -> 8450.7744 | H14: =TD!I11 -> 1850.7662 | I14: =TD!J11 -> 3638.2928 | J14: =TD!K11 -> 2908.4191 | K14: 0 | L14: 0 | M14: =F14+G14+H14+I14 -> 146283.16 | N14: =IFERROR(M14/D14,0) -> 3597.7167 | O14: =F14+G14+H14-J14 -> 139736.45 | P14: =IFERROR(O14/D14,0) -> 3436.7056 | Q14: 3900 | R14: =Q14*D14 -> 158574 | S14: =R14-M14+(Q14-$BS$19)*D14*0.03 -> 16908.784 | T14: =IFERROR(S14/R14,0) -> 0.10663024 | U14: =R14-(M14-J14-I14)+(Q14-$BS$19)*D14*0.03 -> 23455.496 | V14: =IFERROR(U14/R14,0) -> 0.14791514 | X14: {=SUM([6]Hoja3!$I$5:$I$19*([6]Hoja3!$F$5:$F$19=X$5)*([6]Hoja3!$K$5:$K$19=$C14))} -> 0 | Y14: {=SUM([6]Hoja3!$J$5:$J$19*([6]Hoja3!$F$5:$F$19=X$5)*([6]Hoja3!$K$5:$K$19=$C14))} -> 0 | Z14: =IFERROR(Y14/X14,0) -> 0 | AA14: {=SUM([6]Hoja3!$I$5:$I$19*([6]Hoja3!$F$5:$F$19=AA$5)*([6]Hoja3!$K$5:$K$19=$C14))} -> 0 | AB14: {=SUM([6]Hoja3!$J$5:$J$19*([6]Hoja3!$F$5:$F$19=AA$5)*([6]Hoja3!$K$5:$K$19=$C14))} -> 0 | AC14: =IFERROR(AB14/AA14,0) -> 0 | AD14: {=SUM([6]Hoja3!$I$5:$I$19*([6]Hoja3!$F$5:$F$19=AD$5)*([6]Hoja3!$K$5:$K$19=$C14))} -> 0 | AE14: {=SUM([6]Hoja3!$J$5:$J$19*([6]Hoja3!$F$5:$F$19=AD$5)*([6]Hoja3!$K$5:$K$19=$C14))} -> 0 | AF14: =IFERROR(AE14/AD14,0) -> 0 | AG14: {=SUM([6]Hoja3!$I$5:$I$19*([6]Hoja3!$F$5:$F$19=AG$5)*([6]Hoja3!$K$5:$K$19=$C14))} -> 0 | AH14: {=SUM([6]Hoja3!$J$5:$J$19*([6]Hoja3!$F$5:$F$19=AG$5)*([6]Hoja3!$K$5:$K$19=$C14))} -> 0 | AI14: =IFERROR(AH14/AG14,0) -> 0 | AJ14: {=SUM([6]Hoja3!$I$5:$I$19*([6]Hoja3!$F$5:$F$19=AJ$5)*([6]Hoja3!$K$5:$K$19=$C14))} -> 0 | AK14: {=SUM([6]Hoja3!$J$5:$J$19*([6]Hoja3!$F$5:$F$19=AJ$5)*([6]Hoja3!$K$5:$K$19=$C14))} -> 0 | AL14: =IFERROR(AK14/AJ14,0) -> 0 | AM14: {=SUM([6]Hoja3!$I$5:$I$19*([6]Hoja3!$F$5:$F$19=AM$5)*([6]Hoja3!$K$5:$K$19=$C14))} -> 0 | AN14: {=SUM([6]Hoja3!$J$5:$J$19*([6]Hoja3!$F$5:$F$19=AM$5)*([6]Hoja3!$K$5:$K$19=$C14))} -> 0 | AO14: =IFERROR(AN14/AM14,0) -> 0 | AP14: {=SUM([6]Hoja3!$I$5:$I$19*([6]Hoja3!$F$5:$F$19=AP$5)*([6]Hoja3!$K$5:$K$19=$C14))} -> 0 | AQ14: {=SUM([6]Hoja3!$J$5:$J$19*([6]Hoja3!$F$5:$F$19=AP$5)*([6]Hoja3!$K$5:$K$19=$C14))} -> 0 | AR14: =IFERROR(AQ14/AP14,0) -> 0 | AS14: {=SUM([6]Hoja3!$I$5:$I$19*([6]Hoja3!$F$5:$F$19=AS$5)*([6]Hoja3!$K$5:$K$19=$C14))} -> 162 | AT14: {=SUM([6]Hoja3!$J$5:$J$19*([6]Hoja3!$F$5:$F$19=AS$5)*([6]Hoja3!$K$5:$K$19=$C14))} -> 550800 | AU14: =IFERROR(AT14/AS14,0) -> 3400 | AV14: {=SUM([2]Hoja2!$I$6:$I$26*([2]Hoja2!$F$6:$F$26=AV$5)*([2]Hoja2!$K$6:$K$26=$C14))} -> 0 | AW14: {=SUM([2]Hoja2!$J$6:$J$26*([2]Hoja2!$F$6:$F$26=AV$5)*([2]Hoja2!$K$6:$K$26=$C14))} -> 0 | AX14: =IFERROR(AW14/AV14,0) -> 0 | AY14: {=SUM([2]Hoja2!$I$6:$I$26*([2]Hoja2!$F$6:$F$26=AY$5)*([2]Hoja2!$K$6:$K$26=$C14))} -> 0 | AZ14: {=SUM([2]Hoja2!$J$6:$J$26*([2]Hoja2!$F$6:$F$26=AY$5)*([2]Hoja2!$K$6:$K$26=$C14))} -> 0 | BA14: =IFERROR(AZ14/AY14,0) -> 0 | BB14: {=SUM([2]Hoja2!$I$6:$I$26*([2]Hoja2!$F$6:$F$26=BB$5)*([2]Hoja2!$K$6:$K$26=$C14))} -> 0 | BC14: {=SUM([2]Hoja2!$J$6:$J$26*([2]Hoja2!$F$6:$F$26=BB$5)*([2]Hoja2!$K$6:$K$26=$C14))} -> 0 | BD14: =IFERROR(BC14/BB14,0) -> 0 | BE14: {=SUM([2]Hoja2!$I$6:$I$26*([2]Hoja2!$F$6:$F$26=BE$5)*([2]Hoja2!$K$6:$K$26=$C14))} -> 0 | BF14: {=SUM([2]Hoja2!$J$6:$J$26*([2]Hoja2!$F$6:$F$26=BE$5)*([2]Hoja2!$K$6:$K$26=$C14))} -> 0 | BG14: =IFERROR(BF14/BE14,0) -> 0 | BH14: {=SUM([2]Hoja2!$I$6:$I$26*([2]Hoja2!$F$6:$F$26=BH$5)*([2]Hoja2!$K$6:$K$26=$C14))} -> 0 | BI14: {=SUM([2]Hoja2!$J$6:$J$26*([2]Hoja2!$F$6:$F$26=BH$5)*([2]Hoja2!$K$6:$K$26=$C14))} -> 0 | BJ14: =IFERROR(BI14/BH14,0) -> 0 | BK14: {=SUM([2]Hoja2!$I$6:$I$26*([2]Hoja2!$F$6:$F$26=BK$5)*([2]Hoja2!$K$6:$K$26=$C14))} -> 0 | BL14: {=SUM([2]Hoja2!$J$6:$J$26*([2]Hoja2!$F$6:$F$26=BK$5)*([2]Hoja2!$K$6:$K$26=$C14))} -> 0 | BM14: =IFERROR(BL14/BK14,0) -> 0 | BN14: =X14+AA14+AD14+AG14+AJ14+AM14+AP14+AS14 -> 162 | BO14: =Y14+AB14+AE14+AH14+AK14+AN14+AQ14+AT14 -> 550800 | BP14: =IFERROR(BO14/BN14,0) -> 3400 | BQ14: =-BN14*'[3]Stock Libre'!H36*1000 -> -527290.19 | BR14: =-207.84*BN14 -> -33670.08 | BS14: =$BS$18/$BN$18*$BN14 -> -15912.248 | BT14: =$BT$18/$BN$18*$BN14 -> -31280.783 | BU14: =$BU$18/$BN$18*$BN14 -> -25005.581 | BV14: =(BO14-BN14*$BS$19)*0.03 -> 15969.097 | BW14: =BO14+SUM(BQ14:BT14,BV14) -> -41384.208 | BX14: =IFERROR(BW14/BO14,0) -> -0.075134727 | BY14: =BO14+BQ14+BR14+BS14+BV14-BU14 -> 14902.156 | BZ14: =IFERROR(BY14/BO14,0) -> 0.027055475 | CB14: =BP14 -> 3400 | CC14: =IFERROR(BQ14/$BN14,0) -> -3254.8777 | CD14: =IFERROR(BR14/$BN14,0) -> -207.84 | CE14: =IFERROR(BS14/$BN14,0) -> -98.22375 | CF14: =IFERROR(BT14/$BN14,0) -> -193.09125 | CG14: =IFERROR(BU14/$BN14,0) -> -154.35544 | CH14: =IFERROR(BV14/$BN14,0) -> 98.574672 | CI14: =IFERROR(BW14/$BN14,0) -> -255.45807 | CJ14: =IFERROR(BY14/$BN14,0) -> 91.988614 | CK14: =CJ14-CI14 -> 347.44669
B15: 10009334 | C15: POTA ALAS COCIDAS | D15: =TD!F12 -> 32.788 | E15: =IFERROR(F15/D15,0) -> 2824.4285 | F15: =TD!G12 -> 92607.362 | G15: =TD!H12 -> 6814.6579 | H15: =TD!I12 -> 1492.4477 | I15: =TD!J12 -> 2933.8993 | J15: =TD!K12 -> 2345.3331 | K15: 0 | L15: 0 | M15: =F15+G15+H15+I15 -> 103848.37 | N15: =IFERROR(M15/D15,0) -> 3167.2675 | O15: =F15+G15+H15-J15 -> 98569.135 | P15: =IFERROR(O15/D15,0) -> 3006.2564 | Q15: 3900 | R15: =Q15*D15 -> 127873.2 | S15: =R15-M15+(Q15-$BS$19)*D15*0.03 -> 27748.719 | T15: =IFERROR(S15/R15,0) -> 0.21700184 | U15: =R15-(M15-J15-I15)+(Q15-$BS$19)*D15*0.03 -> 33027.952 | V15: =IFERROR(U15/R15,0) -> 0.25828674 | X15: {=SUM([6]Hoja3!$I$5:$I$19*([6]Hoja3!$F$5:$F$19=X$5)*([6]Hoja3!$K$5:$K$19=$C15))} -> 0 | Y15: {=SUM([6]Hoja3!$J$5:$J$19*([6]Hoja3!$F$5:$F$19=X$5)*([6]Hoja3!$K$5:$K$19=$C15))} -> 0 | Z15: =IFERROR(Y15/X15,0) -> 0 | AA15: {=SUM([6]Hoja3!$I$5:$I$19*([6]Hoja3!$F$5:$F$19=AA$5)*([6]Hoja3!$K$5:$K$19=$C15))} -> 0 | AB15: {=SUM([6]Hoja3!$J$5:$J$19*([6]Hoja3!$F$5:$F$19=AA$5)*([6]Hoja3!$K$5:$K$19=$C15))} -> 0 | AC15: =IFERROR(AB15/AA15,0) -> 0 | AD15: {=SUM([6]Hoja3!$I$5:$I$19*([6]Hoja3!$F$5:$F$19=AD$5)*([6]Hoja3!$K$5:$K$19=$C15))} -> 0 | AE15: {=SUM([6]Hoja3!$J$5:$J$19*([6]Hoja3!$F$5:$F$19=AD$5)*([6]Hoja3!$K$5:$K$19=$C15))} -> 0 | AF15: =IFERROR(AE15/AD15,0) -> 0 | AG15: {=SUM([6]Hoja3!$I$5:$I$19*([6]Hoja3!$F$5:$F$19=AG$5)*([6]Hoja3!$K$5:$K$19=$C15))} -> 0 | AH15: {=SUM([6]Hoja3!$J$5:$J$19*([6]Hoja3!$F$5:$F$19=AG$5)*([6]Hoja3!$K$5:$K$19=$C15))} -> 0 | AI15: =IFERROR(AH15/AG15,0) -> 0 | AJ15: {=SUM([6]Hoja3!$I$5:$I$19*([6]Hoja3!$F$5:$F$19=AJ$5)*([6]Hoja3!$K$5:$K$19=$C15))} -> 0 | AK15: {=SUM([6]Hoja3!$J$5:$J$19*([6]Hoja3!$F$5:$F$19=AJ$5)*([6]Hoja3!$K$5:$K$19=$C15))} -> 0 | AL15: =IFERROR(AK15/AJ15,0) -> 0 | AM15: {=SUM([6]Hoja3!$I$5:$I$19*([6]Hoja3!$F$5:$F$19=AM$5)*([6]Hoja3!$K$5:$K$19=$C15))} -> 0 | AN15: {=SUM([6]Hoja3!$J$5:$J$19*([6]Hoja3!$F$5:$F$19=AM$5)*([6]Hoja3!$K$5:$K$19=$C15))} -> 0 | AO15: =IFERROR(AN15/AM15,0) -> 0 | AP15: {=SUM([6]Hoja3!$I$5:$I$19*([6]Hoja3!$F$5:$F$19=AP$5)*([6]Hoja3!$K$5:$K$19=$C15))} -> 0 | AQ15: {=SUM([6]Hoja3!$J$5:$J$19*([6]Hoja3!$F$5:$F$19=AP$5)*([6]Hoja3!$K$5:$K$19=$C15))} -> 0 | AR15: =IFERROR(AQ15/AP15,0) -> 0 | AS15: {=SUM([6]Hoja3!$I$5:$I$19*([6]Hoja3!$F$5:$F$19=AS$5)*([6]Hoja3!$K$5:$K$19=$C15))} -> 0 | AT15: {=SUM([6]Hoja3!$J$5:$J$19*([6]Hoja3!$F$5:$F$19=AS$5)*([6]Hoja3!$K$5:$K$19=$C15))} -> 0 | AU15: =IFERROR(AT15/AS15,0) -> 0 | AV15: {=SUM([2]Hoja2!$I$6:$I$26*([2]Hoja2!$F$6:$F$26=AV$5)*([2]Hoja2!$K$6:$K$26=$C15))} -> 0 | AW15: {=SUM([2]Hoja2!$J$6:$J$26*([2]Hoja2!$F$6:$F$26=AV$5)*([2]Hoja2!$K$6:$K$26=$C15))} -> 0 | AX15: =IFERROR(AW15/AV15,0) -> 0 | AY15: {=SUM([2]Hoja2!$I$6:$I$26*([2]Hoja2!$F$6:$F$26=AY$5)*([2]Hoja2!$K$6:$K$26=$C15))} -> 0 | AZ15: {=SUM([2]Hoja2!$J$6:$J$26*([2]Hoja2!$F$6:$F$26=AY$5)*([2]Hoja2!$K$6:$K$26=$C15))} -> 0 | BA15: =IFERROR(AZ15/AY15,0) -> 0 | BB15: {=SUM([2]Hoja2!$I$6:$I$26*([2]Hoja2!$F$6:$F$26=BB$5)*([2]Hoja2!$K$6:$K$26=$C15))} -> 0 | BC15: {=SUM([2]Hoja2!$J$6:$J$26*([2]Hoja2!$F$6:$F$26=BB$5)*([2]Hoja2!$K$6:$K$26=$C15))} -> 0 | BD15: =IFERROR(BC15/BB15,0) -> 0 | BE15: {=SUM([2]Hoja2!$I$6:$I$26*([2]Hoja2!$F$6:$F$26=BE$5)*([2]Hoja2!$K$6:$K$26=$C15))} -> 0 | BF15: {=SUM([2]Hoja2!$J$6:$J$26*([2]Hoja2!$F$6:$F$26=BE$5)*([2]Hoja2!$K$6:$K$26=$C15))} -> 0 | BG15: =IFERROR(BF15/BE15,0) -> 0 | BH15: {=SUM([2]Hoja2!$I$6:$I$26*([2]Hoja2!$F$6:$F$26=BH$5)*([2]Hoja2!$K$6:$K$26=$C15))} -> 0 | BI15: {=SUM([2]Hoja2!$J$6:$J$26*([2]Hoja2!$F$6:$F$26=BH$5)*([2]Hoja2!$K$6:$K$26=$C15))} -> 0 | BJ15: =IFERROR(BI15/BH15,0) -> 0 | BK15: {=SUM([2]Hoja2!$I$6:$I$26*([2]Hoja2!$F$6:$F$26=BK$5)*([2]Hoja2!$K$6:$K$26=$C15))} -> 0 | BL15: {=SUM([2]Hoja2!$J$6:$J$26*([2]Hoja2!$F$6:$F$26=BK$5)*([2]Hoja2!$K$6:$K$26=$C15))} -> 0 | BM15: =IFERROR(BL15/BK15,0) -> 0 | BN15: =X15+AA15+AD15+AG15+AJ15+AM15+AP15+AS15 -> 0 | BO15: =Y15+AB15+AE15+AH15+AK15+AN15+AQ15+AT15 -> 0 | BP15: =IFERROR(BO15/BN15,0) -> 0 | BQ15: =-BN15*'[4]Stock Libre'!H47*1000 -> 0 | BR15: =-207.84*BN15 -> 0 | BS15: =$BS$18/$BN$18*$BN15 -> 0 | BT15: =$BT$18/$BN$18*$BN15 -> 0 | BU15: =$BU$18/$BN$18*$BN15 -> 0 | BV15: =(BO15-BN15*$BS$19)*0.03 -> 0 | BW15: =BO15+SUM(BQ15:BT15,BV15) -> 0 | BX15: =IFERROR(BW15/BO15,0) -> 0 | BY15: =BO15+BQ15+BR15+BS15+BV15-BU15 -> 0 | BZ15: =IFERROR(BY15/BO15,0) -> 0 | CB15: =BP15 -> 0 | CC15: =IFERROR(BQ15/$BN15,0) -> 0 | CD15: =IFERROR(BR15/$BN15,0) -> 0 | CE15: =IFERROR(BS15/$BN15,0) -> 0 | CF15: =IFERROR(BT15/$BN15,0) -> 0 | CG15: =IFERROR(BU15/$BN15,0) -> 0 | CH15: =IFERROR(BV15/$BN15,0) -> 0 | CI15: =IFERROR(BW15/$BN15,0) -> 0 | CJ15: =IFERROR(BY15/$BN15,0) -> 0 | CK15: =CJ15-CI15 -> 0
B16: 10009386 | C16: VENTOSAS | D16: =TD!F13 -> 19.74 | E16: =IFERROR(F16/D16,0) -> 1742.1709 | F16: =TD!G13 -> 34390.454 | G16: =TD!H13 -> 4102.7616 | H16: =TD!I13 -> 898.52743 | I16: =TD!J13 -> 1766.3527 | J16: =TD!K13 -> 1412.0067 | K16: 0 | L16: 0 | M16: =F16+G16+H16+I16 -> 41158.096 | N16: =IFERROR(M16/D16,0) -> 2085.0099 | O16: =F16+G16+H16-J16 -> 37979.736 | P16: =IFERROR(O16/D16,0) -> 1923.9988 | Q16: 2000 | R16: =Q16*D16 -> 39480 | S16: =R16-M16+(Q16-$BS$19)*D16*0.03 -> -561.31178 | T16: =IFERROR(S16/R16,0) -> -0.014217624 | U16: =R16-(M16-J16-I16)+(Q16-$BS$19)*D16*0.03 -> 2617.0476 | V16: =IFERROR(U16/R16,0) -> 0.066287933 | X16: {=SUM([6]Hoja3!$I$5:$I$19*([6]Hoja3!$F$5:$F$19=X$5)*([6]Hoja3!$K$5:$K$19=$C16))} -> 0 | Y16: {=SUM([6]Hoja3!$J$5:$J$19*([6]Hoja3!$F$5:$F$19=X$5)*([6]Hoja3!$K$5:$K$19=$C16))} -> 0 | Z16: =IFERROR(Y16/X16,0) -> 0 | AA16: {=SUM([6]Hoja3!$I$5:$I$19*([6]Hoja3!$F$5:$F$19=AA$5)*([6]Hoja3!$K$5:$K$19=$C16))} -> 0 | AB16: {=SUM([6]Hoja3!$J$5:$J$19*([6]Hoja3!$F$5:$F$19=AA$5)*([6]Hoja3!$K$5:$K$19=$C16))} -> 0 | AC16: =IFERROR(AB16/AA16,0) -> 0 | AD16: {=SUM([6]Hoja3!$I$5:$I$19*([6]Hoja3!$F$5:$F$19=AD$5)*([6]Hoja3!$K$5:$K$19=$C16))} -> 0 | AE16: {=SUM([6]Hoja3!$J$5:$J$19*([6]Hoja3!$F$5:$F$19=AD$5)*([6]Hoja3!$K$5:$K$19=$C16))} -> 0 | AF16: =IFERROR(AE16/AD16,0) -> 0 | AG16: {=SUM([6]Hoja3!$I$5:$I$19*([6]Hoja3!$F$5:$F$19=AG$5)*([6]Hoja3!$K$5:$K$19=$C16))} -> 0 | AH16: {=SUM([6]Hoja3!$J$5:$J$19*([6]Hoja3!$F$5:$F$19=AG$5)*([6]Hoja3!$K$5:$K$19=$C16))} -> 0 | AI16: =IFERROR(AH16/AG16,0) -> 0 | AJ16: {=SUM([6]Hoja3!$I$5:$I$19*([6]Hoja3!$F$5:$F$19=AJ$5)*([6]Hoja3!$K$5:$K$19=$C16))} -> 0 | AK16: {=SUM([6]Hoja3!$J$5:$J$19*([6]Hoja3!$F$5:$F$19=AJ$5)*([6]Hoja3!$K$5:$K$19=$C16))} -> 0 | AL16: =IFERROR(AK16/AJ16,0) -> 0 | AM16: {=SUM([6]Hoja3!$I$5:$I$19*([6]Hoja3!$F$5:$F$19=AM$5)*([6]Hoja3!$K$5:$K$19=$C16))} -> 0 | AN16: {=SUM([6]Hoja3!$J$5:$J$19*([6]Hoja3!$F$5:$F$19=AM$5)*([6]Hoja3!$K$5:$K$19=$C16))} -> 0 | AO16: =IFERROR(AN16/AM16,0) -> 0 | AP16: {=SUM([6]Hoja3!$I$5:$I$19*([6]Hoja3!$F$5:$F$19=AP$5)*([6]Hoja3!$K$5:$K$19=$C16))} -> 0 | AQ16: {=SUM([6]Hoja3!$J$5:$J$19*([6]Hoja3!$F$5:$F$19=AP$5)*([6]Hoja3!$K$5:$K$19=$C16))} -> 0 | AR16: =IFERROR(AQ16/AP16,0) -> 0 | AS16: {=SUM([6]Hoja3!$I$5:$I$19*([6]Hoja3!$F$5:$F$19=AS$5)*([6]Hoja3!$K$5:$K$19=$C16))} -> 0 | AT16: {=SUM([6]Hoja3!$J$5:$J$19*([6]Hoja3!$F$5:$F$19=AS$5)*([6]Hoja3!$K$5:$K$19=$C16))} -> 0 | AU16: =IFERROR(AT16/AS16,0) -> 0 | AV16: {=SUM([2]Hoja2!$I$6:$I$26*([2]Hoja2!$F$6:$F$26=AV$5)*([2]Hoja2!$K$6:$K$26=$C16))} -> 0 | AW16: {=SUM([2]Hoja2!$J$6:$J$26*([2]Hoja2!$F$6:$F$26=AV$5)*([2]Hoja2!$K$6:$K$26=$C16))} -> 0 | AX16: =IFERROR(AW16/AV16,0) -> 0 | AY16: {=SUM([2]Hoja2!$I$6:$I$26*([2]Hoja2!$F$6:$F$26=AY$5)*([2]Hoja2!$K$6:$K$26=$C16))} -> 0 | AZ16: {=SUM([2]Hoja2!$J$6:$J$26*([2]Hoja2!$F$6:$F$26=AY$5)*([2]Hoja2!$K$6:$K$26=$C16))} -> 0 | BA16: =IFERROR(AZ16/AY16,0) -> 0 | BB16: {=SUM([2]Hoja2!$I$6:$I$26*([2]Hoja2!$F$6:$F$26=BB$5)*([2]Hoja2!$K$6:$K$26=$C16))} -> 0 | BC16: {=SUM([2]Hoja2!$J$6:$J$26*([2]Hoja2!$F$6:$F$26=BB$5)*([2]Hoja2!$K$6:$K$26=$C16))} -> 0 | BD16: =IFERROR(BC16/BB16,0) -> 0 | BE16: {=SUM([2]Hoja2!$I$6:$I$26*([2]Hoja2!$F$6:$F$26=BE$5)*([2]Hoja2!$K$6:$K$26=$C16))} -> 0 | BF16: {=SUM([2]Hoja2!$J$6:$J$26*([2]Hoja2!$F$6:$F$26=BE$5)*([2]Hoja2!$K$6:$K$26=$C16))} -> 0 | BG16: =IFERROR(BF16/BE16,0) -> 0 | BH16: {=SUM([2]Hoja2!$I$6:$I$26*([2]Hoja2!$F$6:$F$26=BH$5)*([2]Hoja2!$K$6:$K$26=$C16))} -> 0 | BI16: {=SUM([2]Hoja2!$J$6:$J$26*([2]Hoja2!$F$6:$F$26=BH$5)*([2]Hoja2!$K$6:$K$26=$C16))} -> 0 | BJ16: =IFERROR(BI16/BH16,0) -> 0 | BK16: {=SUM([2]Hoja2!$I$6:$I$26*([2]Hoja2!$F$6:$F$26=BK$5)*([2]Hoja2!$K$6:$K$26=$C16))} -> 0 | BL16: {=SUM([2]Hoja2!$J$6:$J$26*([2]Hoja2!$F$6:$F$26=BK$5)*([2]Hoja2!$K$6:$K$26=$C16))} -> 0 | BM16: =IFERROR(BL16/BK16,0) -> 0 | BN16: =X16+AA16+AD16+AG16+AJ16+AM16+AP16+AS16 -> 0 | BO16: =Y16+AB16+AE16+AH16+AK16+AN16+AQ16+AT16 -> 0 | BP16: =IFERROR(BO16/BN16,0) -> 0 | BQ16: =-IFERROR(F16/D16*BN16,0) -> 0 | BR16: =-207.84*BN16 -> 0 | BS16: =$BS$18/$BN$18*$BN16 -> 0 | BT16: =$BT$18/$BN$18*$BN16 -> 0 | BU16: =$BU$18/$BN$18*$BN16 -> 0 | BV16: =(BO16-BN16*$BS$19)*0.03 -> 0 | BW16: =BO16+SUM(BQ16:BT16,BV16) -> 0 | BX16: =IFERROR(BW16/BO16,0) -> 0 | BY16: =BO16+BQ16+BR16+BS16+BV16-BU16 -> 0 | BZ16: =IFERROR(BY16/BO16,0) -> 0 | CB16: =BP16 -> 0 | CC16: =IFERROR(BQ16/$BN16,0) -> 0 | CD16: =IFERROR(BR16/$BN16,0) -> 0 | CE16: =IFERROR(BS16/$BN16,0) -> 0 | CF16: =IFERROR(BT16/$BN16,0) -> 0 | CG16: =IFERROR(BU16/$BN16,0) -> 0 | CH16: =IFERROR(BV16/$BN16,0) -> 0 | CI16: =IFERROR(BW16/$BN16,0) -> 0 | CJ16: =IFERROR(BY16/$BN16,0) -> 0 | CK16: =CJ16-CI16 -> 0
B17: 10009386 | C17: OTROS | D17: =TD!F14 -> 20.94 | E17: =IFERROR(F17/D17,0) -> 1416.8705 | F17: =TD!G14 -> 29669.268 | G17: =TD!H14 -> 4352.1696 | H17: =TD!I14 -> 953.14915 | I17: =TD!J14 -> 1873.7297 | J17: =TD!K14 -> 1497.843 | K17: 0 | L17: 0 | M17: =F17+G17+H17+I17 -> 36848.317 | N17: =IFERROR(M17/D17,0) -> 1759.7095 | O17: =F17+G17+H17-J17 -> 33476.744 | P17: =IFERROR(O17/D17,0) -> 1598.6984 | Q17: 1700 | R17: =Q17*D17 -> 35598 | S17: =R17-M17+(Q17-$BS$19)*D17*0.03 -> -254.10311 | T17: =IFERROR(S17/R17,0) -> -0.0071381289 | U17: =R17-(M17-J17-I17)+(Q17-$BS$19)*D17*0.03 -> 3117.4696 | V17: =IFERROR(U17/R17,0) -> 0.087574291 | X17: {=SUM([6]Hoja3!$I$5:$I$19*([6]Hoja3!$F$5:$F$19=X$5)*([6]Hoja3!$K$5:$K$19=$C17))} -> 0 | Y17: {=SUM([6]Hoja3!$J$5:$J$19*([6]Hoja3!$F$5:$F$19=X$5)*([6]Hoja3!$K$5:$K$19=$C17))} -> 0 | Z17: =IFERROR(Y17/X17,0) -> 0 | AA17: {=SUM([6]Hoja3!$I$5:$I$19*([6]Hoja3!$F$5:$F$19=AA$5)*([6]Hoja3!$K$5:$K$19=$C17))} -> 0 | AB17: {=SUM([6]Hoja3!$J$5:$J$19*([6]Hoja3!$F$5:$F$19=AA$5)*([6]Hoja3!$K$5:$K$19=$C17))} -> 0 | AC17: =IFERROR(AB17/AA17,0) -> 0 | AD17: {=SUM([6]Hoja3!$I$5:$I$19*([6]Hoja3!$F$5:$F$19=AD$5)*([6]Hoja3!$K$5:$K$19=$C17))} -> 54 | AE17: {=SUM([6]Hoja3!$J$5:$J$19*([6]Hoja3!$F$5:$F$19=AD$5)*([6]Hoja3!$K$5:$K$19=$C17))} -> 91800 | AF17: =IFERROR(AE17/AD17,0) -> 1700 | AG17: {=SUM([6]Hoja3!$I$5:$I$19*([6]Hoja3!$F$5:$F$19=AG$5)*([6]Hoja3!$K$5:$K$19=$C17))} -> 0 | AH17: {=SUM([6]Hoja3!$J$5:$J$19*([6]Hoja3!$F$5:$F$19=AG$5)*([6]Hoja3!$K$5:$K$19=$C17))} -> 0 | AI17: =IFERROR(AH17/AG17,0) -> 0 | AJ17: {=SUM([6]Hoja3!$I$5:$I$19*([6]Hoja3!$F$5:$F$19=AJ$5)*([6]Hoja3!$K$5:$K$19=$C17))} -> 0 | AK17: {=SUM([6]Hoja3!$J$5:$J$19*([6]Hoja3!$F$5:$F$19=AJ$5)*([6]Hoja3!$K$5:$K$19=$C17))} -> 0 | AL17: =IFERROR(AK17/AJ17,0) -> 0 | AM17: {=SUM([6]Hoja3!$I$5:$I$19*([6]Hoja3!$F$5:$F$19=AM$5)*([6]Hoja3!$K$5:$K$19=$C17))} -> 54 | AN17: {=SUM([6]Hoja3!$J$5:$J$19*([6]Hoja3!$F$5:$F$19=AM$5)*([6]Hoja3!$K$5:$K$19=$C17))} -> 91800 | AO17: =IFERROR(AN17/AM17,0) -> 1700 | AP17: {=SUM([6]Hoja3!$I$5:$I$19*([6]Hoja3!$F$5:$F$19=AP$5)*([6]Hoja3!$K$5:$K$19=$C17))} -> 27 | AQ17: {=SUM([6]Hoja3!$J$5:$J$19*([6]Hoja3!$F$5:$F$19=AP$5)*([6]Hoja3!$K$5:$K$19=$C17))} -> 45900 | AR17: =IFERROR(AQ17/AP17,0) -> 1700 | AS17: {=SUM([6]Hoja3!$I$5:$I$19*([6]Hoja3!$F$5:$F$19=AS$5)*([6]Hoja3!$K$5:$K$19=$C17))} -> 27 | AT17: {=SUM([6]Hoja3!$J$5:$J$19*([6]Hoja3!$F$5:$F$19=AS$5)*([6]Hoja3!$K$5:$K$19=$C17))} -> 45900 | AU17: =IFERROR(AT17/AS17,0) -> 1700 | AV17: {=SUM([2]Hoja2!$I$6:$I$26*([2]Hoja2!$F$6:$F$26=AV$5)*([2]Hoja2!$K$6:$K$26=$C17))} -> 0 | AW17: {=SUM([2]Hoja2!$J$6:$J$26*([2]Hoja2!$F$6:$F$26=AV$5)*([2]Hoja2!$K$6:$K$26=$C17))} -> 0 | AX17: =IFERROR(AW17/AV17,0) -> 0 | AY17: {=SUM([2]Hoja2!$I$6:$I$26*([2]Hoja2!$F$6:$F$26=AY$5)*([2]Hoja2!$K$6:$K$26=$C17))} -> 0 | AZ17: {=SUM([2]Hoja2!$J$6:$J$26*([2]Hoja2!$F$6:$F$26=AY$5)*([2]Hoja2!$K$6:$K$26=$C17))} -> 0 | BA17: =IFERROR(AZ17/AY17,0) -> 0 | BB17: {=SUM([2]Hoja2!$I$6:$I$26*([2]Hoja2!$F$6:$F$26=BB$5)*([2]Hoja2!$K$6:$K$26=$C17))} -> 0 | BC17: {=SUM([2]Hoja2!$J$6:$J$26*([2]Hoja2!$F$6:$F$26=BB$5)*([2]Hoja2!$K$6:$K$26=$C17))} -> 0 | BD17: =IFERROR(BC17/BB17,0) -> 0 | BE17: {=SUM([2]Hoja2!$I$6:$I$26*([2]Hoja2!$F$6:$F$26=BE$5)*([2]Hoja2!$K$6:$K$26=$C17))} -> 0 | BF17: {=SUM([2]Hoja2!$J$6:$J$26*([2]Hoja2!$F$6:$F$26=BE$5)*([2]Hoja2!$K$6:$K$26=$C17))} -> 0 | BG17: =IFERROR(BF17/BE17,0) -> 0 | BH17: {=SUM([2]Hoja2!$I$6:$I$26*([2]Hoja2!$F$6:$F$26=BH$5)*([2]Hoja2!$K$6:$K$26=$C17))} -> 0 | BI17: {=SUM([2]Hoja2!$J$6:$J$26*([2]Hoja2!$F$6:$F$26=BH$5)*([2]Hoja2!$K$6:$K$26=$C17))} -> 0 | BJ17: =IFERROR(BI17/BH17,0) -> 0 | BK17: {=SUM([2]Hoja2!$I$6:$I$26*([2]Hoja2!$F$6:$F$26=BK$5)*([2]Hoja2!$K$6:$K$26=$C17))} -> 0 | BL17: {=SUM([2]Hoja2!$J$6:$J$26*([2]Hoja2!$F$6:$F$26=BK$5)*([2]Hoja2!$K$6:$K$26=$C17))} -> 0 | BM17: =IFERROR(BL17/BK17,0) -> 0 | BN17: =X17+AA17+AD17+AG17+AJ17+AM17+AP17+AS17 -> 162 | BO17: =Y17+AB17+AE17+AH17+AK17+AN17+AQ17+AT17 -> 275400 | BP17: =IFERROR(BO17/BN17,0) -> 1700 | BQ17: =-IFERROR(F17/D17*BN17,0) -> -229533.02 | BR17: =-207.84*BN17 -> -33670.08 | BS17: =$BS$18/$BN$18*$BN17 -> -15912.248 | BT17: =$BT$18/$BN$18*$BN17 -> -31280.783 | BU17: =$BU$18/$BN$18*$BN17 -> -25005.581 | BV17: =(BO17-BN17*$BS$19)*0.03 -> 7707.0968 | BW17: =BO17+SUM(BQ17:BT17,BV17) -> -27289.034 | BX17: =IFERROR(BW17/BO17,0) -> -0.099088722 | BY17: =BO17+BQ17+BR17+BS17+BV17-BU17 -> 28997.329 | BZ17: =IFERROR(BY17/BO17,0) -> 0.10529168 | CB17: =BP17 -> 1700 | CC17: =IFERROR(BQ17/$BN17,0) -> -1416.8705 | CD17: =IFERROR(BR17/$BN17,0) -> -207.84 | CE17: =IFERROR(BS17/$BN17,0) -> -98.22375 | CF17: =IFERROR(BT17/$BN17,0) -> -193.09125 | CG17: =IFERROR(BU17/$BN17,0) -> -154.35544 | CH17: =IFERROR(BV17/$BN17,0) -> 47.574672 | CI17: =IFERROR(BW17/$BN17,0) -> -168.45083 | CJ17: =IFERROR(BY17/$BN17,0) -> 178.99586 | CK17: =CJ17-CI17 -> 347.44669
C18: TOTAL | D18: =SUM(D7:D17) -> 1726.324 | E18: =IFERROR(F18/D18,0) -> 1846.6859 | F18: =SUM(F7:F17) -> 3187978.2 | G18: =SUM(G7:G17) -> 358799.18 | H18: =SUM(H7:H17) -> 78579 | I18: =SUM(I7:I17) -> 154473 | J18: =SUM(J7:J17) -> 123484.35 | K18: =SUM(K7:K17) -> 0 | L18: 0 | M18: =SUM(M7:M17) -> 3779829.4 | N18: =IFERROR(M18/D18,0) -> 2189.5249 | O18: =SUM(O7:O17) -> 3501872 | P18: =IFERROR(O18/D18,0) -> 2028.5138 | Q18: =R18/D18 -> 1956.3735 | R18: =SUM(R7:R17) -> 3377334.6 | S18: =SUM(S7:S17) -> -307087.96 | T18: =S18/R18 -> -0.090926127 | U18: =SUM(U7:U17) -> -29130.606 | V18: =IFERROR(U18/R18,0) -> -0.0086253243 | X18: =SUM(X7:X17) -> 27 | Y18: =SUM(Y7:Y17) -> 68850 | Z18: =IFERROR(Y18/X18,0) -> 2550 | AA18: =SUM(AA7:AA17) -> 26 | AB18: =SUM(AB7:AB17) -> 74100 | AC18: =IFERROR(AB18/AA18,0) -> 2850 | AD18: =SUM(AD7:AD17) -> 270 | AE18: =SUM(AE7:AE17) -> 548100 | AF18: =IFERROR(AE18/AD18,0) -> 2030 | AG18: =SUM(AG7:AG17) -> 27 | AH18: =SUM(AH7:AH17) -> 73710 | AI18: =IFERROR(AH18/AG18,0) -> 2730 | AJ18: =SUM(AJ7:AJ17) -> 270 | AK18: =SUM(AK7:AK17) -> 405000 | AL18: =IFERROR(AK18/AJ18,0) -> 1500 | AM18: =SUM(AM7:AM17) -> 54 | AN18: =SUM(AN7:AN17) -> 91800 | AO18: =IFERROR(AN18/AM18,0) -> 1700 | AP18: =SUM(AP7:AP17) -> 27 | AQ18: =SUM(AQ7:AQ17) -> 45900 | AR18: =IFERROR(AQ18/AP18,0) -> 1700 | AS18: =SUM(AS7:AS17) -> 643 | AT18: =SUM(AT7:AT17) -> 1423810 | AU18: =IFERROR(AT18/AS18,0) -> 2214.3235 | AV18: =SUM(AV7:AV17) -> 0 | AW18: =SUM(AW7:AW17) -> 0 | AX18: =IFERROR(AW18/AV18,0) -> 0 | AY18: =SUM(AY7:AY17) -> 0 | AZ18: =SUM(AZ7:AZ17) -> 0 | BA18: =IFERROR(AZ18/AY18,0) -> 0 | BB18: =SUM(BB7:BB17) -> 0 | BC18: =SUM(BC7:BC17) -> 0 | BD18: =IFERROR(BC18/BB18,0) -> 0 | BE18: =SUM(BE7:BE17) -> 0 | BF18: =SUM(BF7:BF17) -> 0 | BG18: =IFERROR(BF18/BE18,0) -> 0 | BH18: =SUM(BH7:BH17) -> 0 | BI18: =SUM(BI7:BI17) -> 0 | BJ18: =IFERROR(BI18/BH18,0) -> 0 | BK18: =SUM(BK7:BK17) -> 0 | BL18: =SUM(BL7:BL17) -> 0 | BM18: =IFERROR(BL18/BK18,0) -> 0 | BN18: =SUM(BN7:BN17) -> 1344 | BO18: =SUM(BO7:BO17) -> 2731270 | BP18: =IFERROR(BO18/BN18,0) -> 2032.1949 | BQ18: =SUM(BQ7:BQ17) -> -2640196.1 | BR18: =SUM(BR7:BR17) -> -279336.96 | BS18: =-'[5]Stock Libre'!N54/800*BN18 -> -132012.72 | BT18: =-'[5]Stock Libre'!O54/800*BN18 -> -259514.64 | BU18: =-'[5]Stock Libre'!P54/800*BN18 -> -207453.71 | BV18: =SUM(BV7:BV17) -> 77334.459 | BW18: =SUM(BW7:BW17) -> -502455.93 | BX18: =IFERROR(BW18/BO18,0) -> -0.18396421 | BY18: =SUM(BY7:BY17) -> -35487.582 | BZ18: =IFERROR(BY18/BO18,0) -> -0.01299307 | CB18: =BP18 -> 2032.1949 | CC18: =IFERROR(BQ18/$BN18,0) -> -1964.4316 | CD18: =IFERROR(BR18/$BN18,0) -> -207.84 | CE18: =IFERROR(BS18/$BN18,0) -> -98.22375 | CF18: =IFERROR(BT18/$BN18,0) -> -193.09125 | CG18: =IFERROR(BU18/$BN18,0) -> -154.35544 | CH18: =IFERROR(BV18/$BN18,0) -> 57.54052 | CI18: =IFERROR(BW18/$BN18,0) -> -373.85114 | CJ18: =IFERROR(BY18/$BN18,0) -> -26.404451 | CK18: =CJ18-CI18 -> 347.44669
N19: =N18-P18 -> 161.01111 | BR19: flete x tm | BS19: 114.17761
C20: TM en Almacén de Yantai | AU20: Neto del despacho a Almacén Yantai | BN20: =BN18-BN14-BN7 -> 618 | BO20: =BO18-BO14-BO7 -> 1315270 | BP20: =IFERROR(BO20/BN20,0) -> 2128.2686 | BQ20: =BQ18-BQ14-BQ7 -> -993599.27 | BR20: =BR18-BR14-BR7 -> -128445.12 | BS20: =BS18-BS14-BS7 -> -60702.278 | BT20: =BT18-BT14-BT7 -> -119330.39 | BU20: =BU18-BU14-BU7 -> -95391.66 | BV20: =BV18-BV14-BV7 -> 37341.247 | BW20: =BW18-BW14-BW7 -> 50534.184 | BX20: =IFERROR(BW20/BO20,0) -> 0.038421149 | BY20: =BY18-BY14-BY7 -> 265256.24 | BZ20: =IFERROR(BY20/BO20,0) -> 0.20167436 | CC20: =SUM(CC7:CF7) -> -2483.7412
C22: Producto | D22: TM en Stock Libre | E22: CU | F22: Costo Ventas | G22: Gasto Ventas | H22: Gasto ADM | I22: Gasto Fin | J22: Depreciación | K22: Utilidad Neta | L22: Margen Neto | M22: Venta Equilibrio a Utd Neta | N22: Precio Equilibrio x TM a Utd Neta | O22: Venta Equilibro a EBITDA | P22: Precio Equilibrio x TM a EBITDA | Q22: Precio Mercado | R22: Venta total | S22: Utilidad | T22: Mg Neto | U22: EBITDA | V22: Mg EBITDA | BN22: Venta Julio | BO22: =BO18-BO14-BO7 -> 1315270 | CC22: =CC7/0.5 -> -3969.1723
C23: POTA FILETE CONGELADO | D23: =26*20 -> 520 | E23: =E7 -> 1984.5862 | F23: =E23*D23 -> 1031984.8 | G23: =D23*207.84 -> 108076.8 | H23: =H$18/$D$18*$D23 -> 23669.415 | I23: =I$18/$D$18*$D23 -> 46530.06 | J23: =J$18/$D$18*$D23 -> 37195.719 | K23: 0 | L23: 0 | M23: =F23+G23+H23+I23 -> 1210261.1 | N23: =IFERROR(M23/D23,0) -> 2327.4252 | O23: =F23+G23+H23-J23 -> 1126535.3 | P23: =IFERROR(O23/D23,0) -> 2166.4141 | Q23: 1800 | R23: =Q23*D23 -> 936000 | S23: =R23-M23+(Q23-$BS$19)*D23*0.03 -> -247962.26 | T23: =IFERROR(S23/R23,0) -> -0.26491694 | U23: =R23-(M23-J23-I23)+(Q23-$BS$19)*D23*0.03 -> -164236.48 | V23: =IFERROR(U23/R23,0) -> -0.17546632 | BN23: Cobranza | BO23: 3849629
C24: POTA FILETE DARUMA | D24: =6*26 -> 156 | E24: =E14 -> 3254.8777 | F24: =E24*D24 -> 507760.93 | G24: =D24*207.84 -> 32423.04 | H24: =H$18/$D$18*$D24 -> 7100.8246 | I24: =I$18/$D$18*$D24 -> 13959.018 | J24: =J$18/$D$18*$D24 -> 11158.716 | K24: 0 | L24: 0 | M24: =F24+G24+H24+I24 -> 561243.81 | N24: =IFERROR(M24/D24,0) -> 3597.7167 | O24: =F24+G24+H24-J24 -> 536126.08 | P24: =IFERROR(O24/D24,0) -> 3436.7056 | Q24: 3900 | R24: =Q24*D24 -> 608400 | S24: =R24-M24+(Q24-$BS$19)*D24*0.03 -> 64873.838 | T24: =IFERROR(S24/R24,0) -> 0.10663024 | U24: =R24-(M24-J24-I24)+(Q24-$BS$19)*D24*0.03 -> 89991.572 | V24: =IFERROR(U24/R24,0) -> 0.14791514 | BN24: Inventario | BO24: =M27 -> 5551334.3
C25: TOTAL | D25: =SUM(D23:D24) -> 676 | E25: =F25/D25 -> 2277.7304 | F25: =SUM(F23:F24) -> 1539745.7 | G25: =SUM(G23:G24) -> 140499.84 | H25: =SUM(H23:H24) -> 30770.24 | I25: =SUM(I23:I24) -> 60489.079 | J25: =SUM(J23:J24) -> 48354.434 | K25: =SUM(K23:K24) -> 0 | L25: 0 | M25: =SUM(M23:M24) -> 1771504.9 | N25: =IFERROR(M25/D25,0) -> 2620.5694 | O25: =SUM(O23:O24) -> 1662661.4 | P25: =IFERROR(O25/D25,0) -> 2459.5583 | Q25: =R25/D25 -> 2284.6154 | R25: =SUM(R23:R24) -> 1544400 | S25: =SUM(S23:S24) -> -183088.42 | T25: =S25/R25 -> -0.11854987 | U25: =SUM(U23:U24) -> -74244.906 | V25: =IFERROR(U25/R25,0) -> -0.048073625 | BO25: =SUM(BO22:BO24) -> 10716233
