Workbook

Sheet RESUMEN AL 31-8-2026
C2: PERU FROST
C3: AVANCE COMERCIAL AL 31-8-2026
F5: RENTABILIDAD DEL INVENTARIO
B6: Código | C6: Producto | D6: TM en Stock Libre | E6: CU | F6: Costo Ventas | G6: Gasto Ventas | H6: Gasto ADM | I6: Gasto Fin | J6: Depreciación | K6: Utilidad Neta | L6: Margen Neto | M6: Venta Equilibrio a Utd Neta | N6: Precio Equilibrio x TM a Utd Neta | O6: Venta Equilibro a EBITDA | P6: Precio Equilibrio x TM a EBITDA | Q6: Precio Mercado | R6: Venta total | S6: Utilidad | T6: Mg Neto | U6: EBITDA | V6: Mg EBITDA
B7: 10005721 | C7: POTA FILETE CONGELADO | D7: =TD!F4 -> 34.66 | E7: =IFERROR(F7/D7,0) -> 1831.106 | F7: =TD!G4 -> 63466.134 | G7: =TD!H4 -> 7203.7344 | H7: =TD!I4 -> 2314.126 | I7: =TD!J4 -> 4549.1797 | J7: =TD!K4 -> 3636.574 | K7: 0 | L7: 0 | M7: =F7+G7+H7+I7 -> 77533.174 | N7: =IFERROR(M7/D7,0) -> 2236.9641 | O7: =F7+G7+H7-J7 -> 69347.42 | P7: =IFERROR(O7/D7,0) -> 2000.7911 | Q7: 1800 | R7: =Q7*D7 -> 62388 | S7: =R7-M7 -> -15145.174 | T7: =IFERROR(S7/R7,0) -> -0.24275781 | U7: =R7-(M7-J7-I7) -> -6959.4204 | V7: =IFERROR(U7/R7,0) -> -0.11155062
B8: 10005779 | C8: POTA NUCAS CONGELADAS | D8: =TD!F5 -> 355.12 | E8: =IFERROR(F8/D8,0) -> 1793.326 | F8: =TD!G5 -> 636845.93 | G8: =TD!H5 -> 73808.141 | H8: =TD!I5 -> 23710.111 | I8: =TD!J5 -> 46610.06 | J8: =TD!K5 -> 37259.67 | K8: 0 | L8: 0 | M8: =F8+G8+H8+I8 -> 780974.24 | N8: =IFERROR(M8/D8,0) -> 2199.1841 | O8: =F8+G8+H8-J8 -> 697104.51 | P8: =IFERROR(O8/D8,0) -> 1963.0111 | Q8: 1400 | R8: =Q8*D8 -> 497168 | S8: =R8-M8 -> -283806.24 | T8: =IFERROR(S8/R8,0) -> -0.57084575 | U8: =R8-(M8-J8-I8) -> -199936.51 | V8: =IFERROR(U8/R8,0) -> -0.4021508
B9: 10006719 | C9: POTA ALAS CONGELADAS | D9: =TD!F6 -> 18.02 | E9: =IFERROR(F9/D9,0) -> 1652.036 | F9: =TD!G6 -> 29769.689 | G9: =TD!H6 -> 3745.2768 | H9: =TD!I6 -> 1203.1319 | I9: =TD!J6 -> 2365.1534 | J9: =TD!K6 -> 1890.6827 | K9: 0 | L9: 0 | M9: =F9+G9+H9+I9 -> 37083.251 | N9: =IFERROR(M9/D9,0) -> 2057.8941 | O9: =F9+G9+H9-J9 -> 32827.415 | P9: =IFERROR(O9/D9,0) -> 1821.7211 | Q9: 1950 | R9: =Q9*D9 -> 35139 | S9: =R9-M9 -> -1944.2508 | T9: =IFERROR(S9/R9,0) -> -0.055330283 | U9: =R9-(M9-J9-I9) -> 2311.5853 | V9: =IFERROR(U9/R9,0) -> 0.065784038
B10: 10007050 | C10: POTA RECORTES COCIDOS | D10: =TD!F7 -> 124.335 | E10: =IFERROR(F10/D10,0) -> 2246.62 | F10: =TD!G7 -> 279333.5 | G10: =TD!H7 -> 25841.786 | H10: =TD!I7 -> 8301.4097 | I10: =TD!J7 -> 16319.165 | J10: =TD!K7 -> 13045.396 | K10: 0 | L10: 0 | M10: =F10+G10+H10+I10 -> 329795.86 | N10: =IFERROR(M10/D10,0) -> 2652.4781 | O10: =F10+G10+H10-J10 -> 300431.3 | P10: =IFERROR(O10/D10,0) -> 2416.3051 | Q10: 1700 | R10: =Q10*D10 -> 211369.5 | S10: =R10-M10 -> -118426.36 | T10: =IFERROR(S10/R10,0) -> -0.56028121 | U10: =R10-(M10-J10-I10) -> -89061.798 | V10: =IFERROR(U10/R10,0) -> -0.42135596
B11: 10007162 | C11: POTA REJOS CONGELADOS | D11: =TD!F8 -> 228.64 | E11: =IFERROR(F11/D11,0) -> 1783.985 | F11: =TD!G8 -> 407890.33 | G11: =TD!H8 -> 47520.538 | H11: =TD!I8 -> 15265.487 | I11: =TD!J8 -> 30009.361 | J11: =TD!K8 -> 23989.217 | K11: 0 | L11: 0 | M11: =F11+G11+H11+I11 -> 500685.72 | N11: =IFERROR(M11/D11,0) -> 2189.8431 | O11: =F11+G11+H11-J11 -> 446687.14 | P11: =IFERROR(O11/D11,0) -> 1953.6701 | Q11: 2700 | R11: =Q11*D11 -> 617328 | S11: =R11-M11 -> 116642.28 | T11: =IFERROR(S11/R11,0) -> 0.18894702 | U11: =R11-(M11-J11-I11) -> 170640.86 | V11: =IFERROR(U11/R11,0) -> 0.27641847
B12: 10007567 | C12: POTA REPRODUCTORES | D12: =TD!F9 -> 35.66 | E12: =IFERROR(F12/D12,0) -> 1712.173 | F12: =TD!G9 -> 61056.089 | G12: =TD!H9 -> 7411.5744 | H12: =TD!I9 -> 2380.8925 | I12: =TD!J9 -> 4680.4312 | J12: =TD!K9 -> 3741.4953 | K12: 0 | L12: 0 | M12: =F12+G12+H12+I12 -> 75528.987 | N12: =IFERROR(M12/D12,0) -> 2118.0311 | O12: =F12+G12+H12-J12 -> 67107.061 | P12: =IFERROR(O12/D12,0) -> 1881.8581 | Q12: 2800 | R12: =Q12*D12 -> 99848 | S12: =R12-M12 -> 24319.013 | T12: =IFERROR(S12/R12,0) -> 0.24356034 | U12: =R12-(M12-J12-I12) -> 32740.939 | V12: =IFERROR(U12/R12,0) -> 0.32790781
B13: 10007969 | C13: POTA CONOS | D13: =TD!F10 -> 0 | E13: =IFERROR(F13/D13,0) -> 0 | F13: =TD!G10 -> 0 | G13: =TD!H10 -> 0 | H13: =TD!I10 -> 0 | I13: =TD!J10 -> 0 | J13: =TD!K10 -> 0 | K13: 0 | L13: 0 | M13: =F13+G13+H13+I13 -> 0 | N13: =IFERROR(M13/D13,0) -> 0 | O13: =F13+G13+H13-J13 -> 0 | P13: =IFERROR(O13/D13,0) -> 0 | Q13: 1700 | R13: =Q13*D13 -> 0 | S13: =R13-M13 -> 0 | T13: =IFERROR(S13/R13,0) -> 0 | U13: =R13-(M13-J13-I13) -> 0 | V13: =IFERROR(U13/R13,0) -> 0
B14: 10009239 | C14: POTA FILETE DARUMA | D14: =TD!F11 -> 16.5 | E14: =IFERROR(F14/D14,0) -> 2846.957 | F14: =TD!G11 -> 46974.791 | G14: =TD!H11 -> 3429.36 | H14: =TD!I11 -> 1101.6468 | I14: =TD!J11 -> 2165.651 | J14: =TD!K11 -> 1731.2023 | K14: 0 | L14: 0 | M14: =F14+G14+H14+I14 -> 53671.448 | N14: =IFERROR(M14/D14,0) -> 3252.8151 | O14: =F14+G14+H14-J14 -> 49774.595 | P14: =IFERROR(O14/D14,0) -> 3016.6421 | Q14: 3500 | R14: =Q14*D14 -> 57750 | S14: =R14-M14 -> 4078.5516 | T14: =IFERROR(S14/R14,0) -> 0.070624271 | U14: =R14-(M14-J14-I14) -> 7975.4049 | V14: =IFERROR(U14/R14,0) -> 0.13810225
B15: 10009334 | C15: POTA ALAS COCIDAS | D15: =TD!F12 -> 311.768 | E15: =IFERROR(F15/D15,0) -> 2574.823 | F15: =TD!G12 -> 802747.42 | G15: =TD!H12 -> 64797.861 | H15: =TD!I12 -> 20815.65 | I15: =TD!J12 -> 40920.042 | J15: =TD!K12 -> 32711.119 | K15: 0 | L15: 0 | M15: =F15+G15+H15+I15 -> 929280.97 | N15: =IFERROR(M15/D15,0) -> 2980.6811 | O15: =F15+G15+H15-J15 -> 855649.81 | P15: =IFERROR(O15/D15,0) -> 2744.5081 | Q15: 3500 | R15: =Q15*D15 -> 1091188 | S15: =R15-M15 -> 161907.03 | T15: =IFERROR(S15/R15,0) -> 0.14837684 | U15: =R15-(M15-J15-I15) -> 235538.19 | V15: =IFERROR(U15/R15,0) -> 0.21585482
B16: 10009386 | C16: VENTOSAS | D16: =TD!F13 -> 21.28 | E16: =IFERROR(F16/D16,0) -> 3230.8044 | F16: =TD!G13 -> 68751.518 | G16: =TD!H13 -> 4422.8352 | H16: =TD!I13 -> 1420.7906 | I16: =TD!J13 -> 2793.0336 | J16: =TD!K13 -> 2232.7263 | K16: 0 | L16: 0 | M16: =F16+G16+H16+I16 -> 77388.177 | N16: =IFERROR(M16/D16,0) -> 3636.6625 | O16: =F16+G16+H16-J16 -> 72362.417 | P16: =IFERROR(O16/D16,0) -> 3400.4895 | Q16: 2000 | R16: =Q16*D16 -> 42560 | S16: =R16-M16 -> -34828.177 | T16: =IFERROR(S16/R16,0) -> -0.81833123 | U16: =R16-(M16-J16-I16) -> -29802.417 | V16: =IFERROR(U16/R16,0) -> -0.70024477
B17: 10009386 | C17: OTROS | D17: =TD!F14 -> 30.94 | E17: =IFERROR(F17/D17,0) -> 1408.5766 | F17: =TD!G14 -> 43581.36 | G17: =TD!H14 -> 6430.5696 | H17: =TD!I14 -> 2065.7547 | I17: =TD!J14 -> 4060.9238 | J17: =TD!K14 -> 3246.2666 | K17: 0 | L17: 0 | M17: =F17+G17+H17+I17 -> 56138.608 | N17: =IFERROR(M17/D17,0) -> 1814.4347 | O17: =F17+G17+H17-J17 -> 48831.418 | P17: =IFERROR(O17/D17,0) -> 1578.2617 | Q17: 1700 | R17: =Q17*D17 -> 52598 | S17: =R17-M17 -> -3540.6081 | T17: =IFERROR(S17/R17,0) -> -0.067314501 | U17: =R17-(M17-J17-I17) -> 3766.5822 | V17: =IFERROR(U17/R17,0) -> 0.07161075
C18: FILETE PARA REPROCESO | D18: 0 | E18: =IFERROR(F18/D18,0) -> 0 | F18: 0 | G18: 0 | H18: 0 | I18: 0 | J18: 0 | K18: 0 | L18: 0 | M18: =F18+G18+H18+I18 -> 0 | N18: =IFERROR(M18/D18,0) -> 0 | O18: =F18+G18+H18-J18 -> 0 | P18: =IFERROR(O18/D18,0) -> 0 | Q18: 1800 | R18: =Q18*D18 -> 0 | S18: =R18-M18 -> 0 | T18: =IFERROR(S18/R18,0) -> 0 | U18: =R18-(M18-J18-I18) -> 0 | V18: =IFERROR(U18/R18,0) -> 0
C19: ALAS PARA REPROCESO | D19: 0 | E19: =IFERROR(F19/D19,0) -> 0 | F19: 0 | G19: 0 | H19: 0 | I19: 0 | J19: 0 | K19: 0 | L19: 0 | M19: =F19+G19+H19+I19 -> 0 | N19: =IFERROR(M19/D19,0) -> 0 | O19: =F19+G19+H19-J19 -> 0 | P19: =IFERROR(O19/D19,0) -> 0 | Q19: 1950 | R19: =Q19*D19 -> 0 | S19: =R19-M19 -> 0 | T19: =IFERROR(S19/R19,0) -> 0 | U19: =R19-(M19-J19-I19) -> 0 | V19: =IFERROR(U19/R19,0) -> 0
C20: TOTAL | D20: =SUM(D7:D19) -> 1176.923 | E20: =IFERROR(F20/D20,0) -> 2073.5569 | F20: =SUM(F7:F19) -> 2440416.8 | G20: =SUM(G7:G19) -> 244611.68 | H20: =SUM(H7:H19) -> 78579 | I20: =SUM(I7:I19) -> 154473 | J20: =SUM(J7:J19) -> 123484.35 | K20: =SUM(K7:K19) -> 0 | L20: 0 | M20: =SUM(M7:M19) -> 2918080.4 | N20: =IFERROR(M20/D20,0) -> 2479.4149 | O20: =SUM(O7:O19) -> 2640123.1 | P20: =IFERROR(O20/D20,0) -> 2243.242 | Q20: =R20/D20 -> 2351.3318 | R20: =SUM(R7:R19) -> 2767336.5 | S20: =SUM(S7:S19) -> -150743.93 | T20: =S20/R20 -> -0.05447257 | U20: =SUM(U7:U19) -> 127213.42 | V20: =IFERROR(U20/R20,0) -> 0.045969624
N21: =M20-R20 -> 150743.93
C22: TM en Almacén de Yantai Jiahong | R22: =7%/12 -> 0.0058333333
R23: =R22*M31 -> 22038.632 | S23: =R23*7 -> 154270.42 | T23: =S23/D31 -> 109.9497
C24: Producto | D24: TM en Stock Libre | E24: CU | F24: Costo Ventas | G24: Gasto Ventas | H24: Gasto ADM | I24: Gasto Fin | J24: Depreciación | K24: Utilidad Neta | L24: Margen Neto | M24: Venta Equilibrio a Utd Neta | N24: Precio Equilibrio x TM a Utd Neta | O24: Venta Equilibro a EBITDA | P24: Precio Equilibrio x TM a EBITDA | Q24: Precio Mercado | R24: Venta total | S24: Utilidad | T24: Mg Neto | U24: EBITDA | V24: Mg EBITDA
C25: POTA FILETE CONGELADO | D25: 567 | E25: =E7 -> 1831.106 | F25: =E25*D25 -> 1038237.1 | G25: =D25*207.84 -> 117845.28 | H25: =H$20/$D$20*$D25 -> 37856.591 | I25: =I$20/$D$20*$D25 -> 74419.644 | J25: =J$20/$D$20*$D25 -> 59490.405 | K25: 0 | L25: 0 | M25: =F25+G25+H25+I25 -> 1268358.6 | N25: =IFERROR(M25/D25,0) -> 2236.9641 | O25: =F25+G25+H25-J25 -> 1134448.6 | P25: =IFERROR(O25/D25,0) -> 2000.7911 | Q25: 1500 | R25: =Q25*D25 -> 850500 | S25: =R25-M25 -> -417858.62 | T25: =IFERROR(S25/R25,0) -> -0.49130937 | U25: =R25-(M25-J25-I25) -> -283948.57 | V25: =IFERROR(U25/R25,0) -> -0.33386075
C26: POTA ALAS CONGELADAS | D26: 54 | E26: =E9 -> 1652.036 | F26: =E26*D26 -> 89209.944 | G26: =D26*207.84 -> 11223.36 | H26: =H$20/$D$20*$D26 -> 3605.3896 | I26: =I$20/$D$20*$D26 -> 7087.5852 | J26: =J$20/$D$20*$D26 -> 5665.7529 | K26: 0 | L26: 0 | M26: =F26+G26+H26+I26 -> 111126.28 | N26: =IFERROR(M26/D26,0) -> 2057.8941 | O26: =F26+G26+H26-J26 -> 98372.941 | P26: =IFERROR(O26/D26,0) -> 1821.7211 | Q26: 1700 | R26: =Q26*D26 -> 91800 | S26: =R26-M26 -> -19326.279 | T26: =IFERROR(S26/R26,0) -> -0.21052591 | U26: =R26-(M26-J26-I26) -> -6572.9407
C27: POTA REJOS CONGELADOS | D27: 108 | E27: =E11 -> 1783.985 | F27: =E27*D27 -> 192670.38 | G27: =D27*207.84 -> 22446.72 | H27: =H$20/$D$20*$D27 -> 7210.7793 | I27: =I$20/$D$20*$D27 -> 14175.17 | J27: =J$20/$D$20*$D27 -> 11331.506 | K27: 0 | L27: 0 | M27: =F27+G27+H27+I27 -> 236503.05 | N27: =IFERROR(M27/D27,0) -> 2189.8431 | O27: =F27+G27+H27-J27 -> 210996.37 | P27: =IFERROR(O27/D27,0) -> 1953.6701 | Q27: 2275 | R27: =Q27*D27 -> 245700 | S27: =R27-M27 -> 9196.9504 | T27: =IFERROR(S27/R27,0) -> 0.037431625 | U27: =R27-(M27-J27-I27) -> 34703.627 | V27: =IFERROR(U27/R27,0) -> 0.1412439
C28: POTA FILETE DARUMA | D28: 594 | E28: =E14 -> 2846.957 | F28: =E28*D28 -> 1691092.5 | G28: =D28*207.84 -> 123456.96 | H28: =H$20/$D$20*$D28 -> 39659.286 | I28: =I$20/$D$20*$D28 -> 77963.437 | J28: =J$20/$D$20*$D28 -> 62323.282 | K28: 0 | L28: 0 | M28: =F28+G28+H28+I28 -> 1932172.1 | N28: =IFERROR(M28/D28,0) -> 3252.8151 | O28: =F28+G28+H28-J28 -> 1791885.4 | P28: =IFERROR(O28/D28,0) -> 3016.6421 | Q28: 3400 | R28: =Q28*D28 -> 2019600 | S28: =R28-M28 -> 87427.859 | T28: =IFERROR(S28/R28,0) -> 0.043289691 | U28: =R28-(M28-J28-I28) -> 227714.58 | V28: =IFERROR(U28/R28,0) -> 0.11275232
C29: POTA ALAS COCIDAS | D29: 53.1 | E29: =E15 -> 2574.823 | F29: =E29*D29 -> 136723.1 | G29: =D29*207.84 -> 11036.304 | H29: =H$20/$D$20*$D29 -> 3545.2998 | I29: =I$20/$D$20*$D29 -> 6969.4587 | J29: =J$20/$D$20*$D29 -> 5571.3237 | K29: 0 | L29: 0 | M29: =F29+G29+H29+I29 -> 158274.16 | N29: =IFERROR(M29/D29,0) -> 2980.6811 | O29: =F29+G29+H29-J29 -> 145733.38 | P29: =IFERROR(O29/D29,0) -> 2744.5081 | Q29: 3400 | R29: =Q29*D29 -> 180540 | S29: =R29-M29 -> 22265.836 | T29: =IFERROR(S29/R29,0) -> 0.1233291 | U29: =R29-(M29-J29-I29) -> 34806.619
C30: POTA RECORTES COCIDOS | D30: 27 | E30: =E10 -> 2246.62 | F30: =E30*D30 -> 60658.74 | G30: =D30*207.84 -> 5611.68 | H30: =H$20/$D$20*$D30 -> 1802.6948 | I30: =I$20/$D$20*$D30 -> 3543.7926 | J30: =J$20/$D$20*$D30 -> 2832.8764 | K30: 0 | L30: 0 | M30: =F30+G30+H30+I30 -> 71616.907 | N30: =IFERROR(M30/D30,0) -> 2652.4781 | O30: =F30+G30+H30-J30 -> 65240.238 | P30: =IFERROR(O30/D30,0) -> 2416.3051 | Q30: 1800 | R30: =Q30*D30 -> 48600 | S30: =R30-M30 -> -23016.907 | T30: =IFERROR(S30/R30,0) -> -0.47359892 | U30: =R30-(M30-J30-I30) -> -16640.238
C31: TOTAL | D31: =SUM(D25:D30) -> 1403.1 | E31: =F31/D31 -> 2286.7876 | F31: =SUM(F25:F30) -> 3208591.7 | G31: =SUM(G25:G30) -> 291620.3 | H31: =SUM(H25:H30) -> 93680.041 | I31: =SUM(I25:I30) -> 184159.09 | J31: =SUM(J25:J30) -> 147215.15 | K31: =SUM(K25:K30) -> 0 | L31: 0 | M31: =SUM(M25:M30) -> 3778051.2 | N31: =IFERROR(M31/D31,0) -> 2692.6457 | O31: =SUM(O25:O30) -> 3446676.9 | P31: =IFERROR(O31/D31,0) -> 2456.4728 | Q31: =R31/D31 -> 2449.3906 | R31: =SUM(R25:R30) -> 3436740 | S31: =SUM(S25:S30) -> -341311.16 | T31: =S31/R31 -> -0.099312476 | U31: =SUM(U25:U30) -> -9936.9241 | V31: =IFERROR(U31/R31,0) -> -0.0028913808
C33: TOTAL | D33: =D20+D31 -> 2580.023 | E33: =F33/D33 -> 2189.5187 | F33: =F20+F31 -> 5649008.5 | G33: =G20+G31 -> 536231.98 | H33: =H20+H31 -> 172259.04 | I33: =I20+I31 -> 338632.09 | J33: =J20+J31 -> 270699.5 | K33: =K20+K31 -> 0 | L33: =L20+L31 -> 0 | M33: =M20+M31 -> 6696131.6 | N33: =IFERROR(M33/D33,0) -> 2595.3767 | O33: =O20+O31 -> 6086800 | P33: =IFERROR(O33/D33,0) -> 2359.2038 | Q33: =R33/D33 -> 2404.6594 | R33: =R20+R31 -> 6204076.5 | S33: =S20+S31 -> -492055.09 | T33: =S33/R33 -> -0.079311577 | U33: =U20+U31 -> 117276.5 | V33: =IFERROR(U33/R33,0) -> 0.018903135
C36: INVENTARIO TOTAL VALORIZADO
C38: Producto | D38: TM en Stock Libre | E38: CU | F38: Costo Ventas | G38: Gasto Ventas | H38: Gasto ADM | I38: Gasto Fin | J38: Depreciación | K38: Utilidad Neta | L38: Margen Neto | M38: Venta Equilibrio a Utd Neta | N38: Precio Equilibrio x TM a Utd Neta | O38: Precio Venta | P38: Venta Esperada | Q38: Utilidad Neta | R38: Margen Neto | S38: Precio actual | T38: venta con precio actual | U38: P/L | V38: variación
C39: POTA FILETE CONGELADO | D39: =D7+D25 -> 601.66 | E39: =IFERROR(F39/D39,0) -> 1831.106 | F39: =F7+F25 -> 1101703.2 | G39: =G7+G25 -> 125049.01 | H39: =H7+H25 -> 40170.717 | I39: =I7+I25 -> 78968.824 | J39: =J7+J25 -> 63126.979 | K39: 0 | L39: 0 | M39: =F39+G39+H39+I39 -> 1345891.8 | N39: =IFERROR(M39/D39,0) -> 2236.9641 | O39: 2200 | P39: =O39*D39 -> 1323652 | Q39: =P39-M39 -> -22239.792 | R39: =Q39/P39 -> -0.016801842 | S39: =Q25 -> 1500 | T39: =S39*D39 -> 902490 | U39: =T39-M39 -> -443401.79 | V39: =Q39-U39 -> 421162
C40: POTA NUCAS CONGELADAS | D40: =D8 -> 355.12 | E40: =IFERROR(F40/D40,0) -> 1793.326 | F40: =F8 -> 636845.93 | G40: =G8 -> 73808.141 | H40: =H8 -> 23710.111 | I40: =I8 -> 46610.06 | J40: =J8 -> 37259.67 | K40: 0 | L40: 0 | M40: =F40+G40+H40+I40 -> 780974.24 | N40: =IFERROR(M40/D40,0) -> 2199.1841 | O40: 1400 | P40: =O40*D40 -> 497168 | Q40: =P40-M40 -> -283806.24 | R40: =Q40/P40 -> -0.57084575 | S40: =Q8 -> 1400 | T40: =S40*D40 -> 497168 | U40: =T40-M40 -> -283806.24 | V40: =Q40-U40 -> 0
C41: POTA ALAS CONGELADAS | D41: =D9+D26 -> 72.02 | E41: =IFERROR(F41/D41,0) -> 1652.036 | F41: =F9+F26 -> 118979.63 | G41: =G9+G26 -> 14968.637 | H41: =H9+H26 -> 4808.5215 | I41: =I9+I26 -> 9452.7386 | J41: =J9+J26 -> 7556.4356 | K41: 0 | L41: 0 | M41: =F41+G41+H41+I41 -> 148209.53 | N41: =IFERROR(M41/D41,0) -> 2057.8941 | O41: 2400 | P41: =O41*D41 -> 172848 | Q41: =P41-M41 -> 24638.47 | R41: =Q41/P41 -> 0.14254414 | S41: =Q9 -> 1950 | T41: =S41*D41 -> 140439 | U41: =T41-M41 -> -7770.5296 | V41: =Q41-U41 -> 32409
C42: POTA RECORTES COCIDOS | D42: =D10+D30 -> 151.335 | E42: =IFERROR(F42/D42,0) -> 2246.62 | F42: =F10+F30 -> 339992.24 | G42: =G10+G30 -> 31453.466 | H42: =H10+H30 -> 10104.104 | I42: =I10+I30 -> 19862.957 | J42: =J10+J30 -> 15878.273 | K42: 0 | L42: 0 | M42: =F42+G42+H42+I42 -> 401412.77 | N42: =IFERROR(M42/D42,0) -> 2652.4781 | O42: 2500 | P42: =O42*D42 -> 378337.5 | Q42: =P42-M42 -> -23075.266 | R42: =Q42/P42 -> -0.060991221 | S42: =Q10 -> 1700 | T42: =S42*D42 -> 257269.5 | U42: =T42-M42 -> -144143.27 | V42: =Q42-U42 -> 121068
C43: POTA REJOS CONGELADOS | D43: =D11+D27 -> 336.64 | E43: =IFERROR(F43/D43,0) -> 1783.985 | F43: =F11+F27 -> 600560.71 | G43: =G11+G27 -> 69967.258 | H43: =H11+H27 -> 22476.266 | I43: =I11+I27 -> 44184.531 | J43: =J11+J27 -> 35320.723 | K43: 0 | L43: 0 | M43: =F43+G43+H43+I43 -> 737188.77 | N43: =IFERROR(M43/D43,0) -> 2189.8431 | O43: 2800 | P43: =O43*D43 -> 942592 | Q43: =P43-M43 -> 205403.23 | R43: =Q43/P43 -> 0.2179132 | S43: =Q11 -> 2700 | T43: =S43*D43 -> 908928 | U43: =T43-M43 -> 171739.23 | V43: =Q43-U43 -> 33664
C44: POTA REPRODUCTORES | D44: =D12 -> 35.66 | E44: =IFERROR(F44/D44,0) -> 1712.173 | F44: =F12 -> 61056.089 | G44: =G12 -> 7411.5744 | H44: =H12 -> 2380.8925 | I44: =I12 -> 4680.4312 | J44: =J12 -> 3741.4953 | K44: 0 | L44: 0 | M44: =F44+G44+H44+I44 -> 75528.987 | N44: =IFERROR(M44/D44,0) -> 2118.0311 | O44: 2800 | P44: =O44*D44 -> 99848 | Q44: =P44-M44 -> 24319.013 | R44: =Q44/P44 -> 0.24356034 | S44: =Q12 -> 2800 | T44: =S44*D44 -> 99848 | U44: =T44-M44 -> 24319.013 | V44: =Q44-U44 -> 0
C45: POTA CONOS | D45: =D13 -> 0 | E45: =IFERROR(F45/D45,0) -> 0 | F45: =F13 -> 0 | G45: =G13 -> 0 | H45: =H13 -> 0 | I45: =I13 -> 0 | J45: =J13 -> 0 | K45: 0 | L45: 0 | M45: =F45+G45+H45+I45 -> 0 | N45: =IFERROR(M45/D45,0) -> 0 | O45: 1800 | P45: =O45*D45 -> 0 | Q45: =P45-M45 -> 0 | R45: =Q45/P45 -> #DIV/0! | S45: =Q13 -> 1700 | T45: =S45*D45 -> 0 | U45: =T45-M45 -> 0 | V45: =Q45-U45 -> 0
C46: POTA FILETE DARUMA | D46: =D14+D28+D18 -> 610.5 | E46: =IFERROR(F46/D46,0) -> 2846.957 | F46: =F14+F28+F18 -> 1738067.2 | G46: =G14+G28+G18 -> 126886.32 | H46: =H14+H28+H18 -> 40760.933 | I46: =I14+I28+I18 -> 80129.088 | J46: =J14+J28+J18 -> 64054.484 | K46: 0 | L46: 0 | M46: =F46+G46+H46+I46 -> 1985843.6 | N46: =IFERROR(M46/D46,0) -> 3252.8151 | O46: 4000 | P46: =O46*D46 -> 2442000 | Q46: =P46-M46 -> 456156.41 | R46: =Q46/P46 -> 0.18679624 | S46: =Q14 -> 3500 | T46: =S46*D46 -> 2136750 | U46: =T46-M46 -> 150906.41 | V46: =Q46-U46 -> 305250
...

Sheet TD
E3: Etiquetas de fila | F3: Suma de TM en Stock libre | G3: Suma de Costo Ventas | H3: Suma de Gasto Ventas | I3: Suma de Gasto ADM | J3: Suma de Gasto Fin | K3: Suma de Depreciación
B4: =C4=E4 -> TRUE | C4: 10005721 | D4: POTA FILETE CONGELADO | E4: 10005721 | F4: 34.66 | G4: 63466.134 | H4: 7203.7344 | I4: 2314.126 | J4: 4549.1797 | K4: 3636.574
B5: =C5=E5 -> TRUE | C5: 10005779 | D5: POTA NUCAS CONGELADAS | E5: 10005779 | F5: 355.12 | G5: 636845.93 | H5: 73808.141 | I5: 23710.111 | J5: 46610.06 | K5: 37259.67
B6: =C6=E6 -> TRUE | C6: 10006719 | D6: POTA ALAS CONGELADAS | E6: 10006719 | F6: 18.02 | G6: 29769.689 | H6: 3745.2768 | I6: 1203.1319 | J6: 2365.1534 | K6: 1890.6827
B7: =C7=E7 -> TRUE | C7: 10007050 | D7: POTA RECORTES COCIDOS | E7: 10007050 | F7: 124.335 | G7: 279333.5 | H7: 25841.786 | I7: 8301.4097 | J7: 16319.165 | K7: 13045.396
B8: =C8=E8 -> TRUE | C8: 10007162 | D8: POTA REJOS CONGELADOS | E8: 10007162 | F8: 228.64 | G8: 407890.33 | H8: 47520.538 | I8: 15265.487 | J8: 30009.361 | K8: 23989.217
B9: =C9=E9 -> TRUE | C9: 10007567 | D9: POTA REPRODUCTORES | E9: 10007567 | F9: 35.66 | G9: 61056.089 | H9: 7411.5744 | I9: 2380.8925 | J9: 4680.4312 | K9: 3741.4953
B10: =C10=E10 -> TRUE | C10: 10007969 | D10: POTA CONOS | E10: 10007969 | F10: 0 | G10: 0 | H10: 0 | I10: 0 | J10: 0 | K10: 0
B11: =C11=E11 -> TRUE | C11: 10009239 | D11: POTA FILETE DARUMA | E11: 10009239 | F11: 16.5 | G11: 46974.791 | H11: 3429.36 | I11: 1101.6468 | J11: 2165.651 | K11: 1731.2023
B12: =C12=E12 -> TRUE | C12: 10009334 | D12: POTA ALAS COCIDAS | E12: 10009334 | F12: 311.768 | G12: 802747.42 | H12: 64797.861 | I12: 20815.65 | J12: 40920.042 | K12: 32711.119
B13: =C13=E13 -> TRUE | C13: 10009386 | D13: VENTOSAS | E13: 10009386 | F13: 21.28 | G13: 68751.518 | H13: 4422.8352 | I13: 1420.7906 | J13: 2793.0336 | K13: 2232.7263
B14: =C14=E14 -> FALSE | D14: OTROS | E14: 10009207 | F14: 30.94 | G14: 43581.36 | H14: 6430.5696 | I14: 2065.7547 | J14: 4060.9238 | K14: 3246.2666
D15: FILETE PARA REPROCESO | E15: Total general | F15: 1176.923 | G15: 2440416.8 | H15: 244611.68 | I15: 78579 | J15: 154473 | K15: 123484.35
D16: ALAS PARA REPROCESO

Sheet STOCK LIBRE
C2: COD | D2: DESCRIPCIÓN | E2: STOCK LIBRE | G2: CÓDIGO | H2: CU X TM | I2: % MP | J2: incremento MP | K2: TM en Stock libre | L2: Costo Ventas | M2: Gasto Ventas | N2: Gasto ADM | O2: Gasto Fin | P2: Depreciación | Q2: Utilidad Neta | R2: Margen Neto | S2: Venta Equilibrio | T2: Precio Equilibrio x TM
C3: 10006668 | D3: POTA ALAS FR C/P C/C < 0.5 BL10 S20 | E3: 680 | G3: 10006719 | H3: =1652.036/1000 -> 1.652036 | I3: 0.71 | J3: =$H$47 -> -0.10965909 | K3: =IF(E3<0,0,E3)/1000 -> 0.68 | L3: =IFERROR(H3*K3,0)*1000 -> 1123.3845 | M3: =207.84*K3 -> 141.3312 | N3: =$N$42/$K$40*K3 -> 45.401203 | O3: =$O$42/$K$40*K3 -> 89.251073 | P3: =$P$42/$K$40*K3 -> 71.346518 | Q3: 0 | R3: 0 | S3: =L3+M3+N3+O3 -> 1399.368 | T3: =IFERROR(S3/K3,0) -> 2057.8941
C4: 10009178 | D4: POTA ALAS FR C/P C/C AA S/COD BL10 S20 | E4: 14840 | G4: 10006719 | H4: =1652.036/1000 -> 1.652036 | I4: 0.71 | J4: =$H$47 -> -0.10965909 | K4: =IF(E4<0,0,E4)/1000 -> 14.84 | L4: =IFERROR(H4*K4,0)*1000 -> 24516.214 | M4: =207.84*K4 -> 3084.3456 | N4: =$N$42/$K$40*K4 -> 990.81449 | O4: =$O$42/$K$40*K4 -> 1947.7734 | P4: =$P$42/$K$40*K4 -> 1557.0328 | Q4: 0 | R4: 0 | S4: =L4+M4+N4+O4 -> 30539.148 | T4: =IFERROR(S4/K4,0) -> 2057.8941
C5: 10006720 | D5: POTA ALAS FR C/P C/C 1.0-2.0 BL10 S20 | E5: 40 | G5: 10006719 | H5: =1652.036/1000 -> 1.652036 | I5: 0.71 | J5: =$H$47 -> -0.10965909 | K5: =IF(E5<0,0,E5)/1000 -> 0.04 | L5: =IFERROR(H5*K5,0)*1000 -> 66.08144 | M5: =207.84*K5 -> 8.3136 | N5: =$N$42/$K$40*K5 -> 2.670659 | O5: =$O$42/$K$40*K5 -> 5.2500631 | P5: =$P$42/$K$40*K5 -> 4.196854 | Q5: 0 | R5: 0 | S5: =L5+M5+N5+O5 -> 82.315762 | T5: =IFERROR(S5/K5,0) -> 2057.8941
C6: 10010110 | D6: POTA ALAS FR C/P C/C 1.0-2.0 ENT BL10 S20 | E6: 2340 | G6: 10006719 | H6: =1652.036/1000 -> 1.652036 | I6: 0.71 | J6: =$H$47 -> -0.10965909 | K6: =IF(E6<0,0,E6)/1000 -> 2.34 | L6: =IFERROR(H6*K6,0)*1000 -> 3865.7642 | M6: =207.84*K6 -> 486.3456 | N6: =$N$42/$K$40*K6 -> 156.23355 | O6: =$O$42/$K$40*K6 -> 307.12869 | P6: =$P$42/$K$40*K6 -> 245.51596 | Q6: 0 | R6: 0 | S6: =L6+M6+N6+O6 -> 4815.4721 | T6: =IFERROR(S6/K6,0) -> 2057.8941
C7: 10006722 | D7: POTA ALAS FR C/P C/C 2.0-UP BL10 S20 | E7: 120 | G7: 10006719 | H7: =1652.036/1000 -> 1.652036 | I7: 0.71 | J7: =$H$47 -> -0.10965909 | K7: =IF(E7<0,0,E7)/1000 -> 0.12 | L7: =IFERROR(H7*K7,0)*1000 -> 198.24432 | M7: =207.84*K7 -> 24.9408 | N7: =$N$42/$K$40*K7 -> 8.011977 | O7: =$O$42/$K$40*K7 -> 15.750189 | P7: =$P$42/$K$40*K7 -> 12.590562 | Q7: 0 | R7: 0 | S7: =L7+M7+N7+O7 -> 246.94729 | T7: =IFERROR(S7/K7,0) -> 2057.8941
C8: 10009241 | D8: POTA ALAS PRE COC S/COD BL10 S20 | E8: 260 | G8: 10009334 | H8: =2574.823/1000 -> 2.574823 | I8: 0.71 | J8: =$H$47 -> -0.10965909 | K8: =IF(E8<0,0,E8)/1000 -> 0.26 | L8: =IFERROR(H8*K8,0)*1000 -> 669.45398 | M8: =207.84*K8 -> 54.0384 | N8: =$N$42/$K$40*K8 -> 17.359283 | O8: =$O$42/$K$40*K8 -> 34.12541 | P8: =$P$42/$K$40*K8 -> 27.279551 | Q8: 0 | R8: 0 | S8: =L8+M8+N8+O8 -> 774.97707 | T8: =IFERROR(S8/K8,0) -> 2980.6811
C9: 10009331 | D9: POTA ALAS PRE COC 0.3 - UP BL9 S18 | E9: =163764+108000+50000/2 -> 296764 | G9: 10009334 | H9: =2574.823/1000 -> 2.574823 | I9: 0.68 | J9: =$H$47 -> -0.10965909 | K9: =IF(E9<0,0,E9)/1000 -> 296.764 | L9: =IFERROR(H9*K9,0)*1000 -> 764114.77 | M9: =207.84*K9 -> 61679.43 | N9: =$N$42/$K$40*K9 -> 19813.886 | O9: =$O$42/$K$40*K9 -> 38950.743 | P9: =$P$42/$K$40*K9 -> 31136.88 | Q9: 0 | R9: 0 | S9: =L9+M9+N9+O9 -> 884558.83 | T9: =IFERROR(S9/K9,0) -> 2980.6811
C10: 10009334 | D10: POTA ALAS PRE COC AA BL9 S18 | E10: 14744 | G10: 10009334 | H10: =2574.823/1000 -> 2.574823 | I10: 0.68 | J10: =$H$47 -> -0.10965909 | K10: =IF(E10<0,0,E10)/1000 -> 14.744 | L10: =IFERROR(H10*K10,0)*1000 -> 37963.19 | M10: =207.84*K10 -> 3064.393 | N10: =$N$42/$K$40*K10 -> 984.40491 | O10: =$O$42/$K$40*K10 -> 1935.1733 | P10: =$P$42/$K$40*K10 -> 1546.9604 | Q10: 0 | R10: 0 | S10: =L10+M10+N10+O10 -> 43947.161 | T10: =IFERROR(S10/K10,0) -> 2980.6811
C11: 10004434 | D11: POTA FILETE C/M C/T FR 1.0 - 2.0 BL10 S20 | E11: 1760 | G11: 10005721 | H11: =1831.106/1000 -> 1.831106 | I11: 0.67 | J11: =$H$47 -> -0.10965909 | K11: =IF(E11<0,0,E11)/1000 -> 1.76 | L11: =IFERROR(H11*K11,0)*1000 -> 3222.7466 | M11: =207.84*K11 -> 365.7984 | N11: =$N$42/$K$40*K11 -> 117.509 | O11: =$O$42/$K$40*K11 -> 231.00278 | P11: =$P$42/$K$40*K11 -> 184.66158 | Q11: 0 | R11: 0 | S11: =L11+M11+N11+O11 -> 3937.0567 | T11: =IFERROR(S11/K11,0) -> 2236.9641
C12: 10005708 | D12: POTA FILETE C/M C/T FR < 0.5 AA BL10 S20 | E12: 1080 | G12: 10005721 | H12: =1831.106/1000 -> 1.831106 | I12: 0.67 | J12: =$H$47 -> -0.10965909 | K12: =IF(E12<0,0,E12)/1000 -> 1.08 | L12: =IFERROR(H12*K12,0)*1000 -> 1977.5945 | M12: =207.84*K12 -> 224.4672 | N12: =$N$42/$K$40*K12 -> 72.107793 | O12: =$O$42/$K$40*K12 -> 141.7517 | P12: =$P$42/$K$40*K12 -> 113.31506 | Q12: 0 | R12: 0 | S12: =L12+M12+N12+O12 -> 2415.9212 | T12: =IFERROR(S12/K12,0) -> 2236.9641
C13: 10005718 | D13: POTA FILETE C/M C/T FR 1.0 - 2.0 AA BL10 S20 | E13: 20240 | G13: 10005721 | H13: =1831.106/1000 -> 1.831106 | I13: 0.67 | J13: =$H$47 -> -0.10965909 | K13: =IF(E13<0,0,E13)/1000 -> 20.24 | L13: =IFERROR(H13*K13,0)*1000 -> 37061.585 | M13: =207.84*K13 -> 4206.6816 | N13: =$N$42/$K$40*K13 -> 1351.3535 | O13: =$O$42/$K$40*K13 -> 2656.5319 | P13: =$P$42/$K$40*K13 -> 2123.6081 | Q13: 0 | R13: 0 | S13: =L13+M13+N13+O13 -> 45276.152 | T13: =IFERROR(S13/K13,0) -> 2236.9641
C14: 10010126 | D14: POTA FILETE C/M C/T FR 1.0 - 3.0 AA BL10 S20 | E14: 5280 | G14: 10005721 | H14: =1831.106/1000 -> 1.831106 | I14: 0.67 | J14: =$H$47 -> -0.10965909 | K14: =IF(E14<0,0,E14)/1000 -> 5.28 | L14: =IFERROR(H14*K14,0)*1000 -> 9668.2397 | M14: =207.84*K14 -> 1097.3952 | N14: =$N$42/$K$40*K14 -> 352.52699 | O14: =$O$42/$K$40*K14 -> 693.00833 | P14: =$P$42/$K$40*K14 -> 553.98473 | Q14: 0 | R14: 0 | S14: =L14+M14+N14+O14 -> 11811.17 | T14: =IFERROR(S14/K14,0) -> 2236.9641
C15: 10005721 | D15: POTA FILETE C/M C/T FR 2.0 - 4.0 AA BL10 S20 | E15: 3100 | G15: 10005721 | H15: =1831.106/1000 -> 1.831106 | I15: 0.67 | J15: =$H$47 -> -0.10965909 | K15: =IF(E15<0,0,E15)/1000 -> 3.1 | L15: =IFERROR(H15*K15,0)*1000 -> 5676.4286 | M15: =207.84*K15 -> 644.304 | N15: =$N$42/$K$40*K15 -> 206.97607 | O15: =$O$42/$K$40*K15 -> 406.87989 | P15: =$P$42/$K$40*K15 -> 325.25618 | Q15: 0 | R15: 0 | S15: =L15+M15+N15+O15 -> 6934.5886 | T15: =IFERROR(S15/K15,0) -> 2236.9641
C16: 10009298 | D16: POTA FILETE S/M S/T FR 1.0-2.0 CM/ESP BL10 S20 | E16: 3200 | G16: 10005721 | H16: =1831.106/1000 -> 1.831106 | I16: 0.67 | J16: =$H$47 -> -0.10965909 | K16: =IF(E16<0,0,E16)/1000 -> 3.2 | L16: =IFERROR(H16*K16,0)*1000 -> 5859.5392 | M16: =207.84*K16 -> 665.088 | N16: =$N$42/$K$40*K16 -> 213.65272 | O16: =$O$42/$K$40*K16 -> 420.00505 | P16: =$P$42/$K$40*K16 -> 335.74832 | Q16: 0 | R16: 0 | S16: =L16+M16+N16+O16 -> 7158.285 | T16: =IFERROR(S16/K16,0) -> 2236.9641
C17: 10009239 | D17: POTA FILETE PRE COCIDO S/M S/T C/P S/COD BL10 S20 | E17: 16480 | G17: 10009239 | H17: =2846.957/1000 -> 2.846957 | I17: 0.56 | J17: =$H$47 -> -0.10965909 | K17: =IF(E17<0,0,E17)/1000 -> 16.48 | L17: =IFERROR(H17*K17,0)*1000 -> 46917.851 | M17: =207.84*K17 -> 3425.2032 | N17: =$N$42/$K$40*K17 -> 1100.3115 | O17: =$O$42/$K$40*K17 -> 2163.026 | P17: =$P$42/$K$40*K17 -> 1729.1038 | Q17: 0 | R17: 0 | S17: =L17+M17+N17+O17 -> 53606.392 | T17: =IFERROR(S17/K17,0) -> 3252.8151
C18: 10009251 | D18: POTA FILETE PRE COCIDO S/M S/T 0.6 - 1.0 BL10 S20 | E18: 20 | G18: 10009239 | H18: =2846.957/1000 -> 2.846957 | I18: 0.56 | J18: =$H$47 -> -0.10965909 | K18: =IF(E18<0,0,E18)/1000 -> 0.02 | L18: =IFERROR(H18*K18,0)*1000 -> 56.93914 | M18: =207.84*K18 -> 4.1568 | N18: =$N$42/$K$40*K18 -> 1.3353295 | O18: =$O$42/$K$40*K18 -> 2.6250315 | P18: =$P$42/$K$40*K18 -> 2.098427 | Q18: 0 | R18: 0 | S18: =L18+M18+N18+O18 -> 65.056301 | T18: =IFERROR(S18/K18,0) -> 3252.8151
D19: POTA CONOS | G19: 10007969 | H19: =1226.35851472471/1000 -> 1.2263585 | I19: 0.56 | J19: =$H$47 -> -0.10965909 | K19: =IF(E19<0,0,E19)/1000 -> 0 | L19: =IFERROR(H19*K19,0)*1000 -> 0 | M19: =207.84*K19 -> 0 | N19: =$N$42/$K$40*K19 -> 0 | O19: =$O$42/$K$40*K19 -> 0 | P19: =$P$42/$K$40*K19 -> 0 | Q19: 0 | R19: 0 | S19: =L19+M19+N19+O19 -> 0 | T19: =IFERROR(S19/K19,0) -> 0
C20: 10009183 | D20: POTA NUCAS CERRADAS < 0.1 BL10 S20 | E20: 1040 | G20: 10005779 | H20: =1793.326/1000 -> 1.793326 | I20: 0.65 | J20: =$H$47 -> -0.10965909 | K20: =IF(E20<0,0,E20)/1000 -> 1.04 | L20: =IFERROR(H20*K20,0)*1000 -> 1865.059 | M20: =207.84*K20 -> 216.1536 | N20: =$N$42/$K$40*K20 -> 69.437134 | O20: =$O$42/$K$40*K20 -> 136.50164 | P20: =$P$42/$K$40*K20 -> 109.1182 | Q20: 0 | R20: 0 | S20: =L20+M20+N20+O20 -> 2287.1514 | T20: =IFERROR(S20/K20,0) -> 2199.1841
C21: 10009271 | D21: POTA NUCAS CERRADAS 0.1 - 0.3 BL10 S20 | E21: 41820 | G21: 10005779 | H21: =1793.326/1000 -> 1.793326 | I21: 0.65 | J21: =$H$47 -> -0.10965909 | K21: =IF(E21<0,0,E21)/1000 -> 41.82 | L21: =IFERROR(H21*K21,0)*1000 -> 74996.893 | M21: =207.84*K21 -> 8691.8688 | N21: =$N$42/$K$40*K21 -> 2792.174 | O21: =$O$42/$K$40*K21 -> 5488.941 | P21: =$P$42/$K$40*K21 -> 4387.8109 | Q21: 0 | R21: 0 | S21: =L21+M21+N21+O21 -> 91969.877 | T21: =IFERROR(S21/K21,0) -> 2199.1841
C22: 10009184 | D22: POTA NUCAS FR ABIERTAS 0.1 - 0.3 BL10 S20 | E22: 138020 | G22: 10005779 | H22: =1793.326/1000 -> 1.793326 | I22: 0.65 | J22: =$H$47 -> -0.10965909 | K22: =IF(E22<0,0,E22)/1000 -> 138.02 | L22: =IFERROR(H22*K22,0)*1000 -> 247514.85 | M22: =207.84*K22 -> 28686.077 | N22: =$N$42/$K$40*K22 -> 9215.1089 | O22: =$O$42/$K$40*K22 -> 18115.343 | P22: =$P$42/$K$40*K22 -> 14481.245 | Q22: 0 | R22: 0 | S22: =L22+M22+N22+O22 -> 303531.38 | T22: =IFERROR(S22/K22,0) -> 2199.1841
C23: 10005776 | D23: POTA NUCAS FR ABIERTAS 0.3 - 0.5 BL10 S20 | E23: 174240 | G23: 10005779 | H23: =1793.326/1000 -> 1.793326 | I23: 0.65 | J23: =$H$47 -> -0.10965909 | K23: =IF(E23<0,0,E23)/1000 -> 174.24 | L23: =IFERROR(H23*K23,0)*1000 -> 312469.12 | M23: =207.84*K23 -> 36214.042 | N23: =$N$42/$K$40*K23 -> 11633.391 | O23: =$O$42/$K$40*K23 -> 22869.275 | P23: =$P$42/$K$40*K23 -> 18281.496 | Q23: 0 | R23: 0 | S23: =L23+M23+N23+O23 -> 383185.83 | T23: =IFERROR(S23/K23,0) -> 2199.1841
C24: 10005779 | D24: POTA NUCAS FR ABIERTAS 0.5 - 1.0 BL10 S20 | E24: 0 | G24: 10005779 | H24: =1793.326/1000 -> 1.793326 | I24: 0.65 | J24: =$H$47 -> -0.10965909 | K24: =IF(E24<0,0,E24)/1000 -> 0 | L24: =IFERROR(H24*K24,0)*1000 -> 0 | M24: =207.84*K24 -> 0 | N24: =$N$42/$K$40*K24 -> 0 | O24: =$O$42/$K$40*K24 -> 0 | P24: =$P$42/$K$40*K24 -> 0 | Q24: 0 | R24: 0 | S24: =L24+M24+N24+O24 -> 0 | T24: =IFERROR(S24/K24,0) -> 0
C25: 10005781 | D25: POTA NUCAS FR ABIERTAS 1.0 - 2.0 BL10 S20 | E25: 0 | G25: 10005779 | H25: =1793.326/1000 -> 1.793326 | I25: 0.65 | J25: =$H$47 -> -0.10965909 | K25: =IF(E25<0,0,E25)/1000 -> 0 | L25: =IFERROR(H25*K25,0)*1000 -> 0 | M25: =207.84*K25 -> 0 | N25: =$N$42/$K$40*K25 -> 0 | O25: =$O$42/$K$40*K25 -> 0 | P25: =$P$42/$K$40*K25 -> 0 | Q25: 0 | R25: 0 | S25: =L25+M25+N25+O25 -> 0 | T25: =IFERROR(S25/K25,0) -> 0
C26: 10009186 | D26: POTA REJOS FR S-S/POR C/UV 0.1 - 0.3 BL10 S20 | E26: 40 | G26: 10007162 | H26: =1783.985/1000 -> 1.783985 | I26: 0.68 | J26: =$H$47 -> -0.10965909 | K26: =IF(E26<0,0,E26)/1000 -> 0.04 | L26: =IFERROR(H26*K26,0)*1000 -> 71.3594 | M26: =207.84*K26 -> 8.3136 | N26: =$N$42/$K$40*K26 -> 2.670659 | O26: =$O$42/$K$40*K26 -> 5.2500631 | P26: =$P$42/$K$40*K26 -> 4.196854 | Q26: 0 | R26: 0 | S26: =L26+M26+N26+O26 -> 87.593722 | T26: =IFERROR(S26/K26,0) -> 2189.8431
C27: 10009187 | D27: POTA REJOS FR C/B S/U S/V S/OR 0.3 - 0.5 BL10 S20 | E27: 120 | G27: 10007162 | H27: =1783.985/1000 -> 1.783985 | I27: 0.68 | J27: =$H$47 -> -0.10965909 | K27: =IF(E27<0,0,E27)/1000 -> 0.12 | L27: =IFERROR(H27*K27,0)*1000 -> 214.0782 | M27: =207.84*K27 -> 24.9408 | N27: =$N$42/$K$40*K27 -> 8.011977 | O27: =$O$42/$K$40*K27 -> 15.750189 | P27: =$P$42/$K$40*K27 -> 12.590562 | Q27: 0 | R27: 0 | S27: =L27+M27+N27+O27 -> 262.78117 | T27: =IFERROR(S27/K27,0) -> 2189.8431
C28: 10007161 | D28: POTA REJOS FR C/B S/U S/V S/OR 0.5 - 1.0 BL10 S20 | E28: 3800 | G28: 10007162 | H28: =1783.985/1000 -> 1.783985 | I28: 0.68 | J28: =$H$47 -> -0.10965909 | K28: =IF(E28<0,0,E28)/1000 -> 3.8 | L28: =IFERROR(H28*K28,0)*1000 -> 6779.143 | M28: =207.84*K28 -> 789.792 | N28: =$N$42/$K$40*K28 -> 253.7126 | O28: =$O$42/$K$40*K28 -> 498.75599 | P28: =$P$42/$K$40*K28 -> 398.70113 | Q28: 0 | R28: 0 | S28: =L28+M28+N28+O28 -> 8321.4036 | T28: =IFERROR(S28/K28,0) -> 2189.8431
C29: 10007162 | D29: POTA REJOS FR C/B S/U S/V S/OR 1.0 - 2.0 BL10 S20 | E29: 172700 | G29: 10007162 | H29: =1783.985/1000 -> 1.783985 | I29: 0.68 | J29: =$H$47 -> -0.10965909 | K29: =IF(E29<0,0,E29)/1000 -> 172.7 | L29: =IFERROR(H29*K29,0)*1000 -> 308094.21 | M29: =207.84*K29 -> 35893.968 | N29: =$N$42/$K$40*K29 -> 11530.57 | O29: =$O$42/$K$40*K29 -> 22667.147 | P29: =$P$42/$K$40*K29 -> 18119.917 | Q29: 0 | R29: 0 | S29: =L29+M29+N29+O29 -> 378185.9 | T29: =IFERROR(S29/K29,0) -> 2189.8431
C30: 10009639 | D30: POTA REJOS FR C/B S/U S/V S/OR 2.0 - UP BL10 S20 | E30: 37180 | G30: 10007162 | H30: =1783.985/1000 -> 1.783985 | I30: 0.68 | J30: =$H$47 -> -0.10965909 | K30: =IF(E30<0,0,E30)/1000 -> 37.18 | L30: =IFERROR(H30*K30,0)*1000 -> 66328.562 | M30: =207.84*K30 -> 7727.4912 | N30: =$N$42/$K$40*K30 -> 2482.3775 | O30: =$O$42/$K$40*K30 -> 4879.9336 | P30: =$P$42/$K$40*K30 -> 3900.9758 | Q30: 0 | R30: 0 | S30: =L30+M30+N30+O30 -> 81418.365 | T30: =IFERROR(S30/K30,0) -> 2189.8431
C31: 10009777 | D31: POTA REJOS FR S-S/POR C/UV 0.3 - 0.5 BL10 S20 | E31: 12840 | G31: 10007162 | H31: =1783.985/1000 -> 1.783985 | I31: 0.68 | J31: =$H$47 -> -0.10965909 | K31: =IF(E31<0,0,E31)/1000 -> 12.84 | L31: =IFERROR(H31*K31,0)*1000 -> 22906.367 | M31: =207.84*K31 -> 2668.6656 | N31: =$N$42/$K$40*K31 -> 857.28154 | O31: =$O$42/$K$40*K31 -> 1685.2703 | P31: =$P$42/$K$40*K31 -> 1347.1901 | Q31: 0 | R31: 0 | S31: =L31+M31+N31+O31 -> 28117.585 | T31: =IFERROR(S31/K31,0) -> 2189.8431
C32: 10009658 | D32: POTA REJOS FR C/B C/U C/V S/OR 1.0 - UP BL10 S20 | E32: 1960 | G32: 10007162 | H32: =1783.985/1000 -> 1.783985 | I32: 0.68 | J32: =$H$47 -> -0.10965909 | K32: =IF(E32<0,0,E32)/1000 -> 1.96 | L32: =IFERROR(H32*K32,0)*1000 -> 3496.6106 | M32: =207.84*K32 -> 407.3664 | N32: =$N$42/$K$40*K32 -> 130.86229 | O32: =$O$42/$K$40*K32 -> 257.25309 | P32: =$P$42/$K$40*K32 -> 205.64585 | Q32: 0 | R32: 0 | S32: =L32+M32+N32+O32 -> 4292.0924 | T32: =IFERROR(S32/K32,0) -> 2189.8431
C33: 10009975 | D33: POTA REJOS OR FR LIMPIOS <60 CM BL10 S20 | E33: 31120 | G33: 10007567 | H33: =1712.173/1000 -> 1.712173 | I33: 0.68 | J33: =$H$47 -> -0.10965909 | K33: =IF(E33<0,0,E33)/1000 -> 31.12 | L33: =IFERROR(H33*K33,0)*1000 -> 53282.824 | M33: =207.84*K33 -> 6467.9808 | N33: =$N$42/$K$40*K33 -> 2077.7727 | O33: =$O$42/$K$40*K33 -> 4084.5491 | P33: =$P$42/$K$40*K33 -> 3265.1524 | Q33: 0 | R33: 0 | S33: =L33+M33+N33+O33 -> 65913.126 | T33: =IFERROR(S33/K33,0) -> 2118.0311
C34: 10010107 | D34: POTA REJOS OR FR LIMPIOS <60 CM BL10 S20 | E34: 4540 | G34: 10007567 | H34: =1712.173/1000 -> 1.712173 | I34: 0.68 | J34: =$H$47 -> -0.10965909 | K34: =IF(E34<0,0,E34)/1000 -> 4.54 | L34: =IFERROR(H34*K34,0)*1000 -> 7773.2654 | M34: =207.84*K34 -> 943.5936 | N34: =$N$42/$K$40*K34 -> 303.1198 | O34: =$O$42/$K$40*K34 -> 595.88216 | P34: =$P$42/$K$40*K34 -> 476.34293 | Q34: 0 | R34: 0 | S34: =L34+M34+N34+O34 -> 9615.861 | T34: =IFERROR(S34/K34,0) -> 2118.0311
C35: 10009336 | D35: POTA VENTOSAS C/U FR BL10 S20 | E35: 21280 | G35: 10009386 | H35: =3230.80440900563/1000 -> 3.2308044 | I35: 0.68 | J35: =$H$47 -> -0.10965909 | K35: =IF(E35<0,0,E35)/1000 -> 21.28 | L35: =IFERROR(H35*K35,0)*1000 -> 68751.518 | M35: =207.84*K35 -> 4422.8352 | N35: =$N$42/$K$40*K35 -> 1420.7906 | O35: =$O$42/$K$40*K35 -> 2793.0336 | P35: =$P$42/$K$40*K35 -> 2232.7263 | Q35: 0 | R35: 0 | S35: =L35+M35+N35+O35 -> 77388.177 | T35: =IFERROR(S35/K35,0) -> 3636.6625
C36: 10007050 | D36: POTA RECORTES PRE COC BL10 S20 | E36: 49120 | G36: 10007050 | H36: =2246.62/1000 -> 2.24662 | I36: 0.68 | J36: =$H$47 -> -0.10965909 | K36: =IF(E36<0,0,E36)/1000 -> 49.12 | L36: =IFERROR(H36*K36,0)*1000 -> 110353.97 | M36: =207.84*K36 -> 10209.101 | N36: =$N$42/$K$40*K36 -> 3279.5692 | O36: =$O$42/$K$40*K36 -> 6447.0775 | P36: =$P$42/$K$40*K36 -> 5153.7367 | Q36: 0 | R36: 0 | S36: =L36+M36+N36+O36 -> 130289.72 | T36: =IFERROR(S36/K36,0) -> 2652.4781
C37: 10009337 | D37: POTA RECORTES LAM PRE COC (M) BL7.5 S15 | E37: 30990 | G37: 10007050 | H37: =2246.62/1000 -> 2.24662 | I37: 0.68 | J37: =$H$47 -> -0.10965909 | K37: =IF(E37<0,0,E37)/1000 -> 30.99 | L37: =IFERROR(H37*K37,0)*1000 -> 69622.754 | M37: =207.84*K37 -> 6440.9616 | N37: =$N$42/$K$40*K37 -> 2069.0931 | O37: =$O$42/$K$40*K37 -> 4067.4864 | P37: =$P$42/$K$40*K37 -> 3251.5126 | Q37: 0 | R37: 0 | S37: =L37+M37+N37+O37 -> 82200.295 | T37: =IFERROR(S37/K37,0) -> 2652.4781
C38: 10009332 | D38: POTA RECORTES LAM PRE COC (T) BL7.5 S15 | E38: 44225 | G38: 10007050 | H38: =2246.62/1000 -> 2.24662 | I38: 0.68 | J38: =$H$47 -> -0.10965909 | K38: =IF(E38<0,0,E38)/1000 -> 44.225 | L38: =IFERROR(H38*K38,0)*1000 -> 99356.77 | M38: =207.84*K38 -> 9191.724 | N38: =$N$42/$K$40*K38 -> 2952.7474 | O38: =$O$42/$K$40*K38 -> 5804.601 | P38: =$P$42/$K$40*K38 -> 4640.1467 | Q38: 0 | R38: 0 | S38: =L38+M38+N38+O38 -> 117305.84 | T38: =IFERROR(S38/K38,0) -> 2652.4781
C39: 10009207 | D39: POTA LABIOS FR S/COD BL10 S20 | E39: 30940 | G39: 10009207 | H39: =1408.57659987072/1000 -> 1.4085766 | I39: 0.71 | J39: =$H$47 -> -0.10965909 | K39: =IF(E39<0,0,E39)/1000 -> 30.94 | L39: =IFERROR(H39*K39,0)*1000 -> 43581.36 | M39: =207.84*K39 -> 6430.5696 | N39: =$N$42/$K$40*K39 -> 2065.7547 | O39: =$O$42/$K$40*K39 -> 4060.9238 | P39: =$P$42/$K$40*K39 -> 3246.2666 | Q39: 0 | R39: 0 | S39: =L39+M39+N39+O39 -> 56138.608 | T39: =IFERROR(S39/K39,0) -> 1814.4347
E40: =SUM(E3:E39) -> 1176923 | K40: =SUM(K3:K39) -> 1176.923 | L40: =SUM(L3:L39) -> 2440416.8 | M40: =SUM(M3:M39) -> 244611.68 | N40: =SUM(N3:N39) -> 78579 | O40: =SUM(O3:O39) -> 154473 | P40: =SUM(P3:P39) -> 123484.35 | Q40: =SUM(Q3:Q39) -> 0 | R40: =SUM(R3:R39) -> 0 | S40: =SUM(S3:S39) -> 2918080.4 | T40: =IFERROR(S40/K40,0) -> 2479.4149
M42: totales | N42: 78579 | O42: 154473 | P42: 123484.35
...
