Workbook

Sheet RESUMEN AL 22-6-2026
C2: PERU FROST
C3: AVANCE COMERCIAL AL 22-6-2026
F5: RENTABILIDAD DEL INVENTARIO | X5: 46174 | AA5: 46182 | AD5: 46185 | AG5: 46188 | AJ5: 46192 | AM5: 46195 | AP5: 46196 | AS5: 46199 | AV5: 46203 | AY5: TOTAL PROYECTADO JUNIO 2026 | BM5: UNITARIOS POR TM
B6: Código | C6: Producto | D6: TM en Stock Libre | E6: CU | F6: Costo Ventas | G6: Gasto Ventas | H6: Gasto ADM | I6: Gasto Fin | J6: Depreciación | K6: Utilidad Neta | L6: Margen Neto | M6: Venta Equilibrio a Utd Neta | N6: Precio Equilibrio x TM a Utd Neta | O6: Venta Equilibro a EBITDA | P6: Precio Equilibrio x TM a EBITDA | Q6: Precio Mercado | R6: Venta total | S6: Utilidad | T6: Mg Neto | U6: EBITDA | V6: Mg EBITDA | X6: TM | Y6: Venta | Z6: Precio x TM | AA6: TM | AB6: Venta | AC6: Precio x TM | AD6: TM | AE6: Venta | AF6: Precio x TM | AG6: TM | AH6: Venta | AI6: Precio x TM | AJ6: TM | AK6: Venta | AL6: Precio x TM | AM6: TM | AN6: Venta | AO6: Precio x TM | AP6: TM | AQ6: Venta | AR6: Precio x TM | AS6: TM | AT6: Venta | AU6: Precio x TM | AV6: TM | AW6: Venta | AX6: Precio x TM | AY6: TM | AZ6: Venta | BA6: Precio x TM | BB6: Costo Ventas | BC6: Gasto Ventas | BD6: Gasto Adm | BE6: Gasto Fin | BF6: Depreciación | BG6: Drawback | BH6: Utilidad Neta | BI6: Mg Neto % | BJ6: EBITDA | BK6: MG EBITDA | BM6: Precio x TM | BN6: Costo Ventas | BO6: Gasto Ventas | BP6: Gasto Adm | BQ6: Gasto Fin | BR6: Depreciación | BS6: Drawback | BT6: Utilidad Neta | BU6: EBITDA
B7: 10005721 | C7: POTA FILETE CONGELADO | D7: =TD!F4 -> 591.56 | E7: =IFERROR(F7/D7,0) -> 1984.5862 | F7: =TD!G4 -> 1174001.8 | G7: =TD!H4 -> 122949.83 | H7: =TD!I4 -> 35479.621 | I7: =TD!J4 -> 69746.924 | J7: =TD!K4 -> 55755.074 | K7: 0 | L7: 0 | M7: =F7+G7+H7+I7 -> 1402178.2 | N7: =IFERROR(M7/D7,0) -> 2370.3059 | O7: =F7+G7+H7-J7 -> 1276676.2 | P7: =IFERROR(O7/D7,0) -> 2158.1516 | Q7: 2000 | R7: =Q7*D7 -> 1183120 | S7: =R7-M7+(Q7-$BD$22)*D7*0.03 -> -185590.86 | T7: =IFERROR(S7/R7,0) -> -0.15686563 | U7: =R7-(M7-J7-I7)+(Q7-$BD$22)*D7*0.03 -> -60088.862 | V7: =IFERROR(U7/R7,0) -> -0.050788476 | X7: {=SUM([3]Hoja2!$I$6:$I$26*([3]Hoja2!$F$6:$F$26=X$5)*([3]Hoja2!$K$6:$K$26=$C7))} -> 0 | Y7: {=SUM([3]Hoja2!$J$6:$J$26*([3]Hoja2!$F$6:$F$26=X$5)*([3]Hoja2!$K$6:$K$26=$C7))} -> 0 | Z7: =IFERROR(Y7/X7,0) -> 0 | AA7: {=SUM([3]Hoja2!$I$6:$I$26*([3]Hoja2!$F$6:$F$26=AA$5)*([3]Hoja2!$K$6:$K$26=$C7))} -> 0 | AB7: {=SUM([3]Hoja2!$J$6:$J$26*([3]Hoja2!$F$6:$F$26=AA$5)*([3]Hoja2!$K$6:$K$26=$C7))} -> 0 | AC7: =IFERROR(AB7/AA7,0) -> 0 | AD7: {=SUM([3]Hoja2!$I$6:$I$26*([3]Hoja2!$F$6:$F$26=AD$5)*([3]Hoja2!$K$6:$K$26=$C7))} -> 0 | AE7: {=SUM([3]Hoja2!$J$6:$J$26*([3]Hoja2!$F$6:$F$26=AD$5)*([3]Hoja2!$K$6:$K$26=$C7))} -> 0 | AF7: =IFERROR(AE7/AD7,0) -> 0 | AG7: {=SUM([3]Hoja2!$I$6:$I$26*([3]Hoja2!$F$6:$F$26=AG$5)*([3]Hoja2!$K$6:$K$26=$C7))} -> 0 | AH7: {=SUM([3]Hoja2!$J$6:$J$26*([3]Hoja2!$F$6:$F$26=AG$5)*([3]Hoja2!$K$6:$K$26=$C7))} -> 0 | AI7: =IFERROR(AH7/AG7,0) -> 0 | AJ7: {=SUM([3]Hoja2!$I$6:$I$26*([3]Hoja2!$F$6:$F$26=AJ$5)*([3]Hoja2!$K$6:$K$26=$C7))} -> 54 | AK7: {=SUM([3]Hoja2!$J$6:$J$26*([3]Hoja2!$F$6:$F$26=AJ$5)*([3]Hoja2!$K$6:$K$26=$C7))} -> 109080 | AL7: =IFERROR(AK7/AJ7,0) -> 2020 | AM7: {=SUM([3]Hoja2!$I$6:$I$26*([3]Hoja2!$F$6:$F$26=AM$5)*([3]Hoja2!$K$6:$K$26=$C7))} -> 48 | AN7: {=SUM([3]Hoja2!$J$6:$J$26*([3]Hoja2!$F$6:$F$26=AM$5)*([3]Hoja2!$K$6:$K$26=$C7))} -> 81600 | AO7: =IFERROR(AN7/AM7,0) -> 1700 | AP7: {=SUM([3]Hoja2!$I$6:$I$26*([3]Hoja2!$F$6:$F$26=AP$5)*([3]Hoja2!$K$6:$K$26=$C7))} -> 27 | AQ7: {=SUM([3]Hoja2!$J$6:$J$26*([3]Hoja2!$F$6:$F$26=AP$5)*([3]Hoja2!$K$6:$K$26=$C7))} -> 54540 | AR7: =IFERROR(AQ7/AP7,0) -> 2020 | AS7: {=SUM([3]Hoja2!$I$6:$I$26*([3]Hoja2!$F$6:$F$26=AS$5)*([3]Hoja2!$K$6:$K$26=$C7))} -> 0 | AT7: {=SUM([3]Hoja2!$J$6:$J$26*([3]Hoja2!$F$6:$F$26=AS$5)*([3]Hoja2!$K$6:$K$26=$C7))} -> 0 | AU7: =IFERROR(AT7/AS7,0) -> 0 | AV7: {=SUM([3]Hoja2!$I$6:$I$26*([3]Hoja2!$F$6:$F$26=AV$5)*([3]Hoja2!$K$6:$K$26=$C7))} -> 0 | AW7: {=SUM([3]Hoja2!$J$6:$J$26*([3]Hoja2!$F$6:$F$26=AV$5)*([3]Hoja2!$K$6:$K$26=$C7))} -> 0 | AX7: =IFERROR(AW7/AV7,0) -> 0 | AY7: =X7+AA7+AD7+AG7+AJ7+AM7+AV7+AP7+AS7 -> 129 | AZ7: =Y7+AB7+AE7+AH7+AK7+AN7+AW7+AQ7+AT7 -> 245220 | BA7: =IFERROR(AZ7/AY7,0) -> 1900.9302 | BB7: =-IFERROR(F7/D7*AY7,0) -> -256011.62 | BC7: =-207.84*AY7 -> -26811.36 | BD7: =$BD$18/$AY$18*$AY7 -> -9167.0052 | BE7: =$BE$18/$AY$18*$AY7 -> -18020.779 | BF7: =$BF$18/$AY$18*$AY7 -> -14405.651 | BG7: =(AZ7-AY7*$BD$22)*0.03 -> 6914.7326 | BH7: =AZ7+SUM(BB7:BE7,BG7) -> -57876.028 | BI7: =IFERROR(BH7/AZ7,0) -> -0.23601675 | BJ7: =AZ7+BB7+BC7+BD7+BG7-BF7 -> -25449.598 | BK7: =IFERROR(BJ7/AZ7,0) -> -0.10378272 | BM7: =BA7 -> 1900.9302 | BN7: =IFERROR(BB7/$AY7,0) -> -1984.5862 | BO7: =IFERROR(BC7/$AY7,0) -> -207.84 | BP7: =IFERROR(BD7/$AY7,0) -> -71.062056 | BQ7: =IFERROR(BE7/$AY7,0) -> -139.69596 | BR7: =IFERROR(BF7/$AY7,0) -> -111.67172 | BS7: =IFERROR(BG7/$AY7,0) -> 53.602579 | BT7: =IFERROR(BH7/$AY7,0) -> -448.65138 | BU7: =IFERROR(BJ7/$AY7,0) -> -197.2837 | BV7: =BU7-BT7 -> 251.36768
B8: 10005779 | C8: POTA NUCAS CONGELADAS | D8: =TD!F5 -> 273.58 | E8: =IFERROR(F8/D8,0) -> 1622.0104 | F8: =TD!G5 -> 443749.6 | G8: =TD!H5 -> 56860.867 | H8: =TD!I5 -> 16408.335 | I8: =TD!J5 -> 32256.007 | J8: =TD!K5 -> 25785.167 | K8: 0 | L8: 0 | M8: =F8+G8+H8+I8 -> 549274.81 | N8: =IFERROR(M8/D8,0) -> 2007.7301 | O8: =F8+G8+H8-J8 -> 491233.64 | P8: =IFERROR(O8/D8,0) -> 1795.5758 | Q8: 1350 | R8: =Q8*D8 -> 369333 | S8: =R8-M8+(Q8-$BD$22)*D8*0.03 -> -169798.92 | T8: =IFERROR(S8/R8,0) -> -0.4597448 | U8: =R8-(M8-J8-I8)+(Q8-$BD$22)*D8*0.03 -> -111757.75 | V8: =IFERROR(U8/R8,0) -> -0.30259346 | X8: {=SUM([3]Hoja2!$I$6:$I$26*([3]Hoja2!$F$6:$F$26=X$5)*([3]Hoja2!$K$6:$K$26=$C8))} -> 0 | Y8: {=SUM([3]Hoja2!$J$6:$J$26*([3]Hoja2!$F$6:$F$26=X$5)*([3]Hoja2!$K$6:$K$26=$C8))} -> 0 | Z8: =IFERROR(Y8/X8,0) -> 0 | AA8: {=SUM([3]Hoja2!$I$6:$I$26*([3]Hoja2!$F$6:$F$26=AA$5)*([3]Hoja2!$K$6:$K$26=$C8))} -> 22.5 | AB8: {=SUM([3]Hoja2!$J$6:$J$26*([3]Hoja2!$F$6:$F$26=AA$5)*([3]Hoja2!$K$6:$K$26=$C8))} -> 29250 | AC8: =IFERROR(AB8/AA8,0) -> 1300 | AD8: {=SUM([3]Hoja2!$I$6:$I$26*([3]Hoja2!$F$6:$F$26=AD$5)*([3]Hoja2!$K$6:$K$26=$C8))} -> 0 | AE8: {=SUM([3]Hoja2!$J$6:$J$26*([3]Hoja2!$F$6:$F$26=AD$5)*([3]Hoja2!$K$6:$K$26=$C8))} -> 0 | AF8: =IFERROR(AE8/AD8,0) -> 0 | AG8: {=SUM([3]Hoja2!$I$6:$I$26*([3]Hoja2!$F$6:$F$26=AG$5)*([3]Hoja2!$K$6:$K$26=$C8))} -> 0 | AH8: {=SUM([3]Hoja2!$J$6:$J$26*([3]Hoja2!$F$6:$F$26=AG$5)*([3]Hoja2!$K$6:$K$26=$C8))} -> 0 | AI8: =IFERROR(AH8/AG8,0) -> 0 | AJ8: {=SUM([3]Hoja2!$I$6:$I$26*([3]Hoja2!$F$6:$F$26=AJ$5)*([3]Hoja2!$K$6:$K$26=$C8))} -> 0 | AK8: {=SUM([3]Hoja2!$J$6:$J$26*([3]Hoja2!$F$6:$F$26=AJ$5)*([3]Hoja2!$K$6:$K$26=$C8))} -> 0 | AL8: =IFERROR(AK8/AJ8,0) -> 0 | AM8: {=SUM([3]Hoja2!$I$6:$I$26*([3]Hoja2!$F$6:$F$26=AM$5)*([3]Hoja2!$K$6:$K$26=$C8))} -> 0 | AN8: {=SUM([3]Hoja2!$J$6:$J$26*([3]Hoja2!$F$6:$F$26=AM$5)*([3]Hoja2!$K$6:$K$26=$C8))} -> 0 | AO8: =IFERROR(AN8/AM8,0) -> 0 | AP8: {=SUM([3]Hoja2!$I$6:$I$26*([3]Hoja2!$F$6:$F$26=AP$5)*([3]Hoja2!$K$6:$K$26=$C8))} -> 0 | AQ8: {=SUM([3]Hoja2!$J$6:$J$26*([3]Hoja2!$F$6:$F$26=AP$5)*([3]Hoja2!$K$6:$K$26=$C8))} -> 0 | AR8: =IFERROR(AQ8/AP8,0) -> 0 | AS8: {=SUM([3]Hoja2!$I$6:$I$26*([3]Hoja2!$F$6:$F$26=AS$5)*([3]Hoja2!$K$6:$K$26=$C8))} -> 26 | AT8: {=SUM([3]Hoja2!$J$6:$J$26*([3]Hoja2!$F$6:$F$26=AS$5)*([3]Hoja2!$K$6:$K$26=$C8))} -> 35100 | AU8: =IFERROR(AT8/AS8,0) -> 1350 | AV8: {=SUM([3]Hoja2!$I$6:$I$26*([3]Hoja2!$F$6:$F$26=AV$5)*([3]Hoja2!$K$6:$K$26=$C8))} -> 0 | AW8: {=SUM([3]Hoja2!$J$6:$J$26*([3]Hoja2!$F$6:$F$26=AV$5)*([3]Hoja2!$K$6:$K$26=$C8))} -> 0 | AX8: =IFERROR(AW8/AV8,0) -> 0 | AY8: =X8+AA8+AD8+AG8+AJ8+AM8+AV8+AP8+AS8 -> 48.5 | AZ8: =Y8+AB8+AE8+AH8+AK8+AN8+AW8+AQ8+AT8 -> 64350 | BA8: =IFERROR(AZ8/AY8,0) -> 1326.8041 | BB8: =-IFERROR(F8/D8*AY8,0) -> -78667.504 | BC8: =-207.84*AY8 -> -10080.24 | BD8: =$BD$18/$AY$18*$AY8 -> -3446.5097 | BE8: =$BE$18/$AY$18*$AY8 -> -6775.2541 | BF8: =$BF$18/$AY$18*$AY8 -> -5416.0782 | BG8: =(AZ8-AY8*$BD$22)*0.03 -> 1764.3716 | BH8: =AZ8+SUM(BB8:BE8,BG8) -> -32855.136 | BI8: =IFERROR(BH8/AZ8,0) -> -0.51056933 | BJ8: =AZ8+BB8+BC8+BD8+BG8-BF8 -> -20663.804 | BK8: =IFERROR(BJ8/AZ8,0) -> -0.32111584 | BM8: =BA8 -> 1326.8041 | BN8: =IFERROR(BB8/$AY8,0) -> -1622.0104 | BO8: =IFERROR(BC8/$AY8,0) -> -207.84 | BP8: =IFERROR(BD8/$AY8,0) -> -71.062056 | BQ8: =IFERROR(BE8/$AY8,0) -> -139.69596 | BR8: =IFERROR(BF8/$AY8,0) -> -111.67172 | BS8: =IFERROR(BG8/$AY8,0) -> 36.378795 | BT8: =IFERROR(BH8/$AY8,0) -> -677.42549 | BU8: =IFERROR(BJ8/$AY8,0) -> -426.05782 | BV8: =BU8-BT8 -> 251.36768
B9: 10006719 | C9: POTA ALAS CONGELADAS | D9: =TD!F6 -> 67.28 | E9: =IFERROR(F9/D9,0) -> 1882.6724 | F9: =TD!G6 -> 126666.2 | G9: =TD!H6 -> 13983.475 | H9: =TD!I6 -> 4035.2101 | I9: =TD!J6 -> 7932.5394 | J9: =TD!K6 -> 6341.2019 | K9: 0 | L9: 0 | M9: =F9+G9+H9+I9 -> 152617.42 | N9: =IFERROR(M9/D9,0) -> 2268.3921 | O9: =F9+G9+H9-J9 -> 138343.68 | P9: =IFERROR(O9/D9,0) -> 2056.2378 | Q9: 2300 | R9: =Q9*D9 -> 154744 | S9: =R9-M9+(Q9-$BD$22)*D9*0.03 -> 6538.4427 | T9: =IFERROR(S9/R9,0) -> 0.042253287 | U9: =R9-(M9-J9-I9)+(Q9-$BD$22)*D9*0.03 -> 20812.184 | V9: =IFERROR(U9/R9,0) -> 0.13449429 | X9: {=SUM([3]Hoja2!$I$6:$I$26*([3]Hoja2!$F$6:$F$26=X$5)*([3]Hoja2!$K$6:$K$26=$C9))} -> 0 | Y9: {=SUM([3]Hoja2!$J$6:$J$26*([3]Hoja2!$F$6:$F$26=X$5)*([3]Hoja2!$K$6:$K$26=$C9))} -> 0 | Z9: =IFERROR(Y9/X9,0) -> 0 | AA9: {=SUM([3]Hoja2!$I$6:$I$26*([3]Hoja2!$F$6:$F$26=AA$5)*([3]Hoja2!$K$6:$K$26=$C9))} -> 0 | AB9: {=SUM([3]Hoja2!$J$6:$J$26*([3]Hoja2!$F$6:$F$26=AA$5)*([3]Hoja2!$K$6:$K$26=$C9))} -> 0 | AC9: =IFERROR(AB9/AA9,0) -> 0 | AD9: {=SUM([3]Hoja2!$I$6:$I$26*([3]Hoja2!$F$6:$F$26=AD$5)*([3]Hoja2!$K$6:$K$26=$C9))} -> 69 | AE9: {=SUM([3]Hoja2!$J$6:$J$26*([3]Hoja2!$F$6:$F$26=AD$5)*([3]Hoja2!$K$6:$K$26=$C9))} -> 144900 | AF9: =IFERROR(AE9/AD9,0) -> 2100 | AG9: {=SUM([3]Hoja2!$I$6:$I$26*([3]Hoja2!$F$6:$F$26=AG$5)*([3]Hoja2!$K$6:$K$26=$C9))} -> 0 | AH9: {=SUM([3]Hoja2!$J$6:$J$26*([3]Hoja2!$F$6:$F$26=AG$5)*([3]Hoja2!$K$6:$K$26=$C9))} -> 0 | AI9: =IFERROR(AH9/AG9,0) -> 0 | AJ9: {=SUM([3]Hoja2!$I$6:$I$26*([3]Hoja2!$F$6:$F$26=AJ$5)*([3]Hoja2!$K$6:$K$26=$C9))} -> 27 | AK9: {=SUM([3]Hoja2!$J$6:$J$26*([3]Hoja2!$F$6:$F$26=AJ$5)*([3]Hoja2!$K$6:$K$26=$C9))} -> 59400 | AL9: =IFERROR(AK9/AJ9,0) -> 2200 | AM9: {=SUM([3]Hoja2!$I$6:$I$26*([3]Hoja2!$F$6:$F$26=AM$5)*([3]Hoja2!$K$6:$K$26=$C9))} -> 0 | AN9: {=SUM([3]Hoja2!$J$6:$J$26*([3]Hoja2!$F$6:$F$26=AM$5)*([3]Hoja2!$K$6:$K$26=$C9))} -> 0 | AO9: =IFERROR(AN9/AM9,0) -> 0 | AP9: {=SUM([3]Hoja2!$I$6:$I$26*([3]Hoja2!$F$6:$F$26=AP$5)*([3]Hoja2!$K$6:$K$26=$C9))} -> 0 | AQ9: {=SUM([3]Hoja2!$J$6:$J$26*([3]Hoja2!$F$6:$F$26=AP$5)*([3]Hoja2!$K$6:$K$26=$C9))} -> 0 | AR9: =IFERROR(AQ9/AP9,0) -> 0 | AS9: {=SUM([3]Hoja2!$I$6:$I$26*([3]Hoja2!$F$6:$F$26=AS$5)*([3]Hoja2!$K$6:$K$26=$C9))} -> 0 | AT9: {=SUM([3]Hoja2!$J$6:$J$26*([3]Hoja2!$F$6:$F$26=AS$5)*([3]Hoja2!$K$6:$K$26=$C9))} -> 0 | AU9: =IFERROR(AT9/AS9,0) -> 0 | AV9: {=SUM([3]Hoja2!$I$6:$I$26*([3]Hoja2!$F$6:$F$26=AV$5)*([3]Hoja2!$K$6:$K$26=$C9))} -> 0 | AW9: {=SUM([3]Hoja2!$J$6:$J$26*([3]Hoja2!$F$6:$F$26=AV$5)*([3]Hoja2!$K$6:$K$26=$C9))} -> 0 | AX9: =IFERROR(AW9/AV9,0) -> 0 | AY9: =X9+AA9+AD9+AG9+AJ9+AM9+AV9+AP9+AS9 -> 96 | AZ9: =Y9+AB9+AE9+AH9+AK9+AN9+AW9+AQ9+AT9 -> 204300 | BA9: =IFERROR(AZ9/AY9,0) -> 2128.125 | BB9: =-IFERROR(F9/D9*AY9,0) -> -180736.55 | BC9: =-207.84*AY9 -> -19952.64 | BD9: =$BD$18/$AY$18*$AY9 -> -6821.9574 | BE9: =$BE$18/$AY$18*$AY9 -> -13410.812 | BF9: =$BF$18/$AY$18*$AY9 -> -10720.485 | BG9: =(AZ9-AY9*$BD$22)*0.03 -> 5800.1685 | BH9: =AZ9+SUM(BB9:BE9,BG9) -> -10821.788 | BI9: =IFERROR(BH9/AZ9,0) -> -0.052970082 | BJ9: =AZ9+BB9+BC9+BD9+BG9-BF9 -> 13309.509 | BK9: =IFERROR(BJ9/AZ9,0) -> 0.065146888 | BM9: =BA9 -> 2128.125 | BN9: =IFERROR(BB9/$AY9,0) -> -1882.6724 | BO9: =IFERROR(BC9/$AY9,0) -> -207.84 | BP9: =IFERROR(BD9/$AY9,0) -> -71.062056 | BQ9: =IFERROR(BE9/$AY9,0) -> -139.69596 | BR9: =IFERROR(BF9/$AY9,0) -> -111.67172 | BS9: =IFERROR(BG9/$AY9,0) -> 60.418422 | BT9: =IFERROR(BH9/$AY9,0) -> -112.72696 | BU9: =IFERROR(BJ9/$AY9,0) -> 138.64072 | BV9: =BU9-BT9 -> 251.36768
B10: 10007050 | C10: POTA RECORTES COCIDOS | D10: =TD!F7 -> 131.76 | E10: =IFERROR(F10/D10,0) -> 1443.946 | F10: =TD!G7 -> 190254.32 | G10: =TD!H7 -> 27384.998 | H10: =TD!I7 -> 7902.4864 | I10: =TD!J7 -> 15534.949 | J10: =TD!K7 -> 12418.501 | K10: 0 | L10: 0 | M10: =F10+G10+H10+I10 -> 241076.75 | N10: =IFERROR(M10/D10,0) -> 1829.6657 | O10: =F10+G10+H10-J10 -> 213123.3 | P10: =IFERROR(O10/D10,0) -> 1617.5114 | Q10: 2300 | R10: =Q10*D10 -> 303048 | S10: =R10-M10+(Q10-$BD$22)*D10*0.03 -> 70611.366 | T10: =IFERROR(S10/R10,0) -> 0.2330039 | U10: =R10-(M10-J10-I10)+(Q10-$BD$22)*D10*0.03 -> 98564.817 | V10: =IFERROR(U10/R10,0) -> 0.3252449 | X10: {=SUM([3]Hoja2!$I$6:$I$26*([3]Hoja2!$F$6:$F$26=X$5)*([3]Hoja2!$K$6:$K$26=$C10))} -> 0 | Y10: {=SUM([3]Hoja2!$J$6:$J$26*([3]Hoja2!$F$6:$F$26=X$5)*([3]Hoja2!$K$6:$K$26=$C10))} -> 0 | Z10: =IFERROR(Y10/X10,0) -> 0 | AA10: {=SUM([3]Hoja2!$I$6:$I$26*([3]Hoja2!$F$6:$F$26=AA$5)*([3]Hoja2!$K$6:$K$26=$C10))} -> 0 | AB10: {=SUM([3]Hoja2!$J$6:$J$26*([3]Hoja2!$F$6:$F$26=AA$5)*([3]Hoja2!$K$6:$K$26=$C10))} -> 0 | AC10: =IFERROR(AB10/AA10,0) -> 0 | AD10: {=SUM([3]Hoja2!$I$6:$I$26*([3]Hoja2!$F$6:$F$26=AD$5)*([3]Hoja2!$K$6:$K$26=$C10))} -> 0 | AE10: {=SUM([3]Hoja2!$J$6:$J$26*([3]Hoja2!$F$6:$F$26=AD$5)*([3]Hoja2!$K$6:$K$26=$C10))} -> 0 | AF10: =IFERROR(AE10/AD10,0) -> 0 | AG10: {=SUM([3]Hoja2!$I$6:$I$26*([3]Hoja2!$F$6:$F$26=AG$5)*([3]Hoja2!$K$6:$K$26=$C10))} -> 0 | AH10: {=SUM([3]Hoja2!$J$6:$J$26*([3]Hoja2!$F$6:$F$26=AG$5)*([3]Hoja2!$K$6:$K$26=$C10))} -> 0 | AI10: =IFERROR(AH10/AG10,0) -> 0 | AJ10: {=SUM([3]Hoja2!$I$6:$I$26*([3]Hoja2!$F$6:$F$26=AJ$5)*([3]Hoja2!$K$6:$K$26=$C10))} -> 0 | AK10: {=SUM([3]Hoja2!$J$6:$J$26*([3]Hoja2!$F$6:$F$26=AJ$5)*([3]Hoja2!$K$6:$K$26=$C10))} -> 0 | AL10: =IFERROR(AK10/AJ10,0) -> 0 | AM10: {=SUM([3]Hoja2!$I$6:$I$26*([3]Hoja2!$F$6:$F$26=AM$5)*([3]Hoja2!$K$6:$K$26=$C10))} -> 0 | AN10: {=SUM([3]Hoja2!$J$6:$J$26*([3]Hoja2!$F$6:$F$26=AM$5)*([3]Hoja2!$K$6:$K$26=$C10))} -> 0 | AO10: =IFERROR(AN10/AM10,0) -> 0 | AP10: {=SUM([3]Hoja2!$I$6:$I$26*([3]Hoja2!$F$6:$F$26=AP$5)*([3]Hoja2!$K$6:$K$26=$C10))} -> 0 | AQ10: {=SUM([3]Hoja2!$J$6:$J$26*([3]Hoja2!$F$6:$F$26=AP$5)*([3]Hoja2!$K$6:$K$26=$C10))} -> 0 | AR10: =IFERROR(AQ10/AP10,0) -> 0 | AS10: {=SUM([3]Hoja2!$I$6:$I$26*([3]Hoja2!$F$6:$F$26=AS$5)*([3]Hoja2!$K$6:$K$26=$C10))} -> 0 | AT10: {=SUM([3]Hoja2!$J$6:$J$26*([3]Hoja2!$F$6:$F$26=AS$5)*([3]Hoja2!$K$6:$K$26=$C10))} -> 0 | AU10: =IFERROR(AT10/AS10,0) -> 0 | AV10: {=SUM([3]Hoja2!$I$6:$I$26*([3]Hoja2!$F$6:$F$26=AV$5)*([3]Hoja2!$K$6:$K$26=$C10))} -> 0 | AW10: {=SUM([3]Hoja2!$J$6:$J$26*([3]Hoja2!$F$6:$F$26=AV$5)*([3]Hoja2!$K$6:$K$26=$C10))} -> 0 | AX10: =IFERROR(AW10/AV10,0) -> 0 | AY10: =X10+AA10+AD10+AG10+AJ10+AM10+AV10+AP10+AS10 -> 0 | AZ10: =Y10+AB10+AE10+AH10+AK10+AN10+AW10+AQ10+AT10 -> 0 | BA10: =IFERROR(AZ10/AY10,0) -> 0 | BB10: =-IFERROR(F10/D10*AY10,0) -> 0 | BC10: =-207.84*AY10 -> 0 | BD10: =$BD$18/$AY$18*$AY10 -> 0 | BE10: =$BE$18/$AY$18*$AY10 -> 0 | BF10: =$BF$18/$AY$18*$AY10 -> 0 | BG10: =(AZ10-AY10*$BD$22)*0.03 -> 0 | BH10: =AZ10+SUM(BB10:BE10,BG10) -> 0 | BI10: =IFERROR(BH10/AZ10,0) -> 0 | BJ10: =AZ10+BB10+BC10+BD10+BG10-BF10 -> 0 | BK10: =IFERROR(BJ10/AZ10,0) -> 0 | BM10: =BA10 -> 0 | BN10: =IFERROR(BB10/$AY10,0) -> 0 | BO10: =IFERROR(BC10/$AY10,0) -> 0 | BP10: =IFERROR(BD10/$AY10,0) -> 0 | BQ10: =IFERROR(BE10/$AY10,0) -> 0 | BR10: =IFERROR(BF10/$AY10,0) -> 0 | BS10: =IFERROR(BG10/$AY10,0) -> 0 | BT10: =IFERROR(BH10/$AY10,0) -> 0 | BU10: =IFERROR(BJ10/$AY10,0) -> 0 | BV10: =BU10-BT10 -> 0
B11: 10007162 | C11: POTA REJOS CONGELADOS | D11: =TD!F8 -> 102.56 | E11: =IFERROR(F11/D11,0) -> 1740.6978 | F11: =TD!G8 -> 178525.96 | G11: =TD!H8 -> 21316.07 | H11: =TD!I8 -> 6151.1764 | I11: =TD!J8 -> 12092.171 | J11: =TD!K8 -> 9666.3743 | K11: 0 | L11: 0 | M11: =F11+G11+H11+I11 -> 218085.38 | N11: =IFERROR(M11/D11,0) -> 2126.4175 | O11: =F11+G11+H11-J11 -> 196326.84 | P11: =IFERROR(O11/D11,0) -> 1914.2632 | Q11: 2300 | R11: =Q11*D11 -> 235888 | S11: =R11-M11+(Q11-$BD$22)*D11*0.03 -> 24527.957 | T11: =IFERROR(S11/R11,0) -> 0.10398137 | U11: =R11-(M11-J11-I11)+(Q11-$BD$22)*D11*0.03 -> 46286.502 | V11: =IFERROR(U11/R11,0) -> 0.19622237 | X11: {=SUM([3]Hoja2!$I$6:$I$26*([3]Hoja2!$F$6:$F$26=X$5)*([3]Hoja2!$K$6:$K$26=$C11))} -> 0 | Y11: {=SUM([3]Hoja2!$J$6:$J$26*([3]Hoja2!$F$6:$F$26=X$5)*([3]Hoja2!$K$6:$K$26=$C11))} -> 0 | Z11: =IFERROR(Y11/X11,0) -> 0 | AA11: {=SUM([3]Hoja2!$I$6:$I$26*([3]Hoja2!$F$6:$F$26=AA$5)*([3]Hoja2!$K$6:$K$26=$C11))} -> 0 | AB11: {=SUM([3]Hoja2!$J$6:$J$26*([3]Hoja2!$F$6:$F$26=AA$5)*([3]Hoja2!$K$6:$K$26=$C11))} -> 0 | AC11: =IFERROR(AB11/AA11,0) -> 0 | AD11: {=SUM([3]Hoja2!$I$6:$I$26*([3]Hoja2!$F$6:$F$26=AD$5)*([3]Hoja2!$K$6:$K$26=$C11))} -> 27 | AE11: {=SUM([3]Hoja2!$J$6:$J$26*([3]Hoja2!$F$6:$F$26=AD$5)*([3]Hoja2!$K$6:$K$26=$C11))} -> 82350 | AF11: =IFERROR(AE11/AD11,0) -> 3050 | AG11: {=SUM([3]Hoja2!$I$6:$I$26*([3]Hoja2!$F$6:$F$26=AG$5)*([3]Hoja2!$K$6:$K$26=$C11))} -> 26 | AH11: {=SUM([3]Hoja2!$J$6:$J$26*([3]Hoja2!$F$6:$F$26=AG$5)*([3]Hoja2!$K$6:$K$26=$C11))} -> 67600 | AI11: =IFERROR(AH11/AG11,0) -> 2600 | AJ11: {=SUM([3]Hoja2!$I$6:$I$26*([3]Hoja2!$F$6:$F$26=AJ$5)*([3]Hoja2!$K$6:$K$26=$C11))} -> 0 | AK11: {=SUM([3]Hoja2!$J$6:$J$26*([3]Hoja2!$F$6:$F$26=AJ$5)*([3]Hoja2!$K$6:$K$26=$C11))} -> 0 | AL11: =IFERROR(AK11/AJ11,0) -> 0 | AM11: {=SUM([3]Hoja2!$I$6:$I$26*([3]Hoja2!$F$6:$F$26=AM$5)*([3]Hoja2!$K$6:$K$26=$C11))} -> 52 | AN11: {=SUM([3]Hoja2!$J$6:$J$26*([3]Hoja2!$F$6:$F$26=AM$5)*([3]Hoja2!$K$6:$K$26=$C11))} -> 135200 | AO11: =IFERROR(AN11/AM11,0) -> 2600 | AP11: {=SUM([3]Hoja2!$I$6:$I$26*([3]Hoja2!$F$6:$F$26=AP$5)*([3]Hoja2!$K$6:$K$26=$C11))} -> 0 | AQ11: {=SUM([3]Hoja2!$J$6:$J$26*([3]Hoja2!$F$6:$F$26=AP$5)*([3]Hoja2!$K$6:$K$26=$C11))} -> 0 | AR11: =IFERROR(AQ11/AP11,0) -> 0 | AS11: {=SUM([3]Hoja2!$I$6:$I$26*([3]Hoja2!$F$6:$F$26=AS$5)*([3]Hoja2!$K$6:$K$26=$C11))} -> 0 | AT11: {=SUM([3]Hoja2!$J$6:$J$26*([3]Hoja2!$F$6:$F$26=AS$5)*([3]Hoja2!$K$6:$K$26=$C11))} -> 0 | AU11: =IFERROR(AT11/AS11,0) -> 0 | AV11: {=SUM([3]Hoja2!$I$6:$I$26*([3]Hoja2!$F$6:$F$26=AV$5)*([3]Hoja2!$K$6:$K$26=$C11))} -> 162 | AW11: {=SUM([3]Hoja2!$J$6:$J$26*([3]Hoja2!$F$6:$F$26=AV$5)*([3]Hoja2!$K$6:$K$26=$C11))} -> 437400 | AX11: =IFERROR(AW11/AV11,0) -> 2700 | AY11: =X11+AA11+AD11+AG11+AJ11+AM11+AV11+AP11+AS11 -> 267 | AZ11: =Y11+AB11+AE11+AH11+AK11+AN11+AW11+AQ11+AT11 -> 722550 | BA11: =IFERROR(AZ11/AY11,0) -> 2706.1798 | BB11: =-IFERROR(F11/D11*AY11,0) -> -464766.31 | BC11: =-207.84*AY11 -> -55493.28 | BD11: =$BD$18/$AY$18*$AY11 -> -18973.569 | BE11: =$BE$18/$AY$18*$AY11 -> -37298.822 | BF11: =$BF$18/$AY$18*$AY11 -> -29816.348 | BG11: =(AZ11-AY11*$BD$22)*0.03 -> 20761.937 | BH11: =AZ11+SUM(BB11:BE11,BG11) -> 166779.96 | BI11: =IFERROR(BH11/AZ11,0) -> 0.23082134 | BJ11: =AZ11+BB11+BC11+BD11+BG11-BF11 -> 233895.13 | BK11: =IFERROR(BJ11/AZ11,0) -> 0.32370788 | BM11: =BA11 -> 2706.1798 | BN11: =IFERROR(BB11/$AY11,0) -> -1740.6978 | BO11: =IFERROR(BC11/$AY11,0) -> -207.84 | BP11: =IFERROR(BD11/$AY11,0) -> -71.062056 | BQ11: =IFERROR(BE11/$AY11,0) -> -139.69596 | BR11: =IFERROR(BF11/$AY11,0) -> -111.67172 | BS11: =IFERROR(BG11/$AY11,0) -> 77.760065 | BT11: =IFERROR(BH11/$AY11,0) -> 624.64405 | BU11: =IFERROR(BJ11/$AY11,0) -> 876.01173 | BV11: =BU11-BT11 -> 251.36768
B12: 10007567 | C12: POTA REPRODUCTORES | D12: =TD!F9 -> 77.6 | E12: =IFERROR(F12/D12,0) -> 1682.6592 | F12: =TD!G9 -> 130574.35 | G12: =TD!H9 -> 16128.384 | H12: =TD!I9 -> 4654.1663 | I12: =TD!J9 -> 9149.3023 | J12: =TD!K9 -> 7313.8713 | K12: 0 | L12: 0 | M12: =F12+G12+H12+I12 -> 160506.21 | N12: =IFERROR(M12/D12,0) -> 2068.379 | O12: =F12+G12+H12-J12 -> 144043.03 | P12: =IFERROR(O12/D12,0) -> 1856.2247 | Q12: 2700 | R12: =Q12*D12 -> 209520 | S12: =R12-M12+(Q12-$BD$22)*D12*0.03 -> 55033.587 | T12: =IFERROR(S12/R12,0) -> 0.26266508 | U12: =R12-(M12-J12-I12)+(Q12-$BD$22)*D12*0.03 -> 71496.761 | V12: =IFERROR(U12/R12,0) -> 0.34124075 | X12: {=SUM([3]Hoja2!$I$6:$I$26*([3]Hoja2!$F$6:$F$26=X$5)*([3]Hoja2!$K$6:$K$26=$C12))} -> 0 | Y12: {=SUM([3]Hoja2!$J$6:$J$26*([3]Hoja2!$F$6:$F$26=X$5)*([3]Hoja2!$K$6:$K$26=$C12))} -> 0 | Z12: =IFERROR(Y12/X12,0) -> 0 | AA12: {=SUM([3]Hoja2!$I$6:$I$26*([3]Hoja2!$F$6:$F$26=AA$5)*([3]Hoja2!$K$6:$K$26=$C12))} -> 0 | AB12: {=SUM([3]Hoja2!$J$6:$J$26*([3]Hoja2!$F$6:$F$26=AA$5)*([3]Hoja2!$K$6:$K$26=$C12))} -> 0 | AC12: =IFERROR(AB12/AA12,0) -> 0 | AD12: {=SUM([3]Hoja2!$I$6:$I$26*([3]Hoja2!$F$6:$F$26=AD$5)*([3]Hoja2!$K$6:$K$26=$C12))} -> 0 | AE12: {=SUM([3]Hoja2!$J$6:$J$26*([3]Hoja2!$F$6:$F$26=AD$5)*([3]Hoja2!$K$6:$K$26=$C12))} -> 0 | AF12: =IFERROR(AE12/AD12,0) -> 0 | AG12: {=SUM([3]Hoja2!$I$6:$I$26*([3]Hoja2!$F$6:$F$26=AG$5)*([3]Hoja2!$K$6:$K$26=$C12))} -> 0 | AH12: {=SUM([3]Hoja2!$J$6:$J$26*([3]Hoja2!$F$6:$F$26=AG$5)*([3]Hoja2!$K$6:$K$26=$C12))} -> 0 | AI12: =IFERROR(AH12/AG12,0) -> 0 | AJ12: {=SUM([3]Hoja2!$I$6:$I$26*([3]Hoja2!$F$6:$F$26=AJ$5)*([3]Hoja2!$K$6:$K$26=$C12))} -> 0 | AK12: {=SUM([3]Hoja2!$J$6:$J$26*([3]Hoja2!$F$6:$F$26=AJ$5)*([3]Hoja2!$K$6:$K$26=$C12))} -> 0 | AL12: =IFERROR(AK12/AJ12,0) -> 0 | AM12: {=SUM([3]Hoja2!$I$6:$I$26*([3]Hoja2!$F$6:$F$26=AM$5)*([3]Hoja2!$K$6:$K$26=$C12))} -> 27 | AN12: {=SUM([3]Hoja2!$J$6:$J$26*([3]Hoja2!$F$6:$F$26=AM$5)*([3]Hoja2!$K$6:$K$26=$C12))} -> 73710 | AO12: =IFERROR(AN12/AM12,0) -> 2730 | AP12: {=SUM([3]Hoja2!$I$6:$I$26*([3]Hoja2!$F$6:$F$26=AP$5)*([3]Hoja2!$K$6:$K$26=$C12))} -> 0 | AQ12: {=SUM([3]Hoja2!$J$6:$J$26*([3]Hoja2!$F$6:$F$26=AP$5)*([3]Hoja2!$K$6:$K$26=$C12))} -> 0 | AR12: =IFERROR(AQ12/AP12,0) -> 0 | AS12: {=SUM([3]Hoja2!$I$6:$I$26*([3]Hoja2!$F$6:$F$26=AS$5)*([3]Hoja2!$K$6:$K$26=$C12))} -> 0 | AT12: {=SUM([3]Hoja2!$J$6:$J$26*([3]Hoja2!$F$6:$F$26=AS$5)*([3]Hoja2!$K$6:$K$26=$C12))} -> 0 | AU12: =IFERROR(AT12/AS12,0) -> 0 | AV12: {=SUM([3]Hoja2!$I$6:$I$26*([3]Hoja2!$F$6:$F$26=AV$5)*([3]Hoja2!$K$6:$K$26=$C12))} -> 0 | AW12: {=SUM([3]Hoja2!$J$6:$J$26*([3]Hoja2!$F$6:$F$26=AV$5)*([3]Hoja2!$K$6:$K$26=$C12))} -> 0 | AX12: =IFERROR(AW12/AV12,0) -> 0 | AY12: =X12+AA12+AD12+AG12+AJ12+AM12+AV12+AP12+AS12 -> 27 | AZ12: =Y12+AB12+AE12+AH12+AK12+AN12+AW12+AQ12+AT12 -> 73710 | BA12: =IFERROR(AZ12/AY12,0) -> 2730 | BB12: =-IFERROR(F12/D12*AY12,0) -> -45431.799 | BC12: =-207.84*AY12 -> -5611.68 | BD12: =$BD$18/$AY$18*$AY12 -> -1918.6755 | BE12: =$BE$18/$AY$18*$AY12 -> -3771.791 | BF12: =$BF$18/$AY$18*$AY12 -> -3015.1363 | BG12: =(AZ12-AY12*$BD$22)*0.03 -> 2118.8161 | BH12: =AZ12+SUM(BB12:BE12,BG12) -> 19094.871 | BI12: =IFERROR(BH12/AZ12,0) -> 0.25905401 | BJ12: =AZ12+BB12+BC12+BD12+BG12-BF12 -> 25881.798 | BK12: =IFERROR(BJ12/AZ12,0) -> 0.35113008 | BM12: =BA12 -> 2730 | BN12: =IFERROR(BB12/$AY12,0) -> -1682.6592 | BO12: =IFERROR(BC12/$AY12,0) -> -207.84 | BP12: =IFERROR(BD12/$AY12,0) -> -71.062056 | BQ12: =IFERROR(BE12/$AY12,0) -> -139.69596 | BR12: =IFERROR(BF12/$AY12,0) -> -111.67172 | BS12: =IFERROR(BG12/$AY12,0) -> 78.474672 | BT12: =IFERROR(BH12/$AY12,0) -> 707.21745 | BU12: =IFERROR(BJ12/$AY12,0) -> 958.58512 | BV12: =BU12-BT12 -> 251.36768
B13: 10007969 | C13: POTA CONOS | D13: =TD!F10 -> 34.46 | E13: =IFERROR(F13/D13,0) -> 1368.5038 | F13: =TD!G10 -> 47158.641 | G13: =TD!H10 -> 7162.1664 | H13: =TD!I10 -> 2066.7857 | I13: =TD!J10 -> 4062.9505 | J13: =TD!K10 -> 3247.8867 | K13: 0 | L13: 0 | M13: =F13+G13+H13+I13 -> 60450.544 | N13: =IFERROR(M13/D13,0) -> 1754.2236 | O13: =F13+G13+H13-J13 -> 53139.707 | P13: =IFERROR(O13/D13,0) -> 1542.0693 | Q13: 1800 | R13: =Q13*D13 -> 62028 | S13: =R13-M13+(Q13-$BD$22)*D13*0.03 -> 3320.2592 | T13: =IFERROR(S13/R13,0) -> 0.053528393 | U13: =R13-(M13-J13-I13)+(Q13-$BD$22)*D13*0.03 -> 10631.096 | V13: =IFERROR(U13/R13,0) -> 0.17139189 | X13: {=SUM([3]Hoja2!$I$6:$I$26*([3]Hoja2!$F$6:$F$26=X$5)*([3]Hoja2!$K$6:$K$26=$C13))} -> 0 | Y13: {=SUM([3]Hoja2!$J$6:$J$26*([3]Hoja2!$F$6:$F$26=X$5)*([3]Hoja2!$K$6:$K$26=$C13))} -> 0 | Z13: =IFERROR(Y13/X13,0) -> 0 | AA13: {=SUM([3]Hoja2!$I$6:$I$26*([3]Hoja2!$F$6:$F$26=AA$5)*([3]Hoja2!$K$6:$K$26=$C13))} -> 0 | AB13: {=SUM([3]Hoja2!$J$6:$J$26*([3]Hoja2!$F$6:$F$26=AA$5)*([3]Hoja2!$K$6:$K$26=$C13))} -> 0 | AC13: =IFERROR(AB13/AA13,0) -> 0 | AD13: {=SUM([3]Hoja2!$I$6:$I$26*([3]Hoja2!$F$6:$F$26=AD$5)*([3]Hoja2!$K$6:$K$26=$C13))} -> 0 | AE13: {=SUM([3]Hoja2!$J$6:$J$26*([3]Hoja2!$F$6:$F$26=AD$5)*([3]Hoja2!$K$6:$K$26=$C13))} -> 0 | AF13: =IFERROR(AE13/AD13,0) -> 0 | AG13: {=SUM([3]Hoja2!$I$6:$I$26*([3]Hoja2!$F$6:$F$26=AG$5)*([3]Hoja2!$K$6:$K$26=$C13))} -> 0 | AH13: {=SUM([3]Hoja2!$J$6:$J$26*([3]Hoja2!$F$6:$F$26=AG$5)*([3]Hoja2!$K$6:$K$26=$C13))} -> 0 | AI13: =IFERROR(AH13/AG13,0) -> 0 | AJ13: {=SUM([3]Hoja2!$I$6:$I$26*([3]Hoja2!$F$6:$F$26=AJ$5)*([3]Hoja2!$K$6:$K$26=$C13))} -> 27 | AK13: {=SUM([3]Hoja2!$J$6:$J$26*([3]Hoja2!$F$6:$F$26=AJ$5)*([3]Hoja2!$K$6:$K$26=$C13))} -> 46710 | AL13: =IFERROR(AK13/AJ13,0) -> 1730 | AM13: {=SUM([3]Hoja2!$I$6:$I$26*([3]Hoja2!$F$6:$F$26=AM$5)*([3]Hoja2!$K$6:$K$26=$C13))} -> 0 | AN13: {=SUM([3]Hoja2!$J$6:$J$26*([3]Hoja2!$F$6:$F$26=AM$5)*([3]Hoja2!$K$6:$K$26=$C13))} -> 0 | AO13: =IFERROR(AN13/AM13,0) -> 0 | AP13: {=SUM([3]Hoja2!$I$6:$I$26*([3]Hoja2!$F$6:$F$26=AP$5)*([3]Hoja2!$K$6:$K$26=$C13))} -> 0 | AQ13: {=SUM([3]Hoja2!$J$6:$J$26*([3]Hoja2!$F$6:$F$26=AP$5)*([3]Hoja2!$K$6:$K$26=$C13))} -> 0 | AR13: =IFERROR(AQ13/AP13,0) -> 0 | AS13: {=SUM([3]Hoja2!$I$6:$I$26*([3]Hoja2!$F$6:$F$26=AS$5)*([3]Hoja2!$K$6:$K$26=$C13))} -> 0 | AT13: {=SUM([3]Hoja2!$J$6:$J$26*([3]Hoja2!$F$6:$F$26=AS$5)*([3]Hoja2!$K$6:$K$26=$C13))} -> 0 | AU13: =IFERROR(AT13/AS13,0) -> 0 | AV13: {=SUM([3]Hoja2!$I$6:$I$26*([3]Hoja2!$F$6:$F$26=AV$5)*([3]Hoja2!$K$6:$K$26=$C13))} -> 0 | AW13: {=SUM([3]Hoja2!$J$6:$J$26*([3]Hoja2!$F$6:$F$26=AV$5)*([3]Hoja2!$K$6:$K$26=$C13))} -> 0 | AX13: =IFERROR(AW13/AV13,0) -> 0 | AY13: =X13+AA13+AD13+AG13+AJ13+AM13+AV13+AP13+AS13 -> 27 | AZ13: =Y13+AB13+AE13+AH13+AK13+AN13+AW13+AQ13+AT13 -> 46710 | BA13: =IFERROR(AZ13/AY13,0) -> 1730 | BB13: =-IFERROR(F13/D13*AY13,0) -> -36949.603 | BC13: =-207.84*AY13 -> -5611.68 | BD13: =$BD$18/$AY$18*$AY13 -> -1918.6755 | BE13: =$BE$18/$AY$18*$AY13 -> -3771.791 | BF13: =$BF$18/$AY$18*$AY13 -> -3015.1363 | BG13: =(AZ13-AY13*$BD$22)*0.03 -> 1308.8161 | BH13: =AZ13+SUM(BB13:BE13,BG13) -> -232.93331 | BI13: =IFERROR(BH13/AZ13,0) -> -0.0049867975 | BJ13: =AZ13+BB13+BC13+BD13+BG13-BF13 -> 6553.994 | BK13: =IFERROR(BJ13/AZ13,0) -> 0.14031244 | BM13: =BA13 -> 1730 | BN13: =IFERROR(BB13/$AY13,0) -> -1368.5038 | BO13: =IFERROR(BC13/$AY13,0) -> -207.84 | BP13: =IFERROR(BD13/$AY13,0) -> -71.062056 | BQ13: =IFERROR(BE13/$AY13,0) -> -139.69596 | BR13: =IFERROR(BF13/$AY13,0) -> -111.67172 | BS13: =IFERROR(BG13/$AY13,0) -> 48.474672 | BT13: =IFERROR(BH13/$AY13,0) -> -8.6271597 | BU13: =IFERROR(BJ13/$AY13,0) -> 242.74052 | BV13: =BU13-BT13 -> 251.36768
B14: 10009239 | C14: POTA FILETE DARUMA | D14: =TD!F11 -> 0 | E14: =IFERROR(F14/D14,0) -> 0 | F14: =TD!G11 -> 0 | G14: =TD!H11 -> 0 | H14: =TD!I11 -> 0 | I14: =TD!J11 -> 0 | J14: =TD!K11 -> 0 | K14: 0 | L14: 0 | M14: =F14+G14+H14+I14 -> 0 | N14: =IFERROR(M14/D14,0) -> 0 | O14: =F14+G14+H14-J14 -> 0 | P14: =IFERROR(O14/D14,0) -> 0 | Q14: 3900 | R14: =Q14*D14 -> 0 | S14: =R14-M14+(Q14-$BD$22)*D14*0.03 -> 0 | T14: =IFERROR(S14/R14,0) -> 0 | U14: =R14-(M14-J14-I14)+(Q14-$BD$22)*D14*0.03 -> 0 | V14: =IFERROR(U14/R14,0) -> 0 | X14: {=SUM([3]Hoja2!$I$6:$I$26*([3]Hoja2!$F$6:$F$26=X$5)*([3]Hoja2!$K$6:$K$26=$C14))} -> 0 | Y14: {=SUM([3]Hoja2!$J$6:$J$26*([3]Hoja2!$F$6:$F$26=X$5)*([3]Hoja2!$K$6:$K$26=$C14))} -> 0 | Z14: =IFERROR(Y14/X14,0) -> 0 | AA14: {=SUM([3]Hoja2!$I$6:$I$26*([3]Hoja2!$F$6:$F$26=AA$5)*([3]Hoja2!$K$6:$K$26=$C14))} -> 0 | AB14: {=SUM([3]Hoja2!$J$6:$J$26*([3]Hoja2!$F$6:$F$26=AA$5)*([3]Hoja2!$K$6:$K$26=$C14))} -> 0 | AC14: =IFERROR(AB14/AA14,0) -> 0 | AD14: {=SUM([3]Hoja2!$I$6:$I$26*([3]Hoja2!$F$6:$F$26=AD$5)*([3]Hoja2!$K$6:$K$26=$C14))} -> 108 | AE14: {=SUM([3]Hoja2!$J$6:$J$26*([3]Hoja2!$F$6:$F$26=AD$5)*([3]Hoja2!$K$6:$K$26=$C14))} -> 421200 | AF14: =IFERROR(AE14/AD14,0) -> 3900 | AG14: {=SUM([3]Hoja2!$I$6:$I$26*([3]Hoja2!$F$6:$F$26=AG$5)*([3]Hoja2!$K$6:$K$26=$C14))} -> 0 | AH14: {=SUM([3]Hoja2!$J$6:$J$26*([3]Hoja2!$F$6:$F$26=AG$5)*([3]Hoja2!$K$6:$K$26=$C14))} -> 0 | AI14: =IFERROR(AH14/AG14,0) -> 0 | AJ14: {=SUM([3]Hoja2!$I$6:$I$26*([3]Hoja2!$F$6:$F$26=AJ$5)*([3]Hoja2!$K$6:$K$26=$C14))} -> 0 | AK14: {=SUM([3]Hoja2!$J$6:$J$26*([3]Hoja2!$F$6:$F$26=AJ$5)*([3]Hoja2!$K$6:$K$26=$C14))} -> 0 | AL14: =IFERROR(AK14/AJ14,0) -> 0 | AM14: {=SUM([3]Hoja2!$I$6:$I$26*([3]Hoja2!$F$6:$F$26=AM$5)*([3]Hoja2!$K$6:$K$26=$C14))} -> 0 | AN14: {=SUM([3]Hoja2!$J$6:$J$26*([3]Hoja2!$F$6:$F$26=AM$5)*([3]Hoja2!$K$6:$K$26=$C14))} -> 0 | AO14: =IFERROR(AN14/AM14,0) -> 0 | AP14: {=SUM([3]Hoja2!$I$6:$I$26*([3]Hoja2!$F$6:$F$26=AP$5)*([3]Hoja2!$K$6:$K$26=$C14))} -> 0 | AQ14: {=SUM([3]Hoja2!$J$6:$J$26*([3]Hoja2!$F$6:$F$26=AP$5)*([3]Hoja2!$K$6:$K$26=$C14))} -> 0 | AR14: =IFERROR(AQ14/AP14,0) -> 0 | AS14: {=SUM([3]Hoja2!$I$6:$I$26*([3]Hoja2!$F$6:$F$26=AS$5)*([3]Hoja2!$K$6:$K$26=$C14))} -> 162 | AT14: {=SUM([3]Hoja2!$J$6:$J$26*([3]Hoja2!$F$6:$F$26=AS$5)*([3]Hoja2!$K$6:$K$26=$C14))} -> 638550 | AU14: =IFERROR(AT14/AS14,0) -> 3941.6667 | AV14: {=SUM([3]Hoja2!$I$6:$I$26*([3]Hoja2!$F$6:$F$26=AV$5)*([3]Hoja2!$K$6:$K$26=$C14))} -> 54 | AW14: {=SUM([3]Hoja2!$J$6:$J$26*([3]Hoja2!$F$6:$F$26=AV$5)*([3]Hoja2!$K$6:$K$26=$C14))} -> 213300 | AX14: =IFERROR(AW14/AV14,0) -> 3950 | AY14: =X14+AA14+AD14+AG14+AJ14+AM14+AV14+AP14+AS14 -> 324 | AZ14: =Y14+AB14+AE14+AH14+AK14+AN14+AW14+AQ14+AT14 -> 1273050 | BA14: =IFERROR(AZ14/AY14,0) -> 3929.1667 | BB14: =-AY14*'Stock Libre'!H36*1000 -> -1054580.4 | BC14: =-207.84*AY14 -> -67340.16 | BD14: =$BD$18/$AY$18*$AY14 -> -23024.106 | BE14: =$BE$18/$AY$18*$AY14 -> -45261.491 | BF14: =$BF$18/$AY$18*$AY14 -> -36181.636 | BG14: =(AZ14-AY14*$BD$22)*0.03 -> 37081.694 | BH14: =AZ14+SUM(BB14:BE14,BG14) -> 119925.55 | BI14: =IFERROR(BH14/AZ14,0) -> 0.094203328 | BJ14: =AZ14+BB14+BC14+BD14+BG14-BF14 -> 201368.67 | BK14: =IFERROR(BJ14/AZ14,0) -> 0.15817813 | BM14: =BA14 -> 3929.1667 | BN14: =IFERROR(BB14/$AY14,0) -> -3254.8777 | BO14: =IFERROR(BC14/$AY14,0) -> -207.84 | BP14: =IFERROR(BD14/$AY14,0) -> -71.062056 | BQ14: =IFERROR(BE14/$AY14,0) -> -139.69596 | BR14: =IFERROR(BF14/$AY14,0) -> -111.67172 | BS14: =IFERROR(BG14/$AY14,0) -> 114.44967 | BT14: =IFERROR(BH14/$AY14,0) -> 370.14058 | BU14: =IFERROR(BJ14/$AY14,0) -> 621.50825 | BV14: =BU14-BT14 -> 251.36768
B15: 10009334 | C15: POTA ALAS COCIDAS | D15: =TD!F12 -> 2.826 | E15: =IFERROR(F15/D15,0) -> 2824.4285 | F15: =TD!G12 -> 7981.835 | G15: =TD!H12 -> 587.35584 | H15: =TD!I12 -> 169.49322 | I15: =TD!J12 -> 333.19495 | J15: =TD!K12 -> 266.3531 | K15: 0 | L15: 0 | M15: =F15+G15+H15+I15 -> 9071.879 | N15: =IFERROR(M15/D15,0) -> 3210.1483 | O15: =F15+G15+H15-J15 -> 8472.3309 | P15: =IFERROR(O15/D15,0) -> 2997.994 | Q15: 3900 | R15: =Q15*D15 -> 11021.4 | S15: =R15-M15+(Q15-$BD$22)*D15*0.03 -> 2270.483 | T15: =IFERROR(S15/R15,0) -> 0.20600677 | U15: =R15-(M15-J15-I15)+(Q15-$BD$22)*D15*0.03 -> 2870.0311 | V15: =IFERROR(U15/R15,0) -> 0.26040531 | X15: {=SUM([3]Hoja2!$I$6:$I$26*([3]Hoja2!$F$6:$F$26=X$5)*([3]Hoja2!$K$6:$K$26=$C15))} -> 0 | Y15: {=SUM([3]Hoja2!$J$6:$J$26*([3]Hoja2!$F$6:$F$26=X$5)*([3]Hoja2!$K$6:$K$26=$C15))} -> 0 | Z15: =IFERROR(Y15/X15,0) -> 0 | AA15: {=SUM([3]Hoja2!$I$6:$I$26*([3]Hoja2!$F$6:$F$26=AA$5)*([3]Hoja2!$K$6:$K$26=$C15))} -> 26.28 | AB15: {=SUM([3]Hoja2!$J$6:$J$26*([3]Hoja2!$F$6:$F$26=AA$5)*([3]Hoja2!$K$6:$K$26=$C15))} -> 113004 | AC15: =IFERROR(AB15/AA15,0) -> 4300 | AD15: {=SUM([3]Hoja2!$I$6:$I$26*([3]Hoja2!$F$6:$F$26=AD$5)*([3]Hoja2!$K$6:$K$26=$C15))} -> 0 | AE15: {=SUM([3]Hoja2!$J$6:$J$26*([3]Hoja2!$F$6:$F$26=AD$5)*([3]Hoja2!$K$6:$K$26=$C15))} -> 0 | AF15: =IFERROR(AE15/AD15,0) -> 0 | AG15: {=SUM([3]Hoja2!$I$6:$I$26*([3]Hoja2!$F$6:$F$26=AG$5)*([3]Hoja2!$K$6:$K$26=$C15))} -> 0 | AH15: {=SUM([3]Hoja2!$J$6:$J$26*([3]Hoja2!$F$6:$F$26=AG$5)*([3]Hoja2!$K$6:$K$26=$C15))} -> 0 | AI15: =IFERROR(AH15/AG15,0) -> 0 | AJ15: {=SUM([3]Hoja2!$I$6:$I$26*([3]Hoja2!$F$6:$F$26=AJ$5)*([3]Hoja2!$K$6:$K$26=$C15))} -> 54 | AK15: {=SUM([3]Hoja2!$J$6:$J$26*([3]Hoja2!$F$6:$F$26=AJ$5)*([3]Hoja2!$K$6:$K$26=$C15))} -> 232200 | AL15: =IFERROR(AK15/AJ15,0) -> 4300 | AM15: {=SUM([3]Hoja2!$I$6:$I$26*([3]Hoja2!$F$6:$F$26=AM$5)*([3]Hoja2!$K$6:$K$26=$C15))} -> 0 | AN15: {=SUM([3]Hoja2!$J$6:$J$26*([3]Hoja2!$F$6:$F$26=AM$5)*([3]Hoja2!$K$6:$K$26=$C15))} -> 0 | AO15: =IFERROR(AN15/AM15,0) -> 0 | AP15: {=SUM([3]Hoja2!$I$6:$I$26*([3]Hoja2!$F$6:$F$26=AP$5)*([3]Hoja2!$K$6:$K$26=$C15))} -> 27 | AQ15: {=SUM([3]Hoja2!$J$6:$J$26*([3]Hoja2!$F$6:$F$26=AP$5)*([3]Hoja2!$K$6:$K$26=$C15))} -> 116100 | AR15: =IFERROR(AQ15/AP15,0) -> 4300 | AS15: {=SUM([3]Hoja2!$I$6:$I$26*([3]Hoja2!$F$6:$F$26=AS$5)*([3]Hoja2!$K$6:$K$26=$C15))} -> 54 | AT15: {=SUM([3]Hoja2!$J$6:$J$26*([3]Hoja2!$F$6:$F$26=AS$5)*([3]Hoja2!$K$6:$K$26=$C15))} -> 213300 | AU15: =IFERROR(AT15/AS15,0) -> 3950 | AV15: {=SUM([3]Hoja2!$I$6:$I$26*([3]Hoja2!$F$6:$F$26=AV$5)*([3]Hoja2!$K$6:$K$26=$C15))} -> 0 | AW15: {=SUM([3]Hoja2!$J$6:$J$26*([3]Hoja2!$F$6:$F$26=AV$5)*([3]Hoja2!$K$6:$K$26=$C15))} -> 0 | AX15: =IFERROR(AW15/AV15,0) -> 0 | AY15: =X15+AA15+AD15+AG15+AJ15+AM15+AV15+AP15+AS15 -> 161.28 | AZ15: =Y15+AB15+AE15+AH15+AK15+AN15+AW15+AQ15+AT15 -> 674604 | BA15: =IFERROR(AZ15/AY15,0) -> 4182.8125 | BB15: =-AY15*'[2]Stock Libre'!H47*1000 -> -455523.83 | BC15: =-207.84*AY15 -> -33520.435 | BD15: =$BD$18/$AY$18*$AY15 -> -11460.888 | BE15: =$BE$18/$AY$18*$AY15 -> -22530.165 | BF15: =$BF$18/$AY$18*$AY15 -> -18010.414 | BG15: =(AZ15-AY15*$BD$22)*0.03 -> 19685.683 | BH15: =AZ15+SUM(BB15:BE15,BG15) -> 171254.36 | BI15: =IFERROR(BH15/AZ15,0) -> 0.2538591 | BJ15: =AZ15+BB15+BC15+BD15+BG15-BF15 -> 211794.94 | BK15: =IFERROR(BJ15/AZ15,0) -> 0.31395447 | BM15: =BA15 -> 4182.8125 | BN15: =IFERROR(BB15/$AY15,0) -> -2824.4285 | BO15: =IFERROR(BC15/$AY15,0) -> -207.84 | BP15: =IFERROR(BD15/$AY15,0) -> -71.062056 | BQ15: =IFERROR(BE15/$AY15,0) -> -139.69596 | BR15: =IFERROR(BF15/$AY15,0) -> -111.67172 | BS15: =IFERROR(BG15/$AY15,0) -> 122.05905 | BT15: =IFERROR(BH15/$AY15,0) -> 1061.845 | BU15: =IFERROR(BJ15/$AY15,0) -> 1313.2127 | BV15: =BU15-BT15 -> 251.36768
B16: 10009386 | C16: VENTOSAS | D16: =TD!F13 -> 17.14 | E16: =IFERROR(F16/D16,0) -> 1742.1709 | F16: =TD!G13 -> 29860.81 | G16: =TD!H13 -> 3562.3776 | H16: =TD!I13 -> 1027.995 | I16: =TD!J13 -> 2020.8639 | J16: =TD!K13 -> 1615.4608 | K16: 0 | L16: 0 | M16: =F16+G16+H16+I16 -> 36472.046 | N16: =IFERROR(M16/D16,0) -> 2127.8907 | O16: =F16+G16+H16-J16 -> 32835.722 | P16: =IFERROR(O16/D16,0) -> 1915.7364 | Q16: 2000 | R16: =Q16*D16 -> 34280 | S16: =R16-M16+(Q16-$BD$22)*D16*0.03 -> -1222.3563 | T16: =IFERROR(S16/R16,0) -> -0.035658002 | U16: =R16-(M16-J16-I16)+(Q16-$BD$22)*D16*0.03 -> 2413.9684 | V16: =IFERROR(U16/R16,0) -> 0.070419147 | X16: {=SUM([3]Hoja2!$I$6:$I$26*([3]Hoja2!$F$6:$F$26=X$5)*([3]Hoja2!$K$6:$K$26=$C16))} -> 0 | Y16: {=SUM([3]Hoja2!$J$6:$J$26*([3]Hoja2!$F$6:$F$26=X$5)*([3]Hoja2!$K$6:$K$26=$C16))} -> 0 | Z16: =IFERROR(Y16/X16,0) -> 0 | AA16: {=SUM([3]Hoja2!$I$6:$I$26*([3]Hoja2!$F$6:$F$26=AA$5)*([3]Hoja2!$K$6:$K$26=$C16))} -> 0 | AB16: {=SUM([3]Hoja2!$J$6:$J$26*([3]Hoja2!$F$6:$F$26=AA$5)*([3]Hoja2!$K$6:$K$26=$C16))} -> 0 | AC16: =IFERROR(AB16/AA16,0) -> 0 | AD16: {=SUM([3]Hoja2!$I$6:$I$26*([3]Hoja2!$F$6:$F$26=AD$5)*([3]Hoja2!$K$6:$K$26=$C16))} -> 0 | AE16: {=SUM([3]Hoja2!$J$6:$J$26*([3]Hoja2!$F$6:$F$26=AD$5)*([3]Hoja2!$K$6:$K$26=$C16))} -> 0 | AF16: =IFERROR(AE16/AD16,0) -> 0 | AG16: {=SUM([3]Hoja2!$I$6:$I$26*([3]Hoja2!$F$6:$F$26=AG$5)*([3]Hoja2!$K$6:$K$26=$C16))} -> 0 | AH16: {=SUM([3]Hoja2!$J$6:$J$26*([3]Hoja2!$F$6:$F$26=AG$5)*([3]Hoja2!$K$6:$K$26=$C16))} -> 0 | AI16: =IFERROR(AH16/AG16,0) -> 0 | AJ16: {=SUM([3]Hoja2!$I$6:$I$26*([3]Hoja2!$F$6:$F$26=AJ$5)*([3]Hoja2!$K$6:$K$26=$C16))} -> 0 | AK16: {=SUM([3]Hoja2!$J$6:$J$26*([3]Hoja2!$F$6:$F$26=AJ$5)*([3]Hoja2!$K$6:$K$26=$C16))} -> 0 | AL16: =IFERROR(AK16/AJ16,0) -> 0 | AM16: {=SUM([3]Hoja2!$I$6:$I$26*([3]Hoja2!$F$6:$F$26=AM$5)*([3]Hoja2!$K$6:$K$26=$C16))} -> 0 | AN16: {=SUM([3]Hoja2!$J$6:$J$26*([3]Hoja2!$F$6:$F$26=AM$5)*([3]Hoja2!$K$6:$K$26=$C16))} -> 0 | AO16: =IFERROR(AN16/AM16,0) -> 0 | AP16: {=SUM([3]Hoja2!$I$6:$I$26*([3]Hoja2!$F$6:$F$26=AP$5)*([3]Hoja2!$K$6:$K$26=$C16))} -> 0 | AQ16: {=SUM([3]Hoja2!$J$6:$J$26*([3]Hoja2!$F$6:$F$26=AP$5)*([3]Hoja2!$K$6:$K$26=$C16))} -> 0 | AR16: =IFERROR(AQ16/AP16,0) -> 0 | AS16: {=SUM([3]Hoja2!$I$6:$I$26*([3]Hoja2!$F$6:$F$26=AS$5)*([3]Hoja2!$K$6:$K$26=$C16))} -> 0 | AT16: {=SUM([3]Hoja2!$J$6:$J$26*([3]Hoja2!$F$6:$F$26=AS$5)*([3]Hoja2!$K$6:$K$26=$C16))} -> 0 | AU16: =IFERROR(AT16/AS16,0) -> 0 | AV16: {=SUM([3]Hoja2!$I$6:$I$26*([3]Hoja2!$F$6:$F$26=AV$5)*([3]Hoja2!$K$6:$K$26=$C16))} -> 0 | AW16: {=SUM([3]Hoja2!$J$6:$J$26*([3]Hoja2!$F$6:$F$26=AV$5)*([3]Hoja2!$K$6:$K$26=$C16))} -> 0 | AX16: =IFERROR(AW16/AV16,0) -> 0 | AY16: =X16+AA16+AD16+AG16+AJ16+AM16+AV16+AP16+AS16 -> 0 | AZ16: =Y16+AB16+AE16+AH16+AK16+AN16+AW16+AQ16+AT16 -> 0 | BA16: =IFERROR(AZ16/AY16,0) -> 0 | BB16: =-IFERROR(F16/D16*AY16,0) -> 0 | BC16: =-207.84*AY16 -> 0 | BD16: =$BD$18/$AY$18*$AY16 -> 0 | BE16: =$BE$18/$AY$18*$AY16 -> 0 | BF16: =$BF$18/$AY$18*$AY16 -> 0 | BG16: =(AZ16-AY16*$BD$22)*0.03 -> 0 | BH16: =AZ16+SUM(BB16:BE16,BG16) -> 0 | BI16: =IFERROR(BH16/AZ16,0) -> 0 | BJ16: =AZ16+BB16+BC16+BD16+BG16-BF16 -> 0 | BK16: =IFERROR(BJ16/AZ16,0) -> 0 | BM16: =BA16 -> 0 | BN16: =IFERROR(BB16/$AY16,0) -> 0 | BO16: =IFERROR(BC16/$AY16,0) -> 0 | BP16: =IFERROR(BD16/$AY16,0) -> 0 | BQ16: =IFERROR(BE16/$AY16,0) -> 0 | BR16: =IFERROR(BF16/$AY16,0) -> 0 | BS16: =IFERROR(BG16/$AY16,0) -> 0 | BT16: =IFERROR(BH16/$AY16,0) -> 0 | BU16: =IFERROR(BJ16/$AY16,0) -> 0 | BV16: =BU16-BT16 -> 0
B17: 10009386 | C17: OTROS | D17: =TD!F14 -> 11.4 | E17: =IFERROR(F17/D17,0) -> 1416.8705 | F17: =TD!G14 -> 16152.324 | G17: =TD!H14 -> 2369.376 | H17: =TD!I14 -> 683.73061 | I17: =TD!J14 -> 1344.0985 | J17: =TD!K14 -> 1074.4605 | K17: 0 | L17: 0 | M17: =F17+G17+H17+I17 -> 20549.529 | N17: =IFERROR(M17/D17,0) -> 1802.5902 | O17: =F17+G17+H17-J17 -> 18130.97 | P17: =IFERROR(O17/D17,0) -> 1590.4359 | Q17: 2000 | R17: =Q17*D17 -> 22800 | S17: =R17-M17+(Q17-$BD$22)*D17*0.03 -> 2895.4224 | T17: =IFERROR(S17/R17,0) -> 0.12699221 | U17: =R17-(M17-J17-I17)+(Q17-$BD$22)*D17*0.03 -> 5313.9814 | V17: =IFERROR(U17/R17,0) -> 0.23306936 | X17: {=SUM([3]Hoja2!$I$6:$I$26*([3]Hoja2!$F$6:$F$26=X$5)*([3]Hoja2!$K$6:$K$26=$C17))} -> 26 | Y17: {=SUM([3]Hoja2!$J$6:$J$26*([3]Hoja2!$F$6:$F$26=X$5)*([3]Hoja2!$K$6:$K$26=$C17))} -> 36400 | Z17: =IFERROR(Y17/X17,0) -> 1400 | AA17: {=SUM([3]Hoja2!$I$6:$I$26*([3]Hoja2!$F$6:$F$26=AA$5)*([3]Hoja2!$K$6:$K$26=$C17))} -> 0 | AB17: {=SUM([3]Hoja2!$J$6:$J$26*([3]Hoja2!$F$6:$F$26=AA$5)*([3]Hoja2!$K$6:$K$26=$C17))} -> 0 | AC17: =IFERROR(AB17/AA17,0) -> 0 | AD17: {=SUM([3]Hoja2!$I$6:$I$26*([3]Hoja2!$F$6:$F$26=AD$5)*([3]Hoja2!$K$6:$K$26=$C17))} -> 0 | AE17: {=SUM([3]Hoja2!$J$6:$J$26*([3]Hoja2!$F$6:$F$26=AD$5)*([3]Hoja2!$K$6:$K$26=$C17))} -> 0 | AF17: =IFERROR(AE17/AD17,0) -> 0 | AG17: {=SUM([3]Hoja2!$I$6:$I$26*([3]Hoja2!$F$6:$F$26=AG$5)*([3]Hoja2!$K$6:$K$26=$C17))} -> 0 | AH17: {=SUM([3]Hoja2!$J$6:$J$26*([3]Hoja2!$F$6:$F$26=AG$5)*([3]Hoja2!$K$6:$K$26=$C17))} -> 0 | AI17: =IFERROR(AH17/AG17,0) -> 0 | AJ17: {=SUM([3]Hoja2!$I$6:$I$26*([3]Hoja2!$F$6:$F$26=AJ$5)*([3]Hoja2!$K$6:$K$26=$C17))} -> 0 | AK17: {=SUM([3]Hoja2!$J$6:$J$26*([3]Hoja2!$F$6:$F$26=AJ$5)*([3]Hoja2!$K$6:$K$26=$C17))} -> 0 | AL17: =IFERROR(AK17/AJ17,0) -> 0 | AM17: {=SUM([3]Hoja2!$I$6:$I$26*([3]Hoja2!$F$6:$F$26=AM$5)*([3]Hoja2!$K$6:$K$26=$C17))} -> 0 | AN17: {=SUM([3]Hoja2!$J$6:$J$26*([3]Hoja2!$F$6:$F$26=AM$5)*([3]Hoja2!$K$6:$K$26=$C17))} -> 0 | AO17: =IFERROR(AN17/AM17,0) -> 0 | AP17: {=SUM([3]Hoja2!$I$6:$I$26*([3]Hoja2!$F$6:$F$26=AP$5)*([3]Hoja2!$K$6:$K$26=$C17))} -> 0 | AQ17: {=SUM([3]Hoja2!$J$6:$J$26*([3]Hoja2!$F$6:$F$26=AP$5)*([3]Hoja2!$K$6:$K$26=$C17))} -> 0 | AR17: =IFERROR(AQ17/AP17,0) -> 0 | AS17: {=SUM([3]Hoja2!$I$6:$I$26*([3]Hoja2!$F$6:$F$26=AS$5)*([3]Hoja2!$K$6:$K$26=$C17))} -> 0 | AT17: {=SUM([3]Hoja2!$J$6:$J$26*([3]Hoja2!$F$6:$F$26=AS$5)*([3]Hoja2!$K$6:$K$26=$C17))} -> 0 | AU17: =IFERROR(AT17/AS17,0) -> 0 | AV17: {=SUM([3]Hoja2!$I$6:$I$26*([3]Hoja2!$F$6:$F$26=AV$5)*([3]Hoja2!$K$6:$K$26=$C17))} -> 0 | AW17: {=SUM([3]Hoja2!$J$6:$J$26*([3]Hoja2!$F$6:$F$26=AV$5)*([3]Hoja2!$K$6:$K$26=$C17))} -> 0 | AX17: =IFERROR(AW17/AV17,0) -> 0 | AY17: =X17+AA17+AD17+AG17+AJ17+AM17+AV17+AP17+AS17 -> 26 | AZ17: =Y17+AB17+AE17+AH17+AK17+AN17+AW17+AQ17+AT17 -> 36400 | BA17: =IFERROR(AZ17/AY17,0) -> 1400 | BB17: =-IFERROR(F17/D17*AY17,0) -> -36838.633 | BC17: =-207.84*AY17 -> -5403.84 | BD17: =$BD$18/$AY$18*$AY17 -> -1847.6134 | BE17: =$BE$18/$AY$18*$AY17 -> -3632.095 | BF17: =$BF$18/$AY$18*$AY17 -> -2903.4646 | BG17: =(AZ17-AY17*$BD$22)*0.03 -> 1002.9415 | BH17: =AZ17+SUM(BB17:BE17,BG17) -> -10319.24 | BI17: =IFERROR(BH17/AZ17,0) -> -0.2834956 | BJ17: =AZ17+BB17+BC17+BD17+BG17-BF17 -> -3783.6803 | BK17: =IFERROR(BJ17/AZ17,0) -> -0.10394726 | BM17: =BA17 -> 1400 | BN17: =IFERROR(BB17/$AY17,0) -> -1416.8705 | BO17: =IFERROR(BC17/$AY17,0) -> -207.84 | BP17: =IFERROR(BD17/$AY17,0) -> -71.062056 | BQ17: =IFERROR(BE17/$AY17,0) -> -139.69596 | BR17: =IFERROR(BF17/$AY17,0) -> -111.67172 | BS17: =IFERROR(BG17/$AY17,0) -> 38.574672 | BT17: =IFERROR(BH17/$AY17,0) -> -396.89384 | BU17: =IFERROR(BJ17/$AY17,0) -> -145.52617 | BV17: =BU17-BT17 -> 251.36768
C18: TOTAL | D18: =SUM(D7:D17) -> 1310.166 | E18: =IFERROR(F18/D18,0) -> 1789.7929 | F18: =SUM(F7:F17) -> 2344925.8 | G18: =SUM(G7:G17) -> 272304.9 | H18: =SUM(H7:H17) -> 78579 | I18: =SUM(I7:I17) -> 154473 | J18: =SUM(J7:J17) -> 123484.35 | K18: =SUM(K7:K17) -> 0 | L18: 0 | M18: =SUM(M7:M17) -> 2850282.7 | N18: =IFERROR(M18/D18,0) -> 2175.5127 | O18: =SUM(O7:O17) -> 2572325.4 | P18: =IFERROR(O18/D18,0) -> 1963.3584 | Q18: =R18/D18 -> 1973.6296 | R18: =SUM(R7:R17) -> 2585782.4 | S18: =SUM(S7:S17) -> -191414.62 | T18: =S18/R18 -> -0.074025804 | U18: =SUM(U7:U17) -> 86542.728 | V18: =IFERROR(U18/R18,0) -> 0.033468682 | X18: =SUM(X7:X17) -> 26 | Y18: =SUM(Y7:Y17) -> 36400 | Z18: =IFERROR(Y18/X18,0) -> 1400 | AA18: =SUM(AA7:AA17) -> 48.78 | AB18: =SUM(AB7:AB17) -> 142254 | AC18: =IFERROR(AB18/AA18,0) -> 2916.2362 | AD18: =SUM(AD7:AD17) -> 204 | AE18: =SUM(AE7:AE17) -> 648450 | AF18: =IFERROR(AE18/AD18,0) -> 3178.6765 | AG18: =SUM(AG7:AG17) -> 26 | AH18: =SUM(AH7:AH17) -> 67600 | AI18: =IFERROR(AH18/AG18,0) -> 2600 | AJ18: =SUM(AJ7:AJ17) -> 162 | AK18: =SUM(AK7:AK17) -> 447390 | AL18: =IFERROR(AK18/AJ18,0) -> 2761.6667 | AM18: =SUM(AM7:AM17) -> 127 | AN18: =SUM(AN7:AN17) -> 290510 | AO18: =IFERROR(AN18/AM18,0) -> 2287.4803 | AP18: =SUM(AP7:AP17) -> 54 | AQ18: =SUM(AQ7:AQ17) -> 170640 | AR18: =IFERROR(AQ18/AP18,0) -> 3160 | AS18: =SUM(AS7:AS17) -> 242 | AT18: =SUM(AT7:AT17) -> 886950 | AU18: =IFERROR(AT18/AS18,0) -> 3665.0826 | AV18: =SUM(AV7:AV17) -> 216 | AW18: =SUM(AW7:AW17) -> 650700 | AX18: =IFERROR(AW18/AV18,0) -> 3012.5 | AY18: =SUM(AY7:AY17) -> 1105.78 | AZ18: =SUM(AZ7:AZ17) -> 3340894 | BA18: =IFERROR(AZ18/AY18,0) -> 3021.3008 | BB18: =SUM(BB7:BB17) -> -2609506.2 | BC18: =SUM(BC7:BC17) -> -229825.32 | BD18: =-'[2]Stock Libre'!N61 -> -78579 | BE18: =-'[2]Stock Libre'!O61 -> -154473 | BF18: =-'[2]Stock Libre'!P61 -> -123484.35 | BG18: =SUM(BG7:BG17) -> 96439.16 | BH18: =SUM(BH7:BH17) -> 364949.62 | BI18: =IFERROR(BH18/AZ18,0) -> 0.10923711 | BJ18: =SUM(BJ7:BJ17) -> 642906.97 | BK18: =IFERROR(BJ18/AZ18,0) -> 0.19243561 | BM18: =BA18 -> 3021.3008 | BN18: =IFERROR(BB18/$AY18,0) -> -2359.8783 | BO18: =IFERROR(BC18/$AY18,0) -> -207.84 | BP18: =IFERROR(BD18/$AY18,0) -> -71.062056 | BQ18: =IFERROR(BE18/$AY18,0) -> -139.69596 | BR18: =IFERROR(BF18/$AY18,0) -> -111.67172 | BS18: =IFERROR(BG18/$AY18,0) -> 87.213696 | BT18: =IFERROR(BH18/$AY18,0) -> 330.03818 | BU18: =IFERROR(BJ18/$AY18,0) -> 581.40586 | BV18: =BU18-BT18 -> 251.36768
N19: =N18-P18 -> 212.1543
AZ21: 2407050
AZ22: =AZ21/AZ18 -> 0.72048081 | BC22: flete x tm | BD22: 114.17761

Sheet TD
E3: Etiquetas de fila | F3: Suma de TM en Stock | G3: Suma de Costo Ventas | H3: Suma de Gasto Ventas | I3: Suma de Gasto ADM | J3: Suma de Gasto Fin | K3: Suma de Depreciación
B4: =C4=E4 -> TRUE | C4: 10005721 | D4: POTA FILETE CONGELADO | E4: 10005721 | F4: 591.56 | G4: 1174001.8 | H4: 122949.83 | I4: 35479.621 | J4: 69746.924 | K4: 55755.074
B5: =C5=E5 -> TRUE | C5: 10005779 | D5: POTA NUCAS CONGELADAS | E5: 10005779 | F5: 273.58 | G5: 443749.6 | H5: 56860.867 | I5: 16408.335 | J5: 32256.007 | K5: 25785.167
B6: =C6=E6 -> TRUE | C6: 10006719 | D6: POTA ALAS CONGELADAS | E6: 10006719 | F6: 67.28 | G6: 126666.2 | H6: 13983.475 | I6: 4035.2101 | J6: 7932.5394 | K6: 6341.2019
B7: =C7=E7 -> TRUE | C7: 10007050 | D7: POTA RECORTES COCIDOS | E7: 10007050 | F7: 131.76 | G7: 190254.32 | H7: 27384.998 | I7: 7902.4864 | J7: 15534.949 | K7: 12418.501
B8: =C8=E8 -> TRUE | C8: 10007162 | D8: POTA REJOS CONGELADOS | E8: 10007162 | F8: 102.56 | G8: 178525.96 | H8: 21316.07 | I8: 6151.1764 | J8: 12092.171 | K8: 9666.3743
B9: =C9=E9 -> TRUE | C9: 10007567 | D9: POTA REPRODUCTORES | E9: 10007567 | F9: 77.6 | G9: 130574.35 | H9: 16128.384 | I9: 4654.1663 | J9: 9149.3023 | K9: 7313.8713
B10: =C10=E10 -> TRUE | C10: 10007969 | D10: POTA CONOS | E10: 10007969 | F10: 34.46 | G10: 47158.641 | H10: 7162.1664 | I10: 2066.7857 | J10: 4062.9505 | K10: 3247.8867
B11: =C11=E11 -> TRUE | C11: 10009239 | D11: POTA FILETE DARUMA | E11: 10009239 | F11: 0 | G11: 0 | H11: 0 | I11: 0 | J11: 0 | K11: 0
B12: =C12=E12 -> TRUE | C12: 10009334 | D12: POTA ALAS COCIDAS | E12: 10009334 | F12: 2.826 | G12: 7981.835 | H12: 587.35584 | I12: 169.49322 | J12: 333.19495 | K12: 266.3531
B13: =C13=E13 -> TRUE | C13: 10009386 | D13: VENTOSAS | E13: 10009386 | F13: 17.14 | G13: 29860.81 | H13: 3562.3776 | I13: 1027.995 | J13: 2020.8639 | K13: 1615.4608
B14: =C14=E14 -> FALSE | E14: 10009207 | F14: 11.4 | G14: 16152.324 | H14: 2369.376 | I14: 683.73061 | J14: 1344.0985 | K14: 1074.4605
B15: =C15=E15 -> FALSE | E15: Total general | F15: 1310.166 | G15: 2344925.8 | H15: 272304.9 | I15: 78579 | J15: 154473 | K15: 123484.35

Sheet Stock Libre
A1: CODIGO | B1: PRODUCTO | C1: TOTAL STOCK | D1: POR EMBARCAR | E1: STOCK LIBRE | G1: CÓDIGO | H1: CU X TM | I1: % MP | J1: incremento MP | K1: TM en Stock | L1: Costo Ventas | M1: Gasto Ventas | N1: Gasto ADM | O1: Gasto Fin | P1: Depreciación | Q1: Utilidad Neta | R1: Margen Neto | S1: Venta Equilibrio | T1: Precio Equilibrio x TM
A2: 10009178 | B2: POTA ALAS FR C/P C/C (B) S/COD BL10 S20 | C2: 13600 | E2: =+C2-D2 -> 13600 | G2: 10006719 | H2: =IFERROR(INDEX([1]Resumen!$K$3:$K$63,MATCH(G2,[1]Resumen!$C$3:$C$63,0)),0)*(1+I2*J2)/1000-51.89/1000 -> 1.8826724 | I2: 0.71 | J2: -0.07 | K2: =IF(E2<0,0,E2)/1000 -> 13.6 | L2: =IFERROR(H2*K2,0)*1000 -> 25604.344 | M2: =207.84*K2 -> 2826.624 | N2: =$N$48/$K$46*K2 -> 815.67862 | O2: =$O$48/$K$46*K2 -> 1603.486 | P2: =$P$48/$K$46*K2 -> 1281.8125 | Q2: 0 | R2: 0 | S2: =L2+M2+N2+O2 -> 30850.133 | T2: =IFERROR(S2/K2,0) -> 2268.3921
A3: 10006668 | B3: POTA ALAS FR C/P C/C <0.5 BL10 S20 | C3: 3280 | E3: =+C3-D3 -> 3280 | G3: 10006719 | H3: =IFERROR(INDEX([1]Resumen!$K$3:$K$63,MATCH(G3,[1]Resumen!$C$3:$C$63,0)),0)*(1+I3*J3)/1000-51.89/1000 -> 1.8826724 | I3: 0.71 | J3: -0.07 | K3: =IF(E3<0,0,E3)/1000 -> 3.28 | L3: =IFERROR(H3*K3,0)*1000 -> 6175.1653 | M3: =207.84*K3 -> 681.7152 | N3: =$N$48/$K$46*K3 -> 196.72249 | O3: =$O$48/$K$46*K3 -> 386.72309 | P3: =$P$48/$K$46*K3 -> 309.14302 | Q3: 0 | R3: 0 | S3: =L3+M3+N3+O3 -> 7440.3261 | T3: =IFERROR(S3/K3,0) -> 2268.3921
A4: 10006719 | B4: POTA ALAS FR C/P C/C 0.5-1 BL10 S20 | C4: 15280 | E4: =+C4-D4 -> 15280 | G4: 10006719 | H4: =IFERROR(INDEX([1]Resumen!$K$3:$K$63,MATCH(G4,[1]Resumen!$C$3:$C$63,0)),0)*(1+I4*J4)/1000-51.89/1000 -> 1.8826724 | I4: 0.71 | J4: -0.07 | K4: =IF(E4<0,0,E4)/1000 -> 15.28 | L4: =IFERROR(H4*K4,0)*1000 -> 28767.234 | M4: =207.84*K4 -> 3175.7952 | N4: =$N$48/$K$46*K4 -> 916.43892 | O4: =$O$48/$K$46*K4 -> 1801.5636 | P4: =$P$48/$K$46*K4 -> 1440.154 | Q4: 0 | R4: 0 | S4: =L4+M4+N4+O4 -> 34661.031 | T4: =IFERROR(S4/K4,0) -> 2268.3921
A5: 10010005 | B5: POTA ALAS FR C/P C/C 1-2 BL10 S20 ENTERA | C5: 35120 | E5: =+C5-D5 -> 35120 | G5: 10006719 | H5: =IFERROR(INDEX([1]Resumen!$K$3:$K$63,MATCH(G5,[1]Resumen!$C$3:$C$63,0)),0)*(1+I5*J5)/1000-51.89/1000 -> 1.8826724 | I5: 0.71 | J5: -0.07 | K5: =IF(E5<0,0,E5)/1000 -> 35.12 | L5: =IFERROR(H5*K5,0)*1000 -> 66119.453 | M5: =207.84*K5 -> 7299.3408 | N5: =$N$48/$K$46*K5 -> 2106.3701 | O5: =$O$48/$K$46*K5 -> 4140.7667 | P5: =$P$48/$K$46*K5 -> 3310.0923 | Q5: 0 | R5: 0 | S5: =L5+M5+N5+O5 -> 79665.931 | T5: =IFERROR(S5/K5,0) -> 2268.3921
A6: 10009207 | B6: POTA LABIOS FR S/COD BL10 S20 | C6: 11400 | E6: =+C6-D6 -> 11400 | G6: 10009207 | H6: =IFERROR(INDEX([1]Resumen!$K$3:$K$63,MATCH(G6,[1]Resumen!$C$3:$C$63,0)),0)*(1+I6*J6)/1000-51.89/1000 -> 1.4168705 | I6: 0.71 | J6: -0.07 | K6: =IF(E6<0,0,E6)/1000 -> 11.4 | L6: =IFERROR(H6*K6,0)*1000 -> 16152.324 | M6: =207.84*K6 -> 2369.376 | N6: =$N$48/$K$46*K6 -> 683.73061 | O6: =$O$48/$K$46*K6 -> 1344.0985 | P6: =$P$48/$K$46*K6 -> 1074.4605 | Q6: 0 | R6: 0 | S6: =L6+M6+N6+O6 -> 20549.529 | T6: =IFERROR(S6/K6,0) -> 1802.5902
A7: 10007969 | B7: POTA CONOS | C7: 34460 | E7: =+C7-D7 -> 34460 | G7: 10007969 | H7: =IFERROR(INDEX([1]Resumen!$K$3:$K$63,MATCH(G7,[1]Resumen!$C$3:$C$63,0)),0)*(1+I7*J7)/1000-51.89/1000 -> 1.3685038 | I7: 0.71 | J7: -0.07 | K7: =IF(E7<0,0,E7)/1000 -> 34.46 | L7: =IFERROR(H7*K7,0)*1000 -> 47158.641 | M7: =207.84*K7 -> 7162.1664 | N7: =$N$48/$K$46*K7 -> 2066.7857 | O7: =$O$48/$K$46*K7 -> 4062.9505 | P7: =$P$48/$K$46*K7 -> 3247.8867 | Q7: 0 | R7: 0 | S7: =L7+M7+N7+O7 -> 60450.544 | T7: =IFERROR(S7/K7,0) -> 1754.2236
A8: 10004433 | B8: POTA FILETE C/M C/T FR 0.5-1.0 BL10 S20 | C8: 1400 | E8: =+C8-D8 -> 1400 | G8: 10005721 | H8: =IFERROR(INDEX([1]Resumen!$K$3:$K$63,MATCH(G8,[1]Resumen!$C$3:$C$63,0)),0)*(1+I8*J8)/1000-51.89/1000 -> 1.9845862 | I8: 0.67 | J8: -0.07 | K8: =IF(E8<0,0,E8)/1000 -> 1.4 | L8: =IFERROR(H8*K8,0)*1000 -> 2778.4206 | M8: =207.84*K8 -> 290.976 | N8: =$N$48/$K$46*K8 -> 83.966917 | O8: =$O$48/$K$46*K8 -> 165.06473 | P8: =$P$48/$K$46*K8 -> 131.95129 | Q8: 0 | R8: 0 | S8: =L8+M8+N8+O8 -> 3318.4283 | T8: =IFERROR(S8/K8,0) -> 2370.3059
A9: 10004434 | B9: POTA FILETE C/M C/T FR 1-2 BL10 S20 | C9: 2140 | D9: 2140 | E9: =+C9-D9 -> 0 | G9: 10005721 | H9: =IFERROR(INDEX([1]Resumen!$K$3:$K$63,MATCH(G9,[1]Resumen!$C$3:$C$63,0)),0)*(1+I9*J9)/1000-51.89/1000 -> 1.9845862 | I9: 0.67 | J9: -0.07 | K9: =IF(E9<0,0,E9)/1000 -> 0 | L9: =IFERROR(H9*K9,0)*1000 -> 0 | M9: =207.84*K9 -> 0 | N9: =$N$48/$K$46*K9 -> 0 | O9: =$O$48/$K$46*K9 -> 0 | P9: =$P$48/$K$46*K9 -> 0 | Q9: 0 | R9: 0 | S9: =L9+M9+N9+O9 -> 0 | T9: =IFERROR(S9/K9,0) -> 0
A10: 10010125 | B10: POTA FILETE C/M C/T FR 1.0 - 3.0 BL10 S20 | C10: 220 | D10: 220 | E10: =+C10-D10 -> 0 | G10: 10005721 | H10: =IFERROR(INDEX([1]Resumen!$K$3:$K$63,MATCH(G10,[1]Resumen!$C$3:$C$63,0)),0)*(1+I10*J10)/1000-51.89/1000 -> 1.9845862 | I10: 0.67 | J10: -0.07 | K10: =IF(E10<0,0,E10)/1000 -> 0 | L10: =IFERROR(H10*K10,0)*1000 -> 0 | M10: =207.84*K10 -> 0 | N10: =$N$48/$K$46*K10 -> 0 | O10: =$O$48/$K$46*K10 -> 0 | P10: =$P$48/$K$46*K10 -> 0 | Q10: 0 | R10: 0 | S10: =L10+M10+N10+O10 -> 0 | T10: =IFERROR(S10/K10,0) -> 0
A11: 10004435 | B11: POTA FILETE C/M C/T FR 2-4 S20 | C11: 14400 | E11: =+C11-D11 -> 14400 | G11: 10005721 | H11: =IFERROR(INDEX([1]Resumen!$K$3:$K$63,MATCH(G11,[1]Resumen!$C$3:$C$63,0)),0)*(1+I11*J11)/1000-51.89/1000 -> 1.9845862 | I11: 0.67 | J11: -0.07 | K11: =IF(E11<0,0,E11)/1000 -> 14.4 | L11: =IFERROR(H11*K11,0)*1000 -> 28578.041 | M11: =207.84*K11 -> 2992.896 | N11: =$N$48/$K$46*K11 -> 863.65972 | O11: =$O$48/$K$46*K11 -> 1697.8087 | P11: =$P$48/$K$46*K11 -> 1357.2132 | Q11: 0 | R11: 0 | S11: =L11+M11+N11+O11 -> 34132.405 | T11: =IFERROR(S11/K11,0) -> 2370.3059
A12: 10005708 | B12: POTA FILETE C/M C/T FR <0.5 Kg AA BL10 S20 | C12: 1080 | E12: =+C12-D12 -> 1080 | G12: 10005721 | H12: =IFERROR(INDEX([1]Resumen!$K$3:$K$63,MATCH(G12,[1]Resumen!$C$3:$C$63,0)),0)*(1+I12*J12)/1000-51.89/1000 -> 1.9845862 | I12: 0.67 | J12: -0.07 | K12: =IF(E12<0,0,E12)/1000 -> 1.08 | L12: =IFERROR(H12*K12,0)*1000 -> 2143.3531 | M12: =207.84*K12 -> 224.4672 | N12: =$N$48/$K$46*K12 -> 64.774479 | O12: =$O$48/$K$46*K12 -> 127.33565 | P12: =$P$48/$K$46*K12 -> 101.79099 | Q12: 0 | R12: 0 | S12: =L12+M12+N12+O12 -> 2559.9304 | T12: =IFERROR(S12/K12,0) -> 2370.3059
A13: 10005721 | B13: POTA FILETE C/M C/T FR 2-4 (AA) BL10 S20 | C13: 530420 | E13: =+C13-D13 -> 530420 | G13: 10005721 | H13: =IFERROR(INDEX([1]Resumen!$K$3:$K$63,MATCH(G13,[1]Resumen!$C$3:$C$63,0)),0)*(1+I13*J13)/1000-51.89/1000 -> 1.9845862 | I13: 0.67 | J13: -0.07 | K13: =IF(E13<0,0,E13)/1000 -> 530.42 | L13: =IFERROR(H13*K13,0)*1000 -> 1052664.2 | M13: =207.84*K13 -> 110242.49 | N13: =$N$48/$K$46*K13 -> 31812.666 | O13: =$O$48/$K$46*K13 -> 62538.311 | P13: =$P$48/$K$46*K13 -> 49992.573 | Q13: 0 | R13: 0 | S13: =L13+M13+N13+O13 -> 1257257.7 | T13: =IFERROR(S13/K13,0) -> 2370.3059
A14: 10005711 | B14: POTA FILETE C/M C/T FR 0.5-1.0 AA BL10 S20 | C14: 11340 | E14: =+C14-D14 -> 11340 | G14: 10005721 | H14: =IFERROR(INDEX([1]Resumen!$K$3:$K$63,MATCH(G14,[1]Resumen!$C$3:$C$63,0)),0)*(1+I14*J14)/1000-51.89/1000 -> 1.9845862 | I14: 0.67 | J14: -0.07 | K14: =IF(E14<0,0,E14)/1000 -> 11.34 | L14: =IFERROR(H14*K14,0)*1000 -> 22505.207 | M14: =207.84*K14 -> 2356.9056 | N14: =$N$48/$K$46*K14 -> 680.13203 | O14: =$O$48/$K$46*K14 -> 1337.0243 | P14: =$P$48/$K$46*K14 -> 1068.8054 | Q14: 0 | R14: 0 | S14: =L14+M14+N14+O14 -> 26879.269 | T14: =IFERROR(S14/K14,0) -> 2370.3059
A15: 10010126 | B15: POTA FILETE C/M C/T FR 1.0 - 3.0 AA BL10 S20 | C15: 3300 | D15: 3300 | E15: =+C15-D15 -> 0 | G15: 10005721 | H15: =IFERROR(INDEX([1]Resumen!$K$3:$K$63,MATCH(G15,[1]Resumen!$C$3:$C$63,0)),0)*(1+I15*J15)/1000-51.89/1000 -> 1.9845862 | I15: 0.67 | J15: -0.07 | K15: =IF(E15<0,0,E15)/1000 -> 0 | L15: =IFERROR(H15*K15,0)*1000 -> 0 | M15: =207.84*K15 -> 0 | N15: =$N$48/$K$46*K15 -> 0 | O15: =$O$48/$K$46*K15 -> 0 | P15: =$P$48/$K$46*K15 -> 0 | Q15: 0 | R15: 0 | S15: =L15+M15+N15+O15 -> 0 | T15: =IFERROR(S15/K15,0) -> 0
A16: 10005718 | B16: POTA FILETE C/M C/T FR 1-2 AA BL10 S20 JAPON | C16: 380 | D16: 32480 | E16: =+C16-D16 -> -32100 | G16: 10005721 | H16: =IFERROR(INDEX([1]Resumen!$K$3:$K$63,MATCH(G16,[1]Resumen!$C$3:$C$63,0)),0)*(1+I16*J16)/1000-51.89/1000 -> 1.9845862 | I16: 0.67 | J16: -0.07 | K16: =IF(E16<0,0,E16)/1000 -> 0 | L16: =IFERROR(H16*K16,0)*1000 -> 0 | M16: =207.84*K16 -> 0 | N16: =$N$48/$K$46*K16 -> 0 | O16: =$O$48/$K$46*K16 -> 0 | P16: =$P$48/$K$46*K16 -> 0 | Q16: 0 | R16: 0 | S16: =L16+M16+N16+O16 -> 0 | T16: =IFERROR(S16/K16,0) -> 0
A17: 10009972 | B17: POTA FILETE C/M C/T FR 1-2 AA BL10 S20 50% ROSADO | C17: 29720 | E17: =+C17-D17 -> 29720 | G17: 10005721 | H17: =IFERROR(INDEX([1]Resumen!$K$3:$K$63,MATCH(G17,[1]Resumen!$C$3:$C$63,0)),0)*(1+I17*J17)/1000-51.89/1000 -> 1.9845862 | I17: 0.67 | J17: -0.07 | K17: =IF(E17<0,0,E17)/1000 -> 29.72 | L17: =IFERROR(H17*K17,0)*1000 -> 58981.901 | M17: =207.84*K17 -> 6177.0048 | N17: =$N$48/$K$46*K17 -> 1782.4977 | O17: =$O$48/$K$46*K17 -> 3504.0885 | P17: =$P$48/$K$46*K17 -> 2801.1373 | Q17: 0 | R17: 0 | S17: =L17+M17+N17+O17 -> 70445.492 | T17: =IFERROR(S17/K17,0) -> 2370.3059
A18: 10009298 | B18: POTA FILETE SM ST 1-2 CM/ESP | C18: 3200 | E18: =+C18-D18 -> 3200 | G18: 10005721 | H18: =IFERROR(INDEX([1]Resumen!$K$3:$K$63,MATCH(G18,[1]Resumen!$C$3:$C$63,0)),0)*(1+I18*J18)/1000-51.89/1000 -> 1.9845862 | I18: 0.67 | J18: -0.07 | K18: =IF(E18<0,0,E18)/1000 -> 3.2 | L18: =IFERROR(H18*K18,0)*1000 -> 6350.6758 | M18: =207.84*K18 -> 665.088 | N18: =$N$48/$K$46*K18 -> 191.92438 | O18: =$O$48/$K$46*K18 -> 377.29082 | P18: =$P$48/$K$46*K18 -> 301.60294 | Q18: 0 | R18: 0 | S18: =L18+M18+N18+O18 -> 7584.979 | T18: =IFERROR(S18/K18,0) -> 2370.3059
A19: 10009184 | B19: POTA NUCAS FR ABIERTAS 0.1 - 0.3 BL10 S2 | C19: 95200 | E19: =+C19-D19 -> 95200 | G19: 10005779 | H19: =IFERROR(INDEX([1]Resumen!$K$3:$K$63,MATCH(G19,[1]Resumen!$C$3:$C$63,0)),0)*(1+I19*J19)/1000-51.89/1000 -> 1.6220104 | I19: 0.65 | J19: -0.07 | K19: =IF(E19<0,0,E19)/1000 -> 95.2 | L19: =IFERROR(H19*K19,0)*1000 -> 154415.39 | M19: =207.84*K19 -> 19786.368 | N19: =$N$48/$K$46*K19 -> 5709.7504 | O19: =$O$48/$K$46*K19 -> 11224.402 | P19: =$P$48/$K$46*K19 -> 8972.6875 | Q19: 0 | R19: 0 | S19: =L19+M19+N19+O19 -> 191135.91 | T19: =IFERROR(S19/K19,0) -> 2007.7301
A20: 10009271 | B20: POTA NUCAS FR CERRADA 0.1 - 0.3 BL10 S2 | C20: 40100 | E20: =+C20-D20 -> 40100 | G20: 10005779 | H20: =IFERROR(INDEX([1]Resumen!$K$3:$K$63,MATCH(G20,[1]Resumen!$C$3:$C$63,0)),0)*(1+I20*J20)/1000-51.89/1000 -> 1.6220104 | I20: 0.65 | J20: -0.07 | K20: =IF(E20<0,0,E20)/1000 -> 40.1 | L20: =IFERROR(H20*K20,0)*1000 -> 65042.617 | M20: =207.84*K20 -> 8334.384 | N20: =$N$48/$K$46*K20 -> 2405.0524 | O20: =$O$48/$K$46*K20 -> 4727.9255 | P20: =$P$48/$K$46*K20 -> 3779.4619 | Q20: 0 | R20: 0 | S20: =L20+M20+N20+O20 -> 80509.979 | T20: =IFERROR(S20/K20,0) -> 2007.7301
A21: 10009183 | B21: POTA NUCAS FR CERRADA <0.1 BL10 S2 | C21: 1040 | E21: =+C21-D21 -> 1040 | G21: 10005779 | H21: =IFERROR(INDEX([1]Resumen!$K$3:$K$63,MATCH(G21,[1]Resumen!$C$3:$C$63,0)),0)*(1+I21*J21)/1000-51.89/1000 -> 1.6220104 | I21: 0.65 | J21: -0.07 | K21: =IF(E21<0,0,E21)/1000 -> 1.04 | L21: =IFERROR(H21*K21,0)*1000 -> 1686.8908 | M21: =207.84*K21 -> 216.1536 | N21: =$N$48/$K$46*K21 -> 62.375424 | O21: =$O$48/$K$46*K21 -> 122.61952 | P21: =$P$48/$K$46*K21 -> 98.020956 | Q21: 0 | R21: 0 | S21: =L21+M21+N21+O21 -> 2088.0394 | T21: =IFERROR(S21/K21,0) -> 2007.7301
A22: 10005779 | B22: POTA NUCAS FR ABIERTAS 0.5-1 BL10 S20 | C22: 72960 | D22: 24000 | E22: =+C22-D22 -> 48960 | G22: 10005779 | H22: =IFERROR(INDEX([1]Resumen!$K$3:$K$63,MATCH(G22,[1]Resumen!$C$3:$C$63,0)),0)*(1+I22*J22)/1000-51.89/1000 -> 1.6220104 | I22: 0.65 | J22: -0.07 | K22: =IF(E22<0,0,E22)/1000 -> 48.96 | L22: =IFERROR(H22*K22,0)*1000 -> 79413.629 | M22: =207.84*K22 -> 10175.846 | N22: =$N$48/$K$46*K22 -> 2936.443 | O22: =$O$48/$K$46*K22 -> 5772.5495 | P22: =$P$48/$K$46*K22 -> 4614.525 | Q22: 0 | R22: 0 | S22: =L22+M22+N22+O22 -> 98298.468 | T22: =IFERROR(S22/K22,0) -> 2007.7301
A23: 10005776 | B23: POTA NUCAS FR ABIERTAS 0.3-0.5 BL10 S20 | C23: 146280 | D23: 58000 | E23: =+C23-D23 -> 88280 | G23: 10005779 | H23: =IFERROR(INDEX([1]Resumen!$K$3:$K$63,MATCH(G23,[1]Resumen!$C$3:$C$63,0)),0)*(1+I23*J23)/1000-51.89/1000 -> 1.6220104 | I23: 0.65 | J23: -0.07 | K23: =IF(E23<0,0,E23)/1000 -> 88.28 | L23: =IFERROR(H23*K23,0)*1000 -> 143191.08 | M23: =207.84*K23 -> 18348.115 | N23: =$N$48/$K$46*K23 -> 5294.7139 | O23: =$O$48/$K$46*K23 -> 10408.51 | P23: =$P$48/$K$46*K23 -> 8320.4712 | Q23: 0 | R23: 0 | S23: =L23+M23+N23+O23 -> 177242.42 | T23: =IFERROR(S23/K23,0) -> 2007.7301
A24: 10005781 | B24: POTA NUCAS FR ABIERTAS 1-2 BL10 S20 | C24: 5940 | D24: 104000 | E24: =+C24-D24 -> -98060 | G24: 10005779 | H24: =IFERROR(INDEX([1]Resumen!$K$3:$K$63,MATCH(G24,[1]Resumen!$C$3:$C$63,0)),0)*(1+I24*J24)/1000-51.89/1000 -> 1.6220104 | I24: 0.65 | J24: -0.07 | K24: =IF(E24<0,0,E24)/1000 -> 0 | L24: =IFERROR(H24*K24,0)*1000 -> 0 | M24: =207.84*K24 -> 0 | N24: =$N$48/$K$46*K24 -> 0 | O24: =$O$48/$K$46*K24 -> 0 | P24: =$P$48/$K$46*K24 -> 0 | Q24: 0 | R24: 0 | S24: =L24+M24+N24+O24 -> 0 | T24: =IFERROR(S24/K24,0) -> 0
A25: 10007567 | B25: POTA REJOS OR FR LIMPIOS S/COD BL10 S20 | C25: 71520 | D25: 27000 | E25: =+C25-D25 -> 44520 | G25: 10007567 | H25: =IFERROR(INDEX([1]Resumen!$K$3:$K$63,MATCH(G25,[1]Resumen!$C$3:$C$63,0)),0)*(1+I25*J25)/1000-51.89/1000 -> 1.6826592 | I25: 0.68 | J25: -0.07 | K25: =IF(E25<0,0,E25)/1000 -> 44.52 | L25: =IFERROR(H25*K25,0)*1000 -> 74911.988 | M25: =207.84*K25 -> 9253.0368 | N25: =$N$48/$K$46*K25 -> 2670.148 | O25: =$O$48/$K$46*K25 -> 5249.0585 | P25: =$P$48/$K$46*K25 -> 4196.0509 | Q25: 0 | R25: 0 | S25: =L25+M25+N25+O25 -> 92084.231 | T25: =IFERROR(S25/K25,0) -> 2068.379
