Workbook

Sheet Resumen Inventario
C2: PERU FROST
C3: AVANCE COMERCIAL AL 28-9-2026
C5: STOCK PAITA | F5: RENTABILIDAD DEL INVENTARIO
B6: Código | C6: Producto | D6: TM en Stock Libre | E6: CU | F6: Costo Ventas | G6: Gasto Ventas | H6: Gasto ADM | I6: Gasto Fin | J6: Depreciación | K6: Utilidad Neta | L6: Margen Neto | M6: Venta Equilibrio a Utd Neta | N6: Precio Equilibrio x TM a Utd Neta | O6: Venta Equilibro a EBITDA | P6: Precio Equilibrio x TM a EBITDA | Q6: Precio Mercado | R6: Venta total | S6: Utilidad | T6: Mg Neto | U6: EBITDA | V6: Mg EBITDA
B7: 10005721 | C7: POTA FILETE CONGELADO | D7: =TD!F4 -> 116.14 | E7: =IFERROR(F7/D7,0) -> 1647.131 | F7: =TD!G4 -> 191297.8 | G7: =TD!H4 -> 27903.796 | H7: =TD!I4 -> 3717.0249 | I7: =TD!J4 -> 10041.267 | J7: =TD!K4 -> 7313.5926 | K7: 0 | L7: 0 | M7: =F7+G7+H7+I7 -> 232959.88 | N7: =IFERROR(M7/D7,0) -> 2005.854 | O7: =F7+G7+H7-J7 -> 215605.02 | P7: =IFERROR(O7/D7,0) -> 1856.4235 | Q7: 1550 | R7: =Q7*D7 -> 180017 | S7: =R7-M7 -> -52942.884 | T7: =IFERROR(S7/R7,0) -> -0.29409936 | U7: =R7-(M7-J7-I7) -> -35588.024 | V7: =IFERROR(U7/R7,0) -> -0.19769257
B8: 10005779 | C8: POTA NUCAS CONGELADAS | D8: =TD!F5 -> 493.02 | E8: =IFERROR(F8/D8,0) -> 1522.3482 | F8: =TD!G5 -> 750548.13 | G8: =TD!H5 -> 118452.99 | H8: =TD!I5 -> 15778.953 | I8: =TD!J5 -> 42625.673 | J8: =TD!K5 -> 31046.56 | K8: 0 | L8: 0 | M8: =F8+G8+H8+I8 -> 927405.74 | N8: =IFERROR(M8/D8,0) -> 1881.0712 | O8: =F8+G8+H8-J8 -> 853733.51 | P8: =IFERROR(O8/D8,0) -> 1731.6407 | Q8: 1400 | R8: =Q8*D8 -> 690228 | S8: =R8-M8 -> -237177.74 | T8: =IFERROR(S8/R8,0) -> -0.34362231 | U8: =R8-(M8-J8-I8) -> -163505.51 | V8: =IFERROR(U8/R8,0) -> -0.23688623
B9: 10006719 | C9: POTA ALAS CONGELADAS | D9: =TD!F6 -> 51.42 | E9: =IFERROR(F9/D9,0) -> 1353.7612 | F9: =TD!G6 -> 69610.403 | G9: =TD!H6 -> 12354.169 | H9: =TD!I6 -> 1645.6812 | I9: =TD!J6 -> 4445.686 | J9: =TD!K6 -> 3238.0311 | K9: 0 | L9: 0 | M9: =F9+G9+H9+I9 -> 88055.94 | N9: =IFERROR(M9/D9,0) -> 1712.4842 | O9: =F9+G9+H9-J9 -> 80372.223 | P9: =IFERROR(O9/D9,0) -> 1563.0537 | Q9: 1800 | R9: =Q9*D9 -> 92556 | S9: =R9-M9 -> 4500.0604 | T9: =IFERROR(S9/R9,0) -> 0.048619867 | U9: =R9-(M9-J9-I9) -> 12183.777 | V9: =IFERROR(U9/R9,0) -> 0.13163682
B10: 10007050 | C10: POTA RECORTES COCIDOS | D10: =TD!F7 -> 171.83 | E10: =IFERROR(F10/D10,0) -> 1611.8872 | F10: =TD!G7 -> 276970.58 | G10: =TD!H7 -> 41283.876 | H10: =TD!I7 -> 5499.3661 | I10: =TD!J7 -> 14856.13 | J10: =TD!K7 -> 10820.515 | K10: 0 | L10: 0 | M10: =F10+G10+H10+I10 -> 338609.95 | N10: =IFERROR(M10/D10,0) -> 1970.6102 | O10: =F10+G10+H10-J10 -> 312933.3 | P10: =IFERROR(O10/D10,0) -> 1821.1797 | Q10: 2200 | R10: =Q10*D10 -> 378026 | S10: =R10-M10 -> 39416.053 | T10: =IFERROR(S10/R10,0) -> 0.1042681 | U10: =R10-(M10-J10-I10) -> 65092.698 | V10: =IFERROR(U10/R10,0) -> 0.17219106
B11: 10007162 | C11: POTA REJOS CONGELADOS | D11: =TD!F8 -> 520.24 | E11: =IFERROR(F11/D11,0) -> 1649.2592 | F11: =TD!G8 -> 858010.61 | G11: =TD!H8 -> 124992.86 | H11: =TD!I8 -> 16650.121 | I11: =TD!J8 -> 44979.068 | J11: =TD!K8 -> 32760.663 | K11: 0 | L11: 0 | M11: =F11+G11+H11+I11 -> 1044632.7 | N11: =IFERROR(M11/D11,0) -> 2007.9822 | O11: =F11+G11+H11-J11 -> 966892.93 | P11: =IFERROR(O11/D11,0) -> 1858.5517 | Q11: 2400 | R11: =Q11*D11 -> 1248576 | S11: =R11-M11 -> 203943.34 | T11: =IFERROR(S11/R11,0) -> 0.16334075 | U11: =R11-(M11-J11-I11) -> 281683.07 | V11: =IFERROR(U11/R11,0) -> 0.22560347
B12: 10007567 | C12: POTA REPRODUCTORES | D12: =TD!F9 -> 135.72 | E12: =IFERROR(F12/D12,0) -> 1615.1088 | F12: =TD!G9 -> 219202.57 | G12: =TD!H9 -> 32608.087 | H12: =TD!I9 -> 4343.6767 | I12: =TD!J9 -> 11734.121 | J12: =TD!K9 -> 8546.5885 | K12: 0 | L12: 0 | M12: =F12+G12+H12+I12 -> 267888.45 | N12: =IFERROR(M12/D12,0) -> 1973.8318 | O12: =F12+G12+H12-J12 -> 247607.74 | P12: =IFERROR(O12/D12,0) -> 1824.4013 | Q12: 2500 | R12: =Q12*D12 -> 339300 | S12: =R12-M12 -> 71411.547 | T12: =IFERROR(S12/R12,0) -> 0.21046728 | U12: =R12-(M12-J12-I12) -> 91692.257 | V12: =IFERROR(U12/R12,0) -> 0.27023948
B13: 10007969 | C13: POTA CONOS | D13: =TD!F10 -> 0 | E13: =IFERROR(F13/D13,0) -> 0 | F13: =TD!G10 -> 0 | G13: =TD!H10 -> 0 | H13: =TD!I10 -> 0 | I13: =TD!J10 -> 0 | J13: =TD!K10 -> 0 | K13: 0 | L13: 0 | M13: =F13+G13+H13+I13 -> 0 | N13: =IFERROR(M13/D13,0) -> 0 | O13: =F13+G13+H13-J13 -> 0 | P13: =IFERROR(O13/D13,0) -> 0 | Q13: 1750 | R13: =Q13*D13 -> 0 | S13: =R13-M13 -> 0 | T13: =IFERROR(S13/R13,0) -> 0 | U13: =R13-(M13-J13-I13) -> 0 | V13: =IFERROR(U13/R13,0) -> 0
B14: 10009239 | C14: POTA FILETE DARUMA | D14: =TD!F11 -> 264.46 | E14: =IFERROR(F14/D14,0) -> 3028.2341 | F14: =TD!G11 -> 800846.8 | G14: =TD!H11 -> 63539.16 | H14: =TD!I11 -> 8463.9607 | I14: =TD!J11 -> 22864.763 | J14: =TD!K11 -> 16653.631 | K14: 0 | L14: 0 | M14: =F14+G14+H14+I14 -> 895714.68 | N14: =IFERROR(M14/D14,0) -> 3386.9571 | O14: =F14+G14+H14-J14 -> 856196.29 | P14: =IFERROR(O14/D14,0) -> 3237.5266 | Q14: 3500 | R14: =Q14*D14 -> 925610 | S14: =R14-M14 -> 29895.315 | T14: =IFERROR(S14/R14,0) -> 0.03229796 | U14: =R14-(M14-J14-I14) -> 69413.709 | V14: =IFERROR(U14/R14,0) -> 0.074992393
B15: 10009334 | C15: POTA ALAS COCIDAS | D15: =TD!F12 -> 94.718 | E15: =IFERROR(F15/D15,0) -> 2781.2425 | F15: =TD!G12 -> 263433.73 | G15: =TD!H12 -> 22756.947 | H15: =TD!I12 -> 3031.4204 | I15: =TD!J12 -> 8189.1576 | J15: =TD!K12 -> 5964.6019 | K15: 0 | L15: 0 | M15: =F15+G15+H15+I15 -> 297411.25 | N15: =IFERROR(M15/D15,0) -> 3139.9655 | O15: =F15+G15+H15-J15 -> 283257.49 | P15: =IFERROR(O15/D15,0) -> 2990.535 | Q15: 3500 | R15: =Q15*D15 -> 331513 | S15: =R15-M15 -> 34101.746 | T15: =IFERROR(S15/R15,0) -> 0.10286699 | U15: =R15-(M15-J15-I15) -> 48255.505 | V15: =IFERROR(U15/R15,0) -> 0.14556143
B16: 10009386 | C16: VENTOSAS | D16: =TD!F13 -> 24.36 | E16: =IFERROR(F16/D16,0) -> 2183.6494 | F16: =TD!G13 -> 53193.7 | G16: =TD!H13 -> 5852.7336 | H16: =TD!I13 -> 779.63428 | I16: =TD!J13 -> 2106.1243 | J16: =TD!K13 -> 1534.0031 | K16: 0 | L16: 0 | M16: =F16+G16+H16+I16 -> 61932.192 | N16: =IFERROR(M16/D16,0) -> 2542.3724 | O16: =F16+G16+H16-J16 -> 58292.065 | P16: =IFERROR(O16/D16,0) -> 2392.9419 | Q16: 1600 | R16: =Q16*D16 -> 38976 | S16: =R16-M16 -> -22956.192 | T16: =IFERROR(S16/R16,0) -> -0.58898276 | U16: =R16-(M16-J16-I16) -> -19316.065 | V16: =IFERROR(U16/R16,0) -> -0.49558869
B17: 10009386 | C17: OTROS | D17: =TD!F14 -> 45.46 | E17: =IFERROR(F17/D17,0) -> 1355.7979 | F17: =TD!G14 -> 61634.574 | G17: =TD!H14 -> 10922.22 | H17: =TD!I14 -> 1454.9333 | I17: =TD!J14 -> 3930.3945 | J17: =TD!K14 -> 2862.7167 | K17: 0 | L17: 0 | M17: =F17+G17+H17+I17 -> 77942.121 | N17: =IFERROR(M17/D17,0) -> 1714.5209 | O17: =F17+G17+H17-J17 -> 71149.01 | P17: =IFERROR(O17/D17,0) -> 1565.0904 | Q17: 1600 | R17: =Q17*D17 -> 72736 | S17: =R17-M17 -> -5206.1212 | T17: =IFERROR(S17/R17,0) -> -0.071575578 | U17: =R17-(M17-J17-I17) -> 1586.9899 | V17: =IFERROR(U17/R17,0) -> 0.021818494
C18: FILETE PARA REPROCESO | D18: =TD!F15 -> 49.32 | E18: =IFERROR(F18/D18,0) -> 1236.1466 | F18: =TD!G15 -> 60966.749 | G18: =TD!H15 -> 11849.623 | H18: =TD!I15 -> 1578.4714 | I18: =TD!J15 -> 4264.1235 | J18: =TD!K15 -> 3105.7895 | K18: 0 | L18: 0 | M18: =F18+G18+H18+I18 -> 78658.968 | N18: =IFERROR(M18/D18,0) -> 1594.8696 | O18: =F18+G18+H18-J18 -> 71289.055 | P18: =IFERROR(O18/D18,0) -> 1445.4391 | Q18: 1550 | R18: =Q18*D18 -> 76446 | S18: =R18-M18 -> -2212.9675 | T18: =IFERROR(S18/R18,0) -> -0.028948114 | U18: =R18-(M18-J18-I18) -> 5156.9455 | V18: =IFERROR(U18/R18,0) -> 0.06745867
C19: ALAS PARA REPROCESO | D19: =TD!F16 -> 0 | E19: =IFERROR(F19/D19,0) -> 0 | F19: =TD!G16 -> 0 | G19: =TD!H16 -> 0 | H19: =TD!I16 -> 0 | I19: =TD!J16 -> 0 | J19: =TD!K16 -> 0 | K19: 0 | L19: 0 | M19: =F19+G19+H19+I19 -> 0 | N19: =IFERROR(M19/D19,0) -> 0 | O19: =F19+G19+H19-J19 -> 0 | P19: =IFERROR(O19/D19,0) -> 0 | Q19: 1800 | R19: =Q19*D19 -> 0 | S19: =R19-M19 -> 0 | T19: =IFERROR(S19/R19,0) -> 0 | U19: =R19-(M19-J19-I19) -> 0 | V19: =IFERROR(U19/R19,0) -> 0
C20: TOTAL | D20: =SUM(D7:D19) -> 1966.688 | E20: =IFERROR(F20/D20,0) -> 1833.3948 | F20: =SUM(F7:F19) -> 3605715.6 | G20: =SUM(G7:G19) -> 472516.46 | H20: =SUM(H7:H19) -> 62943.242 | I20: =SUM(I7:I19) -> 170036.51 | J20: =SUM(J7:J19) -> 123846.69 | K20: =SUM(K7:K19) -> 0 | L20: 0 | M20: =SUM(M7:M19) -> 4311211.8 | N20: =IFERROR(M20/D20,0) -> 2192.1178 | O20: =SUM(O7:O19) -> 4017328.6 | P20: =IFERROR(O20/D20,0) -> 2042.6873 | Q20: =R20/D20 -> 2224.0355 | R20: =SUM(R7:R19) -> 4373984 | S20: =SUM(S7:S19) -> 62772.157 | T20: =S20/R20 -> 0.014351254 | U20: =SUM(U7:U19) -> 356655.36 | V20: =IFERROR(U20/R20,0) -> 0.08154016
C22: STOCK DE CHINA
C23: Producto | D23: TM en Stock Libre | E23: CU | F23: Costo Ventas | G23: Gasto Ventas | H23: Gasto ADM | I23: Gasto Fin | J23: Depreciación | K23: Utilidad Neta | L23: Margen Neto | M23: Venta Equilibrio a Utd Neta | N23: Precio Equilibrio x TM a Utd Neta | O23: Venta Equilibro a EBITDA | P23: Precio Equilibrio x TM a EBITDA | Q23: Precio Mercado | R23: Venta total | S23: Utilidad | T23: Mg Neto | U23: EBITDA | V23: Mg EBITDA
C24: POTA FILETE CONGELADO | D24: =Stock!K58 -> 27 | E24: =IFERROR(F24/D24,0) -> 1831.106 | F24: =Stock!L58 -> 49439.862 | G24: =Stock!M58 -> 6487.02 | H24: =Stock!N58 -> 2250.6523 | I24: =Stock!O58 -> 6079.9705 | J24: =Stock!P58 -> 4428.368 | K24: 0 | L24: 0 | M24: =F24+G24+H24+I24 -> 64257.505 | N24: =IFERROR(M24/D24,0) -> 2379.9076 | O24: =F24+G24+H24-J24 -> 53749.166 | P24: =IFERROR(O24/D24,0) -> 1990.7099 | Q24: =Q7 -> 1550 | R24: =Q24*D24 -> 41850 | S24: =R24-M24 -> -22407.505 | T24: =IFERROR(S24/R24,0) -> -0.53542425 | U24: =R24-(M24-J24-I24) -> -11899.166 | V24: =IFERROR(U24/R24,0) -> -0.28432894
C25: POTA ALAS CONGELADAS | D25: =Stock!K59 -> 54 | E25: =IFERROR(F25/D25,0) -> 1652.036 | F25: =Stock!L59 -> 89209.944 | G25: =Stock!M59 -> 12974.04 | H25: =Stock!N59 -> 4501.3046 | I25: =Stock!O59 -> 12159.941 | J25: =Stock!P59 -> 8856.7361 | K25: 0 | L25: 0 | M25: =F25+G25+H25+I25 -> 118845.23 | N25: =IFERROR(M25/D25,0) -> 2200.8376 | O25: =F25+G25+H25-J25 -> 97828.553 | P25: =IFERROR(O25/D25,0) -> 1811.6399 | Q25: =Q9 -> 1800 | R25: =Q25*D25 -> 97200 | S25: =R25-M25 -> -21645.23 | T25: =IFERROR(S25/R25,0) -> -0.22268755 | U25: =R25-(M25-J25-I25) -> -628.55253 | V25: =IFERROR(U25/R25,0) -> -0.0064665899
C26: POTA REJOS CONGELADOS | D26: =Stock!K60 -> 0 | E26: =IFERROR(F26/D26,0) -> 0 | F26: =Stock!L60 -> 0 | G26: =Stock!M60 -> 0 | H26: =Stock!N60 -> 0 | I26: =Stock!O60 -> 0 | J26: =Stock!P60 -> 0 | K26: 0 | L26: 0 | M26: =F26+G26+H26+I26 -> 0 | N26: =IFERROR(M26/D26,0) -> 0 | O26: =F26+G26+H26-J26 -> 0 | P26: =IFERROR(O26/D26,0) -> 0 | Q26: =Q11 -> 2400 | R26: =Q26*D26 -> 0 | S26: =R26-M26 -> 0 | T26: =IFERROR(S26/R26,0) -> 0 | U26: =R26-(M26-J26-I26) -> 0 | V26: =IFERROR(U26/R26,0) -> 0
C27: POTA FILETE DARUMA | D27: =Stock!K61 -> 594 | E27: =IFERROR(F27/D27,0) -> 2846.957 | F27: =Stock!L61 -> 1691092.5 | G27: =Stock!M61 -> 142714.44 | H27: =Stock!N61 -> 49514.35 | I27: =Stock!O61 -> 133759.35 | J27: =Stock!P61 -> 97424.097 | K27: 0 | L27: 0 | M27: =F27+G27+H27+I27 -> 2017080.6 | N27: =IFERROR(M27/D27,0) -> 3395.7586 | O27: =F27+G27+H27-J27 -> 1785897.2 | P27: =IFERROR(O27/D27,0) -> 3006.5609 | Q27: =Q14 -> 3500 | R27: =Q27*D27 -> 2079000 | S27: =R27-M27 -> 61919.401 | T27: =IFERROR(S27/R27,0) -> 0.029783262 | U27: =R27-(M27-J27-I27) -> 293102.85 | V27: =IFERROR(U27/R27,0) -> 0.14098261
C28: POTA ALAS COCIDAS | D28: =Stock!K62 -> 53.1 | E28: =IFERROR(F28/D28,0) -> 2574.823 | F28: =Stock!L62 -> 136723.1 | G28: =Stock!M62 -> 12757.806 | H28: =Stock!N62 -> 4426.2828 | I28: =Stock!O62 -> 11957.275 | J28: =Stock!P62 -> 8709.1238 | K28: 0 | L28: 0 | M28: =F28+G28+H28+I28 -> 165864.47 | N28: =IFERROR(M28/D28,0) -> 3123.6246 | O28: =F28+G28+H28-J28 -> 145198.07 | P28: =IFERROR(O28/D28,0) -> 2734.4269 | Q28: =Q15 -> 3500 | R28: =Q28*D28 -> 185850 | S28: =R28-M28 -> 19985.535 | T28: =IFERROR(S28/R28,0) -> 0.10753583 | U28: =R28-(M28-J28-I28) -> 40651.934 | V28: =IFERROR(U28/R28,0) -> 0.21873518
C29: POTA RECORTES COCIDOS | D29: =Stock!K63 -> 27 | E29: =IFERROR(F29/D29,0) -> 2246.62 | F29: =Stock!L63 -> 60658.74 | G29: =Stock!M63 -> 6487.02 | H29: =Stock!N63 -> 2250.6523 | I29: =Stock!O63 -> 6079.9705 | J29: =Stock!P63 -> 4428.368 | K29: 0 | L29: 0 | M29: =F29+G29+H29+I29 -> 75476.383 | N29: =IFERROR(M29/D29,0) -> 2795.4216 | O29: =F29+G29+H29-J29 -> 64968.044 | P29: =IFERROR(O29/D29,0) -> 2406.2239 | Q29: =Q10 -> 2200 | R29: =Q29*D29 -> 59400 | S29: =R29-M29 -> -16076.383 | T29: =IFERROR(S29/R29,0) -> -0.27064617 | U29: =R29-(M29-J29-I29) -> -5568.0443 | V29: =IFERROR(U29/R29,0) -> -0.093738119
C30: TOTAL | D30: =SUM(D24:D29) -> 755.1 | E30: =F30/D30 -> 2684.577 | F30: =SUM(F24:F29) -> 2027124.1 | G30: =SUM(G24:G29) -> 181420.33 | H30: =[2]Stock!N97 -> 78579 | I30: =[2]Stock!O97 -> 154473 | J30: =[2]Stock!P97 -> 123484.35 | K30: =SUM(K24:K29) -> 0 | L30: 0 | M30: =SUM(M24:M29) -> 2441524.2 | N30: =IFERROR(M30/D30,0) -> 3233.3786 | O30: =SUM(O24:O29) -> 2147641 | P30: =IFERROR(O30/D30,0) -> 2844.1809 | Q30: =R30/D30 -> 3262.2169 | R30: =SUM(R24:R29) -> 2463300 | S30: =SUM(S24:S29) -> 21775.819 | T30: =S30/R30 -> 0.0088401002 | U30: =SUM(U24:U29) -> 315659.02 | V30: =IFERROR(U30/R30,0) -> 0.12814477
D31: 909.72 | E31: 270
C32: TOTAL | D32: =D20+D30 -> 2721.788 | E32: =F32/D32 -> 2069.5365 | F32: =F20+F30 -> 5632839.7 | G32: =G20+G30 -> 653936.78 | H32: =H20+H30 -> 141522.24 | I32: =I20+I30 -> 324509.51 | J32: =J20+J30 -> 247331.04 | K32: =K20+K30 -> 0 | L32: 0 | M32: =M20+M30 -> 6752736 | N32: =IFERROR(M32/D32,0) -> 2480.9927 | O32: =O20+O30 -> 6164969.6 | P32: =IFERROR(O32/D32,0) -> 2265.044 | Q32: =R32/D32 -> 2512.056 | R32: =R20+R30 -> 6837284 | S32: =S20+S30 -> 84547.976 | T32: =S32/R32 -> 0.012365725 | U32: =U20+U30 -> 672314.38 | V32: =IFERROR(U32/R32,0) -> 0.09833062
Q34: venta stock julio + china | R34: =R30+#REF! -> #REF!
R35: =R34-'[2]Inventario Precios Altos'!R51 -> #REF! | S35: =F32*7%/12 -> 32858.232 | T35: costo financiero mes
S36: =S35/D32 -> 12.072297 | T36: costo financiero por tm
S37: =42/6*D30 -> 5285.7 | T37: costo almacenamiento mensual

Sheet Venta Septiembre
A2: VENTA DE SEPTIEMBRE 2026
A4: MES | B4: FP | C4: Fecha FP | D4: Fecha Embarque | E4: Cantidad | F4: Producto | G4: Corte | H4: Espec. | I4: País | J4: Puerto | K4: Cliente (Razón Social) | L4: Contacto | M4: Stock | N4: Precio TM | O4: VENTA CFR | P4: Flete | Q4: CU | R4: Costo Ventas | S4: Utilidad Bruta | T4: Gasto Ventas | U4: Gasto Adm | V4: Drawback | W4: Utilidad Operativa | X4: Gasto Financiero | Y4: Utilidad Neta | Z4: Depreciación | AA4: EBITDA | AC4: Margen Bruto | AD4: Margen Operativo | AE4: Margen Neto | AF4: Margen EBITDA
A5: SEPTIEMBRE | B5: 276-2026 | C5: 237 | D5: 46266 | E5: 27 | F5: POTA REPRODUCTORES | G5: Rejos Re | H5: + 60 CM , SUCKERS OFF | I5: Mexico | J5: Manzanillo | K5: GOLDEN SEAFOOD | L5: alexander | M5: Paita | N5: 2580 | O5: =E5*N5 -> 69660 | P5: 2487 | Q5: ='Resumen Inventario'!E12 -> 1615.1088 | R5: =Q5*E5 -> 43607.938 | S5: =O5-R5 -> 26052.062 | T5: =E5*207.84 -> 5611.68 | U5: =U$19/$E$19*$E5 -> 1645.3041 | V5: =(O5-P5)*0.03 -> 2015.19 | W5: =S5-T5-U5+V5 -> 20810.268 | X5: =X$19/$E$19*$E5 -> 4444.6673 | Y5: =W5-X5 -> 16365.601 | Z5: =Z$19/$E$19*$E5 -> 3237.2891 | AA5: =W5+Z5 -> 24047.557 | AC5: =S5/O5 -> 0.37398883 | AD5: =W5/O5 -> 0.29874057 | AE5: =Y5/O5 -> 0.23493541 | AF5: =AA5/O5 -> 0.34521328
A6: SEPTIEMBRE | B6: 277-2026 | C6: 240 | D6: 46276 | E6: 16.18 | F6: POTA NUCAS | G6: Nucas | H6: 500-1000 | I6: Tailandia | J6: Lat Krabang | K6: TSUJINO | L6: Jose | M6: Paita | N6: 1370 | O6: =+E6*N6 -> 22166.6 | P6: 2171.4875 | Q6: ='Resumen Inventario'!E8 -> 1522.3482 | R6: =Q6*E6 -> 24631.595 | S6: =O6-R6 -> -2464.9946 | T6: =E6*207.84 -> 3362.8512 | U6: =U$19/$E$19*$E6 -> 985.96374 | V6: =(O6-P6)*0.03 -> 599.85337 | W6: =S6-T6-U6+V6 -> -6213.9561 | X6: =X$19/$E$19*$E6 -> 2663.508 | Y6: =W6-X6 -> -8877.4641 | Z6: =Z$19/$E$19*$E6 -> 1939.9755 | AA6: =W6+Z6 -> -4273.9806 | AC6: =S6/O6 -> -0.1112031 | AD6: =W6/O6 -> -0.28032969 | AE6: =Y6/O6 -> -0.40048831 | AF6: =AA6/O6 -> -0.19281174
A7: SEPTIEMBRE | B7: 277-2026 | C7: 240 | D7: 46276 | E7: 6.32 | F7: POTA NUCAS | G7: Nucas | H7: 1 - 2 | I7: Tailandia | J7: Lat Krabang | K7: TSUJINO | L7: Jose | M7: Paita | N7: 1370 | O7: =+E7*N7 -> 8658.4 | P7: 1146.4375 | Q7: =Q6 -> 1522.3482 | R7: =Q7*E7 -> 9621.2409 | S7: =O7-R7 -> -962.8409 | T7: =E7*207.84 -> 1313.5488 | U7: =U$19/$E$19*$E7 -> 385.12304 | V7: =(O7-P7)*0.03 -> 225.35887 | W7: =S7-T7-U7+V7 -> -2436.1539 | X7: =X$19/$E$19*$E7 -> 1040.3814 | Y7: =W7-X7 -> -3476.5352 | Z7: =Z$19/$E$19*$E7 -> 757.76546 | AA7: =W7+Z7 -> -1678.3884 | AC7: =S7/O7 -> -0.1112031 | AD7: =W7/O7 -> -0.28136305 | AE7: =Y7/O7 -> -0.40152167 | AF7: =AA7/O7 -> -0.1938451
A8: SEPTIEMBRE | B8: 278-2026 | C8: 46266 | D8: 46290 | E8: 21.7 | F8: POTA CONOS | G8: Conos | I8: Tailandia | J8: Lat Krabang | K8: DAIRECK S.A. | L8: Julieta | M8: Paita | N8: 1800 | O8: =+E8*N8 -> 39060 | P8: 3237 | Q8: =1.22635851472471*1000 -> 1226.3585 | R8: =Q8*E8 -> 26611.98 | S8: =O8-R8 -> 12448.02 | T8: =E8*207.84 -> 4510.128 | U8: =U$19/$E$19*$E8 -> 1322.337 | V8: =(O8-P8)*0.03 -> 1074.69 | W8: =S8-T8-U8+V8 -> 7690.2452 | X8: =X$19/$E$19*$E8 -> 3572.1955 | Y8: =W8-X8 -> 4118.0497 | Z8: =Z$19/$E$19*$E8 -> 2601.8213 | AA8: =W8+Z8 -> 10292.066 | AC8: =S8/O8 -> 0.31868971 | AD8: =W8/O8 -> 0.19688288 | AE8: =Y8/O8 -> 0.10542882 | AF8: =AA8/O8 -> 0.26349377
A9: SEPTIEMBRE | B9: 282-2026 | C9: RD FP 257 | D9: 46275 | E9: 270 | F9: POTA FILETE CONGELADO | G9: Filete | H9: cm ct 2-4 AA | I9: China | J9: Qingdao | K9: SACRAMENTO CO., LTD | L9: julia | M9: China | N9: 1670 | O9: =+E9*N9 -> 450900 | P9: 24370 | Q9: ='Resumen Inventario'!E24 -> 1831.106 | R9: =Q9*E9 -> 494398.62 | S9: =O9-R9 -> -43498.62 | T9: =E9*207.84 -> 56116.8 | U9: =U$19/$E$19*$E9 -> 16453.041 | V9: =(O9-P9)*0.03 -> 12795.9 | W9: =S9-T9-U9+V9 -> -103272.56 | X9: =X$19/$E$19*$E9 -> 44446.673 | Y9: =W9-X9 -> -147719.23 | Z9: =Z$19/$E$19*$E9 -> 32372.891 | AA9: =W9+Z9 -> -70899.67 | AC9: =S9/O9 -> -0.096470659 | AD9: =W9/O9 -> -0.22903651 | AE9: =Y9/O9 -> -0.32760974 | AF9: =AA9/O9 -> -0.15724034
A10: SEPTIEMBRE | B10: 285-2026 | C10: 46276 | D10: 46290 | E10: 13 | F10: POTA REJOS CONGELADOS | G10: Rejos | H10: 300 - 500 | I10: China | J10: Xiamen | K10: Shenzhen Yueshi Supply | L10: susan | M10: China | N10: 2900 | O10: =+E10*N10 -> 37700 | P10: 1251.8519 | Q10: 1783.985 | R10: =Q10*E10 -> 23191.805 | S10: =O10-R10 -> 14508.195 | T10: =E10*207.84 -> 2701.92 | U10: =U$19/$E$19*$E10 -> 792.18347 | V10: =(O10-P10)*0.03 -> 1093.4444 | W10: =S10-T10-U10+V10 -> 12107.536 | X10: =X$19/$E$19*$E10 -> 2140.025 | Y10: =W10-X10 -> 9967.511 | Z10: =Z$19/$E$19*$E10 -> 1558.6948 | AA10: =W10+Z10 -> 13666.231 | AC10: =S10/O10 -> 0.38483276 | AD10: =W10/O10 -> 0.3211548 | AE10: =Y10/O10 -> 0.26439021 | AF10: =AA10/O10 -> 0.36249949
A11: SEPTIEMBRE | B11: 285-2026 | C11: 46276 | D11: 46290 | E11: 14 | F11: POTA REJOS CONGELADOS | G11: Rejos | H11: 500 - 1000 | I11: China | J11: Xiamen | K11: Shenzhen Yueshi Supply | L11: susan | M11: China | N11: 2500 | O11: =+E11*N11 -> 35000 | P11: 1348.1481 | Q11: 1783.985 | R11: =Q11*E11 -> 24975.79 | S11: =O11-R11 -> 10024.21 | T11: =E11*207.84 -> 2909.76 | U11: =U$19/$E$19*$E11 -> 853.12066 | V11: =(O11-P11)*0.03 -> 1009.5556 | W11: =S11-T11-U11+V11 -> 7270.8849 | X11: =X$19/$E$19*$E11 -> 2304.6423 | Y11: =W11-X11 -> 4966.2426 | Z11: =Z$19/$E$19*$E11 -> 1678.5944 | AA11: =W11+Z11 -> 8949.4793 | AC11: =S11/O11 -> 0.286406 | AD11: =W11/O11 -> 0.20773957 | AE11: =Y11/O11 -> 0.14189265 | AF11: =AA11/O11 -> 0.25569941
A12: SEPTIEMBRE | B12: 286-2026 | C12: 46276 | D12: 46293 | E12: 26 | F12: POTA RECORTES | G12: Recortes cocidos | I12: España | J12: Vigo | K12: PESCIRO | L12: Francisco | M12: Paita | N12: 2300 | O12: =+E12*N12 -> 59800 | P12: 5332 | Q12: ='Resumen Inventario'!E10 -> 1611.8872 | R12: =Q12*E12 -> 41909.067 | S12: =O12-R12 -> 17890.933 | T12: =E12*207.84 -> 5403.84 | U12: =U$19/$E$19*$E12 -> 1584.3669 | V12: =(O12-P12)*0.03 -> 1634.04 | W12: =S12-T12-U12+V12 -> 12536.766 | X12: =X$19/$E$19*$E12 -> 4280.05 | Y12: =W12-X12 -> 8256.7163 | Z12: =Z$19/$E$19*$E12 -> 3117.3895 | AA12: =W12+Z12 -> 15654.156 | AC12: =S12/O12 -> 0.29917948 | AD12: =W12/O12 -> 0.20964492 | AE12: =Y12/O12 -> 0.13807218 | AF12: =AA12/O12 -> 0.26177518
A13: SEPTIEMBRE | B13: 287-2026 | C13: 46277 | D13: 46293 | E13: 26 | F13: POTA RECORTES | G13: Recortes cocidos | I13: España | J13: Vigo | K13: PESCIRO | L13: Francisco | M13: Paita | N13: 2300 | O13: =+E13*N13 -> 59800 | P13: 5332 | Q13: =Q12 -> 1611.8872 | R13: =Q13*E13 -> 41909.067 | S13: =O13-R13 -> 17890.933 | T13: =E13*207.84 -> 5403.84 | U13: =U$19/$E$19*$E13 -> 1584.3669 | V13: =(O13-P13)*0.03 -> 1634.04 | W13: =S13-T13-U13+V13 -> 12536.766 | X13: =X$19/$E$19*$E13 -> 4280.05 | Y13: =W13-X13 -> 8256.7163 | Z13: =Z$19/$E$19*$E13 -> 3117.3895 | AA13: =W13+Z13 -> 15654.156 | AC13: =S13/O13 -> 0.29917948 | AD13: =W13/O13 -> 0.20964492 | AE13: =Y13/O13 -> 0.13807218 | AF13: =AA13/O13 -> 0.26177518
A14: SEPTIEMBRE | B14: 259-2026 | E14: 270 | F14: POTA FILETE CONGELADO | G14: Filete | I14: China | K14: JAMES | L14: James | M14: China | N14: 1500 | O14: =+E14*N14 -> 405000 | P14: 24370 | Q14: =Q9 -> 1831.106 | R14: =Q14*E14 -> 494398.62 | S14: =O14-R14 -> -89398.62 | T14: =E14*207.84 -> 56116.8 | U14: =U$19/$E$19*$E14 -> 16453.041 | V14: =(O14-P14)*0.03 -> 11418.9 | W14: =S14-T14-U14+V14 -> -150549.56 | X14: =X$19/$E$19*$E14 -> 44446.673 | Y14: =W14-X14 -> -194996.23 | Z14: =Z$19/$E$19*$E14 -> 32372.891 | AA14: =W14+Z14 -> -118176.67 | AC14: =S14/O14 -> -0.22073733 | AD14: =W14/O14 -> -0.37172731 | AE14: =Y14/O14 -> -0.48147218 | AF14: =AA14/O14 -> -0.29179425
A15: SEPTIEMBRE | B15: 265-2026 | E15: 81 | F15: POTA REJOS CONGELADOS | G15: Rejos | I15: China | K15: JAMES | L15: James | M15: China | N15: 2300 | O15: =+E15*N15 -> 186300 | P15: 8400 | Q15: =Q10 -> 1783.985 | R15: =Q15*E15 -> 144502.78 | S15: =O15-R15 -> 41797.215 | T15: =E15*207.84 -> 16835.04 | U15: =U$19/$E$19*$E15 -> 4935.9124 | V15: =(O15-P15)*0.03 -> 5337 | W15: =S15-T15-U15+V15 -> 25363.263 | X15: =X$19/$E$19*$E15 -> 13334.002 | Y15: =W15-X15 -> 12029.261 | Z15: =Z$19/$E$19*$E15 -> 9711.8674 | AA15: =W15+Z15 -> 35075.13 | AC15: =S15/O15 -> 0.22435435 | AD15: =W15/O15 -> 0.13614204 | AE15: =Y15/O15 -> 0.064569301 | AF15: =AA15/O15 -> 0.1882723
A16: SEPTIEMBRE | B16: 275-2026A | E16: 130.86 | F16: ALAS COCIDAS | G16: Alas coc | I16: China | K16: JAMES | L16: James | M16: China | N16: 3300 | O16: =+E16*N16 -> 431838 | P16: 13000 | Q16: ='Resumen Inventario'!E28 -> 2574.823 | R16: =Q16*E16 -> 336941.34 | S16: =O16-R16 -> 94896.662 | T16: =E16*207.84 -> 27197.942 | U16: =U$19/$E$19*$E16 -> 7974.2407 | V16: =(O16-P16)*0.03 -> 12565.14 | W16: =S16-T16-U16+V16 -> 72289.619 | X16: =X$19/$E$19*$E16 -> 21541.821 | Y16: =W16-X16 -> 50747.798 | Z16: =Z$19/$E$19*$E16 -> 15690.061 | AA16: =W16+Z16 -> 87979.68 | AC16: =S16/O16 -> 0.21975061 | AD16: =W16/O16 -> 0.16739986 | AE16: =Y16/O16 -> 0.11751582 | AF16: =AA16/O16 -> 0.20373307
A17: SEPTIEMBRE | B17: 275-2026A | E17: 130.86 | F17: ALAS COCIDAS | G17: Alas coc | I17: China | K17: JAMES | L17: James | M17: China | N17: 3300 | O17: =+E17*N17 -> 431838 | P17: 13000 | Q17: =Q16 -> 2574.823 | R17: =Q17*E17 -> 336941.34 | S17: =O17-R17 -> 94896.662 | T17: =E17*207.84 -> 27197.942 | U17: =U$19/$E$19*$E17 -> 7974.2407 | V17: =(O17-P17)*0.03 -> 12565.14 | W17: =S17-T17-U17+V17 -> 72289.619 | X17: =X$19/$E$19*$E17 -> 21541.821 | Y17: =W17-X17 -> 50747.798 | Z17: =Z$19/$E$19*$E17 -> 15690.061 | AA17: =W17+Z17 -> 87979.68 | AC17: =S17/O17 -> 0.21975061 | AD17: =W17/O17 -> 0.16739986 | AE17: =Y17/O17 -> 0.11751582 | AF17: =AA17/O17 -> 0.20373307
D19: TOTAL | E19: =SUBTOTAL(9,E5:E17) -> 1032.92 | O19: =SUBTOTAL(9,O5:O17) -> 2237721 | R19: =SUBTOTAL(9,R5:R17) -> 2043641.2 | S19: =SUBTOTAL(9,S5:S17) -> 194079.82 | T19: =SUBTOTAL(9,T5:T17) -> 214682.09 | U19: =Stock!N52 -> 62943.243 | V19: =SUBTOTAL(9,V5:V17) -> 63968.252 | W19: =SUBTOTAL(9,W5:W17) -> -19577.265 | X19: =Stock!O52 -> 170036.51 | Y19: =SUBTOTAL(9,Y5:Y17) -> -189613.77 | Z19: =Stock!P52 -> 123846.69 | AA19: =SUBTOTAL(9,AA5:AA17) -> 104269.43 | AC19: =S19/O19 -> 0.086731017 | AD19: =W19/O19 -> -0.0087487517 | AE19: =Y19/O19 -> -0.084735216 | AF19: =AA19/O19 -> 0.046596259

Sheet TD
B2: STOCK SEPTIEMBRE
E3: Etiquetas de fila | F3: Suma de TM en Stock | G3: Suma de Costo Ventas | H3: Suma de Gasto Ventas | I3: Suma de Gasto ADM | J3: Suma de Gasto Fin | K3: Suma de Depreciación
B4: =C4=E4 -> TRUE | C4: 10005721 | D4: POTA FILETE CONGELADO | E4: 10005721 | F4: 116.14 | G4: 191297.8 | H4: 27903.796 | I4: 3717.0249 | J4: 10041.267 | K4: 7313.5926
B5: =C5=E5 -> TRUE | C5: 10005779 | D5: POTA NUCAS CONGELADAS | E5: 10005779 | F5: 493.02 | G5: 750548.13 | H5: 118452.99 | I5: 15778.953 | J5: 42625.673 | K5: 31046.56
B6: =C6=E6 -> TRUE | C6: 10006719 | D6: POTA ALAS CONGELADAS | E6: 10006719 | F6: 51.42 | G6: 69610.403 | H6: 12354.169 | I6: 1645.6812 | J6: 4445.686 | K6: 3238.0311
B7: =C7=E7 -> TRUE | C7: 10007050 | D7: POTA RECORTES COCIDOS | E7: 10007050 | F7: 171.83 | G7: 276970.58 | H7: 41283.876 | I7: 5499.3661 | J7: 14856.13 | K7: 10820.515
B8: =C8=E8 -> TRUE | C8: 10007162 | D8: POTA REJOS CONGELADOS | E8: 10007162 | F8: 520.24 | G8: 858010.61 | H8: 124992.86 | I8: 16650.121 | J8: 44979.068 | K8: 32760.663
B9: =C9=E9 -> TRUE | C9: 10007567 | D9: POTA REPRODUCTORES | E9: 10007567 | F9: 135.72 | G9: 219202.57 | H9: 32608.087 | I9: 4343.6767 | J9: 11734.121 | K9: 8546.5885
B10: =C10=E10 -> TRUE | C10: 10007969 | D10: POTA CONOS | E10: 10007969 | F10: 0 | G10: 0 | H10: 0 | I10: 0 | J10: 0 | K10: 0
B11: =C11=E11 -> TRUE | C11: 10009239 | D11: POTA FILETE DARUMA | E11: 10009239 | F11: 264.46 | G11: 800846.8 | H11: 63539.16 | I11: 8463.9607 | J11: 22864.763 | K11: 16653.631
B12: =C12=E12 -> TRUE | C12: 10009334 | D12: POTA ALAS COCIDAS | E12: 10009334 | F12: 94.718 | G12: 263433.73 | H12: 22756.947 | I12: 3031.4204 | J12: 8189.1576 | K12: 5964.6019
B13: =C13=E13 -> TRUE | C13: 10009386 | D13: VENTOSAS | E13: 10009386 | F13: 24.36 | G13: 53193.7 | H13: 5852.7336 | I13: 779.63428 | J13: 2106.1243 | K13: 1534.0031
D14: OTROS | E14: 10010320 | F14: 45.46 | G14: 61634.574 | H14: 10922.22 | I14: 1454.9333 | J14: 3930.3945 | K14: 2862.7167
D15: ALAS REPROCESO | E15: 10009649 | F15: 49.32 | G15: 60966.749 | H15: 11849.623 | I15: 1578.4714 | J15: 4264.1235 | K15: 3105.7895
E16: (en blanco)
E17: Total general | F17: 1966.688 | G17: 3605715.6 | H17: 472516.46 | I17: 62943.242 | J17: 170036.51 | K17: 123846.69

Sheet Stock
K2: STOCK EN PAITA
F3: Al cierre de Agosto | G3: Simulador Septiembre
B4: CODIGO | C4: PRODUCTO | D4: STOCK LIBRE | F4: CU Producción | G4: CU Producción | H4: Promedio CU | J4: CÓDIGO | K4: TM en Stock | L4: Costo Ventas | M4: Gasto Ventas | N4: Gasto ADM | O4: Gasto Fin | P4: Depreciación | Q4: Utilidad Neta | R4: Margen Neto | S4: Venta Equilibrio | T4: Precio Equilibrio x TM
B5: 10009178 | C5: POTA ALAS FR C/P C/C (B) S/COD BL10 S20 | D5: 8920 | F5: =IFERROR(VLOOKUP(B5,[3]Hoja1!$I$25:$J$77,2,0),0) -> 1748.7075 | G5: 1236.1466 | H5: =AVERAGE(F5:G5) -> 1492.4271 | I5: ALAS FRESCAS | J5: 10006719 | K5: =D5/1000 -> 8.92 | L5: =H5*D5/1000 -> 13312.449 | M5: =240.26*D5/1000 -> 2143.1192 | N5: =K5/$K$50*$N$52 -> 285.48185 | O5: =K5/$K$50*$O$52 -> 771.20806 | P5: =K5/$K$50*$P$52 -> 561.71213 | Q5: =0 -> 0 | S5: =SUM(L5:O5) -> 16512.259 | T5: =IFERROR(S5/K5,0) -> 1851.1501
B6: 10006668 | C6: POTA ALAS FR C/P C/C <0.5 BL10 S20 | D6: 760 | F6: =IFERROR(VLOOKUP(B6,[3]Hoja1!$I$25:$J$77,2,0),0) -> 1665.3824 | G6: 1236.1466 | H6: =AVERAGE(F6:G6) -> 1450.7645 | I6: ALAS FRESCAS | J6: 10006719 | K6: =D6/1000 -> 0.76 | L6: =H6*D6/1000 -> 1102.581 | M6: =240.26*D6/1000 -> 182.5976 | N6: =K6/$K$50*$N$52 -> 24.323565 | O6: =K6/$K$50*$O$52 -> 65.70831 | P6: =K6/$K$50*$P$52 -> 47.858881 | Q6: =0 -> 0 | S6: =SUM(L6:O6) -> 1375.2105 | T6: =IFERROR(S6/K6,0) -> 1809.4875
B7: 10006719 | C7: POTA ALAS FR C/P C/C 0.5-1 BL10 S20 | D7: 0 | F7: =IFERROR(VLOOKUP(B7,[3]Hoja1!$I$25:$J$77,2,0),0) -> 1559.625 | G7: 1236.1466 | H7: =AVERAGE(F7:G7) -> 1397.8858 | I7: ALAS FRESCAS | J7: 10006719 | K7: =D7/1000 -> 0 | L7: =H7*D7/1000 -> 0 | M7: =240.26*D7/1000 -> 0 | N7: =K7/$K$50*$N$52 -> 0 | O7: =K7/$K$50*$O$52 -> 0 | P7: =K7/$K$50*$P$52 -> 0 | Q7: =0 -> 0 | S7: =SUM(L7:O7) -> 0 | T7: =IFERROR(S7/K7,0) -> 0
B8: 10010110 | C8: POTA ALAS FR C/P C/C 1-2 BL10 S20 ENTERA | D8: 0 | F8: =IFERROR(VLOOKUP(B8,[3]Hoja1!$I$25:$J$77,2,0),0) -> 1647.8182 | G8: 1236.1466 | H8: =AVERAGE(F8:G8) -> 1441.9824 | I8: ALAS FRESCAS | J8: 10006719 | K8: =D8/1000 -> 0 | L8: =H8*D8/1000 -> 0 | M8: =240.26*D8/1000 -> 0 | N8: =K8/$K$50*$N$52 -> 0 | O8: =K8/$K$50*$O$52 -> 0 | P8: =K8/$K$50*$P$52 -> 0 | Q8: =0 -> 0 | S8: =SUM(L8:O8) -> 0 | T8: =IFERROR(S8/K8,0) -> 0
B9: 10009207 | C9: POTA LABIOS FR S/COD BL10 S20 | D9: 41740 | F9: =IFERROR(VLOOKUP(B9,[3]Hoja1!$I$25:$J$77,2,0),0) -> 1408.5766 | G9: 1236.1466 | H9: =AVERAGE(F9:G9) -> 1322.3616 | I9: ALAS FRESCAS | J9: 10006719 | K9: =D9/1000 -> 41.74 | L9: =H9*D9/1000 -> 55195.373 | M9: =240.26*D9/1000 -> 10028.452 | N9: =K9/$K$50*$N$52 -> 1335.8758 | O9: =K9/$K$50*$O$52 -> 3608.7696 | P9: =K9/$K$50*$P$52 -> 2628.4601 | Q9: =0 -> 0 | S9: =SUM(L9:O9) -> 70168.471 | T9: =IFERROR(S9/K9,0) -> 1681.0846
B10: 10007969 | C10: POTA CONOS | D10: 0 | F10: =IFERROR(VLOOKUP(B10,[3]Hoja1!$I$25:$J$77,2,0),0) -> 1226.375 | G10: 807.53922 | H10: =AVERAGE(F10:G10) -> 1016.9571 | I10: CONOS | J10: 10007969 | K10: =D10/1000 -> 0 | L10: =H10*D10/1000 -> 0 | M10: =240.26*D10/1000 -> 0 | N10: =K10/$K$50*$N$52 -> 0 | O10: =K10/$K$50*$O$52 -> 0 | P10: =K10/$K$50*$P$52 -> 0 | Q10: =0 -> 0 | S10: =SUM(L10:O10) -> 0 | T10: =IFERROR(S10/K10,0) -> 0
B11: 10004434 | C11: POTA FILETE C/M C/T FR 1-2 BL10 S20 | D11: 1900 | F11: =IFERROR(VLOOKUP(B11,[3]Hoja1!$I$25:$J$77,2,0),0) -> 2064.6364 | G11: 1488.5392 | H11: =AVERAGE(F11:G11) -> 1776.5878 | I11: FILETE FRESCO | J11: 10005721 | K11: =D11/1000 -> 1.9 | L11: =H11*D11/1000 -> 3375.5168 | M11: =240.26*D11/1000 -> 456.494 | N11: =K11/$K$50*$N$52 -> 60.808914 | O11: =K11/$K$50*$O$52 -> 164.27078 | P11: =K11/$K$50*$P$52 -> 119.6472 | Q11: =0 -> 0 | S11: =SUM(L11:O11) -> 4057.0905 | T11: =IFERROR(S11/K11,0) -> 2135.3108
B12: 10004435 | C12: POTA FILETE C/M C/T FR 2-4 S20 | D12: 32180 | F12: =IFERROR(VLOOKUP(B12,[3]Hoja1!$I$25:$J$77,2,0),0) -> 1758.0258 | G12: 1488.5392 | H12: =AVERAGE(F12:G12) -> 1623.2825 | I12: FILETE FRESCO | J12: 10005721 | K12: =D12/1000 -> 32.18 | L12: =H12*D12/1000 -> 52237.231 | M12: =240.26*D12/1000 -> 7731.5668 | N12: =K12/$K$50*$N$52 -> 1029.911 | O12: =K12/$K$50*$O$52 -> 2782.2282 | P12: =K12/$K$50*$P$52 -> 2026.4458 | Q12: =0 -> 0 | S12: =SUM(L12:O12) -> 63780.937 | T12: =IFERROR(S12/K12,0) -> 1982.0055
B13: 10005708 | C13: POTA FILETE C/M C/T FR <0.5 Kg AA BL10 S20 | D13: 1080 | F13: =IFERROR(VLOOKUP(B13,[3]Hoja1!$I$25:$J$77,2,0),0) -> 2023.8796 | G13: 1488.5392 | H13: =AVERAGE(F13:G13) -> 1756.2094 | I13: FILETE FRESCO | J13: 10005721 | K13: =D13/1000 -> 1.08 | L13: =H13*D13/1000 -> 1896.7062 | M13: =240.26*D13/1000 -> 259.4808 | N13: =K13/$K$50*$N$52 -> 34.565067 | O13: =K13/$K$50*$O$52 -> 93.374968 | P13: =K13/$K$50*$P$52 -> 68.009988 | Q13: =0 -> 0 | S13: =SUM(L13:O13) -> 2284.127 | T13: =IFERROR(S13/K13,0) -> 2114.9324
B14: 10005721 | C14: POTA FILETE C/M C/T FR 2-4 (AA) BL10 S20 | D14: 3100 | F14: =IFERROR(VLOOKUP(B14,[3]Hoja1!$I$25:$J$77,2,0),0) -> 1959.7103 | G14: 1488.5392 | H14: =AVERAGE(F14:G14) -> 1724.1247 | I14: FILETE FRESCO | J14: 10005721 | K14: =D14/1000 -> 3.1 | L14: =H14*D14/1000 -> 5344.7867 | M14: =240.26*D14/1000 -> 744.806 | N14: =K14/$K$50*$N$52 -> 99.214543 | O14: =K14/$K$50*$O$52 -> 268.02074 | P14: =K14/$K$50*$P$52 -> 195.21386 | Q14: =0 -> 0 | S14: =SUM(L14:O14) -> 6456.828 | T14: =IFERROR(S14/K14,0) -> 2082.8477
B15: 10010126 | C15: POTA FILETE C/M C/T FR 1.0 - 3.0 AA BL10 S20 | D15: 5280 | F15: =IFERROR(VLOOKUP(B15,[3]Hoja1!$I$25:$J$77,2,0),0) -> 1787.3674 | G15: 1488.5392 | H15: =AVERAGE(F15:G15) -> 1637.9533 | I15: FILETE FRESCO | J15: 10005721 | K15: =D15/1000 -> 5.28 | L15: =H15*D15/1000 -> 8648.3936 | M15: =240.26*D15/1000 -> 1268.5728 | N15: =K15/$K$50*$N$52 -> 168.98477 | O15: =K15/$K$50*$O$52 -> 456.49984 | P15: =K15/$K$50*$P$52 -> 332.49328 | Q15: =0 -> 0 | S15: =SUM(L15:O15) -> 10542.451 | T15: =IFERROR(S15/K15,0) -> 1996.6763
B16: 10005718 | C16: POTA FILETE C/M C/T FR 1-2 AA BL10 S20 JAPON | D16: 17700 | F16: =IFERROR(VLOOKUP(B16,[3]Hoja1!$I$25:$J$77,2,0),0) -> 1904.1873 | G16: 1488.5392 | H16: =AVERAGE(F16:G16) -> 1696.3632 | I16: FILETE FRESCO | J16: 10005721 | K16: =D16/1000 -> 17.7 | L16: =H16*D16/1000 -> 30025.629 | M16: =240.26*D16/1000 -> 4252.602 | N16: =K16/$K$50*$N$52 -> 566.48304 | O16: =K16/$K$50*$O$52 -> 1530.312 | P16: =K16/$K$50*$P$52 -> 1114.6081 | Q16: =0 -> 0 | S16: =SUM(L16:O16) -> 36375.026 | T16: =IFERROR(S16/K16,0) -> 2055.0862
B17: 10009972 | C17: POTA FILETE C/M C/T FR 1-2 AA BL10 S20 50% ROSADO | D17: 2720 | F17: =IFERROR(VLOOKUP(B17,[3]Hoja1!$I$25:$J$77,2,0),0) -> 0 | G17: 1488.5392 | H17: =G17 -> 1488.5392 | I17: FILETE FRESCO | J17: 10005721 | K17: =D17/1000 -> 2.72 | L17: =H17*D17/1000 -> 4048.8267 | M17: =240.26*D17/1000 -> 653.5072 | N17: =K17/$K$50*$N$52 -> 87.052761 | O17: =K17/$K$50*$O$52 -> 235.16658 | P17: =K17/$K$50*$P$52 -> 171.28442 | Q17: =0 -> 0 | S17: =SUM(L17:O17) -> 5024.5532 | T17: =IFERROR(S17/K17,0) -> 1847.2622
B18: 10009298 | C18: POTA FILETE SM ST 1-2 CM/ESP | D18: 27040 | F18: =IFERROR(VLOOKUP(B18,[3]Hoja1!$I$25:$J$77,2,0),0) -> 2083.8594 | G18: 1488.5392 | H18: =AVERAGE(F18:G18) -> 1786.1993 | I18: FILETE FRESCO | J18: 10005721 | K18: =D18/1000 -> 27.04 | L18: =H18*D18/1000 -> 48298.829 | M18: =240.26*D18/1000 -> 6496.6304 | N18: =K18/$K$50*$N$52 -> 865.40686 | O18: =K18/$K$50*$O$52 -> 2337.8325 | P18: =K18/$K$50*$P$52 -> 1702.7686 | Q18: =0 -> 0 | S18: =SUM(L18:O18) -> 57998.699 | T18: =IFERROR(S18/K18,0) -> 2144.9223
B19: 10009644 | C19: POTA FILETE C/M C/T 4.0 - UP BL10 S20 | D19: 25140 | F19: =IFERROR(VLOOKUP(B19,[3]Hoja1!$I$25:$J$77,2,0),0) -> 0 | G19: 1488.5392 | H19: =G19 -> 1488.5392 | I19: FILETE FRESCO | J19: 10005721 | K19: =D19/1000 -> 25.14 | L19: =H19*D19/1000 -> 37421.876 | M19: =240.26*D19/1000 -> 6040.1364 | N19: =K19/$K$50*$N$52 -> 804.59794 | O19: =K19/$K$50*$O$52 -> 2173.5617 | P19: =K19/$K$50*$P$52 -> 1583.1214 | Q19: =0 -> 0 | S19: =SUM(L19:O19) -> 46440.172 | T19: =IFERROR(S19/K19,0) -> 1847.2622
B20: 10010320 | C20: POTA MANTO C/M C/T FR 2.0 - 4.0 BL10 S20 | D20: 25440 | F20: =IFERROR(VLOOKUP(B20,[3]Hoja1!$I$25:$J$77,2,0),0) -> 0 | G20: 1355.7979 | H20: =G20 -> 1355.7979 | I20: MANTO | J20: 10010320 | K20: =D20/1000 -> 25.44 | L20: =H20*D20/1000 -> 34491.499 | M20: =240.26*D20/1000 -> 6112.2144 | N20: =K20/$K$50*$N$52 -> 814.19935 | O20: =K20/$K$50*$O$52 -> 2199.4992 | P20: =K20/$K$50*$P$52 -> 1602.0131 | Q20: =0 -> 0 | S20: =SUM(L20:O20) -> 43617.412 | T20: =IFERROR(S20/K20,0) -> 1714.5209
B21: 10010347 | C21: POTA MANTO C/M C/T FR 2.0 - 4.0 AA BL10 S20 | D21: 20020 | F21: =IFERROR(VLOOKUP(B21,[3]Hoja1!$I$25:$J$77,2,0),0) -> 0 | G21: 1355.7979 | H21: =G21 -> 1355.7979 | I21: MANTO | J21: 10010320 | K21: =D21/1000 -> 20.02 | L21: =H21*D21/1000 -> 27143.075 | M21: =240.26*D21/1000 -> 4810.0052 | N21: =K21/$K$50*$N$52 -> 640.73392 | O21: =K21/$K$50*$O$52 -> 1730.8952 | P21: =K21/$K$50*$P$52 -> 1260.7037 | Q21: =0 -> 0 | S21: =SUM(L21:O21) -> 34324.709 | T21: =IFERROR(S21/K21,0) -> 1714.5209
B22: 10009184 | C22: POTA NUCAS FR ABIERTAS 0.1 - 0.3 BL10 S2 | D22: 140860 | F22: =IFERROR(VLOOKUP(B22,[3]Hoja1!$I$25:$J$77,2,0),0) -> 1856.2376 | G22: 1242.7305 | H22: =AVERAGE(F22:G22) -> 1549.484 | I22: NUCAS | J22: 10005779 | K22: =D22/1000 -> 140.86 | L22: =H22*D22/1000 -> 218260.32 | M22: =240.26*D22/1000 -> 33843.024 | N22: =K22/$K$50*$N$52 -> 4508.1808 | O22: =K22/$K$50*$O$52 -> 12178.517 | P22: =K22/$K$50*$P$52 -> 8870.2657 | Q22: =0 -> 0 | S22: =SUM(L22:O22) -> 268790.04 | T22: =IFERROR(S22/K22,0) -> 1908.207
B23: 10009271 | C23: POTA NUCAS FR CERRADA 0.1 - 0.3 BL10 S2 | D23: 41820 | F23: =IFERROR(VLOOKUP(B23,[3]Hoja1!$I$25:$J$77,2,0),0) -> 1837.4357 | G23: 1242.7305 | H23: =AVERAGE(F23:G23) -> 1540.0831 | I23: NUCAS | J23: 10005779 | K23: =D23/1000 -> 41.82 | L23: =H23*D23/1000 -> 64406.276 | M23: =240.26*D23/1000 -> 10047.673 | N23: =K23/$K$50*$N$52 -> 1338.4362 | O23: =K23/$K$50*$O$52 -> 3615.6862 | P23: =K23/$K$50*$P$52 -> 2633.4979 | Q23: =0 -> 0 | S23: =SUM(L23:O23) -> 79408.072 | T23: =IFERROR(S23/K23,0) -> 1898.8061
B24: 10009183 | C24: POTA NUCAS FR CERRADA <0.1 BL10 S2 | D24: 1040 | F24: =IFERROR(VLOOKUP(B24,[3]Hoja1!$I$25:$J$77,2,0),0) -> 1837.7308 | G24: 1242.7305 | H24: =AVERAGE(F24:G24) -> 1540.2306 | I24: NUCAS | J24: 10005779 | K24: =D24/1000 -> 1.04 | L24: =H24*D24/1000 -> 1601.8399 | M24: =240.26*D24/1000 -> 249.8704 | N24: =K24/$K$50*$N$52 -> 33.284879 | O24: =K24/$K$50*$O$52 -> 89.916635 | P24: =K24/$K$50*$P$52 -> 65.4911 | Q24: =0 -> 0 | S24: =SUM(L24:O24) -> 1974.9118 | T24: =IFERROR(S24/K24,0) -> 1898.9536
B25: 10005779 | C25: POTA NUCAS FR ABIERTAS 0.5-1 BL10 S20 | D25: 91080 | F25: =IFERROR(VLOOKUP(B25,[3]Hoja1!$I$25:$J$77,2,0),0) -> 1735.8204 | G25: 1242.7305 | H25: =AVERAGE(F25:G25) -> 1489.2755 | I25: NUCAS | J25: 10005779 | K25: =D25/1000 -> 91.08 | L25: =H25*D25/1000 -> 135643.21 | M25: =240.26*D25/1000 -> 21882.881 | N25: =K25/$K$50*$N$52 -> 2914.9873 | O25: =K25/$K$50*$O$52 -> 7874.6223 | P25: =K25/$K$50*$P$52 -> 5735.509 | Q25: =0 -> 0 | S25: =SUM(L25:O25) -> 168315.7 | T25: =IFERROR(S25/K25,0) -> 1847.9985
B26: 10005776 | C26: POTA NUCAS FR ABIERTAS 0.3-0.5 BL10 S20 | D26: 212380 | F26: =IFERROR(VLOOKUP(B26,[3]Hoja1!$I$25:$J$77,2,0),0) -> 1787.9198 | G26: 1242.7305 | H26: =AVERAGE(F26:G26) -> 1515.3251 | I26: NUCAS | J26: 10005779 | K26: =D26/1000 -> 212.38 | L26: =H26*D26/1000 -> 321824.75 | M26: =240.26*D26/1000 -> 51026.419 | N26: =K26/$K$50*$N$52 -> 6797.1564 | O26: =K26/$K$50*$O$52 -> 18362.014 | P26: =K26/$K$50*$P$52 -> 13374.038 | Q26: =0 -> 0 | S26: =SUM(L26:O26) -> 398010.34 | T26: =IFERROR(S26/K26,0) -> 1874.0481
B27: 10005781 | C27: POTA NUCAS FR ABIERTAS 1-2 BL10 S20 | D27: 5840 | F27: =IFERROR(VLOOKUP(B27,[3]Hoja1!$I$25:$J$77,2,0),0) -> 1774.985 | G27: 1242.7305 | H27: =AVERAGE(F27:G27) -> 1508.8578 | I27: NUCAS | J27: 10005779 | K27: =D27/1000 -> 5.84 | L27: =H27*D27/1000 -> 8811.7294 | M27: =240.26*D27/1000 -> 1403.1184 | N27: =K27/$K$50*$N$52 -> 186.9074 | O27: =K27/$K$50*$O$52 -> 504.91649 | P27: =K27/$K$50*$P$52 -> 367.75771 | Q27: =0 -> 0 | S27: =SUM(L27:O27) -> 10906.672 | T27: =IFERROR(S27/K27,0) -> 1867.5808
B28: 10007567 | C28: POTA REJOS OR FR LIMPIOS S/COD BL10 S20 | D28: 99800 | E28: REPRODUCTORES | F28: =IFERROR(VLOOKUP(B28,[3]Hoja1!$I$25:$J$77,2,0),0) -> 1661.5122 | G28: 1541.8895 | H28: =AVERAGE(F28:G28) -> 1601.7008 | I28: REPRODUCTORES | J28: 10007567 | K28: =D28/1000 -> 99.8 | L28: =H28*D28/1000 -> 159849.74 | M28: =240.26*D28/1000 -> 23977.948 | N28: =K28/$K$50*$N$52 -> 3194.0682 | O28: =K28/$K$50*$O$52 -> 8628.5387 | P28: =K28/$K$50*$P$52 -> 6284.6267 | Q28: =0 -> 0 | S28: =SUM(L28:O28) -> 195650.3 | T28: =IFERROR(S28/K28,0) -> 1960.4238
B29: 10010107 | C29: POTA REJOS OR FR LIMPIOS <60 cm BL10 S20 | D29: 35920 | E29: REPRODUCTORES | F29: =IFERROR(VLOOKUP(B29,[3]Hoja1!$I$25:$J$77,2,0),0) -> 1762.8334 | G29: 1541.8895 | H29: =AVERAGE(F29:G29) -> 1652.3615 | I29: REPRODUCTORES | J29: 10007567 | K29: =D29/1000 -> 35.92 | L29: =H29*D29/1000 -> 59352.824 | M29: =240.26*D29/1000 -> 8630.1392 | N29: =K29/$K$50*$N$52 -> 1149.6085 | O29: =K29/$K$50*$O$52 -> 3105.5823 | P29: =K29/$K$50*$P$52 -> 2261.9618 | Q29: =0 -> 0 | S29: =SUM(L29:O29) -> 72238.154 | T29: =IFERROR(S29/K29,0) -> 2011.0845
B30: 10009186 | C30: POTA REJOS FR C/U C/V S/OR 0.1-0.3 BL10 | D30: 40 | E30: REJOS | F30: =IFERROR(VLOOKUP(B30,[3]Hoja1!$I$25:$J$77,2,0),0) -> 1711 | G30: 1541.8895 | H30: =AVERAGE(F30:G30) -> 1626.4447 | I30: REJOS | J30: 10007162 | K30: =D30/1000 -> 0.04 | L30: =H30*D30/1000 -> 65.05779 | M30: =240.26*D30/1000 -> 9.6104 | N30: =K30/$K$50*$N$52 -> 1.2801877 | O30: =K30/$K$50*$O$52 -> 3.4583321 | P30: =K30/$K$50*$P$52 -> 2.5188885 | Q30: =0 -> 0 | S30: =SUM(L30:O30) -> 79.40671 | T30: =IFERROR(S30/K30,0) -> 1985.1677
B31: 10009777 | C31: POTA REJOS FR C/U C/V S/OR 0.3-0.5BL10 | D31: 640 | E31: REJOS | F31: =IFERROR(VLOOKUP(B31,[3]Hoja1!$I$25:$J$77,2,0),0) -> 1504.8593 | G31: 1541.8895 | H31: =AVERAGE(F31:G31) -> 1523.3744 | I31: REJOS | J31: 10007162 | K31: =D31/1000 -> 0.64 | L31: =H31*D31/1000 -> 974.9596 | M31: =240.26*D31/1000 -> 153.7664 | N31: =K31/$K$50*$N$52 -> 20.483002 | O31: =K31/$K$50*$O$52 -> 55.333314 | P31: =K31/$K$50*$P$52 -> 40.302215 | Q31: =0 -> 0 | S31: =SUM(L31:O31) -> 1204.5423 | T31: =IFERROR(S31/K31,0) -> 1882.0974
B32: 10010108 | C32: POTA REJOS FR C/U C/V S/OR 0.5-1.0 BL10 | D32: 182280 | E32: REJOS | F32: =IFERROR(VLOOKUP(B32,[3]Hoja1!$I$25:$J$77,2,0),0) -> 1506.5947 | G32: 1541.8895 | H32: =AVERAGE(F32:G32) -> 1524.2421 | I32: REJOS | J32: 10007162 | K32: =D32/1000 -> 182.28 | L32: =H32*D32/1000 -> 277838.85 | M32: =240.26*D32/1000 -> 43794.593 | N32: =K32/$K$50*$N$52 -> 5833.8151 | O32: =K32/$K$50*$O$52 -> 15759.62 | P32: =K32/$K$50*$P$52 -> 11478.575 | Q32: =0 -> 0 | S32: =SUM(L32:O32) -> 343226.88 | T32: =IFERROR(S32/K32,0) -> 1882.9651
B33: 10010321 | C33: POTA REJOS FR C/B S/U S/V S/OR 3.0 - UP BL10 S20 | D33: 160 | E33: REJOS | F33: =IFERROR(VLOOKUP(B33,[3]Hoja1!$I$25:$J$77,2,0),0) -> 0 | G33: 1541.8895 | H33: =G33 -> 1541.8895 | I33: REJOS | J33: 10007162 | K33: =D33/1000 -> 0.16 | L33: =H33*D33/1000 -> 246.70232 | M33: =240.26*D33/1000 -> 38.4416 | N33: =K33/$K$50*$N$52 -> 5.1207506 | O33: =K33/$K$50*$O$52 -> 13.833329 | P33: =K33/$K$50*$P$52 -> 10.075554 | Q33: =0 -> 0 | S33: =SUM(L33:O33) -> 304.098 | T33: =IFERROR(S33/K33,0) -> 1900.6125
B34: 10009187 | C34: POTA REJOS FR C/B S/U S/V S/OR 0.3-0.5 BL10 | D34: 220 | E34: REJOS | F34: =IFERROR(VLOOKUP(B34,[3]Hoja1!$I$25:$J$77,2,0),0) -> 2022 | G34: 1541.8895 | H34: =AVERAGE(F34:G34) -> 1781.9447 | I34: REJOS | J34: 10007162 | K34: =D34/1000 -> 0.22 | L34: =H34*D34/1000 -> 392.02784 | M34: =240.26*D34/1000 -> 52.8572 | N34: =K34/$K$50*$N$52 -> 7.0410321 | O34: =K34/$K$50*$O$52 -> 19.020827 | P34: =K34/$K$50*$P$52 -> 13.853887 | Q34: =0 -> 0 | S34: =SUM(L34:O34) -> 470.9469 | T34: =IFERROR(S34/K34,0) -> 2140.6677
B35: 10007161 | C35: POTA REJOS FR C/B S/U S/V S/OR 0.5-1 BL1 0 | D35: 4500 | E35: REJOS | F35: =IFERROR(VLOOKUP(B35,[3]Hoja1!$I$25:$J$77,2,0),0) -> 1928.2289 | G35: 1541.8895 | H35: =AVERAGE(F35:G35) -> 1735.0592 | I35: REJOS | J35: 10007162 | K35: =D35/1000 -> 4.5 | L35: =H35*D35/1000 -> 7807.7665 | M35: =240.26*D35/1000 -> 1081.17 | N35: =K35/$K$50*$N$52 -> 144.02111 | O35: =K35/$K$50*$O$52 -> 389.06236 | P35: =K35/$K$50*$P$52 -> 283.37495 | Q35: =0 -> 0 | S35: =SUM(L35:O35) -> 9422.02 | T35: =IFERROR(S35/K35,0) -> 2093.7822
B36: 10009658 | C36: POTA REJOS FR C/B C/U C/V S/OR 1.0 up BL 10S20 | D36: 2680 | E36: REJOS | F36: =IFERROR(VLOOKUP(B36,[3]Hoja1!$I$25:$J$77,2,0),0) -> 1849.5051 | G36: 1541.8895 | H36: =AVERAGE(F36:G36) -> 1695.6973 | I36: REJOS | J36: 10007162 | K36: =D36/1000 -> 2.68 | L36: =H36*D36/1000 -> 4544.4688 | M36: =240.26*D36/1000 -> 643.8968 | N36: =K36/$K$50*$N$52 -> 85.772573 | O36: =K36/$K$50*$O$52 -> 231.70825 | P36: =K36/$K$50*$P$52 -> 168.76553 | Q36: =0 -> 0 | S36: =SUM(L36:O36) -> 5505.8464 | T36: =IFERROR(S36/K36,0) -> 2054.4203
B37: 10009639 | C37: POTA REJOS FR C/B S/U S/V S/OR 2-UP BL10 | D37: 37180 | E37: REJOS | F37: =IFERROR(VLOOKUP(B37,[3]Hoja1!$I$25:$J$77,2,0),0) -> 1849.3427 | G37: 1541.8895 | H37: =AVERAGE(F37:G37) -> 1695.6161 | I37: REJOS | J37: 10007162 | K37: =D37/1000 -> 37.18 | L37: =H37*D37/1000 -> 63043.006 | M37: =240.26*D37/1000 -> 8932.8668 | N37: =K37/$K$50*$N$52 -> 1189.9344 | O37: =K37/$K$50*$O$52 -> 3214.5197 | P37: =K37/$K$50*$P$52 -> 2341.3068 | Q37: =0 -> 0 | S37: =SUM(L37:O37) -> 76380.327 | T37: =IFERROR(S37/K37,0) -> 2054.3391
B38: 10007163 | C38: POTA REJOS FR C/B S/U S/V S/OR 2.0 -3.0 BL10 S20 | D38: 2260 | E38: REJOS | F38: =IFERROR(VLOOKUP(B38,[3]Hoja1!$I$25:$J$77,2,0),0) -> 0 | G38: 1541.8895 | H38: =G38 -> 1541.8895 | I38: REJOS | J38: 10007162 | K38: =D38/1000 -> 2.26 | L38: =H38*D38/1000 -> 3484.6703 | M38: =240.26*D38/1000 -> 542.9876 | N38: =K38/$K$50*$N$52 -> 72.330603 | O38: =K38/$K$50*$O$52 -> 195.39577 | P38: =K38/$K$50*$P$52 -> 142.3172 | Q38: =0 -> 0 | S38: =SUM(L38:O38) -> 4295.3842 | T38: =IFERROR(S38/K38,0) -> 1900.6125
B39: 10007162 | C39: POTA REJOS FR C/B S/U S/V S/OR 1-2 BL10 | D39: 290280 | E39: REJOS | F39: =IFERROR(VLOOKUP(B39,[3]Hoja1!$I$25:$J$77,2,0),0) -> 1900.3945 | G39: 1541.8895 | H39: =AVERAGE(F39:G39) -> 1721.142 | I39: REJOS | J39: 10007162 | K39: =D39/1000 -> 290.28 | L39: =H39*D39/1000 -> 499613.1 | M39: =240.26*D39/1000 -> 69742.673 | N39: =K39/$K$50*$N$52 -> 9290.3218 | O39: =K39/$K$50*$O$52 -> 25097.116 | P39: =K39/$K$50*$P$52 -> 18279.574 | Q39: =0 -> 0 | S39: =SUM(L39:O39) -> 603743.21 | T39: =IFERROR(S39/K39,0) -> 2079.865
B40: 10009336 | C40: VENTOSAS DE REJOS | D40: 24360 | F40: =IFERROR(VLOOKUP(B40,[3]Hoja1!$I$25:$J$77,2,0),0) -> 3230.8044 | G40: 1136.4944 | H40: =AVERAGE(F40:G40) -> 2183.6494 | I40: VENTOSAS | J40: 10009386 | K40: =D40/1000 -> 24.36 | L40: =H40*D40/1000 -> 53193.7 | M40: =240.26*D40/1000 -> 5852.7336 | N40: =K40/$K$50*$N$52 -> 779.63428 | O40: =K40/$K$50*$O$52 -> 2106.1243 | P40: =K40/$K$50*$P$52 -> 1534.0031 | Q40: =0 -> 0 | S40: =SUM(L40:O40) -> 61932.192 | T40: =IFERROR(S40/K40,0) -> 2542.3724
B41: 10009239 | C41: POTA FILETE PRE COCIDO S/M S/T C/P S/COD | D41: 257760 | F41: =IFERROR(VLOOKUP(B41,[3]Hoja1!$I$25:$J$77,2,0),0) -> 3349.7949 | G41: 2714.9273 | H41: =AVERAGE(F41:G41) -> 3032.3611 | I41: DARUMA | J41: 10009239 | K41: =D41/1000 -> 257.76 | L41: =H41*D41/1000 -> 781621.4 | M41: =240.26*D41/1000 -> 61929.418 | N41: =K41/$K$50*$N$52 -> 8249.5293 | O41: =K41/$K$50*$O$52 -> 22285.492 | P41: =K41/$K$50*$P$52 -> 16231.717 | Q41: =0 -> 0 | S41: =SUM(L41:O41) -> 874085.83 | T41: =IFERROR(S41/K41,0) -> 3391.0841
...
