Workbook

Sheet RESUMEN AL 25-5-2026
C2: PERU FROST
C3: AVANCE COMERCIAL AL 25-5-2026
AR4: VENTA MAYO 2026 (EN USD)
F5: RENTABILIDAD DEL INVENTARIO | T5: 46150 | W5: 46154 | Z5: 46157 | AC5: 46160 | AF5: 46164 | AI5: 46167 | AL5: 46170 | AO5: 46171 | AR5: EMBARCADO al 25/5/2026 | AU5: POR EMBARCAR CON FECHA | AX5: TOTAL PROYECTADO | BK5: UNITARIOS POR TM
B6: Código | C6: Producto | D6: TM en Stock Libre | E6: CU | F6: Costo Ventas | G6: Gasto Ventas | H6: Gasto ADM | I6: Gasto Fin | J6: Depreciación | K6: Utilidad Neta | L6: Margen Neto | M6: Venta Equilibrio | N6: Precio Equilibrio x TM | O6: Precio | P6: Venta total | Q6: Utilidad | R6: Mg Neto | T6: TM | U6: Venta | V6: Precio x TM | W6: TM | X6: Venta | Y6: Precio x TM | Z6: TM | AA6: Venta | AB6: Precio x TM | AC6: TM | AD6: Venta | AE6: Precio x TM | AF6: TM | AG6: Venta | AH6: Precio x TM | AI6: TM | AJ6: Venta | AK6: Precio x TM | AL6: TM | AM6: Venta | AN6: Precio x TM | AO6: TM | AP6: Venta | AQ6: Precio x TM | AR6: TM | AS6: Venta | AT6: Precio x TM | AU6: TM | AV6: Venta | AW6: Precio x TM | AX6: TM | AY6: Venta | AZ6: Precio x TM | BA6: Costo Ventas | BB6: Gasto Ventas | BC6: Gasto Adm | BD6: Gasto Fin Corto | BE6: Gasto Fin Largo | BF6: Depreciación | BG6: Drawback | BH6: Utilidad | BI6: Mg Neto % | BK6: Precio x TM | BL6: Costo Ventas | BM6: Gasto Ventas | BN6: Gasto Adm | BO6: Gasto Fin Corto | BP6: Gasto Fin Largo | BQ6: Depreciación | BR6: Drawback | BS6: Utilidad
B7: 10005721 | C7: POTA FILETE CONGELADO | D7: =TD!E4 -> 285.94 | E7: =IFERROR(F7/D7,0) -> 2136.6868 | F7: =TD!F4 -> 610964.22 | G7: =TD!G4 -> 59429.77 | H7: =TD!H4 -> 11359.393 | I7: =TD!I4 -> 22330.642 | J7: =TD!J4 -> 17850.918 | K7: 0 | L7: 0 | M7: =F7+G7+H7+I7 -> 704084.02 | N7: =IFERROR(M7/D7,0) -> 2462.3488 | P7: =O7*D7 -> 0 | Q7: =P7-M7 -> -704084.02 | R7: =IFERROR(Q7/P7,0) -> 0 | T7: {=SUM([2]Hoja3!$H$5:$H$32*([2]Hoja3!$J$5:$J$32=$C7)*([2]Hoja3!$F$5:$F$32=T$5))} -> 0 | U7: {=SUM([2]Hoja3!$I$5:$I$32*([2]Hoja3!$J$5:$J$32=$C7)*([2]Hoja3!$F$5:$F$32=T$5))} -> 0 | V7: =IFERROR(U7/T7,0) -> 0 | W7: {=SUM([2]Hoja3!$H$5:$H$32*([2]Hoja3!$J$5:$J$32=$C7)*([2]Hoja3!$F$5:$F$32=W$5))} -> 54 | X7: {=SUM([2]Hoja3!$I$5:$I$32*([2]Hoja3!$J$5:$J$32=$C7)*([2]Hoja3!$F$5:$F$32=W$5))} -> 113400 | Y7: =IFERROR(X7/W7,0) -> 2100 | Z7: {=SUM([2]Hoja3!$H$5:$H$32*([2]Hoja3!$J$5:$J$32=$C7)*([2]Hoja3!$F$5:$F$32=Z$5))} -> 74.8 | AA7: {=SUM([2]Hoja3!$I$5:$I$32*([2]Hoja3!$J$5:$J$32=$C7)*([2]Hoja3!$F$5:$F$32=Z$5))} -> 166680 | AB7: =IFERROR(AA7/Z7,0) -> 2228.3422 | AC7: {=SUM([2]Hoja3!$H$5:$H$32*([2]Hoja3!$J$5:$J$32=$C7)*([2]Hoja3!$F$5:$F$32=AC$5))} -> 0 | AD7: {=SUM([2]Hoja3!$I$5:$I$32*([2]Hoja3!$J$5:$J$32=$C7)*([2]Hoja3!$F$5:$F$32=AC$5))} -> 0 | AE7: =IFERROR(AD7/AC7,0) -> 0 | AF7: {=SUM([2]Hoja3!$H$5:$H$32*([2]Hoja3!$J$5:$J$32=$C7)*([2]Hoja3!$F$5:$F$32=AF$5))} -> 351 | AG7: {=SUM([2]Hoja3!$I$5:$I$32*([2]Hoja3!$J$5:$J$32=$C7)*([2]Hoja3!$F$5:$F$32=AF$5))} -> 720090 | AH7: =IFERROR(AG7/AF7,0) -> 2051.5385 | AI7: {=SUM([2]Hoja3!$H$5:$H$32*([2]Hoja3!$J$5:$J$32=$C7)*([2]Hoja3!$F$5:$F$32=AI$5))} -> 0 | AJ7: {=SUM([2]Hoja3!$I$5:$I$32*([2]Hoja3!$J$5:$J$32=$C7)*([2]Hoja3!$F$5:$F$32=AI$5))} -> 0 | AK7: =IFERROR(AJ7/AI7,0) -> 0 | AL7: {=SUM([2]Hoja3!$H$5:$H$32*([2]Hoja3!$J$5:$J$32=$C7)*([2]Hoja3!$F$5:$F$32=AL$5))} -> 27 | AM7: {=SUM([2]Hoja3!$I$5:$I$32*([2]Hoja3!$J$5:$J$32=$C7)*([2]Hoja3!$F$5:$F$32=AL$5))} -> 54540 | AN7: =IFERROR(AM7/AL7,0) -> 2020 | AO7: {=SUM([2]Hoja3!$H$5:$H$32*([2]Hoja3!$J$5:$J$32=$C7)*([2]Hoja3!$F$5:$F$32=AO$5))} -> 0 | AP7: {=SUM([2]Hoja3!$I$5:$I$32*([2]Hoja3!$J$5:$J$32=$C7)*([2]Hoja3!$F$5:$F$32=AO$5))} -> 0 | AQ7: =IFERROR(AP7/AO7,0) -> 0 | AR7: =T7+W7+Z7+AC7+AF7+AI7 -> 479.8 | AS7: =U7+X7+AA7+AD7+AG7+AJ7 -> 1000170 | AT7: =IFERROR(AS7/AR7,0) -> 2084.5561 | AU7: =AL7+AO7 -> 27 | AV7: =AM7+AP7 -> 54540 | AW7: =IFERROR(AV7/AU7,0) -> 2020 | AX7: =AR7+AU7 -> 506.8 | AY7: =AS7+AV7 -> 1054710 | AZ7: =IFERROR(AY7/AX7,0) -> 2081.1168 | BA7: =-IFERROR(F7/D7*AX7,0) -> -1082872.9 | BB7: =-IFERROR(G7/D7*AX7,0) -> -105333.31 | BC7: =$BC$21/$AX$21*$AX7 -> -20130.027 | BD7: =$BD$21/$AX$21*$AX7 -> -11874.254 | BE7: =$BE$21/$AX$21*$AX7 -> -27697.969 | BF7: =$BF$21/$AX$21*$AX7 -> -31633.685 | BG7: =AY7*0.03 -> 31641.3 | BH7: =AY7+SUM(BA7:BE7,BG7) -> -161557.12 | BI7: =IFERROR(BH7/AY7,0) -> -0.15317682 | BK7: =AZ7 -> 2081.1168 | BL7: =IFERROR(BA7/$AX7,0) -> -2136.6868 | BM7: =IFERROR(BB7/$AX7,0) -> -207.84 | BN7: =IFERROR(BC7/$AX7,0) -> -39.719865 | BO7: =IFERROR(BD7/$AX7,0) -> -23.429863 | BP7: =IFERROR(BE7/$AX7,0) -> -54.652662 | BQ7: =IFERROR(BF7/$AX7,0) -> -62.418479 | BR7: =IFERROR(BG7/$AX7,0) -> 62.433504 | BS7: =IFERROR(BH7/$AX7,0) -> -318.77886
B8: 10005779 | C8: POTA NUCAS CONGELADAS | D8: =TD!E5 -> 119.8 | E8: =IFERROR(F8/D8,0) -> 1753.6934 | F8: =TD!F5 -> 210092.48 | G8: =TD!G5 -> 24899.232 | H8: =TD!H5 -> 4759.2337 | I8: =TD!I5 -> 9355.847 | J8: =TD!J5 -> 7478.9814 | K8: 0 | L8: 0 | M8: =F8+G8+H8+I8 -> 249106.79 | N8: =IFERROR(M8/D8,0) -> 2079.3555 | P8: =O8*D8 -> 0 | Q8: =P8-M8 -> -249106.79 | R8: =IFERROR(Q8/P8,0) -> 0 | T8: {=SUM([2]Hoja3!$H$5:$H$32*([2]Hoja3!$J$5:$J$32=$C8)*([2]Hoja3!$F$5:$F$32=T$5))} -> 0 | U8: {=SUM([2]Hoja3!$I$5:$I$32*([2]Hoja3!$J$5:$J$32=$C8)*([2]Hoja3!$F$5:$F$32=T$5))} -> 0 | V8: =IFERROR(U8/T8,0) -> 0 | W8: {=SUM([2]Hoja3!$H$5:$H$32*([2]Hoja3!$J$5:$J$32=$C8)*([2]Hoja3!$F$5:$F$32=W$5))} -> 157 | X8: {=SUM([2]Hoja3!$I$5:$I$32*([2]Hoja3!$J$5:$J$32=$C8)*([2]Hoja3!$F$5:$F$32=W$5))} -> 191725 | Y8: =IFERROR(X8/W8,0) -> 1221.1783 | Z8: {=SUM([2]Hoja3!$H$5:$H$32*([2]Hoja3!$J$5:$J$32=$C8)*([2]Hoja3!$F$5:$F$32=Z$5))} -> 26 | AA8: {=SUM([2]Hoja3!$I$5:$I$32*([2]Hoja3!$J$5:$J$32=$C8)*([2]Hoja3!$F$5:$F$32=Z$5))} -> 33800 | AB8: =IFERROR(AA8/Z8,0) -> 1300 | AC8: {=SUM([2]Hoja3!$H$5:$H$32*([2]Hoja3!$J$5:$J$32=$C8)*([2]Hoja3!$F$5:$F$32=AC$5))} -> 0 | AD8: {=SUM([2]Hoja3!$I$5:$I$32*([2]Hoja3!$J$5:$J$32=$C8)*([2]Hoja3!$F$5:$F$32=AC$5))} -> 0 | AE8: =IFERROR(AD8/AC8,0) -> 0 | AF8: {=SUM([2]Hoja3!$H$5:$H$32*([2]Hoja3!$J$5:$J$32=$C8)*([2]Hoja3!$F$5:$F$32=AF$5))} -> 0 | AG8: {=SUM([2]Hoja3!$I$5:$I$32*([2]Hoja3!$J$5:$J$32=$C8)*([2]Hoja3!$F$5:$F$32=AF$5))} -> 0 | AH8: =IFERROR(AG8/AF8,0) -> 0 | AI8: {=SUM([2]Hoja3!$H$5:$H$32*([2]Hoja3!$J$5:$J$32=$C8)*([2]Hoja3!$F$5:$F$32=AI$5))} -> 0 | AJ8: {=SUM([2]Hoja3!$I$5:$I$32*([2]Hoja3!$J$5:$J$32=$C8)*([2]Hoja3!$F$5:$F$32=AI$5))} -> 0 | AK8: =IFERROR(AJ8/AI8,0) -> 0 | AL8: {=SUM([2]Hoja3!$H$5:$H$32*([2]Hoja3!$J$5:$J$32=$C8)*([2]Hoja3!$F$5:$F$32=AL$5))} -> 0 | AM8: {=SUM([2]Hoja3!$I$5:$I$32*([2]Hoja3!$J$5:$J$32=$C8)*([2]Hoja3!$F$5:$F$32=AL$5))} -> 0 | AN8: =IFERROR(AM8/AL8,0) -> 0 | AO8: {=SUM([2]Hoja3!$H$5:$H$32*([2]Hoja3!$J$5:$J$32=$C8)*([2]Hoja3!$F$5:$F$32=AO$5))} -> 0 | AP8: {=SUM([2]Hoja3!$I$5:$I$32*([2]Hoja3!$J$5:$J$32=$C8)*([2]Hoja3!$F$5:$F$32=AO$5))} -> 0 | AQ8: =IFERROR(AP8/AO8,0) -> 0 | AR8: =T8+W8+Z8+AC8+AF8+AI8 -> 183 | AS8: =U8+X8+AA8+AD8+AG8+AJ8 -> 225525 | AT8: =IFERROR(AS8/AR8,0) -> 1232.377 | AU8: =AL8+AO8 -> 0 | AV8: =AM8+AP8 -> 0 | AW8: =IFERROR(AV8/AU8,0) -> 0 | AX8: =AR8+AU8 -> 183 | AY8: =AS8+AV8 -> 225525 | AZ8: =IFERROR(AY8/AX8,0) -> 1232.377 | BA8: =-IFERROR(F8/D8*AX8,0) -> -320925.9 | BB8: =-IFERROR(G8/D8*AX8,0) -> -38034.72 | BC8: =$BC$21/$AX$21*$AX8 -> -7268.7352 | BD8: =$BD$21/$AX$21*$AX8 -> -4287.6648 | BE8: =$BE$21/$AX$21*$AX8 -> -10001.437 | BF8: =$BF$21/$AX$21*$AX8 -> -11422.582 | BG8: =AY8*0.03 -> 6765.75 | BH8: =AY8+SUM(BA8:BE8,BG8) -> -148227.71 | BI8: =IFERROR(BH8/AY8,0) -> -0.65725622 | BK8: =AZ8 -> 1232.377 | BL8: =IFERROR(BA8/$AX8,0) -> -1753.6934 | BM8: =IFERROR(BB8/$AX8,0) -> -207.84 | BN8: =IFERROR(BC8/$AX8,0) -> -39.719865 | BO8: =IFERROR(BD8/$AX8,0) -> -23.429863 | BP8: =IFERROR(BE8/$AX8,0) -> -54.652662 | BQ8: =IFERROR(BF8/$AX8,0) -> -62.418479 | BR8: =IFERROR(BG8/$AX8,0) -> 36.971311 | BS8: =IFERROR(BH8/$AX8,0) -> -809.98748
B9: 10005781 | C9: POTA NUCAS FR ABIERTAS 0.3-0.5 BL10 S20 | D9: =TD!E6 -> 108.16 | E9: =IFERROR(F9/D9,0) -> 1856.3458 | F9: =TD!F6 -> 200782.37 | G9: =TD!G6 -> 22479.974 | H9: =TD!H6 -> 4296.8173 | I9: =TD!I6 -> 8446.8148 | J9: =TD!J6 -> 6752.309 | K9: 0 | L9: 0 | M9: =F9+G9+H9+I9 -> 236005.97 | N9: =IFERROR(M9/D9,0) -> 2182.0079 | P9: =O9*D9 -> 0 | Q9: =P9-M9 -> -236005.97 | R9: =IFERROR(Q9/P9,0) -> 0 | T9: {=SUM([2]Hoja3!$H$5:$H$32*([2]Hoja3!$J$5:$J$32=$C9)*([2]Hoja3!$F$5:$F$32=T$5))} -> 0 | U9: {=SUM([2]Hoja3!$I$5:$I$32*([2]Hoja3!$J$5:$J$32=$C9)*([2]Hoja3!$F$5:$F$32=T$5))} -> 0 | V9: =IFERROR(U9/T9,0) -> 0 | W9: {=SUM([2]Hoja3!$H$5:$H$32*([2]Hoja3!$J$5:$J$32=$C9)*([2]Hoja3!$F$5:$F$32=W$5))} -> 0 | X9: {=SUM([2]Hoja3!$I$5:$I$32*([2]Hoja3!$J$5:$J$32=$C9)*([2]Hoja3!$F$5:$F$32=W$5))} -> 0 | Y9: =IFERROR(X9/W9,0) -> 0 | Z9: {=SUM([2]Hoja3!$H$5:$H$32*([2]Hoja3!$J$5:$J$32=$C9)*([2]Hoja3!$F$5:$F$32=Z$5))} -> 0 | AA9: {=SUM([2]Hoja3!$I$5:$I$32*([2]Hoja3!$J$5:$J$32=$C9)*([2]Hoja3!$F$5:$F$32=Z$5))} -> 0 | AB9: =IFERROR(AA9/Z9,0) -> 0 | AC9: {=SUM([2]Hoja3!$H$5:$H$32*([2]Hoja3!$J$5:$J$32=$C9)*([2]Hoja3!$F$5:$F$32=AC$5))} -> 0 | AD9: {=SUM([2]Hoja3!$I$5:$I$32*([2]Hoja3!$J$5:$J$32=$C9)*([2]Hoja3!$F$5:$F$32=AC$5))} -> 0 | AE9: =IFERROR(AD9/AC9,0) -> 0 | AF9: {=SUM([2]Hoja3!$H$5:$H$32*([2]Hoja3!$J$5:$J$32=$C9)*([2]Hoja3!$F$5:$F$32=AF$5))} -> 0 | AG9: {=SUM([2]Hoja3!$I$5:$I$32*([2]Hoja3!$J$5:$J$32=$C9)*([2]Hoja3!$F$5:$F$32=AF$5))} -> 0 | AH9: =IFERROR(AG9/AF9,0) -> 0 | AI9: {=SUM([2]Hoja3!$H$5:$H$32*([2]Hoja3!$J$5:$J$32=$C9)*([2]Hoja3!$F$5:$F$32=AI$5))} -> 0 | AJ9: {=SUM([2]Hoja3!$I$5:$I$32*([2]Hoja3!$J$5:$J$32=$C9)*([2]Hoja3!$F$5:$F$32=AI$5))} -> 0 | AK9: =IFERROR(AJ9/AI9,0) -> 0 | AL9: {=SUM([2]Hoja3!$H$5:$H$32*([2]Hoja3!$J$5:$J$32=$C9)*([2]Hoja3!$F$5:$F$32=AL$5))} -> 0 | AM9: {=SUM([2]Hoja3!$I$5:$I$32*([2]Hoja3!$J$5:$J$32=$C9)*([2]Hoja3!$F$5:$F$32=AL$5))} -> 0 | AN9: =IFERROR(AM9/AL9,0) -> 0 | AO9: {=SUM([2]Hoja3!$H$5:$H$32*([2]Hoja3!$J$5:$J$32=$C9)*([2]Hoja3!$F$5:$F$32=AO$5))} -> 0 | AP9: {=SUM([2]Hoja3!$I$5:$I$32*([2]Hoja3!$J$5:$J$32=$C9)*([2]Hoja3!$F$5:$F$32=AO$5))} -> 0 | AQ9: =IFERROR(AP9/AO9,0) -> 0 | AR9: =T9+W9+Z9+AC9+AF9+AI9 -> 0 | AS9: =U9+X9+AA9+AD9+AG9+AJ9 -> 0 | AT9: =IFERROR(AS9/AR9,0) -> 0 | AU9: =AL9+AO9 -> 0 | AV9: =AM9+AP9 -> 0 | AW9: =IFERROR(AV9/AU9,0) -> 0 | AX9: =AR9+AU9 -> 0 | AY9: =AS9+AV9 -> 0 | AZ9: =IFERROR(AY9/AX9,0) -> 0 | BA9: =-IFERROR(F9/D9*AX9,0) -> 0 | BB9: =-IFERROR(G9/D9*AX9,0) -> 0 | BC9: =$BC$21/$AX$21*$AX9 -> 0 | BD9: =$BD$21/$AX$21*$AX9 -> 0 | BE9: =$BE$21/$AX$21*$AX9 -> 0 | BF9: =$BF$21/$AX$21*$AX9 -> 0 | BG9: =AY9*0.03 -> 0 | BH9: =AY9+SUM(BA9:BE9,BG9) -> 0 | BI9: =IFERROR(BH9/AY9,0) -> 0 | BK9: =AZ9 -> 0 | BL9: =IFERROR(BA9/$AX9,0) -> 0 | BM9: =IFERROR(BB9/$AX9,0) -> 0 | BN9: =IFERROR(BC9/$AX9,0) -> 0 | BO9: =IFERROR(BD9/$AX9,0) -> 0 | BP9: =IFERROR(BE9/$AX9,0) -> 0 | BQ9: =IFERROR(BF9/$AX9,0) -> 0 | BR9: =IFERROR(BG9/$AX9,0) -> 0 | BS9: =IFERROR(BH9/$AX9,0) -> 0
B10: 10006719 | C10: POTA ALAS CONGELADAS | D10: =TD!E7 -> 8.1 | E10: =IFERROR(F10/D10,0) -> 2035.7386 | F10: =TD!F7 -> 16489.482 | G10: =TD!G7 -> 1683.504 | H10: =TD!H7 -> 321.78458 | I10: =TD!I7 -> 632.57396 | J10: =TD!J7 -> 505.67403 | K10: 0 | L10: 0 | M10: =F10+G10+H10+I10 -> 19127.345 | N10: =IFERROR(M10/D10,0) -> 2361.4006 | P10: =O10*D10 -> 0 | Q10: =P10-M10 -> -19127.345 | R10: =IFERROR(Q10/P10,0) -> 0 | T10: {=SUM([2]Hoja3!$H$5:$H$32*([2]Hoja3!$J$5:$J$32=$C10)*([2]Hoja3!$F$5:$F$32=T$5))} -> 0 | U10: {=SUM([2]Hoja3!$I$5:$I$32*([2]Hoja3!$J$5:$J$32=$C10)*([2]Hoja3!$F$5:$F$32=T$5))} -> 0 | V10: =IFERROR(U10/T10,0) -> 0 | W10: {=SUM([2]Hoja3!$H$5:$H$32*([2]Hoja3!$J$5:$J$32=$C10)*([2]Hoja3!$F$5:$F$32=W$5))} -> 0 | X10: {=SUM([2]Hoja3!$I$5:$I$32*([2]Hoja3!$J$5:$J$32=$C10)*([2]Hoja3!$F$5:$F$32=W$5))} -> 0 | Y10: =IFERROR(X10/W10,0) -> 0 | Z10: {=SUM([2]Hoja3!$H$5:$H$32*([2]Hoja3!$J$5:$J$32=$C10)*([2]Hoja3!$F$5:$F$32=Z$5))} -> 0 | AA10: {=SUM([2]Hoja3!$I$5:$I$32*([2]Hoja3!$J$5:$J$32=$C10)*([2]Hoja3!$F$5:$F$32=Z$5))} -> 0 | AB10: =IFERROR(AA10/Z10,0) -> 0 | AC10: {=SUM([2]Hoja3!$H$5:$H$32*([2]Hoja3!$J$5:$J$32=$C10)*([2]Hoja3!$F$5:$F$32=AC$5))} -> 0 | AD10: {=SUM([2]Hoja3!$I$5:$I$32*([2]Hoja3!$J$5:$J$32=$C10)*([2]Hoja3!$F$5:$F$32=AC$5))} -> 0 | AE10: =IFERROR(AD10/AC10,0) -> 0 | AF10: {=SUM([2]Hoja3!$H$5:$H$32*([2]Hoja3!$J$5:$J$32=$C10)*([2]Hoja3!$F$5:$F$32=AF$5))} -> 54 | AG10: {=SUM([2]Hoja3!$I$5:$I$32*([2]Hoja3!$J$5:$J$32=$C10)*([2]Hoja3!$F$5:$F$32=AF$5))} -> 113400 | AH10: =IFERROR(AG10/AF10,0) -> 2100 | AI10: {=SUM([2]Hoja3!$H$5:$H$32*([2]Hoja3!$J$5:$J$32=$C10)*([2]Hoja3!$F$5:$F$32=AI$5))} -> 0 | AJ10: {=SUM([2]Hoja3!$I$5:$I$32*([2]Hoja3!$J$5:$J$32=$C10)*([2]Hoja3!$F$5:$F$32=AI$5))} -> 0 | AK10: =IFERROR(AJ10/AI10,0) -> 0 | AL10: {=SUM([2]Hoja3!$H$5:$H$32*([2]Hoja3!$J$5:$J$32=$C10)*([2]Hoja3!$F$5:$F$32=AL$5))} -> 243 | AM10: {=SUM([2]Hoja3!$I$5:$I$32*([2]Hoja3!$J$5:$J$32=$C10)*([2]Hoja3!$F$5:$F$32=AL$5))} -> 477900 | AN10: =IFERROR(AM10/AL10,0) -> 1966.6667 | AO10: {=SUM([2]Hoja3!$H$5:$H$32*([2]Hoja3!$J$5:$J$32=$C10)*([2]Hoja3!$F$5:$F$32=AO$5))} -> 0 | AP10: {=SUM([2]Hoja3!$I$5:$I$32*([2]Hoja3!$J$5:$J$32=$C10)*([2]Hoja3!$F$5:$F$32=AO$5))} -> 0 | AQ10: =IFERROR(AP10/AO10,0) -> 0 | AR10: =T10+W10+Z10+AC10+AF10+AI10 -> 54 | AS10: =U10+X10+AA10+AD10+AG10+AJ10 -> 113400 | AT10: =IFERROR(AS10/AR10,0) -> 2100 | AU10: =AL10+AO10 -> 243 | AV10: =AM10+AP10 -> 477900 | AW10: =IFERROR(AV10/AU10,0) -> 1966.6667 | AX10: =AR10+AU10 -> 297 | AY10: =AS10+AV10 -> 591300 | AZ10: =IFERROR(AY10/AX10,0) -> 1990.9091 | BA10: =-IFERROR(F10/D10*AX10,0) -> -604614.35 | BB10: =-IFERROR(G10/D10*AX10,0) -> -61728.48 | BC10: =$BC$21/$AX$21*$AX10 -> -11796.8 | BD10: =$BD$21/$AX$21*$AX10 -> -6958.6692 | BE10: =$BE$21/$AX$21*$AX10 -> -16231.84 | BF10: =$BF$21/$AX$21*$AX10 -> -18538.288 | BG10: =AY10*0.03 -> 17739 | BH10: =AY10+SUM(BA10:BE10,BG10) -> -92291.144 | BI10: =IFERROR(BH10/AY10,0) -> -0.15608176 | BK10: =AZ10 -> 1990.9091 | BL10: =IFERROR(BA10/$AX10,0) -> -2035.7386 | BM10: =IFERROR(BB10/$AX10,0) -> -207.84 | BN10: =IFERROR(BC10/$AX10,0) -> -39.719865 | BO10: =IFERROR(BD10/$AX10,0) -> -23.429863 | BP10: =IFERROR(BE10/$AX10,0) -> -54.652662 | BQ10: =IFERROR(BF10/$AX10,0) -> -62.418479 | BR10: =IFERROR(BG10/$AX10,0) -> 59.727273 | BS10: =IFERROR(BH10/$AX10,0) -> -310.74459
B11: 10006720 | C11: POTA ALAS CONGELADAS FR C/P C/C 0.5-1 BL10 S20 | D11: =TD!E8 -> 0 | E11: =IFERROR(F11/D11,0) -> 0 | F11: =TD!F8 -> 0 | G11: =TD!G8 -> 0 | H11: =TD!H8 -> 0 | I11: =TD!I8 -> 0 | J11: =TD!J8 -> 0 | K11: 0 | L11: 0 | M11: =F11+G11+H11+I11 -> 0 | N11: =IFERROR(M11/D11,0) -> 0 | P11: =O11*D11 -> 0 | Q11: =P11-M11 -> 0 | R11: =IFERROR(Q11/P11,0) -> 0 | T11: {=SUM([2]Hoja3!$H$5:$H$32*([2]Hoja3!$J$5:$J$32=$C11)*([2]Hoja3!$F$5:$F$32=T$5))} -> 0 | U11: {=SUM([2]Hoja3!$I$5:$I$32*([2]Hoja3!$J$5:$J$32=$C11)*([2]Hoja3!$F$5:$F$32=T$5))} -> 0 | V11: =IFERROR(U11/T11,0) -> 0 | W11: {=SUM([2]Hoja3!$H$5:$H$32*([2]Hoja3!$J$5:$J$32=$C11)*([2]Hoja3!$F$5:$F$32=W$5))} -> 0 | X11: {=SUM([2]Hoja3!$I$5:$I$32*([2]Hoja3!$J$5:$J$32=$C11)*([2]Hoja3!$F$5:$F$32=W$5))} -> 0 | Y11: =IFERROR(X11/W11,0) -> 0 | Z11: {=SUM([2]Hoja3!$H$5:$H$32*([2]Hoja3!$J$5:$J$32=$C11)*([2]Hoja3!$F$5:$F$32=Z$5))} -> 0 | AA11: {=SUM([2]Hoja3!$I$5:$I$32*([2]Hoja3!$J$5:$J$32=$C11)*([2]Hoja3!$F$5:$F$32=Z$5))} -> 0 | AB11: =IFERROR(AA11/Z11,0) -> 0 | AC11: {=SUM([2]Hoja3!$H$5:$H$32*([2]Hoja3!$J$5:$J$32=$C11)*([2]Hoja3!$F$5:$F$32=AC$5))} -> 0 | AD11: {=SUM([2]Hoja3!$I$5:$I$32*([2]Hoja3!$J$5:$J$32=$C11)*([2]Hoja3!$F$5:$F$32=AC$5))} -> 0 | AE11: =IFERROR(AD11/AC11,0) -> 0 | AF11: {=SUM([2]Hoja3!$H$5:$H$32*([2]Hoja3!$J$5:$J$32=$C11)*([2]Hoja3!$F$5:$F$32=AF$5))} -> 0 | AG11: {=SUM([2]Hoja3!$I$5:$I$32*([2]Hoja3!$J$5:$J$32=$C11)*([2]Hoja3!$F$5:$F$32=AF$5))} -> 0 | AH11: =IFERROR(AG11/AF11,0) -> 0 | AI11: {=SUM([2]Hoja3!$H$5:$H$32*([2]Hoja3!$J$5:$J$32=$C11)*([2]Hoja3!$F$5:$F$32=AI$5))} -> 0 | AJ11: {=SUM([2]Hoja3!$I$5:$I$32*([2]Hoja3!$J$5:$J$32=$C11)*([2]Hoja3!$F$5:$F$32=AI$5))} -> 0 | AK11: =IFERROR(AJ11/AI11,0) -> 0 | AL11: {=SUM([2]Hoja3!$H$5:$H$32*([2]Hoja3!$J$5:$J$32=$C11)*([2]Hoja3!$F$5:$F$32=AL$5))} -> 0 | AM11: {=SUM([2]Hoja3!$I$5:$I$32*([2]Hoja3!$J$5:$J$32=$C11)*([2]Hoja3!$F$5:$F$32=AL$5))} -> 0 | AN11: =IFERROR(AM11/AL11,0) -> 0 | AO11: {=SUM([2]Hoja3!$H$5:$H$32*([2]Hoja3!$J$5:$J$32=$C11)*([2]Hoja3!$F$5:$F$32=AO$5))} -> 0 | AP11: {=SUM([2]Hoja3!$I$5:$I$32*([2]Hoja3!$J$5:$J$32=$C11)*([2]Hoja3!$F$5:$F$32=AO$5))} -> 0 | AQ11: =IFERROR(AP11/AO11,0) -> 0 | AR11: =T11+W11+Z11+AC11+AF11+AI11 -> 0 | AS11: =U11+X11+AA11+AD11+AG11+AJ11 -> 0 | AT11: =IFERROR(AS11/AR11,0) -> 0 | AU11: =AL11+AO11 -> 0 | AV11: =AM11+AP11 -> 0 | AW11: =IFERROR(AV11/AU11,0) -> 0 | AX11: =AR11+AU11 -> 0 | AY11: =AS11+AV11 -> 0 | AZ11: =IFERROR(AY11/AX11,0) -> 0 | BA11: =-IFERROR(F11/D11*AX11,0) -> 0 | BB11: =-IFERROR(G11/D11*AX11,0) -> 0 | BC11: =$BC$21/$AX$21*$AX11 -> 0 | BD11: =$BD$21/$AX$21*$AX11 -> 0 | BE11: =$BE$21/$AX$21*$AX11 -> 0 | BF11: =$BF$21/$AX$21*$AX11 -> 0 | BG11: =AY11*0.03 -> 0 | BH11: =AY11+SUM(BA11:BE11,BG11) -> 0 | BI11: =IFERROR(BH11/AY11,0) -> 0 | BK11: =AZ11 -> 0 | BL11: =IFERROR(BA11/$AX11,0) -> 0 | BM11: =IFERROR(BB11/$AX11,0) -> 0 | BN11: =IFERROR(BC11/$AX11,0) -> 0 | BO11: =IFERROR(BD11/$AX11,0) -> 0 | BP11: =IFERROR(BE11/$AX11,0) -> 0 | BQ11: =IFERROR(BF11/$AX11,0) -> 0 | BR11: =IFERROR(BG11/$AX11,0) -> 0 | BS11: =IFERROR(BH11/$AX11,0) -> 0
B12: 10007050 | C12: POTA REJOS COCIDOS | D12: =TD!E9 -> 80.905 | E12: =IFERROR(F12/D12,0) -> 1570.5963 | F12: =TD!F9 -> 127069.1 | G12: =TD!G9 -> 16815.295 | H12: =TD!H9 -> 3214.0718 | I12: =TD!I9 -> 6318.3206 | J12: =TD!J9 -> 5050.8096 | K12: 0 | L12: 0 | M12: =F12+G12+H12+I12 -> 153416.78 | N12: =IFERROR(M12/D12,0) -> 1896.2584 | P12: =O12*D12 -> 0 | Q12: =P12-M12 -> -153416.78 | R12: =IFERROR(Q12/P12,0) -> 0 | T12: {=SUM([2]Hoja3!$H$5:$H$32*([2]Hoja3!$J$5:$J$32=$C12)*([2]Hoja3!$F$5:$F$32=T$5))} -> 0 | U12: {=SUM([2]Hoja3!$I$5:$I$32*([2]Hoja3!$J$5:$J$32=$C12)*([2]Hoja3!$F$5:$F$32=T$5))} -> 0 | V12: =IFERROR(U12/T12,0) -> 0 | W12: {=SUM([2]Hoja3!$H$5:$H$32*([2]Hoja3!$J$5:$J$32=$C12)*([2]Hoja3!$F$5:$F$32=W$5))} -> 0 | X12: {=SUM([2]Hoja3!$I$5:$I$32*([2]Hoja3!$J$5:$J$32=$C12)*([2]Hoja3!$F$5:$F$32=W$5))} -> 0 | Y12: =IFERROR(X12/W12,0) -> 0 | Z12: {=SUM([2]Hoja3!$H$5:$H$32*([2]Hoja3!$J$5:$J$32=$C12)*([2]Hoja3!$F$5:$F$32=Z$5))} -> 0 | AA12: {=SUM([2]Hoja3!$I$5:$I$32*([2]Hoja3!$J$5:$J$32=$C12)*([2]Hoja3!$F$5:$F$32=Z$5))} -> 0 | AB12: =IFERROR(AA12/Z12,0) -> 0 | AC12: {=SUM([2]Hoja3!$H$5:$H$32*([2]Hoja3!$J$5:$J$32=$C12)*([2]Hoja3!$F$5:$F$32=AC$5))} -> 0 | AD12: {=SUM([2]Hoja3!$I$5:$I$32*([2]Hoja3!$J$5:$J$32=$C12)*([2]Hoja3!$F$5:$F$32=AC$5))} -> 0 | AE12: =IFERROR(AD12/AC12,0) -> 0 | AF12: {=SUM([2]Hoja3!$H$5:$H$32*([2]Hoja3!$J$5:$J$32=$C12)*([2]Hoja3!$F$5:$F$32=AF$5))} -> 0 | AG12: {=SUM([2]Hoja3!$I$5:$I$32*([2]Hoja3!$J$5:$J$32=$C12)*([2]Hoja3!$F$5:$F$32=AF$5))} -> 0 | AH12: =IFERROR(AG12/AF12,0) -> 0 | AI12: {=SUM([2]Hoja3!$H$5:$H$32*([2]Hoja3!$J$5:$J$32=$C12)*([2]Hoja3!$F$5:$F$32=AI$5))} -> 0 | AJ12: {=SUM([2]Hoja3!$I$5:$I$32*([2]Hoja3!$J$5:$J$32=$C12)*([2]Hoja3!$F$5:$F$32=AI$5))} -> 0 | AK12: =IFERROR(AJ12/AI12,0) -> 0 | AL12: {=SUM([2]Hoja3!$H$5:$H$32*([2]Hoja3!$J$5:$J$32=$C12)*([2]Hoja3!$F$5:$F$32=AL$5))} -> 0 | AM12: {=SUM([2]Hoja3!$I$5:$I$32*([2]Hoja3!$J$5:$J$32=$C12)*([2]Hoja3!$F$5:$F$32=AL$5))} -> 0 | AN12: =IFERROR(AM12/AL12,0) -> 0 | AO12: {=SUM([2]Hoja3!$H$5:$H$32*([2]Hoja3!$J$5:$J$32=$C12)*([2]Hoja3!$F$5:$F$32=AO$5))} -> 0 | AP12: {=SUM([2]Hoja3!$I$5:$I$32*([2]Hoja3!$J$5:$J$32=$C12)*([2]Hoja3!$F$5:$F$32=AO$5))} -> 0 | AQ12: =IFERROR(AP12/AO12,0) -> 0 | AR12: =T12+W12+Z12+AC12+AF12+AI12 -> 0 | AS12: =U12+X12+AA12+AD12+AG12+AJ12 -> 0 | AT12: =IFERROR(AS12/AR12,0) -> 0 | AU12: =AL12+AO12 -> 0 | AV12: =AM12+AP12 -> 0 | AW12: =IFERROR(AV12/AU12,0) -> 0 | AX12: =AR12+AU12 -> 0 | AY12: =AS12+AV12 -> 0 | AZ12: =IFERROR(AY12/AX12,0) -> 0 | BA12: =-IFERROR(F12/D12*AX12,0) -> 0 | BB12: =-IFERROR(G12/D12*AX12,0) -> 0 | BC12: =$BC$21/$AX$21*$AX12 -> 0 | BD12: =$BD$21/$AX$21*$AX12 -> 0 | BE12: =$BE$21/$AX$21*$AX12 -> 0 | BF12: =$BF$21/$AX$21*$AX12 -> 0 | BG12: =AY12*0.03 -> 0 | BH12: =AY12+SUM(BA12:BE12,BG12) -> 0 | BI12: =IFERROR(BH12/AY12,0) -> 0 | BK12: =AZ12 -> 0 | BL12: =IFERROR(BA12/$AX12,0) -> 0 | BM12: =IFERROR(BB12/$AX12,0) -> 0 | BN12: =IFERROR(BC12/$AX12,0) -> 0 | BO12: =IFERROR(BD12/$AX12,0) -> 0 | BP12: =IFERROR(BE12/$AX12,0) -> 0 | BQ12: =IFERROR(BF12/$AX12,0) -> 0 | BR12: =IFERROR(BG12/$AX12,0) -> 0 | BS12: =IFERROR(BH12/$AX12,0) -> 0
B13: 10007162 | C13: POTA REJOS CONGELADOS | D13: =TD!E10 -> 27.28 | E13: =IFERROR(F13/D13,0) -> 1882.1795 | F13: =TD!F10 -> 51345.857 | G13: =TD!G10 -> 5669.8752 | H13: =TD!H10 -> 1083.7387 | I13: =TD!I10 -> 2130.4466 | J13: =TD!J10 -> 1703.0602 | K13: 0 | L13: 0 | M13: =F13+G13+H13+I13 -> 60229.918 | N13: =IFERROR(M13/D13,0) -> 2207.8416 | P13: =O13*D13 -> 0 | Q13: =P13-M13 -> -60229.918 | R13: =IFERROR(Q13/P13,0) -> 0 | T13: {=SUM([2]Hoja3!$H$5:$H$32*([2]Hoja3!$J$5:$J$32=$C13)*([2]Hoja3!$F$5:$F$32=T$5))} -> 0 | U13: {=SUM([2]Hoja3!$I$5:$I$32*([2]Hoja3!$J$5:$J$32=$C13)*([2]Hoja3!$F$5:$F$32=T$5))} -> 0 | V13: =IFERROR(U13/T13,0) -> 0 | W13: {=SUM([2]Hoja3!$H$5:$H$32*([2]Hoja3!$J$5:$J$32=$C13)*([2]Hoja3!$F$5:$F$32=W$5))} -> 81 | X13: {=SUM([2]Hoja3!$I$5:$I$32*([2]Hoja3!$J$5:$J$32=$C13)*([2]Hoja3!$F$5:$F$32=W$5))} -> 230850 | Y13: =IFERROR(X13/W13,0) -> 2850 | Z13: {=SUM([2]Hoja3!$H$5:$H$32*([2]Hoja3!$J$5:$J$32=$C13)*([2]Hoja3!$F$5:$F$32=Z$5))} -> 81 | AA13: {=SUM([2]Hoja3!$I$5:$I$32*([2]Hoja3!$J$5:$J$32=$C13)*([2]Hoja3!$F$5:$F$32=Z$5))} -> 234900 | AB13: =IFERROR(AA13/Z13,0) -> 2900 | AC13: {=SUM([2]Hoja3!$H$5:$H$32*([2]Hoja3!$J$5:$J$32=$C13)*([2]Hoja3!$F$5:$F$32=AC$5))} -> 0 | AD13: {=SUM([2]Hoja3!$I$5:$I$32*([2]Hoja3!$J$5:$J$32=$C13)*([2]Hoja3!$F$5:$F$32=AC$5))} -> 0 | AE13: =IFERROR(AD13/AC13,0) -> 0 | AF13: {=SUM([2]Hoja3!$H$5:$H$32*([2]Hoja3!$J$5:$J$32=$C13)*([2]Hoja3!$F$5:$F$32=AF$5))} -> 108 | AG13: {=SUM([2]Hoja3!$I$5:$I$32*([2]Hoja3!$J$5:$J$32=$C13)*([2]Hoja3!$F$5:$F$32=AF$5))} -> 321300 | AH13: =IFERROR(AG13/AF13,0) -> 2975 | AI13: {=SUM([2]Hoja3!$H$5:$H$32*([2]Hoja3!$J$5:$J$32=$C13)*([2]Hoja3!$F$5:$F$32=AI$5))} -> 0 | AJ13: {=SUM([2]Hoja3!$I$5:$I$32*([2]Hoja3!$J$5:$J$32=$C13)*([2]Hoja3!$F$5:$F$32=AI$5))} -> 0 | AK13: =IFERROR(AJ13/AI13,0) -> 0 | AL13: {=SUM([2]Hoja3!$H$5:$H$32*([2]Hoja3!$J$5:$J$32=$C13)*([2]Hoja3!$F$5:$F$32=AL$5))} -> 108 | AM13: {=SUM([2]Hoja3!$I$5:$I$32*([2]Hoja3!$J$5:$J$32=$C13)*([2]Hoja3!$F$5:$F$32=AL$5))} -> 318600 | AN13: =IFERROR(AM13/AL13,0) -> 2950 | AO13: {=SUM([2]Hoja3!$H$5:$H$32*([2]Hoja3!$J$5:$J$32=$C13)*([2]Hoja3!$F$5:$F$32=AO$5))} -> 0 | AP13: {=SUM([2]Hoja3!$I$5:$I$32*([2]Hoja3!$J$5:$J$32=$C13)*([2]Hoja3!$F$5:$F$32=AO$5))} -> 0 | AQ13: =IFERROR(AP13/AO13,0) -> 0 | AR13: =T13+W13+Z13+AC13+AF13+AI13 -> 270 | AS13: =U13+X13+AA13+AD13+AG13+AJ13 -> 787050 | AT13: =IFERROR(AS13/AR13,0) -> 2915 | AU13: =AL13+AO13 -> 108 | AV13: =AM13+AP13 -> 318600 | AW13: =IFERROR(AV13/AU13,0) -> 2950 | AX13: =AR13+AU13 -> 378 | AY13: =AS13+AV13 -> 1105650 | AZ13: =IFERROR(AY13/AX13,0) -> 2925 | BA13: =-IFERROR(F13/D13*AX13,0) -> -711463.86 | BB13: =-IFERROR(G13/D13*AX13,0) -> -78563.52 | BC13: =$BC$21/$AX$21*$AX13 -> -15014.109 | BD13: =$BD$21/$AX$21*$AX13 -> -8856.488 | BE13: =$BE$21/$AX$21*$AX13 -> -20658.706 | BF13: =$BF$21/$AX$21*$AX13 -> -23594.185 | BG13: =AY13*0.03 -> 33169.5 | BH13: =AY13+SUM(BA13:BE13,BG13) -> 304262.82 | BI13: =IFERROR(BH13/AY13,0) -> 0.27518909 | BK13: =AZ13 -> 2925 | BL13: =IFERROR(BA13/$AX13,0) -> -1882.1795 | BM13: =IFERROR(BB13/$AX13,0) -> -207.84 | BN13: =IFERROR(BC13/$AX13,0) -> -39.719865 | BO13: =IFERROR(BD13/$AX13,0) -> -23.429863 | BP13: =IFERROR(BE13/$AX13,0) -> -54.652662 | BQ13: =IFERROR(BF13/$AX13,0) -> -62.418479 | BR13: =IFERROR(BG13/$AX13,0) -> 87.75 | BS13: =IFERROR(BH13/$AX13,0) -> 804.92809
B14: 10007567 | C14: POTA REPRODUCTORES | D14: =TD!E11 -> 65.68 | E14: =IFERROR(F14/D14,0) -> 1821.2402 | F14: =TD!F11 -> 119619.06 | G14: =TD!G11 -> 13650.931 | H14: =TD!H11 -> 2609.236 | I14: =TD!I11 -> 5129.3158 | J14: =TD!J11 -> 4100.3297 | K14: 0 | L14: 0 | M14: =F14+G14+H14+I14 -> 141008.54 | N14: =IFERROR(M14/D14,0) -> 2146.9023 | P14: =O14*D14 -> 0 | Q14: =P14-M14 -> -141008.54 | R14: =IFERROR(Q14/P14,0) -> 0 | T14: {=SUM([2]Hoja3!$H$5:$H$32*([2]Hoja3!$J$5:$J$32=$C14)*([2]Hoja3!$F$5:$F$32=T$5))} -> 0 | U14: {=SUM([2]Hoja3!$I$5:$I$32*([2]Hoja3!$J$5:$J$32=$C14)*([2]Hoja3!$F$5:$F$32=T$5))} -> 0 | V14: =IFERROR(U14/T14,0) -> 0 | W14: {=SUM([2]Hoja3!$H$5:$H$32*([2]Hoja3!$J$5:$J$32=$C14)*([2]Hoja3!$F$5:$F$32=W$5))} -> 0 | X14: {=SUM([2]Hoja3!$I$5:$I$32*([2]Hoja3!$J$5:$J$32=$C14)*([2]Hoja3!$F$5:$F$32=W$5))} -> 0 | Y14: =IFERROR(X14/W14,0) -> 0 | Z14: {=SUM([2]Hoja3!$H$5:$H$32*([2]Hoja3!$J$5:$J$32=$C14)*([2]Hoja3!$F$5:$F$32=Z$5))} -> 0 | AA14: {=SUM([2]Hoja3!$I$5:$I$32*([2]Hoja3!$J$5:$J$32=$C14)*([2]Hoja3!$F$5:$F$32=Z$5))} -> 0 | AB14: =IFERROR(AA14/Z14,0) -> 0 | AC14: {=SUM([2]Hoja3!$H$5:$H$32*([2]Hoja3!$J$5:$J$32=$C14)*([2]Hoja3!$F$5:$F$32=AC$5))} -> 26 | AD14: {=SUM([2]Hoja3!$I$5:$I$32*([2]Hoja3!$J$5:$J$32=$C14)*([2]Hoja3!$F$5:$F$32=AC$5))} -> 80600 | AE14: =IFERROR(AD14/AC14,0) -> 3100 | AF14: {=SUM([2]Hoja3!$H$5:$H$32*([2]Hoja3!$J$5:$J$32=$C14)*([2]Hoja3!$F$5:$F$32=AF$5))} -> 0 | AG14: {=SUM([2]Hoja3!$I$5:$I$32*([2]Hoja3!$J$5:$J$32=$C14)*([2]Hoja3!$F$5:$F$32=AF$5))} -> 0 | AH14: =IFERROR(AG14/AF14,0) -> 0 | AI14: {=SUM([2]Hoja3!$H$5:$H$32*([2]Hoja3!$J$5:$J$32=$C14)*([2]Hoja3!$F$5:$F$32=AI$5))} -> 26 | AJ14: {=SUM([2]Hoja3!$I$5:$I$32*([2]Hoja3!$J$5:$J$32=$C14)*([2]Hoja3!$F$5:$F$32=AI$5))} -> 74100 | AK14: =IFERROR(AJ14/AI14,0) -> 2850 | AL14: {=SUM([2]Hoja3!$H$5:$H$32*([2]Hoja3!$J$5:$J$32=$C14)*([2]Hoja3!$F$5:$F$32=AL$5))} -> 0 | AM14: {=SUM([2]Hoja3!$I$5:$I$32*([2]Hoja3!$J$5:$J$32=$C14)*([2]Hoja3!$F$5:$F$32=AL$5))} -> 0 | AN14: =IFERROR(AM14/AL14,0) -> 0 | AO14: {=SUM([2]Hoja3!$H$5:$H$32*([2]Hoja3!$J$5:$J$32=$C14)*([2]Hoja3!$F$5:$F$32=AO$5))} -> 0 | AP14: {=SUM([2]Hoja3!$I$5:$I$32*([2]Hoja3!$J$5:$J$32=$C14)*([2]Hoja3!$F$5:$F$32=AO$5))} -> 0 | AQ14: =IFERROR(AP14/AO14,0) -> 0 | AR14: =T14+W14+Z14+AC14+AF14+AI14 -> 52 | AS14: =U14+X14+AA14+AD14+AG14+AJ14 -> 154700 | AT14: =IFERROR(AS14/AR14,0) -> 2975 | AU14: =AL14+AO14 -> 0 | AV14: =AM14+AP14 -> 0 | AW14: =IFERROR(AV14/AU14,0) -> 0 | AX14: =AR14+AU14 -> 52 | AY14: =AS14+AV14 -> 154700 | AZ14: =IFERROR(AY14/AX14,0) -> 2975 | BA14: =-IFERROR(F14/D14*AX14,0) -> -94704.493 | BB14: =-IFERROR(G14/D14*AX14,0) -> -10807.68 | BC14: =$BC$21/$AX$21*$AX14 -> -2065.433 | BD14: =$BD$21/$AX$21*$AX14 -> -1218.3529 | BE14: =$BE$21/$AX$21*$AX14 -> -2841.9384 | BF14: =$BF$21/$AX$21*$AX14 -> -3245.7609 | BG14: =AY14*0.03 -> 4641 | BH14: =AY14+SUM(BA14:BE14,BG14) -> 47703.103 | BI14: =IFERROR(BH14/AY14,0) -> 0.30835878 | BK14: =AZ14 -> 2975 | BL14: =IFERROR(BA14/$AX14,0) -> -1821.2402 | BM14: =IFERROR(BB14/$AX14,0) -> -207.84 | BN14: =IFERROR(BC14/$AX14,0) -> -39.719865 | BO14: =IFERROR(BD14/$AX14,0) -> -23.429863 | BP14: =IFERROR(BE14/$AX14,0) -> -54.652662 | BQ14: =IFERROR(BF14/$AX14,0) -> -62.418479 | BR14: =IFERROR(BG14/$AX14,0) -> 89.25 | BS14: =IFERROR(BH14/$AX14,0) -> 917.36737
B15: 10007969 | C15: POTA CONOS | D15: =TD!E12 -> 15.56 | E15: =IFERROR(F15/D15,0) -> 1494.6794 | F15: =TD!F12 -> 23257.211 | G15: =TD!G12 -> 3233.9904 | H15: =TD!H12 -> 618.14421 | I15: =TD!I12 -> 1215.1668 | J15: =TD!J12 -> 971.39357 | K15: 0 | L15: 0 | M15: =F15+G15+H15+I15 -> 28324.513 | N15: =IFERROR(M15/D15,0) -> 1820.3414 | P15: =O15*D15 -> 0 | Q15: =P15-M15 -> -28324.513 | R15: =IFERROR(Q15/P15,0) -> 0 | T15: {=SUM([2]Hoja3!$H$5:$H$32*([2]Hoja3!$J$5:$J$32=$C15)*([2]Hoja3!$F$5:$F$32=T$5))} -> 0 | U15: {=SUM([2]Hoja3!$I$5:$I$32*([2]Hoja3!$J$5:$J$32=$C15)*([2]Hoja3!$F$5:$F$32=T$5))} -> 0 | V15: =IFERROR(U15/T15,0) -> 0 | W15: {=SUM([2]Hoja3!$H$5:$H$32*([2]Hoja3!$J$5:$J$32=$C15)*([2]Hoja3!$F$5:$F$32=W$5))} -> 0 | X15: {=SUM([2]Hoja3!$I$5:$I$32*([2]Hoja3!$J$5:$J$32=$C15)*([2]Hoja3!$F$5:$F$32=W$5))} -> 0 | Y15: =IFERROR(X15/W15,0) -> 0 | Z15: {=SUM([2]Hoja3!$H$5:$H$32*([2]Hoja3!$J$5:$J$32=$C15)*([2]Hoja3!$F$5:$F$32=Z$5))} -> 0 | AA15: {=SUM([2]Hoja3!$I$5:$I$32*([2]Hoja3!$J$5:$J$32=$C15)*([2]Hoja3!$F$5:$F$32=Z$5))} -> 0 | AB15: =IFERROR(AA15/Z15,0) -> 0 | AC15: {=SUM([2]Hoja3!$H$5:$H$32*([2]Hoja3!$J$5:$J$32=$C15)*([2]Hoja3!$F$5:$F$32=AC$5))} -> 0 | AD15: {=SUM([2]Hoja3!$I$5:$I$32*([2]Hoja3!$J$5:$J$32=$C15)*([2]Hoja3!$F$5:$F$32=AC$5))} -> 0 | AE15: =IFERROR(AD15/AC15,0) -> 0 | AF15: {=SUM([2]Hoja3!$H$5:$H$32*([2]Hoja3!$J$5:$J$32=$C15)*([2]Hoja3!$F$5:$F$32=AF$5))} -> 0 | AG15: {=SUM([2]Hoja3!$I$5:$I$32*([2]Hoja3!$J$5:$J$32=$C15)*([2]Hoja3!$F$5:$F$32=AF$5))} -> 0 | AH15: =IFERROR(AG15/AF15,0) -> 0 | AI15: {=SUM([2]Hoja3!$H$5:$H$32*([2]Hoja3!$J$5:$J$32=$C15)*([2]Hoja3!$F$5:$F$32=AI$5))} -> 0 | AJ15: {=SUM([2]Hoja3!$I$5:$I$32*([2]Hoja3!$J$5:$J$32=$C15)*([2]Hoja3!$F$5:$F$32=AI$5))} -> 0 | AK15: =IFERROR(AJ15/AI15,0) -> 0 | AL15: {=SUM([2]Hoja3!$H$5:$H$32*([2]Hoja3!$J$5:$J$32=$C15)*([2]Hoja3!$F$5:$F$32=AL$5))} -> 0 | AM15: {=SUM([2]Hoja3!$I$5:$I$32*([2]Hoja3!$J$5:$J$32=$C15)*([2]Hoja3!$F$5:$F$32=AL$5))} -> 0 | AN15: =IFERROR(AM15/AL15,0) -> 0 | AO15: {=SUM([2]Hoja3!$H$5:$H$32*([2]Hoja3!$J$5:$J$32=$C15)*([2]Hoja3!$F$5:$F$32=AO$5))} -> 24 | AP15: {=SUM([2]Hoja3!$I$5:$I$32*([2]Hoja3!$J$5:$J$32=$C15)*([2]Hoja3!$F$5:$F$32=AO$5))} -> 43200 | AQ15: =IFERROR(AP15/AO15,0) -> 1800 | AR15: =T15+W15+Z15+AC15+AF15+AI15 -> 0 | AS15: =U15+X15+AA15+AD15+AG15+AJ15 -> 0 | AT15: =IFERROR(AS15/AR15,0) -> 0 | AU15: =AL15+AO15 -> 24 | AV15: =AM15+AP15 -> 43200 | AW15: =IFERROR(AV15/AU15,0) -> 1800 | AX15: =AR15+AU15 -> 24 | AY15: =AS15+AV15 -> 43200 | AZ15: =IFERROR(AY15/AX15,0) -> 1800 | BA15: =-IFERROR(F15/D15*AX15,0) -> -35872.305 | BB15: =-IFERROR(G15/D15*AX15,0) -> -4988.16 | BC15: =$BC$21/$AX$21*$AX15 -> -953.27675 | BD15: =$BD$21/$AX$21*$AX15 -> -562.3167 | BE15: =$BE$21/$AX$21*$AX15 -> -1311.6639 | BF15: =$BF$21/$AX$21*$AX15 -> -1498.0435 | BG15: =AY15*0.03 -> 1296 | BH15: =AY15+SUM(BA15:BE15,BG15) -> 808.27756 | BI15: =IFERROR(BH15/AY15,0) -> 0.018710129 | BK15: =AZ15 -> 1800 | BL15: =IFERROR(BA15/$AX15,0) -> -1494.6794 | BM15: =IFERROR(BB15/$AX15,0) -> -207.84 | BN15: =IFERROR(BC15/$AX15,0) -> -39.719865 | BO15: =IFERROR(BD15/$AX15,0) -> -23.429863 | BP15: =IFERROR(BE15/$AX15,0) -> -54.652662 | BQ15: =IFERROR(BF15/$AX15,0) -> -62.418479 | BR15: =IFERROR(BG15/$AX15,0) -> 54 | BS15: =IFERROR(BH15/$AX15,0) -> 33.678232
B16: 10009207 | C16: POTA LABIOS FR S/COD BL10 S20 | D16: =TD!E13 -> 0.38 | E16: =IFERROR(F16/D16,0) -> 1545.5756 | F16: =TD!F13 -> 587.31873 | G16: =TD!G13 -> 78.9792 | H16: =TD!H13 -> 15.096067 | I16: =TD!I13 -> 29.676309 | J16: =TD!J13 -> 23.722979 | K16: 0 | L16: 0 | M16: =F16+G16+H16+I16 -> 711.07031 | N16: =IFERROR(M16/D16,0) -> 1871.2376 | P16: =O16*D16 -> 0 | Q16: =P16-M16 -> -711.07031 | R16: =IFERROR(Q16/P16,0) -> 0 | T16: {=SUM([2]Hoja3!$H$5:$H$32*([2]Hoja3!$J$5:$J$32=$C16)*([2]Hoja3!$F$5:$F$32=T$5))} -> 0 | U16: {=SUM([2]Hoja3!$I$5:$I$32*([2]Hoja3!$J$5:$J$32=$C16)*([2]Hoja3!$F$5:$F$32=T$5))} -> 0 | V16: =IFERROR(U16/T16,0) -> 0 | W16: {=SUM([2]Hoja3!$H$5:$H$32*([2]Hoja3!$J$5:$J$32=$C16)*([2]Hoja3!$F$5:$F$32=W$5))} -> 0 | X16: {=SUM([2]Hoja3!$I$5:$I$32*([2]Hoja3!$J$5:$J$32=$C16)*([2]Hoja3!$F$5:$F$32=W$5))} -> 0 | Y16: =IFERROR(X16/W16,0) -> 0 | Z16: {=SUM([2]Hoja3!$H$5:$H$32*([2]Hoja3!$J$5:$J$32=$C16)*([2]Hoja3!$F$5:$F$32=Z$5))} -> 0 | AA16: {=SUM([2]Hoja3!$I$5:$I$32*([2]Hoja3!$J$5:$J$32=$C16)*([2]Hoja3!$F$5:$F$32=Z$5))} -> 0 | AB16: =IFERROR(AA16/Z16,0) -> 0 | AC16: {=SUM([2]Hoja3!$H$5:$H$32*([2]Hoja3!$J$5:$J$32=$C16)*([2]Hoja3!$F$5:$F$32=AC$5))} -> 26 | AD16: {=SUM([2]Hoja3!$I$5:$I$32*([2]Hoja3!$J$5:$J$32=$C16)*([2]Hoja3!$F$5:$F$32=AC$5))} -> 36400 | AE16: =IFERROR(AD16/AC16,0) -> 1400 | AF16: {=SUM([2]Hoja3!$H$5:$H$32*([2]Hoja3!$J$5:$J$32=$C16)*([2]Hoja3!$F$5:$F$32=AF$5))} -> 0 | AG16: {=SUM([2]Hoja3!$I$5:$I$32*([2]Hoja3!$J$5:$J$32=$C16)*([2]Hoja3!$F$5:$F$32=AF$5))} -> 0 | AH16: =IFERROR(AG16/AF16,0) -> 0 | AI16: {=SUM([2]Hoja3!$H$5:$H$32*([2]Hoja3!$J$5:$J$32=$C16)*([2]Hoja3!$F$5:$F$32=AI$5))} -> 0 | AJ16: {=SUM([2]Hoja3!$I$5:$I$32*([2]Hoja3!$J$5:$J$32=$C16)*([2]Hoja3!$F$5:$F$32=AI$5))} -> 0 | AK16: =IFERROR(AJ16/AI16,0) -> 0 | AL16: {=SUM([2]Hoja3!$H$5:$H$32*([2]Hoja3!$J$5:$J$32=$C16)*([2]Hoja3!$F$5:$F$32=AL$5))} -> 0 | AM16: {=SUM([2]Hoja3!$I$5:$I$32*([2]Hoja3!$J$5:$J$32=$C16)*([2]Hoja3!$F$5:$F$32=AL$5))} -> 0 | AN16: =IFERROR(AM16/AL16,0) -> 0 | AO16: {=SUM([2]Hoja3!$H$5:$H$32*([2]Hoja3!$J$5:$J$32=$C16)*([2]Hoja3!$F$5:$F$32=AO$5))} -> 0 | AP16: {=SUM([2]Hoja3!$I$5:$I$32*([2]Hoja3!$J$5:$J$32=$C16)*([2]Hoja3!$F$5:$F$32=AO$5))} -> 0 | AQ16: =IFERROR(AP16/AO16,0) -> 0 | AR16: =T16+W16+Z16+AC16+AF16+AI16 -> 26 | AS16: =U16+X16+AA16+AD16+AG16+AJ16 -> 36400 | AT16: =IFERROR(AS16/AR16,0) -> 1400 | AU16: =AL16+AO16 -> 0 | AV16: =AM16+AP16 -> 0 | AW16: =IFERROR(AV16/AU16,0) -> 0 | AX16: =AR16+AU16 -> 26 | AY16: =AS16+AV16 -> 36400 | AZ16: =IFERROR(AY16/AX16,0) -> 1400 | BA16: =-AX16*1570 -> -40820 | BB16: =BB15/AX15*AX16 -> -5403.84 | BC16: =$BC$21/$AX$21*$AX16 -> -1032.7165 | BD16: =$BD$21/$AX$21*$AX16 -> -609.17643 | BE16: =$BE$21/$AX$21*$AX16 -> -1420.9692 | BF16: =$BF$21/$AX$21*$AX16 -> -1622.8805 | BG16: =AY16*0.03 -> 1092 | BH16: =AY16+SUM(BA16:BE16,BG16) -> -11794.702 | BI16: =IFERROR(BH16/AY16,0) -> -0.32403028 | BK16: =AZ16 -> 1400 | BL16: =IFERROR(BA16/$AX16,0) -> -1570 | BM16: =IFERROR(BB16/$AX16,0) -> -207.84 | BN16: =IFERROR(BC16/$AX16,0) -> -39.719865 | BO16: =IFERROR(BD16/$AX16,0) -> -23.429863 | BP16: =IFERROR(BE16/$AX16,0) -> -54.652662 | BQ16: =IFERROR(BF16/$AX16,0) -> -62.418479 | BR16: =IFERROR(BG16/$AX16,0) -> 42 | BS16: =IFERROR(BH16/$AX16,0) -> -453.64239
B17: 10009239 | C17: POTA FILETE DARUMA | D17: =TD!E14 -> 50.26 | E17: =IFERROR(F17/D17,0) -> 3441.6817 | F17: =TD!F14 -> 172978.92 | G17: =TD!G14 -> 10446.038 | H17: =TD!H14 -> 1996.6535 | I17: =TD!I14 -> 3925.0824 | J17: =TD!J14 -> 3137.6762 | K17: 0 | L17: 0 | M17: =F17+G17+H17+I17 -> 189346.69 | N17: =IFERROR(M17/D17,0) -> 3767.3437 | P17: =O17*D17 -> 0 | Q17: =P17-M17 -> -189346.69 | R17: =IFERROR(Q17/P17,0) -> 0 | T17: {=SUM([2]Hoja3!$H$5:$H$32*([2]Hoja3!$J$5:$J$32=$C17)*([2]Hoja3!$F$5:$F$32=T$5))} -> 81 | U17: {=SUM([2]Hoja3!$I$5:$I$32*([2]Hoja3!$J$5:$J$32=$C17)*([2]Hoja3!$F$5:$F$32=T$5))} -> 315900 | V17: =IFERROR(U17/T17,0) -> 3900 | W17: {=SUM([2]Hoja3!$H$5:$H$32*([2]Hoja3!$J$5:$J$32=$C17)*([2]Hoja3!$F$5:$F$32=W$5))} -> 81 | X17: {=SUM([2]Hoja3!$I$5:$I$32*([2]Hoja3!$J$5:$J$32=$C17)*([2]Hoja3!$F$5:$F$32=W$5))} -> 299700 | Y17: =IFERROR(X17/W17,0) -> 3700 | Z17: {=SUM([2]Hoja3!$H$5:$H$32*([2]Hoja3!$J$5:$J$32=$C17)*([2]Hoja3!$F$5:$F$32=Z$5))} -> 0 | AA17: {=SUM([2]Hoja3!$I$5:$I$32*([2]Hoja3!$J$5:$J$32=$C17)*([2]Hoja3!$F$5:$F$32=Z$5))} -> 0 | AB17: =IFERROR(AA17/Z17,0) -> 0 | AC17: {=SUM([2]Hoja3!$H$5:$H$32*([2]Hoja3!$J$5:$J$32=$C17)*([2]Hoja3!$F$5:$F$32=AC$5))} -> 0 | AD17: {=SUM([2]Hoja3!$I$5:$I$32*([2]Hoja3!$J$5:$J$32=$C17)*([2]Hoja3!$F$5:$F$32=AC$5))} -> 0 | AE17: =IFERROR(AD17/AC17,0) -> 0 | AF17: {=SUM([2]Hoja3!$H$5:$H$32*([2]Hoja3!$J$5:$J$32=$C17)*([2]Hoja3!$F$5:$F$32=AF$5))} -> 108 | AG17: {=SUM([2]Hoja3!$I$5:$I$32*([2]Hoja3!$J$5:$J$32=$C17)*([2]Hoja3!$F$5:$F$32=AF$5))} -> 421200 | AH17: =IFERROR(AG17/AF17,0) -> 3900 | AI17: {=SUM([2]Hoja3!$H$5:$H$32*([2]Hoja3!$J$5:$J$32=$C17)*([2]Hoja3!$F$5:$F$32=AI$5))} -> 0 | AJ17: {=SUM([2]Hoja3!$I$5:$I$32*([2]Hoja3!$J$5:$J$32=$C17)*([2]Hoja3!$F$5:$F$32=AI$5))} -> 0 | AK17: =IFERROR(AJ17/AI17,0) -> 0 | AL17: {=SUM([2]Hoja3!$H$5:$H$32*([2]Hoja3!$J$5:$J$32=$C17)*([2]Hoja3!$F$5:$F$32=AL$5))} -> 27 | AM17: {=SUM([2]Hoja3!$I$5:$I$32*([2]Hoja3!$J$5:$J$32=$C17)*([2]Hoja3!$F$5:$F$32=AL$5))} -> 105300 | AN17: =IFERROR(AM17/AL17,0) -> 3900 | AO17: {=SUM([2]Hoja3!$H$5:$H$32*([2]Hoja3!$J$5:$J$32=$C17)*([2]Hoja3!$F$5:$F$32=AO$5))} -> 0 | AP17: {=SUM([2]Hoja3!$I$5:$I$32*([2]Hoja3!$J$5:$J$32=$C17)*([2]Hoja3!$F$5:$F$32=AO$5))} -> 0 | AQ17: =IFERROR(AP17/AO17,0) -> 0 | AR17: =T17+W17+Z17+AC17+AF17+AI17 -> 270 | AS17: =U17+X17+AA17+AD17+AG17+AJ17 -> 1036800 | AT17: =IFERROR(AS17/AR17,0) -> 3840 | AU17: =AL17+AO17 -> 27 | AV17: =AM17+AP17 -> 105300 | AW17: =IFERROR(AV17/AU17,0) -> 3900 | AX17: =AR17+AU17 -> 297 | AY17: =AS17+AV17 -> 1142100 | AZ17: =IFERROR(AY17/AX17,0) -> 3845.4545 | BA17: =-IFERROR(F17/D17*AX17,0) -> -1022179.5 | BB17: =-IFERROR(G17/D17*AX17,0) -> -61728.48 | BC17: =$BC$21/$AX$21*$AX17 -> -11796.8 | BD17: =$BD$21/$AX$21*$AX17 -> -6958.6692 | BE17: =$BE$21/$AX$21*$AX17 -> -16231.84 | BF17: =$BF$21/$AX$21*$AX17 -> -18538.288 | BG17: =AY17*0.03 -> 34263 | BH17: =AY17+SUM(BA17:BE17,BG17) -> 57467.756 | BI17: =IFERROR(BH17/AY17,0) -> 0.050317622 | BK17: =AZ17 -> 3845.4545 | BL17: =IFERROR(BA17/$AX17,0) -> -3441.6817 | BM17: =IFERROR(BB17/$AX17,0) -> -207.84 | BN17: =IFERROR(BC17/$AX17,0) -> -39.719865 | BO17: =IFERROR(BD17/$AX17,0) -> -23.429863 | BP17: =IFERROR(BE17/$AX17,0) -> -54.652662 | BQ17: =IFERROR(BF17/$AX17,0) -> -62.418479 | BR17: =IFERROR(BG17/$AX17,0) -> 115.36364 | BS17: =IFERROR(BH17/$AX17,0) -> 193.49413
B18: 10009334 | C18: POTA ALAS COCIDAS | D18: =TD!E15 -> 1.352 | E18: =IFERROR(F18/D18,0) -> 3020.074 | F18: =TD!F15 -> 4083.1401 | G18: =TD!G15 -> 280.99968 | H18: =TD!H15 -> 53.710216 | I18: =TD!I15 -> 105.58519 | J18: =TD!J15 -> 84.403863 | K18: 0 | L18: 0 | M18: =F18+G18+H18+I18 -> 4523.4352 | N18: =IFERROR(M18/D18,0) -> 3345.7361 | P18: =O18*D18 -> 0 | Q18: =P18-M18 -> -4523.4352 | R18: =IFERROR(Q18/P18,0) -> 0 | T18: {=SUM([2]Hoja3!$H$5:$H$32*([2]Hoja3!$J$5:$J$32=$C18)*([2]Hoja3!$F$5:$F$32=T$5))} -> 27 | U18: {=SUM([2]Hoja3!$I$5:$I$32*([2]Hoja3!$J$5:$J$32=$C18)*([2]Hoja3!$F$5:$F$32=T$5))} -> 106650 | V18: =IFERROR(U18/T18,0) -> 3950 | W18: {=SUM([2]Hoja3!$H$5:$H$32*([2]Hoja3!$J$5:$J$32=$C18)*([2]Hoja3!$F$5:$F$32=W$5))} -> 0 | X18: {=SUM([2]Hoja3!$I$5:$I$32*([2]Hoja3!$J$5:$J$32=$C18)*([2]Hoja3!$F$5:$F$32=W$5))} -> 0 | Y18: =IFERROR(X18/W18,0) -> 0 | Z18: {=SUM([2]Hoja3!$H$5:$H$32*([2]Hoja3!$J$5:$J$32=$C18)*([2]Hoja3!$F$5:$F$32=Z$5))} -> 26.28 | AA18: {=SUM([2]Hoja3!$I$5:$I$32*([2]Hoja3!$J$5:$J$32=$C18)*([2]Hoja3!$F$5:$F$32=Z$5))} -> 103806 | AB18: =IFERROR(AA18/Z18,0) -> 3950 | AC18: {=SUM([2]Hoja3!$H$5:$H$32*([2]Hoja3!$J$5:$J$32=$C18)*([2]Hoja3!$F$5:$F$32=AC$5))} -> 0 | AD18: {=SUM([2]Hoja3!$I$5:$I$32*([2]Hoja3!$J$5:$J$32=$C18)*([2]Hoja3!$F$5:$F$32=AC$5))} -> 0 | AE18: =IFERROR(AD18/AC18,0) -> 0 | AF18: {=SUM([2]Hoja3!$H$5:$H$32*([2]Hoja3!$J$5:$J$32=$C18)*([2]Hoja3!$F$5:$F$32=AF$5))} -> 27 | AG18: {=SUM([2]Hoja3!$I$5:$I$32*([2]Hoja3!$J$5:$J$32=$C18)*([2]Hoja3!$F$5:$F$32=AF$5))} -> 106650 | AH18: =IFERROR(AG18/AF18,0) -> 3950 | AI18: {=SUM([2]Hoja3!$H$5:$H$32*([2]Hoja3!$J$5:$J$32=$C18)*([2]Hoja3!$F$5:$F$32=AI$5))} -> 0 | AJ18: {=SUM([2]Hoja3!$I$5:$I$32*([2]Hoja3!$J$5:$J$32=$C18)*([2]Hoja3!$F$5:$F$32=AI$5))} -> 0 | AK18: =IFERROR(AJ18/AI18,0) -> 0 | AL18: {=SUM([2]Hoja3!$H$5:$H$32*([2]Hoja3!$J$5:$J$32=$C18)*([2]Hoja3!$F$5:$F$32=AL$5))} -> 27 | AM18: {=SUM([2]Hoja3!$I$5:$I$32*([2]Hoja3!$J$5:$J$32=$C18)*([2]Hoja3!$F$5:$F$32=AL$5))} -> 106650 | AN18: =IFERROR(AM18/AL18,0) -> 3950 | AO18: {=SUM([2]Hoja3!$H$5:$H$32*([2]Hoja3!$J$5:$J$32=$C18)*([2]Hoja3!$F$5:$F$32=AO$5))} -> 0 | AP18: {=SUM([2]Hoja3!$I$5:$I$32*([2]Hoja3!$J$5:$J$32=$C18)*([2]Hoja3!$F$5:$F$32=AO$5))} -> 0 | AQ18: =IFERROR(AP18/AO18,0) -> 0 | AR18: =T18+W18+Z18+AC18+AF18+AI18 -> 80.28 | AS18: =U18+X18+AA18+AD18+AG18+AJ18 -> 317106 | AT18: =IFERROR(AS18/AR18,0) -> 3950 | AU18: =AL18+AO18 -> 27 | AV18: =AM18+AP18 -> 106650 | AW18: =IFERROR(AV18/AU18,0) -> 3950 | AX18: =AR18+AU18 -> 107.28 | AY18: =AS18+AV18 -> 423756 | AZ18: =IFERROR(AY18/AX18,0) -> 3950 | BA18: =-IFERROR(F18/D18*AX18,0) -> -323993.54 | BB18: =-IFERROR(G18/D18*AX18,0) -> -22297.075 | BC18: =$BC$21/$AX$21*$AX18 -> -4261.1471 | BD18: =$BD$21/$AX$21*$AX18 -> -2513.5557 | BE18: =$BE$21/$AX$21*$AX18 -> -5863.1375 | BF18: =$BF$21/$AX$21*$AX18 -> -6696.2545 | BG18: =AY18*0.03 -> 12712.68 | BH18: =AY18+SUM(BA18:BE18,BG18) -> 77540.222 | BI18: =IFERROR(BH18/AY18,0) -> 0.18298318 | BK18: =AZ18 -> 3950 | BL18: =IFERROR(BA18/$AX18,0) -> -3020.074 | BM18: =IFERROR(BB18/$AX18,0) -> -207.84 | BN18: =IFERROR(BC18/$AX18,0) -> -39.719865 | BO18: =IFERROR(BD18/$AX18,0) -> -23.429863 | BP18: =IFERROR(BE18/$AX18,0) -> -54.652662 | BQ18: =IFERROR(BF18/$AX18,0) -> -62.418479 | BR18: =IFERROR(BG18/$AX18,0) -> 118.5 | BS18: =IFERROR(BH18/$AX18,0) -> 722.78358
B19: 10009386 | C19: VENTOSAS | D19: =TD!E16 -> 14.52 | E19: =IFERROR(F19/D19,0) -> 1883.7263 | F19: =TD!F16 -> 27351.706 | G19: =TD!G16 -> 3017.8368 | H19: =TD!H16 -> 576.82866 | I19: =TD!I16 -> 1133.9474 | J19: =TD!J16 -> 906.46752 | K19: 0 | L19: 0 | M19: =F19+G19+H19+I19 -> 32080.319 | N19: =IFERROR(M19/D19,0) -> 2209.3883 | P19: =O19*D19 -> 0 | Q19: =P19-M19 -> -32080.319 | R19: =IFERROR(Q19/P19,0) -> 0 | T19: {=SUM([2]Hoja3!$H$5:$H$32*([2]Hoja3!$J$5:$J$32=$C19)*([2]Hoja3!$F$5:$F$32=T$5))} -> 0 | U19: {=SUM([2]Hoja3!$I$5:$I$32*([2]Hoja3!$J$5:$J$32=$C19)*([2]Hoja3!$F$5:$F$32=T$5))} -> 0 | V19: =IFERROR(U19/T19,0) -> 0 | W19: {=SUM([2]Hoja3!$H$5:$H$32*([2]Hoja3!$J$5:$J$32=$C19)*([2]Hoja3!$F$5:$F$32=W$5))} -> 0 | X19: {=SUM([2]Hoja3!$I$5:$I$32*([2]Hoja3!$J$5:$J$32=$C19)*([2]Hoja3!$F$5:$F$32=W$5))} -> 0 | Y19: =IFERROR(X19/W19,0) -> 0 | Z19: {=SUM([2]Hoja3!$H$5:$H$32*([2]Hoja3!$J$5:$J$32=$C19)*([2]Hoja3!$F$5:$F$32=Z$5))} -> 0 | AA19: {=SUM([2]Hoja3!$I$5:$I$32*([2]Hoja3!$J$5:$J$32=$C19)*([2]Hoja3!$F$5:$F$32=Z$5))} -> 0 | AB19: =IFERROR(AA19/Z19,0) -> 0 | AC19: {=SUM([2]Hoja3!$H$5:$H$32*([2]Hoja3!$J$5:$J$32=$C19)*([2]Hoja3!$F$5:$F$32=AC$5))} -> 0 | AD19: {=SUM([2]Hoja3!$I$5:$I$32*([2]Hoja3!$J$5:$J$32=$C19)*([2]Hoja3!$F$5:$F$32=AC$5))} -> 0 | AE19: =IFERROR(AD19/AC19,0) -> 0 | AF19: {=SUM([2]Hoja3!$H$5:$H$32*([2]Hoja3!$J$5:$J$32=$C19)*([2]Hoja3!$F$5:$F$32=AF$5))} -> 0 | AG19: {=SUM([2]Hoja3!$I$5:$I$32*([2]Hoja3!$J$5:$J$32=$C19)*([2]Hoja3!$F$5:$F$32=AF$5))} -> 0 | AH19: =IFERROR(AG19/AF19,0) -> 0 | AI19: {=SUM([2]Hoja3!$H$5:$H$32*([2]Hoja3!$J$5:$J$32=$C19)*([2]Hoja3!$F$5:$F$32=AI$5))} -> 0 | AJ19: {=SUM([2]Hoja3!$I$5:$I$32*([2]Hoja3!$J$5:$J$32=$C19)*([2]Hoja3!$F$5:$F$32=AI$5))} -> 0 | AK19: =IFERROR(AJ19/AI19,0) -> 0 | AL19: {=SUM([2]Hoja3!$H$5:$H$32*([2]Hoja3!$J$5:$J$32=$C19)*([2]Hoja3!$F$5:$F$32=AL$5))} -> 0 | AM19: {=SUM([2]Hoja3!$I$5:$I$32*([2]Hoja3!$J$5:$J$32=$C19)*([2]Hoja3!$F$5:$F$32=AL$5))} -> 0 | AN19: =IFERROR(AM19/AL19,0) -> 0 | AO19: {=SUM([2]Hoja3!$H$5:$H$32*([2]Hoja3!$J$5:$J$32=$C19)*([2]Hoja3!$F$5:$F$32=AO$5))} -> 0 | AP19: {=SUM([2]Hoja3!$I$5:$I$32*([2]Hoja3!$J$5:$J$32=$C19)*([2]Hoja3!$F$5:$F$32=AO$5))} -> 0 | AQ19: =IFERROR(AP19/AO19,0) -> 0 | AR19: =T19+W19+Z19+AC19+AF19+AI19 -> 0 | AS19: =U19+X19+AA19+AD19+AG19+AJ19 -> 0 | AT19: =IFERROR(AS19/AR19,0) -> 0 | AU19: =AL19+AO19 -> 0 | AV19: =AM19+AP19 -> 0 | AW19: =IFERROR(AV19/AU19,0) -> 0 | AX19: =AR19+AU19 -> 0 | AY19: =AS19+AV19 -> 0 | AZ19: =IFERROR(AY19/AX19,0) -> 0 | BA19: =-IFERROR(F19/D19*AX19,0) -> 0 | BB19: =-IFERROR(G19/D19*AX19,0) -> 0 | BC19: =$BC$21/$AX$21*$AX19 -> 0 | BD19: =$BD$21/$AX$21*$AX19 -> 0 | BE19: =$BE$21/$AX$21*$AX19 -> 0 | BF19: =$BF$21/$AX$21*$AX19 -> 0 | BG19: =AY19*0.03 -> 0 | BH19: =AY19+SUM(BA19:BE19,BG19) -> 0 | BI19: =IFERROR(BH19/AY19,0) -> 0 | BK19: =AZ19 -> 0 | BL19: =IFERROR(BA19/$AX19,0) -> 0 | BM19: =IFERROR(BB19/$AX19,0) -> 0 | BN19: =IFERROR(BC19/$AX19,0) -> 0 | BO19: =IFERROR(BD19/$AX19,0) -> 0 | BP19: =IFERROR(BE19/$AX19,0) -> 0 | BQ19: =IFERROR(BF19/$AX19,0) -> 0 | BR19: =IFERROR(BG19/$AX19,0) -> 0 | BS19: =IFERROR(BH19/$AX19,0) -> 0
C20: OTROS | L20: 0 | M20: =F20+G20+H20+I20 -> 0 | N20: =IFERROR(M20/D20,0) -> 0 | P20: =O20*D20 -> 0 | Q20: =P20-M20 -> 0 | R20: =IFERROR(Q20/P20,0) -> 0 | T20: {=SUM([2]Hoja3!$H$5:$H$32*([2]Hoja3!$J$5:$J$32=$C20)*([2]Hoja3!$F$5:$F$32=T$5))} -> 0 | U20: {=SUM([2]Hoja3!$I$5:$I$32*([2]Hoja3!$J$5:$J$32=$C20)*([2]Hoja3!$F$5:$F$32=T$5))} -> 0 | V20: =IFERROR(U20/T20,0) -> 0 | W20: {=SUM([2]Hoja3!$H$5:$H$32*([2]Hoja3!$J$5:$J$32=$C20)*([2]Hoja3!$F$5:$F$32=W$5))} -> 53.25 | X20: {=SUM([2]Hoja3!$I$5:$I$32*([2]Hoja3!$J$5:$J$32=$C20)*([2]Hoja3!$F$5:$F$32=W$5))} -> 107812.5 | Y20: =IFERROR(X20/W20,0) -> 2024.6479 | Z20: {=SUM([2]Hoja3!$H$5:$H$32*([2]Hoja3!$J$5:$J$32=$C20)*([2]Hoja3!$F$5:$F$32=Z$5))} -> 0 | AA20: {=SUM([2]Hoja3!$I$5:$I$32*([2]Hoja3!$J$5:$J$32=$C20)*([2]Hoja3!$F$5:$F$32=Z$5))} -> 0 | AB20: =IFERROR(AA20/Z20,0) -> 0 | AC20: {=SUM([2]Hoja3!$H$5:$H$32*([2]Hoja3!$J$5:$J$32=$C20)*([2]Hoja3!$F$5:$F$32=AC$5))} -> 27 | AD20: {=SUM([2]Hoja3!$I$5:$I$32*([2]Hoja3!$J$5:$J$32=$C20)*([2]Hoja3!$F$5:$F$32=AC$5))} -> 63450 | AE20: =IFERROR(AD20/AC20,0) -> 2350 | AF20: {=SUM([2]Hoja3!$H$5:$H$32*([2]Hoja3!$J$5:$J$32=$C20)*([2]Hoja3!$F$5:$F$32=AF$5))} -> 0 | AG20: {=SUM([2]Hoja3!$I$5:$I$32*([2]Hoja3!$J$5:$J$32=$C20)*([2]Hoja3!$F$5:$F$32=AF$5))} -> 0 | AH20: =IFERROR(AG20/AF20,0) -> 0 | AI20: {=SUM([2]Hoja3!$H$5:$H$32*([2]Hoja3!$J$5:$J$32=$C20)*([2]Hoja3!$F$5:$F$32=AI$5))} -> 0 | AJ20: {=SUM([2]Hoja3!$I$5:$I$32*([2]Hoja3!$J$5:$J$32=$C20)*([2]Hoja3!$F$5:$F$32=AI$5))} -> 0 | AK20: =IFERROR(AJ20/AI20,0) -> 0 | AL20: {=SUM([2]Hoja3!$H$5:$H$32*([2]Hoja3!$J$5:$J$32=$C20)*([2]Hoja3!$F$5:$F$32=AL$5))} -> 27 | AM20: {=SUM([2]Hoja3!$I$5:$I$32*([2]Hoja3!$J$5:$J$32=$C20)*([2]Hoja3!$F$5:$F$32=AL$5))} -> 67500 | AN20: =IFERROR(AM20/AL20,0) -> 2500 | AO20: {=SUM([2]Hoja3!$H$5:$H$32*([2]Hoja3!$J$5:$J$32=$C20)*([2]Hoja3!$F$5:$F$32=AO$5))} -> 0 | AP20: {=SUM([2]Hoja3!$I$5:$I$32*([2]Hoja3!$J$5:$J$32=$C20)*([2]Hoja3!$F$5:$F$32=AO$5))} -> 0 | AQ20: =IFERROR(AP20/AO20,0) -> 0 | AR20: =T20+W20+Z20+AC20+AF20+AI20 -> 80.25 | AS20: =U20+X20+AA20+AD20+AG20+AJ20 -> 171262.5 | AT20: =IFERROR(AS20/AR20,0) -> 2134.1121 | AU20: =AL20+AO20 -> 27 | AV20: =AM20+AP20 -> 67500 | AW20: =IFERROR(AV20/AU20,0) -> 2500 | AX20: =AR20+AU20 -> 107.25 | AY20: =AS20+AV20 -> 238762.5 | AZ20: =IFERROR(AY20/AX20,0) -> 2226.2238 | BA20: =-IFERROR(F20/D20*AX20,0) -> 0 | BB20: =-IFERROR(G20/D20*AX20,0) -> 0 | BC20: =$BC$21/$AX$21*$AX20 -> -4259.9555 | BD20: =$BD$21/$AX$21*$AX20 -> -2512.8528 | BE20: =$BE$21/$AX$21*$AX20 -> -5861.498 | BF20: =$BF$21/$AX$21*$AX20 -> -6694.3819 | BG20: =AY20*0.03 -> 7162.875 | BH20: =AY20+SUM(BA20:BE20,BG20) -> 233291.07 | BI20: =IFERROR(BH20/AY20,0) -> 0.97708421 | BK20: =AZ20 -> 2226.2238 | BL20: =IFERROR(BA20/$AX20,0) -> 0 | BM20: =IFERROR(BB20/$AX20,0) -> 0 | BN20: =IFERROR(BC20/$AX20,0) -> -39.719865 | BO20: =IFERROR(BD20/$AX20,0) -> -23.429863 | BP20: =IFERROR(BE20/$AX20,0) -> -54.652662 | BQ20: =IFERROR(BF20/$AX20,0) -> -62.418479 | BR20: =IFERROR(BG20/$AX20,0) -> 66.786713 | BS20: =IFERROR(BH20/$AX20,0) -> 2175.2081
C21: TOTAL | D21: =SUM(D7:D20) -> 777.937 | E21: =IFERROR(F21/D21,0) -> 2011.2437 | F21: =SUM(F7:F20) -> 1564620.9 | G21: =SUM(G7:G20) -> 161686.43 | H21: =SUM(H7:H20) -> 30904.708 | I21: =SUM(I7:I20) -> 60753.419 | J21: =SUM(J7:J20) -> 48565.746 | K21: =SUM(K7:K20) -> 0 | L21: 0 | M21: =SUM(M7:M20) -> 1817965.4 | N21: =IFERROR(M21/D21,0) -> 2336.9057 | O21: =P21/D21 -> 0 | P21: =SUM(P7:P20) -> 0 | Q21: =SUM(Q7:Q20) -> -1817965.4 | R21: =Q21/P21 -> #DIV/0! | T21: =SUM(T7:T20) -> 108 | U21: =SUM(U7:U20) -> 422550 | V21: =IFERROR(U21/T21,0) -> 3912.5 | W21: =SUM(W7:W20) -> 426.25 | X21: =SUM(X7:X20) -> 943487.5 | Y21: =IFERROR(X21/W21,0) -> 2213.4604 | Z21: =SUM(Z7:Z20) -> 208.08 | AA21: =SUM(AA7:AA20) -> 539186 | AB21: =IFERROR(AA21/Z21,0) -> 2591.2438 | AC21: =SUM(AC7:AC20) -> 79 | AD21: =SUM(AD7:AD20) -> 180450 | AE21: =IFERROR(AD21/AC21,0) -> 2284.1772 | AF21: =SUM(AF7:AF20) -> 648 | AG21: =SUM(AG7:AG20) -> 1682640 | AH21: =IFERROR(AG21/AF21,0) -> 2596.6667 | AI21: =SUM(AI7:AI20) -> 26 | AJ21: =SUM(AJ7:AJ20) -> 74100 | AK21: =IFERROR(AJ21/AI21,0) -> 2850 | AL21: =SUM(AL7:AL20) -> 459 | AM21: =SUM(AM7:AM20) -> 1130490 | AN21: =IFERROR(AM21/AL21,0) -> 2462.9412 | AO21: =SUM(AO7:AO20) -> 24 | AP21: =SUM(AP7:AP20) -> 43200 | AQ21: =IFERROR(AP21/AO21,0) -> 1800 | AR21: =SUM(AR7:AR20) -> 1495.33 | AS21: =SUM(AS7:AS20) -> 3842413.5 | AT21: =IFERROR(AS21/AR21,0) -> 2569.609 | AU21: =SUM(AU7:AU20) -> 483 | AV21: =SUM(AV7:AV20) -> 1173690 | AW21: =IFERROR(AV21/AU21,0) -> 2430 | AX21: =SUM(AX7:AX20) -> 1978.33 | AY21: =SUM(AY7:AY20) -> 5016103.5 | AZ21: =IFERROR(AY21/AX21,0) -> 2535.5242 | BA21: =SUM(BA7:BA20) -> -4237446.8 | BB21: =SUM(BB7:BB20) -> -388885.27 | BC21: =-'Stock Libre'!Y61 -> -78579 | BD21: -46352 | BE21: -108121 | BF21: =-'Stock Libre'!AA61 -> -123484.35 | BG21: =SUM(BG7:BG20) -> 150483.11 | BH21: =SUM(BH7:BH20) -> 307202.57 | BI21: =IFERROR(BH21/AY21,0) -> 0.061243267 | BK21: =AZ21 -> 2535.5242 | BL21: =IFERROR(BA21/$AX21,0) -> -2141.9312 | BM21: =IFERROR(BB21/$AX21,0) -> -196.5725 | BN21: =IFERROR(BC21/$AX21,0) -> -39.719865 | BO21: =IFERROR(BD21/$AX21,0) -> -23.429863 | BP21: =IFERROR(BE21/$AX21,0) -> -54.652662 | BQ21: =IFERROR(BF21/$AX21,0) -> -62.418479 | BR21: =IFERROR(BG21/$AX21,0) -> 76.065725 | BS21: =IFERROR(BH21/$AX21,0) -> 155.28378
I22: =I21/D21 -> 78.095551
BL23: =BL21+BM21+BN21-BQ21 -> -2315.8051

Sheet TD
D3: Etiquetas de fila | E3: Suma de TM en Stock | F3: Suma de Costo Ventas | G3: Suma de Gasto Ventas | H3: Suma de Gasto ADM | I3: Suma de Gasto Fin | J3: Suma de Depreciación
A4: =B4=D4 -> TRUE | B4: 10005721 | C4: POTA FILETE CONGELADO | D4: 10005721 | E4: 285.94 | F4: 610964.22 | G4: 59429.77 | H4: 11359.393 | I4: 22330.642 | J4: 17850.918
A5: =B5=D5 -> TRUE | B5: 10005779 | C5: POTA NUCAS CONGELADAS | D5: 10005779 | E5: 119.8 | F5: 210092.48 | G5: 24899.232 | H5: 4759.2337 | I5: 9355.847 | J5: 7478.9814
A6: =B6=D6 -> TRUE | B6: 10005781 | C6: POTA NUCAS FR ABIERTAS 0.3-0.5 BL10 S20 | D6: 10005781 | E6: 108.16 | F6: 200782.37 | G6: 22479.974 | H6: 4296.8173 | I6: 8446.8148 | J6: 6752.309
A7: =B7=D7 -> TRUE | B7: 10006719 | C7: POTA ALAS CONGELADAS | D7: 10006719 | E7: 8.1 | F7: 16489.482 | G7: 1683.504 | H7: 321.78458 | I7: 632.57396 | J7: 505.67403
A8: =B8=D8 -> TRUE | B8: 10006720 | C8: POTA ALAS CONGELADAS FR C/P C/C 0.5-1 BL10 S20 | D8: 10006720 | E8: 0 | F8: 0 | G8: 0 | H8: 0 | I8: 0 | J8: 0
A9: =B9=D9 -> TRUE | B9: 10007050 | C9: POTA REJOS COCIDOS | D9: 10007050 | E9: 80.905 | F9: 127069.1 | G9: 16815.295 | H9: 3214.0718 | I9: 6318.3206 | J9: 5050.8096
A10: =B10=D10 -> TRUE | B10: 10007162 | C10: POTA REJOS CONGELADOS | D10: 10007162 | E10: 27.28 | F10: 51345.857 | G10: 5669.8752 | H10: 1083.7387 | I10: 2130.4466 | J10: 1703.0602
A11: =B11=D11 -> TRUE | B11: 10007567 | C11: POTA REPRODUCTORES | D11: 10007567 | E11: 65.68 | F11: 119619.06 | G11: 13650.931 | H11: 2609.236 | I11: 5129.3158 | J11: 4100.3297
A12: =B12=D12 -> TRUE | B12: 10007969 | C12: POTA CONOS | D12: 10007969 | E12: 15.56 | F12: 23257.211 | G12: 3233.9904 | H12: 618.14421 | I12: 1215.1668 | J12: 971.39357
A13: =B13=D13 -> TRUE | B13: 10009207 | C13: POTA LABIOS FR S/COD BL10 S20 | D13: 10009207 | E13: 0.38 | F13: 587.31873 | G13: 78.9792 | H13: 15.096067 | I13: 29.676309 | J13: 23.722979
A14: =B14=D14 -> TRUE | B14: 10009239 | C14: POTA FILETE DARUMA | D14: 10009239 | E14: 50.26 | F14: 172978.92 | G14: 10446.038 | H14: 1996.6535 | I14: 3925.0824 | J14: 3137.6762
A15: =B15=D15 -> TRUE | B15: 10009334 | C15: POTA ALAS COCIDAS | D15: 10009334 | E15: 1.352 | F15: 4083.1401 | G15: 280.99968 | H15: 53.710216 | I15: 105.58519 | J15: 84.403863
A16: =B16=D16 -> TRUE | B16: 10009386 | C16: VENTOSAS | D16: 10009386 | E16: 14.52 | F16: 27351.706 | G16: 3017.8368 | H16: 576.82866 | I16: 1133.9474 | J16: 906.46752
C17: OTROS | D17: (en blanco) | E17: 0 | F17: 0 | G17: 0 | H17: 0 | I17: 0 | J17: 0
D18: Total general | E18: 777.937 | F18: 1564620.9 | G18: 161686.43 | H18: 30904.708 | I18: 60753.419 | J18: 48565.746

Sheet Stock Libre
A1: PRODUCTO | B1: TOTAL STOCK | C1: 18-05-2026 LOTE 090 | D1: 21/05/2026 LOTE 091 | E1: 22/05/2026 LOTE 092 | J1: RESUMEN SEMANA | K1: EMBARQUE | L1: EMBARQUE | M1: EMBARQUE Y REPROCESO | N1: TOTAL STOCK | O1: POR EMBARCAR | P1: STOCK LIBRE | R1: CÓDIGO | S1: CU X TM | T1: % MP | U1: incremento MP | V1: TM en Stock | W1: Costo Ventas | X1: Gasto Ventas | Y1: Gasto ADM | Z1: Gasto Fin | AA1: Depreciación | AB1: Utilidad Neta | AC1: Margen Neto | AD1: Venta Equilibrio | AE1: Precio Equilibrio x TM
A2: POTA ALAS FR C/P C/C (B) S/COD BL10 S20 | B2: 19780 | C2: 100 | E2: 20 | J2: =+C2+D2+E2+F2+G2+H2+I2 -> 120 | K2: 1880 | N2: =+J2+B2-K2-L2-M2 -> 18020 | O2: =6000+4000 -> 10000 | P2: =+N2-O2 -> 8020 | R2: 10006719 | S2: =IFERROR(INDEX([1]Resumen!$K$3:$K$63,MATCH(R2,[1]Resumen!$C$3:$C$63,0)),0)*(1+T2*U2)/1000 -> 2.0357386 | T2: 0.71 | U2: 0 | V2: =IF(P2<0,0,P2)/1000 -> 8.02 | W2: =IFERROR(S2*V2,0)*1000 -> 16326.623 | X2: =207.84*V2 -> 1666.8768 | Y2: =$Y$61/1978*V2 -> 318.60646 | Z2: =$Z$61/1978*V2 -> 626.32632 | AA2: =$AA$61/1978*V2 -> 500.67972 | AB2: 0 | AC2: 0 | AD2: =W2+X2+Y2+Z2 -> 18938.433 | AE2: =IFERROR(AD2/V2,0) -> 2361.4006
A3: POTA ALAS FR C/P C/C <0.5 BL10 S20 | B3: 22500 | C3: 60 | E3: 20 | J3: =+C3+D3+E3+F3+G3+H3+I3 -> 80 | N3: =+J3+B3-K3-L3-M3 -> 22580 | O3: 22500 | P3: =+N3-O3 -> 80 | R3: 10006719 | S3: =IFERROR(INDEX([1]Resumen!$K$3:$K$63,MATCH(R3,[1]Resumen!$C$3:$C$63,0)),0)*(1+T3*U3)/1000 -> 2.0357386 | T3: 0.71 | U3: 0 | V3: =IF(P3<0,0,P3)/1000 -> 0.08 | W3: =IFERROR(S3*V3,0)*1000 -> 162.85909 | X3: =207.84*V3 -> 16.6272 | Y3: =$Y$61/1978*V3 -> 3.1781193 | Z3: =$Z$61/1978*V3 -> 6.2476441 | AA3: =$AA$61/1978*V3 -> 4.9943114 | AB3: 0 | AC3: 0 | AD3: =W3+X3+Y3+Z3 -> 188.91205 | AE3: =IFERROR(AD3/V3,0) -> 2361.4006
A4: POTA ALAS FR C/P C/C 0.5-1 BL10 S20 | B4: 236420 | C4: 1220 | E4: 1540 | J4: =+C4+D4+E4+F4+G4+H4+I4 -> 2760 | N4: =+J4+B4-K4-L4-M4 -> 239180 | O4: =54000+216000-4000-4000 -> 262000 | P4: =+N4-O4 -> -22820 | R4: 10006719 | S4: =IFERROR(INDEX([1]Resumen!$K$3:$K$63,MATCH(R4,[1]Resumen!$C$3:$C$63,0)),0)*(1+T4*U4)/1000 -> 2.0357386 | T4: 0.71 | U4: 0 | V4: =IF(P4<0,0,P4)/1000 -> 0 | W4: =IFERROR(S4*V4,0)*1000 -> 0 | X4: =207.84*V4 -> 0 | Y4: =$Y$61/1978*V4 -> 0 | Z4: =$Z$61/1978*V4 -> 0 | AA4: =$AA$61/1978*V4 -> 0 | AB4: 0 | AC4: 0 | AD4: =W4+X4+Y4+Z4 -> 0 | AE4: =IFERROR(AD4/V4,0) -> 0
A5: POTA ALAS FR C/P C/C 0.3 - 0.5 BL10 S20 | B5: 0 | J5: =+C5+D5+E5+F5+G5+H5+I5 -> 0 | N5: =+J5+B5-K5-L5-M5 -> 0 | P5: =+N5-O5 -> 0 | R5: 10006719 | S5: =IFERROR(INDEX([1]Resumen!$K$3:$K$63,MATCH(R5,[1]Resumen!$C$3:$C$63,0)),0)*(1+T5*U5)/1000 -> 2.0357386 | T5: 0.71 | U5: 0 | V5: =IF(P5<0,0,P5)/1000 -> 0 | W5: =IFERROR(S5*V5,0)*1000 -> 0 | X5: =207.84*V5 -> 0 | Y5: =$Y$61/1978*V5 -> 0 | Z5: =$Z$61/1978*V5 -> 0 | AA5: =$AA$61/1978*V5 -> 0 | AB5: 0 | AC5: 0 | AD5: =W5+X5+Y5+Z5 -> 0 | AE5: =IFERROR(AD5/V5,0) -> 0
A6: POTA ALAS FR C/P C/C 1-2 BL10 S20 | B6: 320 | E6: 160 | J6: =+C6+D6+E6+F6+G6+H6+I6 -> 160 | N6: =+J6+B6-K6-L6-M6 -> 480 | O6: =+N6 -> 480 | P6: =+N6-O6 -> 0 | R6: 10006720 | S6: =IFERROR(INDEX([1]Resumen!$K$3:$K$63,MATCH(R6,[1]Resumen!$C$3:$C$63,0)),0)*(1+T6*U6)/1000 -> 1.5292757 | T6: 0.71 | U6: 0 | V6: =IF(P6<0,0,P6)/1000 -> 0 | W6: =IFERROR(S6*V6,0)*1000 -> 0 | X6: =207.84*V6 -> 0 | Y6: =$Y$61/1978*V6 -> 0 | Z6: =$Z$61/1978*V6 -> 0 | AA6: =$AA$61/1978*V6 -> 0 | AB6: 0 | AC6: 0 | AD6: =W6+X6+Y6+Z6 -> 0 | AE6: =IFERROR(AD6/V6,0) -> 0
A7: POTA ALAS FR C/P C/C 1-2 BL10 S20 ENTERA | B7: 102020 | C7: 2440 | E7: 2860 | J7: =+C7+D7+E7+F7+G7+H7+I7 -> 5300 | L7: =54000+27000 -> 81000 | N7: =+J7+B7-K7-L7-M7 -> 26320 | O7: =27000+72000-O6-27000 -> 71520 | P7: =+N7-O7 -> -45200 | R7: 10006720 | S7: =IFERROR(INDEX([1]Resumen!$K$3:$K$63,MATCH(R7,[1]Resumen!$C$3:$C$63,0)),0)*(1+T7*U7)/1000 -> 1.5292757 | T7: 0.71 | U7: 0 | V7: =IF(P7<0,0,P7)/1000 -> 0 | W7: =IFERROR(S7*V7,0)*1000 -> 0 | X7: =207.84*V7 -> 0 | Y7: =$Y$61/1978*V7 -> 0 | Z7: =$Z$61/1978*V7 -> 0 | AA7: =$AA$61/1978*V7 -> 0 | AB7: 0 | AC7: 0 | AD7: =W7+X7+Y7+Z7 -> 0 | AE7: =IFERROR(AD7/V7,0) -> 0
A8: POTA ALAS FR C/P C/C 2up | B8: 120 | J8: =+C8+D8+E8+F8+G8+H8+I8 -> 0 | N8: =+J8+B8-K8-L8-M8 -> 120 | P8: =+N8-O8-120 -> 0 | R8: 10006720 | S8: =IFERROR(INDEX([1]Resumen!$K$3:$K$63,MATCH(R8,[1]Resumen!$C$3:$C$63,0)),0)*(1+T8*U8)/1000 -> 1.5292757 | T8: 0.71 | U8: 0 | V8: =IF(P8<0,0,P8)/1000 -> 0 | W8: =IFERROR(S8*V8,0)*1000 -> 0 | X8: =207.84*V8 -> 0 | Y8: =$Y$61/1978*V8 -> 0 | Z8: =$Z$61/1978*V8 -> 0 | AA8: =$AA$61/1978*V8 -> 0 | AB8: 0 | AC8: 0 | AD8: =W8+X8+Y8+Z8 -> 0 | AE8: =IFERROR(AD8/V8,0) -> 0
A9: POTA LABIOS FR S/COD BL10 S20 | B9: 49740 | C9: 640 | D9: 120 | E9: 120 | J9: =+C9+D9+E9+F9+G9+H9+I9 -> 880 | K9: 24400 | N9: =+J9+B9-K9-L9-M9 -> 26220 | O9: 26000 | P9: =+N9-O9+160 -> 380 | R9: 10009207 | S9: =IFERROR(INDEX([1]Resumen!$K$3:$K$63,MATCH(R9,[1]Resumen!$C$3:$C$63,0)),0)*(1+T9*U9)/1000 -> 1.5455756 | T9: 0.71 | U9: 0 | V9: =IF(P9<0,0,P9)/1000 -> 0.38 | W9: =IFERROR(S9*V9,0)*1000 -> 587.31873 | X9: =207.84*V9 -> 78.9792 | Y9: =$Y$61/1978*V9 -> 15.096067 | Z9: =$Z$61/1978*V9 -> 29.676309 | AA9: =$AA$61/1978*V9 -> 23.722979 | AB9: 0 | AC9: 0 | AD9: =W9+X9+Y9+Z9 -> 711.07031 | AE9: =IFERROR(AD9/V9,0) -> 1871.2376
A10: POTA CONOS | B10: 35660 | C10: 2040 | D10: 1380 | E10: 480 | J10: =+C10+D10+E10+F10+G10+H10+I10 -> 3900 | N10: =+J10+B10-K10-L10-M10 -> 39560 | O10: 24000 | P10: =+N10-O10 -> 15560 | R10: 10007969 | S10: =IFERROR(INDEX([1]Resumen!$K$3:$K$63,MATCH(R10,[1]Resumen!$C$3:$C$63,0)),0)*(1+T10*U10)/1000 -> 1.4946794 | T10: 0.71 | U10: 0 | V10: =IF(P10<0,0,P10)/1000 -> 15.56 | W10: =IFERROR(S10*V10,0)*1000 -> 23257.211 | X10: =207.84*V10 -> 3233.9904 | Y10: =$Y$61/1978*V10 -> 618.14421 | Z10: =$Z$61/1978*V10 -> 1215.1668 | AA10: =$AA$61/1978*V10 -> 971.39357 | AB10: 0 | AC10: 0 | AD10: =W10+X10+Y10+Z10 -> 28324.513 | AE10: =IFERROR(AD10/V10,0) -> 1820.3414
A11: POTA ENTERA < 1KG | B11: 0 | J11: =+C11+D11+E11+F11+G11+H11+I11 -> 0 | N11: =+J11+B11-K11-L11-M11 -> 0 | P11: =+N11-O11 -> 0 | S11: =IFERROR(INDEX([1]Resumen!$K$3:$K$63,MATCH(R11,[1]Resumen!$C$3:$C$63,0)),0)*(1+T11*U11)/1000 -> 0 | U11: 0 | V11: =IF(P11<0,0,P11)/1000 -> 0 | W11: =IFERROR(S11*V11,0)*1000 -> 0 | X11: =207.84*V11 -> 0 | Y11: =$Y$61/1978*V11 -> 0 | Z11: =$Z$61/1978*V11 -> 0 | AA11: =$AA$61/1978*V11 -> 0 | AB11: 0 | AC11: 0 | AD11: =W11+X11+Y11+Z11 -> 0 | AE11: =IFERROR(AD11/V11,0) -> 0
A12: TUBO ALETA 0.1-0.5 KG | B12: 0 | J12: =+C12+D12+E12+F12+G12+H12+I12 -> 0 | N12: =+J12+B12-K12-L12-M12 -> 0 | P12: =+N12-O12 -> 0 | S12: =IFERROR(INDEX([1]Resumen!$K$3:$K$63,MATCH(R12,[1]Resumen!$C$3:$C$63,0)),0)*(1+T12*U12)/1000 -> 0 | U12: 0 | V12: =IF(P12<0,0,P12)/1000 -> 0 | W12: =IFERROR(S12*V12,0)*1000 -> 0 | X12: =207.84*V12 -> 0 | Y12: =$Y$61/1978*V12 -> 0 | Z12: =$Z$61/1978*V12 -> 0 | AA12: =$AA$61/1978*V12 -> 0 | AB12: 0 | AC12: 0 | AD12: =W12+X12+Y12+Z12 -> 0 | AE12: =IFERROR(AD12/V12,0) -> 0
A13: TUBO ALETA 0.5-1.0 KG | B13: 0 | J13: =+C13+D13+E13+F13+G13+H13+I13 -> 0 | N13: =+J13+B13-K13-L13-M13 -> 0 | P13: =+N13-O13 -> 0 | S13: =IFERROR(INDEX([1]Resumen!$K$3:$K$63,MATCH(R13,[1]Resumen!$C$3:$C$63,0)),0)*(1+T13*U13)/1000 -> 0 | U13: 0 | V13: =IF(P13<0,0,P13)/1000 -> 0 | W13: =IFERROR(S13*V13,0)*1000 -> 0 | X13: =207.84*V13 -> 0 | Y13: =$Y$61/1978*V13 -> 0 | Z13: =$Z$61/1978*V13 -> 0 | AA13: =$AA$61/1978*V13 -> 0 | AB13: 0 | AC13: 0 | AD13: =W13+X13+Y13+Z13 -> 0 | AE13: =IFERROR(AD13/V13,0) -> 0
A14: TUBO ALETA 1.0-1.5 kg | B14: 0 | J14: =+C14+D14+E14+F14+G14+H14+I14 -> 0 | N14: =+J14+B14-K14-L14-M14 -> 0 | P14: =+N14-O14 -> 0 | S14: =IFERROR(INDEX([1]Resumen!$K$3:$K$63,MATCH(R14,[1]Resumen!$C$3:$C$63,0)),0)*(1+T14*U14)/1000 -> 0 | U14: 0 | V14: =IF(P14<0,0,P14)/1000 -> 0 | W14: =IFERROR(S14*V14,0)*1000 -> 0 | X14: =207.84*V14 -> 0 | Y14: =$Y$61/1978*V14 -> 0 | Z14: =$Z$61/1978*V14 -> 0 | AA14: =$AA$61/1978*V14 -> 0 | AB14: 0 | AC14: 0 | AD14: =W14+X14+Y14+Z14 -> 0 | AE14: =IFERROR(AD14/V14,0) -> 0
A15: TUBO ALETA 1.0-2.0 KG | B15: 0 | J15: =+C15+D15+E15+F15+G15+H15+I15 -> 0 | N15: =+J15+B15-K15-L15-M15 -> 0 | P15: =+N15-O15 -> 0 | S15: =IFERROR(INDEX([1]Resumen!$K$3:$K$63,MATCH(R15,[1]Resumen!$C$3:$C$63,0)),0)*(1+T15*U15)/1000 -> 0 | U15: 0 | V15: =IF(P15<0,0,P15)/1000 -> 0 | W15: =IFERROR(S15*V15,0)*1000 -> 0 | X15: =207.84*V15 -> 0 | Y15: =$Y$61/1978*V15 -> 0 | Z15: =$Z$61/1978*V15 -> 0 | AA15: =$AA$61/1978*V15 -> 0 | AB15: 0 | AC15: 0 | AD15: =W15+X15+Y15+Z15 -> 0 | AE15: =IFERROR(AD15/V15,0) -> 0
