Workbook

Sheet RESUMEN AL 1-6-2026
C2: PERU FROST
C3: AVANCE COMERCIAL AL 25-5-2026
F5: RENTABILIDAD DEL INVENTARIO | T5: 46174 | W5: POR DEFINIR | Z5: TOTAL PROYECTADO | AN5: UNITARIOS POR TM
B6: Código | C6: Producto | D6: TM en Stock Libre | E6: CU | F6: Costo Ventas | G6: Gasto Ventas | H6: Gasto ADM | I6: Gasto Fin | J6: Depreciación | K6: Utilidad Neta | L6: Margen Neto | M6: Venta Equilibrio | N6: Precio Equilibrio x TM | O6: Precio | P6: Venta total | Q6: Utilidad | R6: Mg Neto | T6: TM | U6: Venta | V6: Precio x TM | W6: TM | X6: Venta | Y6: Precio x TM | Z6: TM | AA6: Venta | AB6: Precio x TM | AC6: Costo Ventas | AD6: Gasto Ventas | AE6: Gasto Adm | AF6: Gasto Fin | AG6: Depreciación | AH6: Drawback | AI6: Utilidad | AJ6: Mg Neto % | AK6: EBITDA | AL6: MG EBITDA | AN6: Precio x TM | AO6: Costo Ventas | AP6: Gasto Ventas | AQ6: Gasto Adm | AR6: Gasto Fin Corto | AS6: Depreciación | AT6: Drawback | AU6: Utilidad Neta | AV6: EBITDA
B7: 10005721 | C7: POTA FILETE CONGELADO | D7: =TD!E4 -> 302.5 | E7: =IFERROR(F7/D7,0) -> 2116.1126 | F7: =TD!F4 -> 640124.06 | G7: =TD!G4 -> 62871.6 | H7: =TD!H4 -> 15846.765 | I7: =TD!I4 -> 31152.055 | J7: =TD!J4 -> 24902.677 | K7: 0 | L7: 0 | M7: =F7+G7+H7+I7 -> 749994.48 | N7: =IFERROR(M7/D7,0) -> 2479.3206 | P7: =O7*D7 -> 0 | Q7: =P7-M7 -> -749994.48 | R7: =IFERROR(Q7/P7,0) -> 0 | T7: {=SUM([2]Hoja2!$J$6:$J$14*([2]Hoja2!$L$6:$L$14=$C7)*([2]Hoja2!$G$6:$G$14=T$5))} -> 0 | U7: {=SUM([2]Hoja2!$K$6:$K$14*([2]Hoja2!$L$6:$L$14=$C7)*([2]Hoja2!$G$6:$G$14=T$5))} -> 0 | V7: =IFERROR(U7/T7,0) -> 0 | W7: {=SUM([2]Hoja2!$J$6:$J$14*([2]Hoja2!$L$6:$L$14=$C7)*([2]Hoja2!$G$6:$G$14=W$5))} -> 119 | X7: {=SUM([2]Hoja2!$K$6:$K$14*([2]Hoja2!$L$6:$L$14=$C7)*([2]Hoja2!$G$6:$G$14=W$5))} -> 249620 | Y7: =IFERROR(X7/W7,0) -> 2097.6471 | Z7: =T7+W7 -> 119 | AA7: =U7+X7 -> 249620 | AB7: =IFERROR(AA7/Z7,0) -> 2097.6471 | AC7: =-IFERROR(F7/D7*Z7,0) -> -251817.4 | AD7: =-207.84*Z7 -> -24732.96 | AE7: =$AE$21/$Z$21*$Z7 -> -5878.2658 | AF7: =$AF$21/$Z$21*$Z7 -> -11555.675 | AG7: =$AG$21/$Z$21*$Z7 -> -9237.5041 | AH7: =(AA7-Z7*$AE$25)*0.03 -> 7080.9859 | AI7: =AA7+SUM(AC7:AF7,AH7) -> -37283.314 | AJ7: =IFERROR(AI7/AA7,0) -> -0.14936028 | AK7: =AA7+AC7+AD7+AE7+AH7-AG7 -> -16490.135 | AL7: =IFERROR(AK7/AA7,0) -> -0.066060953 | AN7: =AB7 -> 2097.6471 | AO7: =IFERROR(AC7/$Z7,0) -> -2116.1126 | AP7: =IFERROR(AD7/$Z7,0) -> -207.84 | AQ7: =IFERROR(AE7/$Z7,0) -> -49.397192 | AR7: =IFERROR(AF7/$Z7,0) -> -97.106509 | AS7: =IFERROR(AG7/$Z7,0) -> -77.626085 | AT7: =IFERROR(AH7/$Z7,0) -> 59.504083 | AU7: =IFERROR(AI7/$Z7,0) -> -313.30516 | AV7: =IFERROR(AK7/$Z7,0) -> -138.57256
B8: 10005779 | C8: POTA NUCAS CONGELADAS | D8: =TD!E5 -> 120.7 | E8: =IFERROR(F8/D8,0) -> 1726.7388 | F8: =TD!F5 -> 208417.37 | G8: =TD!G5 -> 25086.288 | H8: =TD!H5 -> 6322.9902 | I8: =TD!I5 -> 12429.927 | J8: =TD!J5 -> 9936.374 | K8: 0 | L8: 0 | M8: =F8+G8+H8+I8 -> 252256.58 | N8: =IFERROR(M8/D8,0) -> 2089.9468 | P8: =O8*D8 -> 0 | Q8: =P8-M8 -> -252256.58 | R8: =IFERROR(Q8/P8,0) -> 0 | T8: {=SUM([2]Hoja2!$J$6:$J$14*([2]Hoja2!$L$6:$L$14=$C8)*([2]Hoja2!$G$6:$G$14=T$5))} -> 0 | U8: {=SUM([2]Hoja2!$K$6:$K$14*([2]Hoja2!$L$6:$L$14=$C8)*([2]Hoja2!$G$6:$G$14=T$5))} -> 0 | V8: =IFERROR(U8/T8,0) -> 0 | W8: {=SUM([2]Hoja2!$J$6:$J$14*([2]Hoja2!$L$6:$L$14=$C8)*([2]Hoja2!$G$6:$G$14=W$5))} -> 140 | X8: {=SUM([2]Hoja2!$K$6:$K$14*([2]Hoja2!$L$6:$L$14=$C8)*([2]Hoja2!$G$6:$G$14=W$5))} -> 186120 | Y8: =IFERROR(X8/W8,0) -> 1329.4286 | Z8: =T8+W8 -> 140 | AA8: =U8+X8 -> 186120 | AB8: =IFERROR(AA8/Z8,0) -> 1329.4286 | AC8: =-IFERROR(F8/D8*Z8,0) -> -241743.43 | AD8: =-207.84*Z8 -> -29097.6 | AE8: =$AE$21/$Z$21*$Z8 -> -6915.6068 | AF8: =$AF$21/$Z$21*$Z8 -> -13594.911 | AG8: =$AG$21/$Z$21*$Z8 -> -10867.652 | AH8: =(AA8-Z8*$AE$25)*0.03 -> 5104.054 | AI8: =AA8+SUM(AC8:AF8,AH8) -> -100127.49 | AJ8: =IFERROR(AI8/AA8,0) -> -0.53797277 | AK8: =AA8+AC8+AD8+AE8+AH8-AG8 -> -75664.93 | AL8: =IFERROR(AK8/AA8,0) -> -0.40653841 | AN8: =AB8 -> 1329.4286 | AO8: =IFERROR(AC8/$Z8,0) -> -1726.7388 | AP8: =IFERROR(AD8/$Z8,0) -> -207.84 | AQ8: =IFERROR(AE8/$Z8,0) -> -49.397192 | AR8: =IFERROR(AF8/$Z8,0) -> -97.106509 | AS8: =IFERROR(AG8/$Z8,0) -> -77.626085 | AT8: =IFERROR(AH8/$Z8,0) -> 36.457529 | AU8: =IFERROR(AI8/$Z8,0) -> -715.19638 | AV8: =IFERROR(AK8/$Z8,0) -> -540.46378
B9: 10005781 | C9: POTA NUCAS FR ABIERTAS 0.3-0.5 BL10 S20 | D9: =TD!E6 -> 78.94 | E9: =IFERROR(F9/D9,0) -> 1830.8508 | F9: =TD!F6 -> 144527.36 | G9: =TD!G6 -> 16406.89 | H9: =TD!H6 -> 4135.3508 | I9: =TD!I6 -> 8129.3991 | J9: =TD!J6 -> 6498.5697 | K9: 0 | L9: 0 | M9: =F9+G9+H9+I9 -> 173199 | N9: =IFERROR(M9/D9,0) -> 2194.0588 | P9: =O9*D9 -> 0 | Q9: =P9-M9 -> -173199 | R9: =IFERROR(Q9/P9,0) -> 0 | T9: {=SUM([2]Hoja2!$J$6:$J$14*([2]Hoja2!$L$6:$L$14=$C9)*([2]Hoja2!$G$6:$G$14=T$5))} -> 0 | U9: {=SUM([2]Hoja2!$K$6:$K$14*([2]Hoja2!$L$6:$L$14=$C9)*([2]Hoja2!$G$6:$G$14=T$5))} -> 0 | V9: =IFERROR(U9/T9,0) -> 0 | W9: {=SUM([2]Hoja2!$J$6:$J$14*([2]Hoja2!$L$6:$L$14=$C9)*([2]Hoja2!$G$6:$G$14=W$5))} -> 0 | X9: {=SUM([2]Hoja2!$K$6:$K$14*([2]Hoja2!$L$6:$L$14=$C9)*([2]Hoja2!$G$6:$G$14=W$5))} -> 0 | Y9: =IFERROR(X9/W9,0) -> 0 | Z9: =T9+W9 -> 0 | AA9: =U9+X9 -> 0 | AB9: =IFERROR(AA9/Z9,0) -> 0 | AC9: =-IFERROR(F9/D9*Z9,0) -> 0 | AD9: =-207.84*Z9 -> 0 | AE9: =$AE$21/$Z$21*$Z9 -> 0 | AF9: =$AF$21/$Z$21*$Z9 -> 0 | AG9: =$AG$21/$Z$21*$Z9 -> 0 | AH9: =(AA9-Z9*$AE$25)*0.03 -> 0 | AI9: =AA9+SUM(AC9:AF9,AH9) -> 0 | AJ9: =IFERROR(AI9/AA9,0) -> 0 | AK9: =AA9+AC9+AD9+AE9+AH9-AG9 -> 0 | AL9: =IFERROR(AK9/AA9,0) -> 0 | AN9: =AB9 -> 0 | AO9: =IFERROR(AC9/$Z9,0) -> 0 | AP9: =IFERROR(AD9/$Z9,0) -> 0 | AQ9: =IFERROR(AE9/$Z9,0) -> 0 | AR9: =IFERROR(AF9/$Z9,0) -> 0 | AS9: =IFERROR(AG9/$Z9,0) -> 0 | AT9: =IFERROR(AH9/$Z9,0) -> 0 | AU9: =IFERROR(AI9/$Z9,0) -> 0 | AV9: =IFERROR(AK9/$Z9,0) -> 0
B10: 10006719 | C10: POTA ALAS CONGELADAS | D10: =TD!E7 -> 8.3 | E10: =IFERROR(F10/D10,0) -> 2015.4661 | F10: =TD!F7 -> 16728.369 | G10: =TD!G7 -> 1725.072 | H10: =TD!H7 -> 434.8038 | I10: =TD!I7 -> 854.7506 | J10: =TD!J7 -> 683.28007 | K10: 0 | L10: 0 | M10: =F10+G10+H10+I10 -> 19742.995 | N10: =IFERROR(M10/D10,0) -> 2378.6741 | P10: =O10*D10 -> 0 | Q10: =P10-M10 -> -19742.995 | R10: =IFERROR(Q10/P10,0) -> 0 | T10: {=SUM([2]Hoja2!$J$6:$J$14*([2]Hoja2!$L$6:$L$14=$C10)*([2]Hoja2!$G$6:$G$14=T$5))} -> 0 | U10: {=SUM([2]Hoja2!$K$6:$K$14*([2]Hoja2!$L$6:$L$14=$C10)*([2]Hoja2!$G$6:$G$14=T$5))} -> 0 | V10: =IFERROR(U10/T10,0) -> 0 | W10: {=SUM([2]Hoja2!$J$6:$J$14*([2]Hoja2!$L$6:$L$14=$C10)*([2]Hoja2!$G$6:$G$14=W$5))} -> 72 | X10: {=SUM([2]Hoja2!$K$6:$K$14*([2]Hoja2!$L$6:$L$14=$C10)*([2]Hoja2!$G$6:$G$14=W$5))} -> 151200 | Y10: =IFERROR(X10/W10,0) -> 2100 | Z10: =T10+W10 -> 72 | AA10: =U10+X10 -> 151200 | AB10: =IFERROR(AA10/Z10,0) -> 2100 | AC10: =-IFERROR(F10/D10*Z10,0) -> -145113.56 | AD10: =-207.84*Z10 -> -14964.48 | AE10: =$AE$21/$Z$21*$Z10 -> -3556.5978 | AF10: =$AF$21/$Z$21*$Z10 -> -6991.6687 | AG10: =$AG$21/$Z$21*$Z10 -> -5589.0781 | AH10: =(AA10-Z10*$AE$25)*0.03 -> 4289.3764 | AI10: =AA10+SUM(AC10:AF10,AH10) -> -15136.932 | AJ10: =IFERROR(AI10/AA10,0) -> -0.10011198 | AK10: =AA10+AC10+AD10+AE10+AH10-AG10 -> -2556.1849 | AL10: =IFERROR(AK10/AA10,0) -> -0.016905985 | AN10: =AB10 -> 2100 | AO10: =IFERROR(AC10/$Z10,0) -> -2015.4661 | AP10: =IFERROR(AD10/$Z10,0) -> -207.84 | AQ10: =IFERROR(AE10/$Z10,0) -> -49.397192 | AR10: =IFERROR(AF10/$Z10,0) -> -97.106509 | AS10: =IFERROR(AG10/$Z10,0) -> -77.626085 | AT10: =IFERROR(AH10/$Z10,0) -> 59.574672 | AU10: =IFERROR(AI10/$Z10,0) -> -210.23516 | AV10: =IFERROR(AK10/$Z10,0) -> -35.502568
B11: 10006720 | C11: POTA ALAS CONGELADAS FR C/P C/C 0.5-1 BL10 S20 | D11: =TD!E8 -> 0.12 | E11: =IFERROR(F11/D11,0) -> 1501.1373 | F11: =TD!F8 -> 180.13648 | G11: =TD!G8 -> 24.9408 | H11: =TD!H8 -> 6.28632 | I11: =TD!I8 -> 12.35784 | J11: =TD!J8 -> 9.878748 | K11: 0 | L11: 0 | M11: =F11+G11+H11+I11 -> 223.72144 | N11: =IFERROR(M11/D11,0) -> 1864.3453 | P11: =O11*D11 -> 0 | Q11: =P11-M11 -> -223.72144 | R11: =IFERROR(Q11/P11,0) -> 0 | T11: {=SUM([2]Hoja2!$J$6:$J$14*([2]Hoja2!$L$6:$L$14=$C11)*([2]Hoja2!$G$6:$G$14=T$5))} -> 0 | U11: {=SUM([2]Hoja2!$K$6:$K$14*([2]Hoja2!$L$6:$L$14=$C11)*([2]Hoja2!$G$6:$G$14=T$5))} -> 0 | V11: =IFERROR(U11/T11,0) -> 0 | W11: {=SUM([2]Hoja2!$J$6:$J$14*([2]Hoja2!$L$6:$L$14=$C11)*([2]Hoja2!$G$6:$G$14=W$5))} -> 0 | X11: {=SUM([2]Hoja2!$K$6:$K$14*([2]Hoja2!$L$6:$L$14=$C11)*([2]Hoja2!$G$6:$G$14=W$5))} -> 0 | Y11: =IFERROR(X11/W11,0) -> 0 | Z11: =T11+W11 -> 0 | AA11: =U11+X11 -> 0 | AB11: =IFERROR(AA11/Z11,0) -> 0 | AC11: =-IFERROR(F11/D11*Z11,0) -> 0 | AD11: =-207.84*Z11 -> 0 | AE11: =$AE$21/$Z$21*$Z11 -> 0 | AF11: =$AF$21/$Z$21*$Z11 -> 0 | AG11: =$AG$21/$Z$21*$Z11 -> 0 | AH11: =(AA11-Z11*$AE$25)*0.03 -> 0 | AI11: =AA11+SUM(AC11:AF11,AH11) -> 0 | AJ11: =IFERROR(AI11/AA11,0) -> 0 | AK11: =AA11+AC11+AD11+AE11+AH11-AG11 -> 0 | AL11: =IFERROR(AK11/AA11,0) -> 0 | AN11: =AB11 -> 0 | AO11: =IFERROR(AC11/$Z11,0) -> 0 | AP11: =IFERROR(AD11/$Z11,0) -> 0 | AQ11: =IFERROR(AE11/$Z11,0) -> 0 | AR11: =IFERROR(AF11/$Z11,0) -> 0 | AS11: =IFERROR(AG11/$Z11,0) -> 0 | AT11: =IFERROR(AH11/$Z11,0) -> 0 | AU11: =IFERROR(AI11/$Z11,0) -> 0 | AV11: =IFERROR(AK11/$Z11,0) -> 0
B12: 10007050 | C12: POTA REJOS COCIDOS | D12: =TD!E9 -> 109.815 | E12: =IFERROR(F12/D12,0) -> 1542.069 | F12: =TD!F9 -> 169342.3 | G12: =TD!G9 -> 22823.95 | H12: =TD!H9 -> 5752.7686 | I12: =TD!I9 -> 11308.968 | J12: =TD!J9 -> 9040.2893 | K12: 0 | L12: 0 | M12: =F12+G12+H12+I12 -> 209227.99 | N12: =IFERROR(M12/D12,0) -> 1905.277 | P12: =O12*D12 -> 0 | Q12: =P12-M12 -> -209227.99 | R12: =IFERROR(Q12/P12,0) -> 0 | T12: {=SUM([2]Hoja2!$J$6:$J$14*([2]Hoja2!$L$6:$L$14=$C12)*([2]Hoja2!$G$6:$G$14=T$5))} -> 0 | U12: {=SUM([2]Hoja2!$K$6:$K$14*([2]Hoja2!$L$6:$L$14=$C12)*([2]Hoja2!$G$6:$G$14=T$5))} -> 0 | V12: =IFERROR(U12/T12,0) -> 0 | W12: {=SUM([2]Hoja2!$J$6:$J$14*([2]Hoja2!$L$6:$L$14=$C12)*([2]Hoja2!$G$6:$G$14=W$5))} -> 0 | X12: {=SUM([2]Hoja2!$K$6:$K$14*([2]Hoja2!$L$6:$L$14=$C12)*([2]Hoja2!$G$6:$G$14=W$5))} -> 0 | Y12: =IFERROR(X12/W12,0) -> 0 | Z12: =T12+W12 -> 0 | AA12: =U12+X12 -> 0 | AB12: =IFERROR(AA12/Z12,0) -> 0 | AC12: =-IFERROR(F12/D12*Z12,0) -> 0 | AD12: =-207.84*Z12 -> 0 | AE12: =$AE$21/$Z$21*$Z12 -> 0 | AF12: =$AF$21/$Z$21*$Z12 -> 0 | AG12: =$AG$21/$Z$21*$Z12 -> 0 | AH12: =(AA12-Z12*$AE$25)*0.03 -> 0 | AI12: =AA12+SUM(AC12:AF12,AH12) -> 0 | AJ12: =IFERROR(AI12/AA12,0) -> 0 | AK12: =AA12+AC12+AD12+AE12+AH12-AG12 -> 0 | AL12: =IFERROR(AK12/AA12,0) -> 0 | AN12: =AB12 -> 0 | AO12: =IFERROR(AC12/$Z12,0) -> 0 | AP12: =IFERROR(AD12/$Z12,0) -> 0 | AQ12: =IFERROR(AE12/$Z12,0) -> 0 | AR12: =IFERROR(AF12/$Z12,0) -> 0 | AS12: =IFERROR(AG12/$Z12,0) -> 0 | AT12: =IFERROR(AH12/$Z12,0) -> 0 | AU12: =IFERROR(AI12/$Z12,0) -> 0 | AV12: =IFERROR(AK12/$Z12,0) -> 0
B13: 10007162 | C13: POTA REJOS CONGELADOS | D13: =TD!E10 -> 19.24 | E13: =IFERROR(F13/D13,0) -> 1858.2869 | F13: =TD!F10 -> 35753.441 | G13: =TD!G10 -> 3998.8416 | H13: =TD!H10 -> 1007.9066 | I13: =TD!I10 -> 1981.3737 | J13: =TD!J10 -> 1583.8926 | K13: 0 | L13: 0 | M13: =F13+G13+H13+I13 -> 42741.563 | N13: =IFERROR(M13/D13,0) -> 2221.4949 | P13: =O13*D13 -> 0 | Q13: =P13-M13 -> -42741.563 | R13: =IFERROR(Q13/P13,0) -> 0 | T13: {=SUM([2]Hoja2!$J$6:$J$14*([2]Hoja2!$L$6:$L$14=$C13)*([2]Hoja2!$G$6:$G$14=T$5))} -> 0 | U13: {=SUM([2]Hoja2!$K$6:$K$14*([2]Hoja2!$L$6:$L$14=$C13)*([2]Hoja2!$G$6:$G$14=T$5))} -> 0 | V13: =IFERROR(U13/T13,0) -> 0 | W13: {=SUM([2]Hoja2!$J$6:$J$14*([2]Hoja2!$L$6:$L$14=$C13)*([2]Hoja2!$G$6:$G$14=W$5))} -> 159 | X13: {=SUM([2]Hoja2!$K$6:$K$14*([2]Hoja2!$L$6:$L$14=$C13)*([2]Hoja2!$G$6:$G$14=W$5))} -> 452550 | Y13: =IFERROR(X13/W13,0) -> 2846.2264 | Z13: =T13+W13 -> 159 | AA13: =U13+X13 -> 452550 | AB13: =IFERROR(AA13/Z13,0) -> 2846.2264 | AC13: =-IFERROR(F13/D13*Z13,0) -> -295467.62 | AD13: =-207.84*Z13 -> -33046.56 | AE13: =$AE$21/$Z$21*$Z13 -> -7854.1535 | AF13: =$AF$21/$Z$21*$Z13 -> -15439.935 | AG13: =$AG$21/$Z$21*$Z13 -> -12342.547 | AH13: =(AA13-Z13*$AE$25)*0.03 -> 13031.873 | AI13: =AA13+SUM(AC13:AF13,AH13) -> 113773.6 | AJ13: =IFERROR(AI13/AA13,0) -> 0.25140559 | AK13: =AA13+AC13+AD13+AE13+AH13-AG13 -> 141556.08 | AL13: =IFERROR(AK13/AA13,0) -> 0.31279656 | AN13: =AB13 -> 2846.2264 | AO13: =IFERROR(AC13/$Z13,0) -> -1858.2869 | AP13: =IFERROR(AD13/$Z13,0) -> -207.84 | AQ13: =IFERROR(AE13/$Z13,0) -> -49.397192 | AR13: =IFERROR(AF13/$Z13,0) -> -97.106509 | AS13: =IFERROR(AG13/$Z13,0) -> -77.626085 | AT13: =IFERROR(AH13/$Z13,0) -> 81.961464 | AU13: =IFERROR(AI13/$Z13,0) -> 715.55724 | AV13: =IFERROR(AK13/$Z13,0) -> 890.28983
B14: 10007567 | C14: POTA REPRODUCTORES | D14: =TD!E11 -> 94.3 | E14: =IFERROR(F14/D14,0) -> 1796.4412 | F14: =TD!F11 -> 169404.4 | G14: =TD!G11 -> 19599.312 | H14: =TD!H11 -> 4939.9998 | I14: =TD!I11 -> 9711.2026 | J14: =TD!J11 -> 7763.0495 | K14: 0 | L14: 0 | M14: =F14+G14+H14+I14 -> 203654.92 | N14: =IFERROR(M14/D14,0) -> 2159.6492 | P14: =O14*D14 -> 0 | Q14: =P14-M14 -> -203654.92 | R14: =IFERROR(Q14/P14,0) -> 0 | T14: {=SUM([2]Hoja2!$J$6:$J$14*([2]Hoja2!$L$6:$L$14=$C14)*([2]Hoja2!$G$6:$G$14=T$5))} -> 0 | U14: {=SUM([2]Hoja2!$K$6:$K$14*([2]Hoja2!$L$6:$L$14=$C14)*([2]Hoja2!$G$6:$G$14=T$5))} -> 0 | V14: =IFERROR(U14/T14,0) -> 0 | W14: {=SUM([2]Hoja2!$J$6:$J$14*([2]Hoja2!$L$6:$L$14=$C14)*([2]Hoja2!$G$6:$G$14=W$5))} -> 0 | X14: {=SUM([2]Hoja2!$K$6:$K$14*([2]Hoja2!$L$6:$L$14=$C14)*([2]Hoja2!$G$6:$G$14=W$5))} -> 0 | Y14: =IFERROR(X14/W14,0) -> 0 | Z14: =T14+W14 -> 0 | AA14: =U14+X14 -> 0 | AB14: =IFERROR(AA14/Z14,0) -> 0 | AC14: =-IFERROR(F14/D14*Z14,0) -> 0 | AD14: =-207.84*Z14 -> 0 | AE14: =$AE$21/$Z$21*$Z14 -> 0 | AF14: =$AF$21/$Z$21*$Z14 -> 0 | AG14: =$AG$21/$Z$21*$Z14 -> 0 | AH14: =(AA14-Z14*$AE$25)*0.03 -> 0 | AI14: =AA14+SUM(AC14:AF14,AH14) -> 0 | AJ14: =IFERROR(AI14/AA14,0) -> 0 | AK14: =AA14+AC14+AD14+AE14+AH14-AG14 -> 0 | AL14: =IFERROR(AK14/AA14,0) -> 0 | AN14: =AB14 -> 0 | AO14: =IFERROR(AC14/$Z14,0) -> 0 | AP14: =IFERROR(AD14/$Z14,0) -> 0 | AQ14: =IFERROR(AE14/$Z14,0) -> 0 | AR14: =IFERROR(AF14/$Z14,0) -> 0 | AS14: =IFERROR(AG14/$Z14,0) -> 0 | AT14: =IFERROR(AH14/$Z14,0) -> 0 | AU14: =IFERROR(AI14/$Z14,0) -> 0 | AV14: =IFERROR(AK14/$Z14,0) -> 0
B15: 10007969 | C15: POTA CONOS | D15: =TD!E12 -> 17.54 | E15: =IFERROR(F15/D15,0) -> 1466.0036 | F15: =TD!F12 -> 25713.703 | G15: =TD!G12 -> 3645.5136 | H15: =TD!H12 -> 918.85044 | I15: =TD!I12 -> 1806.3043 | J15: =TD!J12 -> 1443.9437 | K15: 0 | L15: 0 | M15: =F15+G15+H15+I15 -> 32084.372 | N15: =IFERROR(M15/D15,0) -> 1829.2116 | P15: =O15*D15 -> 0 | Q15: =P15-M15 -> -32084.372 | R15: =IFERROR(Q15/P15,0) -> 0 | T15: {=SUM([2]Hoja2!$J$6:$J$14*([2]Hoja2!$L$6:$L$14=$C15)*([2]Hoja2!$G$6:$G$14=T$5))} -> 0 | U15: {=SUM([2]Hoja2!$K$6:$K$14*([2]Hoja2!$L$6:$L$14=$C15)*([2]Hoja2!$G$6:$G$14=T$5))} -> 0 | V15: =IFERROR(U15/T15,0) -> 0 | W15: {=SUM([2]Hoja2!$J$6:$J$14*([2]Hoja2!$L$6:$L$14=$C15)*([2]Hoja2!$G$6:$G$14=W$5))} -> 0 | X15: {=SUM([2]Hoja2!$K$6:$K$14*([2]Hoja2!$L$6:$L$14=$C15)*([2]Hoja2!$G$6:$G$14=W$5))} -> 0 | Y15: =IFERROR(X15/W15,0) -> 0 | Z15: =T15+W15 -> 0 | AA15: =U15+X15 -> 0 | AB15: =IFERROR(AA15/Z15,0) -> 0 | AC15: =-IFERROR(F15/D15*Z15,0) -> 0 | AD15: =-207.84*Z15 -> 0 | AE15: =$AE$21/$Z$21*$Z15 -> 0 | AF15: =$AF$21/$Z$21*$Z15 -> 0 | AG15: =$AG$21/$Z$21*$Z15 -> 0 | AH15: =(AA15-Z15*$AE$25)*0.03 -> 0 | AI15: =AA15+SUM(AC15:AF15,AH15) -> 0 | AJ15: =IFERROR(AI15/AA15,0) -> 0 | AK15: =AA15+AC15+AD15+AE15+AH15-AG15 -> 0 | AL15: =IFERROR(AK15/AA15,0) -> 0 | AN15: =AB15 -> 0 | AO15: =IFERROR(AC15/$Z15,0) -> 0 | AP15: =IFERROR(AD15/$Z15,0) -> 0 | AQ15: =IFERROR(AE15/$Z15,0) -> 0 | AR15: =IFERROR(AF15/$Z15,0) -> 0 | AS15: =IFERROR(AG15/$Z15,0) -> 0 | AT15: =IFERROR(AH15/$Z15,0) -> 0 | AU15: =IFERROR(AI15/$Z15,0) -> 0 | AV15: =IFERROR(AK15/$Z15,0) -> 0
B16: 10009207 | C16: POTA LABIOS FR S/COD BL10 S20 | D16: =TD!E13 -> 25.98 | E16: =IFERROR(F16/D16,0) -> 1517.6903 | F16: =TD!F13 -> 39429.595 | G16: =TD!G13 -> 5399.6832 | H16: =TD!H13 -> 1360.9883 | I16: =TD!I13 -> 2675.4724 | J16: =TD!J13 -> 2138.7489 | K16: 0 | L16: 0 | M16: =F16+G16+H16+I16 -> 48865.739 | N16: =IFERROR(M16/D16,0) -> 1880.8983 | P16: =O16*D16 -> 0 | Q16: =P16-M16 -> -48865.739 | R16: =IFERROR(Q16/P16,0) -> 0 | T16: {=SUM([2]Hoja2!$J$6:$J$14*([2]Hoja2!$L$6:$L$14=$C16)*([2]Hoja2!$G$6:$G$14=T$5))} -> 26 | U16: {=SUM([2]Hoja2!$K$6:$K$14*([2]Hoja2!$L$6:$L$14=$C16)*([2]Hoja2!$G$6:$G$14=T$5))} -> 36400 | V16: =IFERROR(U16/T16,0) -> 1400 | W16: {=SUM([2]Hoja2!$J$6:$J$14*([2]Hoja2!$L$6:$L$14=$C16)*([2]Hoja2!$G$6:$G$14=W$5))} -> 0 | X16: {=SUM([2]Hoja2!$K$6:$K$14*([2]Hoja2!$L$6:$L$14=$C16)*([2]Hoja2!$G$6:$G$14=W$5))} -> 0 | Y16: =IFERROR(X16/W16,0) -> 0 | Z16: =T16+W16 -> 26 | AA16: =U16+X16 -> 36400 | AB16: =IFERROR(AA16/Z16,0) -> 1400 | AC16: =-'Stock Libre'!T9*Z16*1000 -> -39459.949 | AD16: =-207.84*Z16 -> -5403.84 | AE16: =$AE$21/$Z$21*$Z16 -> -1284.327 | AF16: =$AF$21/$Z$21*$Z16 -> -2524.7692 | AG16: =$AG$21/$Z$21*$Z16 -> -2018.2782 | AH16: =(AA16-Z16*$AE$25)*0.03 -> 1002.9415 | AI16: =AA16+SUM(AC16:AF16,AH16) -> -11269.943 | AJ16: =IFERROR(AI16/AA16,0) -> -0.30961383 | AK16: =AA16+AC16+AD16+AE16+AH16-AG16 -> -6726.8958 | AL16: =IFERROR(AK16/AA16,0) -> -0.18480483 | AN16: =AB16 -> 1400 | AO16: =IFERROR(AC16/$Z16,0) -> -1517.6903 | AP16: =IFERROR(AD16/$Z16,0) -> -207.84 | AQ16: =IFERROR(AE16/$Z16,0) -> -49.397192 | AR16: =IFERROR(AF16/$Z16,0) -> -97.106509 | AS16: =IFERROR(AG16/$Z16,0) -> -77.626085 | AT16: =IFERROR(AH16/$Z16,0) -> 38.574672 | AU16: =IFERROR(AI16/$Z16,0) -> -433.45936 | AV16: =IFERROR(AK16/$Z16,0) -> -258.72676
B17: 10009239 | C17: POTA FILETE DARUMA | D17: =TD!E14 -> 0 | E17: =IFERROR(F17/D17,0) -> 0 | F17: =TD!F14 -> 0 | G17: =TD!G14 -> 0 | H17: =TD!H14 -> 0 | I17: =TD!I14 -> 0 | J17: =TD!J14 -> 0 | K17: 0 | L17: 0 | M17: =F17+G17+H17+I17 -> 0 | N17: =IFERROR(M17/D17,0) -> 0 | P17: =O17*D17 -> 0 | Q17: =P17-M17 -> 0 | R17: =IFERROR(Q17/P17,0) -> 0 | T17: {=SUM([2]Hoja2!$J$6:$J$14*([2]Hoja2!$L$6:$L$14=$C17)*([2]Hoja2!$G$6:$G$14=T$5))} -> 0 | U17: {=SUM([2]Hoja2!$K$6:$K$14*([2]Hoja2!$L$6:$L$14=$C17)*([2]Hoja2!$G$6:$G$14=T$5))} -> 0 | V17: =IFERROR(U17/T17,0) -> 0 | W17: {=SUM([2]Hoja2!$J$6:$J$14*([2]Hoja2!$L$6:$L$14=$C17)*([2]Hoja2!$G$6:$G$14=W$5))} -> 135 | X17: {=SUM([2]Hoja2!$K$6:$K$14*([2]Hoja2!$L$6:$L$14=$C17)*([2]Hoja2!$G$6:$G$14=W$5))} -> 526500 | Y17: =IFERROR(X17/W17,0) -> 3900 | Z17: =T17+W17 -> 135 | AA17: =U17+X17 -> 526500 | AB17: =IFERROR(AA17/Z17,0) -> 3900 | AC17: =-'Stock Libre'!T45*1000*Z17 -> -463313.56 | AD17: =-207.84*Z17 -> -28058.4 | AE17: =$AE$21/$Z$21*$Z17 -> -6668.6209 | AF17: =$AF$21/$Z$21*$Z17 -> -13109.379 | AG17: =$AG$21/$Z$21*$Z17 -> -10479.521 | AH17: =(AA17-Z17*$AE$25)*0.03 -> 15332.581 | AI17: =AA17+SUM(AC17:AF17,AH17) -> 30682.625 | AJ17: =IFERROR(AI17/AA17,0) -> 0.058276591 | AK17: =AA17+AC17+AD17+AE17+AH17-AG17 -> 54271.525 | AL17: =IFERROR(AK17/AA17,0) -> 0.10307982 | AN17: =AB17 -> 3900 | AO17: =IFERROR(AC17/$Z17,0) -> -3431.9523 | AP17: =IFERROR(AD17/$Z17,0) -> -207.84 | AQ17: =IFERROR(AE17/$Z17,0) -> -49.397192 | AR17: =IFERROR(AF17/$Z17,0) -> -97.106509 | AS17: =IFERROR(AG17/$Z17,0) -> -77.626085 | AT17: =IFERROR(AH17/$Z17,0) -> 113.57467 | AU17: =IFERROR(AI17/$Z17,0) -> 227.2787 | AV17: =IFERROR(AK17/$Z17,0) -> 402.0113
B18: 10009334 | C18: POTA ALAS COCIDAS | D18: =TD!E15 -> 0 | E18: =IFERROR(F18/D18,0) -> 0 | F18: =TD!F15 -> 0 | G18: =TD!G15 -> 0 | H18: =TD!H15 -> 0 | I18: =TD!I15 -> 0 | J18: =TD!J15 -> 0 | K18: 0 | L18: 0 | M18: =F18+G18+H18+I18 -> 0 | N18: =IFERROR(M18/D18,0) -> 0 | P18: =O18*D18 -> 0 | Q18: =P18-M18 -> 0 | R18: =IFERROR(Q18/P18,0) -> 0 | T18: {=SUM([2]Hoja2!$J$6:$J$14*([2]Hoja2!$L$6:$L$14=$C18)*([2]Hoja2!$G$6:$G$14=T$5))} -> 0 | U18: {=SUM([2]Hoja2!$K$6:$K$14*([2]Hoja2!$L$6:$L$14=$C18)*([2]Hoja2!$G$6:$G$14=T$5))} -> 0 | V18: =IFERROR(U18/T18,0) -> 0 | W18: {=SUM([2]Hoja2!$J$6:$J$14*([2]Hoja2!$L$6:$L$14=$C18)*([2]Hoja2!$G$6:$G$14=W$5))} -> 162 | X18: {=SUM([2]Hoja2!$K$6:$K$14*([2]Hoja2!$L$6:$L$14=$C18)*([2]Hoja2!$G$6:$G$14=W$5))} -> 677700 | Y18: =IFERROR(X18/W18,0) -> 4183.3333 | Z18: =T18+W18 -> 162 | AA18: =U18+X18 -> 677700 | AB18: =IFERROR(AA18/Z18,0) -> 4183.3333 | AC18: =-Z18*'Stock Libre'!T48*1000 -> -488123.44 | AD18: =-207.84*Z18 -> -33670.08 | AE18: =$AE$21/$Z$21*$Z18 -> -8002.345 | AF18: =$AF$21/$Z$21*$Z18 -> -15731.254 | AG18: =$AG$21/$Z$21*$Z18 -> -12575.426 | AH18: =(AA18-Z18*$AE$25)*0.03 -> 19776.097 | AI18: =AA18+SUM(AC18:AF18,AH18) -> 151948.98 | AJ18: =IFERROR(AI18/AA18,0) -> 0.22421275 | AK18: =AA18+AC18+AD18+AE18+AH18-AG18 -> 180255.66 | AL18: =IFERROR(AK18/AA18,0) -> 0.2659815 | AN18: =AB18 -> 4183.3333 | AO18: =IFERROR(AC18/$Z18,0) -> -3013.1076 | AP18: =IFERROR(AD18/$Z18,0) -> -207.84 | AQ18: =IFERROR(AE18/$Z18,0) -> -49.397192 | AR18: =IFERROR(AF18/$Z18,0) -> -97.106509 | AS18: =IFERROR(AG18/$Z18,0) -> -77.626085 | AT18: =IFERROR(AH18/$Z18,0) -> 122.07467 | AU18: =IFERROR(AI18/$Z18,0) -> 937.95667 | AV18: =IFERROR(AK18/$Z18,0) -> 1112.6893
B19: 10009386 | C19: VENTOSAS | D19: =TD!E16 -> 14.64 | E19: =IFERROR(F19/D19,0) -> 1859.8567 | F19: =TD!F16 -> 27228.302 | G19: =TD!G16 -> 3042.7776 | H19: =TD!H16 -> 766.93104 | I19: =TD!I16 -> 1507.6565 | J19: =TD!J16 -> 1205.2073 | K19: 0 | L19: 0 | M19: =F19+G19+H19+I19 -> 32545.668 | N19: =IFERROR(M19/D19,0) -> 2223.0647 | P19: =O19*D19 -> 0 | Q19: =P19-M19 -> -32545.668 | R19: =IFERROR(Q19/P19,0) -> 0 | T19: {=SUM([2]Hoja2!$J$6:$J$14*([2]Hoja2!$L$6:$L$14=$C19)*([2]Hoja2!$G$6:$G$14=T$5))} -> 0 | U19: {=SUM([2]Hoja2!$K$6:$K$14*([2]Hoja2!$L$6:$L$14=$C19)*([2]Hoja2!$G$6:$G$14=T$5))} -> 0 | V19: =IFERROR(U19/T19,0) -> 0 | W19: {=SUM([2]Hoja2!$J$6:$J$14*([2]Hoja2!$L$6:$L$14=$C19)*([2]Hoja2!$G$6:$G$14=W$5))} -> 27 | X19: {=SUM([2]Hoja2!$K$6:$K$14*([2]Hoja2!$L$6:$L$14=$C19)*([2]Hoja2!$G$6:$G$14=W$5))} -> 67500 | Y19: =IFERROR(X19/W19,0) -> 2500 | Z19: =T19+W19 -> 27 | AA19: =U19+X19 -> 67500 | AB19: =IFERROR(AA19/Z19,0) -> 2500 | AC19: =-IFERROR(F19/D19*Z19,0) -> -50216.132 | AD19: =-207.84*Z19 -> -5611.68 | AE19: =$AE$21/$Z$21*$Z19 -> -1333.7242 | AF19: =$AF$21/$Z$21*$Z19 -> -2621.8757 | AG19: =$AG$21/$Z$21*$Z19 -> -2095.9043 | AH19: =(AA19-Z19*$AE$25)*0.03 -> 1932.5161 | AI19: =AA19+SUM(AC19:AF19,AH19) -> 9649.1046 | AJ19: =IFERROR(AI19/AA19,0) -> 0.1429497 | AK19: =AA19+AC19+AD19+AE19+AH19-AG19 -> 14366.885 | AL19: =IFERROR(AK19/AA19,0) -> 0.21284273 | AN19: =AB19 -> 2500 | AO19: =IFERROR(AC19/$Z19,0) -> -1859.8567 | AP19: =IFERROR(AD19/$Z19,0) -> -207.84 | AQ19: =IFERROR(AE19/$Z19,0) -> -49.397192 | AR19: =IFERROR(AF19/$Z19,0) -> -97.106509 | AS19: =IFERROR(AG19/$Z19,0) -> -77.626085 | AT19: =IFERROR(AH19/$Z19,0) -> 71.574672 | AU19: =IFERROR(AI19/$Z19,0) -> 357.37424 | AV19: =IFERROR(AK19/$Z19,0) -> 532.10684
C20: OTROS | L20: 0 | M20: =F20+G20+H20+I20 -> 0 | N20: =IFERROR(M20/D20,0) -> 0 | P20: =O20*D20 -> 0 | Q20: =P20-M20 -> 0 | R20: =IFERROR(Q20/P20,0) -> 0 | T20: {=SUM([2]Hoja2!$J$6:$J$14*([2]Hoja2!$L$6:$L$14=$C20)*([2]Hoja2!$G$6:$G$14=T$5))} -> 0 | U20: {=SUM([2]Hoja2!$K$6:$K$14*([2]Hoja2!$L$6:$L$14=$C20)*([2]Hoja2!$G$6:$G$14=T$5))} -> 0 | V20: =IFERROR(U20/T20,0) -> 0 | W20: {=SUM([2]Hoja2!$J$6:$J$14*([2]Hoja2!$L$6:$L$14=$C20)*([2]Hoja2!$G$6:$G$14=W$5))} -> 0 | X20: {=SUM([2]Hoja2!$K$6:$K$14*([2]Hoja2!$L$6:$L$14=$C20)*([2]Hoja2!$G$6:$G$14=W$5))} -> 0 | Y20: =IFERROR(X20/W20,0) -> 0 | Z20: =T20+W20 -> 0 | AA20: =U20+X20 -> 0 | AB20: =IFERROR(AA20/Z20,0) -> 0 | AC20: =-IFERROR(F20/D20*Z20,0) -> 0 | AD20: =-207.84*Z20 -> 0 | AE20: =$AE$21/$Z$21*$Z20 -> 0 | AF20: =$AF$21/$Z$21*$Z20 -> 0 | AG20: =$AG$21/$Z$21*$Z20 -> 0 | AH20: =(AA20-Z20*$AE$25)*0.03 -> 0 | AI20: =AA20+SUM(AC20:AF20,AH20) -> 0 | AJ20: =IFERROR(AI20/AA20,0) -> 0 | AK20: =AA20+AC20+AD20+AE20+AH20-AG20 -> 0 | AL20: =IFERROR(AK20/AA20,0) -> 0 | AN20: =AB20 -> 0 | AO20: =IFERROR(AC20/$Z20,0) -> 0 | AP20: =IFERROR(AD20/$Z20,0) -> 0 | AQ20: =IFERROR(AE20/$Z20,0) -> 0 | AR20: =IFERROR(AF20/$Z20,0) -> 0 | AS20: =IFERROR(AG20/$Z20,0) -> 0 | AT20: =IFERROR(AH20/$Z20,0) -> 0 | AU20: =IFERROR(AI20/$Z20,0) -> 0 | AV20: =IFERROR(AK20/$Z20,0) -> 0
C21: TOTAL | D21: =SUM(D7:D20) -> 792.075 | E21: =IFERROR(F21/D21,0) -> 1864.5318 | F21: =SUM(F7:F20) -> 1476849 | G21: =SUM(G7:G20) -> 164624.87 | H21: =SUM(H7:H20) -> 41493.641 | I21: =SUM(I7:I20) -> 81569.468 | J21: =SUM(J7:J20) -> 65205.911 | K21: =SUM(K7:K20) -> 0 | L21: 0 | M21: =SUM(M7:M20) -> 1764537 | N21: =IFERROR(M21/D21,0) -> 2227.7398 | O21: =P21/D21 -> 0 | P21: =SUM(P7:P20) -> 0 | Q21: =SUM(Q7:Q20) -> -1764537 | R21: =Q21/P21 -> #DIV/0! | T21: =SUM(T7:T20) -> 26 | U21: =SUM(U7:U20) -> 36400 | V21: =IFERROR(U21/T21,0) -> 1400 | W21: =SUM(W7:W20) -> 814 | X21: =SUM(X7:X20) -> 2311190 | Y21: =IFERROR(X21/W21,0) -> 2839.2998 | Z21: =SUM(Z7:Z20) -> 840 | AA21: =SUM(AA7:AA20) -> 2347590 | AB21: =IFERROR(AA21/Z21,0) -> 2794.75 | AC21: =SUM(AC7:AC20) -> -1975255.1 | AD21: =SUM(AD7:AD20) -> -174585.6 | AE21: =-'Stock Libre'!Z59 -> -41493.641 | AF21: =-'Stock Libre'!AA59 -> -81569.468 | AG21: =-'Stock Libre'!AB59 -> -65205.911 | AH21: =SUM(AH7:AH20) -> 67550.424 | AI21: =SUM(AI7:AI20) -> 142236.63 | AJ21: =IFERROR(AI21/AA21,0) -> 0.060588361 | AK21: =SUM(AK7:AK20) -> 289012.01 | AL21: =IFERROR(AK21/AA21,0) -> 0.12311009 | AN21: =AB21 -> 2794.75 | AO21: =IFERROR(AC21/$Z21,0) -> -2351.4942 | AP21: =IFERROR(AD21/$Z21,0) -> -207.84 | AQ21: =IFERROR(AE21/$Z21,0) -> -49.397192 | AR21: =IFERROR(AF21/$Z21,0) -> -97.106509 | AS21: =IFERROR(AG21/$Z21,0) -> -77.626085 | AT21: =IFERROR(AH21/$Z21,0) -> 80.417172 | AU21: =IFERROR(AI21/$Z21,0) -> 169.32932 | AV21: =IFERROR(AK21/$Z21,0) -> 344.06191
I22: =I21/D21 -> 102.982
AD25: flete x tm | AE25: 114.17761

Sheet TD
D3: Etiquetas de fila | E3: Suma de TM en Stock | F3: Suma de Costo Ventas | G3: Suma de Gasto Ventas | H3: Suma de Gasto ADM | I3: Suma de Gasto Fin | J3: Suma de Depreciación
A4: =B4=D4 -> TRUE | B4: 10005721 | C4: POTA FILETE CONGELADO | D4: 10005721 | E4: 302.5 | F4: 640124.06 | G4: 62871.6 | H4: 15846.765 | I4: 31152.055 | J4: 24902.677
A5: =B5=D5 -> TRUE | B5: 10005779 | C5: POTA NUCAS CONGELADAS | D5: 10005779 | E5: 120.7 | F5: 208417.37 | G5: 25086.288 | H5: 6322.9902 | I5: 12429.927 | J5: 9936.374
A6: =B6=D6 -> TRUE | B6: 10005781 | C6: POTA NUCAS FR ABIERTAS 0.3-0.5 BL10 S20 | D6: 10005781 | E6: 78.94 | F6: 144527.36 | G6: 16406.89 | H6: 4135.3508 | I6: 8129.3991 | J6: 6498.5697
A7: =B7=D7 -> TRUE | B7: 10006719 | C7: POTA ALAS CONGELADAS | D7: 10006719 | E7: 8.3 | F7: 16728.369 | G7: 1725.072 | H7: 434.8038 | I7: 854.7506 | J7: 683.28007
A8: =B8=D8 -> TRUE | B8: 10006720 | C8: POTA ALAS CONGELADAS FR C/P C/C 0.5-1 BL10 S20 | D8: 10006720 | E8: 0.12 | F8: 180.13648 | G8: 24.9408 | H8: 6.28632 | I8: 12.35784 | J8: 9.878748
A9: =B9=D9 -> TRUE | B9: 10007050 | C9: POTA REJOS COCIDOS | D9: 10007050 | E9: 109.815 | F9: 169342.3 | G9: 22823.95 | H9: 5752.7686 | I9: 11308.968 | J9: 9040.2893
A10: =B10=D10 -> TRUE | B10: 10007162 | C10: POTA REJOS CONGELADOS | D10: 10007162 | E10: 19.24 | F10: 35753.441 | G10: 3998.8416 | H10: 1007.9066 | I10: 1981.3737 | J10: 1583.8926
A11: =B11=D11 -> TRUE | B11: 10007567 | C11: POTA REPRODUCTORES | D11: 10007567 | E11: 94.3 | F11: 169404.4 | G11: 19599.312 | H11: 4939.9998 | I11: 9711.2026 | J11: 7763.0495
A12: =B12=D12 -> TRUE | B12: 10007969 | C12: POTA CONOS | D12: 10007969 | E12: 17.54 | F12: 25713.703 | G12: 3645.5136 | H12: 918.85044 | I12: 1806.3043 | J12: 1443.9437
A13: =B13=D13 -> TRUE | B13: 10009207 | C13: POTA LABIOS FR S/COD BL10 S20 | D13: 10009207 | E13: 25.98 | F13: 39429.595 | G13: 5399.6832 | H13: 1360.9883 | I13: 2675.4724 | J13: 2138.7489
A14: =B14=D14 -> TRUE | B14: 10009239 | C14: POTA FILETE DARUMA | D14: 10009239 | E14: 0 | F14: 0 | G14: 0 | H14: 0 | I14: 0 | J14: 0
A15: =B15=D15 -> TRUE | B15: 10009334 | C15: POTA ALAS COCIDAS | D15: 10009334 | E15: 0 | F15: 0 | G15: 0 | H15: 0 | I15: 0 | J15: 0
A16: =B16=D16 -> TRUE | B16: 10009386 | C16: VENTOSAS | D16: 10009386 | E16: 14.64 | F16: 27228.302 | G16: 3042.7776 | H16: 766.93104 | I16: 1507.6565 | J16: 1205.2073
C17: OTROS | D17: (en blanco) | E17: 0 | F17: 0 | G17: 0 | H17: 0 | I17: 0 | J17: 0
D18: Total general | E18: 792.075 | F18: 1476849 | G18: 164624.87 | H18: 41493.641 | I18: 81569.468 | J18: 65205.911

Sheet Stock Libre
A1: CODIGO | B1: PRODUCTO | C1: TOTAL STOCK | D1: 01-06-2026 LOTE 095 | K1: RESUMEN SEMANA | L1: EMBARQUE | M1: EMBARQUE | N1: EMBARQUE Y REPROCESO | O1: TOTAL STOCK | P1: POR EMBARCAR | Q1: STOCK LIBRE | S1: CÓDIGO | T1: CU X TM | U1: % MP | V1: incremento MP | W1: TM en Stock | X1: Costo Ventas | Y1: Gasto Ventas | Z1: Gasto ADM | AA1: Gasto Fin | AB1: Depreciación | AC1: Utilidad Neta | AD1: Margen Neto | AE1: Venta Equilibrio | AF1: Precio Equilibrio x TM
A2: 10009178 | B2: POTA ALAS FR C/P C/C (B) S/COD BL10 S20 | C2: 12420 | K2: =+D2+E2+F2+G2+H2+I2+J2 -> 0 | O2: =+K2+C2-L2-M2-N2 -> 12420 | P2: 5000 | Q2: =+O2-P2 -> 7420 | S2: 10006719 | T2: =IFERROR(INDEX([1]Resumen!$K$3:$K$63,MATCH(S2,[1]Resumen!$C$3:$C$63,0)),0)*(1+U2*V2)/1000-51.89/1000 -> 2.0154661 | U2: 0.71 | V2: =3.597/3.52-1 -> 0.021875 | W2: =IF(Q2<0,0,Q2)/1000 -> 7.42 | X2: =IFERROR(T2*W2,0)*1000 -> 14954.759 | Y2: =207.84*W2 -> 1542.1728 | Z2: =$Z$61/1500*W2 -> 388.70412 | AA2: =$AA$61/1500*W2 -> 764.12644 | AB2: =$AB$61/1500*W2 -> 610.83592 | AC2: 0 | AD2: 0 | AE2: =X2+Y2+Z2+AA2 -> 17649.762 | AF2: =IFERROR(AE2/W2,0) -> 2378.6741
A3: 10006668 | B3: POTA ALAS FR C/P C/C <0.5 BL10 S20 | C3: 880 | K3: =+D3+E3+F3+G3+H3+I3+J3 -> 0 | O3: =+K3+C3-L3-M3-N3 -> 880 | P3: =21720-21720 -> 0 | Q3: =+O3-P3 -> 880 | S3: 10006719 | T3: =IFERROR(INDEX([1]Resumen!$K$3:$K$63,MATCH(S3,[1]Resumen!$C$3:$C$63,0)),0)*(1+U3*V3)/1000-51.89/1000 -> 2.0154661 | U3: 0.71 | V3: =3.597/3.52-1 -> 0.021875 | W3: =IF(Q3<0,0,Q3)/1000 -> 0.88 | X3: =IFERROR(T3*W3,0)*1000 -> 1773.6102 | Y3: =207.84*W3 -> 182.8992 | Z3: =$Z$61/1500*W3 -> 46.09968 | AA3: =$AA$61/1500*W3 -> 90.62416 | AB3: =$AB$61/1500*W3 -> 72.444152 | AC3: 0 | AD3: 0 | AE3: =X3+Y3+Z3+AA3 -> 2093.2332 | AF3: =IFERROR(AE3/W3,0) -> 2378.6741
A4: 10006719 | B4: POTA ALAS FR C/P C/C 0.5-1 BL10 S20 | C4: 3380 | K4: =+D4+E4+F4+G4+H4+I4+J4 -> 0 | O4: =+K4+C4-L4-M4-N4 -> 3380 | P4: =54000+216000-4000-4000-162000-25000-25000-25000 -> 25000 | Q4: =+O4-P4 -> -21620 | S4: 10006719 | T4: =IFERROR(INDEX([1]Resumen!$K$3:$K$63,MATCH(S4,[1]Resumen!$C$3:$C$63,0)),0)*(1+U4*V4)/1000-51.89/1000 -> 2.0154661 | U4: 0.71 | V4: =3.597/3.52-1 -> 0.021875 | W4: =IF(Q4<0,0,Q4)/1000 -> 0 | X4: =IFERROR(T4*W4,0)*1000 -> 0 | Y4: =207.84*W4 -> 0 | Z4: =$Z$61/1500*W4 -> 0 | AA4: =$AA$61/1500*W4 -> 0 | AB4: =$AB$61/1500*W4 -> 0 | AC4: 0 | AD4: 0 | AE4: =X4+Y4+Z4+AA4 -> 0 | AF4: =IFERROR(AE4/W4,0) -> 0
A5: 10009265 | B5: POTA ALAS FR C/P C/C 0.3 - 0.5 BL10 S20 | C5: 0 | K5: =+D5+E5+F5+G5+H5+I5+J5 -> 0 | O5: =+K5+C5-L5-M5-N5 -> 0 | Q5: =+O5-P5 -> 0 | S5: 10006719 | T5: =IFERROR(INDEX([1]Resumen!$K$3:$K$63,MATCH(S5,[1]Resumen!$C$3:$C$63,0)),0)*(1+U5*V5)/1000-51.89/1000 -> 2.0154661 | U5: 0.71 | V5: =3.597/3.52-1 -> 0.021875 | W5: =IF(Q5<0,0,Q5)/1000 -> 0 | X5: =IFERROR(T5*W5,0)*1000 -> 0 | Y5: =207.84*W5 -> 0 | Z5: =$Z$61/1500*W5 -> 0 | AA5: =$AA$61/1500*W5 -> 0 | AB5: =$AB$61/1500*W5 -> 0 | AC5: 0 | AD5: 0 | AE5: =X5+Y5+Z5+AA5 -> 0 | AF5: =IFERROR(AE5/W5,0) -> 0
A6: 10006720 | B6: POTA ALAS FR C/P C/C 1-2 BL10 S20 | C6: 680 | K6: =+D6+E6+F6+G6+H6+I6+J6 -> 0 | O6: =+K6+C6-L6-M6-N6 -> 680 | P6: =+O6 -> 680 | Q6: =+O6-P6 -> 0 | S6: 10006720 | T6: =IFERROR(INDEX([1]Resumen!$K$3:$K$63,MATCH(S6,[1]Resumen!$C$3:$C$63,0)),0)*(1+U6*V6)/1000-51.89/1000 -> 1.5011373 | U6: 0.71 | V6: =3.597/3.52-1 -> 0.021875 | W6: =IF(Q6<0,0,Q6)/1000 -> 0 | X6: =IFERROR(T6*W6,0)*1000 -> 0 | Y6: =207.84*W6 -> 0 | Z6: =$Z$61/1500*W6 -> 0 | AA6: =$AA$61/1500*W6 -> 0 | AB6: =$AB$61/1500*W6 -> 0 | AC6: 0 | AD6: 0 | AE6: =X6+Y6+Z6+AA6 -> 0 | AF6: =IFERROR(AE6/W6,0) -> 0
A7: 10010005 | B7: POTA ALAS FR C/P C/C 1-2 BL10 S20 ENTERA | C7: 32380 | K7: =+D7+E7+F7+G7+H7+I7+J7 -> 0 | O7: =+K7+C7-L7-M7-N7 -> 32380 | P7: =69000-P6 -> 68320 | Q7: =+O7-P7 -> -35940 | S7: 10006720 | T7: =IFERROR(INDEX([1]Resumen!$K$3:$K$63,MATCH(S7,[1]Resumen!$C$3:$C$63,0)),0)*(1+U7*V7)/1000-51.89/1000 -> 1.5011373 | U7: 0.71 | V7: =3.597/3.52-1 -> 0.021875 | W7: =IF(Q7<0,0,Q7)/1000 -> 0 | X7: =IFERROR(T7*W7,0)*1000 -> 0 | Y7: =207.84*W7 -> 0 | Z7: =$Z$61/1500*W7 -> 0 | AA7: =$AA$61/1500*W7 -> 0 | AB7: =$AB$61/1500*W7 -> 0 | AC7: 0 | AD7: 0 | AE7: =X7+Y7+Z7+AA7 -> 0 | AF7: =IFERROR(AE7/W7,0) -> 0
A8: 10006722 | B8: POTA ALAS FR C/P C/C 2up | C8: 120 | K8: =+D8+E8+F8+G8+H8+I8+J8 -> 0 | O8: =+K8+C8-L8-M8-N8 -> 120 | Q8: =+O8-P8 -> 120 | S8: 10006720 | T8: =IFERROR(INDEX([1]Resumen!$K$3:$K$63,MATCH(S8,[1]Resumen!$C$3:$C$63,0)),0)*(1+U8*V8)/1000-51.89/1000 -> 1.5011373 | U8: 0.71 | V8: =3.597/3.52-1 -> 0.021875 | W8: =IF(Q8<0,0,Q8)/1000 -> 0.12 | X8: =IFERROR(T8*W8,0)*1000 -> 180.13648 | Y8: =207.84*W8 -> 24.9408 | Z8: =$Z$61/1500*W8 -> 6.28632 | AA8: =$AA$61/1500*W8 -> 12.35784 | AB8: =$AB$61/1500*W8 -> 9.878748 | AC8: 0 | AD8: 0 | AE8: =X8+Y8+Z8+AA8 -> 223.72144 | AF8: =IFERROR(AE8/W8,0) -> 1864.3453
A9: 10009207 | B9: POTA LABIOS FR S/COD BL10 S20 | C9: 25980 | K9: =+D9+E9+F9+G9+H9+I9+J9 -> 0 | O9: =+K9+C9-L9-M9-N9 -> 25980 | Q9: =+O9-P9 -> 25980 | S9: 10009207 | T9: =IFERROR(INDEX([1]Resumen!$K$3:$K$63,MATCH(S9,[1]Resumen!$C$3:$C$63,0)),0)*(1+U9*V9)/1000-51.89/1000 -> 1.5176903 | U9: 0.71 | V9: =3.597/3.52-1 -> 0.021875 | W9: =IF(Q9<0,0,Q9)/1000 -> 25.98 | X9: =IFERROR(T9*W9,0)*1000 -> 39429.595 | Y9: =207.84*W9 -> 5399.6832 | Z9: =$Z$61/1500*W9 -> 1360.9883 | AA9: =$AA$61/1500*W9 -> 2675.4724 | AB9: =$AB$61/1500*W9 -> 2138.7489 | AC9: 0 | AD9: 0 | AE9: =X9+Y9+Z9+AA9 -> 48865.739 | AF9: =IFERROR(AE9/W9,0) -> 1880.8983
A10: 10007969 | B10: POTA CONOS | C10: 17540 | K10: =+D10+E10+F10+G10+H10+I10+J10 -> 0 | O10: =+K10+C10-L10-M10-N10 -> 17540 | P10: =24000-24000 -> 0 | Q10: =+O10-P10 -> 17540 | S10: 10007969 | T10: =IFERROR(INDEX([1]Resumen!$K$3:$K$63,MATCH(S10,[1]Resumen!$C$3:$C$63,0)),0)*(1+U10*V10)/1000-51.89/1000 -> 1.4660036 | U10: 0.71 | V10: =3.597/3.52-1 -> 0.021875 | W10: =IF(Q10<0,0,Q10)/1000 -> 17.54 | X10: =IFERROR(T10*W10,0)*1000 -> 25713.703 | Y10: =207.84*W10 -> 3645.5136 | Z10: =$Z$61/1500*W10 -> 918.85044 | AA10: =$AA$61/1500*W10 -> 1806.3043 | AB10: =$AB$61/1500*W10 -> 1443.9437 | AC10: 0 | AD10: 0 | AE10: =X10+Y10+Z10+AA10 -> 32084.372 | AF10: =IFERROR(AE10/W10,0) -> 1829.2116
A11: 10009174 | B11: POTA ENTERA < 1KG | C11: 0 | K11: =+D11+E11+F11+G11+H11+I11+J11 -> 0 | O11: =+K11+C11-L11-M11-N11 -> 0 | Q11: =+O11-P11 -> 0 | V11: =3.597/3.52-1 -> 0.021875 | W11: =IF(Q11<0,0,Q11)/1000 -> 0 | X11: =IFERROR(T11*W11,0)*1000 -> 0 | Y11: =207.84*W11 -> 0 | Z11: =$Z$61/1500*W11 -> 0 | AA11: =$AA$61/1500*W11 -> 0 | AB11: =$AB$61/1500*W11 -> 0 | AC11: 0 | AD11: 0 | AE11: =X11+Y11+Z11+AA11 -> 0 | AF11: =IFERROR(AE11/W11,0) -> 0
A12: 10009175 | B12: TUBO ALETA 0.1-0.5 KG | C12: 0 | K12: =+D12+E12+F12+G12+H12+I12+J12 -> 0 | O12: =+K12+C12-L12-M12-N12 -> 0 | Q12: =+O12-P12 -> 0 | V12: =3.597/3.52-1 -> 0.021875 | W12: =IF(Q12<0,0,Q12)/1000 -> 0 | X12: =IFERROR(T12*W12,0)*1000 -> 0 | Y12: =207.84*W12 -> 0 | Z12: =$Z$61/1500*W12 -> 0 | AA12: =$AA$61/1500*W12 -> 0 | AB12: =$AB$61/1500*W12 -> 0 | AC12: 0 | AD12: 0 | AE12: =X12+Y12+Z12+AA12 -> 0 | AF12: =IFERROR(AE12/W12,0) -> 0
A13: 10009176 | B13: TUBO ALETA 0.5-1.0 KG | C13: 0 | K13: =+D13+E13+F13+G13+H13+I13+J13 -> 0 | O13: =+K13+C13-L13-M13-N13 -> 0 | Q13: =+O13-P13 -> 0 | V13: =3.597/3.52-1 -> 0.021875 | W13: =IF(Q13<0,0,Q13)/1000 -> 0 | X13: =IFERROR(T13*W13,0)*1000 -> 0 | Y13: =207.84*W13 -> 0 | Z13: =$Z$61/1500*W13 -> 0 | AA13: =$AA$61/1500*W13 -> 0 | AB13: =$AB$61/1500*W13 -> 0 | AC13: 0 | AD13: 0 | AE13: =X13+Y13+Z13+AA13 -> 0 | AF13: =IFERROR(AE13/W13,0) -> 0
A14: 10010003 | B14: TUBO ALETA 1.0-1.5 kg | C14: 0 | K14: =+D14+E14+F14+G14+H14+I14+J14 -> 0 | O14: =+K14+C14-L14-M14-N14 -> 0 | Q14: =+O14-P14 -> 0 | V14: =3.597/3.52-1 -> 0.021875 | W14: =IF(Q14<0,0,Q14)/1000 -> 0 | X14: =IFERROR(T14*W14,0)*1000 -> 0 | Y14: =207.84*W14 -> 0 | Z14: =$Z$61/1500*W14 -> 0 | AA14: =$AA$61/1500*W14 -> 0 | AB14: =$AB$61/1500*W14 -> 0 | AC14: 0 | AD14: 0 | AE14: =X14+Y14+Z14+AA14 -> 0 | AF14: =IFERROR(AE14/W14,0) -> 0
A15: 10009177 | B15: TUBO ALETA 1.0-2.0 KG | C15: 0 | K15: =+D15+E15+F15+G15+H15+I15+J15 -> 0 | O15: =+K15+C15-L15-M15-N15 -> 0 | Q15: =+O15-P15 -> 0 | V15: =3.597/3.52-1 -> 0.021875 | W15: =IF(Q15<0,0,Q15)/1000 -> 0 | X15: =IFERROR(T15*W15,0)*1000 -> 0 | Y15: =207.84*W15 -> 0 | Z15: =$Z$61/1500*W15 -> 0 | AA15: =$AA$61/1500*W15 -> 0 | AB15: =$AB$61/1500*W15 -> 0 | AC15: 0 | AD15: 0 | AE15: =X15+Y15+Z15+AA15 -> 0 | AF15: =IFERROR(AE15/W15,0) -> 0
A16: 10004433 | B16: POTA FILETE C/M C/T FR 0.5-1.0 BL10 S20 | C16: 1380 | K16: =+D16+E16+F16+G16+H16+I16+J16 -> 0 | O16: =+K16+C16-L16-M16-N16 -> 1380 | Q16: =+O16-P16 -> 1380 | S16: 10005721 | T16: =IFERROR(INDEX([1]Resumen!$K$3:$K$63,MATCH(S16,[1]Resumen!$C$3:$C$63,0)),0)*(1+U16*V16)/1000-51.89/1000 -> 2.1161126 | U16: 0.67 | V16: =3.597/3.52-1 -> 0.021875 | W16: =IF(Q16<0,0,Q16)/1000 -> 1.38 | X16: =IFERROR(T16*W16,0)*1000 -> 2920.2354 | Y16: =207.84*W16 -> 286.8192 | Z16: =$Z$61/1500*W16 -> 72.29268 | AA16: =$AA$61/1500*W16 -> 142.11516 | AB16: =$AB$61/1500*W16 -> 113.6056 | AC16: 0 | AD16: 0 | AE16: =X16+Y16+Z16+AA16 -> 3421.4624 | AF16: =IFERROR(AE16/W16,0) -> 2479.3206
A17: 10004434 | B17: POTA FILETE C/M C/T FR 1-2 BL10 S20 | C17: 1920 | K17: =+D17+E17+F17+G17+H17+I17+J17 -> 0 | O17: =+K17+C17-L17-M17-N17 -> 1920 | Q17: =+O17-P17 -> 1920 | S17: 10005721 | T17: =IFERROR(INDEX([1]Resumen!$K$3:$K$63,MATCH(S17,[1]Resumen!$C$3:$C$63,0)),0)*(1+U17*V17)/1000-51.89/1000 -> 2.1161126 | U17: 0.67 | V17: =3.597/3.52-1 -> 0.021875 | W17: =IF(Q17<0,0,Q17)/1000 -> 1.92 | X17: =IFERROR(T17*W17,0)*1000 -> 4062.9362 | Y17: =207.84*W17 -> 399.0528 | Z17: =$Z$61/1500*W17 -> 100.58112 | AA17: =$AA$61/1500*W17 -> 197.72544 | AB17: =$AB$61/1500*W17 -> 158.05997 | AC17: 0 | AD17: 0 | AE17: =X17+Y17+Z17+AA17 -> 4760.2956 | AF17: =IFERROR(AE17/W17,0) -> 2479.3206
A18: 10004435 | B18: POTA FILETE C/M C/T FR 2-4 S20 | C18: 13100 | K18: =+D18+E18+F18+G18+H18+I18+J18 -> 0 | O18: =+K18+C18-L18-M18-N18 -> 13100 | Q18: =+O18-P18 -> 13100 | S18: 10005721 | T18: =IFERROR(INDEX([1]Resumen!$K$3:$K$63,MATCH(S18,[1]Resumen!$C$3:$C$63,0)),0)*(1+U18*V18)/1000-51.89/1000 -> 2.1161126 | U18: 0.67 | V18: =3.597/3.52-1 -> 0.021875 | W18: =IF(Q18<0,0,Q18)/1000 -> 13.1 | X18: =IFERROR(T18*W18,0)*1000 -> 27721.075 | Y18: =207.84*W18 -> 2722.704 | Z18: =$Z$61/1500*W18 -> 686.2566 | AA18: =$AA$61/1500*W18 -> 1349.0642 | AB18: =$AB$61/1500*W18 -> 1078.43 | AC18: 0 | AD18: 0 | AE18: =X18+Y18+Z18+AA18 -> 32479.1 | AF18: =IFERROR(AE18/W18,0) -> 2479.3206
A19: 10005708 | B19: POTA FILETE C/M C/T FR <0.5 Kg AA BL10 S20 | C19: 1060 | K19: =+D19+E19+F19+G19+H19+I19+J19 -> 0 | O19: =+K19+C19-L19-M19-N19 -> 1060 | Q19: =+O19-P19 -> 1060 | S19: 10005721 | T19: =IFERROR(INDEX([1]Resumen!$K$3:$K$63,MATCH(S19,[1]Resumen!$C$3:$C$63,0)),0)*(1+U19*V19)/1000-51.89/1000 -> 2.1161126 | U19: 0.67 | V19: =3.597/3.52-1 -> 0.021875 | W19: =IF(Q19<0,0,Q19)/1000 -> 1.06 | X19: =IFERROR(T19*W19,0)*1000 -> 2243.0794 | Y19: =207.84*W19 -> 220.3104 | Z19: =$Z$61/1500*W19 -> 55.52916 | AA19: =$AA$61/1500*W19 -> 109.16092 | AB19: =$AB$61/1500*W19 -> 87.262274 | AC19: 0 | AD19: 0 | AE19: =X19+Y19+Z19+AA19 -> 2628.0798 | AF19: =IFERROR(AE19/W19,0) -> 2479.3206
A20: 10005721 | B20: POTA FILETE C/M C/T FR 2-4 (AA) BL10 S20 | C20: 270520 | K20: =+D20+E20+F20+G20+H20+I20+J20 -> 0 | O20: =+K20+C20-L20-M20-N20 -> 270520 | Q20: =+O20-P20 -> 270520 | S20: 10005721 | T20: =IFERROR(INDEX([1]Resumen!$K$3:$K$63,MATCH(S20,[1]Resumen!$C$3:$C$63,0)),0)*(1+U20*V20)/1000-51.89/1000 -> 2.1161126 | U20: 0.67 | V20: =3.597/3.52-1 -> 0.021875 | W20: =IF(Q20<0,0,Q20)/1000 -> 270.52 | X20: =IFERROR(T20*W20,0)*1000 -> 572450.78 | Y20: =207.84*W20 -> 56224.877 | Z20: =$Z$61/1500*W20 -> 14171.461 | AA20: =$AA$61/1500*W20 -> 27858.691 | AB20: =$AB$61/1500*W20 -> 22269.991 | AC20: 0 | AD20: 0 | AE20: =X20+Y20+Z20+AA20 -> 670705.81 | AF20: =IFERROR(AE20/W20,0) -> 2479.3206
A21: 10005711 | B21: POTA FILETE C/M C/T FR 0.5-1.0 AA BL10 S20 | C21: 11320 | K21: =+D21+E21+F21+G21+H21+I21+J21 -> 0 | O21: =+K21+C21-L21-M21-N21 -> 11320 | Q21: =+O21-P21 -> 11320 | S21: 10005721 | T21: =IFERROR(INDEX([1]Resumen!$K$3:$K$63,MATCH(S21,[1]Resumen!$C$3:$C$63,0)),0)*(1+U21*V21)/1000-51.89/1000 -> 2.1161126 | U21: 0.67 | V21: =3.597/3.52-1 -> 0.021875 | W21: =IF(Q21<0,0,Q21)/1000 -> 11.32 | X21: =IFERROR(T21*W21,0)*1000 -> 23954.395 | Y21: =207.84*W21 -> 2352.7488 | Z21: =$Z$61/1500*W21 -> 593.00952 | AA21: =$AA$61/1500*W21 -> 1165.7562 | AB21: =$AB$61/1500*W21 -> 931.89523 | AC21: 0 | AD21: 0 | AE21: =X21+Y21+Z21+AA21 -> 28065.909 | AF21: =IFERROR(AE21/W21,0) -> 2479.3206
A22: 10005718 | B22: POTA FILETE C/M C/T FR 1-2 AA BL10 S20 | C22: 21920 | K22: =+D22+E22+F22+G22+H22+I22+J22 -> 0 | O22: =+K22+C22-L22-M22-N22 -> 21920 | P22: =24000+108000-27000+14000-O24 -> 114220 | Q22: =+O22-P22 -> -92300 | S22: 10005721 | T22: =IFERROR(INDEX([1]Resumen!$K$3:$K$63,MATCH(S22,[1]Resumen!$C$3:$C$63,0)),0)*(1+U22*V22)/1000-51.89/1000 -> 2.1161126 | U22: 0.67 | V22: =3.597/3.52-1 -> 0.021875 | W22: =IF(Q22<0,0,Q22)/1000 -> 0 | X22: =IFERROR(T22*W22,0)*1000 -> 0 | Y22: =207.84*W22 -> 0 | Z22: =$Z$61/1500*W22 -> 0 | AA22: =$AA$61/1500*W22 -> 0 | AB22: =$AB$61/1500*W22 -> 0 | AC22: 0 | AD22: 0 | AE22: =X22+Y22+Z22+AA22 -> 0 | AF22: =IFERROR(AE22/W22,0) -> 0
A23: 10009971 | B23: POTA FILETE C/M C/T FR 0.5-1.0 AAA BL10 S20 | C23: 0 | K23: =+D23+E23+F23+G23+H23+I23+J23 -> 0 | O23: =+K23+C23-L23-M23-N23 -> 0 | Q23: =+O23-P23 -> 0 | S23: 10005721 | T23: =IFERROR(INDEX([1]Resumen!$K$3:$K$63,MATCH(S23,[1]Resumen!$C$3:$C$63,0)),0)*(1+U23*V23)/1000-51.89/1000 -> 2.1161126 | U23: 0.67 | V23: =3.597/3.52-1 -> 0.021875 | W23: =IF(Q23<0,0,Q23)/1000 -> 0 | X23: =IFERROR(T23*W23,0)*1000 -> 0 | Y23: =207.84*W23 -> 0 | Z23: =$Z$61/1500*W23 -> 0 | AA23: =$AA$61/1500*W23 -> 0 | AB23: =$AB$61/1500*W23 -> 0 | AC23: 0 | AD23: 0 | AE23: =X23+Y23+Z23+AA23 -> 0 | AF23: =IFERROR(AE23/W23,0) -> 0
A24: 10009972 | B24: POTA FILETE C/M C/T FR 1-2 AAA BL10 S20 | C24: 4780 | K24: =+D24+E24+F24+G24+H24+I24+J24 -> 0 | O24: =+K24+C24-L24-M24-N24 -> 4780 | P24: =+O24 -> 4780 | Q24: =+O24-P24 -> 0 | S24: 10005721 | T24: =IFERROR(INDEX([1]Resumen!$K$3:$K$63,MATCH(S24,[1]Resumen!$C$3:$C$63,0)),0)*(1+U24*V24)/1000-51.89/1000 -> 2.1161126 | U24: 0.67 | V24: =3.597/3.52-1 -> 0.021875 | W24: =IF(Q24<0,0,Q24)/1000 -> 0 | X24: =IFERROR(T24*W24,0)*1000 -> 0 | Y24: =207.84*W24 -> 0 | Z24: =$Z$61/1500*W24 -> 0 | AA24: =$AA$61/1500*W24 -> 0 | AB24: =$AB$61/1500*W24 -> 0 | AC24: 0 | AD24: 0 | AE24: =X24+Y24+Z24+AA24 -> 0 | AF24: =IFERROR(AE24/W24,0) -> 0
A25: 10010063 | B25: POTA FILETE C/M C/T FR 2-4 AAA BL10 S20 | C25: 0 | K25: =+D25+E25+F25+G25+H25+I25+J25 -> 0 | O25: =+K25+C25-L25-M25-N25 -> 0 | P25: =+O25 -> 0 | Q25: =+O25-P25 -> 0 | S25: 10005721 | T25: =IFERROR(INDEX([1]Resumen!$K$3:$K$63,MATCH(S25,[1]Resumen!$C$3:$C$63,0)),0)*(1+U25*V25)/1000-51.89/1000 -> 2.1161126 | U25: 0.67 | V25: =3.597/3.52-1 -> 0.021875 | W25: =IF(Q25<0,0,Q25)/1000 -> 0 | X25: =IFERROR(T25*W25,0)*1000 -> 0 | Y25: =207.84*W25 -> 0 | Z25: =$Z$61/1500*W25 -> 0 | AA25: =$AA$61/1500*W25 -> 0 | AB25: =$AB$61/1500*W25 -> 0 | AC25: 0 | AD25: 0 | AE25: =X25+Y25+Z25+AA25 -> 0 | AF25: =IFERROR(AE25/W25,0) -> 0
A26: 10009298 | B26: POTA FILETE SM ST 1-2 CM/ESP | C26: 3200 | K26: =+D26+E26+F26+G26+H26+I26+J26 -> 0 | O26: =+K26+C26-L26-M26-N26 -> 3200 | Q26: =+O26-P26 -> 3200 | S26: 10005721 | T26: =IFERROR(INDEX([1]Resumen!$K$3:$K$63,MATCH(S26,[1]Resumen!$C$3:$C$63,0)),0)*(1+U26*V26)/1000-51.89/1000 -> 2.1161126 | U26: 0.67 | V26: =3.597/3.52-1 -> 0.021875 | W26: =IF(Q26<0,0,Q26)/1000 -> 3.2 | X26: =IFERROR(T26*W26,0)*1000 -> 6771.5603 | Y26: =207.84*W26 -> 665.088 | Z26: =$Z$61/1500*W26 -> 167.6352 | AA26: =$AA$61/1500*W26 -> 329.5424 | AB26: =$AB$61/1500*W26 -> 263.43328 | AC26: 0 | AD26: 0 | AE26: =X26+Y26+Z26+AA26 -> 7933.8259 | AF26: =IFERROR(AE26/W26,0) -> 2479.3206
A27: 10009184 | B27: POTA NUCAS FR ABIERTAS 0.1 - 0.3 BL10 S2 | C27: 79600 | K27: =+D27+E27+F27+G27+H27+I27+J27 -> 0 | O27: =+K27+C27-L27-M27-N27 -> 79600 | Q27: =+O27-P27 -> 79600 | S27: 10005779 | T27: =IFERROR(INDEX([1]Resumen!$K$3:$K$63,MATCH(S27,[1]Resumen!$C$3:$C$63,0)),0)*(1+U27*V27)/1000-51.89/1000 -> 1.7267388 | U27: 0.65 | V27: =3.597/3.52-1 -> 0.021875 | W27: =IF(Q27<0,0,Q27)/1000 -> 79.6 | X27: =IFERROR(T27*W27,0)*1000 -> 137448.41 | Y27: =207.84*W27 -> 16544.064 | Z27: =$Z$61/1500*W27 -> 4169.9256 | AA27: =$AA$61/1500*W27 -> 8197.3672 | AB27: =$AB$61/1500*W27 -> 6552.9028 | AC27: 0 | AD27: 0 | AE27: =X27+Y27+Z27+AA27 -> 166359.76 | AF27: =IFERROR(AE27/W27,0) -> 2089.9468
A28: 10009271 | B28: POTA NUCAS FR CERRADA 0.1 - 0.3 BL10 S2 | C28: 40100 | K28: =+D28+E28+F28+G28+H28+I28+J28 -> 0 | O28: =+K28+C28-L28-M28-N28 -> 40100 | Q28: =+O28-P28 -> 40100 | S28: 10005779 | T28: =IFERROR(INDEX([1]Resumen!$K$3:$K$63,MATCH(S28,[1]Resumen!$C$3:$C$63,0)),0)*(1+U28*V28)/1000-51.89/1000 -> 1.7267388 | U28: 0.65 | V28: =3.597/3.52-1 -> 0.021875 | W28: =IF(Q28<0,0,Q28)/1000 -> 40.1 | X28: =IFERROR(T28*W28,0)*1000 -> 69242.225 | Y28: =207.84*W28 -> 8334.384 | Z28: =$Z$61/1500*W28 -> 2100.6786 | AA28: =$AA$61/1500*W28 -> 4129.5782 | AB28: =$AB$61/1500*W28 -> 3301.1483 | AC28: 0 | AD28: 0 | AE28: =X28+Y28+Z28+AA28 -> 83806.866 | AF28: =IFERROR(AE28/W28,0) -> 2089.9468
A29: 10009183 | B29: POTA NUCAS FR CERRADA <0.1 BL10 S2 | C29: 1000 | K29: =+D29+E29+F29+G29+H29+I29+J29 -> 0 | O29: =+K29+C29-L29-M29-N29 -> 1000 | Q29: =+O29-P29 -> 1000 | S29: 10005779 | T29: =IFERROR(INDEX([1]Resumen!$K$3:$K$63,MATCH(S29,[1]Resumen!$C$3:$C$63,0)),0)*(1+U29*V29)/1000-51.89/1000 -> 1.7267388 | U29: 0.65 | V29: =3.597/3.52-1 -> 0.021875 | W29: =IF(Q29<0,0,Q29)/1000 -> 1 | X29: =IFERROR(T29*W29,0)*1000 -> 1726.7388 | Y29: =207.84*W29 -> 207.84 | Z29: =$Z$61/1500*W29 -> 52.386 | AA29: =$AA$61/1500*W29 -> 102.982 | AB29: =$AB$61/1500*W29 -> 82.3229 | AC29: 0 | AD29: 0 | AE29: =X29+Y29+Z29+AA29 -> 2089.9468 | AF29: =IFERROR(AE29/W29,0) -> 2089.9468
A30: 10005779 | B30: POTA NUCAS FR ABIERTAS 0.5-1 BL10 S20 | C30: 12360 | K30: =+D30+E30+F30+G30+H30+I30+J30 -> 0 | O30: =+K30+C30-L30-M30-N30 -> 12360 | Q30: =+O30-P30 -> 12360 | S30: 10005781 | T30: =IFERROR(INDEX([1]Resumen!$K$3:$K$63,MATCH(S30,[1]Resumen!$C$3:$C$63,0)),0)*(1+U30*V30)/1000-51.89/1000 -> 1.8308508 | U30: 0.65 | V30: =3.597/3.52-1 -> 0.021875 | W30: =IF(Q30<0,0,Q30)/1000 -> 12.36 | X30: =IFERROR(T30*W30,0)*1000 -> 22629.315 | Y30: =207.84*W30 -> 2568.9024 | Z30: =$Z$61/1500*W30 -> 647.49096 | AA30: =$AA$61/1500*W30 -> 1272.8575 | AB30: =$AB$61/1500*W30 -> 1017.511 | AC30: 0 | AD30: 0 | AE30: =X30+Y30+Z30+AA30 -> 27118.566 | AF30: =IFERROR(AE30/W30,0) -> 2194.0588
A31: 10005776 | B31: POTA NUCAS FR ABIERTAS 0.3-0.5 BL10 S20 | C31: 76580 | K31: =+D31+E31+F31+G31+H31+I31+J31 -> 0 | O31: =+K31+C31-L31-M31-N31 -> 76580 | P31: =10000 -> 10000 | Q31: =+O31-P31 -> 66580 | S31: 10005781 | T31: =IFERROR(INDEX([1]Resumen!$K$3:$K$63,MATCH(S31,[1]Resumen!$C$3:$C$63,0)),0)*(1+U31*V31)/1000-51.89/1000 -> 1.8308508 | U31: 0.65 | V31: =3.597/3.52-1 -> 0.021875 | W31: =IF(Q31<0,0,Q31)/1000 -> 66.58 | X31: =IFERROR(T31*W31,0)*1000 -> 121898.04 | Y31: =207.84*W31 -> 13837.987 | Z31: =$Z$61/1500*W31 -> 3487.8599 | AA31: =$AA$61/1500*W31 -> 6856.5416 | AB31: =$AB$61/1500*W31 -> 5481.0587 | AC31: 0 | AD31: 0 | AE31: =X31+Y31+Z31+AA31 -> 146080.43 | AF31: =IFERROR(AE31/W31,0) -> 2194.0588
A32: 10005781 | B32: POTA NUCAS FR ABIERTAS 1-2 BL10 S20 | C32: 24220 | K32: =+D32+E32+F32+G32+H32+I32+J32 -> 0 | O32: =+K32+C32-L32-M32-N32 -> 24220 | P32: =24000+104000 -> 128000 | Q32: =+O32-P32 -> -103780 | S32: 10005781 | T32: =IFERROR(INDEX([1]Resumen!$K$3:$K$63,MATCH(S32,[1]Resumen!$C$3:$C$63,0)),0)*(1+U32*V32)/1000-51.89/1000 -> 1.8308508 | U32: 0.65 | V32: =3.597/3.52-1 -> 0.021875 | W32: =IF(Q32<0,0,Q32)/1000 -> 0 | X32: =IFERROR(T32*W32,0)*1000 -> 0 | Y32: =207.84*W32 -> 0 | Z32: =$Z$61/1500*W32 -> 0 | AA32: =$AA$61/1500*W32 -> 0 | AB32: =$AB$61/1500*W32 -> 0 | AC32: 0 | AD32: 0 | AE32: =X32+Y32+Z32+AA32 -> 0 | AF32: =IFERROR(AE32/W32,0) -> 0
A33: 10007567 | B33: POTA REJOS OR FR LIMPIOS S/COD BL10 S20 | C33: 58360 | K33: =+D33+E33+F33+G33+H33+I33+J33 -> 0 | O33: =+K33+C33-L33-M33-N33 -> 58360 | Q33: =+O33-P33 -> 58360 | S33: 10007567 | T33: =IFERROR(INDEX([1]Resumen!$K$3:$K$63,MATCH(S33,[1]Resumen!$C$3:$C$63,0)),0)*(1+U33*V33)/1000-51.89/1000 -> 1.7964412 | U33: 0.68 | V33: =3.597/3.52-1 -> 0.021875 | W33: =IF(Q33<0,0,Q33)/1000 -> 58.36 | X33: =IFERROR(T33*W33,0)*1000 -> 104840.31 | Y33: =207.84*W33 -> 12129.542 | Z33: =$Z$61/1500*W33 -> 3057.247 | AA33: =$AA$61/1500*W33 -> 6010.0295 | AB33: =$AB$61/1500*W33 -> 4804.3644 | AC33: 0 | AD33: 0 | AE33: =X33+Y33+Z33+AA33 -> 126037.13 | AF33: =IFERROR(AE33/W33,0) -> 2159.6492
A34: 10009975 | B34: POTA REJOS OR FR LIMPIOS <60 cm BL10 S20 | C34: 35940 | K34: =+D34+E34+F34+G34+H34+I34+J34 -> 0 | O34: =+K34+C34-L34-M34-N34 -> 35940 | Q34: =+O34-P34 -> 35940 | S34: 10007567 | T34: =IFERROR(INDEX([1]Resumen!$K$3:$K$63,MATCH(S34,[1]Resumen!$C$3:$C$63,0)),0)*(1+U34*V34)/1000-51.89/1000 -> 1.7964412 | U34: 0.68 | V34: =3.597/3.52-1 -> 0.021875 | W34: =IF(Q34<0,0,Q34)/1000 -> 35.94 | X34: =IFERROR(T34*W34,0)*1000 -> 64564.096 | Y34: =207.84*W34 -> 7469.7696 | Z34: =$Z$61/1500*W34 -> 1882.7528 | AA34: =$AA$61/1500*W34 -> 3701.1731 | AB34: =$AB$61/1500*W34 -> 2958.685 | AC34: 0 | AD34: 0 | AE34: =X34+Y34+Z34+AA34 -> 77617.792 | AF34: =IFERROR(AE34/W34,0) -> 2159.6492
A35: 10009185 | B35: POTA REJOS FR C/U C/V S/OR <0.1 BL10 | C35: 0 | K35: =+D35+E35+F35+G35+H35+I35+J35 -> 0 | O35: =+K35+C35-L35-M35-N35 -> 0 | Q35: =+O35-P35 -> 0 | S35: 10007162 | T35: =IFERROR(INDEX([1]Resumen!$K$3:$K$63,MATCH(S35,[1]Resumen!$C$3:$C$63,0)),0)*(1+U35*V35)/1000-51.89/1000 -> 1.8582869 | U35: 0.68 | V35: =3.597/3.52-1 -> 0.021875 | W35: =IF(Q35<0,0,Q35)/1000 -> 0 | X35: =IFERROR(T35*W35,0)*1000 -> 0 | Y35: =207.84*W35 -> 0 | Z35: =$Z$61/1500*W35 -> 0 | AA35: =$AA$61/1500*W35 -> 0 | AB35: =$AB$61/1500*W35 -> 0 | AC35: 0 | AD35: 0 | AE35: =X35+Y35+Z35+AA35 -> 0 | AF35: =IFERROR(AE35/W35,0) -> 0
A36: 10009186 | B36: POTA REJOS FR C/U C/V S/OR 0.1-0.3 BL10 | C36: 5700 | K36: =+D36+E36+F36+G36+H36+I36+J36 -> 0 | O36: =+K36+C36-L36-M36-N36 -> 5700 | P36: 5700 | Q36: =+O36-P36 -> 0 | S36: 10007162 | T36: =IFERROR(INDEX([1]Resumen!$K$3:$K$63,MATCH(S36,[1]Resumen!$C$3:$C$63,0)),0)*(1+U36*V36)/1000-51.89/1000 -> 1.8582869 | U36: 0.68 | V36: =3.597/3.52-1 -> 0.021875 | W36: =IF(Q36<0,0,Q36)/1000 -> 0 | X36: =IFERROR(T36*W36,0)*1000 -> 0 | Y36: =207.84*W36 -> 0 | Z36: =$Z$61/1500*W36 -> 0 | AA36: =$AA$61/1500*W36 -> 0 | AB36: =$AB$61/1500*W36 -> 0 | AC36: 0 | AD36: 0 | AE36: =X36+Y36+Z36+AA36 -> 0 | AF36: =IFERROR(AE36/W36,0) -> 0
A37: 10009777 | B37: POTA REJOS FR C/U C/V S/OR 0.3-0.5BL10 | C37: 1360 | K37: =+D37+E37+F37+G37+H37+I37+J37 -> 0 | O37: =+K37+C37-L37-M37-N37 -> 1360 | P37: 54000 | Q37: =+O37-P37 -> -52640 | S37: 10007162 | T37: =IFERROR(INDEX([1]Resumen!$K$3:$K$63,MATCH(S37,[1]Resumen!$C$3:$C$63,0)),0)*(1+U37*V37)/1000-51.89/1000 -> 1.8582869 | U37: 0.68 | V37: =3.597/3.52-1 -> 0.021875 | W37: =IF(Q37<0,0,Q37)/1000 -> 0 | X37: =IFERROR(T37*W37,0)*1000 -> 0 | Y37: =207.84*W37 -> 0 | Z37: =$Z$61/1500*W37 -> 0 | AA37: =$AA$61/1500*W37 -> 0 | AB37: =$AB$61/1500*W37 -> 0 | AC37: 0 | AD37: 0 | AE37: =X37+Y37+Z37+AA37 -> 0 | AF37: =IFERROR(AE37/W37,0) -> 0
A38: 10009989 | B38: POTA REJOS FR C/U C/V S/OR 0.5-1.0 BL10 | C38: 15580 | K38: =+D38+E38+F38+G38+H38+I38+J38 -> 0 | O38: =+K38+C38-L38-M38-N38 -> 15580 | P38: =27000-1360-5700 -> 19940 | Q38: =+O38-P38 -> -4360 | S38: 10007162 | T38: =IFERROR(INDEX([1]Resumen!$K$3:$K$63,MATCH(S38,[1]Resumen!$C$3:$C$63,0)),0)*(1+U38*V38)/1000-51.89/1000 -> 1.8582869 | U38: 0.68 | V38: =3.597/3.52-1 -> 0.021875 | W38: =IF(Q38<0,0,Q38)/1000 -> 0 | X38: =IFERROR(T38*W38,0)*1000 -> 0 | Y38: =207.84*W38 -> 0 | Z38: =$Z$61/1500*W38 -> 0 | AA38: =$AA$61/1500*W38 -> 0 | AB38: =$AB$61/1500*W38 -> 0 | AC38: 0 | AD38: 0 | AE38: =X38+Y38+Z38+AA38 -> 0 | AF38: =IFERROR(AE38/W38,0) -> 0
A39: 10009187 | B39: POTA REJOS FR C/B S/U S/V S/OR 0.3-0.5 BL10 | C39: 340 | K39: =+D39+E39+F39+G39+H39+I39+J39 -> 0 | O39: =+K39+C39-L39-M39-N39 -> 340 | Q39: =+O39-P39 -> 340 | S39: 10007162 | T39: =IFERROR(INDEX([1]Resumen!$K$3:$K$63,MATCH(S39,[1]Resumen!$C$3:$C$63,0)),0)*(1+U39*V39)/1000-51.89/1000 -> 1.8582869 | U39: 0.68 | V39: =3.597/3.52-1 -> 0.021875 | W39: =IF(Q39<0,0,Q39)/1000 -> 0.34 | X39: =IFERROR(T39*W39,0)*1000 -> 631.81756 | Y39: =207.84*W39 -> 70.6656 | Z39: =$Z$61/1500*W39 -> 17.81124 | AA39: =$AA$61/1500*W39 -> 35.01388 | AB39: =$AB$61/1500*W39 -> 27.989786 | AC39: 0 | AD39: 0 | AE39: =X39+Y39+Z39+AA39 -> 755.30828 | AF39: =IFERROR(AE39/W39,0) -> 2221.4949
A40: 10007161 | B40: POTA REJOS FR C/B S/U S/V S/OR 0.5-1 BL1 0 | C40: 6420 | K40: =+D40+E40+F40+G40+H40+I40+J40 -> 0 | O40: =+K40+C40-L40-M40-N40 -> 6420 | Q40: =+O40-P40 -> 6420 | S40: 10007162 | T40: =IFERROR(INDEX([1]Resumen!$K$3:$K$63,MATCH(S40,[1]Resumen!$C$3:$C$63,0)),0)*(1+U40*V40)/1000-51.89/1000 -> 1.8582869 | U40: 0.68 | V40: =3.597/3.52-1 -> 0.021875 | W40: =IF(Q40<0,0,Q40)/1000 -> 6.42 | X40: =IFERROR(T40*W40,0)*1000 -> 11930.202 | Y40: =207.84*W40 -> 1334.3328 | Z40: =$Z$61/1500*W40 -> 336.31812 | AA40: =$AA$61/1500*W40 -> 661.14444 | AB40: =$AB$61/1500*W40 -> 528.51302 | AC40: 0 | AD40: 0 | AE40: =X40+Y40+Z40+AA40 -> 14261.998 | AF40: =IFERROR(AE40/W40,0) -> 2221.4949
...
