Workbook

Sheet RESUMEN AL 8-6-2026
C2: PERU FROST
C3: AVANCE COMERCIAL AL 8-6-2026
F5: RENTABILIDAD DEL INVENTARIO | T5: 46174 | W5: 46182 | Z5: 46185 | AC5: POR DEFINIR | AF5: TOTAL PROYECTADO | AT5: UNITARIOS POR TM
B6: Código | C6: Producto | D6: TM en Stock Libre | E6: CU | F6: Costo Ventas | G6: Gasto Ventas | H6: Gasto ADM | I6: Gasto Fin | J6: Depreciación | K6: Utilidad Neta | L6: Margen Neto | M6: Venta Equilibrio | N6: Precio Equilibrio x TM | O6: Precio | P6: Venta total | Q6: Utilidad | R6: Mg Neto | T6: TM | U6: Venta | V6: Precio x TM | W6: TM | X6: Venta | Y6: Precio x TM | Z6: TM | AA6: Venta | AB6: Precio x TM | AC6: TM | AD6: Venta | AE6: Precio x TM | AF6: TM | AG6: Venta | AH6: Precio x TM | AI6: Costo Ventas | AJ6: Gasto Ventas | AK6: Gasto Adm | AL6: Gasto Fin | AM6: Depreciación | AN6: Drawback | AO6: Utilidad Neta | AP6: Mg Neto % | AQ6: EBITDA | AR6: MG EBITDA | AT6: Precio x TM | AU6: Costo Ventas | AV6: Gasto Ventas | AW6: Gasto Adm | AX6: Gasto Fin | AY6: Depreciación | AZ6: Drawback | BA6: Utilidad Neta | BB6: EBITDA
B7: 10005721 | C7: POTA FILETE CONGELADO | D7: =TD!E4 -> 551.98 | E7: =IFERROR(F7/D7,0) -> 2116.1126 | F7: =TD!F4 -> 1168051.8 | G7: =TD!G4 -> 114723.52 | H7: =TD!H4 -> 36145.03 | I7: =TD!I4 -> 71055.005 | J7: =TD!J4 -> 56800.743 | K7: 0 | L7: 0 | M7: =F7+G7+H7+I7 -> 1389975.4 | N7: =IFERROR(M7/D7,0) -> 2518.1626 | O7: 2300 | P7: =O7*D7 -> 1269554 | Q7: =P7-M7 -> -120421.39 | R7: =IFERROR(Q7/P7,0) -> -0.094853304 | T7: {=SUM([3]Hoja2!$J$5:$J$16*([3]Hoja2!$G$5:$G$16=T$5)*([3]Hoja2!$L$5:$L$16=$C7))} -> 0 | U7: {=SUM([3]Hoja2!$K$5:$K$16*([3]Hoja2!$G$5:$G$16=T$5)*([3]Hoja2!$L$5:$L$16=$C7))} -> 0 | V7: =IFERROR(U7/T7,0) -> 0 | W7: {=SUM([3]Hoja2!$J$5:$J$16*([3]Hoja2!$G$5:$G$16=W$5)*([3]Hoja2!$L$5:$L$16=$C7))} -> 0 | X7: {=SUM([3]Hoja2!$K$5:$K$16*([3]Hoja2!$G$5:$G$16=W$5)*([3]Hoja2!$L$5:$L$16=$C7))} -> 0 | Y7: =IFERROR(X7/W7,0) -> 0 | Z7: {=SUM([3]Hoja2!$J$5:$J$16*([3]Hoja2!$G$5:$G$16=Z$5)*([3]Hoja2!$L$5:$L$16=$C7))} -> 0 | AA7: {=SUM([3]Hoja2!$K$5:$K$16*([3]Hoja2!$G$5:$G$16=Z$5)*([3]Hoja2!$L$5:$L$16=$C7))} -> 0 | AB7: =IFERROR(AA7/Z7,0) -> 0 | AC7: {=SUM([3]Hoja2!$J$5:$J$16*([3]Hoja2!$G$5:$G$16=AC$5)*([3]Hoja2!$L$5:$L$16=$C7))} -> 119 | AD7: {=SUM([3]Hoja2!$K$5:$K$16*([3]Hoja2!$G$5:$G$16=AC$5)*([3]Hoja2!$L$5:$L$16=$C7))} -> 249620 | AE7: =IFERROR(AD7/AC7,0) -> 2097.6471 | AF7: =T7+W7+Z7+AC7 -> 119 | AG7: =U7+X7+AA7+AD7 -> 249620 | AH7: =IFERROR(AG7/AF7,0) -> 2097.6471 | AI7: =-IFERROR(F7/D7*AF7,0) -> -251817.4 | AJ7: =-207.84*AF7 -> -24732.96 | AK7: =$AK$21/$AF$21*$AF7 -> -7792.4175 | AL7: =$AL$21/$AF$21*$AF7 -> -15318.573 | AM7: =$AM$21/$AF$21*$AF7 -> -12245.531 | AN7: =(AG7-AF7*$AK$25)*0.03 -> 7080.9859 | AO7: =AG7+SUM(AI7:AL7,AN7) -> -42960.363 | AP7: =IFERROR(AO7/AG7,0) -> -0.17210305 | AQ7: =AG7+AI7+AJ7+AK7+AN7-AM7 -> -15396.259 | AR7: =IFERROR(AQ7/AG7,0) -> -0.06167879 | AT7: =AH7 -> 2097.6471 | AU7: =IFERROR(AI7/$AF7,0) -> -2116.1126 | AV7: =IFERROR(AJ7/$AF7,0) -> -207.84 | AW7: =IFERROR(AK7/$AF7,0) -> -65.4825 | AX7: =IFERROR(AL7/$AF7,0) -> -128.7275 | AY7: =IFERROR(AM7/$AF7,0) -> -102.90363 | AZ7: =IFERROR(AN7/$AF7,0) -> 59.504083 | BA7: =IFERROR(AO7/$AF7,0) -> -361.01146 | BB7: =IFERROR(AQ7/$AF7,0) -> -129.38033
B8: 10005779 | C8: POTA NUCAS CONGELADAS | D8: =TD!E5 -> 126.84 | E8: =IFERROR(F8/D8,0) -> 1726.7388 | F8: =TD!F5 -> 219019.55 | G8: =TD!G5 -> 26362.426 | H8: =TD!H5 -> 8305.8003 | I8: =TD!I5 -> 16327.796 | J8: =TD!J5 -> 13052.296 | K8: 0 | L8: 0 | M8: =F8+G8+H8+I8 -> 270015.57 | N8: =IFERROR(M8/D8,0) -> 2128.7888 | O8: 1350 | P8: =O8*D8 -> 171234 | Q8: =P8-M8 -> -98781.568 | R8: =IFERROR(Q8/P8,0) -> -0.57688057 | T8: {=SUM([3]Hoja2!$J$5:$J$16*([3]Hoja2!$G$5:$G$16=T$5)*([3]Hoja2!$L$5:$L$16=$C8))} -> 0 | U8: {=SUM([3]Hoja2!$K$5:$K$16*([3]Hoja2!$G$5:$G$16=T$5)*([3]Hoja2!$L$5:$L$16=$C8))} -> 0 | V8: =IFERROR(U8/T8,0) -> 0 | W8: {=SUM([3]Hoja2!$J$5:$J$16*([3]Hoja2!$G$5:$G$16=W$5)*([3]Hoja2!$L$5:$L$16=$C8))} -> 26 | X8: {=SUM([3]Hoja2!$K$5:$K$16*([3]Hoja2!$G$5:$G$16=W$5)*([3]Hoja2!$L$5:$L$16=$C8))} -> 33800 | Y8: =IFERROR(X8/W8,0) -> 1300 | Z8: {=SUM([3]Hoja2!$J$5:$J$16*([3]Hoja2!$G$5:$G$16=Z$5)*([3]Hoja2!$L$5:$L$16=$C8))} -> 0 | AA8: {=SUM([3]Hoja2!$K$5:$K$16*([3]Hoja2!$G$5:$G$16=Z$5)*([3]Hoja2!$L$5:$L$16=$C8))} -> 0 | AB8: =IFERROR(AA8/Z8,0) -> 0 | AC8: {=SUM([3]Hoja2!$J$5:$J$16*([3]Hoja2!$G$5:$G$16=AC$5)*([3]Hoja2!$L$5:$L$16=$C8))} -> 114 | AD8: {=SUM([3]Hoja2!$K$5:$K$16*([3]Hoja2!$G$5:$G$16=AC$5)*([3]Hoja2!$L$5:$L$16=$C8))} -> 152320 | AE8: =IFERROR(AD8/AC8,0) -> 1336.1404 | AF8: =T8+W8+Z8+AC8 -> 140 | AG8: =U8+X8+AA8+AD8 -> 186120 | AH8: =IFERROR(AG8/AF8,0) -> 1329.4286 | AI8: =-IFERROR(F8/D8*AF8,0) -> -241743.43 | AJ8: =-207.84*AF8 -> -29097.6 | AK8: =$AK$21/$AF$21*$AF8 -> -9167.55 | AL8: =$AL$21/$AF$21*$AF8 -> -18021.85 | AM8: =$AM$21/$AF$21*$AF8 -> -14406.508 | AN8: =(AG8-AF8*$AK$25)*0.03 -> 5104.054 | AO8: =AG8+SUM(AI8:AL8,AN8) -> -106806.37 | AP8: =IFERROR(AO8/AG8,0) -> -0.57385759 | AQ8: =AG8+AI8+AJ8+AK8+AN8-AM8 -> -74378.017 | AR8: =IFERROR(AQ8/AG8,0) -> -0.39962399 | AT8: =AH8 -> 1329.4286 | AU8: =IFERROR(AI8/$AF8,0) -> -1726.7388 | AV8: =IFERROR(AJ8/$AF8,0) -> -207.84 | AW8: =IFERROR(AK8/$AF8,0) -> -65.4825 | AX8: =IFERROR(AL8/$AF8,0) -> -128.7275 | AY8: =IFERROR(AM8/$AF8,0) -> -102.90363 | AZ8: =IFERROR(AN8/$AF8,0) -> 36.457529 | BA8: =IFERROR(AO8/$AF8,0) -> -762.90268 | BB8: =IFERROR(AQ8/$AF8,0) -> -531.27155
B9: 10005781 | C9: POTA NUCAS FR ABIERTAS 0.3-0.5 BL10 S20 | D9: =TD!E6 -> 128.34 | E9: =IFERROR(F9/D9,0) -> 1830.8508 | F9: =TD!F6 -> 234971.39 | G9: =TD!G6 -> 26674.186 | H9: =TD!H6 -> 8404.0241 | I9: =TD!I6 -> 16520.887 | J9: =TD!J6 -> 13206.651 | K9: 0 | L9: 0 | M9: =F9+G9+H9+I9 -> 286570.48 | N9: =IFERROR(M9/D9,0) -> 2232.9008 | O9: 1350 | P9: =O9*D9 -> 173259 | Q9: =P9-M9 -> -113311.48 | R9: =IFERROR(Q9/P9,0) -> -0.65400057 | T9: {=SUM([3]Hoja2!$J$5:$J$16*([3]Hoja2!$G$5:$G$16=T$5)*([3]Hoja2!$L$5:$L$16=$C9))} -> 0 | U9: {=SUM([3]Hoja2!$K$5:$K$16*([3]Hoja2!$G$5:$G$16=T$5)*([3]Hoja2!$L$5:$L$16=$C9))} -> 0 | V9: =IFERROR(U9/T9,0) -> 0 | W9: {=SUM([3]Hoja2!$J$5:$J$16*([3]Hoja2!$G$5:$G$16=W$5)*([3]Hoja2!$L$5:$L$16=$C9))} -> 0 | X9: {=SUM([3]Hoja2!$K$5:$K$16*([3]Hoja2!$G$5:$G$16=W$5)*([3]Hoja2!$L$5:$L$16=$C9))} -> 0 | Y9: =IFERROR(X9/W9,0) -> 0 | Z9: {=SUM([3]Hoja2!$J$5:$J$16*([3]Hoja2!$G$5:$G$16=Z$5)*([3]Hoja2!$L$5:$L$16=$C9))} -> 0 | AA9: {=SUM([3]Hoja2!$K$5:$K$16*([3]Hoja2!$G$5:$G$16=Z$5)*([3]Hoja2!$L$5:$L$16=$C9))} -> 0 | AB9: =IFERROR(AA9/Z9,0) -> 0 | AC9: {=SUM([3]Hoja2!$J$5:$J$16*([3]Hoja2!$G$5:$G$16=AC$5)*([3]Hoja2!$L$5:$L$16=$C9))} -> 0 | AD9: {=SUM([3]Hoja2!$K$5:$K$16*([3]Hoja2!$G$5:$G$16=AC$5)*([3]Hoja2!$L$5:$L$16=$C9))} -> 0 | AE9: =IFERROR(AD9/AC9,0) -> 0 | AF9: =T9+W9+Z9+AC9 -> 0 | AG9: =U9+X9+AA9+AD9 -> 0 | AH9: =IFERROR(AG9/AF9,0) -> 0 | AI9: =-IFERROR(F9/D9*AF9,0) -> 0 | AJ9: =-207.84*AF9 -> 0 | AK9: =$AK$21/$AF$21*$AF9 -> 0 | AL9: =$AL$21/$AF$21*$AF9 -> 0 | AM9: =$AM$21/$AF$21*$AF9 -> 0 | AN9: =(AG9-AF9*$AK$25)*0.03 -> 0 | AO9: =AG9+SUM(AI9:AL9,AN9) -> 0 | AP9: =IFERROR(AO9/AG9,0) -> 0 | AQ9: =AG9+AI9+AJ9+AK9+AN9-AM9 -> 0 | AR9: =IFERROR(AQ9/AG9,0) -> 0 | AT9: =AH9 -> 0 | AU9: =IFERROR(AI9/$AF9,0) -> 0 | AV9: =IFERROR(AJ9/$AF9,0) -> 0 | AW9: =IFERROR(AK9/$AF9,0) -> 0 | AX9: =IFERROR(AL9/$AF9,0) -> 0 | AY9: =IFERROR(AM9/$AF9,0) -> 0 | AZ9: =IFERROR(AN9/$AF9,0) -> 0 | BA9: =IFERROR(AO9/$AF9,0) -> 0 | BB9: =IFERROR(AQ9/$AF9,0) -> 0
B10: 10006719 | C10: POTA ALAS CONGELADAS | D10: =TD!E7 -> 20.14 | E10: =IFERROR(F10/D10,0) -> 2015.4661 | F10: =TD!F7 -> 40591.488 | G10: =TD!G7 -> 4185.8976 | H10: =TD!H7 -> 1318.8176 | I10: =TD!I7 -> 2592.5719 | J10: =TD!J7 -> 2072.479 | K10: 0 | L10: 0 | M10: =F10+G10+H10+I10 -> 48688.775 | N10: =IFERROR(M10/D10,0) -> 2417.5161 | O10: 2300 | P10: =O10*D10 -> 46322 | Q10: =P10-M10 -> -2366.7749 | R10: =IFERROR(Q10/P10,0) -> -0.051093971 | T10: {=SUM([3]Hoja2!$J$5:$J$16*([3]Hoja2!$G$5:$G$16=T$5)*([3]Hoja2!$L$5:$L$16=$C10))} -> 0 | U10: {=SUM([3]Hoja2!$K$5:$K$16*([3]Hoja2!$G$5:$G$16=T$5)*([3]Hoja2!$L$5:$L$16=$C10))} -> 0 | V10: =IFERROR(U10/T10,0) -> 0 | W10: {=SUM([3]Hoja2!$J$5:$J$16*([3]Hoja2!$G$5:$G$16=W$5)*([3]Hoja2!$L$5:$L$16=$C10))} -> 0 | X10: {=SUM([3]Hoja2!$K$5:$K$16*([3]Hoja2!$G$5:$G$16=W$5)*([3]Hoja2!$L$5:$L$16=$C10))} -> 0 | Y10: =IFERROR(X10/W10,0) -> 0 | Z10: {=SUM([3]Hoja2!$J$5:$J$16*([3]Hoja2!$G$5:$G$16=Z$5)*([3]Hoja2!$L$5:$L$16=$C10))} -> 24 | AA10: {=SUM([3]Hoja2!$K$5:$K$16*([3]Hoja2!$G$5:$G$16=Z$5)*([3]Hoja2!$L$5:$L$16=$C10))} -> 50400 | AB10: =IFERROR(AA10/Z10,0) -> 2100 | AC10: {=SUM([3]Hoja2!$J$5:$J$16*([3]Hoja2!$G$5:$G$16=AC$5)*([3]Hoja2!$L$5:$L$16=$C10))} -> 75 | AD10: {=SUM([3]Hoja2!$K$5:$K$16*([3]Hoja2!$G$5:$G$16=AC$5)*([3]Hoja2!$L$5:$L$16=$C10))} -> 160200 | AE10: =IFERROR(AD10/AC10,0) -> 2136 | AF10: =T10+W10+Z10+AC10 -> 99 | AG10: =U10+X10+AA10+AD10 -> 210600 | AH10: =IFERROR(AG10/AF10,0) -> 2127.2727 | AI10: =-IFERROR(F10/D10*AF10,0) -> -199531.15 | AJ10: =-207.84*AF10 -> -20576.16 | AK10: =$AK$21/$AF$21*$AF10 -> -6482.7675 | AL10: =$AL$21/$AF$21*$AF10 -> -12744.023 | AM10: =$AM$21/$AF$21*$AF10 -> -10187.459 | AN10: =(AG10-AF10*$AK$25)*0.03 -> 5978.8925 | AO10: =AG10+SUM(AI10:AL10,AN10) -> -22755.205 | AP10: =IFERROR(AO10/AG10,0) -> -0.1080494 | AQ10: =AG10+AI10+AJ10+AK10+AN10-AM10 -> 176.27674 | AR10: =IFERROR(AQ10/AG10,0) -> 0.00083702156 | AT10: =AH10 -> 2127.2727 | AU10: =IFERROR(AI10/$AF10,0) -> -2015.4661 | AV10: =IFERROR(AJ10/$AF10,0) -> -207.84 | AW10: =IFERROR(AK10/$AF10,0) -> -65.4825 | AX10: =IFERROR(AL10/$AF10,0) -> -128.7275 | AY10: =IFERROR(AM10/$AF10,0) -> -102.90363 | AZ10: =IFERROR(AN10/$AF10,0) -> 60.392853 | BA10: =IFERROR(AO10/$AF10,0) -> -229.85055 | BB10: =IFERROR(AQ10/$AF10,0) -> 1.7805731
B11: 10006720 | C11: POTA ALAS CONGELADAS FR C/P C/C 0.5-1 BL10 S20 | D11: =TD!E8 -> 33.5 | E11: =IFERROR(F11/D11,0) -> 1501.1373 | F11: =TD!F8 -> 50288.099 | G11: =TD!G8 -> 6962.64 | H11: =TD!H8 -> 2193.6638 | I11: =TD!I8 -> 4312.3713 | J11: =TD!J8 -> 3447.2714 | K11: 0 | L11: 0 | M11: =F11+G11+H11+I11 -> 63756.774 | N11: =IFERROR(M11/D11,0) -> 1903.1873 | O11: 2300 | P11: =O11*D11 -> 77050 | Q11: =P11-M11 -> 13293.226 | R11: =IFERROR(Q11/P11,0) -> 0.17252726 | T11: {=SUM([3]Hoja2!$J$5:$J$16*([3]Hoja2!$G$5:$G$16=T$5)*([3]Hoja2!$L$5:$L$16=$C11))} -> 0 | U11: {=SUM([3]Hoja2!$K$5:$K$16*([3]Hoja2!$G$5:$G$16=T$5)*([3]Hoja2!$L$5:$L$16=$C11))} -> 0 | V11: =IFERROR(U11/T11,0) -> 0 | W11: {=SUM([3]Hoja2!$J$5:$J$16*([3]Hoja2!$G$5:$G$16=W$5)*([3]Hoja2!$L$5:$L$16=$C11))} -> 0 | X11: {=SUM([3]Hoja2!$K$5:$K$16*([3]Hoja2!$G$5:$G$16=W$5)*([3]Hoja2!$L$5:$L$16=$C11))} -> 0 | Y11: =IFERROR(X11/W11,0) -> 0 | Z11: {=SUM([3]Hoja2!$J$5:$J$16*([3]Hoja2!$G$5:$G$16=Z$5)*([3]Hoja2!$L$5:$L$16=$C11))} -> 0 | AA11: {=SUM([3]Hoja2!$K$5:$K$16*([3]Hoja2!$G$5:$G$16=Z$5)*([3]Hoja2!$L$5:$L$16=$C11))} -> 0 | AB11: =IFERROR(AA11/Z11,0) -> 0 | AC11: {=SUM([3]Hoja2!$J$5:$J$16*([3]Hoja2!$G$5:$G$16=AC$5)*([3]Hoja2!$L$5:$L$16=$C11))} -> 0 | AD11: {=SUM([3]Hoja2!$K$5:$K$16*([3]Hoja2!$G$5:$G$16=AC$5)*([3]Hoja2!$L$5:$L$16=$C11))} -> 0 | AE11: =IFERROR(AD11/AC11,0) -> 0 | AF11: =T11+W11+Z11+AC11 -> 0 | AG11: =U11+X11+AA11+AD11 -> 0 | AH11: =IFERROR(AG11/AF11,0) -> 0 | AI11: =-IFERROR(F11/D11*AF11,0) -> 0 | AJ11: =-207.84*AF11 -> 0 | AK11: =$AK$21/$AF$21*$AF11 -> 0 | AL11: =$AL$21/$AF$21*$AF11 -> 0 | AM11: =$AM$21/$AF$21*$AF11 -> 0 | AN11: =(AG11-AF11*$AK$25)*0.03 -> 0 | AO11: =AG11+SUM(AI11:AL11,AN11) -> 0 | AP11: =IFERROR(AO11/AG11,0) -> 0 | AQ11: =AG11+AI11+AJ11+AK11+AN11-AM11 -> 0 | AR11: =IFERROR(AQ11/AG11,0) -> 0 | AT11: =AH11 -> 0 | AU11: =IFERROR(AI11/$AF11,0) -> 0 | AV11: =IFERROR(AJ11/$AF11,0) -> 0 | AW11: =IFERROR(AK11/$AF11,0) -> 0 | AX11: =IFERROR(AL11/$AF11,0) -> 0 | AY11: =IFERROR(AM11/$AF11,0) -> 0 | AZ11: =IFERROR(AN11/$AF11,0) -> 0 | BA11: =IFERROR(AO11/$AF11,0) -> 0 | BB11: =IFERROR(AQ11/$AF11,0) -> 0
B12: 10007050 | C12: POTA REJOS COCIDOS | D12: =TD!E9 -> 93.215 | E12: =IFERROR(F12/D12,0) -> 1542.069 | F12: =TD!F9 -> 143743.96 | G12: =TD!G9 -> 19373.806 | H12: =TD!H9 -> 6103.9512 | I12: =TD!I9 -> 11999.334 | J12: =TD!J9 -> 9592.1614 | K12: 0 | L12: 0 | M12: =F12+G12+H12+I12 -> 181221.05 | N12: =IFERROR(M12/D12,0) -> 1944.119 | P12: =O12*D12 -> 0 | Q12: =P12-M12 -> -181221.05 | R12: =IFERROR(Q12/P12,0) -> 0 | T12: {=SUM([3]Hoja2!$J$5:$J$16*([3]Hoja2!$G$5:$G$16=T$5)*([3]Hoja2!$L$5:$L$16=$C12))} -> 0 | U12: {=SUM([3]Hoja2!$K$5:$K$16*([3]Hoja2!$G$5:$G$16=T$5)*([3]Hoja2!$L$5:$L$16=$C12))} -> 0 | V12: =IFERROR(U12/T12,0) -> 0 | W12: {=SUM([3]Hoja2!$J$5:$J$16*([3]Hoja2!$G$5:$G$16=W$5)*([3]Hoja2!$L$5:$L$16=$C12))} -> 0 | X12: {=SUM([3]Hoja2!$K$5:$K$16*([3]Hoja2!$G$5:$G$16=W$5)*([3]Hoja2!$L$5:$L$16=$C12))} -> 0 | Y12: =IFERROR(X12/W12,0) -> 0 | Z12: {=SUM([3]Hoja2!$J$5:$J$16*([3]Hoja2!$G$5:$G$16=Z$5)*([3]Hoja2!$L$5:$L$16=$C12))} -> 0 | AA12: {=SUM([3]Hoja2!$K$5:$K$16*([3]Hoja2!$G$5:$G$16=Z$5)*([3]Hoja2!$L$5:$L$16=$C12))} -> 0 | AB12: =IFERROR(AA12/Z12,0) -> 0 | AC12: {=SUM([3]Hoja2!$J$5:$J$16*([3]Hoja2!$G$5:$G$16=AC$5)*([3]Hoja2!$L$5:$L$16=$C12))} -> 0 | AD12: {=SUM([3]Hoja2!$K$5:$K$16*([3]Hoja2!$G$5:$G$16=AC$5)*([3]Hoja2!$L$5:$L$16=$C12))} -> 0 | AE12: =IFERROR(AD12/AC12,0) -> 0 | AF12: =T12+W12+Z12+AC12 -> 0 | AG12: =U12+X12+AA12+AD12 -> 0 | AH12: =IFERROR(AG12/AF12,0) -> 0 | AI12: =-IFERROR(F12/D12*AF12,0) -> 0 | AJ12: =-207.84*AF12 -> 0 | AK12: =$AK$21/$AF$21*$AF12 -> 0 | AL12: =$AL$21/$AF$21*$AF12 -> 0 | AM12: =$AM$21/$AF$21*$AF12 -> 0 | AN12: =(AG12-AF12*$AK$25)*0.03 -> 0 | AO12: =AG12+SUM(AI12:AL12,AN12) -> 0 | AP12: =IFERROR(AO12/AG12,0) -> 0 | AQ12: =AG12+AI12+AJ12+AK12+AN12-AM12 -> 0 | AR12: =IFERROR(AQ12/AG12,0) -> 0 | AT12: =AH12 -> 0 | AU12: =IFERROR(AI12/$AF12,0) -> 0 | AV12: =IFERROR(AJ12/$AF12,0) -> 0 | AW12: =IFERROR(AK12/$AF12,0) -> 0 | AX12: =IFERROR(AL12/$AF12,0) -> 0 | AY12: =IFERROR(AM12/$AF12,0) -> 0 | AZ12: =IFERROR(AN12/$AF12,0) -> 0 | BA12: =IFERROR(AO12/$AF12,0) -> 0 | BB12: =IFERROR(AQ12/$AF12,0) -> 0
B13: 10007162 | C13: POTA REJOS CONGELADOS | D13: =TD!E10 -> 99.26 | E13: =IFERROR(F13/D13,0) -> 1858.2869 | F13: =TD!F10 -> 184453.56 | G13: =TD!G10 -> 20630.198 | H13: =TD!H10 -> 6499.793 | I13: =TD!I10 -> 12777.492 | J13: =TD!J10 -> 10214.214 | K13: 0 | L13: 0 | M13: =F13+G13+H13+I13 -> 224361.04 | N13: =IFERROR(M13/D13,0) -> 2260.3369 | O13: 3000 | P13: =O13*D13 -> 297780 | Q13: =P13-M13 -> 73418.955 | R13: =IFERROR(Q13/P13,0) -> 0.24655435 | T13: {=SUM([3]Hoja2!$J$5:$J$16*([3]Hoja2!$G$5:$G$16=T$5)*([3]Hoja2!$L$5:$L$16=$C13))} -> 0 | U13: {=SUM([3]Hoja2!$K$5:$K$16*([3]Hoja2!$G$5:$G$16=T$5)*([3]Hoja2!$L$5:$L$16=$C13))} -> 0 | V13: =IFERROR(U13/T13,0) -> 0 | W13: {=SUM([3]Hoja2!$J$5:$J$16*([3]Hoja2!$G$5:$G$16=W$5)*([3]Hoja2!$L$5:$L$16=$C13))} -> 0 | X13: {=SUM([3]Hoja2!$K$5:$K$16*([3]Hoja2!$G$5:$G$16=W$5)*([3]Hoja2!$L$5:$L$16=$C13))} -> 0 | Y13: =IFERROR(X13/W13,0) -> 0 | Z13: {=SUM([3]Hoja2!$J$5:$J$16*([3]Hoja2!$G$5:$G$16=Z$5)*([3]Hoja2!$L$5:$L$16=$C13))} -> 0 | AA13: {=SUM([3]Hoja2!$K$5:$K$16*([3]Hoja2!$G$5:$G$16=Z$5)*([3]Hoja2!$L$5:$L$16=$C13))} -> 0 | AB13: =IFERROR(AA13/Z13,0) -> 0 | AC13: {=SUM([3]Hoja2!$J$5:$J$16*([3]Hoja2!$G$5:$G$16=AC$5)*([3]Hoja2!$L$5:$L$16=$C13))} -> 159 | AD13: {=SUM([3]Hoja2!$K$5:$K$16*([3]Hoja2!$G$5:$G$16=AC$5)*([3]Hoja2!$L$5:$L$16=$C13))} -> 452550 | AE13: =IFERROR(AD13/AC13,0) -> 2846.2264 | AF13: =T13+W13+Z13+AC13 -> 159 | AG13: =U13+X13+AA13+AD13 -> 452550 | AH13: =IFERROR(AG13/AF13,0) -> 2846.2264 | AI13: =-IFERROR(F13/D13*AF13,0) -> -295467.62 | AJ13: =-207.84*AF13 -> -33046.56 | AK13: =$AK$21/$AF$21*$AF13 -> -10411.718 | AL13: =$AL$21/$AF$21*$AF13 -> -20467.673 | AM13: =$AM$21/$AF$21*$AF13 -> -16361.676 | AN13: =(AG13-AF13*$AK$25)*0.03 -> 13031.873 | AO13: =AG13+SUM(AI13:AL13,AN13) -> 106188.3 | AP13: =IFERROR(AO13/AG13,0) -> 0.23464435 | AQ13: =AG13+AI13+AJ13+AK13+AN13-AM13 -> 143017.65 | AR13: =IFERROR(AQ13/AG13,0) -> 0.31602618 | AT13: =AH13 -> 2846.2264 | AU13: =IFERROR(AI13/$AF13,0) -> -1858.2869 | AV13: =IFERROR(AJ13/$AF13,0) -> -207.84 | AW13: =IFERROR(AK13/$AF13,0) -> -65.4825 | AX13: =IFERROR(AL13/$AF13,0) -> -128.7275 | AY13: =IFERROR(AM13/$AF13,0) -> -102.90363 | AZ13: =IFERROR(AN13/$AF13,0) -> 81.961464 | BA13: =IFERROR(AO13/$AF13,0) -> 667.85094 | BB13: =IFERROR(AQ13/$AF13,0) -> 899.48207
B14: 10007567 | C14: POTA REPRODUCTORES | D14: =TD!E11 -> 91.96 | E14: =IFERROR(F14/D14,0) -> 1796.4412 | F14: =TD!F11 -> 165200.73 | G14: =TD!G11 -> 19112.966 | H14: =TD!H11 -> 6021.7707 | I14: =TD!I11 -> 11837.781 | J14: =TD!J11 -> 9463.0174 | K14: 0 | L14: 0 | M14: =F14+G14+H14+I14 -> 202173.25 | N14: =IFERROR(M14/D14,0) -> 2198.4912 | O14: 3000 | P14: =O14*D14 -> 275880 | Q14: =P14-M14 -> 73706.75 | R14: =IFERROR(Q14/P14,0) -> 0.2671696 | T14: {=SUM([3]Hoja2!$J$5:$J$16*([3]Hoja2!$G$5:$G$16=T$5)*([3]Hoja2!$L$5:$L$16=$C14))} -> 0 | U14: {=SUM([3]Hoja2!$K$5:$K$16*([3]Hoja2!$G$5:$G$16=T$5)*([3]Hoja2!$L$5:$L$16=$C14))} -> 0 | V14: =IFERROR(U14/T14,0) -> 0 | W14: {=SUM([3]Hoja2!$J$5:$J$16*([3]Hoja2!$G$5:$G$16=W$5)*([3]Hoja2!$L$5:$L$16=$C14))} -> 0 | X14: {=SUM([3]Hoja2!$K$5:$K$16*([3]Hoja2!$G$5:$G$16=W$5)*([3]Hoja2!$L$5:$L$16=$C14))} -> 0 | Y14: =IFERROR(X14/W14,0) -> 0 | Z14: {=SUM([3]Hoja2!$J$5:$J$16*([3]Hoja2!$G$5:$G$16=Z$5)*([3]Hoja2!$L$5:$L$16=$C14))} -> 0 | AA14: {=SUM([3]Hoja2!$K$5:$K$16*([3]Hoja2!$G$5:$G$16=Z$5)*([3]Hoja2!$L$5:$L$16=$C14))} -> 0 | AB14: =IFERROR(AA14/Z14,0) -> 0 | AC14: {=SUM([3]Hoja2!$J$5:$J$16*([3]Hoja2!$G$5:$G$16=AC$5)*([3]Hoja2!$L$5:$L$16=$C14))} -> 0 | AD14: {=SUM([3]Hoja2!$K$5:$K$16*([3]Hoja2!$G$5:$G$16=AC$5)*([3]Hoja2!$L$5:$L$16=$C14))} -> 0 | AE14: =IFERROR(AD14/AC14,0) -> 0 | AF14: =T14+W14+Z14+AC14 -> 0 | AG14: =U14+X14+AA14+AD14 -> 0 | AH14: =IFERROR(AG14/AF14,0) -> 0 | AI14: =-IFERROR(F14/D14*AF14,0) -> 0 | AJ14: =-207.84*AF14 -> 0 | AK14: =$AK$21/$AF$21*$AF14 -> 0 | AL14: =$AL$21/$AF$21*$AF14 -> 0 | AM14: =$AM$21/$AF$21*$AF14 -> 0 | AN14: =(AG14-AF14*$AK$25)*0.03 -> 0 | AO14: =AG14+SUM(AI14:AL14,AN14) -> 0 | AP14: =IFERROR(AO14/AG14,0) -> 0 | AQ14: =AG14+AI14+AJ14+AK14+AN14-AM14 -> 0 | AR14: =IFERROR(AQ14/AG14,0) -> 0 | AT14: =AH14 -> 0 | AU14: =IFERROR(AI14/$AF14,0) -> 0 | AV14: =IFERROR(AJ14/$AF14,0) -> 0 | AW14: =IFERROR(AK14/$AF14,0) -> 0 | AX14: =IFERROR(AL14/$AF14,0) -> 0 | AY14: =IFERROR(AM14/$AF14,0) -> 0 | AZ14: =IFERROR(AN14/$AF14,0) -> 0 | BA14: =IFERROR(AO14/$AF14,0) -> 0 | BB14: =IFERROR(AQ14/$AF14,0) -> 0
B15: 10007969 | C15: POTA CONOS | D15: =TD!E12 -> 7.64 | E15: =IFERROR(F15/D15,0) -> 1466.0036 | F15: =TD!F12 -> 11200.268 | G15: =TD!G12 -> 1587.8976 | H15: =TD!H12 -> 500.2863 | I15: =TD!I12 -> 983.4781 | J15: =TD!J12 -> 786.1837 | K15: 0 | L15: 0 | M15: =F15+G15+H15+I15 -> 14271.93 | N15: =IFERROR(M15/D15,0) -> 1868.0536 | O15: 1730 | P15: =O15*D15 -> 13217.2 | Q15: =P15-M15 -> -1054.7296 | R15: =IFERROR(Q15/P15,0) -> -0.07979978 | T15: {=SUM([3]Hoja2!$J$5:$J$16*([3]Hoja2!$G$5:$G$16=T$5)*([3]Hoja2!$L$5:$L$16=$C15))} -> 0 | U15: {=SUM([3]Hoja2!$K$5:$K$16*([3]Hoja2!$G$5:$G$16=T$5)*([3]Hoja2!$L$5:$L$16=$C15))} -> 0 | V15: =IFERROR(U15/T15,0) -> 0 | W15: {=SUM([3]Hoja2!$J$5:$J$16*([3]Hoja2!$G$5:$G$16=W$5)*([3]Hoja2!$L$5:$L$16=$C15))} -> 0 | X15: {=SUM([3]Hoja2!$K$5:$K$16*([3]Hoja2!$G$5:$G$16=W$5)*([3]Hoja2!$L$5:$L$16=$C15))} -> 0 | Y15: =IFERROR(X15/W15,0) -> 0 | Z15: {=SUM([3]Hoja2!$J$5:$J$16*([3]Hoja2!$G$5:$G$16=Z$5)*([3]Hoja2!$L$5:$L$16=$C15))} -> 0 | AA15: {=SUM([3]Hoja2!$K$5:$K$16*([3]Hoja2!$G$5:$G$16=Z$5)*([3]Hoja2!$L$5:$L$16=$C15))} -> 0 | AB15: =IFERROR(AA15/Z15,0) -> 0 | AC15: {=SUM([3]Hoja2!$J$5:$J$16*([3]Hoja2!$G$5:$G$16=AC$5)*([3]Hoja2!$L$5:$L$16=$C15))} -> 0 | AD15: {=SUM([3]Hoja2!$K$5:$K$16*([3]Hoja2!$G$5:$G$16=AC$5)*([3]Hoja2!$L$5:$L$16=$C15))} -> 0 | AE15: =IFERROR(AD15/AC15,0) -> 0 | AF15: =T15+W15+Z15+AC15 -> 0 | AG15: =U15+X15+AA15+AD15 -> 0 | AH15: =IFERROR(AG15/AF15,0) -> 0 | AI15: =-IFERROR(F15/D15*AF15,0) -> 0 | AJ15: =-207.84*AF15 -> 0 | AK15: =$AK$21/$AF$21*$AF15 -> 0 | AL15: =$AL$21/$AF$21*$AF15 -> 0 | AM15: =$AM$21/$AF$21*$AF15 -> 0 | AN15: =(AG15-AF15*$AK$25)*0.03 -> 0 | AO15: =AG15+SUM(AI15:AL15,AN15) -> 0 | AP15: =IFERROR(AO15/AG15,0) -> 0 | AQ15: =AG15+AI15+AJ15+AK15+AN15-AM15 -> 0 | AR15: =IFERROR(AQ15/AG15,0) -> 0 | AT15: =AH15 -> 0 | AU15: =IFERROR(AI15/$AF15,0) -> 0 | AV15: =IFERROR(AJ15/$AF15,0) -> 0 | AW15: =IFERROR(AK15/$AF15,0) -> 0 | AX15: =IFERROR(AL15/$AF15,0) -> 0 | AY15: =IFERROR(AM15/$AF15,0) -> 0 | AZ15: =IFERROR(AN15/$AF15,0) -> 0 | BA15: =IFERROR(AO15/$AF15,0) -> 0 | BB15: =IFERROR(AQ15/$AF15,0) -> 0
B16: 10009207 | C16: POTA LABIOS FR S/COD BL10 S20 | D16: =TD!E13 -> 4.86 | E16: =IFERROR(F16/D16,0) -> 1517.6903 | F16: =TD!F13 -> 7375.975 | G16: =TD!G13 -> 1010.1024 | H16: =TD!H13 -> 318.24495 | I16: =TD!I13 -> 625.61565 | J16: =TD!J13 -> 500.11162 | K16: 0 | L16: 0 | M16: =F16+G16+H16+I16 -> 9329.938 | N16: =IFERROR(M16/D16,0) -> 1919.7403 | P16: =O16*D16 -> 0 | Q16: =P16-M16 -> -9329.938 | R16: =IFERROR(Q16/P16,0) -> 0 | T16: {=SUM([3]Hoja2!$J$5:$J$16*([3]Hoja2!$G$5:$G$16=T$5)*([3]Hoja2!$L$5:$L$16=$C16))} -> 26 | U16: {=SUM([3]Hoja2!$K$5:$K$16*([3]Hoja2!$G$5:$G$16=T$5)*([3]Hoja2!$L$5:$L$16=$C16))} -> 36400 | V16: =IFERROR(U16/T16,0) -> 1400 | W16: {=SUM([3]Hoja2!$J$5:$J$16*([3]Hoja2!$G$5:$G$16=W$5)*([3]Hoja2!$L$5:$L$16=$C16))} -> 0 | X16: {=SUM([3]Hoja2!$K$5:$K$16*([3]Hoja2!$G$5:$G$16=W$5)*([3]Hoja2!$L$5:$L$16=$C16))} -> 0 | Y16: =IFERROR(X16/W16,0) -> 0 | Z16: {=SUM([3]Hoja2!$J$5:$J$16*([3]Hoja2!$G$5:$G$16=Z$5)*([3]Hoja2!$L$5:$L$16=$C16))} -> 0 | AA16: {=SUM([3]Hoja2!$K$5:$K$16*([3]Hoja2!$G$5:$G$16=Z$5)*([3]Hoja2!$L$5:$L$16=$C16))} -> 0 | AB16: =IFERROR(AA16/Z16,0) -> 0 | AC16: {=SUM([3]Hoja2!$J$5:$J$16*([3]Hoja2!$G$5:$G$16=AC$5)*([3]Hoja2!$L$5:$L$16=$C16))} -> 0 | AD16: {=SUM([3]Hoja2!$K$5:$K$16*([3]Hoja2!$G$5:$G$16=AC$5)*([3]Hoja2!$L$5:$L$16=$C16))} -> 0 | AE16: =IFERROR(AD16/AC16,0) -> 0 | AF16: =T16+W16+Z16+AC16 -> 26 | AG16: =U16+X16+AA16+AD16 -> 36400 | AH16: =IFERROR(AG16/AF16,0) -> 1400 | AI16: =-'[1]Stock Libre'!T9*AF16*1000 -> -39459.949 | AJ16: =-207.84*AF16 -> -5403.84 | AK16: =$AK$21/$AF$21*$AF16 -> -1702.545 | AL16: =$AL$21/$AF$21*$AF16 -> -3346.915 | AM16: =$AM$21/$AF$21*$AF16 -> -2675.4943 | AN16: =(AG16-AF16*$AK$25)*0.03 -> 1002.9415 | AO16: =AG16+SUM(AI16:AL16,AN16) -> -12510.307 | AP16: =IFERROR(AO16/AG16,0) -> -0.34368975 | AQ16: =AG16+AI16+AJ16+AK16+AN16-AM16 -> -6487.8978 | AR16: =IFERROR(AQ16/AG16,0) -> -0.17823895 | AT16: =AH16 -> 1400 | AU16: =IFERROR(AI16/$AF16,0) -> -1517.6903 | AV16: =IFERROR(AJ16/$AF16,0) -> -207.84 | AW16: =IFERROR(AK16/$AF16,0) -> -65.4825 | AX16: =IFERROR(AL16/$AF16,0) -> -128.7275 | AY16: =IFERROR(AM16/$AF16,0) -> -102.90363 | AZ16: =IFERROR(AN16/$AF16,0) -> 38.574672 | BA16: =IFERROR(AO16/$AF16,0) -> -481.16566 | BB16: =IFERROR(AQ16/$AF16,0) -> -249.53453
B17: 10009239 | C17: POTA FILETE DARUMA | D17: =TD!E14 -> 0.3 | E17: =IFERROR(F17/D17,0) -> 3431.9523 | F17: =TD!F14 -> 1029.5857 | G17: =TD!G14 -> 62.352 | H17: =TD!H14 -> 19.64475 | I17: =TD!I14 -> 38.61825 | J17: =TD!J14 -> 30.871088 | K17: 0 | L17: 0 | M17: =F17+G17+H17+I17 -> 1150.2007 | N17: =IFERROR(M17/D17,0) -> 3834.0023 | O17: 3900 | P17: =O17*D17 -> 1170 | Q17: =P17-M17 -> 19.79932 | R17: =IFERROR(Q17/P17,0) -> 0.016922496 | T17: {=SUM([3]Hoja2!$J$5:$J$16*([3]Hoja2!$G$5:$G$16=T$5)*([3]Hoja2!$L$5:$L$16=$C17))} -> 0 | U17: {=SUM([3]Hoja2!$K$5:$K$16*([3]Hoja2!$G$5:$G$16=T$5)*([3]Hoja2!$L$5:$L$16=$C17))} -> 0 | V17: =IFERROR(U17/T17,0) -> 0 | W17: {=SUM([3]Hoja2!$J$5:$J$16*([3]Hoja2!$G$5:$G$16=W$5)*([3]Hoja2!$L$5:$L$16=$C17))} -> 0 | X17: {=SUM([3]Hoja2!$K$5:$K$16*([3]Hoja2!$G$5:$G$16=W$5)*([3]Hoja2!$L$5:$L$16=$C17))} -> 0 | Y17: =IFERROR(X17/W17,0) -> 0 | Z17: {=SUM([3]Hoja2!$J$5:$J$16*([3]Hoja2!$G$5:$G$16=Z$5)*([3]Hoja2!$L$5:$L$16=$C17))} -> 0 | AA17: {=SUM([3]Hoja2!$K$5:$K$16*([3]Hoja2!$G$5:$G$16=Z$5)*([3]Hoja2!$L$5:$L$16=$C17))} -> 0 | AB17: =IFERROR(AA17/Z17,0) -> 0 | AC17: {=SUM([3]Hoja2!$J$5:$J$16*([3]Hoja2!$G$5:$G$16=AC$5)*([3]Hoja2!$L$5:$L$16=$C17))} -> 0 | AD17: {=SUM([3]Hoja2!$K$5:$K$16*([3]Hoja2!$G$5:$G$16=AC$5)*([3]Hoja2!$L$5:$L$16=$C17))} -> 0 | AE17: =IFERROR(AD17/AC17,0) -> 0 | AF17: =T17+W17+Z17+AC17 -> 0 | AG17: =U17+X17+AA17+AD17 -> 0 | AH17: =IFERROR(AG17/AF17,0) -> 0 | AI17: =-'[1]Stock Libre'!T45*1000*AF17 -> 0 | AJ17: =-207.84*AF17 -> 0 | AK17: =$AK$21/$AF$21*$AF17 -> 0 | AL17: =$AL$21/$AF$21*$AF17 -> 0 | AM17: =$AM$21/$AF$21*$AF17 -> 0 | AN17: =(AG17-AF17*$AK$25)*0.03 -> 0 | AO17: =AG17+SUM(AI17:AL17,AN17) -> 0 | AP17: =IFERROR(AO17/AG17,0) -> 0 | AQ17: =AG17+AI17+AJ17+AK17+AN17-AM17 -> 0 | AR17: =IFERROR(AQ17/AG17,0) -> 0 | AT17: =AH17 -> 0 | AU17: =IFERROR(AI17/$AF17,0) -> 0 | AV17: =IFERROR(AJ17/$AF17,0) -> 0 | AW17: =IFERROR(AK17/$AF17,0) -> 0 | AX17: =IFERROR(AL17/$AF17,0) -> 0 | AY17: =IFERROR(AM17/$AF17,0) -> 0 | AZ17: =IFERROR(AN17/$AF17,0) -> 0 | BA17: =IFERROR(AO17/$AF17,0) -> 0 | BB17: =IFERROR(AQ17/$AF17,0) -> 0
B18: 10009334 | C18: POTA ALAS COCIDAS | D18: =TD!E15 -> 0 | E18: =IFERROR(F18/D18,0) -> 0 | F18: =TD!F15 -> 0 | G18: =TD!G15 -> 0 | H18: =TD!H15 -> 0 | I18: =TD!I15 -> 0 | J18: =TD!J15 -> 0 | K18: 0 | L18: 0 | M18: =F18+G18+H18+I18 -> 0 | N18: =IFERROR(M18/D18,0) -> 0 | O18: 4300 | P18: =O18*D18 -> 0 | Q18: =P18-M18 -> 0 | R18: =IFERROR(Q18/P18,0) -> 0 | T18: {=SUM([3]Hoja2!$J$5:$J$16*([3]Hoja2!$G$5:$G$16=T$5)*([3]Hoja2!$L$5:$L$16=$C18))} -> 0 | U18: {=SUM([3]Hoja2!$K$5:$K$16*([3]Hoja2!$G$5:$G$16=T$5)*([3]Hoja2!$L$5:$L$16=$C18))} -> 0 | V18: =IFERROR(U18/T18,0) -> 0 | W18: {=SUM([3]Hoja2!$J$5:$J$16*([3]Hoja2!$G$5:$G$16=W$5)*([3]Hoja2!$L$5:$L$16=$C18))} -> 27 | X18: {=SUM([3]Hoja2!$K$5:$K$16*([3]Hoja2!$G$5:$G$16=W$5)*([3]Hoja2!$L$5:$L$16=$C18))} -> 116100 | Y18: =IFERROR(X18/W18,0) -> 4300 | Z18: {=SUM([3]Hoja2!$J$5:$J$16*([3]Hoja2!$G$5:$G$16=Z$5)*([3]Hoja2!$L$5:$L$16=$C18))} -> 0 | AA18: {=SUM([3]Hoja2!$K$5:$K$16*([3]Hoja2!$G$5:$G$16=Z$5)*([3]Hoja2!$L$5:$L$16=$C18))} -> 0 | AB18: =IFERROR(AA18/Z18,0) -> 0 | AC18: {=SUM([3]Hoja2!$J$5:$J$16*([3]Hoja2!$G$5:$G$16=AC$5)*([3]Hoja2!$L$5:$L$16=$C18))} -> 135 | AD18: {=SUM([3]Hoja2!$K$5:$K$16*([3]Hoja2!$G$5:$G$16=AC$5)*([3]Hoja2!$L$5:$L$16=$C18))} -> 561600 | AE18: =IFERROR(AD18/AC18,0) -> 4160 | AF18: =T18+W18+Z18+AC18 -> 162 | AG18: =U18+X18+AA18+AD18 -> 677700 | AH18: =IFERROR(AG18/AF18,0) -> 4183.3333 | AI18: =-AF18*'[1]Stock Libre'!T48*1000 -> -488123.44 | AJ18: =-207.84*AF18 -> -33670.08 | AK18: =$AK$21/$AF$21*$AF18 -> -10608.165 | AL18: =$AL$21/$AF$21*$AF18 -> -20853.855 | AM18: =$AM$21/$AF$21*$AF18 -> -16670.387 | AN18: =(AG18-AF18*$AK$25)*0.03 -> 19776.097 | AO18: =AG18+SUM(AI18:AL18,AN18) -> 144220.56 | AP18: =IFERROR(AO18/AG18,0) -> 0.21280885 | AQ18: =AG18+AI18+AJ18+AK18+AN18-AM18 -> 181744.8 | AR18: =IFERROR(AQ18/AG18,0) -> 0.26817884 | AT18: =AH18 -> 4183.3333 | AU18: =IFERROR(AI18/$AF18,0) -> -3013.1076 | AV18: =IFERROR(AJ18/$AF18,0) -> -207.84 | AW18: =IFERROR(AK18/$AF18,0) -> -65.4825 | AX18: =IFERROR(AL18/$AF18,0) -> -128.7275 | AY18: =IFERROR(AM18/$AF18,0) -> -102.90363 | AZ18: =IFERROR(AN18/$AF18,0) -> 122.07467 | BA18: =IFERROR(AO18/$AF18,0) -> 890.25037 | BB18: =IFERROR(AQ18/$AF18,0) -> 1121.8815
B19: 10009386 | C19: VENTOSAS | D19: =TD!E16 -> 15.56 | E19: =IFERROR(F19/D19,0) -> 1859.8567 | F19: =TD!F16 -> 28939.371 | G19: =TD!G16 -> 3233.9904 | H19: =TD!H16 -> 1018.9077 | I19: =TD!I16 -> 2002.9999 | J19: =TD!J16 -> 1601.1804 | K19: 0 | L19: 0 | M19: =F19+G19+H19+I19 -> 35195.269 | N19: =IFERROR(M19/D19,0) -> 2261.9067 | P19: =O19*D19 -> 0 | Q19: =P19-M19 -> -35195.269 | R19: =IFERROR(Q19/P19,0) -> 0 | T19: {=SUM([3]Hoja2!$J$5:$J$16*([3]Hoja2!$G$5:$G$16=T$5)*([3]Hoja2!$L$5:$L$16=$C19))} -> 0 | U19: {=SUM([3]Hoja2!$K$5:$K$16*([3]Hoja2!$G$5:$G$16=T$5)*([3]Hoja2!$L$5:$L$16=$C19))} -> 0 | V19: =IFERROR(U19/T19,0) -> 0 | W19: {=SUM([3]Hoja2!$J$5:$J$16*([3]Hoja2!$G$5:$G$16=W$5)*([3]Hoja2!$L$5:$L$16=$C19))} -> 0 | X19: {=SUM([3]Hoja2!$K$5:$K$16*([3]Hoja2!$G$5:$G$16=W$5)*([3]Hoja2!$L$5:$L$16=$C19))} -> 0 | Y19: =IFERROR(X19/W19,0) -> 0 | Z19: {=SUM([3]Hoja2!$J$5:$J$16*([3]Hoja2!$G$5:$G$16=Z$5)*([3]Hoja2!$L$5:$L$16=$C19))} -> 0 | AA19: {=SUM([3]Hoja2!$K$5:$K$16*([3]Hoja2!$G$5:$G$16=Z$5)*([3]Hoja2!$L$5:$L$16=$C19))} -> 0 | AB19: =IFERROR(AA19/Z19,0) -> 0 | AC19: {=SUM([3]Hoja2!$J$5:$J$16*([3]Hoja2!$G$5:$G$16=AC$5)*([3]Hoja2!$L$5:$L$16=$C19))} -> 0 | AD19: {=SUM([3]Hoja2!$K$5:$K$16*([3]Hoja2!$G$5:$G$16=AC$5)*([3]Hoja2!$L$5:$L$16=$C19))} -> 0 | AE19: =IFERROR(AD19/AC19,0) -> 0 | AF19: =T19+W19+Z19+AC19 -> 0 | AG19: =U19+X19+AA19+AD19 -> 0 | AH19: =IFERROR(AG19/AF19,0) -> 0 | AI19: =-IFERROR(F19/D19*AF19,0) -> 0 | AJ19: =-207.84*AF19 -> 0 | AK19: =$AK$21/$AF$21*$AF19 -> 0 | AL19: =$AL$21/$AF$21*$AF19 -> 0 | AM19: =$AM$21/$AF$21*$AF19 -> 0 | AN19: =(AG19-AF19*$AK$25)*0.03 -> 0 | AO19: =AG19+SUM(AI19:AL19,AN19) -> 0 | AP19: =IFERROR(AO19/AG19,0) -> 0 | AQ19: =AG19+AI19+AJ19+AK19+AN19-AM19 -> 0 | AR19: =IFERROR(AQ19/AG19,0) -> 0 | AT19: =AH19 -> 0 | AU19: =IFERROR(AI19/$AF19,0) -> 0 | AV19: =IFERROR(AJ19/$AF19,0) -> 0 | AW19: =IFERROR(AK19/$AF19,0) -> 0 | AX19: =IFERROR(AL19/$AF19,0) -> 0 | AY19: =IFERROR(AM19/$AF19,0) -> 0 | AZ19: =IFERROR(AN19/$AF19,0) -> 0 | BA19: =IFERROR(AO19/$AF19,0) -> 0 | BB19: =IFERROR(AQ19/$AF19,0) -> 0
C20: OTROS | L20: 0 | M20: =F20+G20+H20+I20 -> 0 | N20: =IFERROR(M20/D20,0) -> 0 | O20: 2400 | P20: =O20*D20 -> 0 | Q20: =P20-M20 -> 0 | R20: =IFERROR(Q20/P20,0) -> 0 | T20: {=SUM([3]Hoja2!$J$5:$J$16*([3]Hoja2!$G$5:$G$16=T$5)*([3]Hoja2!$L$5:$L$16=$C20))} -> 0 | U20: {=SUM([3]Hoja2!$K$5:$K$16*([3]Hoja2!$G$5:$G$16=T$5)*([3]Hoja2!$L$5:$L$16=$C20))} -> 0 | V20: =IFERROR(U20/T20,0) -> 0 | W20: {=SUM([3]Hoja2!$J$5:$J$16*([3]Hoja2!$G$5:$G$16=W$5)*([3]Hoja2!$L$5:$L$16=$C20))} -> 0 | X20: {=SUM([3]Hoja2!$K$5:$K$16*([3]Hoja2!$G$5:$G$16=W$5)*([3]Hoja2!$L$5:$L$16=$C20))} -> 0 | Y20: =IFERROR(X20/W20,0) -> 0 | Z20: {=SUM([3]Hoja2!$J$5:$J$16*([3]Hoja2!$G$5:$G$16=Z$5)*([3]Hoja2!$L$5:$L$16=$C20))} -> 0 | AA20: {=SUM([3]Hoja2!$K$5:$K$16*([3]Hoja2!$G$5:$G$16=Z$5)*([3]Hoja2!$L$5:$L$16=$C20))} -> 0 | AB20: =IFERROR(AA20/Z20,0) -> 0 | AC20: {=SUM([3]Hoja2!$J$5:$J$16*([3]Hoja2!$G$5:$G$16=AC$5)*([3]Hoja2!$L$5:$L$16=$C20))} -> 27 | AD20: {=SUM([3]Hoja2!$K$5:$K$16*([3]Hoja2!$G$5:$G$16=AC$5)*([3]Hoja2!$L$5:$L$16=$C20))} -> 67500 | AE20: =IFERROR(AD20/AC20,0) -> 2500 | AF20: =T20+W20+Z20+AC20 -> 27 | AG20: =U20+X20+AA20+AD20 -> 67500 | AH20: =IFERROR(AG20/AF20,0) -> 2500 | AI20: =-1570.59633628428*AF20 -> -42406.101 | AJ20: =-207.84*AF20 -> -5611.68 | AK20: =$AK$21/$AF$21*$AF20 -> -1768.0275 | AL20: =$AL$21/$AF$21*$AF20 -> -3475.6425 | AM20: =$AM$21/$AF$21*$AF20 -> -2778.3979 | AN20: =(AG20-AF20*$AK$25)*0.03 -> 1932.5161 | AO20: =AG20+SUM(AI20:AL20,AN20) -> 16171.065 | AP20: =IFERROR(AO20/AG20,0) -> 0.23957133 | AQ20: =AG20+AI20+AJ20+AK20+AN20-AM20 -> 22425.105 | AR20: =IFERROR(AQ20/AG20,0) -> 0.33222378 | AT20: =AH20 -> 2500 | AU20: =IFERROR(AI20/$AF20,0) -> -1570.5963 | AV20: =IFERROR(AJ20/$AF20,0) -> -207.84 | AW20: =IFERROR(AK20/$AF20,0) -> -65.4825 | AX20: =IFERROR(AL20/$AF20,0) -> -128.7275 | AY20: =IFERROR(AM20/$AF20,0) -> -102.90363 | AZ20: =IFERROR(AN20/$AF20,0) -> 71.574672 | BA20: =IFERROR(AO20/$AF20,0) -> 598.92834 | BB20: =IFERROR(AQ20/$AF20,0) -> 830.55946
C21: TOTAL | D21: =SUM(D7:D20) -> 1173.595 | E21: =IFERROR(F21/D21,0) -> 1921.3321 | F21: =SUM(F7:F20) -> 2254865.8 | G21: =SUM(G7:G20) -> 243919.98 | H21: =SUM(H7:H20) -> 76849.935 | I21: =SUM(I7:I20) -> 151073.95 | J21: =SUM(J7:J20) -> 120767.18 | K21: =SUM(K7:K20) -> 0 | L21: 0 | M21: =SUM(M7:M20) -> 2726709.7 | N21: =IFERROR(M21/D21,0) -> 2323.3821 | O21: =P21/D21 -> 1981.4895 | P21: =SUM(P7:P20) -> 2325466.2 | Q21: =SUM(Q7:Q20) -> -401243.47 | R21: =Q21/P21 -> -0.17254324 | T21: =SUM(T7:T20) -> 26 | U21: =SUM(U7:U20) -> 36400 | V21: =IFERROR(U21/T21,0) -> 1400 | W21: =SUM(W7:W20) -> 53 | X21: =SUM(X7:X20) -> 149900 | Y21: =IFERROR(X21/W21,0) -> 2828.3019 | Z21: =SUM(Z7:Z20) -> 24 | AA21: =SUM(AA7:AA20) -> 50400 | AB21: =IFERROR(AA21/Z21,0) -> 2100 | AC21: =SUM(AC7:AC20) -> 629 | AD21: =SUM(AD7:AD20) -> 1643790 | AE21: =IFERROR(AD21/AC21,0) -> 2613.3386 | AF21: =SUM(AF7:AF20) -> 732 | AG21: =SUM(AG7:AG20) -> 1880490 | AH21: =IFERROR(AG21/AF21,0) -> 2568.9754 | AI21: =SUM(AI7:AI20) -> -1558549.1 | AJ21: =SUM(AJ7:AJ20) -> -152138.88 | AK21: =-'Stock Libre'!N61/1200*AF21 -> -47933.19 | AL21: =-'Stock Libre'!O61/1200*AF21 -> -94228.53 | AM21: =-'Stock Libre'!P61/1200*AF21 -> -75325.454 | AN21: =SUM(AN7:AN20) -> 53907.36 | AO21: =SUM(AO7:AO20) -> 81547.674 | AP21: =IFERROR(AO21/AG21,0) -> 0.04336512 | AQ21: =SUM(AQ7:AQ20) -> 251101.66 | AR21: =IFERROR(AQ21/AG21,0) -> 0.13352991 | AT21: =AH21 -> 2568.9754 | AU21: =IFERROR(AI21/$AF21,0) -> -2129.1654 | AV21: =IFERROR(AJ21/$AF21,0) -> -207.84 | AW21: =IFERROR(AK21/$AF21,0) -> -65.4825 | AX21: =IFERROR(AL21/$AF21,0) -> -128.7275 | AY21: =IFERROR(AM21/$AF21,0) -> -102.90363 | AZ21: =IFERROR(AN21/$AF21,0) -> 73.643934 | BA21: =IFERROR(AO21/$AF21,0) -> 111.40393 | BB21: =IFERROR(AQ21/$AF21,0) -> 343.03505
I22: =I21/D21 -> 128.7275
AJ25: flete x tm | AK25: 114.17761

Sheet TD
D3: Etiquetas de fila | E3: Suma de TM en Stock | F3: Suma de Costo Ventas | G3: Suma de Gasto Ventas | H3: Suma de Gasto ADM | I3: Suma de Gasto Fin | J3: Suma de Depreciación
A4: =B4=D4 -> TRUE | B4: 10005721 | C4: POTA FILETE CONGELADO | D4: 10005721 | E4: 551.98 | F4: 1168051.8 | G4: 114723.52 | H4: 36145.03 | I4: 71055.005 | J4: 56800.743
A5: =B5=D5 -> TRUE | B5: 10005779 | C5: POTA NUCAS CONGELADAS | D5: 10005779 | E5: 126.84 | F5: 219019.55 | G5: 26362.426 | H5: 8305.8003 | I5: 16327.796 | J5: 13052.296
A6: =B6=D6 -> TRUE | B6: 10005781 | C6: POTA NUCAS FR ABIERTAS 0.3-0.5 BL10 S20 | D6: 10005781 | E6: 128.34 | F6: 234971.39 | G6: 26674.186 | H6: 8404.0241 | I6: 16520.887 | J6: 13206.651
A7: =B7=D7 -> TRUE | B7: 10006719 | C7: POTA ALAS CONGELADAS | D7: 10006719 | E7: 20.14 | F7: 40591.488 | G7: 4185.8976 | H7: 1318.8176 | I7: 2592.5719 | J7: 2072.479
A8: =B8=D8 -> TRUE | B8: 10006720 | C8: POTA ALAS CONGELADAS FR C/P C/C 0.5-1 BL10 S20 | D8: 10006720 | E8: 33.5 | F8: 50288.099 | G8: 6962.64 | H8: 2193.6638 | I8: 4312.3713 | J8: 3447.2714
A9: =B9=D9 -> TRUE | B9: 10007050 | C9: POTA REJOS COCIDOS | D9: 10007050 | E9: 93.215 | F9: 143743.96 | G9: 19373.806 | H9: 6103.9512 | I9: 11999.334 | J9: 9592.1614
A10: =B10=D10 -> TRUE | B10: 10007162 | C10: POTA REJOS CONGELADOS | D10: 10007162 | E10: 99.26 | F10: 184453.56 | G10: 20630.198 | H10: 6499.793 | I10: 12777.492 | J10: 10214.214
A11: =B11=D11 -> TRUE | B11: 10007567 | C11: POTA REPRODUCTORES | D11: 10007567 | E11: 91.96 | F11: 165200.73 | G11: 19112.966 | H11: 6021.7707 | I11: 11837.781 | J11: 9463.0174
A12: =B12=D12 -> TRUE | B12: 10007969 | C12: POTA CONOS | D12: 10007969 | E12: 7.64 | F12: 11200.268 | G12: 1587.8976 | H12: 500.2863 | I12: 983.4781 | J12: 786.1837
A13: =B13=D13 -> TRUE | B13: 10009207 | C13: POTA LABIOS FR S/COD BL10 S20 | D13: 10009207 | E13: 4.86 | F13: 7375.975 | G13: 1010.1024 | H13: 318.24495 | I13: 625.61565 | J13: 500.11162
A14: =B14=D14 -> TRUE | B14: 10009239 | C14: POTA FILETE DARUMA | D14: 10009239 | E14: 0.3 | F14: 1029.5857 | G14: 62.352 | H14: 19.64475 | I14: 38.61825 | J14: 30.871088
A15: =B15=D15 -> TRUE | B15: 10009334 | C15: POTA ALAS COCIDAS | D15: 10009334 | E15: 0 | F15: 0 | G15: 0 | H15: 0 | I15: 0 | J15: 0
A16: =B16=D16 -> TRUE | B16: 10009386 | C16: VENTOSAS | D16: 10009386 | E16: 15.56 | F16: 28939.371 | G16: 3233.9904 | H16: 1018.9077 | I16: 2002.9999 | J16: 1601.1804
C17: OTROS | D17: (en blanco) | E17: 0 | F17: 0 | G17: 0 | H17: 0 | I17: 0 | J17: 0
D18: Total general | E18: 1173.595 | F18: 2254865.8 | G18: 243919.98 | H18: 76849.935 | I18: 151073.95 | J18: 120767.18

Sheet Stock Libre
A1: CODIGO | B1: PRODUCTO | C1: TOTAL STOCK | D1: POR EMBARCAR | E1: STOCK LIBRE | G1: CÓDIGO | H1: CU X TM | I1: % MP | J1: incremento MP | K1: TM en Stock | L1: Costo Ventas | M1: Gasto Ventas | N1: Gasto ADM | O1: Gasto Fin | P1: Depreciación | Q1: Utilidad Neta | R1: Margen Neto | S1: Venta Equilibrio | T1: Precio Equilibrio x TM
A2: 10009178 | B2: POTA ALAS FR C/P C/C (B) S/COD BL10 S20 | C2: 16680 | D2: 5000 | E2: 11680 | G2: 10006719 | H2: =IFERROR(INDEX([2]Resumen!$K$3:$K$63,MATCH(G2,[2]Resumen!$C$3:$C$63,0)),0)*(1+I2*J2)/1000-51.89/1000 -> 2.0154661 | I2: 0.71 | J2: =3.597/3.52-1 -> 0.021875 | K2: =IF(E2<0,0,E2)/1000 -> 11.68 | L2: =IFERROR(H2*K2,0)*1000 -> 23540.644 | M2: =207.84*K2 -> 2427.5712 | N2: =$N$61/1200*K2 -> 764.8356 | O2: =$O$61/1200*K2 -> 1503.5372 | P2: =$P$61/1200*K2 -> 1201.9143 | Q2: 0 | R2: 0 | S2: =L2+M2+N2+O2 -> 28236.588 | T2: =IFERROR(S2/K2,0) -> 2417.5161
A3: 10006668 | B3: POTA ALAS FR C/P C/C <0.5 BL10 S20 | C3: 2160 | D3: 0 | E3: 2160 | G3: 10006719 | H3: =IFERROR(INDEX([2]Resumen!$K$3:$K$63,MATCH(G3,[2]Resumen!$C$3:$C$63,0)),0)*(1+I3*J3)/1000-51.89/1000 -> 2.0154661 | I3: 0.71 | J3: =3.597/3.52-1 -> 0.021875 | K3: =IF(E3<0,0,E3)/1000 -> 2.16 | L3: =IFERROR(H3*K3,0)*1000 -> 4353.4068 | M3: =207.84*K3 -> 448.9344 | N3: =$N$61/1200*K3 -> 141.4422 | O3: =$O$61/1200*K3 -> 278.0514 | P3: =$P$61/1200*K3 -> 222.27183 | Q3: 0 | R3: 0 | S3: =L3+M3+N3+O3 -> 5221.8348 | T3: =IFERROR(S3/K3,0) -> 2417.5161
A4: 10006719 | B4: POTA ALAS FR C/P C/C 0.5-1 BL10 S20 | C4: 31300 | D4: 25000 | E4: 6300 | G4: 10006719 | H4: =IFERROR(INDEX([2]Resumen!$K$3:$K$63,MATCH(G4,[2]Resumen!$C$3:$C$63,0)),0)*(1+I4*J4)/1000-51.89/1000 -> 2.0154661 | I4: 0.71 | J4: =3.597/3.52-1 -> 0.021875 | K4: =IF(E4<0,0,E4)/1000 -> 6.3 | L4: =IFERROR(H4*K4,0)*1000 -> 12697.437 | M4: =207.84*K4 -> 1309.392 | N4: =$N$61/1200*K4 -> 412.53975 | O4: =$O$61/1200*K4 -> 810.98325 | P4: =$P$61/1200*K4 -> 648.29284 | Q4: 0 | R4: 0 | S4: =L4+M4+N4+O4 -> 15230.352 | T4: =IFERROR(S4/K4,0) -> 2417.5161
A5: 10009265 | B5: POTA ALAS FR C/P C/C 0.3 - 0.5 BL10 S20 | C5: 0 | E5: 0 | G5: 10006719 | H5: =IFERROR(INDEX([2]Resumen!$K$3:$K$63,MATCH(G5,[2]Resumen!$C$3:$C$63,0)),0)*(1+I5*J5)/1000-51.89/1000 -> 2.0154661 | I5: 0.71 | J5: =3.597/3.52-1 -> 0.021875 | K5: =IF(E5<0,0,E5)/1000 -> 0 | L5: =IFERROR(H5*K5,0)*1000 -> 0 | M5: =207.84*K5 -> 0 | N5: =$N$61/1200*K5 -> 0 | O5: =$O$61/1200*K5 -> 0 | P5: =$P$61/1200*K5 -> 0 | Q5: 0 | R5: 0 | S5: =L5+M5+N5+O5 -> 0 | T5: =IFERROR(S5/K5,0) -> 0
A6: 10006720 | B6: POTA ALAS FR C/P C/C 1-2 BL10 S20 | C6: 4900 | D6: 4900 | E6: 0 | G6: 10006720 | H6: =IFERROR(INDEX([2]Resumen!$K$3:$K$63,MATCH(G6,[2]Resumen!$C$3:$C$63,0)),0)*(1+I6*J6)/1000-51.89/1000 -> 1.5011373 | I6: 0.71 | J6: =3.597/3.52-1 -> 0.021875 | K6: =IF(E6<0,0,E6)/1000 -> 0 | L6: =IFERROR(H6*K6,0)*1000 -> 0 | M6: =207.84*K6 -> 0 | N6: =$N$61/1200*K6 -> 0 | O6: =$O$61/1200*K6 -> 0 | P6: =$P$61/1200*K6 -> 0 | Q6: 0 | R6: 0 | S6: =L6+M6+N6+O6 -> 0 | T6: =IFERROR(S6/K6,0) -> 0
A7: 10010005 | B7: POTA ALAS FR C/P C/C 1-2 BL10 S20 ENTERA | C7: 97480 | D7: 64100 | E7: 33380 | G7: 10006720 | H7: =IFERROR(INDEX([2]Resumen!$K$3:$K$63,MATCH(G7,[2]Resumen!$C$3:$C$63,0)),0)*(1+I7*J7)/1000-51.89/1000 -> 1.5011373 | I7: 0.71 | J7: =3.597/3.52-1 -> 0.021875 | K7: =IF(E7<0,0,E7)/1000 -> 33.38 | L7: =IFERROR(H7*K7,0)*1000 -> 50107.963 | M7: =207.84*K7 -> 6937.6992 | N7: =$N$61/1200*K7 -> 2185.8059 | O7: =$O$61/1200*K7 -> 4296.924 | P7: =$P$61/1200*K7 -> 3434.923 | Q7: 0 | R7: 0 | S7: =L7+M7+N7+O7 -> 63528.392 | T7: =IFERROR(S7/K7,0) -> 1903.1873
A8: 10006722 | B8: POTA ALAS FR C/P C/C 2up | C8: 120 | E8: 120 | G8: 10006720 | H8: =IFERROR(INDEX([2]Resumen!$K$3:$K$63,MATCH(G8,[2]Resumen!$C$3:$C$63,0)),0)*(1+I8*J8)/1000-51.89/1000 -> 1.5011373 | I8: 0.71 | J8: =3.597/3.52-1 -> 0.021875 | K8: =IF(E8<0,0,E8)/1000 -> 0.12 | L8: =IFERROR(H8*K8,0)*1000 -> 180.13648 | M8: =207.84*K8 -> 24.9408 | N8: =$N$61/1200*K8 -> 7.8579 | O8: =$O$61/1200*K8 -> 15.4473 | P8: =$P$61/1200*K8 -> 12.348435 | Q8: 0 | R8: 0 | S8: =L8+M8+N8+O8 -> 228.38248 | T8: =IFERROR(S8/K8,0) -> 1903.1873
A9: 10009207 | B9: POTA LABIOS FR S/COD BL10 S20 | C9: 4860 | E9: 4860 | G9: 10009207 | H9: =IFERROR(INDEX([2]Resumen!$K$3:$K$63,MATCH(G9,[2]Resumen!$C$3:$C$63,0)),0)*(1+I9*J9)/1000-51.89/1000 -> 1.5176903 | I9: 0.71 | J9: =3.597/3.52-1 -> 0.021875 | K9: =IF(E9<0,0,E9)/1000 -> 4.86 | L9: =IFERROR(H9*K9,0)*1000 -> 7375.975 | M9: =207.84*K9 -> 1010.1024 | N9: =$N$61/1200*K9 -> 318.24495 | O9: =$O$61/1200*K9 -> 625.61565 | P9: =$P$61/1200*K9 -> 500.11162 | Q9: 0 | R9: 0 | S9: =L9+M9+N9+O9 -> 9329.938 | T9: =IFERROR(S9/K9,0) -> 1919.7403
A10: 10007969 | B10: POTA CONOS | C10: 34640 | D10: 27000 | E10: 7640 | G10: 10007969 | H10: =IFERROR(INDEX([2]Resumen!$K$3:$K$63,MATCH(G10,[2]Resumen!$C$3:$C$63,0)),0)*(1+I10*J10)/1000-51.89/1000 -> 1.4660036 | I10: 0.71 | J10: =3.597/3.52-1 -> 0.021875 | K10: =IF(E10<0,0,E10)/1000 -> 7.64 | L10: =IFERROR(H10*K10,0)*1000 -> 11200.268 | M10: =207.84*K10 -> 1587.8976 | N10: =$N$61/1200*K10 -> 500.2863 | O10: =$O$61/1200*K10 -> 983.4781 | P10: =$P$61/1200*K10 -> 786.1837 | Q10: 0 | R10: 0 | S10: =L10+M10+N10+O10 -> 14271.93 | T10: =IFERROR(S10/K10,0) -> 1868.0536
A11: 10009174 | B11: POTA ENTERA < 1KG | C11: 0 | E11: 0 | J11: =3.597/3.52-1 -> 0.021875 | K11: =IF(E11<0,0,E11)/1000 -> 0 | L11: =IFERROR(H11*K11,0)*1000 -> 0 | M11: =207.84*K11 -> 0 | N11: =$N$61/1200*K11 -> 0 | O11: =$O$61/1200*K11 -> 0 | P11: =$P$61/1200*K11 -> 0 | Q11: 0 | R11: 0 | S11: =L11+M11+N11+O11 -> 0 | T11: =IFERROR(S11/K11,0) -> 0
A12: 10009175 | B12: TUBO ALETA 0.1-0.5 KG | C12: 0 | E12: 0 | J12: =3.597/3.52-1 -> 0.021875 | K12: =IF(E12<0,0,E12)/1000 -> 0 | L12: =IFERROR(H12*K12,0)*1000 -> 0 | M12: =207.84*K12 -> 0 | N12: =$N$61/1200*K12 -> 0 | O12: =$O$61/1200*K12 -> 0 | P12: =$P$61/1200*K12 -> 0 | Q12: 0 | R12: 0 | S12: =L12+M12+N12+O12 -> 0 | T12: =IFERROR(S12/K12,0) -> 0
A13: 10009176 | B13: TUBO ALETA 0.5-1.0 KG | C13: 0 | E13: 0 | J13: =3.597/3.52-1 -> 0.021875 | K13: =IF(E13<0,0,E13)/1000 -> 0 | L13: =IFERROR(H13*K13,0)*1000 -> 0 | M13: =207.84*K13 -> 0 | N13: =$N$61/1200*K13 -> 0 | O13: =$O$61/1200*K13 -> 0 | P13: =$P$61/1200*K13 -> 0 | Q13: 0 | R13: 0 | S13: =L13+M13+N13+O13 -> 0 | T13: =IFERROR(S13/K13,0) -> 0
A14: 10010003 | B14: TUBO ALETA 1.0-1.5 kg | C14: 0 | E14: 0 | J14: =3.597/3.52-1 -> 0.021875 | K14: =IF(E14<0,0,E14)/1000 -> 0 | L14: =IFERROR(H14*K14,0)*1000 -> 0 | M14: =207.84*K14 -> 0 | N14: =$N$61/1200*K14 -> 0 | O14: =$O$61/1200*K14 -> 0 | P14: =$P$61/1200*K14 -> 0 | Q14: 0 | R14: 0 | S14: =L14+M14+N14+O14 -> 0 | T14: =IFERROR(S14/K14,0) -> 0
A15: 10009177 | B15: TUBO ALETA 1.0-2.0 KG | C15: 0 | E15: 0 | J15: =3.597/3.52-1 -> 0.021875 | K15: =IF(E15<0,0,E15)/1000 -> 0 | L15: =IFERROR(H15*K15,0)*1000 -> 0 | M15: =207.84*K15 -> 0 | N15: =$N$61/1200*K15 -> 0 | O15: =$O$61/1200*K15 -> 0 | P15: =$P$61/1200*K15 -> 0 | Q15: 0 | R15: 0 | S15: =L15+M15+N15+O15 -> 0 | T15: =IFERROR(S15/K15,0) -> 0
A16: 10004433 | B16: POTA FILETE C/M C/T FR 0.5-1.0 BL10 S20 | C16: 1420 | E16: 1420 | G16: 10005721 | H16: =IFERROR(INDEX([2]Resumen!$K$3:$K$63,MATCH(G16,[2]Resumen!$C$3:$C$63,0)),0)*(1+I16*J16)/1000-51.89/1000 -> 2.1161126 | I16: 0.67 | J16: =3.597/3.52-1 -> 0.021875 | K16: =IF(E16<0,0,E16)/1000 -> 1.42 | L16: =IFERROR(H16*K16,0)*1000 -> 3004.8799 | M16: =207.84*K16 -> 295.1328 | N16: =$N$61/1200*K16 -> 92.98515 | O16: =$O$61/1200*K16 -> 182.79305 | P16: =$P$61/1200*K16 -> 146.12315 | Q16: 0 | R16: 0 | S16: =L16+M16+N16+O16 -> 3575.7909 | T16: =IFERROR(S16/K16,0) -> 2518.1626
A17: 10004434 | B17: POTA FILETE C/M C/T FR 1-2 BL10 S20 | C17: 1940 | E17: 1940 | G17: 10005721 | H17: =IFERROR(INDEX([2]Resumen!$K$3:$K$63,MATCH(G17,[2]Resumen!$C$3:$C$63,0)),0)*(1+I17*J17)/1000-51.89/1000 -> 2.1161126 | I17: 0.67 | J17: =3.597/3.52-1 -> 0.021875 | K17: =IF(E17<0,0,E17)/1000 -> 1.94 | L17: =IFERROR(H17*K17,0)*1000 -> 4105.2584 | M17: =207.84*K17 -> 403.2096 | N17: =$N$61/1200*K17 -> 127.03605 | O17: =$O$61/1200*K17 -> 249.73135 | P17: =$P$61/1200*K17 -> 199.63303 | Q17: 0 | R17: 0 | S17: =L17+M17+N17+O17 -> 4885.2354 | T17: =IFERROR(S17/K17,0) -> 2518.1626
A18: 10004435 | B18: POTA FILETE C/M C/T FR 2-4 S20 | C18: 14400 | E18: 14400 | G18: 10005721 | H18: =IFERROR(INDEX([2]Resumen!$K$3:$K$63,MATCH(G18,[2]Resumen!$C$3:$C$63,0)),0)*(1+I18*J18)/1000-51.89/1000 -> 2.1161126 | I18: 0.67 | J18: =3.597/3.52-1 -> 0.021875 | K18: =IF(E18<0,0,E18)/1000 -> 14.4 | L18: =IFERROR(H18*K18,0)*1000 -> 30472.021 | M18: =207.84*K18 -> 2992.896 | N18: =$N$61/1200*K18 -> 942.948 | O18: =$O$61/1200*K18 -> 1853.676 | P18: =$P$61/1200*K18 -> 1481.8122 | Q18: 0 | R18: 0 | S18: =L18+M18+N18+O18 -> 36261.541 | T18: =IFERROR(S18/K18,0) -> 2518.1626
A19: 10005708 | B19: POTA FILETE C/M C/T FR <0.5 Kg AA BL10 S20 | C19: 1080 | E19: 1080 | G19: 10005721 | H19: =IFERROR(INDEX([2]Resumen!$K$3:$K$63,MATCH(G19,[2]Resumen!$C$3:$C$63,0)),0)*(1+I19*J19)/1000-51.89/1000 -> 2.1161126 | I19: 0.67 | J19: =3.597/3.52-1 -> 0.021875 | K19: =IF(E19<0,0,E19)/1000 -> 1.08 | L19: =IFERROR(H19*K19,0)*1000 -> 2285.4016 | M19: =207.84*K19 -> 224.4672 | N19: =$N$61/1200*K19 -> 70.7211 | O19: =$O$61/1200*K19 -> 139.0257 | P19: =$P$61/1200*K19 -> 111.13592 | Q19: 0 | R19: 0 | S19: =L19+M19+N19+O19 -> 2719.6156 | T19: =IFERROR(S19/K19,0) -> 2518.1626
A20: 10005721 | B20: POTA FILETE C/M C/T FR 2-4 (AA) BL10 S20 | C20: 518600 | E20: 518600 | G20: 10005721 | H20: =IFERROR(INDEX([2]Resumen!$K$3:$K$63,MATCH(G20,[2]Resumen!$C$3:$C$63,0)),0)*(1+I20*J20)/1000-51.89/1000 -> 2.1161126 | I20: 0.67 | J20: =3.597/3.52-1 -> 0.021875 | K20: =IF(E20<0,0,E20)/1000 -> 518.6 | L20: =IFERROR(H20*K20,0)*1000 -> 1097416 | M20: =207.84*K20 -> 107785.82 | N20: =$N$61/1200*K20 -> 33959.225 | O20: =$O$61/1200*K20 -> 66758.082 | P20: =$P$61/1200*K20 -> 53365.82 | Q20: 0 | R20: 0 | S20: =L20+M20+N20+O20 -> 1305919.1 | T20: =IFERROR(S20/K20,0) -> 2518.1626
A21: 10005711 | B21: POTA FILETE C/M C/T FR 0.5-1.0 AA BL10 S20 | C21: 11340 | E21: 11340 | G21: 10005721 | H21: =IFERROR(INDEX([2]Resumen!$K$3:$K$63,MATCH(G21,[2]Resumen!$C$3:$C$63,0)),0)*(1+I21*J21)/1000-51.89/1000 -> 2.1161126 | I21: 0.67 | J21: =3.597/3.52-1 -> 0.021875 | K21: =IF(E21<0,0,E21)/1000 -> 11.34 | L21: =IFERROR(H21*K21,0)*1000 -> 23996.717 | M21: =207.84*K21 -> 2356.9056 | N21: =$N$61/1200*K21 -> 742.57155 | O21: =$O$61/1200*K21 -> 1459.7699 | P21: =$P$61/1200*K21 -> 1166.9271 | Q21: 0 | R21: 0 | S21: =L21+M21+N21+O21 -> 28555.964 | T21: =IFERROR(S21/K21,0) -> 2518.1626
A22: 10005718 | B22: POTA FILETE C/M C/T FR 1-2 AA BL10 S20 | C22: 24840 | D22: 111740 | E22: -86900 | G22: 10005721 | H22: =IFERROR(INDEX([2]Resumen!$K$3:$K$63,MATCH(G22,[2]Resumen!$C$3:$C$63,0)),0)*(1+I22*J22)/1000-51.89/1000 -> 2.1161126 | I22: 0.67 | J22: =3.597/3.52-1 -> 0.021875 | K22: =IF(E22<0,0,E22)/1000 -> 0 | L22: =IFERROR(H22*K22,0)*1000 -> 0 | M22: =207.84*K22 -> 0 | N22: =$N$61/1200*K22 -> 0 | O22: =$O$61/1200*K22 -> 0 | P22: =$P$61/1200*K22 -> 0 | Q22: 0 | R22: 0 | S22: =L22+M22+N22+O22 -> 0 | T22: =IFERROR(S22/K22,0) -> 0
A23: 10009971 | B23: POTA FILETE C/M C/T FR 0.5-1.0 AAA BL10 S20 | C23: 0 | E23: 0 | G23: 10005721 | H23: =IFERROR(INDEX([2]Resumen!$K$3:$K$63,MATCH(G23,[2]Resumen!$C$3:$C$63,0)),0)*(1+I23*J23)/1000-51.89/1000 -> 2.1161126 | I23: 0.67 | J23: =3.597/3.52-1 -> 0.021875 | K23: =IF(E23<0,0,E23)/1000 -> 0 | L23: =IFERROR(H23*K23,0)*1000 -> 0 | M23: =207.84*K23 -> 0 | N23: =$N$61/1200*K23 -> 0 | O23: =$O$61/1200*K23 -> 0 | P23: =$P$61/1200*K23 -> 0 | Q23: 0 | R23: 0 | S23: =L23+M23+N23+O23 -> 0 | T23: =IFERROR(S23/K23,0) -> 0
A24: 10009972 | B24: POTA FILETE C/M C/T FR 1-2 AAA BL10 S20 | C24: 7260 | D24: 7260 | E24: 0 | G24: 10005721 | H24: =IFERROR(INDEX([2]Resumen!$K$3:$K$63,MATCH(G24,[2]Resumen!$C$3:$C$63,0)),0)*(1+I24*J24)/1000-51.89/1000 -> 2.1161126 | I24: 0.67 | J24: =3.597/3.52-1 -> 0.021875 | K24: =IF(E24<0,0,E24)/1000 -> 0 | L24: =IFERROR(H24*K24,0)*1000 -> 0 | M24: =207.84*K24 -> 0 | N24: =$N$61/1200*K24 -> 0 | O24: =$O$61/1200*K24 -> 0 | P24: =$P$61/1200*K24 -> 0 | Q24: 0 | R24: 0 | S24: =L24+M24+N24+O24 -> 0 | T24: =IFERROR(S24/K24,0) -> 0
A25: 10010063 | B25: POTA FILETE C/M C/T FR 2-4 AAA BL10 S20 | C25: 0 | D25: 0 | E25: 0 | G25: 10005721 | H25: =IFERROR(INDEX([2]Resumen!$K$3:$K$63,MATCH(G25,[2]Resumen!$C$3:$C$63,0)),0)*(1+I25*J25)/1000-51.89/1000 -> 2.1161126 | I25: 0.67 | J25: =3.597/3.52-1 -> 0.021875 | K25: =IF(E25<0,0,E25)/1000 -> 0 | L25: =IFERROR(H25*K25,0)*1000 -> 0 | M25: =207.84*K25 -> 0 | N25: =$N$61/1200*K25 -> 0 | O25: =$O$61/1200*K25 -> 0 | P25: =$P$61/1200*K25 -> 0 | Q25: 0 | R25: 0 | S25: =L25+M25+N25+O25 -> 0 | T25: =IFERROR(S25/K25,0) -> 0
A26: 10009298 | B26: POTA FILETE SM ST 1-2 CM/ESP | C26: 3200 | E26: 3200 | G26: 10005721 | H26: =IFERROR(INDEX([2]Resumen!$K$3:$K$63,MATCH(G26,[2]Resumen!$C$3:$C$63,0)),0)*(1+I26*J26)/1000-51.89/1000 -> 2.1161126 | I26: 0.67 | J26: =3.597/3.52-1 -> 0.021875 | K26: =IF(E26<0,0,E26)/1000 -> 3.2 | L26: =IFERROR(H26*K26,0)*1000 -> 6771.5603 | M26: =207.84*K26 -> 665.088 | N26: =$N$61/1200*K26 -> 209.544 | O26: =$O$61/1200*K26 -> 411.928 | P26: =$P$61/1200*K26 -> 329.2916 | Q26: 0 | R26: 0 | S26: =L26+M26+N26+O26 -> 8058.1203 | T26: =IFERROR(S26/K26,0) -> 2518.1626
A27: 10009184 | B27: POTA NUCAS FR ABIERTAS 0.1 - 0.3 BL10 S2 | C27: 85700 | E27: 85700 | G27: 10005779 | H27: =IFERROR(INDEX([2]Resumen!$K$3:$K$63,MATCH(G27,[2]Resumen!$C$3:$C$63,0)),0)*(1+I27*J27)/1000-51.89/1000 -> 1.7267388 | I27: 0.65 | J27: =3.597/3.52-1 -> 0.021875 | K27: =IF(E27<0,0,E27)/1000 -> 85.7 | L27: =IFERROR(H27*K27,0)*1000 -> 147981.51 | M27: =207.84*K27 -> 17811.888 | N27: =$N$61/1200*K27 -> 5611.8503 | O27: =$O$61/1200*K27 -> 11031.947 | P27: =$P$61/1200*K27 -> 8818.8407 | Q27: 0 | R27: 0 | S27: =L27+M27+N27+O27 -> 182437.2 | T27: =IFERROR(S27/K27,0) -> 2128.7888
A28: 10009271 | B28: POTA NUCAS FR CERRADA 0.1 - 0.3 BL10 S2 | C28: 40100 | E28: 40100 | G28: 10005779 | H28: =IFERROR(INDEX([2]Resumen!$K$3:$K$63,MATCH(G28,[2]Resumen!$C$3:$C$63,0)),0)*(1+I28*J28)/1000-51.89/1000 -> 1.7267388 | I28: 0.65 | J28: =3.597/3.52-1 -> 0.021875 | K28: =IF(E28<0,0,E28)/1000 -> 40.1 | L28: =IFERROR(H28*K28,0)*1000 -> 69242.225 | M28: =207.84*K28 -> 8334.384 | N28: =$N$61/1200*K28 -> 2625.8483 | O28: =$O$61/1200*K28 -> 5161.9728 | P28: =$P$61/1200*K28 -> 4126.4354 | Q28: 0 | R28: 0 | S28: =L28+M28+N28+O28 -> 85364.43 | T28: =IFERROR(S28/K28,0) -> 2128.7888
A29: 10009183 | B29: POTA NUCAS FR CERRADA <0.1 BL10 S2 | C29: 1040 | E29: 1040 | G29: 10005779 | H29: =IFERROR(INDEX([2]Resumen!$K$3:$K$63,MATCH(G29,[2]Resumen!$C$3:$C$63,0)),0)*(1+I29*J29)/1000-51.89/1000 -> 1.7267388 | I29: 0.65 | J29: =3.597/3.52-1 -> 0.021875 | K29: =IF(E29<0,0,E29)/1000 -> 1.04 | L29: =IFERROR(H29*K29,0)*1000 -> 1795.8083 | M29: =207.84*K29 -> 216.1536 | N29: =$N$61/1200*K29 -> 68.1018 | O29: =$O$61/1200*K29 -> 133.8766 | P29: =$P$61/1200*K29 -> 107.01977 | Q29: 0 | R29: 0 | S29: =L29+M29+N29+O29 -> 2213.9403 | T29: =IFERROR(S29/K29,0) -> 2128.7888
A30: 10005779 | B30: POTA NUCAS FR ABIERTAS 0.5-1 BL10 S20 | C30: 32520 | E30: 32520 | G30: 10005781 | H30: =IFERROR(INDEX([2]Resumen!$K$3:$K$63,MATCH(G30,[2]Resumen!$C$3:$C$63,0)),0)*(1+I30*J30)/1000-51.89/1000 -> 1.8308508 | I30: 0.65 | J30: =3.597/3.52-1 -> 0.021875 | K30: =IF(E30<0,0,E30)/1000 -> 32.52 | L30: =IFERROR(H30*K30,0)*1000 -> 59539.267 | M30: =207.84*K30 -> 6758.9568 | N30: =$N$61/1200*K30 -> 2129.4909 | O30: =$O$61/1200*K30 -> 4186.2183 | P30: =$P$61/1200*K30 -> 3346.4259 | Q30: 0 | R30: 0 | S30: =L30+M30+N30+O30 -> 72613.933 | T30: =IFERROR(S30/K30,0) -> 2232.9008
A31: 10005776 | B31: POTA NUCAS FR ABIERTAS 0.3-0.5 BL10 S20 | C31: 105820 | D31: 10000 | E31: 95820 | G31: 10005781 | H31: =IFERROR(INDEX([2]Resumen!$K$3:$K$63,MATCH(G31,[2]Resumen!$C$3:$C$63,0)),0)*(1+I31*J31)/1000-51.89/1000 -> 1.8308508 | I31: 0.65 | J31: =3.597/3.52-1 -> 0.021875 | K31: =IF(E31<0,0,E31)/1000 -> 95.82 | L31: =IFERROR(H31*K31,0)*1000 -> 175432.12 | M31: =207.84*K31 -> 19915.229 | N31: =$N$61/1200*K31 -> 6274.5332 | O31: =$O$61/1200*K31 -> 12334.669 | P31: =$P$61/1200*K31 -> 9860.2253 | Q31: 0 | R31: 0 | S31: =L31+M31+N31+O31 -> 213956.55 | T31: =IFERROR(S31/K31,0) -> 2232.9008
A32: 10005781 | B32: POTA NUCAS FR ABIERTAS 1-2 BL10 S20 | C32: 25620 | D32: 128000 | E32: -102380 | G32: 10005781 | H32: =IFERROR(INDEX([2]Resumen!$K$3:$K$63,MATCH(G32,[2]Resumen!$C$3:$C$63,0)),0)*(1+I32*J32)/1000-51.89/1000 -> 1.8308508 | I32: 0.65 | J32: =3.597/3.52-1 -> 0.021875 | K32: =IF(E32<0,0,E32)/1000 -> 0 | L32: =IFERROR(H32*K32,0)*1000 -> 0 | M32: =207.84*K32 -> 0 | N32: =$N$61/1200*K32 -> 0 | O32: =$O$61/1200*K32 -> 0 | P32: =$P$61/1200*K32 -> 0 | Q32: 0 | R32: 0 | S32: =L32+M32+N32+O32 -> 0 | T32: =IFERROR(S32/K32,0) -> 0
A33: 10007567 | B33: POTA REJOS OR FR LIMPIOS S/COD BL10 S20 | C33: 60340 | E33: 60340 | G33: 10007567 | H33: =IFERROR(INDEX([2]Resumen!$K$3:$K$63,MATCH(G33,[2]Resumen!$C$3:$C$63,0)),0)*(1+I33*J33)/1000-51.89/1000 -> 1.7964412 | I33: 0.68 | J33: =3.597/3.52-1 -> 0.021875 | K33: =IF(E33<0,0,E33)/1000 -> 60.34 | L33: =IFERROR(H33*K33,0)*1000 -> 108397.26 | M33: =207.84*K33 -> 12541.066 | N33: =$N$61/1200*K33 -> 3951.2141 | O33: =$O$61/1200*K33 -> 7767.4174 | P33: =$P$61/1200*K33 -> 6209.2047 | Q33: 0 | R33: 0 | S33: =L33+M33+N33+O33 -> 132656.96 | T33: =IFERROR(S33/K33,0) -> 2198.4912
A34: 10009975 | B34: POTA REJOS OR FR LIMPIOS <60 cm BL10 S20 | C34: 31620 | E34: 31620 | G34: 10007567 | H34: =IFERROR(INDEX([2]Resumen!$K$3:$K$63,MATCH(G34,[2]Resumen!$C$3:$C$63,0)),0)*(1+I34*J34)/1000-51.89/1000 -> 1.7964412 | I34: 0.68 | J34: =3.597/3.52-1 -> 0.021875 | K34: =IF(E34<0,0,E34)/1000 -> 31.62 | L34: =IFERROR(H34*K34,0)*1000 -> 56803.47 | M34: =207.84*K34 -> 6571.9008 | N34: =$N$61/1200*K34 -> 2070.5567 | O34: =$O$61/1200*K34 -> 4070.3636 | P34: =$P$61/1200*K34 -> 3253.8126 | Q34: 0 | R34: 0 | S34: =L34+M34+N34+O34 -> 69516.291 | T34: =IFERROR(S34/K34,0) -> 2198.4912
A35: 10009185 | B35: POTA REJOS FR C/U C/V S/OR <0.1 BL10 | C35: 0 | E35: 0 | G35: 10007162 | H35: =IFERROR(INDEX([2]Resumen!$K$3:$K$63,MATCH(G35,[2]Resumen!$C$3:$C$63,0)),0)*(1+I35*J35)/1000-51.89/1000 -> 1.8582869 | I35: 0.68 | J35: =3.597/3.52-1 -> 0.021875 | K35: =IF(E35<0,0,E35)/1000 -> 0 | L35: =IFERROR(H35*K35,0)*1000 -> 0 | M35: =207.84*K35 -> 0 | N35: =$N$61/1200*K35 -> 0 | O35: =$O$61/1200*K35 -> 0 | P35: =$P$61/1200*K35 -> 0 | Q35: 0 | R35: 0 | S35: =L35+M35+N35+O35 -> 0 | T35: =IFERROR(S35/K35,0) -> 0
A36: 10009186 | B36: POTA REJOS FR C/U C/V S/OR 0.1-0.3 BL10 | C36: 6360 | D36: 5700 | E36: 660 | G36: 10007162 | H36: =IFERROR(INDEX([2]Resumen!$K$3:$K$63,MATCH(G36,[2]Resumen!$C$3:$C$63,0)),0)*(1+I36*J36)/1000-51.89/1000 -> 1.8582869 | I36: 0.68 | J36: =3.597/3.52-1 -> 0.021875 | K36: =IF(E36<0,0,E36)/1000 -> 0.66 | L36: =IFERROR(H36*K36,0)*1000 -> 1226.4694 | M36: =207.84*K36 -> 137.1744 | N36: =$N$61/1200*K36 -> 43.21845 | O36: =$O$61/1200*K36 -> 84.96015 | P36: =$P$61/1200*K36 -> 67.916393 | Q36: 0 | R36: 0 | S36: =L36+M36+N36+O36 -> 1491.8224 | T36: =IFERROR(S36/K36,0) -> 2260.3369
A37: 10009777 | B37: POTA REJOS FR C/U C/V S/OR 0.3-0.5BL10 | C37: 6480 | D37: 55360 | E37: -48880 | G37: 10007162 | H37: =IFERROR(INDEX([2]Resumen!$K$3:$K$63,MATCH(G37,[2]Resumen!$C$3:$C$63,0)),0)*(1+I37*J37)/1000-51.89/1000 -> 1.8582869 | I37: 0.68 | J37: =3.597/3.52-1 -> 0.021875 | K37: =IF(E37<0,0,E37)/1000 -> 0 | L37: =IFERROR(H37*K37,0)*1000 -> 0 | M37: =207.84*K37 -> 0 | N37: =$N$61/1200*K37 -> 0 | O37: =$O$61/1200*K37 -> 0 | P37: =$P$61/1200*K37 -> 0 | Q37: 0 | R37: 0 | S37: =L37+M37+N37+O37 -> 0 | T37: =IFERROR(S37/K37,0) -> 0
A38: 10009989 | B38: POTA REJOS FR C/U C/V S/OR 0.5-1.0 BL10 | C38: 81400 | D38: 19940 | E38: 61460 | G38: 10007162 | H38: =IFERROR(INDEX([2]Resumen!$K$3:$K$63,MATCH(G38,[2]Resumen!$C$3:$C$63,0)),0)*(1+I38*J38)/1000-51.89/1000 -> 1.8582869 | I38: 0.68 | J38: =3.597/3.52-1 -> 0.021875 | K38: =IF(E38<0,0,E38)/1000 -> 61.46 | L38: =IFERROR(H38*K38,0)*1000 -> 114210.32 | M38: =207.84*K38 -> 12773.846 | N38: =$N$61/1200*K38 -> 4024.5545 | O38: =$O$61/1200*K38 -> 7911.5922 | P38: =$P$61/1200*K38 -> 6324.4568 | Q38: 0 | R38: 0 | S38: =L38+M38+N38+O38 -> 138920.31 | T38: =IFERROR(S38/K38,0) -> 2260.3369
A39: 10009187 | B39: POTA REJOS FR C/B S/U S/V S/OR 0.3-0.5 BL10 | C39: 340 | E39: 340 | G39: 10007162 | H39: =IFERROR(INDEX([2]Resumen!$K$3:$K$63,MATCH(G39,[2]Resumen!$C$3:$C$63,0)),0)*(1+I39*J39)/1000-51.89/1000 -> 1.8582869 | I39: 0.68 | J39: =3.597/3.52-1 -> 0.021875 | K39: =IF(E39<0,0,E39)/1000 -> 0.34 | L39: =IFERROR(H39*K39,0)*1000 -> 631.81756 | M39: =207.84*K39 -> 70.6656 | N39: =$N$61/1200*K39 -> 22.26405 | O39: =$O$61/1200*K39 -> 43.76735 | P39: =$P$61/1200*K39 -> 34.987233 | Q39: 0 | R39: 0 | S39: =L39+M39+N39+O39 -> 768.51456 | T39: =IFERROR(S39/K39,0) -> 2260.3369
A40: 10007161 | B40: POTA REJOS FR C/B S/U S/V S/OR 0.5-1 BL1 0 | C40: 22550 | E40: 22550 | G40: 10007162 | H40: =IFERROR(INDEX([2]Resumen!$K$3:$K$63,MATCH(G40,[2]Resumen!$C$3:$C$63,0)),0)*(1+I40*J40)/1000-51.89/1000 -> 1.8582869 | I40: 0.68 | J40: =3.597/3.52-1 -> 0.021875 | K40: =IF(E40<0,0,E40)/1000 -> 22.55 | L40: =IFERROR(H40*K40,0)*1000 -> 41904.37 | M40: =207.84*K40 -> 4686.792 | N40: =$N$61/1200*K40 -> 1476.6304 | O40: =$O$61/1200*K40 -> 2902.8051 | P40: =$P$61/1200*K40 -> 2320.4767 | Q40: 0 | R40: 0 | S40: =L40+M40+N40+O40 -> 50970.598 | T40: =IFERROR(S40/K40,0) -> 2260.3369
...
