Workbook

Sheet Resumen Inventario
C2: PERU FROST
C3: AVANCE COMERCIAL AL 19-10-2026
C5: STOCK PAITA | F5: RENTABILIDAD DEL INVENTARIO
B6: Código | C6: Producto | D6: TM en Stock Libre | E6: CU | F6: Costo Ventas | G6: Gasto Ventas | H6: Gasto ADM | I6: Gasto Fin | J6: Depreciación | K6: Utilidad Neta | L6: Margen Neto | M6: Venta Equilibrio a Utd Neta | N6: Precio Equilibrio x TM a Utd Neta | O6: Venta Equilibro a EBITDA | P6: Precio Equilibrio x TM a EBITDA | Q6: Precio Mercado | R6: Venta total | S6: Utilidad | T6: Mg Neto | U6: EBITDA | V6: Mg EBITDA
B7: 10005721 | C7: POTA FILETE CONGELADO | D7: =TD!F4 -> 133.8 | E7: =IFERROR(F7/D7,0) -> 1599.269 | F7: =TD!G4 -> 213982.19 | G7: =TD!H4 -> 32146.788 | H7: =TD!I4 -> 4120.4105 | I7: =TD!J4 -> 11130.984 | J7: =TD!K4 -> 8107.2914 | K7: 0 | L7: 0 | M7: =F7+G7+H7+I7 -> 261380.37 | N7: =IFERROR(M7/D7,0) -> 1953.5155 | O7: =F7+G7+H7-J7 -> 242142.1 | P7: =IFERROR(O7/D7,0) -> 1809.7317 | Q7: 1800 | R7: =Q7*D7 -> 240840 | S7: =R7-M7 -> -20540.371 | T7: =IFERROR(S7/R7,0) -> -0.085286377 | U7: =R7-(M7-J7-I7) -> -1302.096 | V7: =IFERROR(U7/R7,0) -> -0.0054064772
B8: 10005779 | C8: POTA NUCAS CONGELADAS | D8: =TD!F5 -> 448.82 | E8: =IFERROR(F8/D8,0) -> 1529.0556 | F8: =TD!G5 -> 686270.72 | G8: =TD!H5 -> 107833.49 | H8: =TD!I5 -> 13821.544 | I8: =TD!J5 -> 37337.878 | J8: =TD!K5 -> 27195.176 | K8: 0 | L8: 0 | M8: =F8+G8+H8+I8 -> 845263.64 | N8: =IFERROR(M8/D8,0) -> 1883.3021 | O8: =F8+G8+H8-J8 -> 780730.58 | P8: =IFERROR(O8/D8,0) -> 1739.5183 | Q8: 1400 | R8: =Q8*D8 -> 628348 | S8: =R8-M8 -> -216915.64 | T8: =IFERROR(S8/R8,0) -> -0.34521577 | U8: =R8-(M8-J8-I8) -> -152382.58 | V8: =IFERROR(U8/R8,0) -> -0.24251304
B9: 10006719 | C9: POTA ALAS CONGELADAS | D9: =TD!F6 -> 79.06 | E9: =IFERROR(F9/D9,0) -> 1447.9797 | F9: =TD!G6 -> 114477.28 | G9: =TD!H6 -> 18994.956 | H9: =TD!I6 -> 2434.676 | I9: =TD!J6 -> 6577.0969 | J9: =TD!K6 -> 4790.4519 | K9: 0 | L9: 0 | M9: =F9+G9+H9+I9 -> 142484 | N9: =IFERROR(M9/D9,0) -> 1802.2262 | O9: =F9+G9+H9-J9 -> 131116.46 | P9: =IFERROR(O9/D9,0) -> 1658.4424 | Q9: 2000 | R9: =Q9*D9 -> 158120 | S9: =R9-M9 -> 15635.996 | T9: =IFERROR(S9/R9,0) -> 0.098886895 | U9: =R9-(M9-J9-I9) -> 27003.545 | V9: =IFERROR(U9/R9,0) -> 0.1707788
B10: 10007050 | C10: POTA RECORTES COCIDOS | D10: =TD!F7 -> 69.592 | E10: =IFERROR(F10/D10,0) -> 1288.0841 | F10: =TD!G7 -> 89640.352 | G10: =TD!H7 -> 16720.174 | H10: =TD!I7 -> 2143.1062 | I10: =TD!J7 -> 5789.4426 | J10: =TD!K7 -> 4216.761 | K10: 0 | L10: 0 | M10: =F10+G10+H10+I10 -> 114293.07 | N10: =IFERROR(M10/D10,0) -> 1642.3306 | O10: =F10+G10+H10-J10 -> 104286.87 | P10: =IFERROR(O10/D10,0) -> 1498.5468 | Q10: 2200 | R10: =Q10*D10 -> 153102.4 | S10: =R10-M10 -> 38809.326 | T10: =IFERROR(S10/R10,0) -> 0.25348607 | U10: =R10-(M10-J10-I10) -> 48815.529 | V10: =IFERROR(U10/R10,0) -> 0.31884235
B11: 10007162 | C11: POTA REJOS CONGELADOS | D11: =TD!F8 -> 552.72 | E11: =IFERROR(F11/D11,0) -> 1660.2122 | F11: =TD!G8 -> 917632.51 | G11: =TD!H8 -> 132796.51 | H11: =TD!I8 -> 17021.175 | I11: =TD!J8 -> 45981.445 | J11: =TD!K8 -> 33490.748 | K11: 0 | L11: 0 | M11: =F11+G11+H11+I11 -> 1113431.6 | N11: =IFERROR(M11/D11,0) -> 2014.4587 | O11: =F11+G11+H11-J11 -> 1033959.4 | P11: =IFERROR(O11/D11,0) -> 1870.6749 | Q11: 2157.3165 | R11: =Q11*D11 -> 1192392 | S11: =R11-M11 -> 78960.365 | T11: =IFERROR(S11/R11,0) -> 0.06622014 | U11: =R11-(M11-J11-I11) -> 158432.56 | V11: =IFERROR(U11/R11,0) -> 0.13286952
B12: 10007567 | C12: POTA REPRODUCTORES | D12: =TD!F9 -> 148.64 | E12: =IFERROR(F12/D12,0) -> 1613.9706 | F12: =TD!G9 -> 239900.6 | G12: =TD!H9 -> 35712.246 | H12: =TD!I9 -> 4577.4126 | I12: =TD!J9 -> 12365.541 | J12: =TD!K9 -> 9006.4857 | K12: 0 | L12: 0 | M12: =F12+G12+H12+I12 -> 292555.8 | N12: =IFERROR(M12/D12,0) -> 1968.2171 | O12: =F12+G12+H12-J12 -> 271183.77 | P12: =IFERROR(O12/D12,0) -> 1824.4333 | Q12: 2800 | R12: =Q12*D12 -> 416192 | S12: =R12-M12 -> 123636.2 | T12: =IFERROR(S12/R12,0) -> 0.29706531 | U12: =R12-(M12-J12-I12) -> 145008.23 | V12: =IFERROR(U12/R12,0) -> 0.34841667
B13: 10007969 | C13: POTA CONOS | D13: =TD!F10 -> 0 | E13: =IFERROR(F13/D13,0) -> 0 | F13: =TD!G10 -> 0 | G13: =TD!H10 -> 0 | H13: =TD!I10 -> 0 | I13: =TD!J10 -> 0 | J13: =TD!K10 -> 0 | K13: 0 | L13: 0 | M13: =F13+G13+H13+I13 -> 0 | N13: =IFERROR(M13/D13,0) -> 0 | O13: =F13+G13+H13-J13 -> 0 | P13: =IFERROR(O13/D13,0) -> 0 | Q13: 1750 | R13: =Q13*D13 -> 0 | S13: =R13-M13 -> 0 | T13: =IFERROR(S13/R13,0) -> 0 | U13: =R13-(M13-J13-I13) -> 0 | V13: =IFERROR(U13/R13,0) -> 0
B14: 10009239 | C14: POTA FILETE DARUMA | D14: =TD!F11 -> 315.44 | E14: =IFERROR(F14/D14,0) -> 3028.426 | F14: =TD!G11 -> 955286.7 | G14: =TD!H11 -> 75787.614 | H14: =TD!I11 -> 9714.0678 | I14: =TD!J11 -> 26241.835 | J14: =TD!K11 -> 19113.333 | K14: 0 | L14: 0 | M14: =F14+G14+H14+I14 -> 1067030.2 | N14: =IFERROR(M14/D14,0) -> 3382.6725 | O14: =F14+G14+H14-J14 -> 1021675.1 | P14: =IFERROR(O14/D14,0) -> 3238.8887 | Q14: 3600 | R14: =Q14*D14 -> 1135584 | S14: =R14-M14 -> 68553.778 | T14: =IFERROR(S14/R14,0) -> 0.060368743 | U14: =R14-(M14-J14-I14) -> 113908.95 | V14: =IFERROR(U14/R14,0) -> 0.10030869
B15: 10009334 | C15: POTA ALAS COCIDAS | D15: =TD!F12 -> 147.152 | E15: =IFERROR(F15/D15,0) -> 2652.5147 | F15: =TD!G12 -> 390322.85 | G15: =TD!H12 -> 35354.74 | H15: =TD!I12 -> 4531.5892 | I15: =TD!J12 -> 12241.753 | J15: =TD!K12 -> 8916.3239 | K15: 0 | L15: 0 | M15: =F15+G15+H15+I15 -> 442450.93 | N15: =IFERROR(M15/D15,0) -> 3006.7612 | O15: =F15+G15+H15-J15 -> 421292.85 | P15: =IFERROR(O15/D15,0) -> 2862.9774 | Q15: 3800 | R15: =Q15*D15 -> 559177.6 | S15: =R15-M15 -> 116726.67 | T15: =IFERROR(S15/R15,0) -> 0.20874704 | U15: =R15-(M15-J15-I15) -> 137884.75 | V15: =IFERROR(U15/R15,0) -> 0.24658489
B16: 10009386 | C16: VENTOSAS | D16: =TD!F13 -> 25.18 | E16: =IFERROR(F16/D16,0) -> 2183.6494 | F16: =TD!G13 -> 54984.293 | G16: =TD!H13 -> 6049.7468 | H16: =TD!I13 -> 775.42553 | I16: =TD!J13 -> 2094.7546 | J16: =TD!K13 -> 1525.722 | K16: 0 | L16: 0 | M16: =F16+G16+H16+I16 -> 63904.22 | N16: =IFERROR(M16/D16,0) -> 2537.8959 | O16: =F16+G16+H16-J16 -> 60283.743 | P16: =IFERROR(O16/D16,0) -> 2394.1121 | Q16: 3900 | R16: =Q16*D16 -> 98202 | S16: =R16-M16 -> 34297.78 | T16: =IFERROR(S16/R16,0) -> 0.34925745 | U16: =R16-(M16-J16-I16) -> 37918.257 | V16: =IFERROR(U16/R16,0) -> 0.3861251
B17: 10009386 | C17: FILETE REPROCESO | D17: =TD!F14 -> 69.24 | E17: =IFERROR(F17/D17,0) -> 1488.5392 | F17: =TD!G14 -> 103066.46 | G17: =TD!H14 -> 16635.602 | H17: =TD!I14 -> 2132.2662 | I17: =TD!J14 -> 5760.1593 | J17: =TD!K14 -> 4195.4324 | K17: 0 | L17: 0 | M17: =F17+G17+H17+I17 -> 127594.48 | N17: =IFERROR(M17/D17,0) -> 1842.7857 | O17: =F17+G17+H17-J17 -> 117638.89 | P17: =IFERROR(O17/D17,0) -> 1699.0019 | Q17: 1800 | R17: =Q17*D17 -> 124632 | S17: =R17-M17 -> -2962.4838 | T17: =IFERROR(S17/R17,0) -> -0.023769848 | U17: =R17-(M17-J17-I17) -> 6993.1079 | V17: =IFERROR(U17/R17,0) -> 0.056110051
C18: MANTO | D18: =TD!F15 -> 54.28 | E18: =IFERROR(F18/D18,0) -> 1295.7231 | F18: =TD!G15 -> 70331.848 | G18: =TD!H15 -> 13041.313 | H18: =TD!I15 -> 1671.5686 | I18: =TD!J15 -> 4515.6188 | J18: =TD!K15 -> 3288.9669 | K18: 0 | L18: 0 | M18: =F18+G18+H18+I18 -> 89560.348 | N18: =IFERROR(M18/D18,0) -> 1649.9696 | O18: =F18+G18+H18-J18 -> 81755.762 | P18: =IFERROR(O18/D18,0) -> 1506.1857 | Q18: 1550 | R18: =Q18*D18 -> 84134 | S18: =R18-M18 -> -5426.3478 | T18: =IFERROR(S18/R18,0) -> -0.064496491 | U18: =R18-(M18-J18-I18) -> 2378.238 | V18: =IFERROR(U18/R18,0) -> 0.028267264
C19: TOTAL | D19: =SUM(D7:D18) -> 2043.924 | E19: =IFERROR(F19/D19,0) -> 1876.7311 | F19: =SUM(F7:F18) -> 3835895.8 | G19: =SUM(G7:G18) -> 491073.18 | H19: =SUM(H7:H18) -> 62943.242 | I19: =SUM(I7:I18) -> 170036.51 | J19: =SUM(J7:J18) -> 123846.69 | K19: =SUM(K7:K18) -> 0 | L19: 0 | M19: =SUM(M7:M18) -> 4559948.7 | N19: =IFERROR(M19/D19,0) -> 2230.9776 | O19: =SUM(O7:O18) -> 4266065.5 | P19: =IFERROR(O19/D19,0) -> 2087.1938 | Q19: =R19/D19 -> 2343.8856 | R19: =SUM(R7:R18) -> 4790724 | S19: =SUM(S7:S18) -> 230775.28 | T19: =S19/R19 -> 0.048171274 | U19: =SUM(U7:U18) -> 524658.48 | V19: =IFERROR(U19/R19,0) -> 0.10951549
C21: STOCK DE CHINA
C22: Producto | D22: TM en Stock Libre | E22: CU | F22: Costo Ventas | G22: Gasto Ventas | H22: Gasto ADM | I22: Gasto Fin | J22: Depreciación | K22: Utilidad Neta | L22: Margen Neto | M22: Venta Equilibrio a Utd Neta | N22: Precio Equilibrio x TM a Utd Neta | O22: Venta Equilibro a EBITDA | P22: Precio Equilibrio x TM a EBITDA | Q22: Precio Mercado | R22: Venta total | S22: Utilidad | T22: Mg Neto | U22: EBITDA | V22: Mg EBITDA
C23: POTA FILETE CONGELADO | D23: =Stock!K61 -> 0 | E23: =IFERROR(F23/D23,0) -> 0 | F23: =Stock!L61 -> 0 | G23: =Stock!M61 -> 0 | H23: =Stock!N61 -> 0 | I23: =Stock!O61 -> 0 | J23: =Stock!P61 -> 0 | K23: 0 | L23: 0 | M23: =F23+G23+H23+I23 -> 0 | N23: =IFERROR(M23/D23,0) -> 0 | O23: =F23+G23+H23-J23 -> 0 | P23: =IFERROR(O23/D23,0) -> 0 | Q23: =Q7 -> 1800 | R23: =Q23*D23 -> 0 | S23: =R23-M23 -> 0 | T23: =IFERROR(S23/R23,0) -> 0 | U23: =R23-(M23-J23-I23) -> 0 | V23: =IFERROR(U23/R23,0) -> 0
C24: POTA ALAS CONGELADAS | D24: =Stock!K62 -> 0 | E24: =IFERROR(F24/D24,0) -> 0 | F24: =Stock!L62 -> 0 | G24: =Stock!M62 -> 0 | H24: =Stock!N62 -> 0 | I24: =Stock!O62 -> 0 | J24: =Stock!P62 -> 0 | K24: 0 | L24: 0 | M24: =F24+G24+H24+I24 -> 0 | N24: =IFERROR(M24/D24,0) -> 0 | O24: =F24+G24+H24-J24 -> 0 | P24: =IFERROR(O24/D24,0) -> 0 | Q24: =Q9 -> 2000 | R24: =Q24*D24 -> 0 | S24: =R24-M24 -> 0 | T24: =IFERROR(S24/R24,0) -> 0 | U24: =R24-(M24-J24-I24) -> 0 | V24: =IFERROR(U24/R24,0) -> 0
C25: POTA REJOS CONGELADOS | D25: =Stock!K63 -> 27 | E25: =IFERROR(F25/D25,0) -> 1661.5122 | F25: =Stock!L63 -> 44860.829 | G25: =Stock!M63 -> 6487.02 | H25: =Stock!N63 -> 2539.1716 | I25: =Stock!O63 -> 6859.384 | J25: =Stock!P63 -> 4996.0566 | K25: 0 | L25: 0 | M25: =F25+G25+H25+I25 -> 60746.405 | N25: =IFERROR(M25/D25,0) -> 2249.8668 | O25: =F25+G25+H25-J25 -> 48890.964 | P25: =IFERROR(O25/D25,0) -> 1810.7764 | Q25: 2500 | R25: =Q25*D25 -> 67500 | S25: =R25-M25 -> 6753.5952 | T25: =IFERROR(S25/R25,0) -> 0.10005326 | U25: =R25-(M25-J25-I25) -> 18609.036 | V25: =IFERROR(U25/R25,0) -> 0.27568942
C26: POTA FILETE DARUMA | D26: =Stock!K64 -> 589.2 | E26: =IFERROR(F26/D26,0) -> 2846.957 | F26: =Stock!L64 -> 1677427.1 | G26: =Stock!M64 -> 141561.19 | H26: =Stock!N64 -> 55410.367 | I26: =Stock!O64 -> 149687 | J26: =Stock!P64 -> 109025.06 | K26: 0 | L26: 0 | M26: =F26+G26+H26+I26 -> 2024085.6 | N26: =IFERROR(M26/D26,0) -> 3435.3117 | O26: =F26+G26+H26-J26 -> 1765373.6 | P26: =IFERROR(O26/D26,0) -> 2996.2213 | Q26: =Q14 -> 3600 | R26: =Q26*D26 -> 2121120 | S26: =R26-M26 -> 97034.375 | T26: =IFERROR(S26/R26,0) -> 0.045746764 | U26: =R26-(M26-J26-I26) -> 355746.43 | V26: =IFERROR(U26/R26,0) -> 0.16771632
C27: POTA ALAS COCIDAS | D27: =Stock!K65 -> 53.1 | E27: =IFERROR(F27/D27,0) -> 2781.1294 | F27: =Stock!L65 -> 147677.97 | G27: =Stock!M65 -> 12757.806 | H27: =Stock!N65 -> 4993.7041 | I27: =Stock!O65 -> 13490.122 | J27: =Stock!P65 -> 9825.578 | K27: 0 | L27: 0 | M27: =F27+G27+H27+I27 -> 178919.6 | N27: =IFERROR(M27/D27,0) -> 3369.484 | O27: =F27+G27+H27-J27 -> 155603.9 | P27: =IFERROR(O27/D27,0) -> 2930.3936 | Q27: =Q15 -> 3800 | R27: =Q27*D27 -> 201780 | S27: =R27-M27 -> 22860.399 | T27: =IFERROR(S27/R27,0) -> 0.11329368 | U27: =R27-(M27-J27-I27) -> 46176.099 | V27: =IFERROR(U27/R27,0) -> 0.22884378
C28: POTA RECORTES COCIDOS | D28: =Stock!K66 -> 0 | E28: =IFERROR(F28/D28,0) -> 0 | F28: =Stock!L66 -> 0 | G28: =Stock!M66 -> 0 | H28: =Stock!N66 -> 0 | I28: =Stock!O66 -> 0 | J28: =Stock!P66 -> 0 | K28: 0 | L28: 0 | M28: =F28+G28+H28+I28 -> 0 | N28: =IFERROR(M28/D28,0) -> 0 | O28: =F28+G28+H28-J28 -> 0 | P28: =IFERROR(O28/D28,0) -> 0 | Q28: =Q10 -> 2200 | R28: =Q28*D28 -> 0 | S28: =R28-M28 -> 0 | T28: =IFERROR(S28/R28,0) -> 0 | U28: =R28-(M28-J28-I28) -> 0 | V28: =IFERROR(U28/R28,0) -> 0
C29: TOTAL | D29: =SUM(D23:D28) -> 669.3 | E29: =F29/D29 -> 2793.9128 | F29: =SUM(F23:F28) -> 1869965.9 | G29: =SUM(G23:G28) -> 160806.02 | H29: =SUM(H23:H28) -> 62943.243 | I29: =SUM(I23:I28) -> 170036.51 | J29: =SUM(J23:J28) -> 123846.69 | K29: =SUM(K23:K28) -> 0 | L29: 0 | M29: =SUM(M23:M28) -> 2263751.6 | N29: =IFERROR(M29/D29,0) -> 3382.2675 | O29: =SUM(O23:O28) -> 1969868.4 | P29: =IFERROR(O29/D29,0) -> 2943.1771 | Q29: =R29/D29 -> 3571.4926 | R29: =SUM(R23:R28) -> 2390400 | S29: =SUM(S23:S28) -> 126648.37 | T29: =S29/R29 -> 0.052982082 | U29: =SUM(U23:U28) -> 420531.57 | V29: =IFERROR(U29/R29,0) -> 0.17592519
C31: TOTAL | D31: =D19+D29 -> 2713.224 | E31: =F31/D31 -> 2102.9822 | F31: =F19+F29 -> 5705861.7 | G31: =G19+G29 -> 651879.2 | H31: =H19+H29 -> 125886.49 | I31: =I19+I29 -> 340073.01 | J31: =J19+J29 -> 247693.39 | K31: =K19+K29 -> 0 | L31: 0 | M31: =M19+M29 -> 6823700.4 | N31: =IFERROR(M31/D31,0) -> 2514.9786 | O31: =O19+O29 -> 6235934 | P31: =IFERROR(O31/D31,0) -> 2298.3484 | Q31: =R31/D31 -> 2646.7125 | R31: =R19+R29 -> 7181124 | S31: =S19+S29 -> 357423.65 | T31: =S31/R31 -> 0.049772661 | U31: =U19+U29 -> 945190.05 | V31: =IFERROR(U31/R31,0) -> 0.13162146
S34: =F31*7%/12 -> 33284.193 | T34: costo financiero mes
S35: =S34/D31 -> 12.267396 | T35: costo financiero por tm
S36: =42/6*D29 -> 4685.1 | T36: costo almacenamiento mensual

Sheet Venta Octubre
A2: VENTA DE OCTUBRE 2026
A4: MES | B4: FP | C4: Fecha FP | D4: Fecha Embarque | E4: Producto | F4: Cantidad | G4: Corte | H4: Espec. | I4: País | J4: Puerto | K4: Cliente (Razón Social) | L4: Contacto | M4: Stock | N4: Precio TM | O4: VENTA CFR | P4: Flete | Q4: CU | R4: Costo Ventas | S4: Utilidad Bruta | T4: Gasto Ventas | U4: Gasto Adm | V4: Drawback | W4: Utilidad Operativa | X4: Gasto Financiero | Y4: Utilidad Neta | Z4: Depreciación | AA4: EBITDA | AC4: Margen Bruto | AD4: Margen Operativo | AE4: Margen Neto | AF4: Margen EBITDA
A5: OCTUBRE | B5: 281-2026A | C5: 46269 | D5: 46312 | E5: POTA CONOS | F5: 21.6 | G5: Conos | I5: Tailandia | J5: Lat Krabang | K5: TSUJINO | L5: Jose | M5: Paita | N5: 1750 | O5: 37800 | P5: 2900 | Q5: =Stock!H11 -> 1016.9571 | R5: =Q5*F5 -> 21966.274 | S5: =O5-R5 -> 15833.726 | T5: =F5*240.26 -> 5189.616 | U5: =U$23/$F$23*$F5 -> 1746.9519 | V5: =(O5-P5)*0.03 -> 1047 | W5: =S5-T5-U5+V5 -> 9944.1585 | X5: =X$23/$F$23*$F5 -> 4719.2611 | Y5: =W5-X5 -> 5224.8974 | Z5: =Z$23/$F$23*$F5 -> 3437.2906 | AA5: =W5+Z5 -> 13381.449 | AC5: =S5/O5 -> 0.41888165 | AD5: =W5/O5 -> 0.26307298 | AE5: =Y5/O5 -> 0.1382248 | AF5: =AA5/O5 -> 0.35400659
A6: OCTUBRE | B6: 283-2026 | C6: 253 | D6: 46302 | E6: POTA ALAS CONGELADAS | F6: 48 | G6: Alas | H6: 1-2 SIN CORTAR | I6: Japón | J6: Hachinohe | K6: TSUJINO | L6: Jose | M6: Paita | N6: 1700 | O6: 81600 | P6: 7072 | Q6: =Stock!H5 -> 1492.4271 | R6: =Q6*F6 -> 71636.499 | S6: =O6-R6 -> 9963.5009 | T6: =F6*240.26 -> 11532.48 | U6: =U$23/$F$23*$F6 -> 3882.1153 | V6: =(O6-P6)*0.03 -> 2235.84 | W6: =S6-T6-U6+V6 -> -3215.2544 | X6: =X$23/$F$23*$F6 -> 10487.247 | Y6: =W6-X6 -> -13702.501 | Z6: =Z$23/$F$23*$F6 -> 7638.4234 | AA6: =W6+Z6 -> 4423.169 | AC6: =S6/O6 -> 0.12210173 | AD6: =W6/O6 -> -0.039402627 | AE6: =Y6/O6 -> -0.16792281 | AF6: =AA6/O6 -> 0.054205503
A7: OCTUBRE | B7: 284-2026 | C7: 254 | D7: 46304 | E7: POTA REPRODUCTORES | F7: 26.5 | G7: Rejos Re | H7: + 60 CM , SUCKERS OFF | I7: Mexico | J7: Manzanillo | K7: GOLDEN SEAFOOD | L7: alexander | M7: Paita | N7: 2520 | O7: 66780 | P7: 2487 | Q7: =Stock!H31 -> 1601.7008 | R7: =Q7*F7 -> 42445.072 | S7: =O7-R7 -> 24334.928 | T7: =F7*240.26 -> 6366.89 | U7: =U$23/$F$23*$F7 -> 2143.2512 | V7: =(O7-P7)*0.03 -> 1928.79 | W7: =S7-T7-U7+V7 -> 17753.576 | X7: =X$23/$F$23*$F7 -> 5789.8342 | Y7: =W7-X7 -> 11963.742 | Z7: =Z$23/$F$23*$F7 -> 4217.0463 | AA7: =W7+Z7 -> 21970.623 | AC7: =S7/O7 -> 0.36440443 | AD7: =W7/O7 -> 0.2658517 | AE7: =Y7/O7 -> 0.17915158 | AF7: =AA7/O7 -> 0.32900004
A8: OCTUBRE | B8: 289-2026 | C8: 46282 | D8: 46309 | E8: POTA ALAS CONGELADAS | F8: 27 | G8: Alas | H8: 1-2 no cortadas plate frozen | I8: China | J8: Shidao | K8: Shenzhen Yueshi Supply | L8: Susan | M8: Paita | N8: 1700 | O8: 45900 | P8: 2569 | Q8: =Q6 -> 1492.4271 | R8: =Q8*F8 -> 40295.531 | S8: =O8-R8 -> 5604.4693 | T8: =F8*240.26 -> 6487.02 | U8: =U$23/$F$23*$F8 -> 2183.6899 | V8: =(O8-P8)*0.03 -> 1299.93 | W8: =S8-T8-U8+V8 -> -1766.3106 | X8: =X$23/$F$23*$F8 -> 5899.0764 | Y8: =W8-X8 -> -7665.387 | Z8: =Z$23/$F$23*$F8 -> 4296.6132 | AA8: =W8+Z8 -> 2530.3026 | AC8: =S8/O8 -> 0.12210173 | AD8: =W8/O8 -> -0.038481712 | AE8: =Y8/O8 -> -0.1670019 | AF8: =AA8/O8 -> 0.055126418
A9: OCTUBRE | B9: 290-2026 | C9: 46282 | D9: 46309 | E9: POTA ALAS CONGELADAS | F9: 27 | G9: Alas | H9: 1-2 no cortadas plate frozen | I9: China | J9: Shidao | K9: Dexianhui Technology | L9: Susan | M9: Paita | N9: 1700 | O9: 45900 | P9: 2569 | Q9: =Q8 -> 1492.4271 | R9: =Q9*F9 -> 40295.531 | S9: =O9-R9 -> 5604.4693 | T9: =F9*240.26 -> 6487.02 | U9: =U$23/$F$23*$F9 -> 2183.6899 | V9: =(O9-P9)*0.03 -> 1299.93 | W9: =S9-T9-U9+V9 -> -1766.3106 | X9: =X$23/$F$23*$F9 -> 5899.0764 | Y9: =W9-X9 -> -7665.387 | Z9: =Z$23/$F$23*$F9 -> 4296.6132 | AA9: =W9+Z9 -> 2530.3026 | AC9: =S9/O9 -> 0.12210173 | AD9: =W9/O9 -> -0.038481712 | AE9: =Y9/O9 -> -0.1670019 | AF9: =AA9/O9 -> 0.055126418
A10: OCTUBRE | B10: 291-2026A | C10: 261 | D10: 46299 | E10: POTA ALAS CONGELADAS | F10: 81 | G10: Alas | H10: 1-2 SIN CORTAR tunel | I10: China | J10: Shidao | K10: TSUJINO | L10: Jose | M10: Paita | N10: 1650 | O10: 133650 | P10: 10608 | Q10: =Q9 -> 1492.4271 | R10: =Q10*F10 -> 120886.59 | S10: =O10-R10 -> 12763.408 | T10: =F10*240.26 -> 19461.06 | U10: =U$23/$F$23*$F10 -> 6551.0696 | V10: =(O10-P10)*0.03 -> 3691.26 | W10: =S10-T10-U10+V10 -> -9557.4618 | X10: =X$23/$F$23*$F10 -> 17697.229 | Y10: =W10-X10 -> -27254.691 | Z10: =Z$23/$F$23*$F10 -> 12889.84 | AA10: =W10+Z10 -> 3332.3778 | AC10: =S10/O10 -> 0.095498749 | AD10: =W10/O10 -> -0.071511125 | AE10: =Y10/O10 -> -0.20392586 | AF10: =AA10/O10 -> 0.024933616
A11: OCTUBRE | B11: 291-2026B | C11: 261 | D11: 46299 | E11: POTA ALAS CONGELADAS | F11: 54 | G11: Alas | H11: 1-2 SIN CORTAR tunel | I11: China | J11: Shidao | K11: TSUJINO | L11: Jose | M11: Paita | N11: 1650 | O11: 89100 | P11: 7072 | Q11: =Q10 -> 1492.4271 | R11: =Q11*F11 -> 80591.061 | S11: =O11-R11 -> 8508.9385 | T11: =F11*240.26 -> 12974.04 | U11: =U$23/$F$23*$F11 -> 4367.3797 | V11: =(O11-P11)*0.03 -> 2460.84 | W11: =S11-T11-U11+V11 -> -6371.6412 | X11: =X$23/$F$23*$F11 -> 11798.153 | Y11: =W11-X11 -> -18169.794 | Z11: =Z$23/$F$23*$F11 -> 8593.2264 | AA11: =W11+Z11 -> 2221.5852 | AC11: =S11/O11 -> 0.095498749 | AD11: =W11/O11 -> -0.071511125 | AE11: =Y11/O11 -> -0.20392586 | AF11: =AA11/O11 -> 0.024933616
A12: OCTUBRE | B12: 295-2026 | C12: 46288 | D12: 46312 | E12: POTA LABIOS CONGELADOS | F12: 23.8 | G12: Labios | I12: China | J12: Shidao | K12: QINGDAO OCEAN | L12: Barton | M12: Paita | N12: 1400 | O12: 33320 | P12: 2700 | Q12: =Stock!H10 -> 1322.3616 | R12: =Q12*F12 -> 31472.206 | S12: =O12-R12 -> 1847.7941 | T12: =F12*240.26 -> 5718.188 | U12: =U$23/$F$23*$F12 -> 1924.8822 | V12: =(O12-P12)*0.03 -> 918.6 | W12: =S12-T12-U12+V12 -> -4876.676 | X12: =X$23/$F$23*$F12 -> 5199.9266 | Y12: =W12-X12 -> -10076.603 | Z12: =Z$23/$F$23*$F12 -> 3787.385 | AA12: =W12+Z12 -> -1089.2911 | AC12: =S12/O12 -> 0.055456006 | AD12: =W12/O12 -> -0.14635882 | AE12: =Y12/O12 -> -0.30241905 | AF12: =AA12/O12 -> -0.032691809
A13: OCTUBRE | B13: 296-2026 | C13: 272 | D13: 46312 | E13: POTA FILETE DARUMA | F13: 22.6 | G13: Daruma | I13: Japón | J13: Hachinohe | K13: TSUJINO | L13: Jose | M13: Paita | N13: 3250 | O13: 73450 | P13: 3965 | Q13: =Stock!H44 -> 3032.3611 | R13: =Q13*F13 -> 68531.361 | S13: =O13-R13 -> 4918.6393 | T13: =F13*240.26 -> 5429.876 | U13: =U$23/$F$23*$F13 -> 1827.8293 | V13: =(O13-P13)*0.03 -> 2084.55 | W13: =S13-T13-U13+V13 -> -254.51599 | X13: =X$23/$F$23*$F13 -> 4937.7454 | Y13: =W13-X13 -> -5192.2614 | Z13: =Z$23/$F$23*$F13 -> 3596.4244 | AA13: =W13+Z13 -> 3341.9084 | AC13: =S13/O13 -> 0.066965817 | AD13: =W13/O13 -> -0.0034651599 | AE13: =Y13/O13 -> -0.070691102 | AF13: =AA13/O13 -> 0.045499093
A14: OCTUBRE | B14: 297-2026 | C14: 46301 | D14: 46319 | E14: POTA REJOS CONGELADOS | F14: 27 | G14: Rejos | H14: 500 - 1300 - sucios | I14: China | J14: shidao | K14: VIMARSA IMPORTACIONES SLU | L14: Lucia Conde | M14: Paita | N14: 2400 | O14: 64800 | P14: 2600 | Q14: =Stock!H42 -> 1721.142 | R14: =Q14*F14 -> 46470.834 | S14: =O14-R14 -> 18329.166 | T14: =F14*240.26 -> 6487.02 | U14: =U$23/$F$23*$F14 -> 2183.6899 | V14: =(O14-P14)*0.03 -> 1866 | W14: =S14-T14-U14+V14 -> 11524.456 | X14: =X$23/$F$23*$F14 -> 5899.0764 | Y14: =W14-X14 -> 5625.3799 | Z14: =Z$23/$F$23*$F14 -> 4296.6132 | AA14: =W14+Z14 -> 15821.069 | AC14: =S14/O14 -> 0.2828575 | AD14: =W14/O14 -> 0.17784655 | AE14: =Y14/O14 -> 0.086811418 | AF14: =AA14/O14 -> 0.24415231
A15: OCTUBRE | B15: 299-2026 | C15: 46301 | D15: 46313 | E15: POTA TELILLA PRECOCIDA | F15: 50.94 | G15: Telilla PC | I15: China | J15: Yantai | K15: YANTAI HIZEN INTERNATIONAL | L15: Alicia | M15: Paita | N15: 1800 | O15: 91692 | P15: 5600 | Q15: =Stock!H23 -> 1355.7979 | R15: =Q15*F15 -> 69064.347 | S15: =O15-R15 -> 22627.653 | T15: =F15*240.26 -> 12238.844 | U15: =U$23/$F$23*$F15 -> 4119.8949 | V15: =(O15-P15)*0.03 -> 2582.76 | W15: =S15-T15-U15+V15 -> 8851.6742 | X15: =X$23/$F$23*$F15 -> 11129.591 | Y15: =W15-X15 -> -2277.9166 | Z15: =Z$23/$F$23*$F15 -> 8106.2769 | AA15: =W15+Z15 -> 16957.951 | AC15: =S15/O15 -> 0.24677893 | AD15: =W15/O15 -> 0.096537039 | AE15: =Y15/O15 -> -0.024843134 | AF15: =AA15/O15 -> 0.18494472
A16: OCTUBRE | B16: 299-2026 | C16: 46301 | D16: 46313 | E16: POTA MEMBRANA PRECOCIDA | F16: 50.955 | G16: Membrana PC | I16: China | J16: Yantai | K16: YANTAI HIZEN INTERNATIONAL | L16: Alicia | M16: Paita | N16: 1800 | O16: 91719 | P16: 5600 | Q16: =Q15 -> 1355.7979 | R16: =Q16*F16 -> 69084.684 | S16: =O16-R16 -> 22634.316 | T16: =F16*240.26 -> 12242.448 | U16: =U$23/$F$23*$F16 -> 4121.108 | V16: =(O16-P16)*0.03 -> 2583.57 | W16: =S16-T16-U16+V16 -> 8854.3301 | X16: =X$23/$F$23*$F16 -> 11132.868 | Y16: =W16-X16 -> -2278.5379 | Z16: =Z$23/$F$23*$F16 -> 8108.6639 | AA16: =W16+Z16 -> 16962.994 | AC16: =S16/O16 -> 0.24677893 | AD16: =W16/O16 -> 0.096537578 | AE16: =Y16/O16 -> -0.024842595 | AF16: =AA16/O16 -> 0.18494526
A17: OCTUBRE | B17: 301-2026 | C17: RD FP 275A | D17: 46304 | E17: POTA ALAS COCIDAS | F17: 135 | G17: Alas Precocidas | I17: China | J17: Qingdao | K17: Qingdao Haiyujia | L17: Mark | M17: Paita | N17: 3450 | O17: 465750 | P17: 13000 | Q17: =Stock!H47 -> 2782.8682 | R17: =Q17*F17 -> 375687.21 | S17: =O17-R17 -> 90062.794 | T17: =F17*240.26 -> 32435.1 | U17: =U$23/$F$23*$F17 -> 10918.449 | V17: =(O17-P17)*0.03 -> 13582.5 | W17: =S17-T17-U17+V17 -> 60291.744 | X17: =X$23/$F$23*$F17 -> 29495.382 | Y17: =W17-X17 -> 30796.362 | Z17: =Z$23/$F$23*$F17 -> 21483.066 | AA17: =W17+Z17 -> 81774.81 | AC17: =S17/O17 -> 0.19337154 | AD17: =W17/O17 -> 0.12945087 | AE17: =Y17/O17 -> 0.066122088 | AF17: =AA17/O17 -> 0.17557662
A18: OCTUBRE | B18: 302-2026A | C18: 46307 | D18: 46319 | E18: POTA NUCAS | F18: 25 | G18: Nucas | H18: 500-up | I18: Tailandia | J18: Lat Krabang | K18: TSUJINO | L18: Jose | M18: Paita | N18: 1400 | O18: 35000 | P18: 2900 | Q18: =Stock!H30 -> 1658.4373 | R18: =Q18*F18 -> 41460.932 | S18: =O18-R18 -> -6460.9317 | T18: =F18*240.26 -> 6006.5 | U18: =U$23/$F$23*$F18 -> 2021.9351 | V18: =(O18-P18)*0.03 -> 963 | W18: =S18-T18-U18+V18 -> -13526.367 | X18: =X$23/$F$23*$F18 -> 5462.1078 | Y18: =W18-X18 -> -18988.475 | Z18: =Z$23/$F$23*$F18 -> 3978.3455 | AA18: =W18+Z18 -> -9548.0212 | AC18: =S18/O18 -> -0.18459805 | AD18: =W18/O18 -> -0.38646762 | AE18: =Y18/O18 -> -0.54252784 | AF18: =AA18/O18 -> -0.27280061
A19: OCTUBRE | B19: 303-2026 | C19: RD FP 275B | D19: 46313 | E19: POTA ALAS COCIDAS | F19: 130.86 | G19: Alas Precocidas | I19: China | J19: Qingdao | K19: LONGKOU JIABAO AQUATIC | L19: James | M19: Paita | N19: 3500 | O19: 458010 | P19: 13000 | Q19: =Stock!H47 -> 2782.8682 | R19: =Q19*F19 -> 364166.13 | S19: =O19-R19 -> 93843.868 | T19: =F19*240.26 -> 31440.424 | U19: =U$23/$F$23*$F19 -> 10583.617 | V19: =(O19-P19)*0.03 -> 13350.3 | W19: =S19-T19-U19+V19 -> 65170.127 | X19: =X$23/$F$23*$F19 -> 28590.857 | Y19: =W19-X19 -> 36579.27 | Z19: =Z$23/$F$23*$F19 -> 20824.252 | AA19: =W19+Z19 -> 85994.379 | AC19: =S19/O19 -> 0.2048948 | AD19: =W19/O19 -> 0.14228975 | AE19: =Y19/O19 -> 0.079865659 | AF19: =AA19/O19 -> 0.18775655 | AI19: cobrado
A20: OCTUBRE | B20: 304-2026 | C20: 46309 | D20: 46320 | E20: POTA TELILLA PRECOCIDA | F20: 20 | G20: Telilla PC | I20: China | J20: Yantai | K20: YANTAI HIZEN INTERNATIONAL | L20: Alicia | M20: Paita | N20: 1900 | O20: 38000 | P20: 2074.0741 | Q20: =Q15 -> 1355.7979 | R20: =Q20*F20 -> 27115.959 | S20: =O20-R20 -> 10884.041 | T20: =F20*240.26 -> 4805.2 | U20: =U$23/$F$23*$F20 -> 1617.548 | V20: =(O20-P20)*0.03 -> 1077.7778 | W20: =S20-T20-U20+V20 -> 5539.0711 | X20: =X$23/$F$23*$F20 -> 4369.6862 | Y20: =W20-X20 -> 1169.3849 | Z20: =Z$23/$F$23*$F20 -> 3182.6764 | AA20: =W20+Z20 -> 8721.7476 | AC20: =S20/O20 -> 0.28642214 | AD20: =W20/O20 -> 0.14576503 | AE20: =Y20/O20 -> 0.030773287 | AF20: =AA20/O20 -> 0.22951967 | AI20: cobrado
A21: OCTUBRE | B21: 304-2026 | C21: 46309 | D21: 46320 | E21: POTA MEMBRANA PRECOCIDA | F21: 7 | G21: Membrana PC | I21: China | J21: Yantai | K21: YANTAI HIZEN INTERNATIONAL | L21: Alicia | M21: Paita | N21: 1900 | O21: 13300 | P21: 725.92593 | Q21: =Q16 -> 1355.7979 | R21: =Q21*F21 -> 9490.5855 | S21: =O21-R21 -> 3809.4145 | T21: =F21*240.26 -> 1681.82 | U21: =U$23/$F$23*$F21 -> 566.14181 | V21: =(O21-P21)*0.03 -> 377.22222 | W21: =S21-T21-U21+V21 -> 1938.6749 | X21: =X$23/$F$23*$F21 -> 1529.3902 | Y21: =W21-X21 -> 409.28472 | Z21: =Z$23/$F$23*$F21 -> 1113.9368 | AA21: =W21+Z21 -> 3052.6116 | AC21: =S21/O21 -> 0.28642214 | AD21: =W21/O21 -> 0.14576503 | AE21: =Y21/O21 -> 0.030773287 | AF21: =AA21/O21 -> 0.22951967 | AI21: pendiente cobro primera semana de octubre
E23: TOTAL | F23: =SUBTOTAL(9,F5:F21) -> 778.255 | O23: =SUBTOTAL(9,O5:O21) -> 1865771 | R23: =SUBTOTAL(9,R5:R21) -> 1520660.8 | S23: =SUBTOTAL(9,S5:S21) -> 345110.19 | T23: =SUBTOTAL(9,T5:T21) -> 186983.55 | U23: =[3]Stock!N52 -> 62943.243 | V23: =SUBTOTAL(9,V5:V21) -> 53349.87 | W23: =SUBTOTAL(9,W5:W21) -> 148533.28 | X23: =[3]Stock!O52 -> 170036.51 | Y23: =SUBTOTAL(9,Y5:Y21) -> -21503.232 | Z23: =[3]Stock!P52 -> 123846.69 | AA23: =SUBTOTAL(9,AA5:AA21) -> 272379.97 | AC23: =S23/O23 -> 0.18496921 | AD23: =W23/O23 -> 0.079609596 | AE23: =Y23/O23 -> -0.011525118 | AF23: =AA23/O23 -> 0.14598789

Sheet TD
B2: STOCK OCTUBRE
E3: Etiquetas de fila | F3: Suma de TM en Stock | G3: Suma de Costo Ventas | H3: Suma de Gasto Ventas | I3: Suma de Gasto ADM | J3: Suma de Gasto Fin | K3: Suma de Depreciación
B4: =C4=E4 -> TRUE | C4: 10005721 | D4: POTA FILETE CONGELADO | E4: 10005721 | F4: 133.8 | G4: 213982.19 | H4: 32146.788 | I4: 4120.4105 | J4: 11130.984 | K4: 8107.2914
B5: =C5=E5 -> TRUE | C5: 10005779 | D5: POTA NUCAS CONGELADAS | E5: 10005779 | F5: 448.82 | G5: 686270.72 | H5: 107833.49 | I5: 13821.544 | J5: 37337.878 | K5: 27195.176
B6: =C6=E6 -> TRUE | C6: 10006719 | D6: POTA ALAS CONGELADAS | E6: 10006719 | F6: 79.06 | G6: 114477.28 | H6: 18994.956 | I6: 2434.676 | J6: 6577.0969 | K6: 4790.4519
B7: =C7=E7 -> TRUE | C7: 10007050 | D7: POTA RECORTES COCIDOS | E7: 10007050 | F7: 69.592 | G7: 89640.352 | H7: 16720.174 | I7: 2143.1062 | J7: 5789.4426 | K7: 4216.761
B8: =C8=E8 -> TRUE | C8: 10007162 | D8: POTA REJOS CONGELADOS | E8: 10007162 | F8: 552.72 | G8: 917632.51 | H8: 132796.51 | I8: 17021.175 | J8: 45981.445 | K8: 33490.748
B9: =C9=E9 -> TRUE | C9: 10007567 | D9: POTA REPRODUCTORES | E9: 10007567 | F9: 148.64 | G9: 239900.6 | H9: 35712.246 | I9: 4577.4126 | J9: 12365.541 | K9: 9006.4857
B10: =C10=E10 -> TRUE | C10: 10007969 | D10: POTA CONOS | E10: 10007969 | F10: 0 | G10: 0 | H10: 0 | I10: 0 | J10: 0 | K10: 0
B11: =C11=E11 -> TRUE | C11: 10009239 | D11: POTA FILETE DARUMA | E11: 10009239 | F11: 315.44 | G11: 955286.7 | H11: 75787.614 | I11: 9714.0678 | J11: 26241.835 | K11: 19113.333
B12: =C12=E12 -> TRUE | C12: 10009334 | D12: POTA ALAS COCIDAS | E12: 10009334 | F12: 147.152 | G12: 390322.85 | H12: 35354.74 | I12: 4531.5892 | J12: 12241.753 | K12: 8916.3239
B13: =C13=E13 -> TRUE | C13: 10009386 | D13: VENTOSAS | E13: 10009386 | F13: 25.18 | G13: 54984.293 | H13: 6049.7468 | I13: 775.42553 | J13: 2094.7546 | K13: 1525.722
D14: FILETE REPROCESO | E14: 10009649 | F14: 69.24 | G14: 103066.46 | H14: 16635.602 | I14: 2132.2662 | J14: 5760.1593 | K14: 4195.4324
D15: MANTO | E15: 10010320 | F15: 54.28 | G15: 70331.848 | H15: 13041.313 | I15: 1671.5686 | J15: 4515.6188 | K15: 3288.9669
E16: Total general | F16: 2043.924 | G16: 3835895.8 | H16: 491073.18 | I16: 62943.242 | J16: 170036.51 | K16: 123846.69

Sheet Stock
K2: STOCK EN PAITA
F3: Al cierre de Agosto | G3: Simulador Septiembre
B4: CODIGO | C4: PRODUCTO | D4: STOCK LIBRE | F4: CU Producción | G4: CU Producción | H4: Promedio CU | J4: CÓDIGO | K4: TM en Stock | L4: Costo Ventas | M4: Gasto Ventas | N4: Gasto ADM | O4: Gasto Fin | P4: Depreciación | Q4: Utilidad Neta | R4: Margen Neto | S4: Venta Equilibrio | T4: Precio Equilibrio x TM
B5: 10009178 | C5: POTA ALAS FR C/P C/C (B) S/COD BL10 S20 | D5: 57600 | F5: =IFERROR(VLOOKUP(B5,[1]Hoja1!$I$25:$J$77,2,0),0) -> 1748.7075 | G5: 1236.1466 | H5: =AVERAGE(F5:G5) -> 1492.4271 | I5: ALAS FRESCAS | J5: 10006719 | K5: =D5/1000 -> 57.6 | L5: =H5*D5/1000 -> 85963.799 | M5: =240.26*D5/1000 -> 13838.976 | N5: =K5/$K$53*$N$55 -> 1773.809 | O5: =K5/$K$53*$O$55 -> 4791.8136 | P5: =K5/$K$53*$P$55 -> 3490.1344 | Q5: =0 -> 0 | S5: =SUM(L5:O5) -> 106368.4 | T5: =IFERROR(S5/K5,0) -> 1846.6736
B6: 10006668 | C6: POTA ALAS FR C/P C/C <0.5 BL10 S20 | D6: 760 | F6: =IFERROR(VLOOKUP(B6,[1]Hoja1!$I$25:$J$77,2,0),0) -> 1665.3824 | G6: 1236.1466 | H6: =AVERAGE(F6:G6) -> 1450.7645 | I6: ALAS FRESCAS | J6: 10006719 | K6: =D6/1000 -> 0.76 | L6: =H6*D6/1000 -> 1102.581 | M6: =240.26*D6/1000 -> 182.5976 | N6: =K6/$K$53*$N$55 -> 23.404424 | O6: =K6/$K$53*$O$55 -> 63.225318 | P6: =K6/$K$53*$P$55 -> 46.050385 | Q6: =0 -> 0 | S6: =SUM(L6:O6) -> 1371.8083 | T6: =IFERROR(S6/K6,0) -> 1805.011
B7: 10006719 | C7: POTA ALAS FR C/P C/C 0.5-1 BL10 S20 | D7: 0 | F7: =IFERROR(VLOOKUP(B7,[1]Hoja1!$I$25:$J$77,2,0),0) -> 1559.625 | G7: 1236.1466 | H7: =AVERAGE(F7:G7) -> 1397.8858 | I7: ALAS FRESCAS | J7: 10006719 | K7: =D7/1000 -> 0 | L7: =H7*D7/1000 -> 0 | M7: =240.26*D7/1000 -> 0 | N7: =K7/$K$53*$N$55 -> 0 | O7: =K7/$K$53*$O$55 -> 0 | P7: =K7/$K$53*$P$55 -> 0 | Q7: =0 -> 0 | S7: =SUM(L7:O7) -> 0 | T7: =IFERROR(S7/K7,0) -> 0
B8: 10006720 | C8: POTA ALAS FR C/P C/C 1-2 BL10 S20 | D8: 240 | F8: =IFERROR(VLOOKUP(B8,[1]Hoja1!$I$25:$J$77,2,0),0) -> 1725.3333 | G8: 1236.1466 | H8: =AVERAGE(F8:G8) -> 1480.74 | I8: ALAS FRESCAS | J8: 10006719 | K8: =D8/1000 -> 0.24 | L8: =H8*D8/1000 -> 355.37759 | M8: =240.26*D8/1000 -> 57.6624 | N8: =K8/$K$53*$N$55 -> 7.3908708 | O8: =K8/$K$53*$O$55 -> 19.96589 | P8: =K8/$K$53*$P$55 -> 14.542227 | Q8: =0 -> 0 | S8: =SUM(L8:O8) -> 440.39675 | T8: =IFERROR(S8/K8,0) -> 1834.9865
B9: 10010110 | C9: POTA ALAS FR C/P C/C 1-2 BL10 S20 ENTERA | D9: 0 | F9: =IFERROR(VLOOKUP(B9,[1]Hoja1!$I$25:$J$77,2,0),0) -> 1647.8182 | G9: 1236.1466 | H9: =AVERAGE(F9:G9) -> 1441.9824 | I9: ALAS FRESCAS | J9: 10006719 | K9: =D9/1000 -> 0 | L9: =H9*D9/1000 -> 0 | M9: =240.26*D9/1000 -> 0 | N9: =K9/$K$53*$N$55 -> 0 | O9: =K9/$K$53*$O$55 -> 0 | P9: =K9/$K$53*$P$55 -> 0 | Q9: =0 -> 0 | S9: =SUM(L9:O9) -> 0 | T9: =IFERROR(S9/K9,0) -> 0
B10: 10009207 | C10: POTA LABIOS FR S/COD BL10 S20 | D10: 20460 | F10: =IFERROR(VLOOKUP(B10,[1]Hoja1!$I$25:$J$77,2,0),0) -> 1408.5766 | G10: 1236.1466 | H10: =AVERAGE(F10:G10) -> 1322.3616 | I10: ALAS FRESCAS | J10: 10006719 | K10: =D10/1000 -> 20.46 | L10: =H10*D10/1000 -> 27055.518 | M10: =240.26*D10/1000 -> 4915.7196 | N10: =K10/$K$53*$N$55 -> 630.07174 | O10: =K10/$K$53*$O$55 -> 1702.0921 | P10: =K10/$K$53*$P$55 -> 1239.7248 | S10: =SUM(L10:O10) -> 34303.402 | T10: =IFERROR(S10/K10,0) -> 1676.6081
B11: 10007969 | C11: POTA CONOS | D11: 0 | F11: =IFERROR(VLOOKUP(B11,[1]Hoja1!$I$25:$J$77,2,0),0) -> 1226.375 | G11: 807.53922 | H11: =AVERAGE(F11:G11) -> 1016.9571 | I11: CONOS | J11: 10007969 | K11: =D11/1000 -> 0 | L11: =H11*D11/1000 -> 0 | M11: =240.26*D11/1000 -> 0 | N11: =K11/$K$53*$N$55 -> 0 | O11: =K11/$K$53*$O$55 -> 0 | P11: =K11/$K$53*$P$55 -> 0 | S11: =SUM(L11:O11) -> 0 | T11: =IFERROR(S11/K11,0) -> 0
B12: 10004434 | C12: POTA FILETE C/M C/T FR 1-2 BL10 S20 | D12: 1900 | F12: =IFERROR(VLOOKUP(B12,[1]Hoja1!$I$25:$J$77,2,0),0) -> 2064.6364 | G12: 1488.5392 | H12: =AVERAGE(F12:G12) -> 1776.5878 | I12: FILETE FRESCO | J12: 10005721 | K12: =D12/1000 -> 1.9 | L12: =H12*D12/1000 -> 3375.5168 | M12: =240.26*D12/1000 -> 456.494 | N12: =K12/$K$53*$N$55 -> 58.51106 | O12: =K12/$K$53*$O$55 -> 158.0633 | P12: =K12/$K$53*$P$55 -> 115.12596 | Q12: =0 -> 0 | S12: =SUM(L12:O12) -> 4048.5852 | T12: =IFERROR(S12/K12,0) -> 2130.8343
B13: 10010125 | C13: POTA FILETE C/M C/T FR 1.0 - 3.0 BL10 S20 | D13: 0 | F13: =IFERROR(VLOOKUP(B13,[1]Hoja1!$I$25:$J$77,2,0),0) -> 0 | G13: 1488.5392 | H13: =G13 -> 1488.5392 | I13: FILETE FRESCO | J13: 10005721 | K13: =D13/1000 -> 0 | L13: =H13*D13/1000 -> 0 | M13: =240.26*D13/1000 -> 0 | N13: =K13/$K$53*$N$55 -> 0 | O13: =K13/$K$53*$O$55 -> 0 | P13: =K13/$K$53*$P$55 -> 0 | Q13: =0 -> 0 | S13: =SUM(L13:O13) -> 0 | T13: =IFERROR(S13/K13,0) -> 0
B14: 10004435 | C14: POTA FILETE C/M C/T FR 2-4 S20 | D14: 32160 | F14: =IFERROR(VLOOKUP(B14,[1]Hoja1!$I$25:$J$77,2,0),0) -> 1758.0258 | G14: 1488.5392 | H14: =AVERAGE(F14:G14) -> 1623.2825 | I14: FILETE FRESCO | J14: 10005721 | K14: =D14/1000 -> 32.16 | L14: =H14*D14/1000 -> 52204.765 | M14: =240.26*D14/1000 -> 7726.7616 | N14: =K14/$K$53*$N$55 -> 990.37669 | O14: =K14/$K$53*$O$55 -> 2675.4293 | P14: =K14/$K$53*$P$55 -> 1948.6584 | Q14: =0 -> 0 | S14: =SUM(L14:O14) -> 63597.333 | T14: =IFERROR(S14/K14,0) -> 1977.529
B15: 10005708 | C15: POTA FILETE C/M C/T FR <0.5 Kg AA BL10 S20 | D15: 1080 | F15: =IFERROR(VLOOKUP(B15,[1]Hoja1!$I$25:$J$77,2,0),0) -> 2023.8796 | G15: 1488.5392 | H15: =AVERAGE(F15:G15) -> 1756.2094 | I15: FILETE FRESCO | J15: 10005721 | K15: =D15/1000 -> 1.08 | L15: =H15*D15/1000 -> 1896.7062 | M15: =240.26*D15/1000 -> 259.4808 | N15: =K15/$K$53*$N$55 -> 33.258919 | O15: =K15/$K$53*$O$55 -> 89.846505 | P15: =K15/$K$53*$P$55 -> 65.44002 | Q15: =0 -> 0 | S15: =SUM(L15:O15) -> 2279.2924 | T15: =IFERROR(S15/K15,0) -> 2110.4559
B16: 10005721 | C16: POTA FILETE C/M C/T FR 2-4 (AA) BL10 S20 | D16: 3100 | F16: =IFERROR(VLOOKUP(B16,[1]Hoja1!$I$25:$J$77,2,0),0) -> 1959.7103 | G16: 1488.5392 | H16: =AVERAGE(F16:G16) -> 1724.1247 | I16: FILETE FRESCO | J16: 10005721 | K16: =D16/1000 -> 3.1 | L16: =H16*D16/1000 -> 5344.7867 | M16: =240.26*D16/1000 -> 744.806 | N16: =K16/$K$53*$N$55 -> 95.465414 | O16: =K16/$K$53*$O$55 -> 257.89275 | P16: =K16/$K$53*$P$55 -> 187.8371 | Q16: =0 -> 0 | S16: =SUM(L16:O16) -> 6442.9509 | T16: =IFERROR(S16/K16,0) -> 2078.3712
B17: 10010126 | C17: POTA FILETE C/M C/T FR 1.0 - 3.0 AA BL10 S20 | D17: 5280 | F17: =IFERROR(VLOOKUP(B17,[1]Hoja1!$I$25:$J$77,2,0),0) -> 1787.3674 | G17: 1488.5392 | H17: =AVERAGE(F17:G17) -> 1637.9533 | I17: FILETE FRESCO | J17: 10005721 | K17: =D17/1000 -> 5.28 | L17: =H17*D17/1000 -> 8648.3936 | M17: =240.26*D17/1000 -> 1268.5728 | N17: =K17/$K$53*$N$55 -> 162.59916 | O17: =K17/$K$53*$O$55 -> 439.24958 | P17: =K17/$K$53*$P$55 -> 319.92899 | Q17: =0 -> 0 | S17: =SUM(L17:O17) -> 10518.815 | T17: =IFERROR(S17/K17,0) -> 1992.1998
B18: 10005718 | C18: POTA FILETE C/M C/T FR 1-2 AA BL10 S20 JAPON | D18: 19920 | F18: =IFERROR(VLOOKUP(B18,[1]Hoja1!$I$25:$J$77,2,0),0) -> 1904.1873 | G18: 1488.5392 | H18: =AVERAGE(F18:G18) -> 1696.3632 | I18: FILETE FRESCO | J18: 10005721 | K18: =D18/1000 -> 19.92 | L18: =H18*D18/1000 -> 33791.556 | M18: =240.26*D18/1000 -> 4785.9792 | N18: =K18/$K$53*$N$55 -> 613.44228 | O18: =K18/$K$53*$O$55 -> 1657.1689 | P18: =K18/$K$53*$P$55 -> 1207.0048 | Q18: =0 -> 0 | S18: =SUM(L18:O18) -> 40848.146 | T18: =IFERROR(S18/K18,0) -> 2050.6097
B19: 10009972 | C19: POTA FILETE C/M C/T FR 1-2 AA BL10 S20 50% ROSADO | D19: 2720 | F19: =IFERROR(VLOOKUP(B19,[1]Hoja1!$I$25:$J$77,2,0),0) -> 0 | G19: 1488.5392 | H19: =G19 -> 1488.5392 | I19: FILETE FRESCO | J19: 10005721 | K19: =D19/1000 -> 2.72 | L19: =H19*D19/1000 -> 4048.8267 | M19: =240.26*D19/1000 -> 653.5072 | N19: =K19/$K$53*$N$55 -> 83.763202 | O19: =K19/$K$53*$O$55 -> 226.28009 | P19: =K19/$K$53*$P$55 -> 164.8119 | Q19: =0 -> 0 | S19: =SUM(L19:O19) -> 5012.3772 | T19: =IFERROR(S19/K19,0) -> 1842.7857
B20: 10009298 | C20: POTA FILETE SM ST 1-2 CM/ESP | D20: 27040 | F20: =IFERROR(VLOOKUP(B20,[1]Hoja1!$I$25:$J$77,2,0),0) -> 2083.8594 | G20: 1488.5392 | H20: =AVERAGE(F20:G20) -> 1786.1993 | I20: FILETE FRESCO | J20: 10005721 | K20: =D20/1000 -> 27.04 | L20: =H20*D20/1000 -> 48298.829 | M20: =240.26*D20/1000 -> 6496.6304 | N20: =K20/$K$53*$N$55 -> 832.70478 | O20: =K20/$K$53*$O$55 -> 2249.4903 | P20: =K20/$K$53*$P$55 -> 1638.4242 | Q20: =0 -> 0 | S20: =SUM(L20:O20) -> 57877.655 | T20: =IFERROR(S20/K20,0) -> 2140.4458
C21: POTA FILETE C/M C/T 4.0 - UP AA BL10 S20 | D21: 10000 | F21: =IFERROR(VLOOKUP(B21,[1]Hoja1!$I$25:$J$77,2,0),0) -> 0 | G21: 1488.5392 | H21: =G21 -> 1488.5392 | I21: FILETE FRESCO | J21: 10005721 | K21: =D21/1000 -> 10 | L21: =H21*D21/1000 -> 14885.392 | M21: =240.26*D21/1000 -> 2402.6 | N21: =K21/$K$53*$N$55 -> 307.95295 | O21: =K21/$K$53*$O$55 -> 831.91208 | P21: =K21/$K$53*$P$55 -> 605.92611 | Q21: =0 -> 0 | S21: =SUM(L21:O21) -> 18427.857 | T21: =IFERROR(S21/K21,0) -> 1842.7857
B22: 10009644 | C22: POTA FILETE C/M C/T 4.0 - UP BL10 S20 | D22: 30600 | F22: =IFERROR(VLOOKUP(B22,[1]Hoja1!$I$25:$J$77,2,0),0) -> 0 | G22: 1355.7979 | H22: =G22 -> 1355.7979 | I22: FILETE FRESCO | J22: 10005721 | K22: =D22/1000 -> 30.6 | L22: =H22*D22/1000 -> 41487.417 | M22: =240.26*D22/1000 -> 7351.956 | N22: =K22/$K$53*$N$55 -> 942.33603 | O22: =K22/$K$53*$O$55 -> 2545.651 | P22: =K22/$K$53*$P$55 -> 1854.1339 | Q22: =0 -> 0 | S22: =SUM(L22:O22) -> 52327.36 | T22: =IFERROR(S22/K22,0) -> 1710.0444
B23: 10010320 | C23: POTA MANTO C/M C/T FR 2.0 - 4.0 BL10 S20 | D23: 25440 | F23: =IFERROR(VLOOKUP(B23,[1]Hoja1!$I$25:$J$77,2,0),0) -> 0 | G23: 1355.7979 | H23: =G23 -> 1355.7979 | I23: MANTO | J23: 10010320 | K23: =D23/1000 -> 25.44 | L23: =H23*D23/1000 -> 34491.499 | M23: =240.26*D23/1000 -> 6112.2144 | N23: =K23/$K$53*$N$55 -> 783.4323 | O23: =K23/$K$53*$O$55 -> 2116.3843 | P23: =K23/$K$53*$P$55 -> 1541.476 | Q23: =0 -> 0 | S23: =SUM(L23:O23) -> 43503.53 | T23: =IFERROR(S23/K23,0) -> 1710.0444
B24: 10010347 | C24: POTA MANTO C/M C/T FR 2.0 - 4.0 AA BL10 S20 | D24: 28840 | F24: =IFERROR(VLOOKUP(B24,[1]Hoja1!$I$25:$J$77,2,0),0) -> 0 | G24: 1242.7305 | H24: =G24 -> 1242.7305 | I24: MANTO | J24: 10010320 | K24: =D24/1000 -> 28.84 | L24: =H24*D24/1000 -> 35840.348 | M24: =240.26*D24/1000 -> 6929.0984 | N24: =K24/$K$53*$N$55 -> 888.13631 | O24: =K24/$K$53*$O$55 -> 2399.2345 | P24: =K24/$K$53*$P$55 -> 1747.4909 | Q24: =0 -> 0 | S24: =SUM(L24:O24) -> 46056.817 | T24: =IFERROR(S24/K24,0) -> 1596.977
B25: 10009184 | C25: POTA NUCAS FR ABIERTAS 0.1 - 0.3 BL10 S2 | D25: 141440 | F25: =IFERROR(VLOOKUP(B25,[1]Hoja1!$I$25:$J$77,2,0),0) -> 1856.2376 | G25: 1242.7305 | H25: =AVERAGE(F25:G25) -> 1549.484 | I25: NUCAS | J25: 10005779 | K25: =D25/1000 -> 141.44 | L25: =H25*D25/1000 -> 219159.02 | M25: =240.26*D25/1000 -> 33982.374 | N25: =K25/$K$53*$N$55 -> 4355.6865 | O25: =K25/$K$53*$O$55 -> 11766.565 | P25: =K25/$K$53*$P$55 -> 8570.2189 | Q25: =0 -> 0 | S25: =SUM(L25:O25) -> 269263.65 | T25: =IFERROR(S25/K25,0) -> 1903.7306
B26: 10009271 | C26: POTA NUCAS FR CERRADA 0.1 - 0.3 BL10 S2 | D26: 41820 | F26: =IFERROR(VLOOKUP(B26,[1]Hoja1!$I$25:$J$77,2,0),0) -> 1837.4357 | G26: 1242.7305 | H26: =AVERAGE(F26:G26) -> 1540.0831 | I26: NUCAS | J26: 10005779 | K26: =D26/1000 -> 41.82 | L26: =H26*D26/1000 -> 64406.276 | M26: =240.26*D26/1000 -> 10047.673 | N26: =K26/$K$53*$N$55 -> 1287.8592 | O26: =K26/$K$53*$O$55 -> 3479.0563 | P26: =K26/$K$53*$P$55 -> 2533.983 | Q26: =0 -> 0 | S26: =SUM(L26:O26) -> 79220.865 | T26: =IFERROR(S26/K26,0) -> 1894.3296
B27: 10009183 | C27: POTA NUCAS FR CERRADA <0.1 BL10 S2 | D27: 1040 | F27: =IFERROR(VLOOKUP(B27,[1]Hoja1!$I$25:$J$77,2,0),0) -> 1837.7308 | G27: 1242.7305 | H27: =AVERAGE(F27:G27) -> 1540.2306 | I27: NUCAS | J27: 10005779 | K27: =D27/1000 -> 1.04 | L27: =H27*D27/1000 -> 1601.8399 | M27: =240.26*D27/1000 -> 249.8704 | N27: =K27/$K$53*$N$55 -> 32.027107 | O27: =K27/$K$53*$O$55 -> 86.518857 | P27: =K27/$K$53*$P$55 -> 63.016316 | Q27: =0 -> 0 | S27: =SUM(L27:O27) -> 1970.2562 | T27: =IFERROR(S27/K27,0) -> 1894.4771
B28: 10005779 | C28: POTA NUCAS FR ABIERTAS 0.5-1 BL10 S20 | D28: 37440 | F28: =IFERROR(VLOOKUP(B28,[1]Hoja1!$I$25:$J$77,2,0),0) -> 1735.8204 | G28: 1242.7305 | H28: =AVERAGE(F28:G28) -> 1489.2755 | I28: NUCAS | J28: 10005779 | K28: =D28/1000 -> 37.44 | L28: =H28*D28/1000 -> 55758.473 | M28: =240.26*D28/1000 -> 8995.3344 | N28: =K28/$K$53*$N$55 -> 1152.9758 | O28: =K28/$K$53*$O$55 -> 3114.6788 | P28: =K28/$K$53*$P$55 -> 2268.5874 | Q28: =0 -> 0 | S28: =SUM(L28:O28) -> 69021.462 | T28: =IFERROR(S28/K28,0) -> 1843.522
B29: 10005776 | C29: POTA NUCAS FR ABIERTAS 0.3-0.5 BL10 S20 | D29: 218380 | F29: =IFERROR(VLOOKUP(B29,[1]Hoja1!$I$25:$J$77,2,0),0) -> 1787.9198 | G29: 1242.7305 | H29: =AVERAGE(F29:G29) -> 1515.3251 | I29: NUCAS | J29: 10005779 | K29: =D29/1000 -> 218.38 | L29: =H29*D29/1000 -> 330916.7 | M29: =240.26*D29/1000 -> 52467.979 | N29: =K29/$K$53*$N$55 -> 6725.0765 | O29: =K29/$K$53*$O$55 -> 18167.296 | P29: =K29/$K$53*$P$55 -> 13232.214 | Q29: =0 -> 0 | S29: =SUM(L29:O29) -> 408277.05 | T29: =IFERROR(S29/K29,0) -> 1869.5716
B30: 10005781 | C30: POTA NUCAS FR ABIERTAS 1-2 BL10 S20 | D30: 8700 | F30: =IFERROR(VLOOKUP(B30,[1]Hoja1!$I$25:$J$77,2,0),0) -> 1774.985 | G30: 1541.8895 | H30: =AVERAGE(F30:G30) -> 1658.4373 | I30: NUCAS | J30: 10005779 | K30: =D30/1000 -> 8.7 | L30: =H30*D30/1000 -> 14428.404 | M30: =240.26*D30/1000 -> 2090.262 | N30: =K30/$K$53*$N$55 -> 267.91907 | O30: =K30/$K$53*$O$55 -> 723.76351 | P30: =K30/$K$53*$P$55 -> 527.15572 | Q30: =0 -> 0 | S30: =SUM(L30:O30) -> 17510.349 | T30: =IFERROR(S30/K30,0) -> 2012.6838
B31: 10007567 | C31: POTA REJOS OR FR LIMPIOS S/COD BL10 S20 | D31: 112640 | F31: =IFERROR(VLOOKUP(B31,[1]Hoja1!$I$25:$J$77,2,0),0) -> 1661.5122 | G31: 1541.8895 | H31: =AVERAGE(F31:G31) -> 1601.7008 | I31: REPRODUCTORES | J31: 10007567 | K31: =D31/1000 -> 112.64 | L31: =H31*D31/1000 -> 180415.58 | M31: =240.26*D31/1000 -> 27062.886 | N31: =K31/$K$53*$N$55 -> 3468.782 | O31: =K31/$K$53*$O$55 -> 9370.6577 | P31: =K31/$K$53*$P$55 -> 6825.1517 | Q31: =0 -> 0 | S31: =SUM(L31:O31) -> 220317.91 | T31: =IFERROR(S31/K31,0) -> 1955.9473
B32: 10010107 | C32: POTA REJOS OR FR LIMPIOS <60 cm BL10 S20 | D32: 36000 | F32: =IFERROR(VLOOKUP(B32,[1]Hoja1!$I$25:$J$77,2,0),0) -> 1762.8334 | G32: 1541.8895 | H32: =AVERAGE(F32:G32) -> 1652.3615 | I32: REPRODUCTORES | J32: 10007567 | K32: =D32/1000 -> 36 | L32: =H32*D32/1000 -> 59485.013 | M32: =240.26*D32/1000 -> 8649.36 | N32: =K32/$K$53*$N$55 -> 1108.6306 | O32: =K32/$K$53*$O$55 -> 2994.8835 | P32: =K32/$K$53*$P$55 -> 2181.334 | Q32: =0 -> 0 | S32: =SUM(L32:O32) -> 72237.887 | T32: =IFERROR(S32/K32,0) -> 2006.608
B33: 10009186 | C33: POTA REJOS FR C/U C/V S/OR 0.1-0.3 BL10 | D33: 80 | F33: =IFERROR(VLOOKUP(B33,[1]Hoja1!$I$25:$J$77,2,0),0) -> 1711 | G33: 1541.8895 | H33: =AVERAGE(F33:G33) -> 1626.4447 | I33: REJOS | J33: 10007162 | K33: =D33/1000 -> 0.08 | L33: =H33*D33/1000 -> 130.11558 | M33: =240.26*D33/1000 -> 19.2208 | N33: =K33/$K$53*$N$55 -> 2.4636236 | O33: =K33/$K$53*$O$55 -> 6.6552967 | P33: =K33/$K$53*$P$55 -> 4.8474089 | Q33: =0 -> 0 | S33: =SUM(L33:O33) -> 158.4553 | T33: =IFERROR(S33/K33,0) -> 1980.6913
B34: 10009777 | C34: POTA REJOS FR C/U C/V S/OR 0.3-0.5BL10 | D34: 760 | F34: =IFERROR(VLOOKUP(B34,[1]Hoja1!$I$25:$J$77,2,0),0) -> 1504.8593 | G34: 1541.8895 | H34: =AVERAGE(F34:G34) -> 1523.3744 | I34: REJOS | J34: 10007162 | K34: =D34/1000 -> 0.76 | L34: =H34*D34/1000 -> 1157.7645 | M34: =240.26*D34/1000 -> 182.5976 | N34: =K34/$K$53*$N$55 -> 23.404424 | O34: =K34/$K$53*$O$55 -> 63.225318 | P34: =K34/$K$53*$P$55 -> 46.050385 | Q34: =0 -> 0 | S34: =SUM(L34:O34) -> 1426.9919 | T34: =IFERROR(S34/K34,0) -> 1877.6209
B35: 10010108 | C35: POTA REJOS FR C/U C/V S/OR 0.5-1.0 BL10 | D35: 161900 | F35: =IFERROR(VLOOKUP(B35,[1]Hoja1!$I$25:$J$77,2,0),0) -> 1506.5947 | G35: 1541.8895 | H35: =AVERAGE(F35:G35) -> 1524.2421 | I35: REJOS | J35: 10007162 | K35: =D35/1000 -> 161.9 | L35: =H35*D35/1000 -> 246774.8 | M35: =240.26*D35/1000 -> 38898.094 | N35: =K35/$K$53*$N$55 -> 4985.7583 | O35: =K35/$K$53*$O$55 -> 13468.657 | P35: =K35/$K$53*$P$55 -> 9809.9438 | Q35: =0 -> 0 | S35: =SUM(L35:O35) -> 304127.3 | T35: =IFERROR(S35/K35,0) -> 1878.4886
B36: 10010321 | C36: POTA REJOS FR C/B S/U S/V S/OR 3.0 - UP BL10 S20 | D36: 280 | F36: =IFERROR(VLOOKUP(B36,[1]Hoja1!$I$25:$J$77,2,0),0) -> 0 | G36: 1541.8895 | H36: =G36 -> 1541.8895 | I36: REJOS | J36: 10007162 | K36: =D36/1000 -> 0.28 | L36: =H36*D36/1000 -> 431.72906 | M36: =240.26*D36/1000 -> 67.2728 | N36: =K36/$K$53*$N$55 -> 8.6226826 | O36: =K36/$K$53*$O$55 -> 23.293538 | P36: =K36/$K$53*$P$55 -> 16.965931 | Q36: =0 -> 0 | S36: =SUM(L36:O36) -> 530.91808 | T36: =IFERROR(S36/K36,0) -> 1896.136
B37: 10009187 | C37: POTA REJOS FR C/B S/U S/V S/OR 0.3-0.5 BL10 | D37: 120 | F37: =IFERROR(VLOOKUP(B37,[1]Hoja1!$I$25:$J$77,2,0),0) -> 2022 | G37: 1541.8895 | H37: =AVERAGE(F37:G37) -> 1781.9447 | I37: REJOS | J37: 10007162 | K37: =D37/1000 -> 0.12 | L37: =H37*D37/1000 -> 213.83337 | M37: =240.26*D37/1000 -> 28.8312 | N37: =K37/$K$53*$N$55 -> 3.6954354 | O37: =K37/$K$53*$O$55 -> 9.982945 | P37: =K37/$K$53*$P$55 -> 7.2711134 | Q37: =0 -> 0 | S37: =SUM(L37:O37) -> 256.34295 | T37: =IFERROR(S37/K37,0) -> 2136.1913
B38: 10007161 | C38: POTA REJOS FR C/B S/U S/V S/OR 0.5-1 BL1 0 | D38: 14640 | F38: =IFERROR(VLOOKUP(B38,[1]Hoja1!$I$25:$J$77,2,0),0) -> 1928.2289 | G38: 1541.8895 | H38: =AVERAGE(F38:G38) -> 1735.0592 | I38: REJOS | J38: 10007162 | K38: =D38/1000 -> 14.64 | L38: =H38*D38/1000 -> 25401.267 | M38: =240.26*D38/1000 -> 3517.4064 | N38: =K38/$K$53*$N$55 -> 450.84312 | O38: =K38/$K$53*$O$55 -> 1217.9193 | P38: =K38/$K$53*$P$55 -> 887.07583 | Q38: =0 -> 0 | S38: =SUM(L38:O38) -> 30587.436 | T38: =IFERROR(S38/K38,0) -> 2089.3057
B39: 10009658 | C39: POTA REJOS FR C/B C/U C/V S/OR 1.0 up BL 10S20 | D39: 1960 | F39: =IFERROR(VLOOKUP(B39,[1]Hoja1!$I$25:$J$77,2,0),0) -> 1849.5051 | G39: 1541.8895 | H39: =AVERAGE(F39:G39) -> 1695.6973 | I39: REJOS | J39: 10007162 | K39: =D39/1000 -> 1.96 | L39: =H39*D39/1000 -> 3323.5667 | M39: =240.26*D39/1000 -> 470.9096 | N39: =K39/$K$53*$N$55 -> 60.358778 | O39: =K39/$K$53*$O$55 -> 163.05477 | P39: =K39/$K$53*$P$55 -> 118.76152 | Q39: =0 -> 0 | S39: =SUM(L39:O39) -> 4017.8899 | T39: =IFERROR(S39/K39,0) -> 2049.9438
B40: 10009639 | C40: POTA REJOS FR C/B S/U S/V S/OR 2-UP BL10 | D40: 37180 | F40: =IFERROR(VLOOKUP(B40,[1]Hoja1!$I$25:$J$77,2,0),0) -> 1849.3427 | G40: 1541.8895 | H40: =AVERAGE(F40:G40) -> 1695.6161 | I40: REJOS | J40: 10007162 | K40: =D40/1000 -> 37.18 | L40: =H40*D40/1000 -> 63043.006 | M40: =240.26*D40/1000 -> 8932.8668 | N40: =K40/$K$53*$N$55 -> 1144.9691 | O40: =K40/$K$53*$O$55 -> 3093.0491 | P40: =K40/$K$53*$P$55 -> 2252.8333 | Q40: =0 -> 0 | S40: =SUM(L40:O40) -> 76213.891 | T40: =IFERROR(S40/K40,0) -> 2049.8626
B41: 10007163 | C41: POTA REJOS FR C/B S/U S/V S/OR 2.0 -3.0 BL10 S20 | D41: 4480 | F41: =IFERROR(VLOOKUP(B41,[1]Hoja1!$I$25:$J$77,2,0),0) -> 0 | G41: 1541.8895 | H41: =G41 -> 1541.8895 | I41: REJOS | J41: 10007162 | K41: =D41/1000 -> 4.48 | L41: =H41*D41/1000 -> 6907.665 | M41: =240.26*D41/1000 -> 1076.3648 | N41: =K41/$K$53*$N$55 -> 137.96292 | O41: =K41/$K$53*$O$55 -> 372.69661 | P41: =K41/$K$53*$P$55 -> 271.4549 | Q41: =0 -> 0 | S41: =SUM(L41:O41) -> 8494.6893 | T41: =IFERROR(S41/K41,0) -> 1896.136
...
