Workbook

Sheet RESUMEN AL 13-4-2026
C2: INVENTARIO PRODUCTO TERMINADO
F3: RENTABILIDAD DEL INVENTARIO | U3: 46119 | X3: 46122 | AA3: 46125 | AD3: 46129 | AG3: 46132 | AJ3: 46136 | AM3: 46139 | AP3: EMBARCADO | AS3: POR EMBARCAR CON FECHA | AV3: POR EMBARCAR SIN FECHA | AY3: VENTA ABRIL PROYECTADA | BB3: RENTABILIDAD ABRIL | BI3: RENTABILIDAD STOCK FALTANTE
B4: Código | C4: Producto | D4: TM en Stock | E4: CU | F4: Costo Ventas | G4: Gasto Ventas | H4: Gasto ADM | I4: Gasto Fin | J4: Depreciación | K4: Utilidad Neta | L4: Margen Neto | M4: Venta Equilibrio | N4: Precio Equilibrio x TM | P4: Precio Abril x TM | Q4: Venta Abril | R4: Utilidad Neta | S4: Margen Neto | U4: TM | V4: Venta | W4: Precio x TM | X4: TM | Y4: Venta | Z4: Precio x TM | AA4: TM | AB4: Venta | AC4: Precio x TM | AD4: TM | AE4: Venta | AF4: Precio x TM | AG4: TM | AH4: Venta | AI4: Precio x TM | AJ4: TM | AK4: Venta | AL4: Precio x TM | AM4: TM | AN4: Venta | AO4: Precio x TM | AP4: TM | AQ4: Venta | AR4: Precio x TM | AS4: TM | AT4: Venta | AU4: Precio x TM | AV4: TM | AW4: Venta | AX4: Precio x TM | AY4: TM | AZ4: Venta | BA4: Precio x TM | BB4: Costo Ventas | BC4: Gasto Ventas | BD4: Gasto ADM | BE4: Gasto Fin | BF4: Depreciación | BG4: Utilidad Neta | BH4: Margen Neto | BI4: TM | BJ4: Venta | BK4: Utilidad | BL4: Margen Neto
B5: 10005721 | C5: POTA FILETE CONGELADO | D5: 396.6 | E5: =IFERROR(F5/D5,0) -> 1740 | F5: 690084 | G5: 72181.2 | H5: 14485.365 | I5: 32795.362 | J5: 27418.624 | K5: 0 | L5: 0 | M5: =F5+G5+H5+I5 -> 809545.93 | N5: =IFERROR(M5/D5,0) -> 2041.2151 | P5: 2100 | Q5: =D5*P5 -> 832860 | R5: =Q5-M5 -> 23314.073 | S5: =IFERROR(R5/Q5,0) -> 0.027992787 | U5: {=SUM([2]Hoja3!$I$5:$I$19*([2]Hoja3!$F$5:$F$19=$B5)*([2]Hoja3!$G$5:$G$19=$U$3))} -> 293 | V5: {=SUM([2]Hoja3!$J$5:$J$19*([2]Hoja3!$F$5:$F$19=$B5)*([2]Hoja3!$G$5:$G$19=$U$3))} -> 436600 | W5: =IFERROR(V5/U5,0) -> 1490.1024 | X5: {=SUM([2]Hoja3!$I$5:$I$19*([2]Hoja3!$F$5:$F$19=$B5)*([2]Hoja3!$G$5:$G$19=$X$3))} -> 27 | Y5: {=SUM([2]Hoja3!$J$5:$J$19*([2]Hoja3!$F$5:$F$19=$B5)*([2]Hoja3!$G$5:$G$19=$X$3))} -> 43200 | Z5: =IFERROR(Y5/X5,0) -> 1600 | AA5: {=SUM([2]Hoja3!$I$5:$I$19*([2]Hoja3!$F$5:$F$19=$B5)*([2]Hoja3!$G$5:$G$19=$AA$3))} -> 26 | AB5: {=SUM([2]Hoja3!$J$5:$J$19*([2]Hoja3!$F$5:$F$19=$B5)*([2]Hoja3!$G$5:$G$19=$AA$3))} -> 36400 | AC5: =IFERROR(AB5/AA5,0) -> 1400 | AD5: {=SUM([2]Hoja3!$I$5:$I$19*([2]Hoja3!$F$5:$F$19=$B5)*([2]Hoja3!$G$5:$G$19=$AD$3))} -> 0 | AE5: {=SUM([2]Hoja3!$J$5:$J$19*([2]Hoja3!$F$5:$F$19=$B5)*([2]Hoja3!$G$5:$G$19=$AD$3))} -> 0 | AF5: =IFERROR(AE5/AD5,0) -> 0 | AG5: {=SUM([2]Hoja3!$I$5:$I$19*([2]Hoja3!$F$5:$F$19=$B5)*([2]Hoja3!$G$5:$G$19=$AG$3))} -> 131 | AH5: {=SUM([2]Hoja3!$J$5:$J$19*([2]Hoja3!$F$5:$F$19=$B5)*([2]Hoja3!$G$5:$G$19=$AG$3))} -> 257800 | AI5: =IFERROR(AH5/AG5,0) -> 1967.9389 | AJ5: {=SUM([2]Hoja3!$I$5:$I$19*([2]Hoja3!$F$5:$F$19=$B5)*([2]Hoja3!$G$5:$G$19=$AJ$3))} -> 0 | AK5: {=SUM([2]Hoja3!$J$5:$J$19*([2]Hoja3!$F$5:$F$19=$B5)*([2]Hoja3!$G$5:$G$19=$AJ$3))} -> 0 | AL5: =IFERROR(AK5/AJ5,0) -> 0 | AM5: {=SUM([2]Hoja3!$I$5:$I$19*([2]Hoja3!$F$5:$F$19=$B5)*([2]Hoja3!$G$5:$G$19=$AM$3))} -> 26 | AN5: {=SUM([2]Hoja3!$J$5:$J$19*([2]Hoja3!$F$5:$F$19=$B5)*([2]Hoja3!$G$5:$G$19=$AM$3))} -> 36400 | AO5: =IFERROR(AN5/AM5,0) -> 1400 | AP5: =U5+X5+AA5 -> 346 | AQ5: =V5+Y5+AB5 -> 516200 | AR5: =IFERROR(AQ5/AP5,0) -> 1491.9075 | AS5: =AD5+AG5+AJ5+AM5 -> 157 | AT5: =AE5+AH5+AK5+AN5 -> 294200 | AU5: =IFERROR(AT5/AS5,0) -> 1873.8854 | AV5: {=SUM([2]Hoja3!$I$27:$I$34*([2]Hoja3!$F$27:$F$34=$B5))} -> 294 | AW5: {=SUM([2]Hoja3!$J$27:$J$34*([2]Hoja3!$F$27:$F$34=$B5))} -> 622200 | AX5: =IFERROR(AW5/AV5,0) -> 2116.3265 | AY5: =AP5+AS5+AV5 -> 797 | AZ5: =AQ5+AT5+AW5 -> 1432600 | BA5: =IFERROR(AZ5/AY5,0) -> 1797.4906 | BB5: =AY5*E5 -> 1386780 | BC5: =IFERROR(G5/$D5*$AY5,0) -> 145054 | BD5: =$BD$22/$AY$22*AY5 -> 24087.847 | BE5: =$BE$22/$AY$22*AY5 -> 54535.709 | BF5: =$BF$22/$AY$22*AY5 -> 45594.681 | BG5: =AZ5-BB5-BC5-BD5-BE5 -> -177857.56 | BH5: =IFERROR(BG5/AZ5,0) -> -0.12415019 | BI5: =IF((AS5+AV5)>D5,AS5+AV5-D5,0) -> 54.4 | BJ5: =IFERROR(AW5/AV5*BI5,0) -> 115128.16 | BK5: =IFERROR(BJ5-(BB5+BC5+BD5+BE5)/AY5*BI5,0) -> 5204.837 | BL5: =IFERROR(BK5/BJ5,0) -> 0.045209068
B6: 10005779 | C6: POTA NUCAS CONGELADAS | D6: 158.72 | E6: =IFERROR(F6/D6,0) -> 1860 | F6: 295219.2 | G6: 28887.04 | H6: 5797.0681 | I6: 13124.76 | J6: 10972.98 | K6: 0 | L6: 0 | M6: =F6+G6+H6+I6 -> 343028.07 | N6: =IFERROR(M6/D6,0) -> 2161.2151 | P6: 1200 | Q6: =D6*P6 -> 190464 | R6: =Q6-M6 -> -152564.07 | S6: =IFERROR(R6/Q6,0) -> -0.80101262 | U6: {=SUM([2]Hoja3!$I$5:$I$19*([2]Hoja3!$F$5:$F$19=$B6)*([2]Hoja3!$G$5:$G$19=$U$3))} -> 0 | V6: {=SUM([2]Hoja3!$J$5:$J$19*([2]Hoja3!$F$5:$F$19=$B6)*([2]Hoja3!$G$5:$G$19=$U$3))} -> 0 | W6: =IFERROR(V6/U6,0) -> 0 | X6: {=SUM([2]Hoja3!$I$5:$I$19*([2]Hoja3!$F$5:$F$19=$B6)*([2]Hoja3!$G$5:$G$19=$X$3))} -> 0 | Y6: {=SUM([2]Hoja3!$J$5:$J$19*([2]Hoja3!$F$5:$F$19=$B6)*([2]Hoja3!$G$5:$G$19=$X$3))} -> 0 | Z6: =IFERROR(Y6/X6,0) -> 0 | AA6: {=SUM([2]Hoja3!$I$5:$I$19*([2]Hoja3!$F$5:$F$19=$B6)*([2]Hoja3!$G$5:$G$19=$AA$3))} -> 0 | AB6: {=SUM([2]Hoja3!$J$5:$J$19*([2]Hoja3!$F$5:$F$19=$B6)*([2]Hoja3!$G$5:$G$19=$AA$3))} -> 0 | AC6: =IFERROR(AB6/AA6,0) -> 0 | AD6: {=SUM([2]Hoja3!$I$5:$I$19*([2]Hoja3!$F$5:$F$19=$B6)*([2]Hoja3!$G$5:$G$19=$AD$3))} -> 0 | AE6: {=SUM([2]Hoja3!$J$5:$J$19*([2]Hoja3!$F$5:$F$19=$B6)*([2]Hoja3!$G$5:$G$19=$AD$3))} -> 0 | AF6: =IFERROR(AE6/AD6,0) -> 0 | AG6: {=SUM([2]Hoja3!$I$5:$I$19*([2]Hoja3!$F$5:$F$19=$B6)*([2]Hoja3!$G$5:$G$19=$AG$3))} -> 0 | AH6: {=SUM([2]Hoja3!$J$5:$J$19*([2]Hoja3!$F$5:$F$19=$B6)*([2]Hoja3!$G$5:$G$19=$AG$3))} -> 0 | AI6: =IFERROR(AH6/AG6,0) -> 0 | AJ6: {=SUM([2]Hoja3!$I$5:$I$19*([2]Hoja3!$F$5:$F$19=$B6)*([2]Hoja3!$G$5:$G$19=$AJ$3))} -> 0 | AK6: {=SUM([2]Hoja3!$J$5:$J$19*([2]Hoja3!$F$5:$F$19=$B6)*([2]Hoja3!$G$5:$G$19=$AJ$3))} -> 0 | AL6: =IFERROR(AK6/AJ6,0) -> 0 | AM6: {=SUM([2]Hoja3!$I$5:$I$19*([2]Hoja3!$F$5:$F$19=$B6)*([2]Hoja3!$G$5:$G$19=$AM$3))} -> 0 | AN6: {=SUM([2]Hoja3!$J$5:$J$19*([2]Hoja3!$F$5:$F$19=$B6)*([2]Hoja3!$G$5:$G$19=$AM$3))} -> 0 | AO6: =IFERROR(AN6/AM6,0) -> 0 | AP6: =U6+X6+AA6 -> 0 | AQ6: =V6+Y6+AB6 -> 0 | AR6: =IFERROR(AQ6/AP6,0) -> 0 | AS6: =AD6+AG6+AJ6+AM6 -> 0 | AT6: =AE6+AH6+AK6+AN6 -> 0 | AU6: =IFERROR(AT6/AS6,0) -> 0 | AV6: {=SUM([2]Hoja3!$I$27:$I$34*([2]Hoja3!$F$27:$F$34=$B6))} -> 0 | AW6: {=SUM([2]Hoja3!$J$27:$J$34*([2]Hoja3!$F$27:$F$34=$B6))} -> 0 | AX6: =IFERROR(AW6/AV6,0) -> 0 | AY6: =AP6+AS6+AV6 -> 0 | AZ6: =AQ6+AT6+AW6 -> 0 | BA6: =IFERROR(AZ6/AY6,0) -> 0 | BB6: =AY6*E6 -> 0 | BC6: =IFERROR(G6/$D6*$AY6,0) -> 0 | BD6: =$BD$22/$AY$22*AY6 -> 0 | BE6: =$BE$22/$AY$22*AY6 -> 0 | BF6: =$BF$22/$AY$22*AY6 -> 0 | BG6: =AZ6-BB6-BC6-BD6-BE6 -> 0 | BH6: =IFERROR(BG6/AZ6,0) -> 0 | BI6: =IF((AS6+AV6)>D6,AS6+AV6-D6,0) -> 0 | BJ6: =IFERROR(AW6/AV6*BI6,0) -> 0 | BK6: =IFERROR(BJ6-(BB6+BC6+BD6+BE6)/AY6*BI6,0) -> 0 | BL6: =IFERROR(BK6/BJ6,0) -> 0
B7: 10005781 | C7: POTA NUCAS CONGELADAS FR<0.1 BL10 S20 | D7: 5.48 | E7: =IFERROR(F7/D7,0) -> 1860 | F7: 10192.8 | G7: 997.36 | H7: 200.15079 | I7: 453.14822 | J7: 378.85542 | K7: 0 | L7: 0 | M7: =F7+G7+H7+I7 -> 11843.459 | N7: =IFERROR(M7/D7,0) -> 2161.2151 | P7: 1200 | Q7: =D7*P7 -> 6576 | R7: =Q7-M7 -> -5267.459 | S7: =IFERROR(R7/Q7,0) -> -0.80101262 | U7: {=SUM([2]Hoja3!$I$5:$I$19*([2]Hoja3!$F$5:$F$19=$B7)*([2]Hoja3!$G$5:$G$19=$U$3))} -> 0 | V7: {=SUM([2]Hoja3!$J$5:$J$19*([2]Hoja3!$F$5:$F$19=$B7)*([2]Hoja3!$G$5:$G$19=$U$3))} -> 0 | W7: =IFERROR(V7/U7,0) -> 0 | X7: {=SUM([2]Hoja3!$I$5:$I$19*([2]Hoja3!$F$5:$F$19=$B7)*([2]Hoja3!$G$5:$G$19=$X$3))} -> 0 | Y7: {=SUM([2]Hoja3!$J$5:$J$19*([2]Hoja3!$F$5:$F$19=$B7)*([2]Hoja3!$G$5:$G$19=$X$3))} -> 0 | Z7: =IFERROR(Y7/X7,0) -> 0 | AA7: {=SUM([2]Hoja3!$I$5:$I$19*([2]Hoja3!$F$5:$F$19=$B7)*([2]Hoja3!$G$5:$G$19=$AA$3))} -> 0 | AB7: {=SUM([2]Hoja3!$J$5:$J$19*([2]Hoja3!$F$5:$F$19=$B7)*([2]Hoja3!$G$5:$G$19=$AA$3))} -> 0 | AC7: =IFERROR(AB7/AA7,0) -> 0 | AD7: {=SUM([2]Hoja3!$I$5:$I$19*([2]Hoja3!$F$5:$F$19=$B7)*([2]Hoja3!$G$5:$G$19=$AD$3))} -> 0 | AE7: {=SUM([2]Hoja3!$J$5:$J$19*([2]Hoja3!$F$5:$F$19=$B7)*([2]Hoja3!$G$5:$G$19=$AD$3))} -> 0 | AF7: =IFERROR(AE7/AD7,0) -> 0 | AG7: {=SUM([2]Hoja3!$I$5:$I$19*([2]Hoja3!$F$5:$F$19=$B7)*([2]Hoja3!$G$5:$G$19=$AG$3))} -> 0 | AH7: {=SUM([2]Hoja3!$J$5:$J$19*([2]Hoja3!$F$5:$F$19=$B7)*([2]Hoja3!$G$5:$G$19=$AG$3))} -> 0 | AI7: =IFERROR(AH7/AG7,0) -> 0 | AJ7: {=SUM([2]Hoja3!$I$5:$I$19*([2]Hoja3!$F$5:$F$19=$B7)*([2]Hoja3!$G$5:$G$19=$AJ$3))} -> 0 | AK7: {=SUM([2]Hoja3!$J$5:$J$19*([2]Hoja3!$F$5:$F$19=$B7)*([2]Hoja3!$G$5:$G$19=$AJ$3))} -> 0 | AL7: =IFERROR(AK7/AJ7,0) -> 0 | AM7: {=SUM([2]Hoja3!$I$5:$I$19*([2]Hoja3!$F$5:$F$19=$B7)*([2]Hoja3!$G$5:$G$19=$AM$3))} -> 0 | AN7: {=SUM([2]Hoja3!$J$5:$J$19*([2]Hoja3!$F$5:$F$19=$B7)*([2]Hoja3!$G$5:$G$19=$AM$3))} -> 0 | AO7: =IFERROR(AN7/AM7,0) -> 0 | AP7: =U7+X7+AA7 -> 0 | AQ7: =V7+Y7+AB7 -> 0 | AR7: =IFERROR(AQ7/AP7,0) -> 0 | AS7: =AD7+AG7+AJ7+AM7 -> 0 | AT7: =AE7+AH7+AK7+AN7 -> 0 | AU7: =IFERROR(AT7/AS7,0) -> 0 | AV7: {=SUM([2]Hoja3!$I$27:$I$34*([2]Hoja3!$F$27:$F$34=$B7))} -> 0 | AW7: {=SUM([2]Hoja3!$J$27:$J$34*([2]Hoja3!$F$27:$F$34=$B7))} -> 0 | AX7: =IFERROR(AW7/AV7,0) -> 0 | AY7: =AP7+AS7+AV7 -> 0 | AZ7: =AQ7+AT7+AW7 -> 0 | BA7: =IFERROR(AZ7/AY7,0) -> 0 | BB7: =AY7*E7 -> 0 | BC7: =IFERROR(G7/$D7*$AY7,0) -> 0 | BD7: =$BD$22/$AY$22*AY7 -> 0 | BE7: =$BE$22/$AY$22*AY7 -> 0 | BF7: =$BF$22/$AY$22*AY7 -> 0 | BG7: =AZ7-BB7-BC7-BD7-BE7 -> 0 | BH7: =IFERROR(BG7/AZ7,0) -> 0 | BI7: =IF((AS7+AV7)>D7,AS7+AV7-D7,0) -> 0 | BJ7: =IFERROR(AW7/AV7*BI7,0) -> 0 | BK7: =IFERROR(BJ7-(BB7+BC7+BD7+BE7)/AY7*BI7,0) -> 0 | BL7: =IFERROR(BK7/BJ7,0) -> 0
B8: 10006720 | C8: POTA ALAS CONGELADAS | D8: 247.26 | E8: =IFERROR(F8/D8,0) -> 1640 | F8: 405506.4 | G8: 45001.32 | H8: 9030.8912 | I8: 20446.246 | J8: 17094.122 | K8: 0 | L8: 0 | M8: =F8+G8+H8+I8 -> 479984.86 | N8: =IFERROR(M8/D8,0) -> 1941.2151 | P8: 2150 | Q8: =D8*P8 -> 531609 | R8: =Q8-M8 -> 51624.143 | S8: =IFERROR(R8/Q8,0) -> 0.097109234 | U8: {=SUM([2]Hoja3!$I$5:$I$19*([2]Hoja3!$F$5:$F$19=$B8)*([2]Hoja3!$G$5:$G$19=$U$3))} -> 0 | V8: {=SUM([2]Hoja3!$J$5:$J$19*([2]Hoja3!$F$5:$F$19=$B8)*([2]Hoja3!$G$5:$G$19=$U$3))} -> 0 | W8: =IFERROR(V8/U8,0) -> 0 | X8: {=SUM([2]Hoja3!$I$5:$I$19*([2]Hoja3!$F$5:$F$19=$B8)*([2]Hoja3!$G$5:$G$19=$X$3))} -> 27 | Y8: {=SUM([2]Hoja3!$J$5:$J$19*([2]Hoja3!$F$5:$F$19=$B8)*([2]Hoja3!$G$5:$G$19=$X$3))} -> 45900 | Z8: =IFERROR(Y8/X8,0) -> 1700 | AA8: {=SUM([2]Hoja3!$I$5:$I$19*([2]Hoja3!$F$5:$F$19=$B8)*([2]Hoja3!$G$5:$G$19=$AA$3))} -> 0 | AB8: {=SUM([2]Hoja3!$J$5:$J$19*([2]Hoja3!$F$5:$F$19=$B8)*([2]Hoja3!$G$5:$G$19=$AA$3))} -> 0 | AC8: =IFERROR(AB8/AA8,0) -> 0 | AD8: {=SUM([2]Hoja3!$I$5:$I$19*([2]Hoja3!$F$5:$F$19=$B8)*([2]Hoja3!$G$5:$G$19=$AD$3))} -> 0 | AE8: {=SUM([2]Hoja3!$J$5:$J$19*([2]Hoja3!$F$5:$F$19=$B8)*([2]Hoja3!$G$5:$G$19=$AD$3))} -> 0 | AF8: =IFERROR(AE8/AD8,0) -> 0 | AG8: {=SUM([2]Hoja3!$I$5:$I$19*([2]Hoja3!$F$5:$F$19=$B8)*([2]Hoja3!$G$5:$G$19=$AG$3))} -> 192 | AH8: {=SUM([2]Hoja3!$J$5:$J$19*([2]Hoja3!$F$5:$F$19=$B8)*([2]Hoja3!$G$5:$G$19=$AG$3))} -> 313200 | AI8: =IFERROR(AH8/AG8,0) -> 1631.25 | AJ8: {=SUM([2]Hoja3!$I$5:$I$19*([2]Hoja3!$F$5:$F$19=$B8)*([2]Hoja3!$G$5:$G$19=$AJ$3))} -> 0 | AK8: {=SUM([2]Hoja3!$J$5:$J$19*([2]Hoja3!$F$5:$F$19=$B8)*([2]Hoja3!$G$5:$G$19=$AJ$3))} -> 0 | AL8: =IFERROR(AK8/AJ8,0) -> 0 | AM8: {=SUM([2]Hoja3!$I$5:$I$19*([2]Hoja3!$F$5:$F$19=$B8)*([2]Hoja3!$G$5:$G$19=$AM$3))} -> 0 | AN8: {=SUM([2]Hoja3!$J$5:$J$19*([2]Hoja3!$F$5:$F$19=$B8)*([2]Hoja3!$G$5:$G$19=$AM$3))} -> 0 | AO8: =IFERROR(AN8/AM8,0) -> 0 | AP8: =U8+X8+AA8 -> 27 | AQ8: =V8+Y8+AB8 -> 45900 | AR8: =IFERROR(AQ8/AP8,0) -> 1700 | AS8: =AD8+AG8+AJ8+AM8 -> 192 | AT8: =AE8+AH8+AK8+AN8 -> 313200 | AU8: =IFERROR(AT8/AS8,0) -> 1631.25 | AV8: {=SUM([2]Hoja3!$I$27:$I$34*([2]Hoja3!$F$27:$F$34=$B8))} -> 105 | AW8: {=SUM([2]Hoja3!$J$27:$J$34*([2]Hoja3!$F$27:$F$34=$B8))} -> 227700 | AX8: =IFERROR(AW8/AV8,0) -> 2168.5714 | AY8: =AP8+AS8+AV8 -> 324 | AZ8: =AQ8+AT8+AW8 -> 586800 | BA8: =IFERROR(AZ8/AY8,0) -> 1811.1111 | BB8: =AY8*E8 -> 531360 | BC8: =IFERROR(G8/$D8*$AY8,0) -> 58968 | BD8: =$BD$22/$AY$22*AY8 -> 9792.2992 | BE8: =$BE$22/$AY$22*AY8 -> 22170.1 | BF8: =$BF$22/$AY$22*AY8 -> 18535.353 | BG8: =AZ8-BB8-BC8-BD8-BE8 -> -35490.399 | BH8: =IFERROR(BG8/AZ8,0) -> -0.060481253 | BI8: =IF((AS8+AV8)>D8,AS8+AV8-D8,0) -> 49.74 | BJ8: =IFERROR(AW8/AV8*BI8,0) -> 107864.74 | BK8: =IFERROR(BJ8-(BB8+BC8+BD8+BE8)/AY8*BI8,0) -> 12331.643 | BL8: =IFERROR(BK8/BJ8,0) -> 0.11432506
B9: 10006722 | C9: POTA ALAS CONGELADAS FR C/P C/C 2-UP BL10 S20 | D9: 0.12 | E9: =IFERROR(F9/D9,0) -> 1870 | F9: 224.4 | G9: 21.84 | H9: 4.382864 | I9: 9.9229537 | J9: 8.296104 | K9: 0 | L9: 0 | M9: =F9+G9+H9+I9 -> 260.54582 | N9: =IFERROR(M9/D9,0) -> 2171.2151 | P9: 2150 | Q9: =D9*P9 -> 258 | R9: =Q9-M9 -> -2.5458177 | S9: =IFERROR(R9/Q9,0) -> -0.0098675105 | U9: {=SUM([2]Hoja3!$I$5:$I$19*([2]Hoja3!$F$5:$F$19=$B9)*([2]Hoja3!$G$5:$G$19=$U$3))} -> 0 | V9: {=SUM([2]Hoja3!$J$5:$J$19*([2]Hoja3!$F$5:$F$19=$B9)*([2]Hoja3!$G$5:$G$19=$U$3))} -> 0 | W9: =IFERROR(V9/U9,0) -> 0 | X9: {=SUM([2]Hoja3!$I$5:$I$19*([2]Hoja3!$F$5:$F$19=$B9)*([2]Hoja3!$G$5:$G$19=$X$3))} -> 0 | Y9: {=SUM([2]Hoja3!$J$5:$J$19*([2]Hoja3!$F$5:$F$19=$B9)*([2]Hoja3!$G$5:$G$19=$X$3))} -> 0 | Z9: =IFERROR(Y9/X9,0) -> 0 | AA9: {=SUM([2]Hoja3!$I$5:$I$19*([2]Hoja3!$F$5:$F$19=$B9)*([2]Hoja3!$G$5:$G$19=$AA$3))} -> 0 | AB9: {=SUM([2]Hoja3!$J$5:$J$19*([2]Hoja3!$F$5:$F$19=$B9)*([2]Hoja3!$G$5:$G$19=$AA$3))} -> 0 | AC9: =IFERROR(AB9/AA9,0) -> 0 | AD9: {=SUM([2]Hoja3!$I$5:$I$19*([2]Hoja3!$F$5:$F$19=$B9)*([2]Hoja3!$G$5:$G$19=$AD$3))} -> 0 | AE9: {=SUM([2]Hoja3!$J$5:$J$19*([2]Hoja3!$F$5:$F$19=$B9)*([2]Hoja3!$G$5:$G$19=$AD$3))} -> 0 | AF9: =IFERROR(AE9/AD9,0) -> 0 | AG9: {=SUM([2]Hoja3!$I$5:$I$19*([2]Hoja3!$F$5:$F$19=$B9)*([2]Hoja3!$G$5:$G$19=$AG$3))} -> 0 | AH9: {=SUM([2]Hoja3!$J$5:$J$19*([2]Hoja3!$F$5:$F$19=$B9)*([2]Hoja3!$G$5:$G$19=$AG$3))} -> 0 | AI9: =IFERROR(AH9/AG9,0) -> 0 | AJ9: {=SUM([2]Hoja3!$I$5:$I$19*([2]Hoja3!$F$5:$F$19=$B9)*([2]Hoja3!$G$5:$G$19=$AJ$3))} -> 0 | AK9: {=SUM([2]Hoja3!$J$5:$J$19*([2]Hoja3!$F$5:$F$19=$B9)*([2]Hoja3!$G$5:$G$19=$AJ$3))} -> 0 | AL9: =IFERROR(AK9/AJ9,0) -> 0 | AM9: {=SUM([2]Hoja3!$I$5:$I$19*([2]Hoja3!$F$5:$F$19=$B9)*([2]Hoja3!$G$5:$G$19=$AM$3))} -> 0 | AN9: {=SUM([2]Hoja3!$J$5:$J$19*([2]Hoja3!$F$5:$F$19=$B9)*([2]Hoja3!$G$5:$G$19=$AM$3))} -> 0 | AO9: =IFERROR(AN9/AM9,0) -> 0 | AP9: =U9+X9+AA9 -> 0 | AQ9: =V9+Y9+AB9 -> 0 | AR9: =IFERROR(AQ9/AP9,0) -> 0 | AS9: =AD9+AG9+AJ9+AM9 -> 0 | AT9: =AE9+AH9+AK9+AN9 -> 0 | AU9: =IFERROR(AT9/AS9,0) -> 0 | AV9: {=SUM([2]Hoja3!$I$27:$I$34*([2]Hoja3!$F$27:$F$34=$B9))} -> 0 | AW9: {=SUM([2]Hoja3!$J$27:$J$34*([2]Hoja3!$F$27:$F$34=$B9))} -> 0 | AX9: =IFERROR(AW9/AV9,0) -> 0 | AY9: =AP9+AS9+AV9 -> 0 | AZ9: =AQ9+AT9+AW9 -> 0 | BA9: =IFERROR(AZ9/AY9,0) -> 0 | BB9: =AY9*E9 -> 0 | BC9: =IFERROR(G9/$D9*$AY9,0) -> 0 | BD9: =$BD$22/$AY$22*AY9 -> 0 | BE9: =$BE$22/$AY$22*AY9 -> 0 | BF9: =$BF$22/$AY$22*AY9 -> 0 | BG9: =AZ9-BB9-BC9-BD9-BE9 -> 0 | BH9: =IFERROR(BG9/AZ9,0) -> 0 | BI9: =IF((AS9+AV9)>D9,AS9+AV9-D9,0) -> 0 | BJ9: =IFERROR(AW9/AV9*BI9,0) -> 0 | BK9: =IFERROR(BJ9-(BB9+BC9+BD9+BE9)/AY9*BI9,0) -> 0 | BL9: =IFERROR(BK9/BJ9,0) -> 0
B10: 10009178 | C10: POTA ALAS CONGELADAS FR C/P C/C 0.5-1 BL10 S20 | D10: 61.86 | E10: =IFERROR(F10/D10,0) -> 1730 | F10: 107017.8 | G10: 11258.52 | H10: 2259.3664 | I10: 5115.2826 | J10: 4276.6416 | K10: 0 | L10: 0 | M10: =F10+G10+H10+I10 -> 125650.97 | N10: =IFERROR(M10/D10,0) -> 2031.2151 | P10: 2150 | Q10: =D10*P10 -> 132999 | R10: =Q10-M10 -> 7348.031 | S10: =IFERROR(R10/Q10,0) -> 0.055248769 | U10: {=SUM([2]Hoja3!$I$5:$I$19*([2]Hoja3!$F$5:$F$19=$B10)*([2]Hoja3!$G$5:$G$19=$U$3))} -> 0 | V10: {=SUM([2]Hoja3!$J$5:$J$19*([2]Hoja3!$F$5:$F$19=$B10)*([2]Hoja3!$G$5:$G$19=$U$3))} -> 0 | W10: =IFERROR(V10/U10,0) -> 0 | X10: {=SUM([2]Hoja3!$I$5:$I$19*([2]Hoja3!$F$5:$F$19=$B10)*([2]Hoja3!$G$5:$G$19=$X$3))} -> 0 | Y10: {=SUM([2]Hoja3!$J$5:$J$19*([2]Hoja3!$F$5:$F$19=$B10)*([2]Hoja3!$G$5:$G$19=$X$3))} -> 0 | Z10: =IFERROR(Y10/X10,0) -> 0 | AA10: {=SUM([2]Hoja3!$I$5:$I$19*([2]Hoja3!$F$5:$F$19=$B10)*([2]Hoja3!$G$5:$G$19=$AA$3))} -> 0 | AB10: {=SUM([2]Hoja3!$J$5:$J$19*([2]Hoja3!$F$5:$F$19=$B10)*([2]Hoja3!$G$5:$G$19=$AA$3))} -> 0 | AC10: =IFERROR(AB10/AA10,0) -> 0 | AD10: {=SUM([2]Hoja3!$I$5:$I$19*([2]Hoja3!$F$5:$F$19=$B10)*([2]Hoja3!$G$5:$G$19=$AD$3))} -> 0 | AE10: {=SUM([2]Hoja3!$J$5:$J$19*([2]Hoja3!$F$5:$F$19=$B10)*([2]Hoja3!$G$5:$G$19=$AD$3))} -> 0 | AF10: =IFERROR(AE10/AD10,0) -> 0 | AG10: {=SUM([2]Hoja3!$I$5:$I$19*([2]Hoja3!$F$5:$F$19=$B10)*([2]Hoja3!$G$5:$G$19=$AG$3))} -> 0 | AH10: {=SUM([2]Hoja3!$J$5:$J$19*([2]Hoja3!$F$5:$F$19=$B10)*([2]Hoja3!$G$5:$G$19=$AG$3))} -> 0 | AI10: =IFERROR(AH10/AG10,0) -> 0 | AJ10: {=SUM([2]Hoja3!$I$5:$I$19*([2]Hoja3!$F$5:$F$19=$B10)*([2]Hoja3!$G$5:$G$19=$AJ$3))} -> 0 | AK10: {=SUM([2]Hoja3!$J$5:$J$19*([2]Hoja3!$F$5:$F$19=$B10)*([2]Hoja3!$G$5:$G$19=$AJ$3))} -> 0 | AL10: =IFERROR(AK10/AJ10,0) -> 0 | AM10: {=SUM([2]Hoja3!$I$5:$I$19*([2]Hoja3!$F$5:$F$19=$B10)*([2]Hoja3!$G$5:$G$19=$AM$3))} -> 0 | AN10: {=SUM([2]Hoja3!$J$5:$J$19*([2]Hoja3!$F$5:$F$19=$B10)*([2]Hoja3!$G$5:$G$19=$AM$3))} -> 0 | AO10: =IFERROR(AN10/AM10,0) -> 0 | AP10: =U10+X10+AA10 -> 0 | AQ10: =V10+Y10+AB10 -> 0 | AR10: =IFERROR(AQ10/AP10,0) -> 0 | AS10: =AD10+AG10+AJ10+AM10 -> 0 | AT10: =AE10+AH10+AK10+AN10 -> 0 | AU10: =IFERROR(AT10/AS10,0) -> 0 | AV10: {=SUM([2]Hoja3!$I$27:$I$34*([2]Hoja3!$F$27:$F$34=$B10))} -> 0 | AW10: {=SUM([2]Hoja3!$J$27:$J$34*([2]Hoja3!$F$27:$F$34=$B10))} -> 0 | AX10: =IFERROR(AW10/AV10,0) -> 0 | AY10: =AP10+AS10+AV10 -> 0 | AZ10: =AQ10+AT10+AW10 -> 0 | BA10: =IFERROR(AZ10/AY10,0) -> 0 | BB10: =AY10*E10 -> 0 | BC10: =IFERROR(G10/$D10*$AY10,0) -> 0 | BD10: =$BD$22/$AY$22*AY10 -> 0 | BE10: =$BE$22/$AY$22*AY10 -> 0 | BF10: =$BF$22/$AY$22*AY10 -> 0 | BG10: =AZ10-BB10-BC10-BD10-BE10 -> 0 | BH10: =IFERROR(BG10/AZ10,0) -> 0 | BI10: =IF((AS10+AV10)>D10,AS10+AV10-D10,0) -> 0 | BJ10: =IFERROR(AW10/AV10*BI10,0) -> 0 | BK10: =IFERROR(BJ10-(BB10+BC10+BD10+BE10)/AY10*BI10,0) -> 0 | BL10: =IFERROR(BK10/BJ10,0) -> 0
B11: 10007162 | C11: POTA REJOS CONGELADOS | D11: 371.8 | E11: =IFERROR(F11/D11,0) -> 1720 | F11: 639496 | G11: 67667.6 | H11: 13579.574 | I11: 30744.618 | J11: 25704.096 | K11: 0 | L11: 0 | M11: =F11+G11+H11+I11 -> 751487.79 | N11: =IFERROR(M11/D11,0) -> 2021.2151 | P11: 2700 | Q11: =D11*P11 -> 1003860 | R11: =Q11-M11 -> 252372.21 | S11: =IFERROR(R11/Q11,0) -> 0.2514018 | U11: {=SUM([2]Hoja3!$I$5:$I$19*([2]Hoja3!$F$5:$F$19=$B11)*([2]Hoja3!$G$5:$G$19=$U$3))} -> 0 | V11: {=SUM([2]Hoja3!$J$5:$J$19*([2]Hoja3!$F$5:$F$19=$B11)*([2]Hoja3!$G$5:$G$19=$U$3))} -> 0 | W11: =IFERROR(V11/U11,0) -> 0 | X11: {=SUM([2]Hoja3!$I$5:$I$19*([2]Hoja3!$F$5:$F$19=$B11)*([2]Hoja3!$G$5:$G$19=$X$3))} -> 0 | Y11: {=SUM([2]Hoja3!$J$5:$J$19*([2]Hoja3!$F$5:$F$19=$B11)*([2]Hoja3!$G$5:$G$19=$X$3))} -> 0 | Z11: =IFERROR(Y11/X11,0) -> 0 | AA11: {=SUM([2]Hoja3!$I$5:$I$19*([2]Hoja3!$F$5:$F$19=$B11)*([2]Hoja3!$G$5:$G$19=$AA$3))} -> 0 | AB11: {=SUM([2]Hoja3!$J$5:$J$19*([2]Hoja3!$F$5:$F$19=$B11)*([2]Hoja3!$G$5:$G$19=$AA$3))} -> 0 | AC11: =IFERROR(AB11/AA11,0) -> 0 | AD11: {=SUM([2]Hoja3!$I$5:$I$19*([2]Hoja3!$F$5:$F$19=$B11)*([2]Hoja3!$G$5:$G$19=$AD$3))} -> 0 | AE11: {=SUM([2]Hoja3!$J$5:$J$19*([2]Hoja3!$F$5:$F$19=$B11)*([2]Hoja3!$G$5:$G$19=$AD$3))} -> 0 | AF11: =IFERROR(AE11/AD11,0) -> 0 | AG11: {=SUM([2]Hoja3!$I$5:$I$19*([2]Hoja3!$F$5:$F$19=$B11)*([2]Hoja3!$G$5:$G$19=$AG$3))} -> 0 | AH11: {=SUM([2]Hoja3!$J$5:$J$19*([2]Hoja3!$F$5:$F$19=$B11)*([2]Hoja3!$G$5:$G$19=$AG$3))} -> 0 | AI11: =IFERROR(AH11/AG11,0) -> 0 | AJ11: {=SUM([2]Hoja3!$I$5:$I$19*([2]Hoja3!$F$5:$F$19=$B11)*([2]Hoja3!$G$5:$G$19=$AJ$3))} -> 0 | AK11: {=SUM([2]Hoja3!$J$5:$J$19*([2]Hoja3!$F$5:$F$19=$B11)*([2]Hoja3!$G$5:$G$19=$AJ$3))} -> 0 | AL11: =IFERROR(AK11/AJ11,0) -> 0 | AM11: {=SUM([2]Hoja3!$I$5:$I$19*([2]Hoja3!$F$5:$F$19=$B11)*([2]Hoja3!$G$5:$G$19=$AM$3))} -> 0 | AN11: {=SUM([2]Hoja3!$J$5:$J$19*([2]Hoja3!$F$5:$F$19=$B11)*([2]Hoja3!$G$5:$G$19=$AM$3))} -> 0 | AO11: =IFERROR(AN11/AM11,0) -> 0 | AP11: =U11+X11+AA11 -> 0 | AQ11: =V11+Y11+AB11 -> 0 | AR11: =IFERROR(AQ11/AP11,0) -> 0 | AS11: =AD11+AG11+AJ11+AM11 -> 0 | AT11: =AE11+AH11+AK11+AN11 -> 0 | AU11: =IFERROR(AT11/AS11,0) -> 0 | AV11: {=SUM([2]Hoja3!$I$27:$I$34*([2]Hoja3!$F$27:$F$34=$B11))} -> 135 | AW11: {=SUM([2]Hoja3!$J$27:$J$34*([2]Hoja3!$F$27:$F$34=$B11))} -> 380700 | AX11: =IFERROR(AW11/AV11,0) -> 2820 | AY11: =AP11+AS11+AV11 -> 135 | AZ11: =AQ11+AT11+AW11 -> 380700 | BA11: =IFERROR(AZ11/AY11,0) -> 2820 | BB11: =AY11*E11 -> 232200 | BC11: =IFERROR(G11/$D11*$AY11,0) -> 24570 | BD11: =$BD$22/$AY$22*AY11 -> 4080.1247 | BE11: =$BE$22/$AY$22*AY11 -> 9237.5416 | BF11: =$BF$22/$AY$22*AY11 -> 7723.0639 | BG11: =AZ11-BB11-BC11-BD11-BE11 -> 110612.33 | BH11: =IFERROR(BG11/AZ11,0) -> 0.29054987 | BI11: =IF((AS11+AV11)>D11,AS11+AV11-D11,0) -> 0 | BJ11: =IFERROR(AW11/AV11*BI11,0) -> 0 | BK11: =IFERROR(BJ11-(BB11+BC11+BD11+BE11)/AY11*BI11,0) -> 0 | BL11: =IFERROR(BK11/BJ11,0) -> 0
B12: 10007567 | C12: POTA REJOS CONGELADOS FR LIMPIOS S/COD BL10 S20 | D12: 88.76 | E12: =IFERROR(F12/D12,0) -> 1700 | F12: 150892 | G12: 16154.32 | H12: 3241.8584 | I12: 7339.6781 | J12: 6136.3516 | K12: 0 | L12: 0 | M12: =F12+G12+H12+I12 -> 177627.86 | N12: =IFERROR(M12/D12,0) -> 2001.2151 | P12: 2700 | Q12: =D12*P12 -> 239652 | R12: =Q12-M12 -> 62024.144 | S12: =IFERROR(R12/Q12,0) -> 0.2588092 | U12: {=SUM([2]Hoja3!$I$5:$I$19*([2]Hoja3!$F$5:$F$19=$B12)*([2]Hoja3!$G$5:$G$19=$U$3))} -> 0 | V12: {=SUM([2]Hoja3!$J$5:$J$19*([2]Hoja3!$F$5:$F$19=$B12)*([2]Hoja3!$G$5:$G$19=$U$3))} -> 0 | W12: =IFERROR(V12/U12,0) -> 0 | X12: {=SUM([2]Hoja3!$I$5:$I$19*([2]Hoja3!$F$5:$F$19=$B12)*([2]Hoja3!$G$5:$G$19=$X$3))} -> 0 | Y12: {=SUM([2]Hoja3!$J$5:$J$19*([2]Hoja3!$F$5:$F$19=$B12)*([2]Hoja3!$G$5:$G$19=$X$3))} -> 0 | Z12: =IFERROR(Y12/X12,0) -> 0 | AA12: {=SUM([2]Hoja3!$I$5:$I$19*([2]Hoja3!$F$5:$F$19=$B12)*([2]Hoja3!$G$5:$G$19=$AA$3))} -> 26 | AB12: {=SUM([2]Hoja3!$J$5:$J$19*([2]Hoja3!$F$5:$F$19=$B12)*([2]Hoja3!$G$5:$G$19=$AA$3))} -> 80600 | AC12: =IFERROR(AB12/AA12,0) -> 3100 | AD12: {=SUM([2]Hoja3!$I$5:$I$19*([2]Hoja3!$F$5:$F$19=$B12)*([2]Hoja3!$G$5:$G$19=$AD$3))} -> 0 | AE12: {=SUM([2]Hoja3!$J$5:$J$19*([2]Hoja3!$F$5:$F$19=$B12)*([2]Hoja3!$G$5:$G$19=$AD$3))} -> 0 | AF12: =IFERROR(AE12/AD12,0) -> 0 | AG12: {=SUM([2]Hoja3!$I$5:$I$19*([2]Hoja3!$F$5:$F$19=$B12)*([2]Hoja3!$G$5:$G$19=$AG$3))} -> 0 | AH12: {=SUM([2]Hoja3!$J$5:$J$19*([2]Hoja3!$F$5:$F$19=$B12)*([2]Hoja3!$G$5:$G$19=$AG$3))} -> 0 | AI12: =IFERROR(AH12/AG12,0) -> 0 | AJ12: {=SUM([2]Hoja3!$I$5:$I$19*([2]Hoja3!$F$5:$F$19=$B12)*([2]Hoja3!$G$5:$G$19=$AJ$3))} -> 0 | AK12: {=SUM([2]Hoja3!$J$5:$J$19*([2]Hoja3!$F$5:$F$19=$B12)*([2]Hoja3!$G$5:$G$19=$AJ$3))} -> 0 | AL12: =IFERROR(AK12/AJ12,0) -> 0 | AM12: {=SUM([2]Hoja3!$I$5:$I$19*([2]Hoja3!$F$5:$F$19=$B12)*([2]Hoja3!$G$5:$G$19=$AM$3))} -> 0 | AN12: {=SUM([2]Hoja3!$J$5:$J$19*([2]Hoja3!$F$5:$F$19=$B12)*([2]Hoja3!$G$5:$G$19=$AM$3))} -> 0 | AO12: =IFERROR(AN12/AM12,0) -> 0 | AP12: =U12+X12+AA12 -> 26 | AQ12: =V12+Y12+AB12 -> 80600 | AR12: =IFERROR(AQ12/AP12,0) -> 3100 | AS12: =AD12+AG12+AJ12+AM12 -> 0 | AT12: =AE12+AH12+AK12+AN12 -> 0 | AU12: =IFERROR(AT12/AS12,0) -> 0 | AV12: {=SUM([2]Hoja3!$I$27:$I$34*([2]Hoja3!$F$27:$F$34=$B12))} -> 106 | AW12: {=SUM([2]Hoja3!$J$27:$J$34*([2]Hoja3!$F$27:$F$34=$B12))} -> 314980 | AX12: =IFERROR(AW12/AV12,0) -> 2971.5094 | AY12: =AP12+AS12+AV12 -> 132 | AZ12: =AQ12+AT12+AW12 -> 395580 | BA12: =IFERROR(AZ12/AY12,0) -> 2996.8182 | BB12: =AY12*E12 -> 224400 | BC12: =IFERROR(G12/$D12*$AY12,0) -> 24024 | BD12: =$BD$22/$AY$22*AY12 -> 3989.4552 | BE12: =$BE$22/$AY$22*AY12 -> 9032.2629 | BF12: =$BF$22/$AY$22*AY12 -> 7551.4403 | BG12: =AZ12-BB12-BC12-BD12-BE12 -> 134134.28 | BH12: =IFERROR(BG12/AZ12,0) -> 0.33908257 | BI12: =IF((AS12+AV12)>D12,AS12+AV12-D12,0) -> 17.24 | BJ12: =IFERROR(AW12/AV12*BI12,0) -> 51228.823 | BK12: =IFERROR(BJ12-(BB12+BC12+BD12+BE12)/AY12*BI12,0) -> 17082.427 | BL12: =IFERROR(BK12/BJ12,0) -> 0.33345344
B13: 10009639 | C13: POTA REJOS CONGELADOS FR C/B S/U S/V S/OR 0.3 - 0.5 | D13: 4.7 | E13: =IFERROR(F13/D13,0) -> 1750 | F13: 8225 | G13: 855.4 | H13: 171.66217 | I13: 388.64902 | J13: 324.93074 | K13: 0 | L13: 0 | M13: =F13+G13+H13+I13 -> 9640.7112 | N13: =IFERROR(M13/D13,0) -> 2051.2151 | P13: 2700 | Q13: =D13*P13 -> 12690 | R13: =Q13-M13 -> 3049.2888 | S13: =IFERROR(R13/Q13,0) -> 0.24029069 | U13: {=SUM([2]Hoja3!$I$5:$I$19*([2]Hoja3!$F$5:$F$19=$B13)*([2]Hoja3!$G$5:$G$19=$U$3))} -> 0 | V13: {=SUM([2]Hoja3!$J$5:$J$19*([2]Hoja3!$F$5:$F$19=$B13)*([2]Hoja3!$G$5:$G$19=$U$3))} -> 0 | W13: =IFERROR(V13/U13,0) -> 0 | X13: {=SUM([2]Hoja3!$I$5:$I$19*([2]Hoja3!$F$5:$F$19=$B13)*([2]Hoja3!$G$5:$G$19=$X$3))} -> 0 | Y13: {=SUM([2]Hoja3!$J$5:$J$19*([2]Hoja3!$F$5:$F$19=$B13)*([2]Hoja3!$G$5:$G$19=$X$3))} -> 0 | Z13: =IFERROR(Y13/X13,0) -> 0 | AA13: {=SUM([2]Hoja3!$I$5:$I$19*([2]Hoja3!$F$5:$F$19=$B13)*([2]Hoja3!$G$5:$G$19=$AA$3))} -> 0 | AB13: {=SUM([2]Hoja3!$J$5:$J$19*([2]Hoja3!$F$5:$F$19=$B13)*([2]Hoja3!$G$5:$G$19=$AA$3))} -> 0 | AC13: =IFERROR(AB13/AA13,0) -> 0 | AD13: {=SUM([2]Hoja3!$I$5:$I$19*([2]Hoja3!$F$5:$F$19=$B13)*([2]Hoja3!$G$5:$G$19=$AD$3))} -> 0 | AE13: {=SUM([2]Hoja3!$J$5:$J$19*([2]Hoja3!$F$5:$F$19=$B13)*([2]Hoja3!$G$5:$G$19=$AD$3))} -> 0 | AF13: =IFERROR(AE13/AD13,0) -> 0 | AG13: {=SUM([2]Hoja3!$I$5:$I$19*([2]Hoja3!$F$5:$F$19=$B13)*([2]Hoja3!$G$5:$G$19=$AG$3))} -> 0 | AH13: {=SUM([2]Hoja3!$J$5:$J$19*([2]Hoja3!$F$5:$F$19=$B13)*([2]Hoja3!$G$5:$G$19=$AG$3))} -> 0 | AI13: =IFERROR(AH13/AG13,0) -> 0 | AJ13: {=SUM([2]Hoja3!$I$5:$I$19*([2]Hoja3!$F$5:$F$19=$B13)*([2]Hoja3!$G$5:$G$19=$AJ$3))} -> 0 | AK13: {=SUM([2]Hoja3!$J$5:$J$19*([2]Hoja3!$F$5:$F$19=$B13)*([2]Hoja3!$G$5:$G$19=$AJ$3))} -> 0 | AL13: =IFERROR(AK13/AJ13,0) -> 0 | AM13: {=SUM([2]Hoja3!$I$5:$I$19*([2]Hoja3!$F$5:$F$19=$B13)*([2]Hoja3!$G$5:$G$19=$AM$3))} -> 0 | AN13: {=SUM([2]Hoja3!$J$5:$J$19*([2]Hoja3!$F$5:$F$19=$B13)*([2]Hoja3!$G$5:$G$19=$AM$3))} -> 0 | AO13: =IFERROR(AN13/AM13,0) -> 0 | AP13: =U13+X13+AA13 -> 0 | AQ13: =V13+Y13+AB13 -> 0 | AR13: =IFERROR(AQ13/AP13,0) -> 0 | AS13: =AD13+AG13+AJ13+AM13 -> 0 | AT13: =AE13+AH13+AK13+AN13 -> 0 | AU13: =IFERROR(AT13/AS13,0) -> 0 | AV13: {=SUM([2]Hoja3!$I$27:$I$34*([2]Hoja3!$F$27:$F$34=$B13))} -> 0 | AW13: {=SUM([2]Hoja3!$J$27:$J$34*([2]Hoja3!$F$27:$F$34=$B13))} -> 0 | AX13: =IFERROR(AW13/AV13,0) -> 0 | AY13: =AP13+AS13+AV13 -> 0 | AZ13: =AQ13+AT13+AW13 -> 0 | BA13: =IFERROR(AZ13/AY13,0) -> 0 | BB13: =AY13*E13 -> 0 | BC13: =IFERROR(G13/$D13*$AY13,0) -> 0 | BD13: =$BD$22/$AY$22*AY13 -> 0 | BE13: =$BE$22/$AY$22*AY13 -> 0 | BF13: =$BF$22/$AY$22*AY13 -> 0 | BG13: =AZ13-BB13-BC13-BD13-BE13 -> 0 | BH13: =IFERROR(BG13/AZ13,0) -> 0 | BI13: =IF((AS13+AV13)>D13,AS13+AV13-D13,0) -> 0 | BJ13: =IFERROR(AW13/AV13*BI13,0) -> 0 | BK13: =IFERROR(BJ13-(BB13+BC13+BD13+BE13)/AY13*BI13,0) -> 0 | BL13: =IFERROR(BK13/BJ13,0) -> 0
B14: 10007050 | C14: POTA ALAS COCIDAS | D14: 70.744 | E14: =IFERROR(F14/D14,0) -> 1310 | F14: 92674.64 | G14: 12875.408 | H14: 2583.8444 | I14: 5849.912 | J14: 4890.8298 | K14: 0 | L14: 0 | M14: =F14+G14+H14+I14 -> 113983.8 | N14: =IFERROR(M14/D14,0) -> 1611.2151 | P14: 3950 | Q14: =D14*P14 -> 279438.8 | R14: =Q14-M14 -> 165455 | S14: =IFERROR(R14/Q14,0) -> 0.59209743 | U14: {=SUM([2]Hoja3!$I$5:$I$19*([2]Hoja3!$F$5:$F$19=$B14)*([2]Hoja3!$G$5:$G$19=$U$3))} -> 0 | V14: {=SUM([2]Hoja3!$J$5:$J$19*([2]Hoja3!$F$5:$F$19=$B14)*([2]Hoja3!$G$5:$G$19=$U$3))} -> 0 | W14: =IFERROR(V14/U14,0) -> 0 | X14: {=SUM([2]Hoja3!$I$5:$I$19*([2]Hoja3!$F$5:$F$19=$B14)*([2]Hoja3!$G$5:$G$19=$X$3))} -> 0 | Y14: {=SUM([2]Hoja3!$J$5:$J$19*([2]Hoja3!$F$5:$F$19=$B14)*([2]Hoja3!$G$5:$G$19=$X$3))} -> 0 | Z14: =IFERROR(Y14/X14,0) -> 0 | AA14: {=SUM([2]Hoja3!$I$5:$I$19*([2]Hoja3!$F$5:$F$19=$B14)*([2]Hoja3!$G$5:$G$19=$AA$3))} -> 0 | AB14: {=SUM([2]Hoja3!$J$5:$J$19*([2]Hoja3!$F$5:$F$19=$B14)*([2]Hoja3!$G$5:$G$19=$AA$3))} -> 0 | AC14: =IFERROR(AB14/AA14,0) -> 0 | AD14: {=SUM([2]Hoja3!$I$5:$I$19*([2]Hoja3!$F$5:$F$19=$B14)*([2]Hoja3!$G$5:$G$19=$AD$3))} -> 27 | AE14: {=SUM([2]Hoja3!$J$5:$J$19*([2]Hoja3!$F$5:$F$19=$B14)*([2]Hoja3!$G$5:$G$19=$AD$3))} -> 97200 | AF14: =IFERROR(AE14/AD14,0) -> 3600 | AG14: {=SUM([2]Hoja3!$I$5:$I$19*([2]Hoja3!$F$5:$F$19=$B14)*([2]Hoja3!$G$5:$G$19=$AG$3))} -> 0 | AH14: {=SUM([2]Hoja3!$J$5:$J$19*([2]Hoja3!$F$5:$F$19=$B14)*([2]Hoja3!$G$5:$G$19=$AG$3))} -> 0 | AI14: =IFERROR(AH14/AG14,0) -> 0 | AJ14: {=SUM([2]Hoja3!$I$5:$I$19*([2]Hoja3!$F$5:$F$19=$B14)*([2]Hoja3!$G$5:$G$19=$AJ$3))} -> 0 | AK14: {=SUM([2]Hoja3!$J$5:$J$19*([2]Hoja3!$F$5:$F$19=$B14)*([2]Hoja3!$G$5:$G$19=$AJ$3))} -> 0 | AL14: =IFERROR(AK14/AJ14,0) -> 0 | AM14: {=SUM([2]Hoja3!$I$5:$I$19*([2]Hoja3!$F$5:$F$19=$B14)*([2]Hoja3!$G$5:$G$19=$AM$3))} -> 0 | AN14: {=SUM([2]Hoja3!$J$5:$J$19*([2]Hoja3!$F$5:$F$19=$B14)*([2]Hoja3!$G$5:$G$19=$AM$3))} -> 0 | AO14: =IFERROR(AN14/AM14,0) -> 0 | AP14: =U14+X14+AA14 -> 0 | AQ14: =V14+Y14+AB14 -> 0 | AR14: =IFERROR(AQ14/AP14,0) -> 0 | AS14: =AD14+AG14+AJ14+AM14 -> 27 | AT14: =AE14+AH14+AK14+AN14 -> 97200 | AU14: =IFERROR(AT14/AS14,0) -> 3600 | AV14: {=SUM([2]Hoja3!$I$27:$I$34*([2]Hoja3!$F$27:$F$34=$B14))} -> 216 | AW14: {=SUM([2]Hoja3!$J$27:$J$34*([2]Hoja3!$F$27:$F$34=$B14))} -> 820800 | AX14: =IFERROR(AW14/AV14,0) -> 3800 | AY14: =AP14+AS14+AV14 -> 243 | AZ14: =AQ14+AT14+AW14 -> 918000 | BA14: =IFERROR(AZ14/AY14,0) -> 3777.7778 | BB14: =AY14*E14 -> 318330 | BC14: =IFERROR(G14/$D14*$AY14,0) -> 44226 | BD14: =$BD$22/$AY$22*AY14 -> 7344.2244 | BE14: =$BE$22/$AY$22*AY14 -> 16627.575 | BF14: =$BF$22/$AY$22*AY14 -> 13901.515 | BG14: =AZ14-BB14-BC14-BD14-BE14 -> 531472.2 | BH14: =IFERROR(BG14/AZ14,0) -> 0.57894575 | BI14: =IF((AS14+AV14)>D14,AS14+AV14-D14,0) -> 172.256 | BJ14: =IFERROR(AW14/AV14*BI14,0) -> 654572.8 | BK14: =IFERROR(BJ14-(BB14+BC14+BD14+BE14)/AY14*BI14,0) -> 380573.9 | BL14: =IFERROR(BK14/BJ14,0) -> 0.58140806
B15: 10009239 | C15: POTA FILETE DARUMA | D15: 203.7 | E15: =IFERROR(F15/D15,0) -> 2110 | F15: 429807 | G15: 37073.4 | H15: 7439.9116 | I15: 16844.214 | J15: 14082.637 | K15: 0 | L15: 0 | M15: =F15+G15+H15+I15 -> 491164.53 | N15: =IFERROR(M15/D15,0) -> 2411.2151 | P15: 3950 | Q15: =D15*P15 -> 804615 | R15: =Q15-M15 -> 313450.47 | S15: =IFERROR(R15/Q15,0) -> 0.38956579 | U15: {=SUM([2]Hoja3!$I$5:$I$19*([2]Hoja3!$F$5:$F$19=$B15)*([2]Hoja3!$G$5:$G$19=$U$3))} -> 0 | V15: {=SUM([2]Hoja3!$J$5:$J$19*([2]Hoja3!$F$5:$F$19=$B15)*([2]Hoja3!$G$5:$G$19=$U$3))} -> 0 | W15: =IFERROR(V15/U15,0) -> 0 | X15: {=SUM([2]Hoja3!$I$5:$I$19*([2]Hoja3!$F$5:$F$19=$B15)*([2]Hoja3!$G$5:$G$19=$X$3))} -> 27 | Y15: {=SUM([2]Hoja3!$J$5:$J$19*([2]Hoja3!$F$5:$F$19=$B15)*([2]Hoja3!$G$5:$G$19=$X$3))} -> 94500 | Z15: =IFERROR(Y15/X15,0) -> 3500 | AA15: {=SUM([2]Hoja3!$I$5:$I$19*([2]Hoja3!$F$5:$F$19=$B15)*([2]Hoja3!$G$5:$G$19=$AA$3))} -> 0 | AB15: {=SUM([2]Hoja3!$J$5:$J$19*([2]Hoja3!$F$5:$F$19=$B15)*([2]Hoja3!$G$5:$G$19=$AA$3))} -> 0 | AC15: =IFERROR(AB15/AA15,0) -> 0 | AD15: {=SUM([2]Hoja3!$I$5:$I$19*([2]Hoja3!$F$5:$F$19=$B15)*([2]Hoja3!$G$5:$G$19=$AD$3))} -> 162 | AE15: {=SUM([2]Hoja3!$J$5:$J$19*([2]Hoja3!$F$5:$F$19=$B15)*([2]Hoja3!$G$5:$G$19=$AD$3))} -> 631800 | AF15: =IFERROR(AE15/AD15,0) -> 3900 | AG15: {=SUM([2]Hoja3!$I$5:$I$19*([2]Hoja3!$F$5:$F$19=$B15)*([2]Hoja3!$G$5:$G$19=$AG$3))} -> 0 | AH15: {=SUM([2]Hoja3!$J$5:$J$19*([2]Hoja3!$F$5:$F$19=$B15)*([2]Hoja3!$G$5:$G$19=$AG$3))} -> 0 | AI15: =IFERROR(AH15/AG15,0) -> 0 | AJ15: {=SUM([2]Hoja3!$I$5:$I$19*([2]Hoja3!$F$5:$F$19=$B15)*([2]Hoja3!$G$5:$G$19=$AJ$3))} -> 0 | AK15: {=SUM([2]Hoja3!$J$5:$J$19*([2]Hoja3!$F$5:$F$19=$B15)*([2]Hoja3!$G$5:$G$19=$AJ$3))} -> 0 | AL15: =IFERROR(AK15/AJ15,0) -> 0 | AM15: {=SUM([2]Hoja3!$I$5:$I$19*([2]Hoja3!$F$5:$F$19=$B15)*([2]Hoja3!$G$5:$G$19=$AM$3))} -> 0 | AN15: {=SUM([2]Hoja3!$J$5:$J$19*([2]Hoja3!$F$5:$F$19=$B15)*([2]Hoja3!$G$5:$G$19=$AM$3))} -> 0 | AO15: =IFERROR(AN15/AM15,0) -> 0 | AP15: =U15+X15+AA15 -> 27 | AQ15: =V15+Y15+AB15 -> 94500 | AR15: =IFERROR(AQ15/AP15,0) -> 3500 | AS15: =AD15+AG15+AJ15+AM15 -> 162 | AT15: =AE15+AH15+AK15+AN15 -> 631800 | AU15: =IFERROR(AT15/AS15,0) -> 3900 | AV15: {=SUM([2]Hoja3!$I$27:$I$34*([2]Hoja3!$F$27:$F$34=$B15))} -> 243 | AW15: {=SUM([2]Hoja3!$J$27:$J$34*([2]Hoja3!$F$27:$F$34=$B15))} -> 904500 | AX15: =IFERROR(AW15/AV15,0) -> 3722.2222 | AY15: =AP15+AS15+AV15 -> 432 | AZ15: =AQ15+AT15+AW15 -> 1630800 | BA15: =IFERROR(AZ15/AY15,0) -> 3775 | BB15: =AY15*E15 -> 911520 | BC15: =IFERROR(G15/$D15*$AY15,0) -> 78624 | BD15: =$BD$22/$AY$22*AY15 -> 13056.399 | BE15: =$BE$22/$AY$22*AY15 -> 29560.133 | BF15: =$BF$22/$AY$22*AY15 -> 24713.805 | BG15: =AZ15-BB15-BC15-BD15-BE15 -> 598039.47 | BH15: =IFERROR(BG15/AZ15,0) -> 0.3667154 | BI15: =IF((AS15+AV15)>D15,AS15+AV15-D15,0) -> 201.3 | BJ15: =IFERROR(AW15/AV15*BI15,0) -> 749283.33 | BK15: =IFERROR(BJ15-(BB15+BC15+BD15+BE15)/AY15*BI15,0) -> 268045.61 | BL15: =IFERROR(BK15/BJ15,0) -> 0.35773599
B16: 10009332 | C16: POTA RECORTE COCIDO | D16: 63.555 | E16: =IFERROR(F16/D16,0) -> 1530 | F16: 97239.15 | G16: 11567.01 | H16: 2321.2743 | I16: 5255.4444 | J16: 4393.8241 | K16: 0 | L16: 0 | M16: =F16+G16+H16+I16 -> 116382.88 | N16: =IFERROR(M16/D16,0) -> 1831.2151 | P16: 2000 | Q16: =D16*P16 -> 127110 | R16: =Q16-M16 -> 10727.121 | S16: =IFERROR(R16/Q16,0) -> 0.084392426 | U16: {=SUM([2]Hoja3!$I$5:$I$19*([2]Hoja3!$F$5:$F$19=$B16)*([2]Hoja3!$G$5:$G$19=$U$3))} -> 0 | V16: {=SUM([2]Hoja3!$J$5:$J$19*([2]Hoja3!$F$5:$F$19=$B16)*([2]Hoja3!$G$5:$G$19=$U$3))} -> 0 | W16: =IFERROR(V16/U16,0) -> 0 | X16: {=SUM([2]Hoja3!$I$5:$I$19*([2]Hoja3!$F$5:$F$19=$B16)*([2]Hoja3!$G$5:$G$19=$X$3))} -> 0 | Y16: {=SUM([2]Hoja3!$J$5:$J$19*([2]Hoja3!$F$5:$F$19=$B16)*([2]Hoja3!$G$5:$G$19=$X$3))} -> 0 | Z16: =IFERROR(Y16/X16,0) -> 0 | AA16: {=SUM([2]Hoja3!$I$5:$I$19*([2]Hoja3!$F$5:$F$19=$B16)*([2]Hoja3!$G$5:$G$19=$AA$3))} -> 0 | AB16: {=SUM([2]Hoja3!$J$5:$J$19*([2]Hoja3!$F$5:$F$19=$B16)*([2]Hoja3!$G$5:$G$19=$AA$3))} -> 0 | AC16: =IFERROR(AB16/AA16,0) -> 0 | AD16: {=SUM([2]Hoja3!$I$5:$I$19*([2]Hoja3!$F$5:$F$19=$B16)*([2]Hoja3!$G$5:$G$19=$AD$3))} -> 0 | AE16: {=SUM([2]Hoja3!$J$5:$J$19*([2]Hoja3!$F$5:$F$19=$B16)*([2]Hoja3!$G$5:$G$19=$AD$3))} -> 0 | AF16: =IFERROR(AE16/AD16,0) -> 0 | AG16: {=SUM([2]Hoja3!$I$5:$I$19*([2]Hoja3!$F$5:$F$19=$B16)*([2]Hoja3!$G$5:$G$19=$AG$3))} -> 0 | AH16: {=SUM([2]Hoja3!$J$5:$J$19*([2]Hoja3!$F$5:$F$19=$B16)*([2]Hoja3!$G$5:$G$19=$AG$3))} -> 0 | AI16: =IFERROR(AH16/AG16,0) -> 0 | AJ16: {=SUM([2]Hoja3!$I$5:$I$19*([2]Hoja3!$F$5:$F$19=$B16)*([2]Hoja3!$G$5:$G$19=$AJ$3))} -> 0 | AK16: {=SUM([2]Hoja3!$J$5:$J$19*([2]Hoja3!$F$5:$F$19=$B16)*([2]Hoja3!$G$5:$G$19=$AJ$3))} -> 0 | AL16: =IFERROR(AK16/AJ16,0) -> 0 | AM16: {=SUM([2]Hoja3!$I$5:$I$19*([2]Hoja3!$F$5:$F$19=$B16)*([2]Hoja3!$G$5:$G$19=$AM$3))} -> 0 | AN16: {=SUM([2]Hoja3!$J$5:$J$19*([2]Hoja3!$F$5:$F$19=$B16)*([2]Hoja3!$G$5:$G$19=$AM$3))} -> 0 | AO16: =IFERROR(AN16/AM16,0) -> 0 | AP16: =U16+X16+AA16 -> 0 | AQ16: =V16+Y16+AB16 -> 0 | AR16: =IFERROR(AQ16/AP16,0) -> 0 | AS16: =AD16+AG16+AJ16+AM16 -> 0 | AT16: =AE16+AH16+AK16+AN16 -> 0 | AU16: =IFERROR(AT16/AS16,0) -> 0 | AV16: {=SUM([2]Hoja3!$I$27:$I$34*([2]Hoja3!$F$27:$F$34=$B16))} -> 0 | AW16: {=SUM([2]Hoja3!$J$27:$J$34*([2]Hoja3!$F$27:$F$34=$B16))} -> 0 | AX16: =IFERROR(AW16/AV16,0) -> 0 | AY16: =AP16+AS16+AV16 -> 0 | AZ16: =AQ16+AT16+AW16 -> 0 | BA16: =IFERROR(AZ16/AY16,0) -> 0 | BB16: =AY16*E16 -> 0 | BC16: =IFERROR(G16/$D16*$AY16,0) -> 0 | BD16: =$BD$22/$AY$22*AY16 -> 0 | BE16: =$BE$22/$AY$22*AY16 -> 0 | BF16: =$BF$22/$AY$22*AY16 -> 0 | BG16: =AZ16-BB16-BC16-BD16-BE16 -> 0 | BH16: =IFERROR(BG16/AZ16,0) -> 0 | BI16: =IF((AS16+AV16)>D16,AS16+AV16-D16,0) -> 0 | BJ16: =IFERROR(AW16/AV16*BI16,0) -> 0 | BK16: =IFERROR(BJ16-(BB16+BC16+BD16+BE16)/AY16*BI16,0) -> 0 | BL16: =IFERROR(BK16/BJ16,0) -> 0
... B20: 10009224 | C20: BONITO ENT | D20: 0 | E20: =IFERROR(F20/D20,0) -> 0 | F20: 0 | G20: 0 | H20: 0 | I20: 0 | J20: 0 | K20: 0 | L20: 0 | M20: =F20+G20+H20+I20 -> 0 | N20: =IFERROR(M20/D20,0) -> 0 | P20: 0 | Q20: =D20*P20 -> 0 | R20: =Q20-M20 -> 0 | S20: =IFERROR(R20/Q20,0) -> 0 | U20: {=SUM([2]Hoja3!$I$5:$I$19*([2]Hoja3!$F$5:$F$19=$B20)*([2]Hoja3!$G$5:$G$19=$U$3))} -> 0 | V20: {=SUM([2]Hoja3!$J$5:$J$19*([2]Hoja3!$F$5:$F$19=$B20)*([2]Hoja3!$G$5:$G$19=$U$3))} -> 0 | W20: =IFERROR(V20/U20,0) -> 0 | X20: {=SUM([2]Hoja3!$I$5:$I$19*([2]Hoja3!$F$5:$F$19=$B20)*([2]Hoja3!$G$5:$G$19=$X$3))} -> 0 | Y20: {=SUM([2]Hoja3!$J$5:$J$19*([2]Hoja3!$F$5:$F$19=$B20)*([2]Hoja3!$G$5:$G$19=$X$3))} -> 0 | Z20: =IFERROR(Y20/X20,0) -> 0 | AA20: {=SUM([2]Hoja3!$I$5:$I$19*([2]Hoja3!$F$5:$F$19=$B20)*([2]Hoja3!$G$5:$G$19=$AA$3))} -> 0 | AB20: {=SUM([2]Hoja3!$J$5:$J$19*([2]Hoja3!$F$5:$F$19=$B20)*([2]Hoja3!$G$5:$G$19=$AA$3))} -> 0 | AC20: =IFERROR(AB20/AA20,0) -> 0 | AD20: {=SUM([2]Hoja3!$I$5:$I$19*([2]Hoja3!$F$5:$F$19=$B20)*([2]Hoja3!$G$5:$G$19=$AD$3))} -> 0 | AE20: {=SUM([2]Hoja3!$J$5:$J$19*([2]Hoja3!$F$5:$F$19=$B20)*([2]Hoja3!$G$5:$G$19=$AD$3))} -> 0 | AF20: =IFERROR(AE20/AD20,0) -> 0 | AG20: {=SUM([2]Hoja3!$I$5:$I$19*([2]Hoja3!$F$5:$F$19=$B20)*([2]Hoja3!$G$5:$G$19=$AG$3))} -> 0 | AH20: {=SUM([2]Hoja3!$J$5:$J$19*([2]Hoja3!$F$5:$F$19=$B20)*([2]Hoja3!$G$5:$G$19=$AG$3))} -> 0 | AI20: =IFERROR(AH20/AG20,0) -> 0 | AJ20: {=SUM([2]Hoja3!$I$5:$I$19*([2]Hoja3!$F$5:$F$19=$B20)*([2]Hoja3!$G$5:$G$19=$AJ$3))} -> 0 | AK20: {=SUM([2]Hoja3!$J$5:$J$19*([2]Hoja3!$F$5:$F$19=$B20)*([2]Hoja3!$G$5:$G$19=$AJ$3))} -> 0 | AL20: =IFERROR(AK20/AJ20,0) -> 0 | AM20: {=SUM([2]Hoja3!$I$5:$I$19*([2]Hoja3!$F$5:$F$19=$B20)*([2]Hoja3!$G$5:$G$19=$AM$3))} -> 0 | AN20: {=SUM([2]Hoja3!$J$5:$J$19*([2]Hoja3!$F$5:$F$19=$B20)*([2]Hoja3!$G$5:$G$19=$AM$3))} -> 0 | AO20: =IFERROR(AN20/AM20,0) -> 0 | AP20: =U20+X20+AA20 -> 0 | AQ20: =V20+Y20+AB20 -> 0 | AR20: =IFERROR(AQ20/AP20,0) -> 0 | AS20: =AD20+AG20+AJ20+AM20 -> 0 | AT20: =AE20+AH20+AK20+AN20 -> 0 | AU20: =IFERROR(AT20/AS20,0) -> 0 | AV20: {=SUM([2]Hoja3!$I$27:$I$34*([2]Hoja3!$F$27:$F$34=$B20))} -> 0 | AW20: {=SUM([2]Hoja3!$J$27:$J$34*([2]Hoja3!$F$27:$F$34=$B20))} -> 0 | AX20: =IFERROR(AW20/AV20,0) -> 0 | AY20: =AP20+AS20+AV20 -> 0 | AZ20: =AQ20+AT20+AW20 -> 0 | BA20: =IFERROR(AZ20/AY20,0) -> 0 | BB20: =AY20*E20 -> 0 | BC20: =IFERROR(G20/$D20*$AY20,0) -> 0 | BD20: =$BD$22/$AY$22*AY20 -> 0 | BE20: =$BE$22/$AY$22*AY20 -> 0 | BF20: =$BF$22/$AY$22*AY20 -> 0 | BG20: =AZ20-BB20-BC20-BD20-BE20 -> 0 | BH20: =IFERROR(BG20/AZ20,0) -> 0 | BI20: =IF((AS20+AV20)>D20,AS20+AV20-D20,0) -> 0 | BJ20: =IFERROR(AW20/AV20*BI20,0) -> 0 | BK20: =IFERROR(BJ20-(BB20+BC20+BD20+BE20)/AY20*BI20,0) -> 0 | BL20: =IFERROR(BK20/BJ20,0) -> 0
C21: OTROS | D21: =Abril2026!Q59/1000-SUM(D5:D19) -> 6.1288 | E21: =IFERROR(F21/D21,0) -> 0 | U21: {=SUM([2]Hoja3!$I$5:$I$19*([2]Hoja3!$F$5:$F$19=$B21)*([2]Hoja3!$G$5:$G$19=$U$3))} -> 0 | V21: {=SUM([2]Hoja3!$J$5:$J$19*([2]Hoja3!$F$5:$F$19=$B21)*([2]Hoja3!$G$5:$G$19=$U$3))} -> 0 | W21: =IFERROR(V21/U21,0) -> 0 | X21: {=SUM([2]Hoja3!$I$5:$I$19*([2]Hoja3!$F$5:$F$19=$B21)*([2]Hoja3!$G$5:$G$19=$X$3))} -> 0 | Y21: {=SUM([2]Hoja3!$J$5:$J$19*([2]Hoja3!$F$5:$F$19=$B21)*([2]Hoja3!$G$5:$G$19=$X$3))} -> 0 | Z21: =IFERROR(Y21/X21,0) -> 0 | AA21: {=SUM([2]Hoja3!$I$5:$I$19*([2]Hoja3!$F$5:$F$19=$B21)*([2]Hoja3!$G$5:$G$19=$AA$3))} -> 0 | AB21: {=SUM([2]Hoja3!$J$5:$J$19*([2]Hoja3!$F$5:$F$19=$B21)*([2]Hoja3!$G$5:$G$19=$AA$3))} -> 0 | AC21: =IFERROR(AB21/AA21,0) -> 0 | AD21: {=SUM([2]Hoja3!$I$5:$I$19*([2]Hoja3!$F$5:$F$19=$B21)*([2]Hoja3!$G$5:$G$19=$AD$3))} -> 0 | AE21: {=SUM([2]Hoja3!$J$5:$J$19*([2]Hoja3!$F$5:$F$19=$B21)*([2]Hoja3!$G$5:$G$19=$AD$3))} -> 0 | AF21: =IFERROR(AE21/AD21,0) -> 0 | AG21: {=SUM([2]Hoja3!$I$5:$I$19*([2]Hoja3!$F$5:$F$19=$B21)*([2]Hoja3!$G$5:$G$19=$AG$3))} -> 0 | AH21: {=SUM([2]Hoja3!$J$5:$J$19*([2]Hoja3!$F$5:$F$19=$B21)*([2]Hoja3!$G$5:$G$19=$AG$3))} -> 0 | AI21: =IFERROR(AH21/AG21,0) -> 0 | AJ21: {=SUM([2]Hoja3!$I$5:$I$19*([2]Hoja3!$F$5:$F$19=$B21)*([2]Hoja3!$G$5:$G$19=$AJ$3))} -> 54 | AK21: {=SUM([2]Hoja3!$J$5:$J$19*([2]Hoja3!$F$5:$F$19=$B21)*([2]Hoja3!$G$5:$G$19=$AJ$3))} -> 108000 | AL21: =IFERROR(AK21/AJ21,0) -> 2000 | AM21: {=SUM([2]Hoja3!$I$5:$I$19*([2]Hoja3!$F$5:$F$19=$B21)*([2]Hoja3!$G$5:$G$19=$AM$3))} -> 0 | AN21: {=SUM([2]Hoja3!$J$5:$J$19*([2]Hoja3!$F$5:$F$19=$B21)*([2]Hoja3!$G$5:$G$19=$AM$3))} -> 0 | AO21: =IFERROR(AN21/AM21,0) -> 0 | AP21: =U21+X21+AA21 -> 0 | AQ21: =V21+Y21+AB21 -> 0 | AR21: =IFERROR(AQ21/AP21,0) -> 0 | AS21: =AD21+AG21+AJ21+AM21 -> 54 | AT21: =AE21+AH21+AK21+AN21 -> 108000 | AU21: =IFERROR(AT21/AS21,0) -> 2000 | AV21: {=SUM([2]Hoja3!$I$27:$I$34*([2]Hoja3!$F$27:$F$34=$B21))} -> 0 | AW21: {=SUM([2]Hoja3!$J$27:$J$34*([2]Hoja3!$F$27:$F$34=$B21))} -> 0 | AX21: =IFERROR(AW21/AV21,0) -> 0 | AY21: =AP21+AS21+AV21 -> 54 | AZ21: =AQ21+AT21+AW21 -> 108000 | BA21: =IFERROR(AZ21/AY21,0) -> 2000 | BB21: =AY21*E21 -> 0 | BC21: =IFERROR(G21/$D21*$AY21,0) -> 0 | BD21: =$BD$22/$AY$22*AY21 -> 1632.0499 | BE21: =$BE$22/$AY$22*AY21 -> 3695.0166 | BF21: =$BF$22/$AY$22*AY21 -> 3089.2256 | BG21: =AZ21-BB21-BC21-BD21-BE21 -> 102672.93 | BH21: =IFERROR(BG21/AZ21,0) -> 0.95067531 | BI21: =IF((AS21+AV21)>D21,AS21+AV21-D21,0) -> 47.8712 | BJ21: =IFERROR(AW21/AV21*BI21,0) -> 0 | BK21: =IFERROR(BJ21-(BB21+BC21+BD21+BE21)/AY21*BI21,0) -> -4722.4642 | BL21: =IFERROR(BK21/BJ21,0) -> 0
C22: TOTAL | D22: =SUM(D5:D21) -> 1800.1278 | E22: =IFERROR(F22/D22,0) -> 1665.3475 | F22: =SUM(F5:F21) -> 2997838.4 | G22: =SUM(G5:G21) -> 326507.82 | H22: =SUM(H5:H21) -> 65523.78 | I22: =SUM(I5:I21) -> 148348.08 | J22: =SUM(J5:J21) -> 124026.69 | K22: =SUM(K5:K21) -> 0 | L22: 0 | M22: =SUM(M5:M21) -> 3538218.1 | N22: =IFERROR(M22/D22,0) -> 1965.5371 | P22: =Q22/D22 -> 2401.8027 | Q22: =SUM(Q5:Q21) -> 4323551.8 | R22: =SUM(R5:R21) -> 785333.74 | S22: =IFERROR(R22/Q22,0) -> 0.18164088 | U22: =SUM(U5:U21) -> 293 | V22: =SUM(V5:V21) -> 436600 | W22: =IFERROR(V22/U22,0) -> 1490.1024 | X22: =SUM(X5:X21) -> 81 | Y22: =SUM(Y5:Y21) -> 183600 | Z22: =IFERROR(Y22/X22,0) -> 2266.6667 | AA22: =SUM(AA5:AA21) -> 52 | AB22: =SUM(AB5:AB21) -> 117000 | AC22: =IFERROR(AB22/AA22,0) -> 2250 | AD22: =SUM(AD5:AD21) -> 189 | AE22: =SUM(AE5:AE21) -> 729000 | AF22: =IFERROR(AE22/AD22,0) -> 3857.1429 | AG22: =SUM(AG5:AG21) -> 347 | AH22: =SUM(AH5:AH21) -> 609400 | AI22: =IFERROR(AH22/AG22,0) -> 1756.196 | AJ22: =SUM(AJ5:AJ21) -> 54 | AK22: =SUM(AK5:AK21) -> 108000 | AL22: =IFERROR(AK22/AJ22,0) -> 2000 | AM22: =SUM(AM5:AM21) -> 26 | AN22: =SUM(AN5:AN21) -> 36400 | AO22: =IFERROR(AN22/AM22,0) -> 1400 | AP22: =SUM(AP5:AP21) -> 426 | AQ22: =SUM(AQ5:AQ21) -> 737200 | AR22: =IFERROR(AQ22/AP22,0) -> 1730.5164 | AS22: =SUM(AS5:AS21) -> 616 | AT22: =SUM(AT5:AT21) -> 1482800 | AU22: =IFERROR(AT22/AS22,0) -> 2407.1429 | AV22: =SUM(AV5:AV21) -> 1126 | AW22: =SUM(AW5:AW21) -> 3304630 | AX22: =IFERROR(AW22/AV22,0) -> 2934.8401 | AY22: =SUM(AY5:AY21) -> 2168 | AZ22: =SUM(AZ5:AZ21) -> 5524630 | BA22: =IFERROR(AZ22/AY22,0) -> 2548.2611 | BB22: =SUM(BB5:BB21) -> 3638190 | BC22: =SUM(BC5:BC21) -> 384748 | BD22: =H22 -> 65523.78 | BE22: =I22 -> 148348.08 | BF22: =J22 -> 124026.69 | BG22: =SUM(BG5:BG21) -> 1287820.1 | BH22: =IFERROR(BG22/AZ22,0) -> 0.23310523 | BI22: =SUM(BI5:BI21) -> 542.8072 | BJ22: =SUM(BJ5:BJ21) -> 1678077.9 | BK22: =SUM(BK5:BK21) -> 678515.96 | BL22: =IFERROR(BK22/BJ22,0) -> 0.40434116

Sheet TD
A3: Etiquetas de fila | B3: Suma de TM en Stock | C3: Suma de Costo Ventas | D3: Suma de Gasto Ventas | E3: Suma de Gasto ADM | F3: Suma de Gasto Fin | G3: Suma de Depreciación
A4: 10005721 | B4: 396.6 | C4: 690084 | D4: 72181.2 | E4: 14485.365 | F4: 32795.362 | G4: 27418.624
A5: 10005779 | B5: 158.72 | C5: 295219.2 | D5: 28887.04 | E5: 5797.0681 | F5: 13124.76 | G5: 10972.98
A6: 10005781 | B6: 5.48 | C6: 10192.8 | D6: 997.36 | E6: 200.15079 | F6: 453.14822 | G6: 378.85542
A7: 10006720 | B7: 247.26 | C7: 405506.4 | D7: 45001.32 | E7: 9030.8912 | F7: 20446.246 | G7: 17094.122
A8: 10006722 | B8: 0.12 | C8: 224.4 | D8: 21.84 | E8: 4.382864 | F8: 9.9229537 | G8: 8.296104
A9: 10007050 | B9: 70.744 | C9: 92674.64 | D9: 12875.408 | E9: 2583.8444 | F9: 5849.912 | G9: 4890.8298
A10: 10007162 | B10: 371.8 | C10: 639496 | D10: 67667.6 | E10: 13579.574 | F10: 30744.618 | G10: 25704.096
A11: 10007567 | B11: 88.76 | C11: 150892 | D11: 16154.32 | E11: 3241.8584 | F11: 7339.6781 | G11: 6136.3516
A12: 10007969 | B12: 50.9 | C12: 71260 | D12: 9263.8 | E12: 1859.0648 | F12: 4208.9862 | G12: 3518.9308
A13: 10009178 | B13: 61.86 | C13: 107017.8 | D13: 11258.52 | E13: 2259.3664 | F13: 5115.2826 | G13: 4276.6416
A14: 10009207 | B14: 32.44 | C14: 0 | D14: 5904.08 | E14: 1184.8342 | F14: 2682.5052 | G14: 2242.7134
A15: 10009224 | B15: 0 | C15: 0 | D15: 0 | E15: 0 | F15: 0 | G15: 0
... A19: 10009639 | B19: 4.7 | C19: 8225 | D19: 855.4 | E19: 171.66217 | F19: 388.64902 | G19: 324.93074
A20: (en blanco) | B20: 0 | C20: 0 | D20: 0 | E20: 0 | F20: 0 | G20: 0
A21: Total general | B21: 1793.999 | C21: 2997838.4 | D21: 326507.82 | E21: 65523.78 | F21: 148348.08 | G21: 124026.69

Sheet Abril2026
A1: ID | B1: CODIGO | C1: MATERIAL | D1: FECHAS DIAS RECEPCION PRODUCCION ENERO 2026 | N1: MOVIMIENTO INVENTARIO | S1: DATA | T1: DIFERENCIA | AW1: 46119 | AZ1: 46122 | BC1: 46125 | BF1: 46129 | BI1: 46132 | BL1: 46136 | BO1: 46139
B2: SAP | D2: STOCK INICIO | E2: 46118 | F2: 46119 | G2: 46120 | H2: 46121 | I2: 46122 | J2: 46123 | N2: Stock Inicial | O2: INGRESOS | P2: SALIDAS | Q2: STOCK KG | S2: MANUAL | U2: REPROCESO | V2: MUESTREO | W2: EMBARQUE | Y2: STOCK KG | AD2: CÓDIGO | AE2: MATCH | AF2: CPU | AG2: TM en Stock | AH2: Costo Ventas | AI2: Gasto Ventas | AJ2: Gasto ADM | AK2: Gasto Fin | AL2: Depreciación | AM2: Utilidad Neta | AN2: Margen Neto | AO2: Venta Equilibrio | AP2: Precio Equilibrio x TM | AR2: Precio Abril x TM | AS2: Venta Abril | AT2: Utilidad Neta | AU2: Margen Neto | AW2: TM | AX2: Venta | AY2: Precio x TM | AZ2: TM | BA2: Venta | BB2: Precio x TM | BC2: TM | BD2: Venta | BE2: Precio x TM | BF2: TM | BG2: Venta | BH2: Precio x TM | BI2: TM | BJ2: Venta | BK2: Precio x TM | BL2: TM | BM2: Venta | BN2: Precio x TM | BO2: TM | BP2: Venta | BQ2: Precio x TM
A3: 1 | B3: 10006668 | C3: POTA ALAS FR C/P C/C < 0.5 BL10 S20 | D3: 620 | E3: 1780 | F3: =280+120 -> 400 | G3: =2640+180 -> 2820 | H3: =1680+0 -> 1680 | I3: =2860+1900 -> 4760 | J3: 1620 | N3: =+D3 -> 620 | O3: =SUM(E3:L3) -> 13060 | Q3: =+N3+O3-P3 -> 13680 | R3: =+N3-Q3 -> -13060 | T3: =+Q3-S3 -> 13680 | Y3: =SUM(U3:W3) -> 0 | Z3: =+Y3-P3 -> 0 | AD3: 10009178 | AE3: ="FEBRERO"&AD3&"Inventario final" -> FEBRERO10009178Inventario final | AF3: =INDEX('[1]Detalle Costos'!$L$5:$L$158,MATCH(AE3,'[1]Detalle Costos'!$C$5:$C$158,0)) -> 1.73 | AG3: =IF(ISERROR(AF3),0,Q3/1000) -> 13.68 | AH3: =IFERROR(AF3*AG3,0)*1000 -> 23666.4 | AI3: =182*AG3 -> 2489.76 | AJ3: =$AJ$59/$AG$59*AG3 -> 499.64649 | AK3: =$AK$59/$AG$59*AG3 -> 1131.2167 | AL3: =$AL$59/$AG$59*AG3 -> 945.75586 | AM3: 0 | AN3: =$BC$50 -> 0 | AO3: =AH3+AI3+AJ3+AK3 -> 27787.023 | AP3: =IFERROR(AO3/AG3,0) -> 2031.2151 | AR3: 2150 | AS3: =AR3*AG3 -> 29412 | AT3: =AS3-AO3 -> 1624.9768 | AU3: =IFERROR(AT3/AS3,0) -> 0.055248769
A4: =+A3+1 -> 2 | B4: 10009178 | C4: POTA ALAS FR C/P C/C (B) S/COD BL10 S20 | D4: 29100 | E4: 400 | F4: 80 | G4: 240 | H4: =100+0 -> 100 | I4: =220+200 -> 420 | J4: 400 | N4: =+D4 -> 29100 | O4: =SUM(E4:L4) -> 1640 | Q4: =+N4+O4-P4 -> 30740 | T4: =+Q4-S4 -> 30740 | Y4: =SUM(U4:W4) -> 0 | Z4: =+Y4-P4 -> 0 | AD4: 10009178 | AE4: ="FEBRERO"&AD4&"Inventario final" -> FEBRERO10009178Inventario final | AF4: =INDEX('[1]Detalle Costos'!$L$5:$L$158,MATCH(AE4,'[1]Detalle Costos'!$C$5:$C$158,0)) -> 1.73 | AG4: =IF(ISERROR(AF4),0,Q4/1000) -> 30.74 | AH4: =IFERROR(AF4*AG4,0)*1000 -> 53180.2 | AI4: =182*AG4 -> 5594.68 | AJ4: =$AJ$59/$AG$59*AG4 -> 1122.7437 | AK4: =$AK$59/$AG$59*AG4 -> 2541.93 | AL4: =$AL$59/$AG$59*AG4 -> 2125.1853 | AM4: 0 | AN4: =$BC$50 -> 0 | AO4: =AH4+AI4+AJ4+AK4 -> 62439.554 | AP4: =IFERROR(AO4/AG4,0) -> 2031.2151 | AR4: 2150 | AS4: =AR4*AG4 -> 66091 | AT4: =AS4-AO4 -> 3651.4464 | AU4: =IFERROR(AT4/AS4,0) -> 0.055248769
A5: =+A4+1 -> 3 | B5: 10006719 | C5: POTA ALAS FR C/P C/C 0.5-1 BL10 S20 | D5: 680 | E5: 1540 | F5: =60+400 -> 460 | G5: =1940+180 -> 2120 | H5: =2820+0 -> 2820 | I5: =3880+2760 -> 6640 | J5: 2500 | N5: =+D5 -> 680 | O5: =SUM(E5:L5) -> 16080 | Q5: =+N5+O5-P5 -> 16760 | T5: =+Q5-S5 -> 16760 | Y5: =SUM(U5:W5) -> 0 | Z5: =+Y5-P5 -> 0 | AD5: 10009178 | AE5: ="FEBRERO"&AD5&"Inventario final" -> FEBRERO10009178Inventario final | AF5: =INDEX('[1]Detalle Costos'!$L$5:$L$158,MATCH(AE5,'[1]Detalle Costos'!$C$5:$C$158,0)) -> 1.73 | AG5: =IF(ISERROR(AF5),0,Q5/1000) -> 16.76 | AH5: =IFERROR(AF5*AG5,0)*1000 -> 28994.8 | AI5: =182*AG5 -> 3050.32 | AJ5: =$AJ$59/$AG$59*AG5 -> 612.14 | AK5: =$AK$59/$AG$59*AG5 -> 1385.9059 | AL5: =$AL$59/$AG$59*AG5 -> 1158.6892 | AM5: 0 | AN5: =$BC$50 -> 0 | AO5: =AH5+AI5+AJ5+AK5 -> 34043.166 | AP5: =IFERROR(AO5/AG5,0) -> 2031.2151 | AR5: 2150 | AS5: =AR5*AG5 -> 36034 | AT5: =AS5-AO5 -> 1990.8341 | AU5: =IFERROR(AT5/AS5,0) -> 0.055248769
A6: =+A5+1 -> 4 | B6: 10009265 | C6: POTA ALAS FR C/P C/C 0.3 - 0.5 BL10 S20 | D6: 680 | N6: =+D6 -> 680 | O6: =SUM(E6:L6) -> 0 | Q6: =+N6+O6-P6 -> 680 | T6: =+Q6-S6 -> 680 | Y6: =SUM(U6:W6) -> 0 | Z6: =+Y6-P6 -> 0 | AD6: 10009178 | AE6: ="FEBRERO"&AD6&"Inventario final" -> FEBRERO10009178Inventario final | AF6: =INDEX('[1]Detalle Costos'!$L$5:$L$158,MATCH(AE6,'[1]Detalle Costos'!$C$5:$C$158,0)) -> 1.73 | AG6: =IF(ISERROR(AF6),0,Q6/1000) -> 0.68 | AH6: =IFERROR(AF6*AG6,0)*1000 -> 1176.4 | AI6: =182*AG6 -> 123.76 | AJ6: =$AJ$59/$AG$59*AG6 -> 24.836229 | AK6: =$AK$59/$AG$59*AG6 -> 56.230071 | AL6: =$AL$59/$AG$59*AG6 -> 47.011256 | AM6: 0 | AN6: =$BC$50 -> 0 | AO6: =AH6+AI6+AJ6+AK6 -> 1381.2263 | AP6: =IFERROR(AO6/AG6,0) -> 2031.2151 | AR6: 2150 | AS6: =AR6*AG6 -> 1462 | AT6: =AS6-AO6 -> 80.7737 | AU6: =IFERROR(AT6/AS6,0) -> 0.055248769
A7: =+A6+1 -> 5 | B7: 10006720 | C7: POTA ALAS FR C/P C/C 1-2 BL10 S20 | D7: 274200 | E7: 60 | N7: =+D7 -> 274200 | O7: =SUM(E7:L7) -> 60 | P7: 27000 | Q7: =+N7+O7-P7 -> 247260 | T7: =+Q7-S7 -> 247260 | Y7: =SUM(U7:W7) -> 0 | Z7: =+Y7-P7 -> -27000 | AD7: 10006720 | AE7: ="FEBRERO"&AD7&"Inventario final" -> FEBRERO10006720Inventario final | AF7: =INDEX('[1]Detalle Costos'!$L$5:$L$158,MATCH(AE7,'[1]Detalle Costos'!$C$5:$C$158,0)) -> 1.64 | AG7: =IF(ISERROR(AF7),0,Q7/1000) -> 247.26 | AH7: =IFERROR(AF7*AG7,0)*1000 -> 405506.4 | AI7: =182*AG7 -> 45001.32 | AJ7: =$AJ$59/$AG$59*AG7 -> 9030.8912 | AK7: =$AK$59/$AG$59*AG7 -> 20446.246 | AL7: =$AL$59/$AG$59*AG7 -> 17094.122 | AM7: 0 | AN7: =$BC$50 -> 0 | AO7: =AH7+AI7+AJ7+AK7 -> 479984.86 | AP7: =IFERROR(AO7/AG7,0) -> 1941.2151 | AR7: 2150 | AS7: =AR7*AG7 -> 531609 | AT7: =AS7-AO7 -> 51624.143 | AU7: =IFERROR(AT7/AS7,0) -> 0.097109234
A8: =+A7+1 -> 6 | B8: 10006722 | C8: POTA ALAS FR C/P C/C 2-UP BL10 S20 | D8: 120 | N8: =+D8 -> 120 | O8: =SUM(E8:L8) -> 0 | Q8: =+N8+O8-P8 -> 120 | T8: =+Q8-S8 -> 120 | Y8: =SUM(U8:W8) -> 0 | Z8: =+Y8-P8 -> 0 | AD8: 10006722 | AE8: ="FEBRERO"&AD8&"Inventario final" -> FEBRERO10006722Inventario final | AF8: =INDEX('[1]Detalle Costos'!$L$5:$L$158,MATCH(AE8,'[1]Detalle Costos'!$C$5:$C$158,0)) -> 1.87 | AG8: =IF(ISERROR(AF8),0,Q8/1000) -> 0.12 | AH8: =IFERROR(AF8*AG8,0)*1000 -> 224.4 | AI8: =182*AG8 -> 21.84 | AJ8: =$AJ$59/$AG$59*AG8 -> 4.382864 | AK8: =$AK$59/$AG$59*AG8 -> 9.9229537 | AL8: =$AL$59/$AG$59*AG8 -> 8.296104 | AM8: 0 | AN8: =$BC$50 -> 0 | AO8: =AH8+AI8+AJ8+AK8 -> 260.54582 | AP8: =IFERROR(AO8/AG8,0) -> 2171.2151 | AR8: 2150 | AS8: =AR8*AG8 -> 258 | AT8: =AS8-AO8 -> -2.5458177 | AU8: =IFERROR(AT8/AS8,0) -> -0.0098675105
A9: =+A8+1 -> 7 | B9: 10009331 | C9: POTA ALAS PRE COC 3-UP BL9 S18 | D9: 15138 | F9: =4086+3078 -> 7164 | G9: =2088+2376 -> 4464 | H9: 2916 | I9: 3124 | J9: 3114 | N9: =+D9 -> 15138 | O9: =SUM(E9:L9) -> 20782 | Q9: =+N9+O9-P9 -> 35920 | T9: =+Q9-S9 -> 35920 | Y9: =SUM(U9:W9) -> 0 | Z9: =+Y9-P9 -> 0 | AD9: 10007050 | AE9: ="FEBRERO"&AD9&"Inventario final" -> FEBRERO10007050Inventario final | AF9: =INDEX('[1]Detalle Costos'!$L$5:$L$158,MATCH(AE9,'[1]Detalle Costos'!$C$5:$C$158,0)) -> 1.31 | AG9: =IF(ISERROR(AF9),0,Q9/1000) -> 35.92 | AH9: =IFERROR(AF9*AG9,0)*1000 -> 47055.2 | AI9: =182*AG9 -> 6537.44 | AJ9: =$AJ$59/$AG$59*AG9 -> 1311.9373 | AK9: =$AK$59/$AG$59*AG9 -> 2970.2708 | AL9: =$AL$59/$AG$59*AG9 -> 2483.3005 | AM9: 0 | AN9: =$BC$50 -> 0 | AO9: =AH9+AI9+AJ9+AK9 -> 57874.848 | AP9: =IFERROR(AO9/AG9,0) -> 1611.2151 | AR9: 3950 | AS9: =AR9*AG9 -> 141884 | AT9: =AS9-AO9 -> 84009.152 | AU9: =IFERROR(AT9/AS9,0) -> 0.59209743
A10: =+A9+1 -> 8 | C10: POTA ALAS PRE COC 3-UP BL10 S20 | D10: 0 | N10: =+D10 -> 0 | O10: =SUM(E10:L10) -> 0 | Q10: =+N10+O10-P10 -> 0 | T10: =+Q10-S10 -> 0 | Y10: =SUM(U10:W10) -> 0 | Z10: =+Y10-P10 -> 0 | AD10: 10007050 | AE10: ="FEBRERO"&AD10&"Inventario final" -> FEBRERO10007050Inventario final | AF10: =INDEX('[1]Detalle Costos'!$L$5:$L$158,MATCH(AE10,'[1]Detalle Costos'!$C$5:$C$158,0)) -> 1.31 | AG10: =IF(ISERROR(AF10),0,Q10/1000) -> 0 | AH10: =IFERROR(AF10*AG10,0)*1000 -> 0 | AI10: =182*AG10 -> 0 | AJ10: =$AJ$59/$AG$59*AG10 -> 0 | AK10: =$AK$59/$AG$59*AG10 -> 0 | AL10: =$AL$59/$AG$59*AG10 -> 0 | AM10: 0 | AN10: =$BC$50 -> 0 | AO10: =AH10+AI10+AJ10+AK10 -> 0 | AP10: =IFERROR(AO10/AG10,0) -> 0 | AS10: =AR10*AG10 -> 0 | AT10: =AS10-AO10 -> 0 | AU10: =IFERROR(AT10/AS10,0) -> 0
A11: =+A10+1 -> 9 | B11: 10009334 | C11: POTA ALAS PRE COC B BL9 S18 | D11: 5472 | F11: =324+342 -> 666 | G11: =540+36 -> 576 | H11: 216 | J11: 234 | N11: =+D11 -> 5472 | O11: =SUM(E11:L11) -> 1692 | Q11: =+N11+O11-P11 -> 7164 | T11: =+Q11-S11 -> 7164 | Y11: =SUM(U11:W11) -> 0 | Z11: =+Y11-P11 -> 0 | AD11: 10007050 | AE11: ="FEBRERO"&AD11&"Inventario final" -> FEBRERO10007050Inventario final | AF11: =INDEX('[1]Detalle Costos'!$L$5:$L$158,MATCH(AE11,'[1]Detalle Costos'!$C$5:$C$158,0)) -> 1.31 | AG11: =IF(ISERROR(AF11),0,Q11/1000) -> 7.164 | AH11: =IFERROR(AF11*AG11,0)*1000 -> 9384.84 | AI11: =182*AG11 -> 1303.848 | AJ11: =$AJ$59/$AG$59*AG11 -> 261.65698 | AK11: =$AK$59/$AG$59*AG11 -> 592.40034 | AL11: =$AL$59/$AG$59*AG11 -> 495.27741 | AM11: 0 | AN11: =$BC$50 -> 0 | AO11: =AH11+AI11+AJ11+AK11 -> 11542.745 | AP11: =IFERROR(AO11/AG11,0) -> 1611.2151 | AR11: 3950 | AS11: =AR11*AG11 -> 28297.8 | AT11: =AS11-AO11 -> 16755.055 | AU11: =IFERROR(AT11/AS11,0) -> 0.59209743
A12: =+A11+1 -> 10 | B12: 10009207 | C12: POTA LABIOS FR S/COD BL10 S20 | D12: 30840 | E12: 320 | F12: 0 | G12: =260+140 -> 400 | H12: 280 | I12: =160+360 -> 520 | J12: 80 | N12: =+D12 -> 30840 | O12: =SUM(E12:L12) -> 1600 | Q12: =+N12+O12-P12 -> 32440 | T12: =+Q12-S12 -> 32440 | Y12: =SUM(U12:W12) -> 0 | Z12: =+Y12-P12 -> 0 | AD12: 10009207 | AE12: ="FEBRERO"&AD12&"Inventario final" -> FEBRERO10009207Inventario final | AF12: 0 | AG12: =IF(ISERROR(AF12),0,Q12/1000) -> 32.44 | AH12: =IFERROR(AF12*AG12,0)*1000 -> 0 | AI12: =182*AG12 -> 5904.08 | AJ12: =$AJ$59/$AG$59*AG12 -> 1184.8342 | AK12: =$AK$59/$AG$59*AG12 -> 2682.5052 | AL12: =$AL$59/$AG$59*AG12 -> 2242.7134 | AM12: 0 | AN12: =$BC$50 -> 0 | AO12: =AH12+AI12+AJ12+AK12 -> 9771.4194 | AP12: =IFERROR(AO12/AG12,0) -> 301.21515 | AR12: 1000 | AS12: =AR12*AG12 -> 32440 | AT12: =AS12-AO12 -> 22668.581 | AU12: =IFERROR(AT12/AS12,0) -> 0.69878485
A13: =+A12+1 -> 11 | B13: 10007969 | C13: POTA CONOS | D13: 48300 | E13: 640 | F13: 280 | G13: =340+300 -> 640 | H13: 340 | I13: 700 | N13: =+D13 -> 48300 | O13: =SUM(E13:L13) -> 2600 | Q13: =+N13+O13-P13 -> 50900 | T13: =+Q13-S13 -> 50900 | Y13: =SUM(U13:W13) -> 0 | Z13: =+Y13-P13 -> 0 | AD13: 10007969 | AE13: ="FEBRERO"&AD13&"Inventario final" -> FEBRERO10007969Inventario final | AF13: =INDEX('[1]Detalle Costos'!$L$5:$L$158,MATCH(AE13,'[1]Detalle Costos'!$C$5:$C$158,0)) -> 1.4 | AG13: =IF(ISERROR(AF13),0,Q13/1000) -> 50.9 | AH13: =IFERROR(AF13*AG13,0)*1000 -> 71260 | AI13: =182*AG13 -> 9263.8 | AJ13: =$AJ$59/$AG$59*AG13 -> 1859.0648 | AK13: =$AK$59/$AG$59*AG13 -> 4208.9862 | AL13: =$AL$59/$AG$59*AG13 -> 3518.9308 | AM13: 0 | AN13: =$BC$50 -> 0 | AO13: =AH13+AI13+AJ13+AK13 -> 86591.851 | AP13: =IFERROR(AO13/AG13,0) -> 1701.2151 | AR13: 1800 | AS13: =AR13*AG13 -> 91620 | AT13: =AS13-AO13 -> 5028.149 | AU13: =IFERROR(AT13/AS13,0) -> 0.054880474
A14: =+A13+1 -> 12 | B14: 10004433 | C14: POTA FILETE C/M C/T FR 0.5-1 BL10 S20 | D14: 300 | F14: =40+160 -> 200 | I14: 60 | N14: =+D14 -> 300 | O14: =SUM(E14:L14) -> 260 | Q14: =+N14+O14-P14 -> 560 | T14: =+Q14-S14 -> 560 | Y14: =SUM(U14:W14) -> 0 | Z14: =+Y14-P14 -> 0 | AD14: 10005721 | AE14: ="FEBRERO"&AD14&"Inventario final" -> FEBRERO10005721Inventario final | AF14: =INDEX('[1]Detalle Costos'!$L$5:$L$158,MATCH(AE14,'[1]Detalle Costos'!$C$5:$C$158,0)) -> 1.74 | AG14: =IF(ISERROR(AF14),0,Q14/1000) -> 0.56 | AH14: =IFERROR(AF14*AG14,0)*1000 -> 974.4 | AI14: =182*AG14 -> 101.92 | AJ14: =$AJ$59/$AG$59*AG14 -> 20.453365 | AK14: =$AK$59/$AG$59*AG14 -> 46.307117 | AL14: =$AL$59/$AG$59*AG14 -> 38.715152 | AM14: 0 | AN14: =$BC$50 -> 0 | AO14: =AH14+AI14+AJ14+AK14 -> 1143.0805 | AP14: =IFERROR(AO14/AG14,0) -> 2041.2151 | AR14: 2100 | AS14: =AR14*AG14 -> 1176 | AT14: =AS14-AO14 -> 32.919517 | AU14: =IFERROR(AT14/AS14,0) -> 0.027992787
B15: 10005711 | C15: POTA FILETE C/M C/T FR 0.5-1AA BL10 S20 | D15: 0 | E15: 1100 | F15: =140+1180 -> 1320 | G15: =700+520 -> 1220 | H15: 1000 | I15: =260+1840 -> 2100 | J15: 1140 | N15: =+D15 -> 0 | O15: =SUM(E15:L15) -> 7880 | Q15: =+N15+O15-P15 -> 7880 | T15: =+Q15-S15 -> 7880 | AD15: 10005721 | AE15: ="FEBRERO"&AD15&"Inventario final" -> FEBRERO10005721Inventario final | AF15: =INDEX('[1]Detalle Costos'!$L$5:$L$158,MATCH(AE15,'[1]Detalle Costos'!$C$5:$C$158,0)) -> 1.74 | AG15: =IF(ISERROR(AF15),0,Q15/1000) -> 7.88 | AH15: =IFERROR(AF15*AG15,0)*1000 -> 13711.2 | AI15: =182*AG15 -> 1434.16 | AJ15: =$AJ$59/$AG$59*AG15 -> 287.80807 | AK15: =$AK$59/$AG$59*AG15 -> 651.60729 | AL15: =$AL$59/$AG$59*AG15 -> 544.7775 | AM15: 0 | AN15: =$BC$50 -> 0 | AO15: =AH15+AI15+AJ15+AK15 -> 16084.775 | AP15: =IFERROR(AO15/AG15,0) -> 2041.2151 | AR15: 2100 | AS15: =AR15*AG15 -> 16548 | AT15: =AS15-AO15 -> 463.22464 | AU15: =IFERROR(AT15/AS15,0) -> 0.027992787
A16: =+A14+1 -> 13 | B16: 10004434 | C16: POTA FILETE C/M C/T FR 1-2 BL10 S20 | D16: 1120 | F16: =280+840 -> 1120 | G16: 280 | I16: 1720 | N16: =+D16 -> 1120 | O16: =SUM(E16:L16) -> 3120 | Q16: =+N16+O16-P16 -> 4240 | T16: =+Q16-S16 -> 4240 | Y16: =SUM(U16:W16) -> 0 | Z16: =+Y16-P16 -> 0 | AD16: 10005721 | AE16: ="FEBRERO"&AD16&"Inventario final" -> FEBRERO10005721Inventario final | AF16: =INDEX('[1]Detalle Costos'!$L$5:$L$158,MATCH(AE16,'[1]Detalle Costos'!$C$5:$C$158,0)) -> 1.74 | AG16: =IF(ISERROR(AF16),0,Q16/1000) -> 4.24 | AH16: =IFERROR(AF16*AG16,0)*1000 -> 7377.6 | AI16: =182*AG16 -> 771.68 | AJ16: =$AJ$59/$AG$59*AG16 -> 154.86119 | AK16: =$AK$59/$AG$59*AG16 -> 350.61103 | AL16: =$AL$59/$AG$59*AG16 -> 293.12901 | AM16: 0 | AN16: =$BC$50 -> 0 | AO16: =AH16+AI16+AJ16+AK16 -> 8654.7522 | AP16: =IFERROR(AO16/AG16,0) -> 2041.2151 | AR16: 2100 | AS16: =AR16*AG16 -> 8904 | AT16: =AS16-AO16 -> 249.24777 | AU16: =IFERROR(AT16/AS16,0) -> 0.027992787
A17: =+A16+1 -> 14 | B17: 10005721 | C17: POTA FILETE C/M C/T FR 2-4 AA BL10 S20 | D17: 486640 | E17: =4760+7800 -> 12560 | F17: =4320+6300 -> 10620 | G17: =1920+2900 -> 4820 | H17: =1280+6180 -> 7460 | I17: =1160+11780 -> 12940 | J17: 1460 | N17: =+D17 -> 486640 | O17: =SUM(E17:L17) -> 49860 | P17: =125000+120000+26000 -> 271000 | Q17: =+N17+O17-P17 -> 265500 | T17: =+Q17-S17 -> 265500 | W17: 125000 | Y17: =SUM(U17:W17) -> 125000 | Z17: =+Y17-P17 -> -146000 | AD17: 10005721 | AE17: ="FEBRERO"&AD17&"Inventario final" -> FEBRERO10005721Inventario final | AF17: =INDEX('[1]Detalle Costos'!$L$5:$L$158,MATCH(AE17,'[1]Detalle Costos'!$C$5:$C$158,0)) -> 1.74 | AG17: =IF(ISERROR(AF17),0,Q17/1000) -> 265.5 | AH17: =IFERROR(AF17*AG17,0)*1000 -> 461970 | AI17: =182*AG17 -> 48321 | AJ17: =$AJ$59/$AG$59*AG17 -> 9697.0865 | AK17: =$AK$59/$AG$59*AG17 -> 21954.535 | AL17: =$AL$59/$AG$59*AG17 -> 18355.13 | AM17: 0 | AN17: =$BC$50 -> 0 | AO17: =AH17+AI17+AJ17+AK17 -> 541942.62 | AP17: =IFERROR(AO17/AG17,0) -> 2041.2151 | AR17: 2100 | AS17: =AR17*AG17 -> 557550 | AT17: =AS17-AO17 -> 15607.378 | AU17: =IFERROR(AT17/AS17,0) -> 0.027992787
