Workbook

Sheet Gráficos ppt
S3: ='Tablas ppt'!S46-'Tablas ppt'!S44 -> -0.27
B5: 1. RESULTADOS INTERNOS
B63: 2. BENCHMARK INDUSTRIA PERUANA DE CONGELADOS (VERITRADE)
B88: Top 15 Exportadores — Productos Congelados (Alas, Filete, Nuca, Tentáculo, Reproductor)
B90: Nro | C90: Exportador | D90: Valor FOB (US$) | E90: TM | F90: Precio por TM
B91: 1 | C91: Industrial Pesquera Santa Monica S.A. | D91: 12800672 | E91: 7371.2 | F91: 1737
B92: 2 | C92: Pesquera Hermanos Cordova S.A.C. | D92: 11792528 | E92: 7242.6 | F92: 1628
B93: 3 | C93: Oceano Seafood S.A. | D93: 11724680 | E93: 6746.5 | F93: 1738
B94: 4 | C94: Productora Andina De Congelados S.R.L. | D94: 8847640 | E94: 5227.2 | F94: 1693
B95: 5 | C95: Costa Mira Sociedad Anonima Cerrada | D95: 8496998 | E95: 4421.2 | F95: 1922
B96: 6 | C96: Novaperu S.A.C. | D96: 6857126 | E96: 3973.8 | F96: 1726
B97: 7 | C97: Peru Frost Sociedad Anonima Cerrada | D97: 6231879 | E97: 3981.4 | F97: 1565
B98: 8 | C98: Esmeralda Corp S.A.C. | D98: 6229395 | E98: 3736 | F98: 1667
B99: 9 | C99: Proveedora De Productos Marinos Sociedad | D99: 6166547 | E99: 3730.3 | F99: 1653
B100: 10 | C100: Peruvian Sea Food S.A. | D100: 6164559 | E100: 3692.9 | F100: 1669
B101: 11 | C101: Pesquera Supercetus S.A.C. | D101: 5928869 | E101: 3562.1 | F101: 1664
B102: 12 | C102: Transmarina Del Peru S.A.C. | D102: 5879029 | E102: 3591.3 | F102: 1637
... B105: 15 | C105: Seafrost S.A.C. | D105: 5556358 | E105: 3119.3 | F105: 1781
B107: Top 15 Exportadores — Productos Cocidos (Alas Cocidas, Filete Daruma)
B109: Nro | C109: Exportador | D109: Valor FOB (US$) | E109: TM | F109: Precio por TM
B110: 1 | C110: Costa Mira Sociedad Anonima Cerrada | D110: 9211788 | E110: 2579.8 | F110: 3571
B111: 2 | C111: KSL S.A.C. | D111: 5319083 | E111: 1670.5 | F111: 3184
B112: 3 | C112: Pacific Freezing Company S.A.C. | D112: 4286058 | E112: 1338 | F112: 3203
B113: 4 | C113: Oceano Seafood S.A. | D113: 4050574 | E113: 1190.4 | F113: 3403
B114: 5 | C114: Frigosa Sociedad S.A.C. | D114: 3921103 | E114: 1215 | F114: 3227
B115: 6 | C115: Dexim Srl | D115: 3883786 | E115: 1076.8 | F115: 3607
B116: 7 | C116: Inversiones Holding Peru Sociedad Anonim | D116: 2905633 | E116: 847.7 | F116: 3428
B117: 8 | C117: Corporacion Pesquera Del Mar Sociedad An | D117: 2751416 | E117: 796 | F117: 3457
B118: 9 | C118: Mik Carpe S.A.C. | D118: 2475284 | E118: 735 | F118: 3368
B119: 10 | C119: Seafrost S.A.C. | D119: 2135285 | E119: 602.9 | F119: 3542
B120: 11 | C120: Pesquera Exalmar S.A.A. | D120: 1926814 | E120: 563.2 | F120: 3421
B121: 12 | C121: Refrigerados Fisholg & Hijos Sociedad An | D121: 1802223 | E121: 539.5 | F121: 3340
... B124: 15 | C124: Industrial Pesquera Santa Monica S.A. | D124: 1603048 | E124: 475.7 | F124: 3370

Sheet Tablas ppt
B5: PERU FROST - CONGELADOS 2026 (MILES US$)
B6: Concepto | C6: 46023 | D6: 46054 | E6: 46082 | F6: 46113 | G6: Acum 2026 | H6: Presupuesto | I6: Variación | M6: cambiar a nombre a presupuesto
B7: TM Materia Prima | C7: =[1]Resumen!$D$4 -> 1877.215 | D7: =[1]Resumen!$D$5 -> 3149.786 | E7: =[1]Resumen!$D$6 -> 2255.518 | F7: =[1]Resumen!$D$7 -> 2853.189 | G7: =SUM(C7:F7) -> 10135.708 | H7: 8550 | I7: =G7-H7 -> 1585.708 | M7: el presupuesto incluye todo de muelle y demas, añadirlos
B8: TM Vendidas PT | C8: =TD!B7 -> 248 | D8: =TD!C7 -> 1634.3 | E8: =TD!D7 -> 1995.8 | F8: =TD!E7 -> 2110.11 | G8: =TD!F7 -> 5988.21 | H8: =TD!G7 -> 5834 | I8: =G8-H8 -> 154.21 | M8: separar cuanto es congelados y muelle
B9: Venta | C9: =TD!B8/1000 -> 564.61528 | D9: =TD!C8/1000 -> 2769.8245 | E9: =TD!D8/1000 -> 3896.4183 | F9: =TD!E8/1000 -> 4888.92 | G9: =TD!F8/1000 -> 12119.778 | H9: =O36/1000 -> 15333.647 | I9: =G9-H9 -> -3213.8689 | M9: añadir fecha de corte
B10: Utilidad Neta | C10: =TD!B16/1000 -> -99.037985 | D10: =TD!C16/1000 -> -488.40746 | E10: =TD!D16/1000 -> -201.20764 | F10: =TD!E16/1000 -> 89.7471 | G10: =TD!F16/1000 -> -698.90598 | H10: =O44/1000 -> 572.67244 | I10: =G10-H10 -> -1271.5784 | M10: colocar en power point
B11: Margen Neto % | C11: =C10/C9 -> -0.17540791 | D11: =D10/D9 -> -0.17633155 | E11: =E10/E9 -> -0.051639126 | F11: =F10/F9 -> 0.018357244 | G11: =G10/G9 -> -0.057666566 | H11: =H10/H9 -> 0.037347439 | I11: =G11-H11 -> -0.095014004
B13: PERU FROST - MERLUZA Y PERICO 2026 (MILES US$)
B14: Concepto | C14: 46023 | D14: 46054 | E14: 46082 | F14: 46113 | G14: Acum 2026 | H14: Presupuesto | I14: Variación
B15: TM Materia Prima | H15: 300 | I15: =G15-H15 -> -300
B16: TM Vendidas PT | C16: 0 | D16: 0 | E16: 0 | F16: 0 | G16: 0 | H16: 129 | I16: =G16-H16 -> -129
B17: Venta | C17: 0 | D17: 0 | E17: 0 | F17: 0 | G17: =SUM(C17:F17) -> 0 | H17: =P36/1000 -> 278.3254 | I17: =G17-H17 -> -278.3254
B18: Utilidad Neta | C18: =-7871.79/1000 -> -7.87179 | D18: -13.224 | E18: =-10009.96/1000 -> -10.00996 | F18: -10 | G18: =SUM(C18:F18) -> -41.10575 | H18: =P44/1000 -> 59.37017 | I18: =G18-H18 -> -100.47592 | L18: Merluza
B19: Margen Neto % | H19: =H18/H17 -> 0.21331208 | I19: =G19-H19 -> -0.21331208 | L19: Presupuesto
K20: Venta | L20: 278325.4
B21: PERU FROST - SERVIOS DE CONGELAMIENTO 2026 (MILES US$)
B22: Concepto | C22: 46023 | D22: 46054 | E22: 46082 | F22: 46113 | G22: Acum 2026 | H22: Presupuesto | I22: Variación
B23: Venta | C23: 0 | D23: 0 | E23: 0 | F23: 0 | G23: =SUM(C23:F23) -> 0 | H23: =Q36/1000 -> 333.33333 | I23: =G23-H23 -> -333.33333
B24: Utilidad Neta | C24: 0 | D24: 0 | E24: 0 | F24: 0 | G24: =SUM(C24:F24) -> 0 | H24: =Q44/1000 -> 333.33333 | I24: =G24-H24 -> -333.33333
B25: Margen Neto % | H25: =H24/H23 -> 1 | I25: =G25-H25 -> -1
B27: PERU FROST - MUELLE 2026 (MILES US$)
B28: Concepto | C28: 46023 | D28: 46054 | E28: 46082 | F28: 46113 | G28: Acum 2026 | H28: Presupuesto | I28: Variación
B29: Venta | C29: =45444/3.35/1000 -> 13.565373 | D29: =57239.28/3.4/1000 -> 16.835082 | E29: =54636.38/3.45/1000 -> 15.836632 | F29: =216375.28/3.5/1000 -> 61.821509 | G29: =SUM(C29:F29) -> 108.0586 | H29: =R36/1000 -> 290.90909 | I29: =G29-H29 -> -182.85049
B30: Utilidad Neta | C30: =C29-41.889 -> -28.323627 | D30: =D29-34.4 -> -17.564918 | E30: =E29-53.1 -> -37.263368 | F30: =F29-43 -> 18.821509 | G30: =SUM(C30:F30) -> -64.330404 | H30: =R44/1000 -> 172.42886 | I30: =G30-H30 -> -236.75926
B31: Margen Neto % | H31: =H30/H29 -> 0.59272421 | I31: =G31-H31 -> -0.59272421
B33: PERU FROST - CONSOLIDADO 2026 (MILES US$)
B34: Concepto | C34: 46023 | D34: 46054 | E34: 46082 | F34: 46113 | G34: Acum 2026 | H34: Presupuesto | I34: Variación
B35: TM Materia Prima | C35: =C15+C7 -> 1877.215 | D35: =D15+D7 -> 3149.786 | E35: =E15+E7 -> 2255.518 | F35: =F15+F7 -> 2853.189 | G35: =SUM(C35:F35) -> 10135.708 | H35: =H15+H7 -> 8850 | I35: =G35-H35 -> 1285.708 | O35: Congelados Pota | P35: Merluza | Q35: SS | R35: Muelle | S35: Total
B36: TM Vendidas PT | C36: =C16+C8 -> 248 | D36: =D16+D8 -> 1634.3 | E36: =E16+E8 -> 1995.8 | F36: =F16+F8 -> 2110.11 | G36: =SUM(C36:F36) -> 5988.21 | H36: =H16+H8 -> 5963 | I36: =G36-H36 -> 25.21 | N36: Suma de VALOR CFR | O36: 15333647 | P36: =L20 -> 278325.4 | Q36: 333333.33 | R36: 290909.09 | S36: =SUM(O36:R36) -> 16236215
B37: Venta | C37: =C17+C9+C23+C29 -> 578.18065 | D37: =D17+D9+D23+D29 -> 2786.6596 | E37: =E17+E9+E23+E29 -> 3912.2549 | F37: =F17+F9+F23+F29 -> 4950.7415 | G37: =SUM(C37:F37) -> 12227.837 | H37: =H17+H9+H23+H29 -> 16236.215 | I37: =G37-H37 -> -4008.3781 | N37: Suma de COSTO VENTAS | O37: 12916735 | P37: =L38-4251 -> 194785.42 | Q37: 0 | R37: =L44 -> 118480.23 | S37: =SUM(O37:R37) -> 13230000
B38: Utilidad Neta | C38: =C18+C10+C30 -> -135.2334 | D38: =D18+D10+D30 -> -519.19638 | E38: =E18+E10+E30 -> -248.48096 | F38: =F18+F10+F30 -> 98.568608 | G38: =SUM(C38:F38) -> -804.34213 | H38: =H18+H10+H24+H30 -> 1137.8048 | I38: =G38-H38 -> -1942.1469 | K38: Costo | L38: 199036.42 | N38: Suma de UTILIDAD BRUTA | O38: =O36-O37 -> 2416912.4 | P38: =P36-P37 -> 83539.98 | Q38: =Q36-Q37 -> 333333.33 | R38: =R36-R37 -> 172428.86 | S38: =SUM(O38:R38) -> 3006214.6
B39: Margen Neto % | C39: =C38/C37 -> -0.23389472 | D39: =D38/D37 -> -0.18631496 | E39: =E38/E37 -> -0.06351349 | F39: =F38/F37 -> 0.019909868 | G39: =G38/G37 -> -0.065779594 | H39: =H38/H37 -> 0.070078206 | I39: =G39-H39 -> -0.1358578 | K39: gasto ventas | L39: =L20-L38 -> 79288.98 | N39: Suma de GASTO VENTAS | O39: 1313000 | P39: =1341135.81-O39 -> 28135.81 | R39: 0 | S39: =SUM(O39:R39) -> 1341135.8
N40: Suma de GASTO ADM | O40: 273515.96 | P40: 0 | R40: 0 | S40: =SUM(O40:R40) -> 273515.96
N41: Suma de DRAWBACK | O41: 283276 | P41: =287242-O41 -> 3966 | R41: 0 | S41: =SUM(O41:R41) -> 287242
B42: Venta | C42: =45444/3.35/1000 -> 13.565373 | D42: =57239/3.4/1000 -> 16.835 | E42: =54636.38/3.45/1000 -> 15.836632 | F42: =216375.28/3.5/1000 -> 61.821509 | G42: =SUM(C42:F42) -> 108.05851 | L42: Muelle | N42: Suma de UTILIDAD OPERATIVA | O42: =O38-O39-O40+O41 -> 1113672.4 | P42: =P38-P39-P40+P41 -> 59370.17 | Q42: =Q38-Q39-Q40+Q41 -> 333333.33 | R42: =R38-R39-R40+R41 -> 172428.86 | S42: =SUM(O42:R42) -> 1678804.8
B43: Costos | C43: =49761/1000 -> 49.761 | D43: =47645/1000 -> 47.645 | E43: =63202/1000 -> 63.202 | G43: =SUM(C43:F43) -> 160.608 | K43: Venta | L43: 333333.33 | N43: Suma de GASTO FINANCIERO | O43: 541000 | P43: 0 | R43: 0 | S43: =SUM(O43:R43) -> 541000
B44: Utilidad | C44: =C42-C43 -> -36.195627 | D44: =D42-D43 -> -30.81 | E44: =E42-E43 -> -47.365368 | G44: =G42-G43 -> -52.549486 | K44: Costo | L44: 118480.23 | N44: Suma de UTILIDAD NETA | O44: =O42-O43 -> 572672.44 | P44: =P42-P43 -> 59370.17 | Q44: =Q42-Q43 -> 333333.33 | R44: =R42-R43 -> 172428.86 | S44: =SUM(O44:R44) -> 1137804.8
K45: Utilidad | L45: =L43-L44 -> 214853.1 | N45: Suma de DEPRECIACIÓN | O45: 466666.67
N46: Suma de EBITDA | O46: =O45+O42 -> 1580339.1 | S46: 1137804.5
B48: PERÚ FROST - RESULTADOS CONGELADOS 2026 (EN MILES DE US$)
...

Sheet TD
N1: Real | O1: Budget | P1: Var
A2: ANÁLISIS DE RENTABILIDAD | M2: Precio Compra MP por TM | N2: =3024.94326918258/3.4 -> 889.6892 | O2: 1119 | P2: =N2/O2-1 -> -0.20492476
M3: Ratio Costo / Compra | N3: =N9/N2 -> 2.0820758 | O3: =O9/O2 -> 1.9865383 | P3: =N3/O3-1 -> 0.04809244
A4: EEFF PERU FROST (USD) | M4: Ratio Precio / Costo | N4: =N8/N2 -> 2.2748844 | O4: =O8/O2 -> 2.3488157 | P4: =N4/O4-1 -> -0.031476018 | AD4: Enero | AE4: Febrero | AF4: Marzo | AG4: Abril | AH4: Real | AI4: Presupuesto
B5: Etiquetas de columna | I5: ANÁLISIS UNITARIO | P5: =P3-P4 -> 0.079568458 | R5: ANÁLISIS VÉRTICAL | AC5: Venta CFR | AD5: =B8/1000 -> 564.61528 | AE5: =C8/1000 -> 2769.8245 | AF5: =D8/1000 -> 3896.4183 | AG5: =E8/1000 -> 4888.92 | AH5: =F8/1000 -> 12119.778 | AI5: =G8/1000 -> 15333.647
A6: Valores | B6: ENERO | C6: FEBRERO | D6: MARZO | E6: ABRIL | F6: Total general | G6: Budget | H6: Var | I6: NOMBRE | J6: ENERO | K6: FEBRERO | L6: MARZO | M6: ABRIL | N6: TOTAL | O6: Budget | R6: NOMBRE | S6: ENERO | T6: FEBRERO | U6: MARZO | V6: ABRIL | W6: TOTAL | X6: Budget | AC6: Utilidad Neta | AD6: =B16/1000 -> -99.037985 | AE6: =C16/1000 -> -488.40746 | AF6: =D16/1000 -> -201.20764 | AG6: =E16/1000 -> 89.7471 | AH6: =F16/1000 -> -698.90598 | AI6: =G16/1000 -> 520.036
A7: Suma de Cantidad | B7: 248 | C7: 1634.3 | D7: 1995.8 | E7: 2110.11 | F7: 5988.21 | G7: 5834 | H7: =(F7-G7)/G7 -> 0.026432979
A8: Suma de VALOR CFR | B8: 564615.28 | C8: 2769824.5 | D8: 3896418.3 | E8: 4888920 | F8: 12119778 | G8: 15333647 | H8: =(F8-G8)/G8 -> -0.20959586 | I8: Suma de VALOR CFR | J8: =B8/B$7 -> 2276.6745 | K8: =C8/C$7 -> 1694.8079 | L8: =D8/D$7 -> 1952.309 | M8: =E8/E$7 -> 2316.9029 | N8: =F8/F$7 -> 2023.9401 | O8: =G8/G$7 -> 2628.3248 | R8: Suma de VALOR CFR | S8: =B8/B$8 -> 1 | T8: =C8/C$8 -> 1 | U8: =D8/D$8 -> 1 | V8: =E8/E$8 -> 1 | W8: =F8/F$8 -> 1 | X8: =G8/G$8 -> 1
A9: Suma de COSTO VENTAS | B9: 442635.6 | C9: 2804315 | D9: 3579964.7 | E9: 4265647 | F9: 11092562 | G9: 12968611 | H9: =(F9-G9)/G9 -> -0.14466072 | I9: Suma de COSTO VENTAS | J9: =B9/B$7 -> 1784.821 | K9: =C9/C$7 -> 1715.912 | L9: =D9/D$7 -> 1793.7492 | M9: =E9/E$7 -> 2021.5283 | N9: =F9/F$7 -> 1852.4004 | O9: =G9/G$7 -> 2222.9364 | R9: Suma de COSTO VENTAS | S9: =B9/B$8 -> 0.78395965 | T9: =C9/C$8 -> 1.0124522 | U9: =D9/D$8 -> 0.91878347 | V9: =E9/E$8 -> 0.87251316 | W9: =F9/F$8 -> 0.91524468 | X9: =G9/G$8 -> 0.84576168 | AK9: Resumen de Precios por TM Peru Frost vs Mercado
A10: Suma de UTILIDAD BRUTA | B10: 121979.68 | C10: -34490.515 | D10: 316453.57 | E10: 623272.97 | F10: 1027215.7 | G10: =G8-G9 -> 2365036 | H10: =(F10-G10)/G10 -> -0.56566593 | I10: Suma de UTILIDAD BRUTA | J10: =B10/B$7 -> 491.85355 | K10: =C10/C$7 -> -21.104152 | L10: =D10/D$7 -> 158.55976 | M10: =E10/E$7 -> 295.37463 | N10: =F10/F$7 -> 171.53969 | O10: =G10/G$7 -> 405.38841 | R10: Suma de UTILIDAD BRUTA | S10: =B10/B$8 -> 0.21604035 | T10: =C10/C$8 -> -0.012452239 | U10: =D10/D$8 -> 0.081216529 | V10: =E10/E$8 -> 0.12748684 | W10: =F10/F$8 -> 0.084755323 | X10: =G10/G$8 -> 0.15423832 | AC10: Acum Abril venta y rentabilidad por producto
A11: Suma de GASTO VENTAS | B11: 54228.385 | C11: 324522.18 | D11: 393245.77 | E11: 438569.02 | F11: 1210565.4 | G11: 1313000 | H11: =(F11-G11)/G11 -> -0.078015725 | I11: Suma de GASTO VENTAS | J11: =B11/B$7 -> 218.66284 | K11: =C11/C$7 -> 198.56953 | L11: =D11/D$7 -> 197.03666 | M11: =E11/E$7 -> 207.84178 | N11: =F11/F$7 -> 202.15813 | O11: =G11/G$7 -> 225.05999 | R11: Suma de GASTO VENTAS | S11: =B11/B$8 -> 0.096044841 | T11: =C11/C$8 -> 0.11716344 | U11: =D11/D$8 -> 0.10092494 | V11: =E11/E$8 -> 0.089706728 | W11: =F11/F$8 -> 0.099883459 | X11: =G11/G$8 -> 0.085628683 | AD11: Venta CFR | AE11: Utilidad Neta | AK11: PRODUCTO | AL11: PERU FROST | AM11: INDUSTRIA PERUANA
A12: Suma de GASTO ADM | B12: 50659 | C12: 56604 | D12: 78579 | E12: 78579 | F12: 264421 | G12: 274000 | H12: =(F12-G12)/G12 -> -0.034959854 | I12: Suma de GASTO ADM | J12: =B12/B$7 -> 204.27016 | K12: =C12/C$7 -> 34.635012 | L12: =D12/D$7 -> 39.372182 | M12: =E12/E$7 -> 37.239291 | N12: =F12/F$7 -> 44.156935 | O12: =G12/G$7 -> 46.966061 | R12: Suma de GASTO ADM | S12: =B12/B$8 -> 0.089723041 | T12: =C12/C$8 -> 0.020435952 | U12: =D12/D$8 -> 0.020166983 | V12: =E12/E$8 -> 0.016072875 | W12: =F12/F$8 -> 0.021817314 | X12: =G12/G$8 -> 0.0178692 | AC12: FILETE CONGELADO | AD12: 3148.23 | AE12: -1138.4306 | AK12: FILETE CONGELADO | AL12: 1323 | AM12: 1525
A13: Suma de DRAWBACK | B13: 15120.72 | C13: 75707.235 | D13: 108636.57 | E13: 138095.15 | F13: 337559.67 | G13: 283000 | H13: =(F13-G13)/G13 -> 0.19279036 | I13: Suma de DRAWBACK | J13: =B13/B$7 -> 60.970645 | K13: =C13/C$7 -> 46.323952 | L13: =D13/D$7 -> 54.432593 | M13: =E13/E$7 -> 65.444526 | N13: =F13/F$7 -> 56.370714 | O13: =G13/G$7 -> 48.508742 | R13: Suma de DRAWBACK | S13: =B13/B$8 -> 0.026780572 | T13: =C13/C$8 -> 0.027332864 | U13: =D13/D$8 -> 0.027881136 | V13: =E13/E$8 -> 0.028246555 | W13: =F13/F$8 -> 0.027851968 | X13: =G13/G$8 -> 0.018456144 | AC13: REJOS CONGELADOS | AD13: 2631.849 | AE13: 311.25595 | AK13: FILETE DARUMA | AL13: 3292 | AM13: 3417
A14: Suma de UTILIDAD OPERATIVA | B14: 32213.015 | C14: -339909.46 | D14: -46734.635 | E14: 244220.1 | F14: -110210.98 | G14: =G10-G11-G12+G13 -> 1061036 | H14: =(F14-G14)/G14 -> -1.1038711 | I14: Suma de UTILIDAD OPERATIVA | J14: =B14/B$7 -> 129.89119 | K14: =C14/C$7 -> -207.98474 | L14: =D14/D$7 -> -23.416492 | M14: =E14/E$7 -> 115.73809 | N14: =F14/F$7 -> -18.404661 | O14: =G14/G$7 -> 181.8711 | R14: Suma de UTILIDAD OPERATIVA | S14: =B14/B$8 -> 0.057053035 | T14: =C14/C$8 -> -0.12271877 | U14: =D14/D$8 -> -0.011994255 | V14: =E14/E$8 -> 0.049953793 | W14: =F14/F$8 -> -0.0090934815 | X14: =G14/G$8 -> 0.069196584 | AC14: ALAS CONGELADAS | AD14: 2273.427 | AE14: -451.32788 | AK14: REPRODUCTOR | AL14: 2724 | AM14: 2704
A15: Suma de GASTO FINANCIERO | B15: 131251 | C15: 148498 | D15: 154473 | E15: 154473 | F15: 588695 | G15: 541000 | H15: =(F15-G15)/G15 -> 0.088160813 | I15: Suma de GASTO FINANCIERO | J15: =B15/B$7 -> 529.2379 | K15: =C15/C$7 -> 90.863367 | L15: =D15/D$7 -> 77.399038 | M15: =E15/E$7 -> 73.206136 | N15: =F15/F$7 -> 98.309011 | O15: =G15/G$7 -> 92.732259 | R15: Suma de GASTO FINANCIERO | S15: =B15/B$8 -> 0.23246094 | T15: =C15/C$8 -> 0.053612783 | U15: =D15/D$8 -> 0.039644871 | V15: =E15/E$8 -> 0.031596549 | W15: =F15/F$8 -> 0.048573084 | X15: =G15/G$8 -> 0.035281887 | AC15: FILETE DARUMA | AD15: 1927.8 | AE15: 513.07693 | AK15: NUCA | AL15: 1123 | AM15: 1171
A16: Suma de UTILIDAD NETA | B16: -99037.985 | C16: -488407.46 | D16: -201207.64 | E16: 89747.1 | F16: -698905.98 | G16: =G14-G15 -> 520036 | H16: =(F16-G16)/G16 -> -2.3439569 | I16: Suma de UTILIDAD NETA | J16: =B16/B$7 -> -399.34671 | K16: =C16/C$7 -> -298.8481 | L16: =D16/D$7 -> -100.81553 | M16: =E16/E$7 -> 42.531953 | N16: =F16/F$7 -> -116.71367 | O16: =G16/G$7 -> 89.138841 | R16: Suma de UTILIDAD NETA | S16: =B16/B$8 -> -0.17540791 | T16: =C16/C$8 -> -0.17633155 | U16: =D16/D$8 -> -0.051639126 | V16: =E16/E$8 -> 0.018357244 | W16: =F16/F$8 -> -0.057666566 | X16: =G16/G$8 -> 0.033914698 | AC16: REPRODUCTORES | AD16: 599.405 | AE16: 126.98725 | AK16: ALAS COCIDAS | AL16: 3240 | AM16: 3318
A17: Suma de DEPRECIACIÓN | B17: 123530 | C17: 124152.39 | D17: 123360.73 | E17: 123484.35 | F17: 494527.47 | G17: 466666.67 | H17: =(F17-G17)/G17 -> 0.059701728 | I17: Suma de DEPRECIACIÓN | J17: =B17/B$7 -> 498.10484 | K17: =C17/C$7 -> 75.96671 | L17: =D17/D$7 -> 61.810166 | M17: =E17/E$7 -> 58.520338 | N17: =F17/F$7 -> 82.583522 | O17: =G17/G$7 -> 79.990858 | R17: Suma de DEPRECIACIÓN | S17: =B17/B$8 -> 0.21878614 | T17: =C17/C$8 -> 0.044823199 | U17: =D17/D$8 -> 0.031660032 | V17: =E17/E$8 -> 0.025258002 | W17: =F17/F$8 -> 0.040803344 | X17: =G17/G$8 -> 0.03043416 | AC17: NUCAS | AD17: 514.83 | AE17: -431.34411 | AK17: ALAS CONGELADAS | AL17: 1509 | AM17: 1579
A18: Suma de EBITDA | B18: 155743.02 | C18: -215757.06 | D18: 76626.094 | E18: 367704.45 | F18: 384316.5 | G18: =G17+G14 -> 1527702.7 | H18: =(F18-G18)/G18 -> -0.74843502 | I18: Suma de EBITDA | J18: =B18/B$7 -> 627.99603 | K18: =C18/C$7 -> -132.01803 | L18: =D18/D$7 -> 38.393674 | M18: =E18/E$7 -> 174.25843 | N18: =F18/F$7 -> 64.178861 | O18: =G18/G$7 -> 261.86196 | R18: Suma de EBITDA | S18: =B18/B$8 -> 0.27583918 | T18: =C18/C$8 -> -0.077895572 | U18: =D18/D$8 -> 0.019665777 | V18: =E18/E$8 -> 0.075211795 | W18: =F18/F$8 -> 0.031709862 | X18: =G18/G$8 -> 0.099630745 | AC18: ALAS COCIDAS | AD18: 384.2577 | AE18: 138.02447 | AK18: TENTACULO | AL18: 2290 | AM18: 2288
A19: EBITDA NETO | B19: =B16+B17 -> 24492.015 | C19: =C16+C17 -> -364255.06 | D19: =D16+D17 -> -77846.906 | E19: =E16+E17 -> 213231.45 | F19: =F16+F17 -> -204378.5 | G19: =G16+G17 -> 986702.67 | H19: =(F19-G19)/G19 -> -1.2071328 | AC19: OTROS | AD19: =SUM(AD20:AD25) -> 639.97939 | AE19: =SUM(AE20:AE25) -> 232.85204
N20: Budget Aprob | O20: Budget Meta | AC20: POTA CONOS | AD20: 231.72 | AE20: 0.42290479
M21: CIF total | N21: 3400000 | O21: 3400000 | AC21: POTA MEMBRANA PRECOCIDA | AD21: 128.90625 | AE21: 66.439886
M22: tm MP | N22: 16000 | O22: 22500 | AC22: POTA TELILLA PRECOCIDA | AD22: 90.80625 | AE22: 36.286582 | AO22: % FOB
M23: tm PT | N23: 10975 | O23: 16500 | AC23: POTA RECORTES COCIDOS | AD23: 67.5 | AE23: 15.71277 | AO23: 0.0692
M24: cif x tm | N24: =N21/N23 -> 309.79499 | O24: =O21/O23 -> 206.06061 | AC24: POTA SUCKERS CONGELADO | AD24: 30.25 | AE24: 23.193002 | AO24: 0.0637
A25: ANÁLISIS POR PRODUCTO | AC25: RESIDUOS DE POTA | AD25: 90.79689 | AE25: 90.79689 | AO25: 0.0634
AO26: 0.0478
A27: RANKING DE VENTAS (USD) | I27: UTILIDAD NETA (USD) | R27: EBITDA (USD) | AC27: Acum Abril venta y rentabilidad por cliente | AO27: 0.0459
A28: Suma de VALOR CFR | B28: Etiquetas de columna | I28: Suma de UTILIDAD NETA | J28: Etiquetas de columna | R28: Suma de EBITDA | S28: Etiquetas de columna | AD28: Venta CFR | AE28: Utilidad Neta | AO28: 0.0371
A29: Etiquetas de fila | B29: ENERO | C29: FEBRERO | D29: MARZO | E29: ABRIL | F29: Total general | G29: % | I29: Etiquetas de fila | J29: ENERO | K29: FEBRERO | L29: MARZO | M29: ABRIL | N29: Total general | O29: MG | R29: Etiquetas de fila | S29: ENERO | T29: FEBRERO | U29: MARZO | V29: ABRIL | W29: Total general | X29: MG | AC29: TSUJINO | AD29: 2790.273 | AE29: -709.0403 | AO29: 0.0337
A30: POTA FILETE CONGELADO | B30: 94800 | C30: 1147500 | D30: 430960 | E30: 1474970 | F30: 3148230 | G30: =E30/$E$43 -> 0.30169649 | I30: POTA FILETE CONGELADO | J30: -36814.029 | K30: -511210.58 | L30: -139940.29 | M30: -450465.71 | N30: -1138430.6 | O30: =N30/F30 -> -0.36160973 | R30: POTA FILETE CONGELADO | S30: 12498.423 | T30: -376073.28 | U30: -99151.993 | V30: -343912.16 | W30: -806639.02 | X30: =W30/F30 -> -0.25621985 | AC30: LONGKOU JIABAO AQUATIC | AD30: 1406.7 | AE30: 394.79634 | AO30: 0.0337
A31: POTA REJOS CONGELADOS | B31: 149248 | C31: 532695 | D31: 779600 | E31: 1170306 | F31: 2631849 | G31: =E31/$E$43 -> 0.23937925 | I31: POTA REJOS CONGELADOS | J31: -6695.1747 | K31: 112709.73 | L31: 122378.78 | M31: 82862.605 | N31: 311255.95 | O31: =N31/F31 -> 0.11826512 | R31: POTA REJOS CONGELADOS | S31: 52849.611 | T31: 147578.49 | U31: 168457.03 | V31: 143317.15 | W31: 512202.29 | X31: =W31/F31 -> 0.1946169 | AC31: KULALIA | AD31: 1378.9217 | AE31: 101.0003 | AO31: 0.0333
A32: POTA ALAS CONGELADAS | B32: 135915 | C32: 710550 | D32: 768480 | E32: 658482 | F32: 2273427 | G32: =E32/$E$43 -> 0.13468864 | I32: POTA ALAS CONGELADAS | J32: -51769.093 | K32: -165345.58 | L32: -132907.65 | M32: -101305.56 | N32: -451327.88 | O32: =N32/F32 -> -0.19852315 | R32: POTA ALAS CONGELADAS | S32: 22199.584 | T32: -88717.727 | U32: -65697.444 | V32: -56041.712 | W32: -188257.3 | X32: =W32/F32 -> -0.082807717 | AC32: AVANCE GROUP | AD32: 1097.2 | AE32: -468.13754 | AO32: 0.0333
A33: POTA FILETE DARUMA | C33: 91800 | D33: 1004400 | E33: 831600 | F33: 1927800 | G33: =E33/$E$43 -> 0.17009892 | I33: POTA FILETE DARUMA | K33: 29126.229 | L33: 185279.47 | M33: 298671.23 | N33: 513076.93 | O33: =N33/F33 -> 0.26614635 | R33: POTA FILETE DARUMA | T33: 33630.806 | U33: 230383.25 | V33: 327124.15 | W33: 591138.2 | X33: =W33/F33 -> 0.30663876 | AC33: FOOD & BEVERAGES TRADERS | AD33: 935.406 | AE33: -74.238541 | AO33: 0.032
A34: POTA REPRODUCTORES | B34: 74064 | C34: 77585 | D34: 139200 | E34: 308556 | F34: 599405 | G34: =E34/$E$43 -> 0.063113326 | I34: POTA REPRODUCTORES | J34: 2979.6903 | K34: 20669.556 | L34: 34424.877 | M34: 68913.124 | N34: 126987.25 | O34: =N34/F34 -> 0.2118555 | R34: POTA REPRODUCTORES | S34: 29690.602 | T34: 25174.132 | U34: 41524.546 | V34: 82586.332 | W34: 178975.61 | X34: =W34/F34 -> 0.29858879 | AC34: Qingdao Haiyujia | AD34: 595.782 | AE34: 101.96621 | AO34: 0.0318
A35: POTA NUCAS | B35: 35874 | C35: 23456 | D35: 455500 | F35: 514830 | G35: =E35/$E$43 -> 0 | I35: POTA NUCAS | J35: -20865.234 | K35: -6749.602 | L35: -403729.28 | N35: -431344.11 | O35: =N35/F35 -> -0.83783795 | R35: POTA ALAS COCIDAS | U35: 78707.593 | V35: 73828.848 | W35: 152536.44 | X35: =W35/F35 -> 0.29628507 | AC35: Longkou Yunfeng Aquatic Food | AD35: 575.1 | AE35: -44.789183 | AO35: 0.0316
A36: POTA ALAS COCIDAS | D36: 177221.7 | E36: 207036 | F36: 384257.7 | G36: =E36/$E$43 -> 0.042348003 | I36: POTA ALAS COCIDAS | L36: 71190.296 | M36: 66834.173 | N36: 138024.47 | O36: =N36/F36 -> 0.35919766 | R36: POTA CONOS | S36: 14467.801 | T36: 17395.748 | U36: 12064.775 | V36: -3574.5429 | W36: 40353.781 | X36: =W36/F36 -> 0.1050175 | AC36: OTROS | AD36: =SUM(AD37:AD51) -> 3340.3954 | AE36: =SUM(AE37:AE51) -> -0.46326558 | AO36: 0.0302
A37: POTA CONOS | B37: 50400 | C37: 69000 | D37: 76800 | E37: 35520 | F37: 231720 | G37: =E37/$E$43 -> 0.0072654083 | I37: POTA CONOS | J37: -10188.424 | K37: 11727.466 | L37: 5382.7333 | M37: -6498.8706 | N37: 422.90479 | O37: =N37/F37 -> 0.0018250681 | R37: POTA MEMBRANA PRECOCIDA | T37: -5368.3017 | U37: 34015.461 | V37: 49513.772 | W37: 78160.931 | X37: =W37/F37 -> 0.33730766 | AC37: OVERSEA | AD37: 354.595 | AE37: 86.215827 | AO37: 0.03
A38: POTA MEMBRANA PRECOCIDA | C38: 38606.25 | D38: 37800 | E38: 52500 | F38: 128906.25 | G38: =E38/$E$43 -> 0.010738568 | I38: POTA MEMBRANA PRECOCIDA | K38: -9872.8783 | L38: 30256.812 | M38: 46055.952 | N38: 66439.886 | O38: =N38/F38 -> 0.51541245 | R38: POTA TELILLA PRECOCIDA | T38: -4983.2234 | V38: 49212.443 | W38: 44229.22 | X38: =W38/F38 -> 0.34311152 | AC38: Pesciro Asia International LTD. | AD38: 352.35 | AE38: -117.23253
A39: POTA TELILLA PRECOCIDA | C39: 38606.25 | E39: 52200 | F39: 90806.25 | G39: =E39/$E$43 -> 0.010677205 | I39: POTA TELILLA PRECOCIDA | K39: -9487.8 | M39: 45774.382 | N39: 36286.582 | O39: =N39/F39 -> 0.39960446 | R39: POTA RECORTES COCIDOS | V39: 19269.385 | W39: 19269.385 | X39: =W39/F39 -> 0.21220329 | AC39: OCEANUS FISH | AD39: 340.564 | AE39: -36.175426
A40: POTA RECORTES COCIDOS | E40: 67500 | F40: 67500 | G40: =E40/$E$43 -> 0.01380673 | I40: POTA RECORTES COCIDOS | M40: 15712.77 | N40: 15712.77 | O40: =N40/F40 -> 0.23278178 | R40: POTA SUCKERS CONGELADO | V40: 26380.783 | W40: 26380.783 | X40: =W40/F40 -> 0.39082641 | AC40: LONGKOU BOHAI | AD40: 334.8 | AE40: 61.759822
...

Sheet Resumen
C2: X | F2: X | G2: X | H2: X | K2: X | M2: X | P2: X | S2: X | AU2: X | AV2: X | BA2: ANÁLISIS UNITARIO
B3: MES LINK | C3: MES EJERCICIO | D3: FP | E3: Emision | F3: Fecha Embarque | G3: Cantidad | H3: Producto | I3: Corte | J3: Espec. | K3: País | L3: Puerto | M3: Cliente (Razón Social) | N3: Contacto | O3: Precio TM | P3: VALOR CFR | Q3: FOB / TM | R3: Costo Flete | S3: VALOR FOB | T3: Cantidad de FCL (Contenedores) | U3: M/V Nave | V3: Booking | W3: Naviera | X3: Puerto | Y3: CÓDIGO | Z3: Categoría | AA3: MATCH | AB3: COSTO UNITARIO | AC3: Materia Prima | AD3: MOD | AE3: Envases | AF3: CIF | AG3: COSTO VENTAS | AH3: Cant | AI3: C.U | AJ3: Cotos Vta | AK3: UTILIDAD BRUTA | AL3: MARGEN BRUTO | AM3: Flete | AN3: SS Logístico | AO3: GASTO VENTAS | AP3: GASTO ADM | AQ3: DRAWBACK | AR3: UTILIDAD OPERATIVA | AS3: MARGEN OPERATIVO | AT3: GASTO FINANCIERO | AU3: UTILIDAD NETA | AV3: MARGEN NETO | AW3: DEPRECIACIÓN | AX3: EBITDA | AY3: MARGEN EBITDA | BA3: PRECIO CFR | BB3: Materia Prima | BC3: MOD | BD3: Envases | BE3: CIF | BF3: COSTO VENTAS | BG3: UTILIDAD BRUTA | BH3: Flete | BI3: SS Logístico | BJ3: GASTO VENTAS | BK3: GASTO ADM | BL3: DRAWBACK | BM3: UTILIDAD OPERATIVA | BN3: GASTO FINANCIERO | BO3: UTILIDAD NETA | BP3: DEPRECIACIÓN | BQ3: EBITDA
B4: ENERO | C4: =B4 -> ENERO | D4: 127-2025 | E4: 325 | F4: 46033 | G4: 26 | H4: POTA REPRODUCTORES | I4: Rejos | K4: España | L4: Valencia | M4: OCEANUS FISH | N4: Ignacio / Ives | O4: =P4/G4 -> 2848.6154 | P4: =78000*0+74064 -> 74064 | Q4: =S4/G4 -> 2670.3846 | R4: 4634 | S4: =P4-R4 -> 69430 | T4: 1 | U4: MERSIN EXPRESS 603N | V4: 26106924 | W4: HAPAG | X4: PAITA | Y4: 10007567 | Z4: Compensación | AA4: =B4&Y4&Z4 -> ENERO10007567Compensación | AB4: =INDEX('Detalle Costos'!$L$5:$L$158,MATCH(Resumen!AA4,'Detalle Costos'!$C$5:$C$158,0))*1000 -> 1830 | AC4: =IFERROR(INDEX('Detalle Costos'!$X$5:$X$158,MATCH(Resumen!AA4,'Detalle Costos'!$C$5:$C$158,0))*AG4,0) -> 31604.019 | AD4: =IFERROR(INDEX('Detalle Costos'!$Z$5:$Z$158,MATCH(Resumen!AA4,'Detalle Costos'!$C$5:$C$158,0))*AG4,0) -> 7767.649 | AE4: =IFERROR(INDEX('Detalle Costos'!$Y$5:$Y$158,MATCH(Resumen!AA4,'Detalle Costos'!$C$5:$C$158,0))*AG4,0) -> 466.19182 | AF4: =IFERROR(INDEX('Detalle Costos'!$AA$5:$AA$158,MATCH(Resumen!AA4,'Detalle Costos'!$C$5:$C$158,0))*AG4,0) -> 7742.1407 | AG4: =AB4*G4 -> 47580 | AH4: =48.96-AH17 -> 22.658 | AI4: =+AJ4/AH4 -> 1829.8235 | AJ4: =89589.14-AJ17 -> 41460.14 | AK4: =P4-AG4 -> 26484 | AL4: =AK4/P4 -> 0.35758263 | AM4: =R4 -> 4634 | AN4: =1882/26*G4 -> 1882 | AO4: =SUM(AM4:AN4) -> 6516 | AP4: =50659/248*G4 -> 5311.0242 | AQ4: =S4*0.03 -> 2082.9 | AR4: =AK4-AO4-AP4+AQ4 -> 16739.876 | AS4: =AR4/P4 -> 0.22601906 | AT4: =131251/248*G4 -> 13760.185 | AU4: =AR4-AT4 -> 2979.6903 | AV4: =AU4/P4 -> 0.040231291 | AW4: =123530/248*G4 -> 12950.726 | AX4: =AR4+AW4 -> 29690.602 | AY4: =AX4/P4 -> 0.40087764 | BA4: =P4/$G4 -> 2848.6154 | BB4: =-AC4/$G4 -> -1215.5392 | BC4: =-AD4/$G4 -> -298.75573 | BD4: =-AE4/$G4 -> -17.930455 | BE4: =-AF4/$G4 -> -297.77464 | BF4: =-AG4/$G4 -> -1830 | BG4: =AK4/$G4 -> 1018.6154 | BH4: =-AM4/$G4 -> -178.23077 | BI4: =-AN4/$G4 -> -72.384615 | BJ4: =-AO4/$G4 -> -250.61538 | BK4: =-AP4/$G4 -> -204.27016 | BL4: =AQ4/$G4 -> 80.111538 | BM4: =AR4/$G4 -> 643.84138 | BN4: =-AT4/$G4 -> -529.2379 | BO4: =AU4/$G4 -> 114.60347 | BP4: =AW4/$G4 -> 498.10484 | BQ4: =AX4/$G4 -> 1141.9462
B5: ENERO | C5: =B5 -> ENERO | D5: 128-2025B | E5: 325 | F5: 46053 | G5: 17.04 | H5: POTA NUCAS | I5: Nucas | J5: 1000-up | K5: Tailandia | L5: Lat Krabang | M5: DAIRECK S.A. | N5: Julieta | O5: 1850 | P5: 31524 | Q5: 1656.338 | R5: =3300/24*G5 -> 2343 | S5: =P5-R5 -> 29181 | T5: 1 | U5: ECO SIROCCO 26005S | V5: 6443191850 | W5: COSCO | X5: PAITA | Y5: 10005779 | Z5: Compensación | AA5: =B5&Y5&Z5 -> ENERO10005779Compensación | AB5: =INDEX('Detalle Costos'!$L$5:$L$158,MATCH(Resumen!AA5,'Detalle Costos'!$C$5:$C$158,0))*1000 -> 1930 | AC5: =IFERROR(INDEX('Detalle Costos'!$X$5:$X$158,MATCH(Resumen!AA5,'Detalle Costos'!$C$5:$C$158,0))*AG5,0) -> 20697.485 | AD5: =IFERROR(INDEX('Detalle Costos'!$Z$5:$Z$158,MATCH(Resumen!AA5,'Detalle Costos'!$C$5:$C$158,0))*AG5,0) -> 6988.7487 | AE5: =IFERROR(INDEX('Detalle Costos'!$Y$5:$Y$158,MATCH(Resumen!AA5,'Detalle Costos'!$C$5:$C$158,0))*AG5,0) -> 251.15165 | AF5: =IFERROR(INDEX('Detalle Costos'!$AA$5:$AA$158,MATCH(Resumen!AA5,'Detalle Costos'!$C$5:$C$158,0))*AG5,0) -> 4949.8151 | AG5: =AB5*G5 -> 32887.2 | AH5: 17.04 | AI5: =+AJ5/AH5 -> 1977.4951 | AJ5: 33696.517 | AK5: =P5-AG5 -> -1363.2 | AL5: =AK5/P5 -> -0.043243243 | AM5: =R5 -> 2343 | AN5: =1882/26*G5 -> 1233.4338 | AO5: =SUM(AM5:AN5) -> 3576.4338 | AP5: =50659/248*G5 -> 3480.7635 | AQ5: =S5*0.03 -> 875.43 | AR5: =AK5-AO5-AP5+AQ5 -> -7544.9674 | AS5: =AR5/P5 -> -0.23934042 | AT5: =131251/248*G5 -> 9018.2139 | AU5: =AR5-AT5 -> -16563.181 | AV5: =AU5/P5 -> -0.52541496 | AW5: =123530/248*G5 -> 8487.7065 | AX5: =AR5+AW5 -> 942.73906 | AY5: =AX5/P5 -> 0.029905439 | BA5: =P5/$G5 -> 1850 | BB5: =-AC5/$G5 -> -1214.6411 | BC5: =-AD5/$G5 -> -410.13784 | BD5: =-AE5/$G5 -> -14.738946 | BE5: =-AF5/$G5 -> -290.48211 | BF5: =-AG5/$G5 -> -1930 | BG5: =AK5/$G5 -> -80 | BH5: =-AM5/$G5 -> -137.5 | BI5: =-AN5/$G5 -> -72.384615 | BJ5: =-AO5/$G5 -> -209.88462 | BK5: =-AP5/$G5 -> -204.27016 | BL5: =AQ5/$G5 -> 51.375 | BM5: =AR5/$G5 -> -442.77978 | BN5: =-AT5/$G5 -> -529.2379 | BO5: =AU5/$G5 -> -972.01768 | BP5: =AW5/$G5 -> 498.10484 | BQ5: =AX5/$G5 -> 55.325062
B6: ENERO | C6: =B6 -> ENERO | D6: 128-2025B | E6: 325 | F6: 46053 | G6: 3 | H6: POTA NUCAS | I6: Nucas | J6: 500 - 1 kg. | K6: Tailandia | L6: Lat Krabang | M6: DAIRECK S.A. | N6: Julieta | O6: 1450 | P6: 4350 | Q6: 1450 | R6: =3300/24*G6 -> 412.5 | S6: =P6-R6 -> 3937.5 | T6: 0 | V6: 6443191850 | W6: COSCO | X6: PAITA | Y6: 10005781 | Z6: Compensación | AA6: =B6&Y6&Z6 -> ENERO10005781Compensación | AB6: =INDEX('Detalle Costos'!$L$5:$L$158,MATCH(Resumen!AA6,'Detalle Costos'!$C$5:$C$158,0))*1000 -> 1980 | AC6: =IFERROR(INDEX('Detalle Costos'!$X$5:$X$158,MATCH(Resumen!AA6,'Detalle Costos'!$C$5:$C$158,0))*AG6,0) -> 3757.0132 | AD6: =IFERROR(INDEX('Detalle Costos'!$Z$5:$Z$158,MATCH(Resumen!AA6,'Detalle Costos'!$C$5:$C$158,0))*AG6,0) -> 1227.8049 | AE6: =IFERROR(INDEX('Detalle Costos'!$Y$5:$Y$158,MATCH(Resumen!AA6,'Detalle Costos'!$C$5:$C$158,0))*AG6,0) -> 49.950511 | AF6: =IFERROR(INDEX('Detalle Costos'!$AA$5:$AA$158,MATCH(Resumen!AA6,'Detalle Costos'!$C$5:$C$158,0))*AG6,0) -> 905.23138 | AG6: =AB6*G6 -> 5940 | AH6: 3 | AI6: =+AJ6/AH6 -> 1934.6564 | AJ6: 5803.9692 | AK6: =P6-AG6 -> -1590 | AL6: =AK6/P6 -> -0.36551724 | AM6: =R6 -> 412.5 | AN6: =1882/26*G6 -> 217.15385 | AO6: =SUM(AM6:AN6) -> 629.65385 | AP6: =50659/248*G6 -> 612.81048 | AQ6: =S6*0.03 -> 118.125 | AR6: =AK6-AO6-AP6+AQ6 -> -2714.3393 | AS6: =AR6/P6 -> -0.62398605 | AT6: =131251/248*G6 -> 1587.7137 | AU6: =AR6-AT6 -> -4302.053 | AV6: =AU6/P6 -> -0.98897771 | AW6: =123530/248*G6 -> 1494.3145 | AX6: =AR6+AW6 -> -1220.0248 | AY6: =AX6/P6 -> -0.28046547 | BA6: =P6/$G6 -> 1450 | BB6: =-AC6/$G6 -> -1252.3377 | BC6: =-AD6/$G6 -> -409.26831 | BD6: =-AE6/$G6 -> -16.65017 | BE6: =-AF6/$G6 -> -301.74379 | BF6: =-AG6/$G6 -> -1980 | BG6: =AK6/$G6 -> -530 | BH6: =-AM6/$G6 -> -137.5 | BI6: =-AN6/$G6 -> -72.384615 | BJ6: =-AO6/$G6 -> -209.88462 | BK6: =-AP6/$G6 -> -204.27016 | BL6: =AQ6/$G6 -> 39.375 | BM6: =AR6/$G6 -> -904.77978 | BN6: =-AT6/$G6 -> -529.2379 | BO6: =AU6/$G6 -> -1434.0177 | BP6: =AW6/$G6 -> 498.10484 | BQ6: =AX6/$G6 -> -406.67494
B7: ENERO | C7: =B7 -> ENERO | D7: 128-2025B | E7: 325 | F7: 46053 | G7: 3.96 | H7: POTA REJOS CONGELADOS | I7: Rejos | J7: 1 - 2 kgs. | K7: Tailandia | L7: Lat Krabang | M7: DAIRECK S.A. | N7: Julieta | O7: =P7/G7 -> 2234.3434 | P7: 8848 | Q7: 2800 | R7: =3300/24*G7 -> 544.5 | S7: =P7-R7 -> 8303.5 | T7: 0 | V7: 6443191850 | W7: COSCO | X7: PAITA | Y7: 10007162 | Z7: Compensación | AA7: =B7&Y7&Z7 -> ENERO10007162Compensación | AB7: =INDEX('Detalle Costos'!$L$5:$L$158,MATCH(Resumen!AA7,'Detalle Costos'!$C$5:$C$158,0))*1000 -> 1790 | AC7: =IFERROR(INDEX('Detalle Costos'!$X$5:$X$158,MATCH(Resumen!AA7,'Detalle Costos'!$C$5:$C$158,0))*AG7,0) -> 4604.3696 | AD7: =IFERROR(INDEX('Detalle Costos'!$Z$5:$Z$158,MATCH(Resumen!AA7,'Detalle Costos'!$C$5:$C$158,0))*AG7,0) -> 1214.8181 | AE7: =IFERROR(INDEX('Detalle Costos'!$Y$5:$Y$158,MATCH(Resumen!AA7,'Detalle Costos'!$C$5:$C$158,0))*AG7,0) -> 61.899523 | AF7: =IFERROR(INDEX('Detalle Costos'!$AA$5:$AA$158,MATCH(Resumen!AA7,'Detalle Costos'!$C$5:$C$158,0))*AG7,0) -> 1207.3128 | AG7: =AB7*G7 -> 7088.4 | AH7: 3.16 | AI7: =+AJ7/AH7 -> 1842.697 | AJ7: 5822.9227 | AK7: =P7-AG7 -> 1759.6 | AL7: =AK7/P7 -> 0.1988698 | AM7: =R7 -> 544.5 | AN7: =1882/26*G7 -> 286.64308 | AO7: =SUM(AM7:AN7) -> 831.14308 | AP7: =50659/248*G7 -> 808.90984 | AQ7: =S7*0.03 -> 249.105 | AR7: =AK7-AO7-AP7+AQ7 -> 368.65208 | AS7: =AR7/P7 -> 0.041665019 | AT7: =131251/248*G7 -> 2095.7821 | AU7: =AR7-AT7 -> -1727.13 | AV7: =AU7/P7 -> -0.19520005 | AW7: =123530/248*G7 -> 1972.4952 | AX7: =AR7+AW7 -> 2341.1472 | AY7: =AX7/P7 -> 0.26459621 | BA7: =P7/$G7 -> 2234.3434 | BB7: =-AC7/$G7 -> -1162.7196 | BC7: =-AD7/$G7 -> -306.77225 | BD7: =-AE7/$G7 -> -15.631193 | BE7: =-AF7/$G7 -> -304.87696 | BF7: =-AG7/$G7 -> -1790 | BG7: =AK7/$G7 -> 444.34343 | BH7: =-AM7/$G7 -> -137.5 | BI7: =-AN7/$G7 -> -72.384615 | BJ7: =-AO7/$G7 -> -209.88462 | BK7: =-AP7/$G7 -> -204.27016 | BL7: =AQ7/$G7 -> 62.905303 | BM7: =AR7/$G7 -> 93.093961 | BN7: =-AT7/$G7 -> -529.2379 | BO7: =AU7/$G7 -> -436.14394 | BP7: =AW7/$G7 -> 498.10484 | BQ7: =AX7/$G7 -> 591.1988
B8: ENERO | C8: =B8 -> ENERO | D8: 129-2025 | E8: 45982 | F8: 46031 | G8: 24 | H8: POTA CONOS | I8: Conos | K8: Tailandia | L8: Bangkok | M8: TSUJINO | N8: Jose | O8: 2100 | P8: 50400 | Q8: 1962.5 | R8: 3300 | S8: =P8-R8 -> 47100 | T8: 1 | U8: ECO MARIN 26002S | V8: 6440924270 | W8: COSCO | X8: PAITA | Y8: 10007969 | Z8: Compensación | AA8: =B8&Y8&Z8 -> ENERO10007969Compensación | AB8: =INDEX('Detalle Costos'!$L$5:$L$158,MATCH(Resumen!AA8,'Detalle Costos'!$C$5:$C$158,0))*1000 -> 1640 | AC8: =IFERROR(INDEX('Detalle Costos'!$X$5:$X$158,MATCH(Resumen!AA8,'Detalle Costos'!$C$5:$C$158,0))*AG8,0) -> 30431.619 | AD8: =IFERROR(INDEX('Detalle Costos'!$Z$5:$Z$158,MATCH(Resumen!AA8,'Detalle Costos'!$C$5:$C$158,0))*AG8,0) -> 5331.8121 | AE8: =IFERROR(INDEX('Detalle Costos'!$Y$5:$Y$158,MATCH(Resumen!AA8,'Detalle Costos'!$C$5:$C$158,0))*AG8,0) -> 403.53077 | AF8: =IFERROR(INDEX('Detalle Costos'!$AA$5:$AA$158,MATCH(Resumen!AA8,'Detalle Costos'!$C$5:$C$158,0))*AG8,0) -> 3193.0382 | AG8: =AB8*G8 -> 39360 | AH8: 24 | AI8: =+AJ8/AH8 -> 1644.3167 | AJ8: 39463.6 | AK8: =P8-AG8 -> 11040 | AL8: =AK8/P8 -> 0.21904762 | AM8: =R8 -> 3300 | AN8: =1882/26*G8 -> 1737.2308 | AO8: =SUM(AM8:AN8) -> 5037.2308 | AP8: =50659/248*G8 -> 4902.4839 | AQ8: =S8*0.03 -> 1413 | AR8: =AK8-AO8-AP8+AQ8 -> 2513.2854 | AS8: =AR8/P8 -> 0.049866773 | AT8: =131251/248*G8 -> 12701.71 | AU8: =AR8-AT8 -> -10188.424 | AV8: =AU8/P8 -> -0.20215128 | AW8: =123530/248*G8 -> 11954.516 | AX8: =AR8+AW8 -> 14467.801 | AY8: =AX8/P8 -> 0.28705955 | BA8: =P8/$G8 -> 2100 | BB8: =-AC8/$G8 -> -1267.9841 | BC8: =-AD8/$G8 -> -222.15884 | BD8: =-AE8/$G8 -> -16.813782 | BE8: =-AF8/$G8 -> -133.04326 | BF8: =-AG8/$G8 -> -1640 | BG8: =AK8/$G8 -> 460 | BH8: =-AM8/$G8 -> -137.5 | BI8: =-AN8/$G8 -> -72.384615 | BJ8: =-AO8/$G8 -> -209.88462 | BK8: =-AP8/$G8 -> -204.27016 | BL8: =AQ8/$G8 -> 58.875 | BM8: =AR8/$G8 -> 104.72022 | BN8: =-AT8/$G8 -> -529.2379 | BO8: =AU8/$G8 -> -424.51768 | BP8: =AW8/$G8 -> 498.10484 | BQ8: =AX8/$G8 -> 602.82506
B9: ENERO | C9: =B9 -> ENERO | D9: 137-2025 | E9: 46000 | F9: 46043 | G9: 24 | H9: POTA FILETE CONGELADO | I9: Filete | J9: 2 - 4 kg | K9: Taiwan | L9: KAOHSIUNG | M9: TSUJINO | N9: Jose | O9: =P9/G9 -> 1966.6667 | P9: =48000*0+47200 -> 47200 | Q9: =S9/G9 -> 1841.5417 | R9: 3003 | S9: =P9-R9 -> 44197 | T9: 1 | U9: ECO MARIN 25052N | V9: LIMF26385300 | W9: ONE | X9: PAITA | Y9: 10005721 | Z9: Compensación | AA9: =B9&Y9&Z9 -> ENERO10005721Compensación | AB9: =INDEX('Detalle Costos'!$L$5:$L$158,MATCH(Resumen!AA9,'Detalle Costos'!$C$5:$C$158,0))*1000 -> 1860 | AC9: =IFERROR(INDEX('Detalle Costos'!$X$5:$X$158,MATCH(Resumen!AA9,'Detalle Costos'!$C$5:$C$158,0))*AG9,0) -> 27074.763 | AD9: =IFERROR(INDEX('Detalle Costos'!$Z$5:$Z$158,MATCH(Resumen!AA9,'Detalle Costos'!$C$5:$C$158,0))*AG9,0) -> 9821.5948 | AE9: =IFERROR(INDEX('Detalle Costos'!$Y$5:$Y$158,MATCH(Resumen!AA9,'Detalle Costos'!$C$5:$C$158,0))*AG9,0) -> 427.38655 | AF9: =IFERROR(INDEX('Detalle Costos'!$AA$5:$AA$158,MATCH(Resumen!AA9,'Detalle Costos'!$C$5:$C$158,0))*AG9,0) -> 7316.2554 | AG9: =AB9*G9 -> 44640 | AH9: 23.7 | AI9: =+AJ9/AH9 -> 1889.3859 | AJ9: 44778.445 | AK9: =P9-AG9 -> 2560 | AL9: =AK9/P9 -> 0.054237288 | AM9: =R9 -> 3003 | AN9: =1882/26*G9 -> 1737.2308 | AO9: =SUM(AM9:AN9) -> 4740.2308 | AP9: =50659/248*G9 -> 4902.4839 | AQ9: =S9*0.03 -> 1325.91 | AR9: =AK9-AO9-AP9+AQ9 -> -5756.8046 | AS9: =AR9/P9 -> -0.1219662 | AT9: =131251/248*G9 -> 12701.71 | AU9: =AR9-AT9 -> -18458.514 | AV9: =AU9/P9 -> -0.39107022 | AW9: =123530/248*G9 -> 11954.516 | AX9: =AR9+AW9 -> 6197.7115 | AY9: =AX9/P9 -> 0.13130745 | BA9: =P9/$G9 -> 1966.6667 | BB9: =-AC9/$G9 -> -1128.1151 | BC9: =-AD9/$G9 -> -409.23312 | BD9: =-AE9/$G9 -> -17.807773 | BE9: =-AF9/$G9 -> -304.84398 | BF9: =-AG9/$G9 -> -1860 | BG9: =AK9/$G9 -> 106.66667 | BH9: =-AM9/$G9 -> -125.125 | BI9: =-AN9/$G9 -> -72.384615 | BJ9: =-AO9/$G9 -> -197.50962 | BK9: =-AP9/$G9 -> -204.27016 | BL9: =AQ9/$G9 -> 55.24625 | BM9: =AR9/$G9 -> -239.86686 | BN9: =-AT9/$G9 -> -529.2379 | BO9: =AU9/$G9 -> -769.10476 | BP9: =AW9/$G9 -> 498.10484 | BQ9: =AX9/$G9 -> 258.23798
B10: ENERO | C10: =B10 -> ENERO | D10: 140-2025 | E10: 347 | F10: 46038 | G10: 24 | H10: POTA FILETE CONGELADO | I10: Filete | J10: 2-4kg | K10: Japón | L10: Sendai | M10: TSUJINO | N10: Jose | O10: =P10/G10 -> 1983.3333 | P10: =48000*0+47600 -> 47600 | Q10: =S10/G10 -> 1845.7083 | R10: 3303 | S10: =P10-R10 -> 44297 | T10: 1 | U10: ECO SIROCCO 26003S | V10: LIMG00358300 | W10: ONE | X10: PAITA | Y10: 10005721 | Z10: Compensación | AA10: =B10&Y10&Z10 -> ENERO10005721Compensación | AB10: =INDEX('Detalle Costos'!$L$5:$L$158,MATCH(Resumen!AA10,'Detalle Costos'!$C$5:$C$158,0))*1000 -> 1860 | AC10: =IFERROR(INDEX('Detalle Costos'!$X$5:$X$158,MATCH(Resumen!AA10,'Detalle Costos'!$C$5:$C$158,0))*AG10,0) -> 27074.763 | AD10: =IFERROR(INDEX('Detalle Costos'!$Z$5:$Z$158,MATCH(Resumen!AA10,'Detalle Costos'!$C$5:$C$158,0))*AG10,0) -> 9821.5948 | AE10: =IFERROR(INDEX('Detalle Costos'!$Y$5:$Y$158,MATCH(Resumen!AA10,'Detalle Costos'!$C$5:$C$158,0))*AG10,0) -> 427.38655 | AF10: =IFERROR(INDEX('Detalle Costos'!$AA$5:$AA$158,MATCH(Resumen!AA10,'Detalle Costos'!$C$5:$C$158,0))*AG10,0) -> 7316.2554 | AG10: =AB10*G10 -> 44640 | AH10: 23.7 | AI10: =+AJ10/AH10 -> 1889.3859 | AJ10: 44778.445 | AK10: =P10-AG10 -> 2960 | AL10: =AK10/P10 -> 0.062184874 | AM10: =R10 -> 3303 | AN10: =1882/26*G10 -> 1737.2308 | AO10: =SUM(AM10:AN10) -> 5040.2308 | AP10: =50659/248*G10 -> 4902.4839 | AQ10: =S10*0.03 -> 1328.91 | AR10: =AK10-AO10-AP10+AQ10 -> -5653.8046 | AS10: =AR10/P10 -> -0.11877741 | AT10: =131251/248*G10 -> 12701.71 | AU10: =AR10-AT10 -> -18355.514 | AV10: =AU10/P10 -> -0.38562005 | AW10: =123530/248*G10 -> 11954.516 | AX10: =AR10+AW10 -> 6300.7115 | AY10: =AX10/P10 -> 0.13236789 | BA10: =P10/$G10 -> 1983.3333 | BB10: =-AC10/$G10 -> -1128.1151 | BC10: =-AD10/$G10 -> -409.23312 | BD10: =-AE10/$G10 -> -17.807773 | BE10: =-AF10/$G10 -> -304.84398 | BF10: =-AG10/$G10 -> -1860 | BG10: =AK10/$G10 -> 123.33333 | BH10: =-AM10/$G10 -> -137.625 | BI10: =-AN10/$G10 -> -72.384615 | BJ10: =-AO10/$G10 -> -210.00962 | BK10: =-AP10/$G10 -> -204.27016 | BL10: =AQ10/$G10 -> 55.37125 | BM10: =AR10/$G10 -> -235.57519 | BN10: =-AT10/$G10 -> -529.2379 | BO10: =AU10/$G10 -> -764.8131 | BP10: =AW10/$G10 -> 498.10484 | BQ10: =AX10/$G10 -> 262.52965
B11: ENERO | C11: =B11 -> ENERO | D11: 145-2025 | E11: 46020 | F11: 46041 | G11: 54 | H11: POTA REJOS CONGELADOS | I11: Rejos | J11: 500-1 / 1-2 | K11: España | L11: Vigo | M11: GLOBAL OCEAN | N11: Jorge | O11: 2600 | P11: 140400 | Q11: 2430.963 | R11: 9128 | S11: =P11-R11 -> 131272 | T11: 2 | U11: IZMIT EXPRESS 604N | V11: 28952064 | W11: HAPAG | X11: PAITA | Y11: 10007162 | Z11: Compensación | AA11: =B11&Y11&Z11 -> ENERO10007162Compensación | AB11: =INDEX('Detalle Costos'!$L$5:$L$158,MATCH(Resumen!AA11,'Detalle Costos'!$C$5:$C$158,0))*1000 -> 1790 | AC11: =IFERROR(INDEX('Detalle Costos'!$X$5:$X$158,MATCH(Resumen!AA11,'Detalle Costos'!$C$5:$C$158,0))*AG11,0) -> 62786.858 | AD11: =IFERROR(INDEX('Detalle Costos'!$Z$5:$Z$158,MATCH(Resumen!AA11,'Detalle Costos'!$C$5:$C$158,0))*AG11,0) -> 16565.702 | AE11: =IFERROR(INDEX('Detalle Costos'!$Y$5:$Y$158,MATCH(Resumen!AA11,'Detalle Costos'!$C$5:$C$158,0))*AG11,0) -> 844.0844 | AF11: =IFERROR(INDEX('Detalle Costos'!$AA$5:$AA$158,MATCH(Resumen!AA11,'Detalle Costos'!$C$5:$C$158,0))*AG11,0) -> 16463.356 | AG11: =AB11*G11 -> 96660 | AH11: 54 | AI11: =+AJ11/AH11 -> 1842.697 | AJ11: 99505.64 | AK11: =P11-AG11 -> 43740 | AL11: =AK11/P11 -> 0.31153846 | AM11: =R11 -> 9128 | AN11: =1882/26*G11 -> 3908.7692 | AO11: =SUM(AM11:AN11) -> 13036.769 | AP11: =50659/248*G11 -> 11030.589 | AQ11: =S11*0.03 -> 3938.16 | AR11: =AK11-AO11-AP11+AQ11 -> 23610.802 | AS11: =AR11/P11 -> 0.16816811 | AT11: =131251/248*G11 -> 28578.847 | AU11: =AR11-AT11 -> -4968.0447 | AV11: =AU11/P11 -> -0.035384934 | AW11: =123530/248*G11 -> 26897.661 | AX11: =AR11+AW11 -> 50508.463 | AY11: =AX11/P11 -> 0.35974689 | BA11: =P11/$G11 -> 2600 | BB11: =-AC11/$G11 -> -1162.7196 | BC11: =-AD11/$G11 -> -306.77225 | BD11: =-AE11/$G11 -> -15.631193 | BE11: =-AF11/$G11 -> -304.87696 | BF11: =-AG11/$G11 -> -1790 | BG11: =AK11/$G11 -> 810 | BH11: =-AM11/$G11 -> -169.03704 | BI11: =-AN11/$G11 -> -72.384615 | BJ11: =-AO11/$G11 -> -241.42165 | BK11: =-AP11/$G11 -> -204.27016 | BL11: =AQ11/$G11 -> 72.928889 | BM11: =AR11/$G11 -> 437.23708 | BN11: =-AT11/$G11 -> -529.2379 | BO11: =AU11/$G11 -> -92.000828 | BP11: =AW11/$G11 -> 498.10484 | BQ11: =AX11/$G11 -> 935.34191
B12: FEBRERO | C12: =B12 -> FEBRERO | D12: 146-2026 | E12: 46027 | F12: 46059 | G12: 10 | H12: POTA CONOS | I12: Conos | J12: 10 cm - up | K12: Tailandia | L12: Lat Krabang | M12: TSUJINO | N12: Jose | O12: 2100 | P12: 21000 | Q12: 2100 | R12: =3500/24*G12 -> 1458.3333 | S12: =P12-R12 -> 19541.667 | T12: 1 | U12: ECO MARIN 26006S | V12: 6444023300 | W12: COSCO | X12: PAITA | Y12: 10007969 | Z12: Compensación | AA12: =B12&Y12&Z12 -> FEBRERO10007969Compensación | AB12: =INDEX('Detalle Costos'!$L$5:$L$158,MATCH(Resumen!AA12,'Detalle Costos'!$C$5:$C$158,0))*1000*0+AI12 -> 1397.2773 | AC12: =IFERROR(INDEX('Detalle Costos'!$X$5:$X$158,MATCH(Resumen!AA12,'Detalle Costos'!$C$5:$C$158,0))*AG12,0) -> 11301.832 | AD12: =IFERROR(INDEX('Detalle Costos'!$Z$5:$Z$158,MATCH(Resumen!AA12,'Detalle Costos'!$C$5:$C$158,0))*AG12,0) -> 2127.4653 | AE12: =IFERROR(INDEX('Detalle Costos'!$Y$5:$Y$158,MATCH(Resumen!AA12,'Detalle Costos'!$C$5:$C$158,0))*AG12,0) -> 166.83162 | AF12: =IFERROR(INDEX('Detalle Costos'!$AA$5:$AA$158,MATCH(Resumen!AA12,'Detalle Costos'!$C$5:$C$158,0))*AG12,0) -> 376.64454 | AG12: =AB12*G12 -> 13972.773 | AH12: =+G12 -> 10 | AI12: 1397.2773 | AJ12: =+AI12*AH12 -> 13972.773 | AK12: =P12-AG12 -> 7027.2269 | AL12: =AK12/P12 -> 0.33462985 | AM12: =R12 -> 1458.3333 | AN12: =1882/26*G12 -> 723.84615 | AO12: =SUM(AM12:AN12) -> 2182.1795 | AP12: =56604/1634.3*G12 -> 346.35012 | AQ12: =S12*0.03 -> 586.25 | AR12: =AK12-AO12-AP12+AQ12 -> 5084.9473 | AS12: =AR12/P12 -> 0.24214035 | AT12: =148498/1634.3*G12 -> 908.63367 | AU12: =AR12-AT12 -> 4176.3136 | AV12: =AU12/P12 -> 0.19887208 | AW12: =123484.35/1634.3*G12 -> 755.57945 | AX12: =AR12+AW12 -> 5840.5268 | AY12: =AX12/P12 -> 0.27812032 | BA12: =P12/$G12 -> 2100 | BB12: =-AC12/$G12 -> -1130.1832 | BC12: =-AD12/$G12 -> -212.74653 | BD12: =-AE12/$G12 -> -16.683162 | BE12: =-AF12/$G12 -> -37.664454 | BF12: =-AG12/$G12 -> -1397.2773 | BG12: =AK12/$G12 -> 702.72269 | BH12: =-AM12/$G12 -> -145.83333 | BI12: =-AN12/$G12 -> -72.384615 | BJ12: =-AO12/$G12 -> -218.21795 | BK12: =-AP12/$G12 -> -34.635012 | BL12: =AQ12/$G12 -> 58.625 | BM12: =AR12/$G12 -> 508.49473 | BN12: =-AT12/$G12 -> -90.863367 | BO12: =AU12/$G12 -> 417.63136 | BP12: =AW12/$G12 -> 75.557945 | BQ12: =AX12/$G12 -> 584.05268
B13: FEBRERO | C13: =B13 -> FEBRERO | D13: 146-2026 | E13: 46027 | F13: 46059 | G13: 14 | H13: POTA NUCAS | I13: Nucas | J13: 500-up | K13: Tailandia | L13: Lat Krabang | M13: TSUJINO | N13: Jose | O13: 1700 | P13: =23800-344 -> 23456 | Q13: 1700 | R13: =3500/24*G13 -> 2041.6667 | S13: =P13-R13 -> 21414.333 | T13: 0 | Y13: 10005779 | Z13: Compensación | AA13: =B13&Y13&Z13 -> FEBRERO10005779Compensación | AB13: =INDEX('Detalle Costos'!$L$5:$L$158,MATCH(Resumen!AA13,'Detalle Costos'!$C$5:$C$158,0))*1000*0+AI13 -> 1859.7145 | AC13: =IFERROR(INDEX('Detalle Costos'!$X$5:$X$158,MATCH(Resumen!AA13,'Detalle Costos'!$C$5:$C$158,0))*AG13,0) -> 15847.871 | AD13: =IFERROR(INDEX('Detalle Costos'!$Z$5:$Z$158,MATCH(Resumen!AA13,'Detalle Costos'!$C$5:$C$158,0))*AG13,0) -> 5732.4075 | AE13: =IFERROR(INDEX('Detalle Costos'!$Y$5:$Y$158,MATCH(Resumen!AA13,'Detalle Costos'!$C$5:$C$158,0))*AG13,0) -> 189.9202 | AF13: =IFERROR(INDEX('Detalle Costos'!$AA$5:$AA$158,MATCH(Resumen!AA13,'Detalle Costos'!$C$5:$C$158,0))*AG13,0) -> 4265.8048 | AG13: =AB13*G13 -> 26036.003 | AH13: 14.849 | AI13: 1859.7145 | AJ13: =AI13*AH13 -> 27614.901 | AK13: =P13-AG13 -> -2580.0034 | AL13: =AK13/P13 -> -0.10999332 | AM13: =R13 -> 2041.6667 | AN13: =1882/26*G13 -> 1013.3846 | AO13: =SUM(AM13:AN13) -> 3055.0513 | AP13: =56604/1634.3*G13 -> 484.89017 | AQ13: =S13*0.03 -> 642.43 | AR13: =AK13-AO13-AP13+AQ13 -> -5477.5148 | AS13: =AR13/P13 -> -0.23352297 | AT13: =148498/1634.3*G13 -> 1272.0871 | AU13: =AR13-AT13 -> -6749.602 | AV13: =AU13/P13 -> -0.28775588 | AW13: =123484.35/1634.3*G13 -> 1057.8112 | AX13: =AR13+AW13 -> -4419.7036 | AY13: =AX13/P13 -> -0.18842529 | BA13: =P13/$G13 -> 1675.4286 | BB13: =-AC13/$G13 -> -1131.9908 | BC13: =-AD13/$G13 -> -409.45768 | BD13: =-AE13/$G13 -> -13.565729 | BE13: =-AF13/$G13 -> -304.70034 | BF13: =-AG13/$G13 -> -1859.7145 | BG13: =AK13/$G13 -> -184.28596 | BH13: =-AM13/$G13 -> -145.83333 | BI13: =-AN13/$G13 -> -72.384615 | BJ13: =-AO13/$G13 -> -218.21795 | BK13: =-AP13/$G13 -> -34.635012 | BL13: =AQ13/$G13 -> 45.887857 | BM13: =AR13/$G13 -> -391.25106 | BN13: =-AT13/$G13 -> -90.863367 | BO13: =AU13/$G13 -> -482.11443 | BP13: =AW13/$G13 -> 75.557945 | BQ13: =AX13/$G13 -> -315.69312
B14: ENERO | C14: =B14 -> ENERO | D14: 147-2026 | E14: 46032 | F14: 46050 | G14: 72 | H14: POTA ALAS CONGELADAS | I14: Alas | J14: 1 - 2 KGS. | K14: Tailandia | L14: Bangkok | M14: TSUJINO | N14: Jose | O14: =P14/G14 -> 1887.7083 | P14: =140400*0+135915 -> 135915 | Q14: =S14/G14 -> 1754.25 | R14: 9609 | S14: =P14-R14 -> 126306 | T14: 3 | U14: ECO MARIN 26004N | V14: LIMG01524600 | W14: ONE | X14: PAITA | Y14: 10006720 | Z14: Compensación | AA14: =B14&Y14&Z14 -> ENERO10006720Compensación | AB14: =INDEX('Detalle Costos'!$L$5:$L$158,MATCH(Resumen!AA14,'Detalle Costos'!$C$5:$C$158,0))*1000 -> 1720 | AC14: =IFERROR(INDEX('Detalle Costos'!$X$5:$X$158,MATCH(Resumen!AA14,'Detalle Costos'!$C$5:$C$158,0))*AG14,0) -> 81764.361 | AD14: =IFERROR(INDEX('Detalle Costos'!$Z$5:$Z$158,MATCH(Resumen!AA14,'Detalle Costos'!$C$5:$C$158,0))*AG14,0) -> 18919.258 | AE14: =IFERROR(INDEX('Detalle Costos'!$Y$5:$Y$158,MATCH(Resumen!AA14,'Detalle Costos'!$C$5:$C$158,0))*AG14,0) -> 1185.8374 | AF14: =IFERROR(INDEX('Detalle Costos'!$AA$5:$AA$158,MATCH(Resumen!AA14,'Detalle Costos'!$C$5:$C$158,0))*AG14,0) -> 21970.544 | AG14: =AB14*G14 -> 123840 | AH14: 69.7 | AI14: =+AJ14/AH14 -> 1723.916 | AJ14: 120156.94 | AK14: =P14-AG14 -> 12075 | AL14: =AK14/P14 -> 0.088842291 | AM14: =R14 -> 9609 | AN14: =1882/26*G14 -> 5211.6923 | AO14: =SUM(AM14:AN14) -> 14820.692 | AP14: =50659/248*G14 -> 14707.452 | AQ14: =S14*0.03 -> 3789.18 | AR14: =AK14-AO14-AP14+AQ14 -> -13663.964 | AS14: =AR14/P14 -> -0.10053316 | AT14: =131251/248*G14 -> 38105.129 | AU14: =AR14-AT14 -> -51769.093 | AV14: =AU14/P14 -> -0.38089315 | AW14: =123530/248*G14 -> 35863.548 | AX14: =AR14+AW14 -> 22199.584 | AY14: =AX14/P14 -> 0.16333432 | BA14: =P14/$G14 -> 1887.7083 | BB14: =-AC14/$G14 -> -1135.6161 | BC14: =-AD14/$G14 -> -262.76747 | BD14: =-AE14/$G14 -> -16.469963 | BE14: =-AF14/$G14 -> -305.14645 | BF14: =-AG14/$G14 -> -1720 | BG14: =AK14/$G14 -> 167.70833 | BH14: =-AM14/$G14 -> -133.45833 | BI14: =-AN14/$G14 -> -72.384615 | BJ14: =-AO14/$G14 -> -205.84295 | BK14: =-AP14/$G14 -> -204.27016 | BL14: =AQ14/$G14 -> 52.6275 | BM14: =AR14/$G14 -> -189.77728 | BN14: =-AT14/$G14 -> -529.2379 | BO14: =AU14/$G14 -> -719.01518 | BP14: =AW14/$G14 -> 498.10484 | BQ14: =AX14/$G14 -> 308.32756
B15: ENERO | C15: =B15 -> ENERO | E15: 46053 | F15: 46053 | G15: 0 | H15: RESIDUOS DE POTA | I15: Residuos | J15: Residuos | K15: Residuos | L15: Residuos | M15: PROVEEDORA DE PRODUCTOS MARINOS | O15: 0 | P15: 24314.28 | Q15: 0 | R15: 0 | S15: =P15-R15 -> 24314.28 | AB15: 0 | AC15: =IFERROR(INDEX('Detalle Costos'!$X$5:$X$158,MATCH(Resumen!AA15,'Detalle Costos'!$C$5:$C$158,0))*AG15,0) -> 0 | AD15: =IFERROR(INDEX('Detalle Costos'!$Z$5:$Z$158,MATCH(Resumen!AA15,'Detalle Costos'!$C$5:$C$158,0))*AG15,0) -> 0 | AE15: =IFERROR(INDEX('Detalle Costos'!$Y$5:$Y$158,MATCH(Resumen!AA15,'Detalle Costos'!$C$5:$C$158,0))*AG15,0) -> 0 | AF15: =IFERROR(INDEX('Detalle Costos'!$AA$5:$AA$158,MATCH(Resumen!AA15,'Detalle Costos'!$C$5:$C$158,0))*AG15,0) -> 0 | AG15: =AB15*G15 -> 0 | AK15: =P15-AG15 -> 24314.28 | AL15: =AK15/P15 -> 1 | AM15: =R15 -> 0 | AN15: =1882/26*G15 -> 0 | AO15: =SUM(AM15:AN15) -> 0 | AP15: =50659/248*G15 -> 0 | AQ15: 0 | AR15: =AK15-AO15-AP15+AQ15 -> 24314.28 | AS15: =AR15/P15 -> 1 | AT15: =131251/248*G15 -> 0 | AU15: =AR15-AT15 -> 24314.28 | AV15: =AU15/P15 -> 1 | AW15: =123530/248*G15 -> 0 | AX15: =AR15+AW15 -> 24314.28 | AY15: =AX15/P15 -> 1 | BA15: 0 | BB15: 0 | BC15: 0 | BD15: 0 | BE15: 0 | BF15: 0 | BG15: 0 | BH15: 0 | BI15: 0 | BJ15: 0 | BK15: 0 | BL15: 0 | BM15: 0 | BN15: 0 | BO15: 0 | BP15: 0 | BQ15: 0
B16: FEBRERO | C16: =B16 -> FEBRERO | D16: 148-2026 | E16: 15 | F16: 46055 | G16: 135 | H16: POTA FILETE CONGELADO | I16: Filete | J16: 2-4 (B) | K16: España | L16: Vigo | M16: FOOD & BEVERAGES TRADERS | N16: Jorge | O16: 1650 | P16: 222750 | Q16: 1480.963 | R16: 22820 | S16: =P16-R16 -> 199930 | T16: 5 | U16: ODYSSEUS 606N | V16: 59582082 | W16: HAPAG | X16: PAITA | Y16: 10005721 | Z16: Compensación | AA16: =B16&Y16&Z16 -> FEBRERO10005721Compensación | AB16: =INDEX('Detalle Costos'!$L$5:$L$158,MATCH(Resumen!AA16,'Detalle Costos'!$C$5:$C$158,0))*1000*0+AI16 -> 1861.4473 | AC16: =IFERROR(INDEX('Detalle Costos'!$X$5:$X$158,MATCH(Resumen!AA16,'Detalle Costos'!$C$5:$C$158,0))*AG16,0) -> 152495.08 | AD16: =IFERROR(INDEX('Detalle Costos'!$Z$5:$Z$158,MATCH(Resumen!AA16,'Detalle Costos'!$C$5:$C$158,0))*AG16,0) -> 50378.669 | AE16: =IFERROR(INDEX('Detalle Costos'!$Y$5:$Y$158,MATCH(Resumen!AA16,'Detalle Costos'!$C$5:$C$158,0))*AG16,0) -> 2680.0174 | AF16: =IFERROR(INDEX('Detalle Costos'!$AA$5:$AA$158,MATCH(Resumen!AA16,'Detalle Costos'!$C$5:$C$158,0))*AG16,0) -> 45741.622 | AG16: =AB16*G16 -> 251295.39 | AH16: =+G16 -> 135 | AI16: =AJ16/AH16 -> 1861.4473 | AJ16: 251295.39 | AK16: =P16-AG16 -> -28545.39 | AL16: =AK16/P16 -> -0.1281499 | AM16: =R16 -> 22820 | AN16: =1882/26*G16 -> 9771.9231 | AO16: =SUM(AM16:AN16) -> 32591.923 | AP16: =56604/1634.3*G16 -> 4675.7266 | AQ16: =S16*0.03 -> 5997.9 | AR16: =AK16-AO16-AP16+AQ16 -> -59815.14 | AS16: =AR16/P16 -> -0.26853037 | AT16: =148498/1634.3*G16 -> 12266.554 | AU16: =AR16-AT16 -> -72081.694 | AV16: =AU16/P16 -> -0.32359908 | AW16: =124162.35/1634.3*G16 -> 10256.328 | AX16: =AR16+AW16 -> -49558.811 | AY16: =AX16/P16 -> -0.22248625 | BA16: =P16/$G16 -> 1650 | BB16: =-AC16/$G16 -> -1129.5932 | BC16: =-AD16/$G16 -> -373.17533 | BD16: =-AE16/$G16 -> -19.85198 | BE16: =-AF16/$G16 -> -338.82683 | BF16: =-AG16/$G16 -> -1861.4473 | BG16: =AK16/$G16 -> -211.44733 | BH16: =-AM16/$G16 -> -169.03704 | BI16: =-AN16/$G16 -> -72.384615 | BJ16: =-AO16/$G16 -> -241.42165 | BK16: =-AP16/$G16 -> -34.635012 | BL16: =AQ16/$G16 -> 44.428889 | BM16: =AR16/$G16 -> -443.07511 | BN16: =-AT16/$G16 -> -90.863367 | BO16: =AU16/$G16 -> -533.93848 | BP16: =AW16/$G16 -> 75.972802 | BQ16: =AX16/$G16 -> -367.10231
B17: FEBRERO | C17: =B17 -> FEBRERO | D17: 149-2026 | E17: 16 | F17: 46055 | G17: 27 | H17: POTA REPRODUCTORES | I17: Rejos | K17: España | L17: Vigo | M17: GLOBAL OCEAN | N17: Jorge | O17: =P17/G17 -> 2873.5185 | P17: =79650*0+77585 -> 77585 | Q17: =S17/G17 -> 2711.8889 | R17: 4364 | S17: =P17-R17 -> 73221 | T17: 1 | Y17: 10007567 | Z17: Entradas | AA17: =B17&Y17&Z17 -> FEBRERO10007567Entradas | AB17: =INDEX('Detalle Costos'!$L$5:$L$158,MATCH(Resumen!AA17,'Detalle Costos'!$C$5:$C$158,0))*1000*0+AI17 -> 1829.8235 | AC17: =IFERROR(INDEX('Detalle Costos'!$X$5:$X$158,MATCH(Resumen!AA17,'Detalle Costos'!$C$5:$C$158,0))*AG17,0) -> 30498.569 | AD17: =IFERROR(INDEX('Detalle Costos'!$Z$5:$Z$158,MATCH(Resumen!AA17,'Detalle Costos'!$C$5:$C$158,0))*AG17,0) -> 8738.5729 | AE17: =IFERROR(INDEX('Detalle Costos'!$Y$5:$Y$158,MATCH(Resumen!AA17,'Detalle Costos'!$C$5:$C$158,0))*AG17,0) -> 554.46203 | AF17: =IFERROR(INDEX('Detalle Costos'!$AA$5:$AA$158,MATCH(Resumen!AA17,'Detalle Costos'!$C$5:$C$158,0))*AG17,0) -> 9613.63 | AG17: =AB17*G17 -> 49405.233 | AH17: 26.302 | AI17: =+AI4 -> 1829.8235 | AJ17: 48129 | AK17: =P17-AG17 -> 28179.767 | AL17: =AK17/P17 -> 0.36321153 | AM17: =R17 -> 4364 | AN17: =1882/26*G17 -> 1954.3846 | AO17: =SUM(AM17:AN17) -> 6318.3846 | AP17: =56604/1634.3*G17 -> 935.14532 | AQ17: =S17*0.03 -> 2196.63 | AR17: =AK17-AO17-AP17+AQ17 -> 23122.867 | AS17: =AR17/P17 -> 0.29803269 | AT17: =148498/1634.3*G17 -> 2453.3109 | AU17: =AR17-AT17 -> 20669.556 | AV17: =AU17/P17 -> 0.26641175 | AW17: =124162.35/1634.3*G17 -> 2051.2656 | AX17: =AR17+AW17 -> 25174.132 | AY17: =AX17/P17 -> 0.32447164 | BA17: =P17/$G17 -> 2873.5185 | BB17: =-AC17/$G17 -> -1129.5766 | BC17: =-AD17/$G17 -> -323.65085 | BD17: =-AE17/$G17 -> -20.535631 | BE17: =-AF17/$G17 -> -356.06037 | BF17: =-AG17/$G17 -> -1829.8235 | BG17: =AK17/$G17 -> 1043.6951 | BH17: =-AM17/$G17 -> -161.62963 | BI17: =-AN17/$G17 -> -72.384615 | BJ17: =-AO17/$G17 -> -234.01425 | BK17: =-AP17/$G17 -> -34.635012 | BL17: =AQ17/$G17 -> 81.356667 | BM17: =AR17/$G17 -> 856.40247 | BN17: =-AT17/$G17 -> -90.863367 | BO17: =AU17/$G17 -> 765.5391 | BP17: =AW17/$G17 -> 75.972802 | BQ17: =AX17/$G17 -> 932.37527
B18: FEBRERO | C18: =B18 -> FEBRERO | D18: 150-2026A | E18: 325 | F18: 46069 | G18: 26 | H18: POTA REJOS CONGELADOS | I18: Rejos | J18: 1-2 KG | K18: España | L18: Vigo | M18: OVERSEA | N18: Avelino | O18: 2600 | P18: 67600 | Q18: 2432.1538 | R18: 4364 | S18: =P18-R18 -> 63236 | T18: 1 | U18: CAPE SPENCER 608N | V18: 11400418 | W18: HAPAG | X18: PAITA | Y18: 10007162 | Z18: Compensación | AA18: =B18&Y18&Z18 -> FEBRERO10007162Compensación | AB18: =INDEX('Detalle Costos'!$L$5:$L$158,MATCH(Resumen!AA18,'Detalle Costos'!$C$5:$C$158,0))*1000*0+AI18 -> 1715.2908 | AC18: =IFERROR(INDEX('Detalle Costos'!$X$5:$X$158,MATCH(Resumen!AA18,'Detalle Costos'!$C$5:$C$158,0))*AG18,0) -> 27996.818 | AD18: =IFERROR(INDEX('Detalle Costos'!$Z$5:$Z$158,MATCH(Resumen!AA18,'Detalle Costos'!$C$5:$C$158,0))*AG18,0) -> 7988.6675 | AE18: =IFERROR(INDEX('Detalle Costos'!$Y$5:$Y$158,MATCH(Resumen!AA18,'Detalle Costos'!$C$5:$C$158,0))*AG18,0) -> 415.9275 | AF18: =IFERROR(INDEX('Detalle Costos'!$AA$5:$AA$158,MATCH(Resumen!AA18,'Detalle Costos'!$C$5:$C$158,0))*AG18,0) -> 8196.1487 | AG18: =AB18*G18 -> 44597.561 | AH18: =+G18 -> 26 | AI18: 1715.2908 | AJ18: =AI18*AH18 -> 44597.561 | AK18: =P18-AG18 -> 23002.439 | AL18: =AK18/P18 -> 0.34027276 | AM18: =R18 -> 4364 | AN18: =1882/26*G18 -> 1882 | AO18: =SUM(AM18:AN18) -> 6246 | AP18: =56604/1634.3*G18 -> 900.51031 | AQ18: =S18*0.03 -> 1897.08 | AR18: =AK18-AO18-AP18+AQ18 -> 17753.008 | AS18: =AR18/P18 -> 0.26261847 | AT18: =148498/1634.3*G18 -> 2362.4475 | AU18: =AR18-AT18 -> 15390.561 | AV18: =AU18/P18 -> 0.22767102 | AW18: =124162.35/1634.3*G18 -> 1975.2928 | AX18: =AR18+AW18 -> 19728.301 | AY18: =AX18/P18 -> 0.29183878 | BA18: =P18/$G18 -> 2600 | BB18: =-AC18/$G18 -> -1076.8007 | BC18: =-AD18/$G18 -> -307.25644 | BD18: =-AE18/$G18 -> -15.997212 | BE18: =-AF18/$G18 -> -315.23649 | BF18: =-AG18/$G18 -> -1715.2908 | BG18: =AK18/$G18 -> 884.70918 | BH18: =-AM18/$G18 -> -167.84615 | BI18: =-AN18/$G18 -> -72.384615 | BJ18: =-AO18/$G18 -> -240.23077 | BK18: =-AP18/$G18 -> -34.635012 | BL18: =AQ18/$G18 -> 72.964615 | BM18: =AR18/$G18 -> 682.80802 | BN18: =-AT18/$G18 -> -90.863367 | BO18: =AU18/$G18 -> 591.94465 | BP18: =AW18/$G18 -> 75.972802 | BQ18: =AX18/$G18 -> 758.78082
B19: FEBRERO | C19: =B19 -> FEBRERO | D19: 151-2025 | E19: 26 | F19: 46080 | G19: 27 | H19: POTA MEMBRANA PRECOCIDA | I19: Membrana | K19: China | L19: Qingdao | M19: Hunan Jinyueyang | O19: =P19/G19 -> 1429.8611 | P19: =39150*0+38606.25 -> 38606.25 | Q19: =S19/G19 -> 1322.4537 | R19: 2900 | S19: =P19-R19 -> 35706.25 | T19: 1 | U19: ECO SIROCCO 26009S | V19: 6445502950 | W19: COSCO | X19: PAITA | Y19: 10009332 | Z19: Entradas | AA19: =B19&Y19&Z19 -> FEBRERO10009332Entradas | AB19: =AI19 -> 1529.9065 | AC19: =IFERROR(INDEX('Detalle Costos'!$X$5:$X$158,MATCH(Resumen!AA19,'Detalle Costos'!$C$5:$C$158,0))*AG19,0) -> 34256.34 | AD19: =IFERROR(INDEX('Detalle Costos'!$Z$5:$Z$158,MATCH(Resumen!AA19,'Detalle Costos'!$C$5:$C$158,0))*AG19,0) -> 6268.5858 | AE19: =IFERROR(INDEX('Detalle Costos'!$Y$5:$Y$158,MATCH(Resumen!AA19,'Detalle Costos'!$C$5:$C$158,0))*AG19,0) -> 633.18765 | AF19: =IFERROR(INDEX('Detalle Costos'!$AA$5:$AA$158,MATCH(Resumen!AA19,'Detalle Costos'!$C$5:$C$158,0))*AG19,0) -> 149.36167 | AG19: =AB19*G19 -> 41307.475 | AH19: 26.625 | AI19: =AJ19/AH19 -> 1529.9065 | AJ19: 40733.76 | AK19: =P19-AG19 -> -2701.2249 | AL19: =AK19/P19 -> -0.069968591 | AM19: =R19 -> 2900 | AN19: =1882/26*G19 -> 1954.3846 | AO19: =SUM(AM19:AN19) -> 4854.3846 | AP19: =56604/1634.3*G19 -> 935.14532 | AQ19: =S19*0.03 -> 1071.1875 | AR19: =AK19-AO19-AP19+AQ19 -> -7419.5674 | AS19: =AR19/P19 -> -0.19218565 | AT19: =148498/1634.3*G19 -> 2453.3109 | AU19: =AR19-AT19 -> -9872.8783 | AV19: =AU19/P19 -> -0.25573264 | AW19: =124162.35/1634.3*G19 -> 2051.2656 | AX19: =AR19+AW19 -> -5368.3017 | AY19: =AX19/P19 -> -0.13905266 | BA19: =P19/$G19 -> 1429.8611 | BB19: =-AC19/$G19 -> -1268.7533 | BC19: =-AD19/$G19 -> -232.16984 | BD19: =-AE19/$G19 -> -23.451395 | BE19: =-AF19/$G19 -> -5.5319137 | BF19: =-AG19/$G19 -> -1529.9065 | BG19: =AK19/$G19 -> -100.04537 | BH19: =-AM19/$G19 -> -107.40741 | BI19: =-AN19/$G19 -> -72.384615 | BJ19: =-AO19/$G19 -> -179.79202 | BK19: =-AP19/$G19 -> -34.635012 | BL19: =AQ19/$G19 -> 39.673611 | BM19: =AR19/$G19 -> -274.79879 | BN19: =-AT19/$G19 -> -90.863367 | BO19: =AU19/$G19 -> -365.66216 | BP19: =AW19/$G19 -> 75.972802 | BQ19: =AX19/$G19 -> -198.82599
