Workbook

Sheet Gráficos
B3: PERU FROST - RESUMEN RESULTADOS CONGELADOS 2026 (MILES US$)
B4: Concepto | C4: 46023 | D4: 46054 | E4: 46082 | F4: 46113 | G4: Acum 2026
B5: TM Materia Prima | C5: =[1]Resumen!$D$4 -> 1877.215 | D5: =[1]Resumen!$D$5 -> 3149.786 | E5: =[1]Resumen!$D$6 -> 2255.518 | F5: =[1]Resumen!$D$7 -> 2853.189 | G5: =SUM(C5:F5) -> 10135.708
B6: TM Vendidas PT | C6: =TD!B7 -> 248 | D6: =TD!C7 -> 1634.3 | E6: =TD!D7 -> 1995.8 | F6: =TD!E7 -> 2110.11 | G6: =TD!F7 -> 1978.33
B7: Venta | C7: =TD!B8 -> 564615.28 | D7: =TD!C8 -> 2769824.5 | E7: =TD!D8 -> 3896418.3 | F7: =TD!E8 -> 4888920 | G7: =TD!F8 -> 5016103.5
B8: Utilidad Neta | C8: =TD!B16 -> -96824.986 | D8: =TD!C16 -> -535236.79 | E8: =TD!D16 -> -326649.27 | F8: =TD!E16 -> 89405.43 | G8: =TD!F16 -> 401885.57
B9: Margen Neto % | C9: =C8/C7 -> -0.17148843 | D9: =D8/D7 -> -0.19323852 | E9: =E8/E7 -> -0.083833214 | F9: =F8/F7 -> 0.018287358 | G9: =G8/G7 -> 0.080119074
B12: 1. RESULTADOS INTERNOS
B62: 2. BENCHMARK INDUSTRIA PERUANA DE CONGELADOS (VERITRADE)
B87: Top 15 Exportadores — Productos Congelados (Alas, Filete, Nuca, Tentáculo, Reproductor) | J87: Top 15 Exportadores — Productos Cocidos (Alas Cocidas, Filete Daruma)
B89: Nro | C89: Exportador | D89: Valor FOB (US$) | E89: TM | F89: Precio por TM | J89: Nro | K89: Exportador | L89: Valor FOB (US$) | M89: TM | N89: Precio por TM
B90: 1 | C90: Industrial Pesquera Santa Monica S.A. | D90: 12800672 | E90: 7371.2 | F90: 1737 | J90: 1 | K90: Costa Mira Sociedad Anonima Cerrada | L90: 9211788 | M90: 2579.8 | N90: 3571
B91: 2 | C91: Pesquera Hermanos Cordova S.A.C. | D91: 11792528 | E91: 7242.6 | F91: 1628 | J91: 2 | K91: KSL S.A.C. | L91: 5319083 | M91: 1670.5 | N91: 3184
B92: 3 | C92: Oceano Seafood S.A. | D92: 11724680 | E92: 6746.5 | F92: 1738 | J92: 3 | K92: Pacific Freezing Company S.A.C. | L92: 4286058 | M92: 1338 | N92: 3203
B93: 4 | C93: Productora Andina De Congelados S.R.L. | D93: 8847640 | E93: 5227.2 | F93: 1693 | J93: 4 | K93: Oceano Seafood S.A. | L93: 4050574 | M93: 1190.4 | N93: 3403
B94: 5 | C94: Costa Mira Sociedad Anonima Cerrada | D94: 8496998 | E94: 4421.2 | F94: 1922 | J94: 5 | K94: Frigosa Sociedad S.A.C. | L94: 3921103 | M94: 1215 | N94: 3227
B95: 6 | C95: Novaperu S.A.C. | D95: 6857126 | E95: 3973.8 | F95: 1726 | J95: 6 | K95: Dexim Srl | L95: 3883786 | M95: 1076.8 | N95: 3607
B96: 7 | C96: Peru Frost Sociedad Anonima Cerrada | D96: 6231879 | E96: 3981.4 | F96: 1565 | J96: 7 | K96: Inversiones Holding Peru Sociedad Anonim | L96: 2905633 | M96: 847.7 | N96: 3428
B97: 8 | C97: Esmeralda Corp S.A.C. | D97: 6229395 | E97: 3736 | F97: 1667 | J97: 8 | K97: Corporacion Pesquera Del Mar Sociedad An | L97: 2751416 | M97: 796 | N97: 3457
B98: 9 | C98: Proveedora De Productos Marinos Sociedad | D98: 6166547 | E98: 3730.3 | F98: 1653 | J98: 9 | K98: Mik Carpe S.A.C. | L98: 2475284 | M98: 735 | N98: 3368
B99: 10 | C99: Peruvian Sea Food S.A. | D99: 6164559 | E99: 3692.9 | F99: 1669 | J99: 10 | K99: Seafrost S.A.C. | L99: 2135285 | M99: 602.9 | N99: 3542
B100: 11 | C100: Pesquera Supercetus S.A.C. | D100: 5928869 | E100: 3562.1 | F100: 1664 | J100: 11 | K100: Pesquera Exalmar S.A.A. | L100: 1926814 | M100: 563.2 | N100: 3421
B101: 12 | C101: Transmarina Del Peru S.A.C. | D101: 5879029 | E101: 3591.3 | F101: 1637 | J101: 12 | K101: Refrigerados Fisholg & Hijos Sociedad An | L101: 1802223 | M101: 539.5 | N101: 3340
... B104: 15 | C104: Seafrost S.A.C. | D104: 5556358 | E104: 3119.3 | F104: 1781 | J104: 15 | K104: Industrial Pesquera Santa Monica S.A. | L104: 1603048 | M104: 475.7 | N104: 3370

Sheet TD
A2: ANÁLISIS DE RENTABILIDAD
A4: EEFF PERU FROST (USD) | AG4: Enero | AH4: Febrero | AI4: Marzo | AJ4: Abril | AK4: Real | AL4: Budget
B5: Etiquetas de columna | J5: ANÁLISIS UNITARIO | T5: ANÁLISIS VÉRTICAL | AF5: Venta CFR | AG5: =B8/1000 -> 564.61528 | AH5: =C8/1000 -> 2769.8245 | AI5: =D8/1000 -> 3896.4183 | AJ5: =E8/1000 -> 4888.92 | AK5: =F8/1000 -> 5016.1035 | AL5: =H8/1000 -> 0
A6: Valores | B6: ENERO | C6: FEBRERO | D6: MARZO | E6: ABRIL | F6: MAYO | G6: Total general | J6: NOMBRE | K6: ENERO | L6: FEBRERO | M6: MARZO | N6: ABRIL | O6: TOTAL | T6: NOMBRE | U6: ENERO | V6: FEBRERO | W6: MARZO | X6: ABRIL | Y6: MAYO | Z6: TOTAL | AF6: Utilidad Neta | AG6: =B16/1000 -> -96.824986 | AH6: =C16/1000 -> -535.23679 | AI6: =D16/1000 -> -326.64927 | AJ6: =E16/1000 -> 89.40543 | AK6: =F16/1000 -> 401.88557 | AL6: =H16/1000 -> 0
A7: Suma de Cantidad | B7: 248 | C7: 1634.3 | D7: 1995.8 | E7: 2110.11 | F7: 1978.33 | G7: 7966.54
A8: Suma de VALOR CFR | B8: 564615.28 | C8: 2769824.5 | D8: 3896418.3 | E8: 4888920 | F8: 5016103.5 | G8: 17135882 | J8: Suma de VALOR CFR | K8: =B8/B$7 -> 2276.6745 | L8: =C8/C$7 -> 1694.8079 | M8: =D8/D$7 -> 1952.309 | N8: =E8/E$7 -> 2316.9029 | O8: =F8/F$7 -> 2535.5242 | T8: Suma de VALOR CFR | U8: =B8/B$8 -> 1 | V8: =C8/C$8 -> 1 | W8: =D8/D$8 -> 1 | X8: =E8/E$8 -> 1 | Y8: =F8/F$8 -> 1 | Z8: =G8/G$8 -> 1
A9: Suma de COSTO VENTAS | B9: 435516.57 | C9: 2818814 | D9: 3665924.7 | E9: 4170536.7 | F9: 4155714.9 | G9: 15246507 | J9: Suma de COSTO VENTAS | K9: =B9/B$7 -> 1756.1152 | L9: =C9/C$7 -> 1724.7837 | M9: =D9/D$7 -> 1836.8197 | N9: =E9/E$7 -> 1976.4546 | O9: =F9/F$7 -> 2100.6176 | T9: Suma de COSTO VENTAS | U9: =B9/B$8 -> 0.77135101 | V9: =C9/C$8 -> 1.0176869 | W9: =D9/D$8 -> 0.94084474 | X9: =E9/E$8 -> 0.85305889 | Y9: =F9/F$8 -> 0.8284747 | Z9: =G9/G$8 -> 0.8897416 | AN9: Resumen de Precios por TM Peru Frost vs Mercado
A10: Suma de UTILIDAD BRUTA | B10: 129098.71 | C10: -48989.478 | D10: 230493.64 | E10: 718383.33 | F10: 860388.64 | G10: 1889374.8 | J10: Suma de UTILIDAD BRUTA | K10: =B10/B$7 -> 520.55932 | L10: =C10/C$7 -> -29.975817 | M10: =D10/D$7 -> 115.48935 | N10: =E10/E$7 -> 340.44828 | O10: =F10/F$7 -> 434.90653 | T10: Suma de UTILIDAD BRUTA | U10: =B10/B$8 -> 0.22864899 | V10: =C10/C$8 -> -0.017686853 | W10: =D10/D$8 -> 0.05915526 | X10: =E10/E$8 -> 0.14694111 | Y10: =F10/F$8 -> 0.1715253 | Z10: =G10/G$8 -> 0.1102584 | AF10: Acum Abril venta y rentabilidad por producto
A11: Suma de GASTO VENTAS | B11: 59134.419 | C11: 356852.55 | D11: 432727.48 | E11: 480312.05 | F11: 369157.75 | G11: 1698184.2 | J11: Suma de GASTO VENTAS | K11: =B11/B$7 -> 238.44524 | L11: =C11/C$7 -> 218.35192 | M11: =D11/D$7 -> 216.81906 | N11: =E11/E$7 -> 227.62418 | O11: =F11/F$7 -> 186.60069 | T11: Suma de GASTO VENTAS | U11: =B11/B$8 -> 0.104734 | V11: =C11/C$8 -> 0.1288358 | W11: =D11/D$8 -> 0.11105776 | X11: =E11/E$8 -> 0.098245021 | Y11: =F11/F$8 -> 0.073594523 | Z11: =G11/G$8 -> 0.099101072 | AG11: Venta CFR | AH11: Utilidad Neta | AN11: PRODUCTO | AO11: PERU FROST | AP11: INDUSTRIA PERUANA
A12: Suma de GASTO ADM | B12: 50659 | C12: 56604 | D12: 78579 | E12: 65076 | F12: 78579 | G12: 329497 | J12: Suma de GASTO ADM | K12: =B12/B$7 -> 204.27016 | L12: =C12/C$7 -> 34.635012 | M12: =D12/D$7 -> 39.372182 | N12: =E12/E$7 -> 30.840098 | O12: =F12/F$7 -> 39.719865 | T12: Suma de GASTO ADM | U12: =B12/B$8 -> 0.089723041 | V12: =C12/C$8 -> 0.020435952 | W12: =D12/D$8 -> 0.020166983 | X12: =E12/E$8 -> 0.013310915 | Y12: =F12/F$8 -> 0.015665347 | Z12: =G12/G$8 -> 0.019228483 | AF12: FILETE CONGELADO | AG12: 3148.23 | AH12: -1138.4306 | AN12: FILETE CONGELADO | AO12: 1323 | AP12: 1525
A13: Suma de DRAWBACK | B13: 15120.72 | C13: 75707.235 | D13: 108636.57 | E13: 138095.15 | F13: 143706.68 | G13: 481266.35 | J13: Suma de DRAWBACK | K13: =B13/B$7 -> 60.970645 | L13: =C13/C$7 -> 46.323952 | M13: =D13/D$7 -> 54.432593 | N13: =E13/E$7 -> 65.444526 | O13: =F13/F$7 -> 72.640396 | T13: Suma de DRAWBACK | U13: =B13/B$8 -> 0.026780572 | V13: =C13/C$8 -> 0.027332864 | W13: =D13/D$8 -> 0.027881136 | X13: =E13/E$8 -> 0.028246555 | Y13: =F13/F$8 -> 0.028649065 | Z13: =G13/G$8 -> 0.028085298 | AF13: REJOS CONGELADOS | AG13: 2631.849 | AH13: 311.25595 | AN13: FILETE DARUMA | AO13: 3292 | AP13: 3417
A14: Suma de UTILIDAD OPERATIVA | B14: 34426.014 | C14: -386738.79 | D14: -172176.27 | E14: 311090.43 | F14: 556358.57 | G14: 342959.95 | J14: Suma de UTILIDAD OPERATIVA | K14: =B14/B$7 -> 138.81457 | L14: =C14/C$7 -> -236.6388 | M14: =D14/D$7 -> -86.269301 | N14: =E14/E$7 -> 147.42854 | O14: =F14/F$7 -> 281.22637 | T14: Suma de UTILIDAD OPERATIVA | U14: =B14/B$8 -> 0.060972515 | V14: =C14/C$8 -> -0.13962574 | W14: =D14/D$8 -> -0.044188343 | X14: =E14/E$8 -> 0.063631729 | Y14: =F14/F$8 -> 0.11091449 | Z14: =G14/G$8 -> 0.020014141 | AF14: ALAS CONGELADAS | AG14: 2273.427 | AH14: -451.32788 | AN14: REPRODUCTOR | AO14: 2724 | AP14: 2704
A15: Suma de GASTO FINANCIERO | B15: 131251 | C15: 148498 | D15: 154473 | E15: 221685 | F15: 154473 | G15: 810380 | J15: Suma de GASTO FINANCIERO | K15: =B15/B$7 -> 529.2379 | L15: =C15/C$7 -> 90.863367 | M15: =D15/D$7 -> 77.399038 | N15: =E15/E$7 -> 105.0585 | O15: =F15/F$7 -> 78.082524 | T15: Suma de GASTO FINANCIERO | U15: =B15/B$8 -> 0.23246094 | V15: =C15/C$8 -> 0.053612783 | W15: =D15/D$8 -> 0.039644871 | X15: =E15/E$8 -> 0.045344371 | Y15: =F15/F$8 -> 0.030795417 | Z15: =G15/G$8 -> 0.04729141 | AF15: FILETE DARUMA | AG15: 1927.8 | AH15: 513.07693 | AN15: NUCA | AO15: 1123 | AP15: 1171
A16: Suma de UTILIDAD NETA | B16: -96824.986 | C16: -535236.79 | D16: -326649.27 | E16: 89405.43 | F16: 401885.57 | G16: -467420.05 | J16: Suma de UTILIDAD NETA | K16: =B16/B$7 -> -390.42333 | L16: =C16/C$7 -> -327.50216 | M16: =D16/D$7 -> -163.66834 | N16: =E16/E$7 -> 42.370033 | O16: =F16/F$7 -> 203.14385 | T16: Suma de UTILIDAD NETA | U16: =B16/B$8 -> -0.17148843 | V16: =C16/C$8 -> -0.19323852 | W16: =D16/D$8 -> -0.083833214 | X16: =E16/E$8 -> 0.018287358 | Y16: =F16/F$8 -> 0.080119074 | Z16: =G16/G$8 -> -0.027277269 | AF16: REPRODUCTORES | AG16: 599.405 | AH16: 126.98725 | AN16: ALAS COCIDAS | AO16: 3240 | AP16: 3318
A17: Suma de DEPRECIACIÓN | B17: 123530 | C17: 124152.39 | D17: 123360.73 | E17: 123484.35 | F17: 123484.35 | G17: 618011.82 | J17: Suma de DEPRECIACIÓN | K17: =B17/B$7 -> 498.10484 | L17: =C17/C$7 -> 75.96671 | M17: =D17/D$7 -> 61.810166 | N17: =E17/E$7 -> 58.520338 | O17: =F17/F$7 -> 62.418479 | T17: Suma de DEPRECIACIÓN | U17: =B17/B$8 -> 0.21878614 | V17: =C17/C$8 -> 0.044823199 | W17: =D17/D$8 -> 0.031660032 | X17: =E17/E$8 -> 0.025258002 | Y17: =F17/F$8 -> 0.024617584 | Z17: =G17/G$8 -> 0.036065365 | AF17: NUCAS | AG17: 514.83 | AH17: -431.34411 | AN17: ALAS CONGELADAS | AO17: 1509 | AP17: 1579
A18: Suma de EBITDA | B18: 157956.01 | C18: -262586.39 | D18: -48815.541 | E18: 434574.78 | F18: 679842.92 | G18: 960971.78 | J18: Suma de EBITDA | K18: =B18/B$7 -> 636.91941 | L18: =C18/C$7 -> -160.67209 | M18: =D18/D$7 -> -24.459135 | N18: =E18/E$7 -> 205.94887 | O18: =F18/F$7 -> 343.64485 | T18: Suma de EBITDA | U18: =B18/B$8 -> 0.27975866 | V18: =C18/C$8 -> -0.094802539 | W18: =D18/D$8 -> -0.012528311 | X18: =E18/E$8 -> 0.08888973 | Y18: =F18/F$8 -> 0.13553208 | Z18: =G18/G$8 -> 0.056079506 | AF18: ALAS COCIDAS | AG18: 384.2577 | AH18: 138.02447 | AN18: TENTACULO | AO18: 2290 | AP18: 2288
A19: EBITDA NETO | B19: =B16+B17 -> 26705.014 | C19: =C16+C17 -> -411084.39 | D19: =D16+D17 -> -203288.54 | E19: =E16+E17 -> 212889.78 | F19: =F16+F17 -> 525369.92 | G19: =G16+G17 -> 150591.78 | AF19: OTROS | AG19: =SUM(AG20:AG23) -> 420.26689 | AH19: =SUM(AH20:AH23) -> 130.12557
AF20: POTA CONOS | AG20: 231.72 | AH20: 0.42290479
AF21: POTA RECORTES COCIDOS | AG21: 67.5 | AH21: 15.71277 | AR21: 0.0692
AF22: POTA SUCKERS CONGELADO | AG22: 30.25 | AH22: 23.193002 | AR22: 0.0637
A23: ANÁLISIS POR PRODUCTO | AF23: RESIDUOS DE POTA | AG23: 90.79689 | AH23: 90.79689 | AR23: 0.0634
AR24: 0.0478
A25: RANKING DE VENTAS (USD) | J25: UTILIDAD NETA (USD) | T25: EBITDA (USD) | AF25: Acum Abril venta y rentabilidad por cliente | AR25: 0.0459
A26: Suma de VALOR CFR | B26: Etiquetas de columna | J26: Suma de UTILIDAD NETA | K26: Etiquetas de columna | T26: Suma de EBITDA | U26: Etiquetas de columna | AG26: Venta CFR | AH26: Utilidad Neta | AR26: 0.0371
A27: Etiquetas de fila | B27: ENERO | C27: FEBRERO | D27: MARZO | E27: ABRIL | F27: MAYO | G27: Total general | H27: % | J27: Etiquetas de fila | K27: ENERO | L27: FEBRERO | M27: MARZO | N27: ABRIL | O27: MAYO | P27: Total general | Q27: MG | T27: Etiquetas de fila | U27: ENERO | V27: FEBRERO | W27: MARZO | X27: ABRIL | Y27: MAYO | Z27: Total general | AA27: MG | AF27: TSUJINO | AG27: 2790.273 | AH27: -709.0403 | AR27: 0.0337
A28: POTA FILETE CONGELADO | B28: 94800 | C28: 1147500 | D28: 430960 | E28: 1474970 | F28: 1054710 | G28: 4202940 | H28: =G28/$G$43 -> 0.2452713 | J28: POTA FILETE CONGELADO | K28: -37529.914 | L28: -527635.82 | M28: -236860.72 | N28: -426642.81 | O28: -124076.38 | P28: -1352745.6 | Q28: =P28/G28 -> -0.32185699 | T28: POTA FILETE CONGELADO | U28: 11782.537 | V28: -392498.52 | W28: -196072.42 | X28: -294323.88 | Y28: -52870.473 | Z28: -923982.76 | AA28: =Z28/G28 -> -0.21984201 | AF28: LONGKOU JIABAO AQUATIC | AG28: 1406.7 | AH28: 394.79634 | AR28: 0.0337
A29: POTA REJOS CONGELADOS | B29: 149248 | C29: 532695 | D29: 779600 | E29: 1170306 | F29: 1105650 | G29: 3737499 | H29: =G29/$G$43 -> 0.21810953 | J29: POTA REJOS CONGELADOS | K29: -6524.1514 | L29: 100438.17 | M29: 95452.995 | N29: 133277.89 | O29: 334078.31 | P29: 656723.2 | Q29: =P29/G29 -> 0.17571194 | T29: POTA REJOS CONGELADOS | U29: 53020.634 | V29: 135306.93 | W29: 141531.24 | X29: 208350.76 | Y29: 387187.69 | Z29: 925397.25 | AA29: =Z29/G29 -> 0.24759799 | AF29: KULALIA | AG29: 1378.9217 | AH29: 101.0003 | AR29: 0.0333
A30: POTA FILETE DARUMA | C30: 91800 | D30: 1004400 | E30: 831600 | F30: 1142100 | G30: 3069900 | H30: =G30/$G$43 -> 0.1791504 | J30: POTA FILETE DARUMA | L30: 27314.314 | M30: 235571.77 | N30: 258609.83 | O30: 85056.072 | P30: 606551.99 | Q30: =P30/G30 -> 0.19758037 | T30: POTA FILETE DARUMA | V30: 31818.891 | W30: 280675.55 | X30: 293942.86 | Y30: 126784.87 | Z30: 733222.17 | AA30: =Z30/G30 -> 0.23884236 | AF30: AVANCE GROUP | AG30: 1097.2 | AH30: -468.13754 | AR30: 0.0333
A31: POTA ALAS CONGELADAS | B31: 135915 | C31: 710550 | D31: 768480 | E31: 658482 | F31: 591300 | G31: 2864727 | H31: =G31/$G$43 -> 0.1671771 | J31: POTA ALAS CONGELADAS | K31: -51593.825 | L31: -196390.88 | M31: -180010.05 | N31: -99943.542 | O31: -66299.328 | P31: -594237.62 | Q31: =P31/G31 -> -0.20743255 | T31: POTA ALAS CONGELADAS | U31: 22374.852 | V31: -119763.03 | W31: -112799.84 | X31: -43734.581 | Y31: -24570.53 | Z31: -278493.13 | AA31: =Z31/G31 -> -0.097214544 | AF31: FOOD & BEVERAGES TRADERS | AG31: 935.406 | AH31: -74.238541 | AR31: 0.032
A32: POTA ALAS COCIDAS | D32: 177221.7 | E32: 207036 | F32: 423756 | G32: 808013.7 | H32: =G32/$G$43 -> 0.04715332 | J32: POTA ALAS COCIDAS | M32: 46804.601 | N32: 37657.94 | O32: 85538.437 | P32: 170000.98 | Q32: =P32/G32 -> 0.21039368 | T32: POTA ALAS COCIDAS | W32: 54321.898 | X32: 46343.977 | Y32: 100611.38 | Z32: 201277.26 | AA32: =Z32/G32 -> 0.2491013 | AF32: Qingdao Haiyujia | AG32: 595.782 | AH32: 101.96621 | AR32: 0.0318
A33: POTA REPRODUCTORES | B33: 74064 | C33: 77585 | D33: 139200 | E33: 308556 | F33: 154700 | G33: 754105 | H33: =G33/$G$43 -> 0.044007365 | J33: POTA REPRODUCTORES | K33: 4395.863 | L33: 22418.891 | M33: 34140.783 | N33: 70608.829 | O33: 46503.823 | P33: 178068.19 | Q33: =P33/G33 -> 0.23613182 | T33: POTA REPRODUCTORES | U33: 31106.774 | V33: 26923.467 | W33: 41240.453 | X33: 87588.313 | Y33: 53809.875 | Z33: 240668.88 | AA33: =Z33/G33 -> 0.31914506 | AF33: Longkou Yunfeng Aquatic Food | AG33: 575.1 | AH33: -44.789183 | AR33: 0.0316
A34: POTA NUCAS | B34: 35874 | C34: 23456 | D34: 455500 | F34: 225525 | G34: 740355 | H34: =G34/$G$43 -> 0.043204955 | J34: POTA NUCAS | K34: -19625.979 | L34: -6759.1635 | M34: -375692.17 | O34: -142861.01 | P34: -544938.33 | Q34: =P34/G34 -> -0.73605004 | T34: POTA NUCAS | U34: 961.96962 | V34: -4429.2651 | W34: -322096.63 | Y34: -117149.33 | Z34: -442713.25 | AA34: =Z34/G34 -> -0.59797429 | AF34: OTROS | AG34: =SUM(AG35:AG51) -> 2863.8454 | AH34: =SUM(AH35:AH51) -> -19.037084 | AR34: 0.0302
A35: POTA CONOS | B35: 50400 | C35: 69000 | D35: 76800 | E35: 35520 | F35: 43200 | G35: 274920 | H35: =G35/$G$43 -> 0.016043528 | J35: POTA CONOS | K35: -10261.26 | L35: 14427.098 | M35: -2235.7781 | N35: -8371.57 | O35: 1716.3337 | P35: -4725.1762 | Q35: =P35/G35 -> -0.017187459 | T35: POTA CONOS | U35: 14394.966 | V35: 20095.379 | W35: 4446.2637 | X35: -4740.1197 | Y35: 5088.3578 | Z35: 39284.847 | AA35: =Z35/G35 -> 0.14289556 | AF35: OVERSEA | AG35: 354.595 | AH35: 86.215827 | AR35: 0.03
A36: POTA RECORTES COCIDOS | E36: 67500 | F36: 130950 | G36: 198450 | H36: =G36/$G$43 -> 0.011580962 | J36: POTA RECORTES COCIDOS | N36: 12648.31 | O36: 116108.82 | P36: 128757.14 | Q36: =P36/G36 -> 0.64881398 | T36: POTA RECORTES COCIDOS | X36: 17064.939 | Y36: 123695.88 | Z36: 140760.82 | AA36: =Z36/G36 -> 0.70930117 | AF36: Pesciro Asia International LTD. | AG36: 352.35 | AH36: -117.23253
A37: POTA MEMBRANA PRECOCIDA | C37: 38606.25 | D37: 37800 | E37: 52500 | G37: 128906.25 | H37: =G37/$G$43 -> 0.0075225922 | J37: POTA MEMBRANA PRECOCIDA | L37: -4537.6993 | M37: 29722.688 | N37: 44868.518 | P37: 70053.507 | Q37: =P37/G37 -> 0.54344538 | T37: POTA MEMBRANA PRECOCIDA | V37: -33.122782 | W37: 33481.336 | X37: 49162.463 | Z37: 82610.676 | AA37: =Z37/G37 -> 0.64085858 | AF37: OCEANUS FISH | AG37: 340.564 | AH37: -36.175426
A38: POTA TELILLA PRECOCIDA | C38: 38606.25 | E38: 52200 | F38: 53812.5 | G38: 144618.75 | H38: =G38/$G$43 -> 0.0084395279 | J38: POTA TELILLA PRECOCIDA | L38: -4537.6993 | N38: 44593.734 | O38: 47651.427 | P38: 87707.461 | Q38: =P38/G38 -> 0.60647365 | T38: POTA TELILLA PRECOCIDA | V38: -33.122782 | X38: 48863.141 | Y38: 51339.578 | Z38: 100169.6 | AA38: =Z38/G38 -> 0.69264598 | AF38: LONGKOU BOHAI | AG38: 334.8 | AH38: 61.759822
A39: POTA SUCKERS CONGELADO | E39: 30250 | G39: 30250 | H39: =G39/$G$43 -> 0.0017653016 | J39: POTA SUCKERS CONGELADO | N39: 22098.301 | P39: 22098.301 | Q39: =P39/G39 -> 0.73052236 | T39: POTA SUCKERS CONGELADO | X39: 26056.909 | Z39: 26056.909 | AA39: =Z39/G39 -> 0.86138543 | AF39: GLOBAL OCEAN | AG39: 285.485 | AH39: 31.414281
A40: RESIDUOS DE POTA | B40: 24314.28 | C40: 40026 | D40: 26456.61 | G40: 90796.89 | H40: =G40/$G$43 -> 0.0052986413 | J40: RESIDUOS DE POTA | K40: 24314.28 | L40: 40026 | M40: 26456.61 | P40: 90796.89 | Q40: =P40/G40 -> 1 | T40: RESIDUOS DE POTA | U40: 24314.28 | V40: 40026 | W40: 26456.61 | Z40: 90796.89 | AA40: =Z40/G40 -> 1 | AF40: DAIRECK S.A. | AG40: 280.782 | AH40: -291.00909
A41: POTA TUBOALETA | F41: 54000 | G41: 54000 | H41: =G41/$G$43 -> 0.0031512823 | J41: POTA TUBOALETA | O41: -8875.5707 | P41: -8875.5707 | Q41: =P41/G41 -> -0.16436242 | T41: POTA TUBOALETA | Y41: -5082.0436 | Z41: -5082.0436 | AA41: =Z41/G41 -> -0.094111919 | AF41: YANTAI TAIXI FOODSTUFF | AG41: 279.504 | AH41: 19.044143
A42: POTA LABIOS CONGELADOS | F42: 36400 | G42: 36400 | H42: =G42/$G$43 -> 0.0021241977 | J42: POTA LABIOS CONGELADOS | O42: 27344.638 | P42: 27344.638 | Q42: =P42/G42 -> 0.75122632 | T42: POTA LABIOS CONGELADOS | Y42: 30997.664 | Z42: 30997.664 | AA42: =Z42/G42 -> 0.85158418
...

Sheet Resumen
G2: X | H2: X | M2: X | P2: X | AV2: X | AW2: X | BB2: ANÁLISIS UNITARIO
B3: MES LINK | C3: MES EJERCICIO | D3: FP | E3: Emision | F3: Fecha Embarque | G3: Cantidad | H3: Producto | I3: Corte | J3: Espec. | K3: País | L3: Puerto | M3: Cliente (Razón Social) | N3: Contacto | O3: Precio TM | P3: VALOR CFR | Q3: FOB / TM | R3: Costo Flete | S3: VALOR FOB | T3: Cantidad de FCL (Contenedores) | U3: M/V Nave | V3: Booking | W3: Naviera | X3: Puerto | Y3: CÓDIGO | Z3: Categoría | AA3: MATCH | AB3: COSTO UNITARIO | AC3: Materia Prima | AD3: MOD | AE3: Envases | AF3: CIF | AG3: COSTO VENTAS | AH3: Cant | AI3: C.U | AJ3: Cotos Vta | AK3: UTILIDAD BRUTA | AL3: MARGEN BRUTO | AM3: Flete | AN3: Otros Gastos Ventas | AO3: SS Logístico | AP3: GASTO VENTAS | AQ3: GASTO ADM | AR3: DRAWBACK | AS3: UTILIDAD OPERATIVA | AT3: MARGEN OPERATIVO | AU3: GASTO FINANCIERO | AV3: UTILIDAD NETA | AW3: MARGEN NETO | AX3: DEPRECIACIÓN | AY3: EBITDA | AZ3: MARGEN EBITDA | BB3: PRECIO CFR | BC3: Materia Prima | BD3: MOD | BE3: Envases | BF3: CIF | BG3: COSTO VENTAS | BH3: UTILIDAD BRUTA | BI3: Flete | BJ3: SS Logístico | BK3: GASTO VENTAS | BL3: GASTO ADM | BM3: DRAWBACK | BN3: UTILIDAD OPERATIVA | BO3: GASTO FINANCIERO | BP3: UTILIDAD NETA | BQ3: DEPRECIACIÓN | BR3: EBITDA
B4: ENERO | C4: =B4 -> ENERO | D4: 127-2025 | E4: 325 | F4: 46033 | G4: 26 | H4: POTA REPRODUCTORES | I4: Rejos | K4: España | L4: Valencia | M4: OCEANUS FISH | N4: Ignacio / Ives | O4: =P4/G4 -> 2848.6154 | P4: =78000*0+74064 -> 74064 | Q4: =S4/G4 -> 2670.3846 | R4: 4634 | S4: =P4-R4 -> 69430 | T4: 1 | U4: MERSIN EXPRESS 603N | V4: 26106924 | W4: HAPAG | X4: PAITA | Y4: 10007567 | Z4: Compensación | AA4: =B4&Y4&Z4 -> ENERO10007567Compensación | AB4: =INDEX('Detalle Costos'!$L$5:$L$158,MATCH(Resumen!AA4,'Detalle Costos'!$C$5:$C$158,0))*1000+4623.769999996/248 -> 1848.6442 | AC4: =IFERROR(INDEX('Detalle Costos'!$X$5:$X$158,MATCH(Resumen!AA4,'Detalle Costos'!$C$5:$C$158,0))*AG4,0) -> 30321.714 | AD4: =IFERROR(INDEX('Detalle Costos'!$Z$5:$Z$158,MATCH(Resumen!AA4,'Detalle Costos'!$C$5:$C$158,0))*AG4,0) -> 7452.4837 | AE4: =IFERROR(INDEX('Detalle Costos'!$Y$5:$Y$158,MATCH(Resumen!AA4,'Detalle Costos'!$C$5:$C$158,0))*AG4,0) -> 447.27651 | AF4: =IFERROR(INDEX('Detalle Costos'!$AA$5:$AA$158,MATCH(Resumen!AA4,'Detalle Costos'!$C$5:$C$158,0))*AG4,0) -> 7428.0104 | AG4: =AI4*G4+6518.87/248*G4-47.35*G4 -> 45649.485 | AH4: =48.96-AH17 -> 22.658 | AI4: 1776.8137 | AJ4: =89589.14-AJ17 -> 41460.14 | AK4: =P4-AG4 -> 28414.515 | AL4: =AK4/P4 -> 0.38364813 | AM4: =R4 -> 4634 | AN4: =118461.136538461/5988.21*G4 -> 514.34227 | AO4: =1882/26*G4 -> 1882 | AP4: =SUM(AM4:AO4) -> 7030.3423 | AQ4: =50659/248*G4 -> 5311.0242 | AR4: =S4*0.03 -> 2082.9 | AS4: =AK4-AP4-AQ4+AR4 -> 18156.049 | AT4: =AS4/P4 -> 0.24513999 | AU4: =131251/248*G4 -> 13760.185 | AV4: =AS4-AU4 -> 4395.863 | AW4: =AV4/P4 -> 0.059352223 | AX4: =123530/248*G4 -> 12950.726 | AY4: =AS4+AX4 -> 31106.774 | AZ4: =AY4/P4 -> 0.41999857 | BB4: =P4/$G4 -> 2848.6154 | BC4: =-AC4/$G4 -> -1166.2198 | BD4: =-AD4/$G4 -> -286.63399 | BE4: =-AE4/$G4 -> -17.202943 | BF4: =-AF4/$G4 -> -285.69271 | BG4: =-AG4/$G4 -> -1755.7494 | BH4: =AK4/$G4 -> 1092.866 | BI4: =-AM4/$G4 -> -178.23077 | BJ4: =-AO4/$G4 -> -72.384615 | BK4: =-AP4/$G4 -> -270.39778 | BL4: =-AQ4/$G4 -> -204.27016 | BM4: =AR4/$G4 -> 80.111538 | BN4: =AS4/$G4 -> 698.30956 | BO4: =-AU4/$G4 -> -529.2379 | BP4: =AV4/$G4 -> 169.07165 | BQ4: =AX4/$G4 -> 498.10484 | BR4: =AY4/$G4 -> 1196.4144
B5: ENERO | C5: =B5 -> ENERO | D5: 128-2025B | E5: 325 | F5: 46053 | G5: 17.04 | H5: POTA NUCAS | I5: Nucas | J5: 1000-up | K5: Tailandia | L5: Lat Krabang | M5: DAIRECK S.A. | N5: Julieta | O5: 1850 | P5: 31524 | Q5: 1656.338 | R5: =3300/24*G5 -> 2343 | S5: =P5-R5 -> 29181 | T5: 1 | U5: ECO SIROCCO 26005S | V5: 6443191850 | W5: COSCO | X5: PAITA | Y5: 10005779 | Z5: Compensación | AA5: =B5&Y5&Z5 -> ENERO10005779Compensación | AB5: =INDEX('Detalle Costos'!$L$5:$L$158,MATCH(Resumen!AA5,'Detalle Costos'!$C$5:$C$158,0))*1000+4623.769999996/248 -> 1948.6442 | AC5: =IFERROR(INDEX('Detalle Costos'!$X$5:$X$158,MATCH(Resumen!AA5,'Detalle Costos'!$C$5:$C$158,0))*AG5,0) -> 19902.439 | AD5: =IFERROR(INDEX('Detalle Costos'!$Z$5:$Z$158,MATCH(Resumen!AA5,'Detalle Costos'!$C$5:$C$158,0))*AG5,0) -> 6720.2922 | AE5: =IFERROR(INDEX('Detalle Costos'!$Y$5:$Y$158,MATCH(Resumen!AA5,'Detalle Costos'!$C$5:$C$158,0))*AG5,0) -> 241.50424 | AF5: =IFERROR(INDEX('Detalle Costos'!$AA$5:$AA$158,MATCH(Resumen!AA5,'Detalle Costos'!$C$5:$C$158,0))*AG5,0) -> 4759.6795 | AG5: =AI5*G5+6518.87/248*G5-47.35*G5 -> 31623.915 | AH5: 17.04 | AI5: 1876.9278 | AJ5: 33696.517 | AK5: =P5-AG5 -> -99.914788 | AL5: =AK5/P5 -> -0.0031694832 | AM5: =R5 -> 2343 | AN5: =118461.136538461/5988.21*G5 -> 337.09201 | AO5: =1882/26*G5 -> 1233.4338 | AP5: =SUM(AM5:AO5) -> 3913.5259 | AQ5: =50659/248*G5 -> 3480.7635 | AR5: =S5*0.03 -> 875.43 | AS5: =AK5-AP5-AQ5+AR5 -> -6618.7742 | AT5: =AS5/P5 -> -0.20995985 | AU5: =131251/248*G5 -> 9018.2139 | AV5: =AS5-AU5 -> -15636.988 | AW5: =AV5/P5 -> -0.49603439 | AX5: =123530/248*G5 -> 8487.7065 | AY5: =AS5+AX5 -> 1868.9323 | AZ5: =AY5/P5 -> 0.059286012 | BB5: =P5/$G5 -> 1850 | BC5: =-AC5/$G5 -> -1167.9835 | BD5: =-AD5/$G5 -> -394.38335 | BE5: =-AE5/$G5 -> -14.172784 | BF5: =-AF5/$G5 -> -279.32391 | BG5: =-AG5/$G5 -> -1855.8635 | BH5: =AK5/$G5 -> -5.8635439 | BI5: =-AM5/$G5 -> -137.5 | BJ5: =-AO5/$G5 -> -72.384615 | BK5: =-AP5/$G5 -> -229.66701 | BL5: =-AQ5/$G5 -> -204.27016 | BM5: =AR5/$G5 -> 51.375 | BN5: =AS5/$G5 -> -388.42572 | BO5: =-AU5/$G5 -> -529.2379 | BP5: =AV5/$G5 -> -917.66362 | BQ5: =AX5/$G5 -> 498.10484 | BR5: =AY5/$G5 -> 109.67912
B6: ENERO | C6: =B6 -> ENERO | D6: 128-2025B | E6: 325 | F6: 46053 | G6: 3 | H6: POTA NUCAS | I6: Nucas | J6: 500 - 1 kg. | K6: Tailandia | L6: Lat Krabang | M6: DAIRECK S.A. | N6: Julieta | O6: 1450 | P6: 4350 | Q6: 1450 | R6: =3300/24*G6 -> 412.5 | S6: =P6-R6 -> 3937.5 | T6: 0 | V6: 6443191850 | W6: COSCO | X6: PAITA | Y6: 10005781 | Z6: Compensación | AA6: =B6&Y6&Z6 -> ENERO10005781Compensación | AB6: =INDEX('Detalle Costos'!$L$5:$L$158,MATCH(Resumen!AA6,'Detalle Costos'!$C$5:$C$158,0))*1000+4623.769999996/248 -> 1998.6442 | AC6: =IFERROR(INDEX('Detalle Costos'!$X$5:$X$158,MATCH(Resumen!AA6,'Detalle Costos'!$C$5:$C$158,0))*AG6,0) -> 3521.4666 | AD6: =IFERROR(INDEX('Detalle Costos'!$Z$5:$Z$158,MATCH(Resumen!AA6,'Detalle Costos'!$C$5:$C$158,0))*AG6,0) -> 1150.8275 | AE6: =IFERROR(INDEX('Detalle Costos'!$Y$5:$Y$158,MATCH(Resumen!AA6,'Detalle Costos'!$C$5:$C$158,0))*AG6,0) -> 46.818855 | AF6: =IFERROR(INDEX('Detalle Costos'!$AA$5:$AA$158,MATCH(Resumen!AA6,'Detalle Costos'!$C$5:$C$158,0))*AG6,0) -> 848.47774 | AG6: =AI6*G6+6518.87/248*G6-47.35*G6 -> 5567.5906 | AH6: 3 | AI6: 1876.9278 | AJ6: 5803.9692 | AK6: =P6-AG6 -> -1217.5906 | AL6: =AK6/P6 -> -0.27990589 | AM6: =R6 -> 412.5 | AN6: =118461.136538461/5988.21*G6 -> 59.347185 | AO6: =1882/26*G6 -> 217.15385 | AP6: =SUM(AM6:AO6) -> 689.00103 | AQ6: =50659/248*G6 -> 612.81048 | AR6: =S6*0.03 -> 118.125 | AS6: =AK6-AP6-AQ6+AR6 -> -2401.2771 | AT6: =AS6/P6 -> -0.55201773 | AU6: =131251/248*G6 -> 1587.7137 | AV6: =AS6-AU6 -> -3988.9909 | AW6: =AV6/P6 -> -0.91700939 | AX6: =123530/248*G6 -> 1494.3145 | AY6: =AS6+AX6 -> -906.96263 | AZ6: =AY6/P6 -> -0.20849716 | BB6: =P6/$G6 -> 1450 | BC6: =-AC6/$G6 -> -1173.8222 | BD6: =-AD6/$G6 -> -383.60916 | BE6: =-AE6/$G6 -> -15.606285 | BF6: =-AF6/$G6 -> -282.82591 | BG6: =-AG6/$G6 -> -1855.8635 | BH6: =AK6/$G6 -> -405.86354 | BI6: =-AM6/$G6 -> -137.5 | BJ6: =-AO6/$G6 -> -72.384615 | BK6: =-AP6/$G6 -> -229.66701 | BL6: =-AQ6/$G6 -> -204.27016 | BM6: =AR6/$G6 -> 39.375 | BN6: =AS6/$G6 -> -800.42572 | BO6: =-AU6/$G6 -> -529.2379 | BP6: =AV6/$G6 -> -1329.6636 | BQ6: =AX6/$G6 -> 498.10484 | BR6: =AY6/$G6 -> -302.32088
B7: ENERO | C7: =B7 -> ENERO | D7: 128-2025B | E7: 325 | F7: 46053 | G7: 3.96 | H7: POTA REJOS CONGELADOS | I7: Rejos | J7: 1 - 2 kgs. | K7: Tailandia | L7: Lat Krabang | M7: DAIRECK S.A. | N7: Julieta | O7: =P7/G7 -> 2234.3434 | P7: 8848 | Q7: 2800 | R7: =3300/24*G7 -> 544.5 | S7: =P7-R7 -> 8303.5 | T7: 0 | V7: 6443191850 | W7: COSCO | X7: PAITA | Y7: 10007162 | Z7: Compensación | AA7: =B7&Y7&Z7 -> ENERO10007162Compensación | AB7: =INDEX('Detalle Costos'!$L$5:$L$158,MATCH(Resumen!AA7,'Detalle Costos'!$C$5:$C$158,0))*1000+4623.769999996/248 -> 1808.6442 | AC7: =IFERROR(INDEX('Detalle Costos'!$X$5:$X$158,MATCH(Resumen!AA7,'Detalle Costos'!$C$5:$C$158,0))*AG7,0) -> 4545.8938 | AD7: =IFERROR(INDEX('Detalle Costos'!$Z$5:$Z$158,MATCH(Resumen!AA7,'Detalle Costos'!$C$5:$C$158,0))*AG7,0) -> 1199.3899 | AE7: =IFERROR(INDEX('Detalle Costos'!$Y$5:$Y$158,MATCH(Resumen!AA7,'Detalle Costos'!$C$5:$C$158,0))*AG7,0) -> 61.113395 | AF7: =IFERROR(INDEX('Detalle Costos'!$AA$5:$AA$158,MATCH(Resumen!AA7,'Detalle Costos'!$C$5:$C$158,0))*AG7,0) -> 1191.9798 | AG7: =AI7*G7+6518.87/248*G7-47.35*G7 -> 6998.3769 | AH7: 3.16 | AI7: 1788.3311 | AJ7: 5822.9227 | AK7: =P7-AG7 -> 1849.6231 | AL7: =AK7/P7 -> 0.2090442 | AM7: =R7 -> 544.5 | AN7: =118461.136538461/5988.21*G7 -> 78.338285 | AO7: =1882/26*G7 -> 286.64308 | AP7: =SUM(AM7:AO7) -> 909.48136 | AQ7: =50659/248*G7 -> 808.90984 | AR7: =S7*0.03 -> 249.105 | AS7: =AK7-AP7-AQ7+AR7 -> 380.33691 | AT7: =AS7/P7 -> 0.042985636 | AU7: =131251/248*G7 -> 2095.7821 | AV7: =AS7-AU7 -> -1715.4452 | AW7: =AV7/P7 -> -0.19387943 | AX7: =123530/248*G7 -> 1972.4952 | AY7: =AS7+AX7 -> 2352.8321 | AZ7: =AY7/P7 -> 0.26591683 | BB7: =P7/$G7 -> 2234.3434 | BC7: =-AC7/$G7 -> -1147.953 | BD7: =-AD7/$G7 -> -302.87623 | BE7: =-AE7/$G7 -> -15.432675 | BF7: =-AF7/$G7 -> -301.00501 | BG7: =-AG7/$G7 -> -1767.2669 | BH7: =AK7/$G7 -> 467.07654 | BI7: =-AM7/$G7 -> -137.5 | BJ7: =-AO7/$G7 -> -72.384615 | BK7: =-AP7/$G7 -> -229.66701 | BL7: =-AQ7/$G7 -> -204.27016 | BM7: =AR7/$G7 -> 62.905303 | BN7: =AS7/$G7 -> 96.044674 | BO7: =-AU7/$G7 -> -529.2379 | BP7: =AV7/$G7 -> -433.19323 | BQ7: =AX7/$G7 -> 498.10484 | BR7: =AY7/$G7 -> 594.14951
B8: ENERO | C8: =B8 -> ENERO | D8: 129-2025 | E8: 45982 | F8: 46031 | G8: 24 | H8: POTA CONOS | I8: Conos | K8: Tailandia | L8: Bangkok | M8: TSUJINO | N8: Jose | O8: 2100 | P8: 50400 | Q8: 1962.5 | R8: 3300 | S8: =P8-R8 -> 47100 | T8: 1 | U8: ECO MARIN 26002S | V8: 6440924270 | W8: COSCO | X8: PAITA | Y8: 10007969 | Z8: Compensación | AA8: =B8&Y8&Z8 -> ENERO10007969Compensación | AB8: =INDEX('Detalle Costos'!$L$5:$L$158,MATCH(Resumen!AA8,'Detalle Costos'!$C$5:$C$158,0))*1000+4623.769999996/248 -> 1658.6442 | AC8: =IFERROR(INDEX('Detalle Costos'!$X$5:$X$158,MATCH(Resumen!AA8,'Detalle Costos'!$C$5:$C$158,0))*AG8,0) -> 30120.853 | AD8: =IFERROR(INDEX('Detalle Costos'!$Z$5:$Z$158,MATCH(Resumen!AA8,'Detalle Costos'!$C$5:$C$158,0))*AG8,0) -> 5277.3639 | AE8: =IFERROR(INDEX('Detalle Costos'!$Y$5:$Y$158,MATCH(Resumen!AA8,'Detalle Costos'!$C$5:$C$158,0))*AG8,0) -> 399.40993 | AF8: =IFERROR(INDEX('Detalle Costos'!$AA$5:$AA$158,MATCH(Resumen!AA8,'Detalle Costos'!$C$5:$C$158,0))*AG8,0) -> 3160.4311 | AG8: =AI8*G8+6518.87/248*G8-47.35*G8 -> 38958.058 | AH8: 24 | AI8: =+AJ8/AH8 -> 1644.3167 | AJ8: 39463.6 | AK8: =P8-AG8 -> 11441.942 | AL8: =AK8/P8 -> 0.22702266 | AM8: =R8 -> 3300 | AN8: =118461.136538461/5988.21*G8 -> 474.77748 | AO8: =1882/26*G8 -> 1737.2308 | AP8: =SUM(AM8:AO8) -> 5512.0083 | AQ8: =50659/248*G8 -> 4902.4839 | AR8: =S8*0.03 -> 1413 | AS8: =AK8-AP8-AQ8+AR8 -> 2440.4499 | AT8: =AS8/P8 -> 0.048421625 | AU8: =131251/248*G8 -> 12701.71 | AV8: =AS8-AU8 -> -10261.26 | AW8: =AV8/P8 -> -0.20359642 | AX8: =123530/248*G8 -> 11954.516 | AY8: =AS8+AX8 -> 14394.966 | AZ8: =AY8/P8 -> 0.2856144 | BB8: =P8/$G8 -> 2100 | BC8: =-AC8/$G8 -> -1255.0355 | BD8: =-AD8/$G8 -> -219.89016 | BE8: =-AE8/$G8 -> -16.642081 | BF8: =-AF8/$G8 -> -131.68463 | BG8: =-AG8/$G8 -> -1623.2524 | BH8: =AK8/$G8 -> 476.74758 | BI8: =-AM8/$G8 -> -137.5 | BJ8: =-AO8/$G8 -> -72.384615 | BK8: =-AP8/$G8 -> -229.66701 | BL8: =-AQ8/$G8 -> -204.27016 | BM8: =AR8/$G8 -> 58.875 | BN8: =AS8/$G8 -> 101.68541 | BO8: =-AU8/$G8 -> -529.2379 | BP8: =AV8/$G8 -> -427.55249 | BQ8: =AX8/$G8 -> 498.10484 | BR8: =AY8/$G8 -> 599.79025
B9: ENERO | C9: =B9 -> ENERO | D9: 137-2025 | E9: 46000 | F9: 46043 | G9: 24 | H9: POTA FILETE CONGELADO | I9: Filete | J9: 2 - 4 kg | K9: Taiwan | L9: KAOHSIUNG | M9: TSUJINO | N9: Jose | O9: =P9/G9 -> 1966.6667 | P9: =48000*0+47200 -> 47200 | Q9: =S9/G9 -> 1841.5417 | R9: 3003 | S9: =P9-R9 -> 44197 | T9: 1 | U9: ECO MARIN 25052N | V9: LIMF26385300 | W9: ONE | X9: PAITA | Y9: 10005721 | Z9: Compensación | AA9: =B9&Y9&Z9 -> ENERO10005721Compensación | AB9: =INDEX('Detalle Costos'!$L$5:$L$158,MATCH(Resumen!AA9,'Detalle Costos'!$C$5:$C$158,0))*1000+4623.769999996/248 -> 1878.6442 | AC9: =IFERROR(INDEX('Detalle Costos'!$X$5:$X$158,MATCH(Resumen!AA9,'Detalle Costos'!$C$5:$C$158,0))*AG9,0) -> 27003.901 | AD9: =IFERROR(INDEX('Detalle Costos'!$Z$5:$Z$158,MATCH(Resumen!AA9,'Detalle Costos'!$C$5:$C$158,0))*AG9,0) -> 9795.8891 | AE9: =IFERROR(INDEX('Detalle Costos'!$Y$5:$Y$158,MATCH(Resumen!AA9,'Detalle Costos'!$C$5:$C$158,0))*AG9,0) -> 426.26796 | AF9: =IFERROR(INDEX('Detalle Costos'!$AA$5:$AA$158,MATCH(Resumen!AA9,'Detalle Costos'!$C$5:$C$158,0))*AG9,0) -> 7297.1068 | AG9: =AI9*G9+6518.87/248*G9-47.35*G9 -> 44523.165 | AH9: 23.7 | AI9: 1876.1961 | AJ9: 44778.445 | AK9: =P9-AG9 -> 2676.8346 | AL9: =AK9/P9 -> 0.056712598 | AM9: =R9 -> 3003 | AN9: =118461.136538461/5988.21*G9 -> 474.77748 | AO9: =1882/26*G9 -> 1737.2308 | AP9: =SUM(AM9:AO9) -> 5215.0083 | AQ9: =50659/248*G9 -> 4902.4839 | AR9: =S9*0.03 -> 1325.91 | AS9: =AK9-AP9-AQ9+AR9 -> -6114.7475 | AT9: =AS9/P9 -> -0.12954973 | AU9: =131251/248*G9 -> 12701.71 | AV9: =AS9-AU9 -> -18816.457 | AW9: =AV9/P9 -> -0.39865375 | AX9: =123530/248*G9 -> 11954.516 | AY9: =AS9+AX9 -> 5839.7686 | AZ9: =AY9/P9 -> 0.12372391 | BB9: =P9/$G9 -> 1966.6667 | BC9: =-AC9/$G9 -> -1125.1626 | BD9: =-AD9/$G9 -> -408.16205 | BE9: =-AE9/$G9 -> -17.761165 | BF9: =-AF9/$G9 -> -304.04612 | BG9: =-AG9/$G9 -> -1855.1319 | BH9: =AK9/$G9 -> 111.53478 | BI9: =-AM9/$G9 -> -125.125 | BJ9: =-AO9/$G9 -> -72.384615 | BK9: =-AP9/$G9 -> -217.29201 | BL9: =-AQ9/$G9 -> -204.27016 | BM9: =AR9/$G9 -> 55.24625 | BN9: =AS9/$G9 -> -254.78115 | BO9: =-AU9/$G9 -> -529.2379 | BP9: =AV9/$G9 -> -784.01905 | BQ9: =AX9/$G9 -> 498.10484 | BR9: =AY9/$G9 -> 243.32369
B10: ENERO | C10: =B10 -> ENERO | D10: 140-2025 | E10: 347 | F10: 46038 | G10: 24 | H10: POTA FILETE CONGELADO | I10: Filete | J10: 2-4kg | K10: Japón | L10: Sendai | M10: TSUJINO | N10: Jose | O10: =P10/G10 -> 1983.3333 | P10: =48000*0+47600 -> 47600 | Q10: =S10/G10 -> 1845.7083 | R10: 3303 | S10: =P10-R10 -> 44297 | T10: 1 | U10: ECO SIROCCO 26003S | V10: LIMG00358300 | W10: ONE | X10: PAITA | Y10: 10005721 | Z10: Compensación | AA10: =B10&Y10&Z10 -> ENERO10005721Compensación | AB10: =INDEX('Detalle Costos'!$L$5:$L$158,MATCH(Resumen!AA10,'Detalle Costos'!$C$5:$C$158,0))*1000+4623.769999996/248 -> 1878.6442 | AC10: =IFERROR(INDEX('Detalle Costos'!$X$5:$X$158,MATCH(Resumen!AA10,'Detalle Costos'!$C$5:$C$158,0))*AG10,0) -> 27003.901 | AD10: =IFERROR(INDEX('Detalle Costos'!$Z$5:$Z$158,MATCH(Resumen!AA10,'Detalle Costos'!$C$5:$C$158,0))*AG10,0) -> 9795.8891 | AE10: =IFERROR(INDEX('Detalle Costos'!$Y$5:$Y$158,MATCH(Resumen!AA10,'Detalle Costos'!$C$5:$C$158,0))*AG10,0) -> 426.26796 | AF10: =IFERROR(INDEX('Detalle Costos'!$AA$5:$AA$158,MATCH(Resumen!AA10,'Detalle Costos'!$C$5:$C$158,0))*AG10,0) -> 7297.1068 | AG10: =AI10*G10+6518.87/248*G10-47.35*G10 -> 44523.165 | AH10: 23.7 | AI10: 1876.1961 | AJ10: 44778.445 | AK10: =P10-AG10 -> 3076.8346 | AL10: =AK10/P10 -> 0.064639383 | AM10: =R10 -> 3303 | AN10: =118461.136538461/5988.21*G10 -> 474.77748 | AO10: =1882/26*G10 -> 1737.2308 | AP10: =SUM(AM10:AO10) -> 5515.0083 | AQ10: =50659/248*G10 -> 4902.4839 | AR10: =S10*0.03 -> 1328.91 | AS10: =AK10-AP10-AQ10+AR10 -> -6011.7475 | AT10: =AS10/P10 -> -0.12629722 | AU10: =131251/248*G10 -> 12701.71 | AV10: =AS10-AU10 -> -18713.457 | AW10: =AV10/P10 -> -0.39313986 | AX10: =123530/248*G10 -> 11954.516 | AY10: =AS10+AX10 -> 5942.7686 | AZ10: =AY10/P10 -> 0.12484808 | BB10: =P10/$G10 -> 1983.3333 | BC10: =-AC10/$G10 -> -1125.1626 | BD10: =-AD10/$G10 -> -408.16205 | BE10: =-AE10/$G10 -> -17.761165 | BF10: =-AF10/$G10 -> -304.04612 | BG10: =-AG10/$G10 -> -1855.1319 | BH10: =AK10/$G10 -> 128.20144 | BI10: =-AM10/$G10 -> -137.625 | BJ10: =-AO10/$G10 -> -72.384615 | BK10: =-AP10/$G10 -> -229.79201 | BL10: =-AQ10/$G10 -> -204.27016 | BM10: =AR10/$G10 -> 55.37125 | BN10: =AS10/$G10 -> -250.48948 | BO10: =-AU10/$G10 -> -529.2379 | BP10: =AV10/$G10 -> -779.72738 | BQ10: =AX10/$G10 -> 498.10484 | BR10: =AY10/$G10 -> 247.61536
B11: ENERO | C11: =B11 -> ENERO | D11: 145-2025 | E11: 46020 | F11: 46041 | G11: 54 | H11: POTA REJOS CONGELADOS | I11: Rejos | J11: 500-1 / 1-2 | K11: España | L11: Vigo | M11: GLOBAL OCEAN | N11: Jorge | O11: 2600 | P11: 140400 | Q11: 2430.963 | R11: 9128 | S11: =P11-R11 -> 131272 | T11: 2 | U11: IZMIT EXPRESS 604N | V11: 28952064 | W11: HAPAG | X11: PAITA | Y11: 10007162 | Z11: Compensación | AA11: =B11&Y11&Z11 -> ENERO10007162Compensación | AB11: =INDEX('Detalle Costos'!$L$5:$L$158,MATCH(Resumen!AA11,'Detalle Costos'!$C$5:$C$158,0))*1000+4623.769999996/248 -> 1808.6442 | AC11: =IFERROR(INDEX('Detalle Costos'!$X$5:$X$158,MATCH(Resumen!AA11,'Detalle Costos'!$C$5:$C$158,0))*AG11,0) -> 61989.461 | AD11: =IFERROR(INDEX('Detalle Costos'!$Z$5:$Z$158,MATCH(Resumen!AA11,'Detalle Costos'!$C$5:$C$158,0))*AG11,0) -> 16355.316 | AE11: =IFERROR(INDEX('Detalle Costos'!$Y$5:$Y$158,MATCH(Resumen!AA11,'Detalle Costos'!$C$5:$C$158,0))*AG11,0) -> 833.36448 | AF11: =IFERROR(INDEX('Detalle Costos'!$AA$5:$AA$158,MATCH(Resumen!AA11,'Detalle Costos'!$C$5:$C$158,0))*AG11,0) -> 16254.27 | AG11: =AI11*G11+6518.87/248*G11-47.35*G11 -> 95432.412 | AH11: 54 | AI11: 1788.3311 | AJ11: 99505.64 | AK11: =P11-AG11 -> 44967.588 | AL11: =AK11/P11 -> 0.32028196 | AM11: =R11 -> 9128 | AN11: =118461.136538461/5988.21*G11 -> 1068.2493 | AO11: =1882/26*G11 -> 3908.7692 | AP11: =SUM(AM11:AO11) -> 14105.019 | AQ11: =50659/248*G11 -> 11030.589 | AR11: =S11*0.03 -> 3938.16 | AS11: =AK11-AP11-AQ11+AR11 -> 23770.141 | AT11: =AS11/P11 -> 0.169303 | AU11: =131251/248*G11 -> 28578.847 | AV11: =AS11-AU11 -> -4808.7062 | AW11: =AV11/P11 -> -0.034250044 | AX11: =123530/248*G11 -> 26897.661 | AY11: =AS11+AX11 -> 50667.802 | AZ11: =AY11/P11 -> 0.36088178 | BB11: =P11/$G11 -> 2600 | BC11: =-AC11/$G11 -> -1147.953 | BD11: =-AD11/$G11 -> -302.87623 | BE11: =-AE11/$G11 -> -15.432675 | BF11: =-AF11/$G11 -> -301.00501 | BG11: =-AG11/$G11 -> -1767.2669 | BH11: =AK11/$G11 -> 832.73311 | BI11: =-AM11/$G11 -> -169.03704 | BJ11: =-AO11/$G11 -> -72.384615 | BK11: =-AP11/$G11 -> -261.20405 | BL11: =-AQ11/$G11 -> -204.27016 | BM11: =AR11/$G11 -> 72.928889 | BN11: =AS11/$G11 -> 440.18779 | BO11: =-AU11/$G11 -> -529.2379 | BP11: =AV11/$G11 -> -89.050115 | BQ11: =AX11/$G11 -> 498.10484 | BR11: =AY11/$G11 -> 938.29263
B12: FEBRERO | C12: =B12 -> FEBRERO | D12: 146-2026 | E12: 46027 | F12: 46059 | G12: 10 | H12: POTA CONOS | I12: Conos | J12: 10 cm - up | K12: Tailandia | L12: Lat Krabang | M12: TSUJINO | N12: Jose | O12: 2100 | P12: 21000 | Q12: 2100 | R12: =3500/24*G12 -> 1458.3333 | S12: =P12-R12 -> 19541.667 | T12: 1 | U12: ECO MARIN 26006S | V12: 6444023300 | W12: COSCO | X12: PAITA | Y12: 10007969 | Z12: Compensación | AA12: =B12&Y12&Z12 -> FEBRERO10007969Compensación | AB12: =INDEX('Detalle Costos'!$L$5:$L$158,MATCH(Resumen!AA12,'Detalle Costos'!$C$5:$C$158,0))*1000*0+AI12+229398.68/1634.3-47.35 -> 1298.094 | AC12: =IFERROR(INDEX('Detalle Costos'!$X$5:$X$158,MATCH(Resumen!AA12,'Detalle Costos'!$C$5:$C$158,0))*AG12,0) -> 10499.591 | AD12: =IFERROR(INDEX('Detalle Costos'!$Z$5:$Z$158,MATCH(Resumen!AA12,'Detalle Costos'!$C$5:$C$158,0))*AG12,0) -> 1976.4508 | AE12: =IFERROR(INDEX('Detalle Costos'!$Y$5:$Y$158,MATCH(Resumen!AA12,'Detalle Costos'!$C$5:$C$158,0))*AG12,0) -> 154.98937 | AF12: =IFERROR(INDEX('Detalle Costos'!$AA$5:$AA$158,MATCH(Resumen!AA12,'Detalle Costos'!$C$5:$C$158,0))*AG12,0) -> 349.90907 | AG12: =AB12*G12 -> 12980.94 | AH12: =+G12 -> 10 | AI12: 1205.0789 | AJ12: =+AI12*AH12 -> 12050.789 | AK12: =P12-AG12 -> 8019.0601 | AL12: =AK12/P12 -> 0.38186001 | AM12: =R12 -> 1458.3333 | AN12: =118461.136538461/5988.21*G12 -> 197.82395 | AO12: =1882/26*G12 -> 723.84615 | AP12: =SUM(AM12:AO12) -> 2380.0034 | AQ12: =56604/1634.3*G12 -> 346.35012 | AR12: =S12*0.03 -> 586.25 | AS12: =AK12-AP12-AQ12+AR12 -> 5878.9566 | AT12: =AS12/P12 -> 0.27995031 | AU12: =148498/1634.3*G12 -> 908.63367 | AV12: =AS12-AU12 -> 4970.3229 | AW12: =AV12/P12 -> 0.23668204 | AX12: =123484.35/1634.3*G12 -> 755.57945 | AY12: =AS12+AX12 -> 6634.536 | AZ12: =AY12/P12 -> 0.31593029 | BB12: =P12/$G12 -> 2100 | BC12: =-AC12/$G12 -> -1049.9591 | BD12: =-AD12/$G12 -> -197.64508 | BE12: =-AE12/$G12 -> -15.498937 | BF12: =-AF12/$G12 -> -34.990907 | BG12: =-AG12/$G12 -> -1298.094 | BH12: =AK12/$G12 -> 801.90601 | BI12: =-AM12/$G12 -> -145.83333 | BJ12: =-AO12/$G12 -> -72.384615 | BK12: =-AP12/$G12 -> -238.00034 | BL12: =-AQ12/$G12 -> -34.635012 | BM12: =AR12/$G12 -> 58.625 | BN12: =AS12/$G12 -> 587.89566 | BO12: =-AU12/$G12 -> -90.863367 | BP12: =AV12/$G12 -> 497.03229 | BQ12: =AX12/$G12 -> 75.557945 | BR12: =AY12/$G12 -> 663.4536
B13: FEBRERO | C13: =B13 -> FEBRERO | D13: 146-2026 | E13: 46027 | F13: 46059 | G13: 14 | H13: POTA NUCAS | I13: Nucas | J13: 500-up | K13: Tailandia | L13: Lat Krabang | M13: TSUJINO | N13: Jose | O13: 1700 | P13: =23800-344 -> 23456 | Q13: 1700 | R13: =3500/24*G13 -> 2041.6667 | S13: =P13-R13 -> 21414.333 | T13: 0 | Y13: 10005779 | Z13: Compensación | AA13: =B13&Y13&Z13 -> FEBRERO10005779Compensación | AB13: =INDEX('Detalle Costos'!$L$5:$L$158,MATCH(Resumen!AA13,'Detalle Costos'!$C$5:$C$158,0))*1000*0+AI13+229398.68/1634.3-47.35 -> 1840.6151 | AC13: =IFERROR(INDEX('Detalle Costos'!$X$5:$X$158,MATCH(Resumen!AA13,'Detalle Costos'!$C$5:$C$158,0))*AG13,0) -> 15685.112 | AD13: =IFERROR(INDEX('Detalle Costos'!$Z$5:$Z$158,MATCH(Resumen!AA13,'Detalle Costos'!$C$5:$C$158,0))*AG13,0) -> 5673.5351 | AE13: =IFERROR(INDEX('Detalle Costos'!$Y$5:$Y$158,MATCH(Resumen!AA13,'Detalle Costos'!$C$5:$C$158,0))*AG13,0) -> 187.96971 | AF13: =IFERROR(INDEX('Detalle Costos'!$AA$5:$AA$158,MATCH(Resumen!AA13,'Detalle Costos'!$C$5:$C$158,0))*AG13,0) -> 4221.9946 | AG13: =AB13*G13 -> 25768.611 | AH13: 14.849 | AI13: 1747.6 | AJ13: =AI13*AH13 -> 25950.112 | AK13: =P13-AG13 -> -2312.6114 | AL13: =AK13/P13 -> -0.098593595 | AM13: =R13 -> 2041.6667 | AN13: =118461.136538461/5988.21*G13 -> 276.95353 | AO13: =1882/26*G13 -> 1013.3846 | AP13: =SUM(AM13:AO13) -> 3332.0048 | AQ13: =56604/1634.3*G13 -> 484.89017 | AR13: =S13*0.03 -> 642.43 | AS13: =AK13-AP13-AQ13+AR13 -> -5487.0764 | AT13: =AS13/P13 -> -0.23393061 | AU13: =148498/1634.3*G13 -> 1272.0871 | AV13: =AS13-AU13 -> -6759.1635 | AW13: =AV13/P13 -> -0.28816352 | AX13: =123484.35/1634.3*G13 -> 1057.8112 | AY13: =AS13+AX13 -> -4429.2651 | AZ13: =AY13/P13 -> -0.18883293 | BB13: =P13/$G13 -> 1675.4286 | BC13: =-AC13/$G13 -> -1120.3651 | BD13: =-AD13/$G13 -> -405.25251 | BE13: =-AE13/$G13 -> -13.426408 | BF13: =-AF13/$G13 -> -301.57104 | BG13: =-AG13/$G13 -> -1840.6151 | BH13: =AK13/$G13 -> -165.18653 | BI13: =-AM13/$G13 -> -145.83333 | BJ13: =-AO13/$G13 -> -72.384615 | BK13: =-AP13/$G13 -> -238.00034 | BL13: =-AQ13/$G13 -> -34.635012 | BM13: =AR13/$G13 -> 45.887857 | BN13: =AS13/$G13 -> -391.93403 | BO13: =-AU13/$G13 -> -90.863367 | BP13: =AV13/$G13 -> -482.79739 | BQ13: =AX13/$G13 -> 75.557945 | BR13: =AY13/$G13 -> -316.37608
B14: ENERO | C14: =B14 -> ENERO | D14: 147-2026 | E14: 46032 | F14: 46050 | G14: 72 | H14: POTA ALAS CONGELADAS | I14: Alas | J14: 1 - 2 KGS. | K14: Tailandia | L14: Bangkok | M14: TSUJINO | N14: Jose | O14: =P14/G14 -> 1887.7083 | P14: =140400*0+135915 -> 135915 | Q14: =S14/G14 -> 1754.25 | R14: 9609 | S14: =P14-R14 -> 126306 | T14: 3 | U14: ECO MARIN 26004N | V14: LIMG01524600 | W14: ONE | X14: PAITA | Y14: 10006720 | Z14: Compensación | AA14: =B14&Y14&Z14 -> ENERO10006720Compensación | AB14: =INDEX('Detalle Costos'!$L$5:$L$158,MATCH(Resumen!AA14,'Detalle Costos'!$C$5:$C$158,0))*1000+4623.769999996/248 -> 1738.6442 | AC14: =IFERROR(INDEX('Detalle Costos'!$X$5:$X$158,MATCH(Resumen!AA14,'Detalle Costos'!$C$5:$C$158,0))*AG14,0) -> 80708.237 | AD14: =IFERROR(INDEX('Detalle Costos'!$Z$5:$Z$158,MATCH(Resumen!AA14,'Detalle Costos'!$C$5:$C$158,0))*AG14,0) -> 18674.884 | AE14: =IFERROR(INDEX('Detalle Costos'!$Y$5:$Y$158,MATCH(Resumen!AA14,'Detalle Costos'!$C$5:$C$158,0))*AG14,0) -> 1170.5203 | AF14: =IFERROR(INDEX('Detalle Costos'!$AA$5:$AA$158,MATCH(Resumen!AA14,'Detalle Costos'!$C$5:$C$158,0))*AG14,0) -> 21686.758 | AG14: =AI14*G14+6518.87/248*G14-47.35*G14 -> 122240.4 | AH14: 69.7 | AI14: 1718.8476 | AJ14: 120156.94 | AK14: =P14-AG14 -> 13674.6 | AL14: =AK14/P14 -> 0.10061141 | AM14: =R14 -> 9609 | AN14: =118461.136538461/5988.21*G14 -> 1424.3325 | AO14: =1882/26*G14 -> 5211.6923 | AP14: =SUM(AM14:AO14) -> 16245.025 | AQ14: =50659/248*G14 -> 14707.452 | AR14: =S14*0.03 -> 3789.18 | AS14: =AK14-AP14-AQ14+AR14 -> -13488.696 | AT14: =AS14/P14 -> -0.099243615 | AU14: =131251/248*G14 -> 38105.129 | AV14: =AS14-AU14 -> -51593.825 | AW14: =AV14/P14 -> -0.37960361 | AX14: =123530/248*G14 -> 35863.548 | AY14: =AS14+AX14 -> 22374.852 | AZ14: =AY14/P14 -> 0.16462386 | BB14: =P14/$G14 -> 1887.7083 | BC14: =-AC14/$G14 -> -1120.9477 | BD14: =-AD14/$G14 -> -259.37339 | BE14: =-AE14/$G14 -> -16.257226 | BF14: =-AF14/$G14 -> -301.20497 | BG14: =-AG14/$G14 -> -1697.7833 | BH14: =AK14/$G14 -> 189.92501 | BI14: =-AM14/$G14 -> -133.45833 | BJ14: =-AO14/$G14 -> -72.384615 | BK14: =-AP14/$G14 -> -225.62534 | BL14: =-AQ14/$G14 -> -204.27016 | BM14: =AR14/$G14 -> 52.6275 | BN14: =AS14/$G14 -> -187.343 | BO14: =-AU14/$G14 -> -529.2379 | BP14: =AV14/$G14 -> -716.5809 | BQ14: =AX14/$G14 -> 498.10484 | BR14: =AY14/$G14 -> 310.76184
B15: ENERO | C15: =B15 -> ENERO | E15: 46053 | F15: 46053 | G15: 0 | H15: RESIDUOS DE POTA | I15: Residuos | J15: Residuos | K15: Residuos | L15: Residuos | M15: PROVEEDORA DE PRODUCTOS MARINOS | O15: 0 | P15: 24314.28 | Q15: 0 | R15: 0 | S15: =P15-R15 -> 24314.28 | AB15: 0 | AC15: =IFERROR(INDEX('Detalle Costos'!$X$5:$X$158,MATCH(Resumen!AA15,'Detalle Costos'!$C$5:$C$158,0))*AG15,0) -> 0 | AD15: =IFERROR(INDEX('Detalle Costos'!$Z$5:$Z$158,MATCH(Resumen!AA15,'Detalle Costos'!$C$5:$C$158,0))*AG15,0) -> 0 | AE15: =IFERROR(INDEX('Detalle Costos'!$Y$5:$Y$158,MATCH(Resumen!AA15,'Detalle Costos'!$C$5:$C$158,0))*AG15,0) -> 0 | AF15: =IFERROR(INDEX('Detalle Costos'!$AA$5:$AA$158,MATCH(Resumen!AA15,'Detalle Costos'!$C$5:$C$158,0))*AG15,0) -> 0 | AG15: =AI15*G15 -> 0 | AK15: =P15-AG15 -> 24314.28 | AL15: =AK15/P15 -> 1 | AM15: =R15 -> 0 | AN15: =118461.136538461/5988.21*G15 -> 0 | AO15: =1882/26*G15 -> 0 | AP15: =SUM(AM15:AO15) -> 0 | AQ15: =50659/248*G15 -> 0 | AR15: 0 | AS15: =AK15-AP15-AQ15+AR15 -> 24314.28 | AT15: =AS15/P15 -> 1 | AU15: =131251/248*G15 -> 0 | AV15: =AS15-AU15 -> 24314.28 | AW15: =AV15/P15 -> 1 | AX15: =123530/248*G15 -> 0 | AY15: =AS15+AX15 -> 24314.28 | AZ15: =AY15/P15 -> 1 | BB15: 0 | BC15: 0 | BD15: 0 | BE15: 0 | BF15: 0 | BG15: 0 | BH15: 0 | BI15: 0 | BJ15: 0 | BK15: 0 | BL15: 0 | BM15: 0 | BN15: 0 | BO15: 0 | BP15: 0 | BQ15: 0 | BR15: 0
B16: FEBRERO | C16: =B16 -> FEBRERO | D16: 148-2026 | E16: 15 | F16: 46055 | G16: 135 | H16: POTA FILETE CONGELADO | I16: Filete | J16: 2-4 (B) | K16: España | L16: Vigo | M16: FOOD & BEVERAGES TRADERS | N16: Jorge | O16: 1650 | P16: 222750 | Q16: 1480.963 | R16: 22820 | S16: =P16-R16 -> 199930 | T16: 5 | U16: ODYSSEUS 606N | V16: 59582082 | W16: HAPAG | X16: PAITA | Y16: 10005721 | Z16: Compensación | AA16: =B16&Y16&Z16 -> FEBRERO10005721Compensación | AB16: =INDEX('Detalle Costos'!$L$5:$L$158,MATCH(Resumen!AA16,'Detalle Costos'!$C$5:$C$158,0))*1000*0+AI16+229398.68/1634.3-47.35 -> 1765.2217 | AC16: =IFERROR(INDEX('Detalle Costos'!$X$5:$X$158,MATCH(Resumen!AA16,'Detalle Costos'!$C$5:$C$158,0))*AG16,0) -> 144612 | AD16: =IFERROR(INDEX('Detalle Costos'!$Z$5:$Z$158,MATCH(Resumen!AA16,'Detalle Costos'!$C$5:$C$158,0))*AG16,0) -> 47774.394 | AE16: =IFERROR(INDEX('Detalle Costos'!$Y$5:$Y$158,MATCH(Resumen!AA16,'Detalle Costos'!$C$5:$C$158,0))*AG16,0) -> 2541.4765 | AF16: =IFERROR(INDEX('Detalle Costos'!$AA$5:$AA$158,MATCH(Resumen!AA16,'Detalle Costos'!$C$5:$C$158,0))*AG16,0) -> 43377.054 | AG16: =AB16*G16 -> 238304.93 | AH16: =+G16 -> 135 | AI16: 1672.2066 | AJ16: 251295.39 | AK16: =P16-AG16 -> -15554.926 | AL16: =AK16/P16 -> -0.069831316 | AM16: =R16 -> 22820 | AN16: =118461.136538461/5988.21*G16 -> 2670.6233 | AO16: =1882/26*G16 -> 9771.9231 | AP16: =SUM(AM16:AO16) -> 35262.546 | AQ16: =56604/1634.3*G16 -> 4675.7266 | AR16: =S16*0.03 -> 5997.9 | AS16: =AK16-AP16-AQ16+AR16 -> -49495.299 | AT16: =AS16/P16 -> -0.22220112 | AU16: =148498/1634.3*G16 -> 12266.554 | AV16: =AS16-AU16 -> -61761.853 | AW16: =AV16/P16 -> -0.27726982 | AX16: =124162.35/1634.3*G16 -> 10256.328 | AY16: =AS16+AX16 -> -39238.97 | AZ16: =AY16/P16 -> -0.17615699 | BB16: =P16/$G16 -> 1650 | BC16: =-AC16/$G16 -> -1071.2 | BD16: =-AD16/$G16 -> -353.8844 | BE16: =-AE16/$G16 -> -18.825752 | BF16: =-AF16/$G16 -> -321.31151 | BG16: =-AG16/$G16 -> -1765.2217 | BH16: =AK16/$G16 -> -115.22167 | BI16: =-AM16/$G16 -> -169.03704 | BJ16: =-AO16/$G16 -> -72.384615 | BK16: =-AP16/$G16 -> -261.20405 | BL16: =-AQ16/$G16 -> -34.635012 | BM16: =AR16/$G16 -> 44.428889 | BN16: =AS16/$G16 -> -366.63184 | BO16: =-AU16/$G16 -> -90.863367 | BP16: =AV16/$G16 -> -457.49521 | BQ16: =AX16/$G16 -> 75.972802 | BR16: =AY16/$G16 -> -290.65904
B17: FEBRERO | C17: =B17 -> FEBRERO | D17: 149-2026 | E17: 16 | F17: 46055 | G17: 27 | H17: POTA REPRODUCTORES | I17: Rejos | K17: España | L17: Vigo | M17: GLOBAL OCEAN | N17: Jorge | O17: =P17/G17 -> 2873.5185 | P17: =79650*0+77585 -> 77585 | Q17: =S17/G17 -> 2711.8889 | R17: 4364 | S17: =P17-R17 -> 73221 | T17: 1 | Y17: 10007567 | Z17: Entradas | AA17: =B17&Y17&Z17 -> FEBRERO10007567Entradas | AB17: =INDEX('Detalle Costos'!$L$5:$L$158,MATCH(Resumen!AA17,'Detalle Costos'!$C$5:$C$158,0))*1000*0+AI17+229398.68/1634.3-47.35 -> 1745.2509 | AC17: =IFERROR(INDEX('Detalle Costos'!$X$5:$X$158,MATCH(Resumen!AA17,'Detalle Costos'!$C$5:$C$158,0))*AG17,0) -> 29088.956 | AD17: =IFERROR(INDEX('Detalle Costos'!$Z$5:$Z$158,MATCH(Resumen!AA17,'Detalle Costos'!$C$5:$C$158,0))*AG17,0) -> 8334.6849 | AE17: =IFERROR(INDEX('Detalle Costos'!$Y$5:$Y$158,MATCH(Resumen!AA17,'Detalle Costos'!$C$5:$C$158,0))*AG17,0) -> 528.83536 | AF17: =IFERROR(INDEX('Detalle Costos'!$AA$5:$AA$158,MATCH(Resumen!AA17,'Detalle Costos'!$C$5:$C$158,0))*AG17,0) -> 9169.2977 | AG17: =AB17*G17 -> 47121.774 | AH17: 26.302 | AI17: 1652.2358 | AJ17: 48129 | AK17: =P17-AG17 -> 30463.226 | AL17: =AK17/P17 -> 0.39264325 | AM17: =R17 -> 4364 | AN17: =118461.136538461/5988.21*G17 -> 534.12467 | AO17: =1882/26*G17 -> 1954.3846 | AP17: =SUM(AM17:AO17) -> 6852.5093 | AQ17: =56604/1634.3*G17 -> 935.14532 | AR17: =S17*0.03 -> 2196.63 | AS17: =AK17-AP17-AQ17+AR17 -> 24872.202 | AT17: =AS17/P17 -> 0.32058003 | AU17: =148498/1634.3*G17 -> 2453.3109 | AV17: =AS17-AU17 -> 22418.891 | AW17: =AV17/P17 -> 0.28895909 | AX17: =124162.35/1634.3*G17 -> 2051.2656 | AY17: =AS17+AX17 -> 26923.467 | AZ17: =AY17/P17 -> 0.34701898 | BB17: =P17/$G17 -> 2873.5185 | BC17: =-AC17/$G17 -> -1077.3687 | BD17: =-AD17/$G17 -> -308.69204 | BE17: =-AE17/$G17 -> -19.586495 | BF17: =-AF17/$G17 -> -339.60362 | BG17: =-AG17/$G17 -> -1745.2509 | BH17: =AK17/$G17 -> 1128.2676 | BI17: =-AM17/$G17 -> -161.62963 | BJ17: =-AO17/$G17 -> -72.384615 | BK17: =-AP17/$G17 -> -253.79664 | BL17: =-AQ17/$G17 -> -34.635012 | BM17: =AR17/$G17 -> 81.356667 | BN17: =AS17/$G17 -> 921.19266 | BO17: =-AU17/$G17 -> -90.863367 | BP17: =AV17/$G17 -> 830.32929 | BQ17: =AX17/$G17 -> 75.972802 | BR17: =AY17/$G17 -> 997.16546
B18: FEBRERO | C18: =B18 -> FEBRERO | D18: 150-2026A | E18: 325 | F18: 46069 | G18: 26 | H18: POTA REJOS CONGELADOS | I18: Rejos | J18: 1-2 KG | K18: España | L18: Vigo | M18: OVERSEA | N18: Avelino | O18: 2600 | P18: 67600 | Q18: 2432.1538 | R18: 4364 | S18: =P18-R18 -> 63236 | T18: 1 | U18: CAPE SPENCER 608N | V18: 11400418 | W18: HAPAG | X18: PAITA | Y18: 10007162 | Z18: Compensación | AA18: =B18&Y18&Z18 -> FEBRERO10007162Compensación | AB18: =INDEX('Detalle Costos'!$L$5:$L$158,MATCH(Resumen!AA18,'Detalle Costos'!$C$5:$C$158,0))*1000*0+AI18+229398.68/1634.3-47.35 -> 1758.8613 | AC18: =IFERROR(INDEX('Detalle Costos'!$X$5:$X$158,MATCH(Resumen!AA18,'Detalle Costos'!$C$5:$C$158,0))*AG18,0) -> 28707.971 | AD18: =IFERROR(INDEX('Detalle Costos'!$Z$5:$Z$158,MATCH(Resumen!AA18,'Detalle Costos'!$C$5:$C$158,0))*AG18,0) -> 8191.5895 | AE18: =IFERROR(INDEX('Detalle Costos'!$Y$5:$Y$158,MATCH(Resumen!AA18,'Detalle Costos'!$C$5:$C$158,0))*AG18,0) -> 426.49257 | AF18: =IFERROR(INDEX('Detalle Costos'!$AA$5:$AA$158,MATCH(Resumen!AA18,'Detalle Costos'!$C$5:$C$158,0))*AG18,0) -> 8404.341 | AG18: =AB18*G18 -> 45730.394 | AH18: =+G18 -> 26 | AI18: 1665.8462 | AJ18: =AI18*AH18 -> 43312.002 | AK18: =P18-AG18 -> 21869.606 | AL18: =AK18/P18 -> 0.32351488 | AM18: =R18 -> 4364 | AN18: =118461.136538461/5988.21*G18 -> 514.34227 | AO18: =1882/26*G18 -> 1882 | AP18: =SUM(AM18:AO18) -> 6760.3423 | AQ18: =56604/1634.3*G18 -> 900.51031 | AR18: =S18*0.03 -> 1897.08 | AS18: =AK18-AP18-AQ18+AR18 -> 16105.833 | AT18: =AS18/P18 -> 0.23825197 | AU18: =148498/1634.3*G18 -> 2362.4475 | AV18: =AS18-AU18 -> 13743.386 | AW18: =AV18/P18 -> 0.20330452 | AX18: =124162.35/1634.3*G18 -> 1975.2928 | AY18: =AS18+AX18 -> 18081.126 | AZ18: =AY18/P18 -> 0.26747228 | BB18: =P18/$G18 -> 2600 | BC18: =-AC18/$G18 -> -1104.1527 | BD18: =-AD18/$G18 -> -315.06113 | BE18: =-AE18/$G18 -> -16.40356 | BF18: =-AF18/$G18 -> -323.24388 | BG18: =-AG18/$G18 -> -1758.8613 | BH18: =AK18/$G18 -> 841.13869 | BI18: =-AM18/$G18 -> -167.84615 | BJ18: =-AO18/$G18 -> -72.384615 | BK18: =-AP18/$G18 -> -260.01316 | BL18: =-AQ18/$G18 -> -34.635012 | BM18: =AR18/$G18 -> 72.964615 | BN18: =AS18/$G18 -> 619.45513 | BO18: =-AU18/$G18 -> -90.863367 | BP18: =AV18/$G18 -> 528.59176 | BQ18: =AX18/$G18 -> 75.972802 | BR18: =AY18/$G18 -> 695.42793
B19: FEBRERO | C19: =B19 -> FEBRERO | D19: 151-2025 | E19: 26 | F19: 46080 | G19: 27 | H19: POTA MEMBRANA PRECOCIDA | I19: Membrana | K19: China | L19: Qingdao | M19: Hunan Jinyueyang | O19: =P19/G19 -> 1429.8611 | P19: =39150*0+38606.25 -> 38606.25 | Q19: =S19/G19 -> 1322.4537 | R19: 2900 | S19: =P19-R19 -> 35706.25 | T19: 1 | U19: ECO SIROCCO 26009S | V19: 6445502950 | W19: COSCO | X19: PAITA | Y19: 10009332 | Z19: Entradas | AA19: =B19&Y19&Z19 -> FEBRERO10009332Entradas | AB19: =INDEX('Detalle Costos'!$L$5:$L$158,MATCH(Resumen!AA19,'Detalle Costos'!$C$5:$C$158,0))*1000*0+AI19+229398.68/1634.3-47.35 -> 1312.5249 | AC19: =IFERROR(INDEX('Detalle Costos'!$X$5:$X$158,MATCH(Resumen!AA19,'Detalle Costos'!$C$5:$C$158,0))*AG19,0) -> 29388.919 | AD19: =IFERROR(INDEX('Detalle Costos'!$Z$5:$Z$158,MATCH(Resumen!AA19,'Detalle Costos'!$C$5:$C$158,0))*AG19,0) -> 5377.8939 | AE19: =IFERROR(INDEX('Detalle Costos'!$Y$5:$Y$158,MATCH(Resumen!AA19,'Detalle Costos'!$C$5:$C$158,0))*AG19,0) -> 543.21918 | AF19: =IFERROR(INDEX('Detalle Costos'!$AA$5:$AA$158,MATCH(Resumen!AA19,'Detalle Costos'!$C$5:$C$158,0))*AG19,0) -> 128.13914 | AG19: =AB19*G19 -> 35438.171 | AH19: 26.625 | AI19: 1219.5098 | AJ19: 40733.76 | AK19: =P19-AG19 -> 3168.0787 | AL19: =AK19/P19 -> 0.08206129 | AM19: =R19 -> 2900 | AN19: =118461.136538461/5988.21*G19 -> 534.12467 | AO19: =1882/26*G19 -> 1954.3846 | AP19: =SUM(AM19:AO19) -> 5388.5093 | AQ19: =56604/1634.3*G19 -> 935.14532 | AR19: =S19*0.03 -> 1071.1875 | AS19: =AK19-AP19-AQ19+AR19 -> -2084.3884 | AT19: =AS19/P19 -> -0.053990958 | AU19: =148498/1634.3*G19 -> 2453.3109 | AV19: =AS19-AU19 -> -4537.6993 | AW19: =AV19/P19 -> -0.11753795 | AX19: =124162.35/1634.3*G19 -> 2051.2656 | AY19: =AS19+AX19 -> -33.122782 | AZ19: =AY19/P19 -> -0.00085796423 | BB19: =P19/$G19 -> 1429.8611 | BC19: =-AC19/$G19 -> -1088.4785 | BD19: =-AD19/$G19 -> -199.18125 | BE19: =-AE19/$G19 -> -20.119229 | BF19: =-AF19/$G19 -> -4.7458942 | BG19: =-AG19/$G19 -> -1312.5249 | BH19: =AK19/$G19 -> 117.33625 | BI19: =-AM19/$G19 -> -107.40741 | BJ19: =-AO19/$G19 -> -72.384615 | BK19: =-AP19/$G19 -> -199.57442 | BL19: =-AQ19/$G19 -> -34.635012 | BM19: =AR19/$G19 -> 39.673611 | BN19: =AS19/$G19 -> -77.199571 | BO19: =-AU19/$G19 -> -90.863367 | BP19: =AV19/$G19 -> -168.06294 | BQ19: =AX19/$G19 -> 75.972802 | BR19: =AY19/$G19 -> -1.2267697
B20: FEBRERO | C20: =B20 -> FEBRERO | D20: 151-2025 | E20: 26 | F20: 46080 | G20: 27 | H20: POTA TELILLA PRECOCIDA | I20: Telilla | K20: China | L20: Qingdao | M20: Hunan Jinyueyang | O20: =P20/G20 -> 1429.8611 | P20: =39150*0+38606.25 -> 38606.25 | Q20: =S20/G20 -> 1322.4537 | R20: 2900 | S20: =P20-R20 -> 35706.25 | T20: 1 | U20: ECO SIROCCO 26009S | V20: 6445502950 | W20: COSCO | X20: PAITA | Y20: 10009332 | Z20: Compensación | AA20: =B20&Y20&Z20 -> FEBRERO10009332Compensación | AB20: =INDEX('Detalle Costos'!$L$5:$L$158,MATCH(Resumen!AA20,'Detalle Costos'!$C$5:$C$158,0))*1000*0+AI20+229398.68/1634.3-47.35 -> 1312.5249 | AC20: =IFERROR(INDEX('Detalle Costos'!$X$5:$X$158,MATCH(Resumen!AA20,'Detalle Costos'!$C$5:$C$158,0))*AG20,0) -> 28828.027 | AD20: =IFERROR(INDEX('Detalle Costos'!$Z$5:$Z$158,MATCH(Resumen!AA20,'Detalle Costos'!$C$5:$C$158,0))*AG20,0) -> 5033.6698 | AE20: =IFERROR(INDEX('Detalle Costos'!$Y$5:$Y$158,MATCH(Resumen!AA20,'Detalle Costos'!$C$5:$C$158,0))*AG20,0) -> 503.76196 | AF20: =IFERROR(INDEX('Detalle Costos'!$AA$5:$AA$158,MATCH(Resumen!AA20,'Detalle Costos'!$C$5:$C$158,0))*AG20,0) -> 1072.7126 | AG20: =AB20*G20 -> 35438.171 | AH20: 26.625 | AI20: 1219.5098 | AJ20: 40354.03 | AK20: =P20-AG20 -> 3168.0787 | AL20: =AK20/P20 -> 0.08206129 | AM20: =R20 -> 2900 | AN20: =118461.136538461/5988.21*G20 -> 534.12467 | AO20: =1882/26*G20 -> 1954.3846 | AP20: =SUM(AM20:AO20) -> 5388.5093 | AQ20: =56604/1634.3*G20 -> 935.14532 | AR20: =S20*0.03 -> 1071.1875 | AS20: =AK20-AP20-AQ20+AR20 -> -2084.3884 | AT20: =AS20/P20 -> -0.053990958 | AU20: =148498/1634.3*G20 -> 2453.3109 | AV20: =AS20-AU20 -> -4537.6993 | AW20: =AV20/P20 -> -0.11753795 | AX20: =124162.35/1634.3*G20 -> 2051.2656 | AY20: =AS20+AX20 -> -33.122782 | AZ20: =AY20/P20 -> -0.00085796423 | BB20: =P20/$G20 -> 1429.8611 | BC20: =-AC20/$G20 -> -1067.7047 | BD20: =-AD20/$G20 -> -186.43222 | BE20: =-AE20/$G20 -> -18.65785 | BF20: =-AF20/$G20 -> -39.730098 | BG20: =-AG20/$G20 -> -1312.5249 | BH20: =AK20/$G20 -> 117.33625 | BI20: =-AM20/$G20 -> -107.40741 | BJ20: =-AO20/$G20 -> -72.384615 | BK20: =-AP20/$G20 -> -199.57442 | BL20: =-AQ20/$G20 -> -34.635012 | BM20: =AR20/$G20 -> 39.673611 | BN20: =AS20/$G20 -> -77.199571 | BO20: =-AU20/$G20 -> -90.863367 | BP20: =AV20/$G20 -> -168.06294 | BQ20: =AX20/$G20 -> 75.972802 | BR20: =AY20/$G20 -> -1.2267697
