Workbook

Sheet Gráficos
B3: PERU FROST - RESUMEN RESULTADOS CONGELADOS 2026 (MILES US$)
B4: Concepto | C4: 46023 | D4: 46054 | E4: 46082 | F4: 46113 | G4: Acum 2026
B5: TM Materia Prima | C5: =[2]Resumen!$D$4 -> 1877.215 | D5: =[2]Resumen!$D$5 -> 3149.786 | E5: =[2]Resumen!$D$6 -> 2255.518 | F5: =[2]Resumen!$D$7 -> 2853.189 | G5: =SUM(C5:F5) -> 10135.708
B6: TM Vendidas PT | C6: =TD!B7 -> 248 | D6: =TD!C7 -> 1634.3 | E6: =TD!D7 -> 1995.8 | F6: =TD!E7 -> 2110.11 | G6: =TD!F7 -> 1978.33
B7: Venta | C7: =TD!B8 -> 564615.28 | D7: =TD!C8 -> 2769824.5 | E7: =TD!D8 -> 3894171.3 | F7: =TD!E8 -> 4921538.6 | G7: =TD!F8 -> 5010204.8
B8: Utilidad Neta | C8: =TD!B16 -> -92104.402 | D8: =TD!C16 -> -484146.17 | E8: =TD!D16 -> -490402.73 | F8: =TD!E16 -> -52490.241 | G8: =TD!F16 -> 417065.74
B9: Margen Neto % | C9: =C8/C7 -> -0.16312772 | D9: =D8/D7 -> -0.17479309 | E9: =E8/E7 -> -0.1259325 | F9: =F8/F7 -> -0.010665413 | G9: =G8/G7 -> 0.083243253
B12: 1. RESULTADOS INTERNOS
B62: 2. BENCHMARK INDUSTRIA PERUANA DE CONGELADOS (VERITRADE)
B87: Top 15 Exportadores — Productos Congelados (Alas, Filete, Nuca, Tentáculo, Reproductor) | J87: Top 15 Exportadores — Productos Cocidos (Alas Cocidas, Filete Daruma)
B89: Nro | C89: Exportador | D89: Valor FOB (US$) | E89: TM | F89: Precio por TM | J89: Nro | K89: Exportador | L89: Valor FOB (US$) | M89: TM | N89: Precio por TM
B90: 1 | C90: Industrial Pesquera Santa Monica S.A. | D90: 12800672 | E90: 7371.2 | F90: 1737 | J90: 1 | K90: Costa Mira Sociedad Anonima Cerrada | L90: 9211788 | M90: 2579.8 | N90: 3571
B91: 2 | C91: Pesquera Hermanos Cordova S.A.C. | D91: 11792528 | E91: 7242.6 | F91: 1628 | J91: 2 | K91: KSL S.A.C. | L91: 5319083 | M91: 1670.5 | N91: 3184
B92: 3 | C92: Oceano Seafood S.A. | D92: 11724680 | E92: 6746.5 | F92: 1738 | J92: 3 | K92: Pacific Freezing Company S.A.C. | L92: 4286058 | M92: 1338 | N92: 3203
B93: 4 | C93: Productora Andina De Congelados S.R.L. | D93: 8847640 | E93: 5227.2 | F93: 1693 | J93: 4 | K93: Oceano Seafood S.A. | L93: 4050574 | M93: 1190.4 | N93: 3403
B94: 5 | C94: Costa Mira Sociedad Anonima Cerrada | D94: 8496998 | E94: 4421.2 | F94: 1922 | J94: 5 | K94: Frigosa Sociedad S.A.C. | L94: 3921103 | M94: 1215 | N94: 3227
B95: 6 | C95: Novaperu S.A.C. | D95: 6857126 | E95: 3973.8 | F95: 1726 | J95: 6 | K95: Dexim Srl | L95: 3883786 | M95: 1076.8 | N95: 3607
B96: 7 | C96: Peru Frost Sociedad Anonima Cerrada | D96: 6231879 | E96: 3981.4 | F96: 1565 | J96: 7 | K96: Inversiones Holding Peru Sociedad Anonim | L96: 2905633 | M96: 847.7 | N96: 3428
B97: 8 | C97: Esmeralda Corp S.A.C. | D97: 6229395 | E97: 3736 | F97: 1667 | J97: 8 | K97: Corporacion Pesquera Del Mar Sociedad An | L97: 2751416 | M97: 796 | N97: 3457
B98: 9 | C98: Proveedora De Productos Marinos Sociedad | D98: 6166547 | E98: 3730.3 | F98: 1653 | J98: 9 | K98: Mik Carpe S.A.C. | L98: 2475284 | M98: 735 | N98: 3368
B99: 10 | C99: Peruvian Sea Food S.A. | D99: 6164559 | E99: 3692.9 | F99: 1669 | J99: 10 | K99: Seafrost S.A.C. | L99: 2135285 | M99: 602.9 | N99: 3542
B100: 11 | C100: Pesquera Supercetus S.A.C. | D100: 5928869 | E100: 3562.1 | F100: 1664 | J100: 11 | K100: Pesquera Exalmar S.A.A. | L100: 1926814 | M100: 563.2 | N100: 3421
B101: 12 | C101: Transmarina Del Peru S.A.C. | D101: 5879029 | E101: 3591.3 | F101: 1637 | J101: 12 | K101: Refrigerados Fisholg & Hijos Sociedad An | L101: 1802223 | M101: 539.5 | N101: 3340
... B104: 15 | C104: Seafrost S.A.C. | D104: 5556358 | E104: 3119.3 | F104: 1781 | J104: 15 | K104: Industrial Pesquera Santa Monica S.A. | L104: 1603048 | M104: 475.7 | N104: 3370

Sheet TD
I1: 20575797 | J1: -20641652 | K1: =J1+I1 -> -65855.17 | L1: diferencia de tsujino
A2: ANÁLISIS DE RENTABILIDAD | K2: 72 | L2: toneladas
A4: EEFF PERU FROST (USD) | AM4: Enero | AN4: Febrero | AO4: Marzo | AP4: Abril | AQ4: Real | AR4: Budget
B5: Etiquetas de columna | L5: ANÁLISIS UNITARIO | X5: ANÁLISIS VÉRTICAL | AL5: Venta CFR | AM5: =B8/1000 -> 564.61528 | AN5: =C8/1000 -> 2769.8245 | AO5: =D8/1000 -> 3894.1713 | AP5: =E8/1000 -> 4921.5386 | AQ5: =F8/1000 -> 5010.2047 | AR5: =H8/1000 -> 1589.3806
A6: Valores | B6: ENERO | C6: FEBRERO | D6: MARZO | E6: ABRIL | F6: MAYO | G6: JUNIO | H6: JULIO | I6: Total general | L6: NOMBRE | M6: ENERO | N6: FEBRERO | O6: MARZO | P6: ABRIL | Q6: MAYO | R6: JUNIO | S6: JULIO | T6: TOTAL | X6: NOMBRE | Y6: ENERO | Z6: FEBRERO | AA6: MARZO | AB6: ABRIL | AC6: MAYO | AD6: JUNIO | AE6: JULIO | AF6: TOTAL | AL6: Utilidad Neta | AM6: =B16/1000 -> -92.104402 | AN6: =C16/1000 -> -484.14617 | AO6: =D16/1000 -> -490.40273 | AP6: =E16/1000 -> -52.490241 | AQ6: =F16/1000 -> 417.06574 | AR6: =H16/1000 -> 91.312258
A7: Suma de Cantidad | B7: 248 | C7: 1634.3 | D7: 1995.8 | E7: 2110.11 | F7: 1978.33 | G7: 1131.78 | H7: 780.905 | I7: 9879.225 | J7: =J8/GETPIVOTDATA("Suma de Cantidad ",$A$5) -> 2221.181
A8: Suma de VALOR CFR | B8: 564615.28 | C8: 2769824.5 | D8: 3894171.3 | E8: 4921538.6 | F8: 5010204.8 | G8: 3415442.3 | H8: 1589380.6 | I8: 22165177 | J8: =GETPIVOTDATA("Suma de VALOR CFR",$A$5)-GETPIVOTDATA("VALOR CFR",$A$25,"Producto","RESIDUOS DE POTA") -> 21943547 | L8: Suma de VALOR CFR | M8: =B8/B$7 -> 2276.6745 | N8: =C8/C$7 -> 1694.8079 | O8: =D8/D$7 -> 1951.1831 | P8: =E8/E$7 -> 2332.3611 | Q8: =F8/F$7 -> 2532.5425 | R8: =G8/G$7 -> 3017.7617 | S8: =H8/H$7 -> 2035.306 | T8: =I8/I$7 -> 2243.615 | X8: Suma de VALOR CFR | Y8: =B8/B$8 -> 1 | Z8: =C8/C$8 -> 1 | AA8: =D8/D$8 -> 1 | AB8: =E8/E$8 -> 1 | AC8: =F8/F$8 -> 1 | AD8: =G8/G$8 -> 1 | AE8: =H8/H$8 -> 1 | AF8: =I8/I$8 -> 1
A9: Suma de COSTO VENTAS | B9: 447259.37 | C9: 2896198.1 | D9: 3759147.4 | E9: 4268330.6 | F9: 4074597.6 | G9: 2480210.9 | H9: 1146770.6 | I9: 19072515 | L9: Suma de COSTO VENTAS | M9: =B9/B$7 -> 1803.4652 | N9: =C9/C$7 -> 1772.1337 | O9: =D9/D$7 -> 1883.5291 | P9: =E9/E$7 -> 2022.8 | Q9: =F9/F$7 -> 2059.6147 | R9: =G9/G$7 -> 2191.4249 | S9: =H9/H$7 -> 1468.5149 | T9: =I9/I$7 -> 1930.5679 | X9: Suma de COSTO VENTAS | Y9: =B9/B$8 -> 0.79214889 | Z9: =C9/C$8 -> 1.0456251 | AA9: =D9/D$8 -> 0.96532665 | AB9: =E9/E$8 -> 0.86727565 | AC9: =F9/F$8 -> 0.8132597 | AD9: =G9/G$8 -> 0.72617561 | AE9: =H9/H$8 -> 0.72152046 | AF9: =I9/I$8 -> 0.860472 | AT9: Resumen de Precios por TM Peru Frost vs Mercado
A10: Suma de UTILIDAD BRUTA | B10: 117355.91 | C10: -126373.58 | D10: 135023.96 | E10: 653208 | F10: 935607.12 | G10: 935231.4 | H10: 442609.97 | I10: 3092662.8 | L10: Suma de UTILIDAD BRUTA | M10: =B10/B$7 -> 473.20932 | N10: =C10/C$7 -> -77.325817 | O10: =D10/D$7 -> 67.654053 | P10: =E10/E$7 -> 309.56111 | Q10: =F10/F$7 -> 472.92773 | R10: =G10/G$7 -> 826.33674 | S10: =H10/H$7 -> 566.79106 | T10: =I10/I$7 -> 313.0471 | X10: Suma de UTILIDAD BRUTA | Y10: =B10/B$8 -> 0.20785111 | Z10: =C10/C$8 -> -0.045625123 | AA10: =D10/D$8 -> 0.034673348 | AB10: =E10/E$8 -> 0.13272435 | AC10: =F10/F$8 -> 0.1867403 | AD10: =G10/G$8 -> 0.27382439 | AE10: =H10/H$8 -> 0.27847954 | AF10: =I10/I$8 -> 0.139528 | AL10: Acum Abril venta y rentabilidad por producto
A11: Suma de GASTO VENTAS | B11: 42671.034 | C11: 228377.82 | D11: 500943.85 | E11: 557032.39 | F11: 455053.16 | G11: 200714.48 | H11: 162303.3 | I11: 2147096 | L11: Suma de GASTO VENTAS | M11: =B11/B$7 -> 172.06062 | N11: =C11/C$7 -> 139.74045 | O11: =D11/D$7 -> 250.99902 | P11: =E11/E$7 -> 263.98263 | Q11: =F11/F$7 -> 230.01883 | R11: =G11/G$7 -> 177.34408 | S11: =H11/H$7 -> 207.84 | T11: =I11/I$7 -> 217.33446 | X11: Suma de GASTO VENTAS | Y11: =B11/B$8 -> 0.075575415 | Z11: =C11/C$8 -> 0.082452091 | AA11: =D11/D$8 -> 0.1286394 | AB11: =E11/E$8 -> 0.11318257 | AC11: =F11/F$8 -> 0.090825262 | AD11: =G11/G$8 -> 0.058766761 | AE11: =H11/H$8 -> 0.10211732 | AF11: =I11/I$8 -> 0.096867984 | AM11: Venta CFR | AN11: Utilidad Neta | AT11: PRODUCTO | AU11: PERU FROST | AV11: INDUSTRIA PERUANA
A12: Suma de GASTO ADM | B12: 50659 | C12: 56604 | D12: 78579 | E12: 65076 | F12: 40133.169 | G12: 87732.79 | H12: 78579 | I12: 457362.96 | L12: Suma de GASTO ADM | M12: =B12/B$7 -> 204.27016 | N12: =C12/C$7 -> 34.635012 | O12: =D12/D$7 -> 39.372182 | P12: =E12/E$7 -> 30.840098 | Q12: =F12/F$7 -> 20.286387 | R12: =G12/G$7 -> 77.51753 | S12: =H12/H$7 -> 100.62556 | T12: =I12/I$7 -> 46.295429 | X12: Suma de GASTO ADM | Y12: =B12/B$8 -> 0.089723041 | Z12: =C12/C$8 -> 0.020435952 | AA12: =D12/D$8 -> 0.020178619 | AB12: =E12/E$8 -> 0.013222694 | AC12: =F12/F$8 -> 0.0080102851 | AD12: =G12/G$8 -> 0.025687095 | AE12: =H12/H$8 -> 0.049440014 | AF12: =I12/I$8 -> 0.020634302 | AL12: FILETE CONGELADO | AM12: 3148.23 | AN12: -1138.4306 | AT12: FILETE CONGELADO | AU12: 1323 | AV12: 1525
A13: Suma de DRAWBACK | B13: 15120.72 | C13: 75707.235 | D13: 108569.16 | E13: 138095.15 | F13: 143706.68 | G13: 97402.26 | H13: 44057.58 | I13: 622658.78 | L13: Suma de DRAWBACK | M13: =B13/B$7 -> 60.970645 | N13: =C13/C$7 -> 46.323952 | O13: =D13/D$7 -> 54.398817 | P13: =E13/E$7 -> 65.444526 | Q13: =F13/F$7 -> 72.640396 | R13: =G13/G$7 -> 86.061125 | S13: =H13/H$7 -> 56.418617 | T13: =I13/I$7 -> 63.027087 | X13: Suma de DRAWBACK | Y13: =B13/B$8 -> 0.026780572 | Z13: =C13/C$8 -> 0.027332864 | AA13: =D13/D$8 -> 0.027879913 | AB13: =E13/E$8 -> 0.028059345 | AC13: =F13/F$8 -> 0.028682795 | AD13: =G13/G$8 -> 0.028518198 | AE13: =H13/H$8 -> 0.027719968 | AF13: =I13/I$8 -> 0.028091757 | AL13: REJOS CONGELADOS | AM13: 2631.849 | AN13: 311.25595 | AT13: FILETE DARUMA | AU13: 3292 | AV13: 3417
A14: Suma de UTILIDAD OPERATIVA | B14: 39146.598 | C14: -335648.17 | D14: -335929.73 | E14: 169194.76 | F14: 584127.46 | G14: 744186.39 | H14: 245785.26 | I14: 1110862.6 | L14: Suma de UTILIDAD OPERATIVA | M14: =B14/B$7 -> 157.84919 | N14: =C14/C$7 -> -205.37733 | O14: =D14/D$7 -> -168.31834 | P14: =E14/E$7 -> 80.182909 | Q14: =F14/F$7 -> 295.2629 | R14: =G14/G$7 -> 657.53626 | S14: =H14/H$7 -> 314.74412 | T14: =I14/I$7 -> 112.4443 | X14: Suma de UTILIDAD OPERATIVA | Y14: =B14/B$8 -> 0.069333225 | Z14: =C14/C$8 -> -0.1211803 | AA14: =D14/D$8 -> -0.086264755 | AB14: =E14/E$8 -> 0.034378428 | AC14: =F14/F$8 -> 0.11658754 | AD14: =G14/G$8 -> 0.21788873 | AE14: =H14/H$8 -> 0.15464216 | AF14: =I14/I$8 -> 0.050117468 | AL14: ALAS CONGELADAS | AM14: 2273.427 | AN14: -451.32788 | AT14: REPRODUCTOR | AU14: 2724 | AV14: 2704
A15: Suma de GASTO FINANCIERO | B15: 131251 | C15: 148498 | D15: 154473 | E15: 221685 | F15: 167061.72 | G15: 121364.63 | H15: 154473 | I15: 1098806.4 | L15: Suma de GASTO FINANCIERO | M15: =B15/B$7 -> 529.2379 | N15: =C15/C$7 -> 90.863367 | O15: =D15/D$7 -> 77.399038 | P15: =E15/E$7 -> 105.0585 | Q15: =F15/F$7 -> 84.445831 | R15: =G15/G$7 -> 107.23341 | S15: =H15/H$7 -> 197.81279 | T15: =I15/I$7 -> 111.22394 | X15: Suma de GASTO FINANCIERO | Y15: =B15/B$8 -> 0.23246094 | Z15: =C15/C$8 -> 0.053612783 | AA15: =D15/D$8 -> 0.039667746 | AB15: =E15/E$8 -> 0.045043841 | AC15: =F15/F$8 -> 0.03334429 | AD15: =G15/G$8 -> 0.035534089 | AE15: =H15/H$8 -> 0.097190691 | AF15: =I15/I$8 -> 0.049573542 | AL15: FILETE DARUMA | AM15: 1927.8 | AN15: 513.07693 | AT15: NUCA | AU15: 1123 | AV15: 1171
A16: Suma de UTILIDAD NETA | B16: -92104.402 | C16: -484146.17 | D16: -490402.73 | E16: -52490.241 | F16: 417065.74 | G16: 622821.76 | H16: 91312.258 | I16: 12056.214 | L16: Suma de UTILIDAD NETA | M16: =B16/B$7 -> -371.38872 | N16: =C16/C$7 -> -296.2407 | O16: =D16/D$7 -> -245.71737 | P16: =E16/E$7 -> -24.875595 | Q16: =F16/F$7 -> 210.81707 | R16: =G16/G$7 -> 550.30285 | S16: =H16/H$7 -> 116.93133 | T16: =I16/I$7 -> 1.2203603 | X16: Suma de UTILIDAD NETA | Y16: =B16/B$8 -> -0.16312772 | Z16: =C16/C$8 -> -0.17479309 | AA16: =D16/D$8 -> -0.1259325 | AB16: =E16/E$8 -> -0.010665413 | AC16: =F16/F$8 -> 0.083243253 | AD16: =G16/G$8 -> 0.18235464 | AE16: =H16/H$8 -> 0.057451474 | AF16: =I16/I$8 -> 0.0005439259 | AL16: REPRODUCTORES | AM16: 599.405 | AN16: 126.98725 | AT16: ALAS COCIDAS | AU16: 3240 | AV16: 3318
A17: Suma de DEPRECIACIÓN | B17: 123844.28 | C17: 123844.28 | D17: 123844.28 | E17: 123844.28 | F17: 123844.28 | G17: 123844.28 | H17: 123843.49 | I17: 866909.19 | L17: Suma de DEPRECIACIÓN | M17: =B17/B$7 -> 499.37211 | N17: =C17/C$7 -> 75.778182 | O17: =D17/D$7 -> 62.052452 | P17: =E17/E$7 -> 58.690913 | Q17: =F17/F$7 -> 62.600417 | R17: =G17/G$7 -> 109.42434 | S17: =H17/H$7 -> 158.5897 | T17: =I17/I$7 -> 87.750728 | X17: Suma de DEPRECIACIÓN | Y17: =B17/B$8 -> 0.21934278 | Z17: =C17/C$8 -> 0.04471196 | AA17: =D17/D$8 -> 0.031802474 | AB17: =E17/E$8 -> 0.025163733 | AC17: =F17/F$8 -> 0.024718408 | AD17: =G17/G$8 -> 0.036260101 | AE17: =H17/H$8 -> 0.077919341 | AF17: =I17/I$8 -> 0.039111313 | AL17: NUCAS | AM17: 514.83 | AN17: -431.34411 | AT17: ALAS CONGELADAS | AU17: 1509 | AV17: 1579
A18: Suma de EBITDA | B18: 162990.88 | C18: -211803.89 | D18: -212085.45 | E18: 293039.04 | F18: 707971.75 | G18: 868030.67 | H18: 369628.75 | I18: 1977771.8 | L18: Suma de EBITDA | M18: =B18/B$7 -> 657.2213 | N18: =C18/C$7 -> -129.59915 | O18: =D18/D$7 -> -106.26588 | P18: =E18/E$7 -> 138.87382 | Q18: =F18/F$7 -> 357.86332 | R18: =G18/G$7 -> 766.9606 | S18: =H18/H$7 -> 473.33382 | T18: =I18/I$7 -> 200.19503 | X18: Suma de EBITDA | Y18: =B18/B$8 -> 0.288676 | Z18: =C18/C$8 -> -0.076468342 | AA18: =D18/D$8 -> -0.05446228 | AB18: =E18/E$8 -> 0.059542161 | AC18: =F18/F$8 -> 0.14130595 | AD18: =G18/G$8 -> 0.25414883 | AE18: =H18/H$8 -> 0.23256151 | AF18: =I18/I$8 -> 0.089228781 | AL18: ALAS COCIDAS | AM18: 384.2577 | AN18: 138.02447 | AT18: TENTACULO | AU18: 2290 | AV18: 2288
AL19: OTROS | AM19: =SUM(AM20:AM22) -> 322.51689 | AN19: =SUM(AN20:AN22) -> 91.219795
AL20: POTA CONOS | AM20: 231.72 | AN20: 0.42290479
A22: ANÁLISIS POR PRODUCTO | AL22: RESIDUOS DE POTA | AM22: 90.79689 | AN22: 90.79689 | AX22: 0.0634
AX23: 0.0478
A24: RANKING DE VENTAS (USD) | L24: UTILIDAD NETA (USD) | X24: EBITDA (USD) | AL24: Acum Abril venta y rentabilidad por cliente | AX24: 0.0459
A25: Suma de VALOR CFR | B25: Etiquetas de columna | L25: Suma de UTILIDAD NETA | M25: Etiquetas de columna | X25: Suma de EBITDA | Y25: Etiquetas de columna | AM25: Venta CFR | AN25: Utilidad Neta | AX25: 0.0371 | BB25: Suma de Cantidad | BC25: Etiquetas de columna | BG25: Suma de VALOR CFR | BH25: Etiquetas de columna
A26: Etiquetas de fila | B26: ENERO | C26: FEBRERO | D26: MARZO | E26: ABRIL | F26: MAYO | G26: JUNIO | H26: JULIO | I26: Total general | J26: % | L26: Etiquetas de fila | M26: ENERO | N26: FEBRERO | O26: MARZO | P26: ABRIL | Q26: MAYO | R26: JUNIO | S26: JULIO | T26: Total general | U26: MG | X26: Etiquetas de fila | Y26: ENERO | Z26: FEBRERO | AA26: MARZO | AB26: ABRIL | AC26: MAYO | AD26: JUNIO | AE26: JULIO | AF26: Total general | AG26: MG | AL26: TSUJINO | AM26: 2790.273 | AN26: -709.0403 | AX26: 0.0337 | BB26: Etiquetas de fila | BC26: FEBRERO | BD26: MARZO | BE26: Total general | BG26: Etiquetas de fila | BH26: FEBRERO | BI26: MARZO | BJ26: Total general | BK26: precio | BL26: precio mayo | BM26: variación | BN26: valor adicional
A27: POTA REJOS CONGELADOS | B27: 149248 | C27: 532695 | D27: 779600 | E27: 1170306 | F27: 1105650 | G27: 722550 | H27: 437010 | I27: 4897059 | J27: =I27/$I$43 -> #DIV/0! | L27: POTA REJOS CONGELADOS | M27: -5420.9051 | N27: 106971.82 | O27: 68462.268 | P27: 94521.111 | Q27: 338985.51 | R27: 211762.61 | S27: 111727.25 | T27: 927009.66 | U27: =T27/I27 -> 0.18929926 | X27: POTA REJOS CONGELADOS | Y27: 54197.331 | Z27: 141799.9 | AA27: 114620.71 | AB27: 169672.27 | AC27: 394568.99 | AD27: 269610.23 | AE27: 169464.45 | AF27: 1313933.9 | AG27: =AF27/I27 -> 0.26831081 | AL27: LONGKOU JIABAO AQUATIC | AM27: 1406.7 | AN27: 394.79634 | AX27: 0.0337 | BB27: POTA REJOS CONGELADOS | BC27: 209 | BD27: 331 | BE27: 540 | BG27: POTA REJOS CONGELADOS | BH27: 532695 | BI27: 779600 | BJ27: 1312295 | BK27: =BJ27/BE27 -> 2430.1759 | BL27: =BL47 -> 2925 | BM27: =BL27-BK27 -> 494.82407 | BN27: =BM27*BE27 -> 267205
A28: POTA FILETE CONGELADO | B28: 94800 | C28: 1147500 | D28: 430960 | E28: 1471690 | F28: 1041860 | G28: 245195 | H28: 78800 | I28: 4510805 | J28: =I28/$I$43 -> #DIV/0! | L28: POTA FILETE CONGELADO | M28: -36616.253 | N28: -502314.03 | O28: -260749.39 | P28: -498233.16 | Q28: -130347.09 | R28: -33898.989 | S28: -9786.388 | T28: -1471945.3 | U28: =T28/I28 -> -0.32631544 | X28: POTA FILETE CONGELADO | Y28: 12757.028 | Z28: -367334.37 | AA28: -219890.1 | AB28: -365776.26 | AC28: -55824.052 | AD28: -5950.1391 | AE28: 3756.9068 | AF28: -998261 | AG28: =AF28/I28 -> -0.2213044 | AL28: KULALIA | AM28: 1378.9217 | AN28: 101.0003 | AX28: 0.0333 | BB28: POTA FILETE CONGELADO | BC28: 810 | BD28: 293 | BE28: 1103 | BG28: POTA FILETE CONGELADO | BH28: 1147500 | BI28: 430960 | BJ28: 1578460 | BK28: =BJ28/BE28 -> 1431.0607 | BL28: =BL45 -> 2055.7616 | BM28: =BL28-BK28 -> 624.7009 | BN28: =BM28*BE28 -> 689045.09
A29: POTA FILETE DARUMA | C29: 91800 | D29: 1004400 | E29: 831600 | F29: 1142100 | G29: 1273050 | I29: 4342950 | J29: =I29/$I$43 -> #DIV/0! | L29: POTA FILETE DARUMA | N29: 28158.374 | O29: 209162.38 | P29: 240368.96 | Q29: 88911.734 | R29: 183241.93 | T29: 749843.38 | U29: =T29/I29 -> 0.17265761 | X29: POTA FILETE DARUMA | Z29: 32657.696 | AA29: 254344.67 | AB29: 275738.84 | AC29: 132584.47 | AD29: 253439.04 | AF29: 948764.71 | AG29: =AF29/I29 -> 0.21846089 | AL29: AVANCE GROUP | AM29: 1097.2 | AN29: -468.13754 | AX29: 0.0333 | BB29: POTA FILETE DARUMA | BC29: 27 | BD29: 324 | BE29: 351 | BG29: POTA FILETE DARUMA | BH29: 91800 | BI29: 1004400 | BJ29: 1096200 | BK29: =BJ29/BE29 -> 3123.0769 | BL29: =BL52 -> 3845.4545 | BM29: =BL29-BK29 -> 722.37762 | BN29: =BM29*BE29 -> 253554.55
A30: POTA ALAS CONGELADAS | B30: 135915 | C30: 710550 | D30: 768480 | E30: 656562 | F30: 591300 | G30: 251204 | H30: 94500 | I30: 3208511 | J30: =I30/$I$43 -> #DIV/0! | L30: POTA ALAS CONGELADAS | M30: -50223.333 | N30: -182032.49 | O30: -219374.82 | P30: -130881.72 | Q30: -62443.666 | R30: -1295.0638 | S30: -22774.894 | T30: -669025.99 | U30: =T30/I30 -> -0.20851603 | X30: POTA ALAS CONGELADAS | Y30: 23836.588 | Z30: -105494.02 | AA30: -152047.64 | AB30: -74614.146 | AC30: -18770.93 | AD30: 25353.84 | AE30: -3529.1597 | AF30: -305265.47 | AG30: =AF30/I30 -> -0.095142411 | AL30: FOOD & BEVERAGES TRADERS | AM30: 935.406 | AN30: -74.238541 | AX30: 0.032 | BB30: POTA ALAS CONGELADAS | BC30: 459.3 | BD30: 482.8 | BE30: 942.1 | BG30: POTA ALAS CONGELADAS | BH30: 710550 | BI30: 768480 | BJ30: 1479030 | BK30: =BJ30/BE30 -> 1569.9289 | BL30: =BL46 -> 1990.9091 | BM30: =BL30-BK30 -> 420.98021 | BN30: =BM30*BE30 -> 396605.45
A31: POTA ALAS COCIDAS | D31: 177221.7 | E31: 207036 | F31: 417358 | G31: 668601 | I31: 1470216.7 | J31: =I31/$I$43 -> #DIV/0! | L31: POTA ALAS COCIDAS | O31: 42400.96 | P31: 33173.727 | Q31: 80533.149 | R31: 196924.08 | T31: 353031.92 | U31: =T31/I31 -> 0.24012237 | X31: POTA ALAS COCIDAS | AA31: 49931.34 | AB31: 41868.821 | AC31: 96308.271 | AD31: 231866.65 | AF31: 419975.08 | AG31: =AF31/I31 -> 0.28565522 | AL31: Qingdao Haiyujia | AM31: 595.782 | AN31: 101.96621 | AX31: 0.0318 | BB31: POTA ALAS COCIDAS | BD31: 54 | BE31: 54 | BG31: POTA ALAS COCIDAS | BI31: 177221.7 | BJ31: 177221.7 | BK31: =BJ31/BE31 -> 3281.8833 | BL31: =BL53 -> 3890.3617 | BM31: =BL31-BK31 -> 608.47834 | BN31: =BM31*BE31 -> 32857.83
A32: POTA REPRODUCTORES | B32: 74064 | C32: 77585 | D32: 139200 | E32: 308556 | F32: 154700 | G32: 70980 | H32: 214416 | I32: 1039501 | J32: =I32/$I$43 -> #DIV/0! | L32: POTA REPRODUCTORES | M32: 4890.763 | N32: 23262.951 | O32: 29982.789 | P32: 61843.08 | Q32: 47178.889 | R32: 23179.219 | S32: 57701.204 | T32: 248038.89 | U32: =T32/I32 -> 0.23861342 | X32: POTA REPRODUCTORES | Y32: 31634.623 | Z32: 27762.272 | AA32: 37094.815 | AB32: 78840.269 | AC32: 54825.294 | AD32: 28812.32 | AE32: 85857.001 | AF32: 344826.59 | AG32: =AF32/I32 -> 0.3317232 | AL32: Longkou Yunfeng Aquatic Food | AM32: 575.1 | AN32: -44.789183 | AX32: 0.0316 | BB32: POTA REPRODUCTORES | BC32: 27 | BD32: 51 | BE32: 78 | BG32: POTA REPRODUCTORES | BH32: 77585 | BI32: 139200 | BJ32: 216785 | BK32: =BJ32/BE32 -> 2779.2949 | BL32: =BL48 -> 2975 | BM32: =BL32-BK32 -> 195.70513 | BN32: =BM32*BE32 -> 15265
A33: POTA NUCAS | B33: 35874 | C33: 23456 | D33: 455500 | F33: 221025 | G33: 59625 | H33: 201300 | I33: 996780 | J33: =I33/$I$43 -> #DIV/0! | L33: POTA NUCAS | M33: -19244.525 | N33: -6321.5029 | O33: -407078.31 | Q33: -144985.3 | R33: -29502.695 | S33: -99499.18 | T33: -706631.52 | U33: =T33/I33 -> -0.70891422 | X33: POTA NUCAS | Y33: 1368.8194 | Z33: -3988.5212 | AA33: -353389.49 | AC33: -118075.84 | AD33: -18994.794 | AE33: -45326.001 | AF33: -538405.82 | AG33: =AF33/I33 -> -0.54014509 | AL33: OTROS | AM33: =SUM(AM34:AM51) -> 2863.8454 | AN33: =SUM(AN34:AN51) -> -19.037084 | AX33: 0.0302 | BB33: POTA NUCAS | BC33: 14 | BD33: 385 | BE33: 399 | BG33: POTA NUCAS | BH33: 23456 | BI33: 455500 | BJ33: 478956 | BK33: =BJ33/BE33 -> 1200.391 | BL33: =BL49 -> 1207.7869 | BM33: =BL33-BK33 -> 7.3959078 | BN33: =BM33*BE33 -> 2950.9672
A34: POTA CONOS | B34: 50400 | C34: 69000 | D34: 76800 | E34: 35520 | F34: 43200 | G34: 46018 | H34: 86400 | I34: 407338 | J34: =I34/$I$43 -> #DIV/0! | L34: POTA CONOS | M34: -9804.429 | N34: 15489.988 | O34: -6150.1256 | P34: -10246.326 | Q34: 2027.9024 | R34: 4450.8385 | S34: -4175.4894 | T34: -8407.641 | U34: =T34/I34 -> -0.020640453 | X34: POTA CONOS | Y34: 14882.211 | Z34: 21155.801 | AA34: 543.54588 | AB34: -6611.0886 | AC34: 5557.0123 | AD34: 10300.598 | AE34: 15070.245 | AF34: 60898.325 | AG34: =AF34/I34 -> 0.14950318 | AL34: OVERSEA | AM34: 354.595 | AN34: 86.215827 | AX34: 0.03 | BB34: POTA CONOS | BC34: 34 | BD34: 48 | BE34: 82 | BG34: POTA CONOS | BH34: 69000 | BI34: 76800 | BJ34: 145800 | BK34: =BJ34/BE34 -> 1778.0488 | BL34: =BL55 -> 1800 | BM34: =BL34-BK34 -> 21.95122 | BN34: =BM34*BE34 -> 1800
A35: POTA RECORTES COCIDOS | E35: 67500 | F35: 126786 | H35: 136350 | I35: 330636 | J35: =I35/$I$43 -> #DIV/0! | L35: POTA RECORTES COCIDOS | P35: 10368.202 | Q35: 110306.03 | S35: 40811.702 | T35: 161485.94 | U35: =T35/I35 -> 0.48841003 | X35: POTA RECORTES COCIDOS | AB35: 14789.436 | AC35: 118246.53 | AE35: 60057.437 | AF35: 193093.4 | AG35: =AF35/I35 -> 0.58400599 | AL35: Pesciro Asia International LTD. | AM35: 352.35 | AN35: -117.23253 | BB35: POTA TELILLA PRECOCIDA | BC35: 27 | BE35: 27 | BG35: POTA TELILLA PRECOCIDA | BH35: 38606.25 | BJ35: 38606.25 | BK35: =BJ35/BE35 -> 1429.8611 | BL35: =BL57 -> 2050 | BM35: =BL35-BK35 -> 620.13889 | BN35: =BM35*BE35 -> 16743.75
A36: POTA TELILLA PRECOCIDA | C36: 38606.25 | E36: 52200 | F36: 53812.5 | H36: 127848 | I36: 272466.75 | J36: =I36/$I$43 -> #DIV/0! | L36: POTA TELILLA PRECOCIDA | N36: -3693.6397 | P36: 43644.778 | Q36: 46854.792 | S36: -10045.752 | T36: 76760.179 | U36: =T36/I36 -> 0.2817231 | X36: POTA TELILLA PRECOCIDA | Z36: 805.68215 | AB36: 47918.638 | AC36: 50714.756 | AE36: 18432.589 | AF36: 117871.67 | AG36: =AF36/I36 -> 0.43260936 | AL36: OCEANUS FISH | AM36: 340.564 | AN36: -36.175426 | BB36: POTA MEMBRANA PRECOCIDA | BC36: 27 | BD36: 27 | BE36: 54 | BG36: POTA MEMBRANA PRECOCIDA | BH36: 38606.25 | BI36: 35553 | BJ36: 74159.25 | BK36: =BJ36/BE36 -> 1373.3194 | BL36: =BK58 -> 2000 | BM36: =BL36-BK36 -> 626.68056 | BN36: =BM36*BE36 -> 33840.75 | BQ36: venta | BR36: utilidad | BS36: margen neto
A37: POTA MEMBRANA PRECOCIDA | C37: 38606.25 | D37: 35553 | E37: 52500 | H37: 186300 | I37: 312959.25 | J37: =I37/$I$43 -> #DIV/0! | L37: POTA MEMBRANA PRECOCIDA | N37: -3693.6397 | O37: 26484.907 | P37: 43914.109 | S37: 897.19774 | T37: 67602.574 | U37: =T37/I37 -> 0.21601079 | X37: POTA MEMBRANA PRECOCIDA | Z37: 805.68215 | AA37: 30250.097 | AB37: 48212.531 | AE37: 39388.667 | AF37: 118656.98 | AG37: =AF37/I37 -> 0.37914514 | AL37: LONGKOU BOHAI | AM37: 334.8 | AN37: 61.759822 | BB37: RESIDUOS DE POTA | BC37: 0 | BD37: 0 | BE37: 0 | BG37: RESIDUOS DE POTA | BH37: 40026 | BI37: 26456.61 | BJ37: 66482.61 | BK37: =BJ37/BE37 -> #DIV/0! | BP37: feb-mar actual | BQ37: =GETPIVOTDATA("VALOR CFR",$BG$25) -> 6663995.8 | BR37: =GETPIVOTDATA("UTILIDAD NETA",$BB$44) -> -974548.9 | BS37: =BR37/BQ37 -> -0.14624092
A38: POTA LABIOS CONGELADOS | F38: 34720 | G38: 35224 | I38: 69944 | J38: =I38/$I$43 -> #DIV/0! | L38: POTA LABIOS CONGELADOS | Q38: 24875.591 | R38: 24964.528 | T38: 49840.119 | U38: =T38/I38 -> 0.71257175 | X38: POTA LABIOS CONGELADOS | AC38: 28698.793 | AD38: 30597.63 | AF38: 59296.423 | AG38: =AF38/I38 -> 0.84776997 | AL38: GLOBAL OCEAN | AM38: 285.485 | AN38: 31.414281 | BB38: Total general | BC38: 1634.3 | BD38: 1995.8 | BE38: 3630.1 | BG38: Total general | BH38: 2769824.5 | BI38: 3894171.3 | BJ38: 6663995.8 | BK38: =BJ38/BE38 -> 1835.7609 | BN38: =SUM(BN27:BN37) -> 1709868.4 | BP38: feb-mar esperando | BQ38: =GETPIVOTDATA("VALOR CFR",$BG$25)+BN38 -> 8373864.2 | BR38: =BN38+GETPIVOTDATA("UTILIDAD NETA",$BB$44)-BR41 -> 696496.64 | BS38: =BR38/BQ38 -> 0.083175058
A39: POTA TUBOALETA | F39: 54080 | I39: 54080 | J39: =I39/$I$43 -> #DIV/0! | L39: POTA TUBOALETA | Q39: -8445.056 | T39: -8445.056 | U39: =T39/I39 -> -0.15615858 | X39: POTA TUBOALETA | AC39: -4474.8073 | AF39: -4474.8073 | AG39: =AF39/I39 -> -0.082744217 | AL39: DAIRECK S.A. | AM39: 280.782 | AN39: -291.00909 | BQ39: =BQ38-BQ37 -> 1709868.4 | BR39: =BR38-BR37 -> 1671045.5 | BS39: =BS38-BS37 -> 0.22941598
A40: POTA SUCKERS CONGELADO | E40: 30300 | I40: 30300 | J40: =I40/$I$43 -> #DIV/0! | L40: POTA SUCKERS CONGELADO | P40: 21268.427 | T40: 21268.427 | U40: =T40/I40 -> 0.70192828 | X40: POTA SUCKERS CONGELADO | AB40: 25231.163 | AF40: 25231.163 | AG40: =AF40/I40 -> 0.83271164 | AL40: YANTAI TAIXI FOODSTUFF | AM40: 279.504 | AN40: 19.044143
A41: RESIDUOS DE POTA | B41: 24314.28 | C41: 40026 | D41: 26456.61 | E41: 37768.57 | F41: 23613.25 | G41: 42995.3 | H41: 26456.61 | I41: 221630.62 | J41: =I41/$I$43 -> #DIV/0! | L41: RESIDUOS DE POTA | M41: 24314.28 | N41: 40026 | O41: 26456.61 | P41: 37768.57 | Q41: 23613.25 | R41: 42995.3 | S41: 26456.61 | T41: 221630.62 | U41: =T41/I41 -> 1 | X41: RESIDUOS DE POTA | Y41: 24314.28 | Z41: 40026 | AA41: 26456.61 | AB41: 37768.57 | AC41: 23613.25 | AD41: 42995.3 | AE41: 26456.61 | AF41: 221630.62 | AG41: =AF41/I41 -> 1 | BR41: =GETPIVOTDATA("COSTO VENTAS",$BB$60)*7%/12 -> 38822.848
A42: Total general | B42: 564615.28 | C42: 2769824.5 | D42: 3894171.3 | E42: 4921538.6 | F42: 5010204.8 | G42: 3415442.3 | H42: 1589380.6 | I42: 22165177 | J42: =I42/$I$43 -> #DIV/0! | L42: Total general | M42: -92104.402 | N42: -484146.17 | O42: -490402.73 | P42: -52490.241 | Q42: 417065.74 | R42: 622821.76 | S42: 91312.258 | T42: 12056.214 | U42: =T42/I42 -> 0.0005439259 | X42: Total general | Y42: 162990.88 | Z42: -211803.89 | AA42: -212085.45 | AB42: 293039.04 | AC42: 707971.75 | AD42: 868030.67 | AE42: 369628.75 | AF42: 1977771.8 | AG42: =AF42/I42 -> 0.089228781
...

Sheet Resumen
G2: X | H2: X | M2: X | P2: X | AW2: X | AX2: X | BC2: ANÁLISIS UNITARIO
B3: MES LINK | C3: MES EJERCICIO | D3: FP | E3: Emision | F3: Fecha Embarque | G3: Cantidad | H3: Producto | I3: Corte | J3: Espec. | K3: País | L3: Puerto | M3: Cliente (Razón Social) | N3: Contacto | O3: Precio TM | P3: VALOR CFR | Q3: FOB / TM | R3: Costo Flete | S3: VALOR FOB | T3: Cantidad de FCL (Contenedores) | U3: M/V Nave | V3: Booking | W3: Naviera | X3: Puerto | Y3: Tipo Producto | Z3: CÓDIGO | AA3: Categoría | AB3: MATCH | AC3: COSTO UNITARIO | AD3: Materia Prima | AE3: MOD | AF3: Envases | AG3: CIF | AH3: COSTO VENTAS | AI3: Cant | AJ3: C.U | AK3: Cotos Vta | AL3: UTILIDAD BRUTA | AM3: MARGEN BRUTO | AN3: Flete | AO3: Otros Gastos Ventas | AP3: Ajuste | AQ3: GASTO VENTAS | AR3: GASTO ADM | AS3: DRAWBACK | AT3: UTILIDAD OPERATIVA | AU3: MARGEN OPERATIVO | AV3: GASTO FINANCIERO | AW3: UTILIDAD NETA | AX3: MARGEN NETO | AY3: DEPRECIACIÓN | AZ3: EBITDA | BA3: MARGEN EBITDA | BC3: PRECIO CFR | BD3: Materia Prima | BE3: MOD | BF3: Envases | BG3: CIF | BH3: COSTO VENTAS | BI3: UTILIDAD BRUTA | BJ3: Flete | BK3: SS Logístico | BL3: GASTO VENTAS | BM3: GASTO ADM | BN3: DRAWBACK | BO3: UTILIDAD OPERATIVA | BP3: GASTO FINANCIERO | BQ3: UTILIDAD NETA | BR3: DEPRECIACIÓN | BS3: EBITDA
B4: ENERO | C4: =B4 -> ENERO | D4: 127-2025 | E4: 325 | F4: 46033 | G4: 26 | H4: POTA REPRODUCTORES | I4: Rejos | K4: España | L4: Valencia | M4: OCEANUS FISH | N4: Ignacio / Ives | O4: =P4/G4 -> 2848.6154 | P4: =78000*0+74064 -> 74064 | Q4: =S4/G4 -> 2670.3846 | R4: 4634 | S4: =P4-R4 -> 69430 | T4: 1 | U4: MERSIN EXPRESS 603N | V4: 26106924 | W4: HAPAG | X4: PAITA | Y4: Fresco | Z4: 10007567 | AA4: Compensación | AB4: =B4&Z4&AA4 -> ENERO10007567Compensación | AC4: =INDEX('Detalle Costos'!$L$5:$L$158,MATCH(Resumen!AB4,'Detalle Costos'!$C$5:$C$158,0))*1000+4623.769999996/248 -> 1848.6442 | AD4: =IFERROR(INDEX('Detalle Costos'!$X$5:$X$158,MATCH(Resumen!AB4,'Detalle Costos'!$C$5:$C$158,0))*AH4,0) -> 31139.447 | AE4: =IFERROR(INDEX('Detalle Costos'!$Z$5:$Z$158,MATCH(Resumen!AB4,'Detalle Costos'!$C$5:$C$158,0))*AH4,0) -> 7653.4663 | AF4: =IFERROR(INDEX('Detalle Costos'!$Y$5:$Y$158,MATCH(Resumen!AB4,'Detalle Costos'!$C$5:$C$158,0))*AH4,0) -> 459.33891 | AG4: =IFERROR(INDEX('Detalle Costos'!$AA$5:$AA$158,MATCH(Resumen!AB4,'Detalle Costos'!$C$5:$C$158,0))*AH4,0) -> 7628.333 | AH4: =AJ4*G4+6518.87/248*G4 -> 46880.585 | AI4: =48.96-AI17 -> 22.658 | AJ4: 1776.8137 | AK4: =89589.14-AK17 -> 41460.14 | AL4: =P4-AH4 -> 27183.415 | AM4: =AL4/P4 -> 0.36702602 | AN4: =R4 -> 4634 | AO4: =118461.136538461/5988.21*G4+6*G4 -> 670.34227 | AP4: 0 | AQ4: =SUM(AN4:AP4) -> 5304.3423 | AR4: =50659/248*G4 -> 5311.0242 | AS4: =S4*0.03 -> 2082.9 | AT4: =AL4-AQ4-AR4+AS4 -> 18650.949 | AU4: =AT4/P4 -> 0.25182205 | AV4: =131251/248*G4 -> 13760.185 | AW4: =AT4-AV4 -> 4890.763 | AX4: =AW4/P4 -> 0.066034281 | AY4: =123844.283333333/248*G4 -> 12983.675 | AZ4: =AT4+AY4 -> 31634.623 | BA4: =AZ4/P4 -> 0.4271255 | BC4: =P4/$G4 -> 2848.6154 | BD4: =-AD4/$G4 -> -1197.671 | BE4: =-AE4/$G4 -> -294.36409 | BF4: =-AF4/$G4 -> -17.666881 | BG4: =-AG4/$G4 -> -293.39742 | BH4: =-AH4/$G4 -> -1803.0994 | BI4: =AL4/$G4 -> 1045.516 | BJ4: =-AN4/$G4 -> -178.23077 | BK4: =-AP4/$G4 -> 0 | BL4: =-AQ4/$G4 -> -204.01316 | BM4: =-AR4/$G4 -> -204.27016 | BN4: =AS4/$G4 -> 80.111538 | BO4: =AT4/$G4 -> 717.34417 | BP4: =-AV4/$G4 -> -529.2379 | BQ4: =AW4/$G4 -> 188.10627 | BR4: =AY4/$G4 -> 499.37211 | BS4: =AZ4/$G4 -> 1216.7163
B5: ENERO | C5: =B5 -> ENERO | D5: 128-2025B | E5: 325 | F5: 46053 | G5: 17.04 | H5: POTA NUCAS | I5: Nucas | J5: 1000-up | K5: Tailandia | L5: Lat Krabang | M5: DAIRECK S.A. | N5: Julieta | O5: 1850 | P5: 31524 | Q5: 1656.338 | R5: =3300/24*G5 -> 2343 | S5: =P5-R5 -> 29181 | T5: 1 | U5: ECO SIROCCO 26005S | V5: 6443191850 | W5: COSCO | X5: PAITA | Y5: Fresco | Z5: 10005779 | AA5: Compensación | AB5: =B5&Z5&AA5 -> ENERO10005779Compensación | AC5: =INDEX('Detalle Costos'!$L$5:$L$158,MATCH(Resumen!AB5,'Detalle Costos'!$C$5:$C$158,0))*1000+4623.769999996/248 -> 1948.6442 | AD5: =IFERROR(INDEX('Detalle Costos'!$X$5:$X$158,MATCH(Resumen!AB5,'Detalle Costos'!$C$5:$C$158,0))*AH5,0) -> 20410.224 | AE5: =IFERROR(INDEX('Detalle Costos'!$Z$5:$Z$158,MATCH(Resumen!AB5,'Detalle Costos'!$C$5:$C$158,0))*AH5,0) -> 6891.7519 | AF5: =IFERROR(INDEX('Detalle Costos'!$Y$5:$Y$158,MATCH(Resumen!AB5,'Detalle Costos'!$C$5:$C$158,0))*AH5,0) -> 247.66592 | AG5: =IFERROR(INDEX('Detalle Costos'!$AA$5:$AA$158,MATCH(Resumen!AB5,'Detalle Costos'!$C$5:$C$158,0))*AH5,0) -> 4881.1167 | AH5: =AJ5*G5+6518.87/248*G5 -> 32430.759 | AI5: 17.04 | AJ5: 1876.9278 | AK5: 33696.517 | AL5: =P5-AH5 -> -906.75879 | AM5: =AL5/P5 -> -0.028764078 | AN5: =R5 -> 2343 | AO5: =118461.136538461/5988.21*G5+6*G5 -> 439.33201 | AP5: 0 | AQ5: =SUM(AN5:AP5) -> 2782.332 | AR5: =50659/248*G5 -> 3480.7635 | AS5: =S5*0.03 -> 875.43 | AT5: =AL5-AQ5-AR5+AS5 -> -6294.4244 | AU5: =AT5/P5 -> -0.19967087 | AV5: =131251/248*G5 -> 9018.2139 | AW5: =AT5-AV5 -> -15312.638 | AX5: =AW5/P5 -> -0.48574541 | AY5: =123844.283333333/248*G5 -> 8509.3008 | AZ5: =AT5+AY5 -> 2214.8764 | BA5: =AZ5/P5 -> 0.070260005 | BC5: =P5/$G5 -> 1850 | BD5: =-AD5/$G5 -> -1197.7831 | BE5: =-AE5/$G5 -> -404.44554 | BF5: =-AF5/$G5 -> -14.534385 | BG5: =-AG5/$G5 -> -286.45051 | BH5: =-AH5/$G5 -> -1903.2135 | BI5: =AL5/$G5 -> -53.213544 | BJ5: =-AN5/$G5 -> -137.5 | BK5: =-AP5/$G5 -> 0 | BL5: =-AQ5/$G5 -> -163.2824 | BM5: =-AR5/$G5 -> -204.27016 | BN5: =AS5/$G5 -> 51.375 | BO5: =AT5/$G5 -> -369.3911 | BP5: =-AV5/$G5 -> -529.2379 | BQ5: =AW5/$G5 -> -898.629 | BR5: =AY5/$G5 -> 499.37211 | BS5: =AZ5/$G5 -> 129.98101
B6: ENERO | C6: =B6 -> ENERO | D6: 128-2025B | E6: 325 | F6: 46053 | G6: 3 | H6: POTA NUCAS | I6: Nucas | J6: 500 - 1 kg. | K6: Tailandia | L6: Lat Krabang | M6: DAIRECK S.A. | N6: Julieta | O6: 1450 | P6: 4350 | Q6: 1450 | R6: =3300/24*G6 -> 412.5 | S6: =P6-R6 -> 3937.5 | T6: 0 | V6: 6443191850 | W6: COSCO | X6: PAITA | Y6: Fresco | Z6: 10005781 | AA6: Compensación | AB6: =B6&Z6&AA6 -> ENERO10005781Compensación | AC6: =INDEX('Detalle Costos'!$L$5:$L$158,MATCH(Resumen!AB6,'Detalle Costos'!$C$5:$C$158,0))*1000+4623.769999996/248 -> 1998.6442 | AD6: =IFERROR(INDEX('Detalle Costos'!$X$5:$X$158,MATCH(Resumen!AB6,'Detalle Costos'!$C$5:$C$158,0))*AH6,0) -> 3611.3123 | AE6: =IFERROR(INDEX('Detalle Costos'!$Z$5:$Z$158,MATCH(Resumen!AB6,'Detalle Costos'!$C$5:$C$158,0))*AH6,0) -> 1180.1894 | AF6: =IFERROR(INDEX('Detalle Costos'!$Y$5:$Y$158,MATCH(Resumen!AB6,'Detalle Costos'!$C$5:$C$158,0))*AH6,0) -> 48.013379 | AG6: =IFERROR(INDEX('Detalle Costos'!$AA$5:$AA$158,MATCH(Resumen!AB6,'Detalle Costos'!$C$5:$C$158,0))*AH6,0) -> 870.12557 | AH6: =AJ6*G6+6518.87/248*G6 -> 5709.6406 | AI6: 3 | AJ6: 1876.9278 | AK6: 5803.9692 | AL6: =P6-AH6 -> -1359.6406 | AM6: =AL6/P6 -> -0.31256106 | AN6: =R6 -> 412.5 | AO6: =118461.136538461/5988.21*G6+6*G6 -> 77.347185 | AP6: 0 | AQ6: =SUM(AN6:AP6) -> 489.84719 | AR6: =50659/248*G6 -> 612.81048 | AS6: =S6*0.03 -> 118.125 | AT6: =AL6-AQ6-AR6+AS6 -> -2344.1733 | AU6: =AT6/P6 -> -0.53889041 | AV6: =131251/248*G6 -> 1587.7137 | AW6: =AT6-AV6 -> -3931.887 | AX6: =AW6/P6 -> -0.90388207 | AY6: =123844.283333333/248*G6 -> 1498.1163 | AZ6: =AT6+AY6 -> -846.05697 | BA6: =AZ6/P6 -> -0.19449586 | BC6: =P6/$G6 -> 1450 | BD6: =-AD6/$G6 -> -1203.7708 | BE6: =-AE6/$G6 -> -393.39646 | BF6: =-AF6/$G6 -> -16.00446 | BG6: =-AG6/$G6 -> -290.04186 | BH6: =-AH6/$G6 -> -1903.2135 | BI6: =AL6/$G6 -> -453.21354 | BJ6: =-AN6/$G6 -> -137.5 | BK6: =-AP6/$G6 -> 0 | BL6: =-AQ6/$G6 -> -163.2824 | BM6: =-AR6/$G6 -> -204.27016 | BN6: =AS6/$G6 -> 39.375 | BO6: =AT6/$G6 -> -781.3911 | BP6: =-AV6/$G6 -> -529.2379 | BQ6: =AW6/$G6 -> -1310.629 | BR6: =AY6/$G6 -> 499.37211 | BS6: =AZ6/$G6 -> -282.01899
B7: ENERO | C7: =B7 -> ENERO | D7: 128-2025B | E7: 325 | F7: 46053 | G7: 3.96 | H7: POTA REJOS CONGELADOS | I7: Rejos | J7: 1 - 2 kgs. | K7: Tailandia | L7: Lat Krabang | M7: DAIRECK S.A. | N7: Julieta | O7: =P7/G7 -> 2234.3434 | P7: 8848 | Q7: 2800 | R7: =3300/24*G7 -> 544.5 | S7: =P7-R7 -> 8303.5 | T7: 0 | V7: 6443191850 | W7: COSCO | X7: PAITA | Y7: Fresco | Z7: 10007162 | AA7: Compensación | AB7: =B7&Z7&AA7 -> ENERO10007162Compensación | AC7: =INDEX('Detalle Costos'!$L$5:$L$158,MATCH(Resumen!AB7,'Detalle Costos'!$C$5:$C$158,0))*1000+4623.769999996/248 -> 1808.6442 | AD7: =IFERROR(INDEX('Detalle Costos'!$X$5:$X$158,MATCH(Resumen!AB7,'Detalle Costos'!$C$5:$C$158,0))*AH7,0) -> 4667.691 | AE7: =IFERROR(INDEX('Detalle Costos'!$Z$5:$Z$158,MATCH(Resumen!AB7,'Detalle Costos'!$C$5:$C$158,0))*AH7,0) -> 1231.5249 | AF7: =IFERROR(INDEX('Detalle Costos'!$Y$5:$Y$158,MATCH(Resumen!AB7,'Detalle Costos'!$C$5:$C$158,0))*AH7,0) -> 62.750793 | AG7: =IFERROR(INDEX('Detalle Costos'!$AA$5:$AA$158,MATCH(Resumen!AB7,'Detalle Costos'!$C$5:$C$158,0))*AH7,0) -> 1223.9163 | AH7: =AJ7*G7+6518.87/248*G7 -> 7185.8829 | AI7: 3.16 | AJ7: 1788.3311 | AK7: 5822.9227 | AL7: =P7-AH7 -> 1662.1171 | AM7: =AL7/P7 -> 0.1878523 | AN7: =R7 -> 544.5 | AO7: =118461.136538461/5988.21*G7+6*G7 -> 102.09828 | AP7: 0 | AQ7: =SUM(AN7:AP7) -> 646.59828 | AR7: =50659/248*G7 -> 808.90984 | AS7: =S7*0.03 -> 249.105 | AT7: =AL7-AQ7-AR7+AS7 -> 455.71398 | AU7: =AT7/P7 -> 0.051504745 | AV7: =131251/248*G7 -> 2095.7821 | AW7: =AT7-AV7 -> -1640.0681 | AX7: =AW7/P7 -> -0.18536032 | AY7: =123844.283333333/248*G7 -> 1977.5136 | AZ7: =AT7+AY7 -> 2433.2275 | BA7: =AZ7/P7 -> 0.27500311 | BC7: =P7/$G7 -> 2234.3434 | BD7: =-AD7/$G7 -> -1178.7098 | BE7: =-AE7/$G7 -> -310.99112 | BF7: =-AF7/$G7 -> -15.84616 | BG7: =-AG7/$G7 -> -309.06977 | BH7: =-AH7/$G7 -> -1814.6169 | BI7: =AL7/$G7 -> 419.72654 | BJ7: =-AN7/$G7 -> -137.5 | BK7: =-AP7/$G7 -> 0 | BL7: =-AQ7/$G7 -> -163.2824 | BM7: =-AR7/$G7 -> -204.27016 | BN7: =AS7/$G7 -> 62.905303 | BO7: =AT7/$G7 -> 115.07929 | BP7: =-AV7/$G7 -> -529.2379 | BQ7: =AW7/$G7 -> -414.15861 | BR7: =AY7/$G7 -> 499.37211 | BS7: =AZ7/$G7 -> 614.4514
B8: ENERO | C8: =B8 -> ENERO | D8: 129-2025 | E8: 45982 | F8: 46031 | G8: 24 | H8: POTA CONOS | I8: Conos | K8: Tailandia | L8: Bangkok | M8: TSUJINO | N8: Jose | O8: 2100 | P8: 50400 | Q8: 1962.5 | R8: 3300 | S8: =P8-R8 -> 47100 | T8: 1 | U8: ECO MARIN 26002S | V8: 6440924270 | W8: COSCO | X8: PAITA | Y8: Subproducto | Z8: 10007969 | AA8: Compensación | AB8: =B8&Z8&AA8 -> ENERO10007969Compensación | AC8: =INDEX('Detalle Costos'!$L$5:$L$158,MATCH(Resumen!AB8,'Detalle Costos'!$C$5:$C$158,0))*1000+4623.769999996/248 -> 1658.6442 | AD8: =IFERROR(INDEX('Detalle Costos'!$X$5:$X$158,MATCH(Resumen!AB8,'Detalle Costos'!$C$5:$C$158,0))*AH8,0) -> 30999.473 | AE8: =IFERROR(INDEX('Detalle Costos'!$Z$5:$Z$158,MATCH(Resumen!AB8,'Detalle Costos'!$C$5:$C$158,0))*AH8,0) -> 5431.3037 | AF8: =IFERROR(INDEX('Detalle Costos'!$Y$5:$Y$158,MATCH(Resumen!AB8,'Detalle Costos'!$C$5:$C$158,0))*AH8,0) -> 411.06065 | AG8: =IFERROR(INDEX('Detalle Costos'!$AA$5:$AA$158,MATCH(Resumen!AB8,'Detalle Costos'!$C$5:$C$158,0))*AH8,0) -> 3252.6203 | AH8: =AJ8*G8+6518.87/248*G8 -> 40094.458 | AI8: 24 | AJ8: =+AK8/AI8 -> 1644.3167 | AK8: 39463.6 | AL8: =P8-AH8 -> 10305.542 | AM8: =AL8/P8 -> 0.20447504 | AN8: =R8 -> 3300 | AO8: =118461.136538461/5988.21*G8+6*G8 -> 618.77748 | AP8: 0 | AQ8: =SUM(AN8:AP8) -> 3918.7775 | AR8: =50659/248*G8 -> 4902.4839 | AS8: =S8*0.03 -> 1413 | AT8: =AL8-AQ8-AR8+AS8 -> 2897.2806 | AU8: =AT8/P8 -> 0.057485727 | AV8: =131251/248*G8 -> 12701.71 | AW8: =AT8-AV8 -> -9804.429 | AX8: =AW8/P8 -> -0.19453232 | AY8: =123844.283333333/248*G8 -> 11984.931 | AZ8: =AT8+AY8 -> 14882.211 | BA8: =AZ8/P8 -> 0.29528197 | BC8: =P8/$G8 -> 2100 | BD8: =-AD8/$G8 -> -1291.6447 | BE8: =-AE8/$G8 -> -226.30432 | BF8: =-AF8/$G8 -> -17.127527 | BG8: =-AG8/$G8 -> -135.52585 | BH8: =-AH8/$G8 -> -1670.6024 | BI8: =AL8/$G8 -> 429.39758 | BJ8: =-AN8/$G8 -> -137.5 | BK8: =-AP8/$G8 -> 0 | BL8: =-AQ8/$G8 -> -163.2824 | BM8: =-AR8/$G8 -> -204.27016 | BN8: =AS8/$G8 -> 58.875 | BO8: =AT8/$G8 -> 120.72003 | BP8: =-AV8/$G8 -> -529.2379 | BQ8: =AW8/$G8 -> -408.51788 | BR8: =AY8/$G8 -> 499.37211 | BS8: =AZ8/$G8 -> 620.09214
B9: ENERO | C9: =B9 -> ENERO | D9: 137-2025 | E9: 46000 | F9: 46043 | G9: 24 | H9: POTA FILETE CONGELADO | I9: Filete | J9: 2 - 4 kg | K9: Taiwan | L9: KAOHSIUNG | M9: TSUJINO | N9: Jose | O9: =P9/G9 -> 1966.6667 | P9: =48000*0+47200 -> 47200 | Q9: =S9/G9 -> 1841.5417 | R9: 3003 | S9: =P9-R9 -> 44197 | T9: 1 | U9: ECO MARIN 25052N | V9: LIMF26385300 | W9: ONE | X9: PAITA | Y9: Fresco | Z9: 10005721 | AA9: Compensación | AB9: =B9&Z9&AA9 -> ENERO10005721Compensación | AC9: =INDEX('Detalle Costos'!$L$5:$L$158,MATCH(Resumen!AB9,'Detalle Costos'!$C$5:$C$158,0))*1000+4623.769999996/248 -> 1878.6442 | AD9: =IFERROR(INDEX('Detalle Costos'!$X$5:$X$158,MATCH(Resumen!AB9,'Detalle Costos'!$C$5:$C$158,0))*AH9,0) -> 27693.143 | AE9: =IFERROR(INDEX('Detalle Costos'!$Z$5:$Z$158,MATCH(Resumen!AB9,'Detalle Costos'!$C$5:$C$158,0))*AH9,0) -> 10045.917 | AF9: =IFERROR(INDEX('Detalle Costos'!$Y$5:$Y$158,MATCH(Resumen!AB9,'Detalle Costos'!$C$5:$C$158,0))*AH9,0) -> 437.14794 | AG9: =IFERROR(INDEX('Detalle Costos'!$AA$5:$AA$158,MATCH(Resumen!AB9,'Detalle Costos'!$C$5:$C$158,0))*AH9,0) -> 7483.3567 | AH9: =AJ9*G9+6518.87/248*G9 -> 45659.565 | AI9: 23.7 | AJ9: 1876.1961 | AK9: 44778.445 | AL9: =P9-AH9 -> 1540.4346 | AM9: =AL9/P9 -> 0.032636327 | AN9: =R9 -> 3003 | AO9: =118461.136538461/5988.21*G9+6*G9 -> 618.77748 | AP9: 0 | AQ9: =SUM(AN9:AP9) -> 3621.7775 | AR9: =50659/248*G9 -> 4902.4839 | AS9: =S9*0.03 -> 1325.91 | AT9: =AL9-AQ9-AR9+AS9 -> -5657.9167 | AU9: =AT9/P9 -> -0.11987112 | AV9: =131251/248*G9 -> 12701.71 | AW9: =AT9-AV9 -> -18359.626 | AX9: =AW9/P9 -> -0.38897514 | AY9: =123844.283333333/248*G9 -> 11984.931 | AZ9: =AT9+AY9 -> 6327.0139 | BA9: =AZ9/P9 -> 0.13404691 | BC9: =P9/$G9 -> 1966.6667 | BD9: =-AD9/$G9 -> -1153.881 | BE9: =-AE9/$G9 -> -418.57989 | BF9: =-AF9/$G9 -> -18.214497 | BG9: =-AG9/$G9 -> -311.80653 | BH9: =-AH9/$G9 -> -1902.4819 | BI9: =AL9/$G9 -> 64.184777 | BJ9: =-AN9/$G9 -> -125.125 | BK9: =-AP9/$G9 -> 0 | BL9: =-AQ9/$G9 -> -150.9074 | BM9: =-AR9/$G9 -> -204.27016 | BN9: =AS9/$G9 -> 55.24625 | BO9: =AT9/$G9 -> -235.74653 | BP9: =-AV9/$G9 -> -529.2379 | BQ9: =AW9/$G9 -> -764.98443 | BR9: =AY9/$G9 -> 499.37211 | BS9: =AZ9/$G9 -> 263.62558
B10: ENERO | C10: =B10 -> ENERO | D10: 140-2025 | E10: 347 | F10: 46038 | G10: 24 | H10: POTA FILETE CONGELADO | I10: Filete | J10: 2-4kg | K10: Japón | L10: Sendai | M10: TSUJINO | N10: Jose | O10: =P10/G10 -> 1983.3333 | P10: =48000*0+47600 -> 47600 | Q10: =S10/G10 -> 1845.7083 | R10: 3303 | S10: =P10-R10 -> 44297 | T10: 1 | U10: ECO SIROCCO 26003S | V10: LIMG00358300 | W10: ONE | X10: PAITA | Y10: Fresco | Z10: 10005721 | AA10: Compensación | AB10: =B10&Z10&AA10 -> ENERO10005721Compensación | AC10: =INDEX('Detalle Costos'!$L$5:$L$158,MATCH(Resumen!AB10,'Detalle Costos'!$C$5:$C$158,0))*1000+4623.769999996/248 -> 1878.6442 | AD10: =IFERROR(INDEX('Detalle Costos'!$X$5:$X$158,MATCH(Resumen!AB10,'Detalle Costos'!$C$5:$C$158,0))*AH10,0) -> 27693.143 | AE10: =IFERROR(INDEX('Detalle Costos'!$Z$5:$Z$158,MATCH(Resumen!AB10,'Detalle Costos'!$C$5:$C$158,0))*AH10,0) -> 10045.917 | AF10: =IFERROR(INDEX('Detalle Costos'!$Y$5:$Y$158,MATCH(Resumen!AB10,'Detalle Costos'!$C$5:$C$158,0))*AH10,0) -> 437.14794 | AG10: =IFERROR(INDEX('Detalle Costos'!$AA$5:$AA$158,MATCH(Resumen!AB10,'Detalle Costos'!$C$5:$C$158,0))*AH10,0) -> 7483.3567 | AH10: =AJ10*G10+6518.87/248*G10 -> 45659.565 | AI10: 23.7 | AJ10: 1876.1961 | AK10: 44778.445 | AL10: =P10-AH10 -> 1940.4346 | AM10: =AL10/P10 -> 0.040765434 | AN10: =R10 -> 3303 | AO10: =118461.136538461/5988.21*G10+6*G10 -> 618.77748 | AP10: 0 | AQ10: =SUM(AN10:AP10) -> 3921.7775 | AR10: =50659/248*G10 -> 4902.4839 | AS10: =S10*0.03 -> 1328.91 | AT10: =AL10-AQ10-AR10+AS10 -> -5554.9167 | AU10: =AT10/P10 -> -0.11669993 | AV10: =131251/248*G10 -> 12701.71 | AW10: =AT10-AV10 -> -18256.626 | AX10: =AW10/P10 -> -0.38354257 | AY10: =123844.283333333/248*G10 -> 11984.931 | AZ10: =AT10+AY10 -> 6430.0139 | BA10: =AZ10/P10 -> 0.13508433 | BC10: =P10/$G10 -> 1983.3333 | BD10: =-AD10/$G10 -> -1153.881 | BE10: =-AE10/$G10 -> -418.57989 | BF10: =-AF10/$G10 -> -18.214497 | BG10: =-AG10/$G10 -> -311.80653 | BH10: =-AH10/$G10 -> -1902.4819 | BI10: =AL10/$G10 -> 80.851443 | BJ10: =-AN10/$G10 -> -137.625 | BK10: =-AP10/$G10 -> 0 | BL10: =-AQ10/$G10 -> -163.4074 | BM10: =-AR10/$G10 -> -204.27016 | BN10: =AS10/$G10 -> 55.37125 | BO10: =AT10/$G10 -> -231.45486 | BP10: =-AV10/$G10 -> -529.2379 | BQ10: =AW10/$G10 -> -760.69277 | BR10: =AY10/$G10 -> 499.37211 | BS10: =AZ10/$G10 -> 267.91725
B11: ENERO | C11: =B11 -> ENERO | D11: 145-2025 | E11: 46020 | F11: 46041 | G11: 54 | H11: POTA REJOS CONGELADOS | I11: Rejos | J11: 500-1 / 1-2 | K11: España | L11: Vigo | M11: GLOBAL OCEAN | N11: Jorge | O11: 2600 | P11: 140400 | Q11: 2430.963 | R11: 9128 | S11: =P11-R11 -> 131272 | T11: 2 | U11: IZMIT EXPRESS 604N | V11: 28952064 | W11: HAPAG | X11: PAITA | Y11: Fresco | Z11: 10007162 | AA11: Compensación | AB11: =B11&Z11&AA11 -> ENERO10007162Compensación | AC11: =INDEX('Detalle Costos'!$L$5:$L$158,MATCH(Resumen!AB11,'Detalle Costos'!$C$5:$C$158,0))*1000+4623.769999996/248 -> 1808.6442 | AD11: =IFERROR(INDEX('Detalle Costos'!$X$5:$X$158,MATCH(Resumen!AB11,'Detalle Costos'!$C$5:$C$158,0))*AH11,0) -> 63650.331 | AE11: =IFERROR(INDEX('Detalle Costos'!$Z$5:$Z$158,MATCH(Resumen!AB11,'Detalle Costos'!$C$5:$C$158,0))*AH11,0) -> 16793.521 | AF11: =IFERROR(INDEX('Detalle Costos'!$Y$5:$Y$158,MATCH(Resumen!AB11,'Detalle Costos'!$C$5:$C$158,0))*AH11,0) -> 855.69263 | AG11: =IFERROR(INDEX('Detalle Costos'!$AA$5:$AA$158,MATCH(Resumen!AB11,'Detalle Costos'!$C$5:$C$158,0))*AH11,0) -> 16689.768 | AH11: =AJ11*G11+6518.87/248*G11 -> 97989.312 | AI11: 54 | AJ11: 1788.3311 | AK11: 99505.64 | AL11: =P11-AH11 -> 42410.688 | AM11: =AL11/P11 -> 0.30207043 | AN11: =R11 -> 9128 | AO11: =118461.136538461/5988.21*G11+6*G11 -> 1392.2493 | AP11: 0 | AQ11: =SUM(AN11:AP11) -> 10520.249 | AR11: =50659/248*G11 -> 11030.589 | AS11: =S11*0.03 -> 3938.16 | AT11: =AL11-AQ11-AR11+AS11 -> 24798.01 | AU11: =AT11/P11 -> 0.176624 | AV11: =131251/248*G11 -> 28578.847 | AW11: =AT11-AV11 -> -3780.837 | AX11: =AW11/P11 -> -0.026929038 | AY11: =123844.283333333/248*G11 -> 26966.094 | AZ11: =AT11+AY11 -> 51764.104 | BA11: =AZ11/P11 -> 0.3686902 | BC11: =P11/$G11 -> 2600 | BD11: =-AD11/$G11 -> -1178.7098 | BE11: =-AE11/$G11 -> -310.99112 | BF11: =-AF11/$G11 -> -15.84616 | BG11: =-AG11/$G11 -> -309.06977 | BH11: =-AH11/$G11 -> -1814.6169 | BI11: =AL11/$G11 -> 785.38311 | BJ11: =-AN11/$G11 -> -169.03704 | BK11: =-AP11/$G11 -> 0 | BL11: =-AQ11/$G11 -> -194.81943 | BM11: =-AR11/$G11 -> -204.27016 | BN11: =AS11/$G11 -> 72.928889 | BO11: =AT11/$G11 -> 459.2224 | BP11: =-AV11/$G11 -> -529.2379 | BQ11: =AW11/$G11 -> -70.0155 | BR11: =AY11/$G11 -> 499.37211 | BS11: =AZ11/$G11 -> 958.59451
B12: FEBRERO | C12: =B12 -> FEBRERO | D12: 146-2026 | E12: 46027 | F12: 46059 | G12: 10 | H12: POTA CONOS | I12: Conos | J12: 10 cm - up | K12: Tailandia | L12: Lat Krabang | M12: TSUJINO | N12: Jose | O12: 2100 | P12: 21000 | Q12: 2100 | R12: =3500/24*G12 -> 1458.3333 | S12: =P12-R12 -> 19541.667 | T12: 1 | U12: ECO MARIN 26006S | V12: 6444023300 | W12: COSCO | X12: PAITA | Y12: Subproducto | Z12: 10007969 | AA12: Compensación | AB12: =B12&Z12&AA12 -> FEBRERO10007969Compensación | AC12: =INDEX('Detalle Costos'!$L$5:$L$158,MATCH(Resumen!AB12,'Detalle Costos'!$C$5:$C$158,0))*1000*0+AJ12+229398.68/1634.3 -> 1345.444 | AD12: =IFERROR(INDEX('Detalle Costos'!$X$5:$X$158,MATCH(Resumen!AB12,'Detalle Costos'!$C$5:$C$158,0))*AH12,0) -> 10882.579 | AE12: =IFERROR(INDEX('Detalle Costos'!$Z$5:$Z$158,MATCH(Resumen!AB12,'Detalle Costos'!$C$5:$C$158,0))*AH12,0) -> 2048.545 | AF12: =IFERROR(INDEX('Detalle Costos'!$Y$5:$Y$158,MATCH(Resumen!AB12,'Detalle Costos'!$C$5:$C$158,0))*AH12,0) -> 160.64285 | AG12: =IFERROR(INDEX('Detalle Costos'!$AA$5:$AA$158,MATCH(Resumen!AB12,'Detalle Costos'!$C$5:$C$158,0))*AH12,0) -> 362.67255 | AH12: =AC12*G12 -> 13454.44 | AI12: =+G12 -> 10 | AJ12: 1205.0789 | AK12: =+AJ12*AI12 -> 12050.789 | AL12: =P12-AH12 -> 7545.5601 | AM12: =AL12/P12 -> 0.35931239 | AN12: =R12 -> 1458.3333 | AO12: =118461.136538461/5988.21*G12 -> 197.82395 | AP12: =-10174.6784147361/1634*G12 -> -62.268534 | AQ12: =SUM(AN12:AP12) -> 1593.8888 | AR12: =56604/1634.3*G12 -> 346.35012 | AS12: =S12*0.03 -> 586.25 | AT12: =AL12-AQ12-AR12+AS12 -> 6191.5713 | AU12: =AT12/P12 -> 0.29483673 | AV12: =148498/1634.3*G12 -> 908.63367 | AW12: =AT12-AV12 -> 5282.9376 | AX12: =AW12/P12 -> 0.25156846 | AY12: =123844.283333333/1634.3*G12 -> 757.78182 | AZ12: =AT12+AY12 -> 6949.3531 | BA12: =AZ12/P12 -> 0.33092158 | BC12: =P12/$G12 -> 2100 | BD12: =-AD12/$G12 -> -1088.2579 | BE12: =-AE12/$G12 -> -204.8545 | BF12: =-AF12/$G12 -> -16.064285 | BG12: =-AG12/$G12 -> -36.267255 | BH12: =-AH12/$G12 -> -1345.444 | BI12: =AL12/$G12 -> 754.55601 | BJ12: =-AN12/$G12 -> -145.83333 | BK12: =-AP12/$G12 -> 6.2268534 | BL12: =-AQ12/$G12 -> -159.38888 | BM12: =-AR12/$G12 -> -34.635012 | BN12: =AS12/$G12 -> 58.625 | BO12: =AT12/$G12 -> 619.15713 | BP12: =-AV12/$G12 -> -90.863367 | BQ12: =AW12/$G12 -> 528.29376 | BR12: =AY12/$G12 -> 75.778182 | BS12: =AZ12/$G12 -> 694.93531
B13: FEBRERO | C13: =B13 -> FEBRERO | D13: 146-2026 | E13: 46027 | F13: 46059 | G13: 14 | H13: POTA NUCAS | I13: Nucas | J13: 500-up | K13: Tailandia | L13: Lat Krabang | M13: TSUJINO | N13: Jose | O13: 1700 | P13: =23800-344 -> 23456 | Q13: 1700 | R13: =3500/24*G13 -> 2041.6667 | S13: =P13-R13 -> 21414.333 | T13: 0 | Y13: Fresco | Z13: 10005779 | AA13: Compensación | AB13: =B13&Z13&AA13 -> FEBRERO10005779Compensación | AC13: =INDEX('Detalle Costos'!$L$5:$L$158,MATCH(Resumen!AB13,'Detalle Costos'!$C$5:$C$158,0))*1000*0+AJ13+229398.68/1634.3 -> 1887.9651 | AD13: =IFERROR(INDEX('Detalle Costos'!$X$5:$X$158,MATCH(Resumen!AB13,'Detalle Costos'!$C$5:$C$158,0))*AH13,0) -> 16088.613 | AE13: =IFERROR(INDEX('Detalle Costos'!$Z$5:$Z$158,MATCH(Resumen!AB13,'Detalle Costos'!$C$5:$C$158,0))*AH13,0) -> 5819.4874 | AF13: =IFERROR(INDEX('Detalle Costos'!$Y$5:$Y$158,MATCH(Resumen!AB13,'Detalle Costos'!$C$5:$C$158,0))*AH13,0) -> 192.80525 | AG13: =IFERROR(INDEX('Detalle Costos'!$AA$5:$AA$158,MATCH(Resumen!AB13,'Detalle Costos'!$C$5:$C$158,0))*AH13,0) -> 4330.6058 | AH13: =AC13*G13 -> 26431.511 | AI13: 14.849 | AJ13: 1747.6 | AK13: =AJ13*AI13 -> 25950.112 | AL13: =P13-AH13 -> -2975.5114 | AM13: =AL13/P13 -> -0.12685502 | AN13: =R13 -> 2041.6667 | AO13: =118461.136538461/5988.21*G13 -> 276.95353 | AP13: =-10174.6784147361/1634*G13 -> -87.175947 | AQ13: =SUM(AN13:AP13) -> 2231.4443 | AR13: =56604/1634.3*G13 -> 484.89017 | AS13: =S13*0.03 -> 642.43 | AT13: =AL13-AQ13-AR13+AS13 -> -5049.4158 | AU13: =AT13/P13 -> -0.21527182 | AV13: =148498/1634.3*G13 -> 1272.0871 | AW13: =AT13-AV13 -> -6321.5029 | AX13: =AW13/P13 -> -0.26950473 | AY13: =123844.283333333/1634.3*G13 -> 1060.8946 | AZ13: =AT13+AY13 -> -3988.5212 | BA13: =AZ13/P13 -> -0.17004269 | BC13: =P13/$G13 -> 1675.4286 | BD13: =-AD13/$G13 -> -1149.1866 | BE13: =-AE13/$G13 -> -415.67767 | BF13: =-AF13/$G13 -> -13.771803 | BG13: =-AG13/$G13 -> -309.32898 | BH13: =-AH13/$G13 -> -1887.9651 | BI13: =AL13/$G13 -> -212.53653 | BJ13: =-AN13/$G13 -> -145.83333 | BK13: =-AP13/$G13 -> 6.2268534 | BL13: =-AQ13/$G13 -> -159.38888 | BM13: =-AR13/$G13 -> -34.635012 | BN13: =AS13/$G13 -> 45.887857 | BO13: =AT13/$G13 -> -360.67256 | BP13: =-AV13/$G13 -> -90.863367 | BQ13: =AW13/$G13 -> -451.53592 | BR13: =AY13/$G13 -> 75.778182 | BS13: =AZ13/$G13 -> -284.89437
B14: ENERO | C14: =B14 -> ENERO | D14: 147-2026 | E14: 46032 | F14: 46050 | G14: 72 | H14: POTA ALAS CONGELADAS | I14: Alas | J14: 1 - 2 KGS. | K14: Tailandia | L14: Bangkok | M14: TSUJINO | N14: Jose | O14: =P14/G14 -> 1887.7083 | P14: =140400*0+135915 -> 135915 | Q14: =S14/G14 -> 1754.25 | R14: 9609 | S14: =P14-R14 -> 126306 | T14: 3 | U14: ECO MARIN 26004N | V14: LIMG01524600 | W14: ONE | X14: PAITA | Y14: Fresco | Z14: 10006720 | AA14: Compensación | AB14: =B14&Z14&AA14 -> ENERO10006720Compensación | AC14: =INDEX('Detalle Costos'!$L$5:$L$158,MATCH(Resumen!AB14,'Detalle Costos'!$C$5:$C$158,0))*1000+4623.769999996/248 -> 1738.6442 | AD14: =IFERROR(INDEX('Detalle Costos'!$X$5:$X$158,MATCH(Resumen!AB14,'Detalle Costos'!$C$5:$C$158,0))*AH14,0) -> 82959.134 | AE14: =IFERROR(INDEX('Detalle Costos'!$Z$5:$Z$158,MATCH(Resumen!AB14,'Detalle Costos'!$C$5:$C$158,0))*AH14,0) -> 19195.713 | AF14: =IFERROR(INDEX('Detalle Costos'!$Y$5:$Y$158,MATCH(Resumen!AB14,'Detalle Costos'!$C$5:$C$158,0))*AH14,0) -> 1203.1653 | AG14: =IFERROR(INDEX('Detalle Costos'!$AA$5:$AA$158,MATCH(Resumen!AB14,'Detalle Costos'!$C$5:$C$158,0))*AH14,0) -> 22291.587 | AH14: =AJ14*G14+6518.87/248*G14 -> 125649.6 | AI14: 69.7 | AJ14: 1718.8476 | AK14: 120156.94 | AL14: =P14-AH14 -> 10265.4 | AM14: =AL14/P14 -> 0.075528091 | AN14: =R14 -> 9609 | AO14: =118461.136538461/5988.21*G14+6*G14 -> 1856.3325 | AP14: 0 | AQ14: =SUM(AN14:AP14) -> 11465.332 | AR14: =50659/248*G14 -> 14707.452 | AS14: =S14*0.03 -> 3789.18 | AT14: =AL14-AQ14-AR14+AS14 -> -12118.204 | AU14: =AT14/P14 -> -0.089160163 | AV14: =131251/248*G14 -> 38105.129 | AW14: =AT14-AV14 -> -50223.333 | AX14: =AW14/P14 -> -0.36952016 | AY14: =123844.283333333/248*G14 -> 35954.792 | AZ14: =AT14+AY14 -> 23836.588 | BA14: =AZ14/P14 -> 0.17537864 | BC14: =P14/$G14 -> 1887.7083 | BD14: =-AD14/$G14 -> -1152.2102 | BE14: =-AE14/$G14 -> -266.60713 | BF14: =-AF14/$G14 -> -16.710629 | BG14: =-AG14/$G14 -> -309.60537 | BH14: =-AH14/$G14 -> -1745.1333 | BI14: =AL14/$G14 -> 142.57501 | BJ14: =-AN14/$G14 -> -133.45833 | BK14: =-AP14/$G14 -> 0 | BL14: =-AQ14/$G14 -> -159.24073 | BM14: =-AR14/$G14 -> -204.27016 | BN14: =AS14/$G14 -> 52.6275 | BO14: =AT14/$G14 -> -168.30838 | BP14: =-AV14/$G14 -> -529.2379 | BQ14: =AW14/$G14 -> -697.54629 | BR14: =AY14/$G14 -> 499.37211 | BS14: =AZ14/$G14 -> 331.06373
B15: ENERO | C15: =B15 -> ENERO | E15: 46053 | F15: 46053 | G15: 0 | H15: RESIDUOS DE POTA | I15: Residuos | J15: Residuos | K15: Residuos | L15: Residuos | M15: PROVEEDORA DE PRODUCTOS MARINOS | O15: 0 | P15: 24314.28 | Q15: 0 | R15: 0 | S15: =P15-R15 -> 24314.28 | Y15: Residuo | AC15: 0 | AD15: =IFERROR(INDEX('Detalle Costos'!$X$5:$X$158,MATCH(Resumen!AB15,'Detalle Costos'!$C$5:$C$158,0))*AH15,0) -> 0 | AE15: =IFERROR(INDEX('Detalle Costos'!$Z$5:$Z$158,MATCH(Resumen!AB15,'Detalle Costos'!$C$5:$C$158,0))*AH15,0) -> 0 | AF15: =IFERROR(INDEX('Detalle Costos'!$Y$5:$Y$158,MATCH(Resumen!AB15,'Detalle Costos'!$C$5:$C$158,0))*AH15,0) -> 0 | AG15: =IFERROR(INDEX('Detalle Costos'!$AA$5:$AA$158,MATCH(Resumen!AB15,'Detalle Costos'!$C$5:$C$158,0))*AH15,0) -> 0 | AH15: =AJ15*G15 -> 0 | AL15: =P15-AH15 -> 24314.28 | AM15: =AL15/P15 -> 1 | AN15: =R15 -> 0 | AO15: =118461.136538461/5988.21*G15 -> 0 | AP15: 0 | AQ15: =SUM(AN15:AP15) -> 0 | AR15: =50659/248*G15 -> 0 | AS15: 0 | AT15: =AL15-AQ15-AR15+AS15 -> 24314.28 | AU15: =AT15/P15 -> 1 | AV15: =131251/248*G15 -> 0 | AW15: =AT15-AV15 -> 24314.28 | AX15: =AW15/P15 -> 1 | AY15: =123844.283333333/248*G15 -> 0 | AZ15: =AT15+AY15 -> 24314.28 | BA15: =AZ15/P15 -> 1 | BC15: =P15/$G15 -> #DIV/0! | BD15: =-AD15/$G15 -> #DIV/0! | BE15: =-AE15/$G15 -> #DIV/0! | BF15: =-AF15/$G15 -> #DIV/0! | BG15: =-AG15/$G15 -> #DIV/0! | BH15: =-AH15/$G15 -> #DIV/0! | BI15: =AL15/$G15 -> #DIV/0! | BJ15: =-AN15/$G15 -> #DIV/0! | BK15: =-AP15/$G15 -> #DIV/0! | BL15: =-AQ15/$G15 -> #DIV/0! | BM15: =-AR15/$G15 -> #DIV/0! | BN15: =AS15/$G15 -> #DIV/0! | BO15: =AT15/$G15 -> #DIV/0! | BP15: =-AV15/$G15 -> #DIV/0! | BQ15: =AW15/$G15 -> #DIV/0! | BR15: =AY15/$G15 -> #DIV/0! | BS15: =AZ15/$G15 -> #DIV/0!
B16: FEBRERO | C16: =B16 -> FEBRERO | D16: 148-2026 | E16: 15 | F16: 46055 | G16: 135 | H16: POTA FILETE CONGELADO | I16: Filete | J16: 2-4 (B) | K16: España | L16: Vigo | M16: FOOD & BEVERAGES TRADERS | N16: Jorge | O16: 1650 | P16: 222750 | Q16: 1480.963 | R16: 22820 | S16: =P16-R16 -> 199930 | T16: 5 | U16: ODYSSEUS 606N | V16: 59582082 | W16: HAPAG | X16: PAITA | Y16: Fresco | Z16: 10005721 | AA16: Compensación | AB16: =B16&Z16&AA16 -> FEBRERO10005721Compensación | AC16: =INDEX('Detalle Costos'!$L$5:$L$158,MATCH(Resumen!AB16,'Detalle Costos'!$C$5:$C$158,0))*1000*0+AJ16+229398.68/1634.3 -> 1812.5717 | AD16: =IFERROR(INDEX('Detalle Costos'!$X$5:$X$158,MATCH(Resumen!AB16,'Detalle Costos'!$C$5:$C$158,0))*AH16,0) -> 148491.05 | AE16: =IFERROR(INDEX('Detalle Costos'!$Z$5:$Z$158,MATCH(Resumen!AB16,'Detalle Costos'!$C$5:$C$158,0))*AH16,0) -> 49055.886 | AF16: =IFERROR(INDEX('Detalle Costos'!$Y$5:$Y$158,MATCH(Resumen!AB16,'Detalle Costos'!$C$5:$C$158,0))*AH16,0) -> 2609.6487 | AG16: =IFERROR(INDEX('Detalle Costos'!$AA$5:$AA$158,MATCH(Resumen!AB16,'Detalle Costos'!$C$5:$C$158,0))*AH16,0) -> 44540.593 | AH16: =AC16*G16 -> 244697.18 | AI16: =+G16 -> 135 | AJ16: 1672.2066 | AK16: 251295.39 | AL16: =P16-AH16 -> -21947.176 | AM16: =AL16/P16 -> -0.098528286 | AN16: =R16 -> 22820 | AO16: =118461.136538461/5988.21*G16 -> 2670.6233 | AP16: =-10174.6784147361/1634*G16 -> -840.62521 | AQ16: =SUM(AN16:AP16) -> 24649.998 | AR16: =56604/1634.3*G16 -> 4675.7266 | AS16: =S16*0.03 -> 5997.9 | AT16: =AL16-AQ16-AR16+AS16 -> -45275 | AU16: =AT16/P16 -> -0.20325477 | AV16: =148498/1634.3*G16 -> 12266.554 | AW16: =AT16-AV16 -> -57541.555 | AX16: =AW16/P16 -> -0.25832348 | AY16: =123844.283333333/1634.3*G16 -> 10230.055 | AZ16: =AT16+AY16 -> -35044.946 | BA16: =AZ16/P16 -> -0.1573286 | BC16: =P16/$G16 -> 1650 | BD16: =-AD16/$G16 -> -1099.9337 | BE16: =-AE16/$G16 -> -363.37693 | BF16: =-AF16/$G16 -> -19.330731 | BG16: =-AG16/$G16 -> -329.93032 | BH16: =-AH16/$G16 -> -1812.5717 | BI16: =AL16/$G16 -> -162.57167 | BJ16: =-AN16/$G16 -> -169.03704 | BK16: =-AP16/$G16 -> 6.2268534 | BL16: =-AQ16/$G16 -> -182.59258 | BM16: =-AR16/$G16 -> -34.635012 | BN16: =AS16/$G16 -> 44.428889 | BO16: =AT16/$G16 -> -335.37037 | BP16: =-AV16/$G16 -> -90.863367 | BQ16: =AW16/$G16 -> -426.23374 | BR16: =AY16/$G16 -> 75.778182 | BS16: =AZ16/$G16 -> -259.59219
B17: FEBRERO | C17: =B17 -> FEBRERO | D17: 149-2026 | E17: 16 | F17: 46055 | G17: 27 | H17: POTA REPRODUCTORES | I17: Rejos | K17: España | L17: Vigo | M17: GLOBAL OCEAN | N17: Jorge | O17: =P17/G17 -> 2873.5185 | P17: =79650*0+77585 -> 77585 | Q17: =S17/G17 -> 2711.8889 | R17: 4364 | S17: =P17-R17 -> 73221 | T17: 1 | Y17: Fresco | Z17: 10007567 | AA17: Entradas | AB17: =B17&Z17&AA17 -> FEBRERO10007567Entradas | AC17: =INDEX('Detalle Costos'!$L$5:$L$158,MATCH(Resumen!AB17,'Detalle Costos'!$C$5:$C$158,0))*1000*0+AJ17+229398.68/1634.3 -> 1792.6009 | AD17: =IFERROR(INDEX('Detalle Costos'!$X$5:$X$158,MATCH(Resumen!AB17,'Detalle Costos'!$C$5:$C$158,0))*AH17,0) -> 29878.161 | AE17: =IFERROR(INDEX('Detalle Costos'!$Z$5:$Z$158,MATCH(Resumen!AB17,'Detalle Costos'!$C$5:$C$158,0))*AH17,0) -> 8560.8114 | AF17: =IFERROR(INDEX('Detalle Costos'!$Y$5:$Y$158,MATCH(Resumen!AB17,'Detalle Costos'!$C$5:$C$158,0))*AH17,0) -> 543.18307 | AG17: =IFERROR(INDEX('Detalle Costos'!$AA$5:$AA$158,MATCH(Resumen!AB17,'Detalle Costos'!$C$5:$C$158,0))*AH17,0) -> 9418.0679 | AH17: =AC17*G17 -> 48400.224 | AI17: 26.302 | AJ17: 1652.2358 | AK17: 48129 | AL17: =P17-AH17 -> 29184.776 | AM17: =AL17/P17 -> 0.37616519 | AN17: =R17 -> 4364 | AO17: =118461.136538461/5988.21*G17 -> 534.12467 | AP17: =-10174.6784147361/1634*G17 -> -168.12504 | AQ17: =SUM(AN17:AP17) -> 4729.9996 | AR17: =56604/1634.3*G17 -> 935.14532 | AS17: =S17*0.03 -> 2196.63 | AT17: =AL17-AQ17-AR17+AS17 -> 25716.261 | AU17: =AT17/P17 -> 0.33145919 | AV17: =148498/1634.3*G17 -> 2453.3109 | AW17: =AT17-AV17 -> 23262.951 | AX17: =AW17/P17 -> 0.29983825 | AY17: =123844.283333333/1634.3*G17 -> 2046.0109 | AZ17: =AT17+AY17 -> 27762.272 | BA17: =AZ17/P17 -> 0.35783041 | BC17: =P17/$G17 -> 2873.5185 | BD17: =-AD17/$G17 -> -1106.5986 | BE17: =-AE17/$G17 -> -317.06709 | BF17: =-AF17/$G17 -> -20.117891 | BG17: =-AG17/$G17 -> -348.81733 | BH17: =-AH17/$G17 -> -1792.6009 | BI17: =AL17/$G17 -> 1080.9176 | BJ17: =-AN17/$G17 -> -161.62963 | BK17: =-AP17/$G17 -> 6.2268534 | BL17: =-AQ17/$G17 -> -175.18517 | BM17: =-AR17/$G17 -> -34.635012 | BN17: =AS17/$G17 -> 81.356667 | BO17: =AT17/$G17 -> 952.45413 | BP17: =-AV17/$G17 -> -90.863367 | BQ17: =AW17/$G17 -> 861.59076 | BR17: =AY17/$G17 -> 75.778182 | BS17: =AZ17/$G17 -> 1028.2323
