Workbook

Sheet TD
H1: 64340.28
A2: ANÁLISIS DE RENTABILIDAD
A4: EEFF PERU FROST (USD)
B5: Etiquetas de columna | H5: ANÁLISIS UNITARIO | O5: ANÁLISIS VÉRTICAL
A6: Valores | B6: ENERO | C6: FEBRERO | D6: MARZO | E6: Total general | H6: NOMBRE | I6: ENERO | J6: FEBRERO | K6: MARZO | L6: TOTAL | O6: NOMBRE | P6: ENERO | Q6: FEBRERO | R6: MARZO | S6: TOTAL
A7: Suma de Cantidad | B7: 248 | C7: 1634.3 | D7: 1995.8 | E7: 3878.1
A8: Suma de VALOR CFR | B8: 564615.28 | C8: 2769824.5 | D8: 3909830 | E8: 7244269.8 | H8: Suma de VALOR CFR | I8: =B8/B$7 -> 2276.6745 | J8: =C8/C$7 -> 1694.8079 | K8: =D8/D$7 -> 1959.029 | L8: =E8/E$7 -> 1867.9946 | O8: Suma de VALOR CFR | P8: =B8/B$8 -> 1 | Q8: =C8/C$8 -> 1 | R8: =D8/D$8 -> 1 | S8: =E8/E$8 -> 1
A9: Suma de COSTO VENTAS | B9: 442635.6 | C9: 2804315 | D9: 3522312 | E9: 6769262.6 | H9: Suma de COSTO VENTAS | I9: =B9/B$7 -> 1784.821 | J9: =C9/C$7 -> 1715.912 | K9: =D9/D$7 -> 1764.8622 | L9: =E9/E$7 -> 1745.5101 | O9: Suma de COSTO VENTAS | P9: =B9/B$8 -> 0.78395965 | Q9: =C9/C$8 -> 1.0124522 | R9: =D9/D$8 -> 0.90088623 | S9: =E9/E$8 -> 0.93442995
A10: Suma de UTILIDAD BRUTA | B10: 121979.68 | C10: -34490.515 | D10: 387518 | E10: 475007.16 | H10: Suma de UTILIDAD BRUTA | I10: =B10/B$7 -> 491.85355 | J10: =C10/C$7 -> -21.104152 | K10: =D10/D$7 -> 194.16675 | L10: =E10/E$7 -> 122.48451 | O10: Suma de UTILIDAD BRUTA | P10: =B10/B$8 -> 0.21604035 | Q10: =C10/C$8 -> -0.012452239 | R10: =D10/D$8 -> 0.099113772 | S10: =E10/E$8 -> 0.065570055
A11: Suma de GASTO VENTAS | B11: 50584.692 | C11: 300510.54 | D11: 363885.06 | E11: 714980.29 | H11: Suma de GASTO VENTAS | I11: =B11/B$7 -> 203.97053 | J11: =C11/C$7 -> 183.87722 | K11: =D11/D$7 -> 182.32541 | L11: =E11/E$7 -> 184.36355 | O11: Suma de GASTO VENTAS | P11: =B11/B$8 -> 0.089591433 | Q11: =C11/C$8 -> 0.10849443 | R11: =D11/D$8 -> 0.093069279 | S11: =E11/E$8 -> 0.098695978
A12: Suma de GASTO ADM | B12: 60070 | C12: 65590 | D12: 70585.576 | E12: 196245.58 | H12: Suma de GASTO ADM | I12: =B12/B$7 -> 242.21774 | J12: =C12/C$7 -> 40.13339 | K12: =D12/D$7 -> 35.367059 | L12: =E12/E$7 -> 50.603537 | O12: Suma de GASTO ADM | P12: =B12/B$8 -> 0.10639103 | Q12: =C12/C$8 -> 0.023680201 | R12: =D12/D$8 -> 0.018053362 | S12: =E12/E$8 -> 0.027089766
A13: Suma de DRAWBACK | B13: 15120.72 | C13: 75707.235 | D13: 109832.62 | E13: 200660.57 | H13: Suma de DRAWBACK | I13: =B13/B$7 -> 60.970645 | J13: =C13/C$7 -> 46.323952 | K13: =D13/D$7 -> 55.031876 | L13: =E13/E$7 -> 51.74198 | O13: Suma de DRAWBACK | P13: =B13/B$8 -> 0.026780572 | Q13: =C13/C$8 -> 0.027332864 | R13: =D13/D$8 -> 0.028091405 | S13: =E13/E$8 -> 0.027699213
A14: Suma de UTILIDAD OPERATIVA | B14: 26445.708 | C14: -324883.82 | D14: 62879.984 | E14: -235558.13 | H14: Suma de UTILIDAD OPERATIVA | I14: =B14/B$7 -> 106.63592 | J14: =C14/C$7 -> -198.79081 | K14: =D14/D$7 -> 31.506155 | L14: =E14/E$7 -> -60.740602 | O14: Suma de UTILIDAD OPERATIVA | P14: =B14/B$8 -> 0.046838456 | Q14: =C14/C$8 -> -0.11729401 | R14: =D14/D$8 -> 0.016082537 | S14: =E14/E$8 -> -0.032516476
A15: Suma de GASTO FINANCIERO | B15: 131251 | C15: 148498 | D15: 105578.68 | E15: 385327.68 | H15: Suma de GASTO FINANCIERO | I15: =B15/B$7 -> 529.2379 | J15: =C15/C$7 -> 90.863367 | K15: =D15/D$7 -> 52.90043 | L15: =E15/E$7 -> 99.359913 | O15: Suma de GASTO FINANCIERO | P15: =B15/B$8 -> 0.23246094 | Q15: =C15/C$8 -> 0.053612783 | R15: =D15/D$8 -> 0.027003394 | S15: =E15/E$8 -> 0.053190686
A16: Suma de UTILIDAD NETA | B16: -104805.29 | C16: -473381.82 | D16: -42698.695 | E16: -620885.81 | H16: Suma de UTILIDAD NETA | I16: =B16/B$7 -> -422.60199 | J16: =C16/C$7 -> -289.65418 | K16: =D16/D$7 -> -21.394276 | L16: =E16/E$7 -> -160.10051 | O16: Suma de UTILIDAD NETA | P16: =B16/B$8 -> -0.18562249 | Q16: =C16/C$8 -> -0.17090679 | R16: =D16/D$8 -> -0.010920857 | S16: =E16/E$8 -> -0.085707162
A17: Suma de DEPRECIACIÓN | B17: 123530 | C17: 124152.39 | D17: 123360.73 | E17: 371043.12 | H17: Suma de DEPRECIACIÓN | I17: =B17/B$7 -> 498.10484 | J17: =C17/C$7 -> 75.96671 | K17: =D17/D$7 -> 61.810166 | L17: =E17/E$7 -> 95.676523 | O17: Suma de DEPRECIACIÓN | P17: =B17/B$8 -> 0.21878614 | Q17: =C17/C$8 -> 0.044823199 | R17: =D17/D$8 -> 0.031551431 | S17: =E17/E$8 -> 0.051218844
A18: Suma de EBITDA | B18: 149975.71 | C18: -200731.43 | D18: 186240.71 | E18: 135485 | H18: Suma de EBITDA | I18: =B18/B$7 -> 604.74076 | J18: =C18/C$7 -> -122.8241 | K18: =D18/D$7 -> 93.316321 | L18: =E18/E$7 -> 34.935921 | O18: Suma de EBITDA | P18: =B18/B$8 -> 0.2656246 | Q18: =C18/C$8 -> -0.07247081 | R18: =D18/D$8 -> 0.047633967 | S18: =E18/E$8 -> 0.018702368
A24: ANÁLISIS POR PRODUCTO
A26: RANKING DE VENTAS (USD) | H26: UTILIDAD NETA (USD) | O26: EBITDA (USD)
A27: Suma de VALOR CFR | B27: Etiquetas de columna | H27: Suma de UTILIDAD NETA | I27: Etiquetas de columna | O27: Suma de EBITDA | P27: Etiquetas de columna
A28: Etiquetas de fila | B28: ENERO | C28: FEBRERO | D28: MARZO | E28: Total general | F28: % | H28: Etiquetas de fila | I28: ENERO | J28: FEBRERO | K28: MARZO | L28: Total general | M28: MG | O28: Etiquetas de fila | P28: ENERO | Q28: FEBRERO | R28: MARZO | S28: Total general | T28: MG
A29: POTA REJOS CONGELADOS | B29: 149248 | C29: 532695 | D29: 795200 | E29: 1477143 | F29: =E29/$E$40 -> 0.20390502 | H29: POTA REJOS CONGELADOS | I29: -8043.0503 | J29: 114631.26 | K29: 147844.77 | L29: 254432.98 | M29: =L29/E29 -> 0.17224668 | O29: POTA REJOS CONGELADOS | P29: 51501.735 | Q29: 149500.02 | R29: 185813.97 | S29: 386815.73 | T29: =S29/E29 -> 0.26186749
A30: POTA ALAS CONGELADAS | B30: 135915 | C30: 710550 | D30: 772480 | E30: 1618945 | F30: =E30/$E$40 -> 0.22347939 | H30: POTA ALAS CONGELADAS | I30: -53443.473 | J30: -161122.81 | K30: -117583.75 | L30: -332150.03 | M30: =L30/E30 -> -0.20516449 | O30: POTA ALAS CONGELADAS | P30: 20525.205 | Q30: -84494.955 | R30: -62201.474 | S30: -126171.22 | T30: =S30/E30 -> -0.077934225
A31: POTA FILETE CONGELADO | B31: 94800 | C31: 1147500 | D31: 432150 | E31: 1674450 | F31: =E31/$E$40 -> 0.23114131 | H31: POTA FILETE CONGELADO | I31: -37930.282 | J31: -503763.5 | K31: -145916.47 | L31: -687610.25 | M31: =L31/E31 -> -0.41064842 | O31: POTA FILETE CONGELADO | P31: 11382.17 | Q31: -368626.2 | R31: -112306.27 | S31: -469550.3 | T31: =S31/E31 -> -0.28042061
A32: POTA FILETE PRECOCIDO | C32: 91800 | D32: 1004400 | E32: 1096200 | F32: =E32/$E$40 -> 0.1513196 | H32: POTA FILETE PRECOCIDO | J32: 29374.465 | K32: 267757.03 | L32: 297131.49 | M32: =L32/E32 -> 0.27105591 | O32: POTA FILETE PRECOCIDO | Q32: 33879.042 | R32: 304923.26 | S32: 338802.3 | T32: =S32/E32 -> 0.30906979
A33: POTA NUCAS | B33: 35874 | C33: 23456 | D33: 470900 | E33: 530230 | F33: =E33/$E$40 -> 0.073193022 | H33: POTA NUCAS | I33: -21331.27 | J33: -6620.887 | K33: -339879.92 | L33: -367832.08 | M33: =L33/E33 -> -0.69372174 | O33: POTA NUCAS | P33: -743.32143 | Q33: -4290.9886 | R33: -295716.34 | S33: -300750.65 | T33: =S33/E33 -> -0.56720791
A34: POTA ALAS COCIDAS | D34: 180900 | E34: 180900 | F34: =E34/$E$40 -> 0.024971461 | H34: POTA ALAS COCIDAS | K34: 74731.171 | L34: 74731.171 | M34: =L34/E34 -> 0.41310763 | O34: POTA ALAS COCIDAS | R34: 80925.543 | S34: 80925.543 | T34: =S34/E34 -> 0.4473496
A35: POTA REPRODUCTORES | B35: 74064 | C35: 77585 | D35: 139200 | E35: 290849 | F35: =E35/$E$40 -> 0.040148836 | H35: POTA REPRODUCTORES | I35: 2375.0532 | J35: 20917.792 | K35: 40825.448 | L35: 64118.293 | M35: =L35/E35 -> 0.22045217 | O35: POTA REPRODUCTORES | P35: 29085.965 | Q35: 25422.368 | R35: 46675.688 | S35: 101184.02 | T35: =S35/E35 -> 0.34789193
A36: POTA CONOS | B36: 50400 | C36: 69000 | D36: 76800 | E36: 196200 | F36: =E36/$E$40 -> 0.027083475 | H36: POTA CONOS | I36: -10746.551 | J36: 12040.06 | K36: -1900.0703 | L36: -606.56114 | M36: =L36/E36 -> -0.0030915451 | O36: POTA CONOS | P36: 13909.675 | Q36: 17708.341 | R36: 3606.0384 | S36: 35224.054 | T36: =S36/E36 -> 0.17953137
A37: POTA MEMBRANA PRECOCIDA | C37: 38606.25 | D37: 37800 | E37: 76406.25 | F37: =E37/$E$40 -> 0.010547129 | H37: POTA MEMBRANA PRECOCIDA | J37: -9624.6422 | K37: 31423.105 | L37: 21798.463 | M37: =L37/E37 -> 0.28529686 | O37: POTA MEMBRANA PRECOCIDA | Q37: -5120.0656 | R37: 34520.292 | S37: 29400.226 | T37: =S37/E37 -> 0.38478823
A38: POTA TELILLA PRECOCIDA | C38: 38606.25 | E38: 38606.25 | F38: =E38/$E$40 -> 0.0053292121 | H38: POTA TELILLA PRECOCIDA | J38: -9239.5639 | L38: -9239.5639 | M38: =L38/E38 -> -0.23932819 | O38: POTA TELILLA PRECOCIDA | Q38: -4734.9873 | S38: -4734.9873 | T38: =S38/E38 -> -0.12264821
A39: RESIDUOS DE POTA | B39: 24314.28 | C39: 40026 | E39: 64340.28 | F39: =E39/$E$40 -> 0.0088815411 | H39: RESIDUOS DE POTA | I39: 24314.28 | J39: 40026 | L39: 64340.28 | M39: =L39/E39 -> 1 | O39: RESIDUOS DE POTA | P39: 24314.28 | Q39: 40026 | S39: 64340.28 | T39: =S39/E39 -> 1
A40: Total general | B40: 564615.28 | C40: 2769824.5 | D40: 3909830 | E40: 7244269.8 | F40: =E40/$E$40 -> 1 | H40: Total general | I40: -104805.29 | J40: -473381.82 | K40: -42698.695 | L40: -620885.81 | M40: =L40/E40 -> -0.085707162 | O40: Total general | P40: 149975.71 | Q40: -200731.43 | R40: 186240.71 | S40: 135485
A46: ANÁLISIS POR CLIENTE
A48: RANKING DE VENTAS (USD) | H48: UTILIDAD NETA (USD) | O48: EBITDA (USD) | V48: UTILIDAD BRUTA (USD)
A49: Suma de VALOR CFR | B49: Etiquetas de columna | H49: Suma de UTILIDAD NETA | I49: Etiquetas de columna | M49: MG | O49: Suma de EBITDA | P49: Etiquetas de columna | T49: MG | V49: Suma de UTILIDAD BRUTA | W49: Etiquetas de columna | AA49: MG
A50: Etiquetas de fila | B50: ENERO | C50: FEBRERO | D50: MARZO | E50: Total general | F50: % | H50: Etiquetas de fila | I50: ENERO | J50: FEBRERO | K50: MARZO | L50: Total general | M50: NETO | O50: Etiquetas de fila | P50: ENERO | Q50: FEBRERO | R50: MARZO | S50: Total general | T50: EBITDA | V50: Etiquetas de fila | W50: ENERO | X50: FEBRERO | Y50: MARZO | Z50: Total general | AA50: BRUTO
A51: TSUJINO | B51: 281115 | C51: 438056 | D51: 1115680 | E51: 1834851 | F51: =E51/$E$68 -> 0.25328309 | H51: TSUJINO | I51: -102120.31 | J51: -57455.589 | K51: -251483.85 | L51: -411059.75 | M51: =L51/E51 -> -0.22402895 | O51: TSUJINO | P51: 45817.05 | Q51: -13420.798 | R51: -168571.03 | S51: -136174.78 | T51: =S51/E51 -> -0.074215716 | V51: TSUJINO | W51: 28635 | X51: 10322.644 | Y51: -97552 | Z51: -58594.356 | AA51: =Z51/E51 -> -0.031934122
A52: KULALIA | C52: 390000 | D52: 833200 | E52: 1223200 | F52: =E52/$E$68 -> 0.1688507 | H52: KULALIA | J52: 78525.378 | K52: 184357.23 | L52: 262882.61 | M52: =L52/E52 -> 0.21491384 | O52: KULALIA | Q52: 104551.82 | R52: 222326.43 | S52: 326878.26 | T52: =S52/E52 -> 0.26723206 | V52: KULALIA | X52: 122414.63 | Y52: 259520 | Z52: 381934.63 | AA52: =Z52/E52 -> 0.31224218
A53: AVANCE GROUP | C53: 1066950 | E53: 1066950 | F53: =E53/$E$68 -> 0.14728193 | H53: AVANCE GROUP | J53: -484128.94 | L53: -484128.94 | M53: =L53/E53 -> -0.45375035 | O53: AVANCE GROUP | Q53: -353446.17 | S53: -353446.17 | T53: =S53/E53 -> -0.33126779 | V53: AVANCE GROUP | X53: -275132.6 | Z53: -275132.6 | AA53: =Z53/E53 -> -0.25786831
...

Sheet Resumen
G2: X | H2: X | M2: X | P2: X | AU2: X | AV2: X | BA2: ANÁLISIS UNITARIO
B3: MES LINK | C3: MES EJERCICIO | D3: FP | E3: Emision | F3: Fecha Embarque | G3: Cantidad | H3: Producto | I3: Corte | J3: Espec. | K3: País | L3: Puerto | M3: Cliente (Razón Social) | N3: Contacto | O3: Precio TM | P3: VALOR CFR | Q3: FOB / TM | R3: Costo Flete | S3: VALOR FOB | T3: Cantidad de FCL (Contenedores) | U3: M/V Nave | V3: Booking | W3: Naviera | X3: Puerto | Y3: CÓDIGO | Z3: Categoría | AA3: MATCH | AB3: COSTO UNITARIO | AC3: Materia Prima | AD3: MOD | AE3: Envases | AF3: CIF | AG3: COSTO VENTAS | AH3: Cant | AI3: C.U | AJ3: Cotos Vta | AK3: UTILIDAD BRUTA | AL3: MARGEN BRUTO | AM3: Flete | AN3: SS Logístico | AO3: GASTO VENTAS | AP3: GASTO ADM | AQ3: DRAWBACK | AR3: UTILIDAD OPERATIVA | AS3: MARGEN OPERATIVO | AT3: GASTO FINANCIERO | AU3: UTILIDAD NETA | AV3: MARGEN NETO | AW3: DEPRECIACIÓN | AX3: EBITDA | AY3: MARGEN EBITDA | BA3: PRECIO CFR | BB3: Materia Prima | BC3: MOD | BD3: Envases | BE3: CIF | BF3: COSTO VENTAS | BG3: UTILIDAD BRUTA | BH3: Flete | BI3: SS Logístico | BJ3: GASTO VENTAS | BK3: GASTO ADM | BL3: DRAWBACK | BM3: UTILIDAD OPERATIVA | BN3: GASTO FINANCIERO | BO3: UTILIDAD NETA | BP3: DEPRECIACIÓN | BQ3: EBITDA
B4: ENERO | C4: =B4 -> ENERO | D4: 127-2025 | E4: 325 | F4: 46033 | G4: 26 | H4: POTA REPRODUCTORES | I4: Rejos | K4: España | L4: Valencia | M4: OCEANUS FISH | N4: Ignacio / Ives | O4: =P4/G4 -> 2848.6154 | P4: =78000*0+74064 -> 74064 | Q4: =S4/G4 -> 2670.3846 | R4: 4634 | S4: =P4-R4 -> 69430 | T4: 1 | U4: MERSIN EXPRESS 603N | V4: 26106924 | W4: HAPAG | X4: PAITA | Y4: 10007567 | Z4: Compensación | AA4: =B4&Y4&Z4 -> ENERO10007567Compensación | AB4: =INDEX('Detalle Costos'!$L$5:$L$158,MATCH(Resumen!AA4,'Detalle Costos'!$C$5:$C$158,0))*1000 -> 1830 | AC4: =IFERROR(INDEX('Detalle Costos'!$X$5:$X$158,MATCH(Resumen!AA4,'Detalle Costos'!$C$5:$C$158,0))*AG4,0) -> 31604.019 | AD4: =IFERROR(INDEX('Detalle Costos'!$Z$5:$Z$158,MATCH(Resumen!AA4,'Detalle Costos'!$C$5:$C$158,0))*AG4,0) -> 7767.649 | AE4: =IFERROR(INDEX('Detalle Costos'!$Y$5:$Y$158,MATCH(Resumen!AA4,'Detalle Costos'!$C$5:$C$158,0))*AG4,0) -> 466.19182 | AF4: =IFERROR(INDEX('Detalle Costos'!$AA$5:$AA$158,MATCH(Resumen!AA4,'Detalle Costos'!$C$5:$C$158,0))*AG4,0) -> 7742.1407 | AG4: =AB4*G4 -> 47580 | AH4: =48.96-AH17 -> 22.658 | AI4: =+AJ4/AH4 -> 1829.8235 | AJ4: =89589.14-AJ17 -> 41460.14 | AK4: =P4-AG4 -> 26484 | AL4: =AK4/P4 -> 0.35758263 | AM4: =R4 -> 4634 | AN4: =1500/26*G4 -> 1500 | AO4: =SUM(AM4:AN4) -> 6134 | AP4: =60070/248*G4 -> 6297.6613 | AQ4: =S4*0.03 -> 2082.9 | AR4: =AK4-AO4-AP4+AQ4 -> 16135.239 | AS4: =AR4/P4 -> 0.21785535 | AT4: =131251/248*G4 -> 13760.185 | AU4: =AR4-AT4 -> 2375.0532 | AV4: =AU4/P4 -> 0.03206758 | AW4: =123530/248*G4 -> 12950.726 | AX4: =AR4+AW4 -> 29085.965 | AY4: =AX4/P4 -> 0.39271393 | BA4: =P4/$G4 -> 2848.6154 | BB4: =-AC4/$G4 -> -1215.5392 | BC4: =-AD4/$G4 -> -298.75573 | BD4: =-AE4/$G4 -> -17.930455 | BE4: =-AF4/$G4 -> -297.77464 | BF4: =-AG4/$G4 -> -1830 | BG4: =AK4/$G4 -> 1018.6154 | BH4: =-AM4/$G4 -> -178.23077 | BI4: =-AN4/$G4 -> -57.692308 | BJ4: =-AO4/$G4 -> -235.92308 | BK4: =-AP4/$G4 -> -242.21774 | BL4: =AQ4/$G4 -> 80.111538 | BM4: =AR4/$G4 -> 620.5861 | BN4: =-AT4/$G4 -> -529.2379 | BO4: =AU4/$G4 -> 91.348201 | BP4: =AW4/$G4 -> 498.10484 | BQ4: =AX4/$G4 -> 1118.6909
B5: ENERO | C5: =B5 -> ENERO | D5: 128-2025B | E5: 325 | F5: 46053 | G5: 17.04 | H5: POTA NUCAS | I5: Nucas | J5: 1000-up | K5: Tailandia | L5: Lat Krabang | M5: DAIRECK S.A. | N5: Julieta | O5: 1850 | P5: 31524 | Q5: 1656.338 | R5: =3300/24*G5 -> 2343 | S5: =P5-R5 -> 29181 | T5: 1 | U5: ECO SIROCCO 26005S | V5: 6443191850 | W5: COSCO | X5: PAITA | Y5: 10005779 | Z5: Compensación | AA5: =B5&Y5&Z5 -> ENERO10005779Compensación | AB5: =INDEX('Detalle Costos'!$L$5:$L$158,MATCH(Resumen!AA5,'Detalle Costos'!$C$5:$C$158,0))*1000 -> 1930 | AC5: =IFERROR(INDEX('Detalle Costos'!$X$5:$X$158,MATCH(Resumen!AA5,'Detalle Costos'!$C$5:$C$158,0))*AG5,0) -> 20697.485 | AD5: =IFERROR(INDEX('Detalle Costos'!$Z$5:$Z$158,MATCH(Resumen!AA5,'Detalle Costos'!$C$5:$C$158,0))*AG5,0) -> 6988.7487 | AE5: =IFERROR(INDEX('Detalle Costos'!$Y$5:$Y$158,MATCH(Resumen!AA5,'Detalle Costos'!$C$5:$C$158,0))*AG5,0) -> 251.15165 | AF5: =IFERROR(INDEX('Detalle Costos'!$AA$5:$AA$158,MATCH(Resumen!AA5,'Detalle Costos'!$C$5:$C$158,0))*AG5,0) -> 4949.8151 | AG5: =AB5*G5 -> 32887.2 | AH5: 17.04 | AI5: =+AJ5/AH5 -> 1977.4951 | AJ5: 33696.517 | AK5: =P5-AG5 -> -1363.2 | AL5: =AK5/P5 -> -0.043243243 | AM5: =R5 -> 2343 | AN5: =1500/26*G5 -> 983.07692 | AO5: =SUM(AM5:AN5) -> 3326.0769 | AP5: =60070/248*G5 -> 4127.3903 | AQ5: =S5*0.03 -> 875.43 | AR5: =AK5-AO5-AP5+AQ5 -> -7941.2372 | AS5: =AR5/P5 -> -0.25191084 | AT5: =131251/248*G5 -> 9018.2139 | AU5: =AR5-AT5 -> -16959.451 | AV5: =AU5/P5 -> -0.53798538 | AW5: =123530/248*G5 -> 8487.7065 | AX5: =AR5+AW5 -> 546.46921 | AY5: =AX5/P5 -> 0.017335021 | BA5: =P5/$G5 -> 1850 | BB5: =-AC5/$G5 -> -1214.6411 | BC5: =-AD5/$G5 -> -410.13784 | BD5: =-AE5/$G5 -> -14.738946 | BE5: =-AF5/$G5 -> -290.48211 | BF5: =-AG5/$G5 -> -1930 | BG5: =AK5/$G5 -> -80 | BH5: =-AM5/$G5 -> -137.5 | BI5: =-AN5/$G5 -> -57.692308 | BJ5: =-AO5/$G5 -> -195.19231 | BK5: =-AP5/$G5 -> -242.21774 | BL5: =AQ5/$G5 -> 51.375 | BM5: =AR5/$G5 -> -466.03505 | BN5: =-AT5/$G5 -> -529.2379 | BO5: =AU5/$G5 -> -995.27295 | BP5: =AW5/$G5 -> 498.10484 | BQ5: =AX5/$G5 -> 32.069789
B6: ENERO | C6: =B6 -> ENERO | D6: 128-2025B | E6: 325 | F6: 46053 | G6: 3 | H6: POTA NUCAS | I6: Nucas | J6: 500 - 1 kg. | K6: Tailandia | L6: Lat Krabang | M6: DAIRECK S.A. | N6: Julieta | O6: 1450 | P6: 4350 | Q6: 1450 | R6: =3300/24*G6 -> 412.5 | S6: =P6-R6 -> 3937.5 | T6: 0 | V6: 6443191850 | W6: COSCO | X6: PAITA | Y6: 10005781 | Z6: Compensación | AA6: =B6&Y6&Z6 -> ENERO10005781Compensación | AB6: =INDEX('Detalle Costos'!$L$5:$L$158,MATCH(Resumen!AA6,'Detalle Costos'!$C$5:$C$158,0))*1000 -> 1980 | AC6: =IFERROR(INDEX('Detalle Costos'!$X$5:$X$158,MATCH(Resumen!AA6,'Detalle Costos'!$C$5:$C$158,0))*AG6,0) -> 3757.0132 | AD6: =IFERROR(INDEX('Detalle Costos'!$Z$5:$Z$158,MATCH(Resumen!AA6,'Detalle Costos'!$C$5:$C$158,0))*AG6,0) -> 1227.8049 | AE6: =IFERROR(INDEX('Detalle Costos'!$Y$5:$Y$158,MATCH(Resumen!AA6,'Detalle Costos'!$C$5:$C$158,0))*AG6,0) -> 49.950511 | AF6: =IFERROR(INDEX('Detalle Costos'!$AA$5:$AA$158,MATCH(Resumen!AA6,'Detalle Costos'!$C$5:$C$158,0))*AG6,0) -> 905.23138 | AG6: =AB6*G6 -> 5940 | AH6: 3 | AI6: =+AJ6/AH6 -> 1934.6564 | AJ6: 5803.9692 | AK6: =P6-AG6 -> -1590 | AL6: =AK6/P6 -> -0.36551724 | AM6: =R6 -> 412.5 | AN6: =1500/26*G6 -> 173.07692 | AO6: =SUM(AM6:AN6) -> 585.57692 | AP6: =60070/248*G6 -> 726.65323 | AQ6: =S6*0.03 -> 118.125 | AR6: =AK6-AO6-AP6+AQ6 -> -2784.1051 | AS6: =AR6/P6 -> -0.64002417 | AT6: =131251/248*G6 -> 1587.7137 | AU6: =AR6-AT6 -> -4371.8189 | AV6: =AU6/P6 -> -1.0050158 | AW6: =123530/248*G6 -> 1494.3145 | AX6: =AR6+AW6 -> -1289.7906 | AY6: =AX6/P6 -> -0.29650359 | BA6: =P6/$G6 -> 1450 | BB6: =-AC6/$G6 -> -1252.3377 | BC6: =-AD6/$G6 -> -409.26831 | BD6: =-AE6/$G6 -> -16.65017 | BE6: =-AF6/$G6 -> -301.74379 | BF6: =-AG6/$G6 -> -1980 | BG6: =AK6/$G6 -> -530 | BH6: =-AM6/$G6 -> -137.5 | BI6: =-AN6/$G6 -> -57.692308 | BJ6: =-AO6/$G6 -> -195.19231 | BK6: =-AP6/$G6 -> -242.21774 | BL6: =AQ6/$G6 -> 39.375 | BM6: =AR6/$G6 -> -928.03505 | BN6: =-AT6/$G6 -> -529.2379 | BO6: =AU6/$G6 -> -1457.273 | BP6: =AW6/$G6 -> 498.10484 | BQ6: =AX6/$G6 -> -429.93021
B7: ENERO | C7: =B7 -> ENERO | D7: 128-2025B | E7: 325 | F7: 46053 | G7: 3.96 | H7: POTA REJOS CONGELADOS | I7: Rejos | J7: 1 - 2 kgs. | K7: Tailandia | L7: Lat Krabang | M7: DAIRECK S.A. | N7: Julieta | O7: =P7/G7 -> 2234.3434 | P7: 8848 | Q7: 2800 | R7: =3300/24*G7 -> 544.5 | S7: =P7-R7 -> 8303.5 | T7: 0 | V7: 6443191850 | W7: COSCO | X7: PAITA | Y7: 10007162 | Z7: Compensación | AA7: =B7&Y7&Z7 -> ENERO10007162Compensación | AB7: =INDEX('Detalle Costos'!$L$5:$L$158,MATCH(Resumen!AA7,'Detalle Costos'!$C$5:$C$158,0))*1000 -> 1790 | AC7: =IFERROR(INDEX('Detalle Costos'!$X$5:$X$158,MATCH(Resumen!AA7,'Detalle Costos'!$C$5:$C$158,0))*AG7,0) -> 4604.3696 | AD7: =IFERROR(INDEX('Detalle Costos'!$Z$5:$Z$158,MATCH(Resumen!AA7,'Detalle Costos'!$C$5:$C$158,0))*AG7,0) -> 1214.8181 | AE7: =IFERROR(INDEX('Detalle Costos'!$Y$5:$Y$158,MATCH(Resumen!AA7,'Detalle Costos'!$C$5:$C$158,0))*AG7,0) -> 61.899523 | AF7: =IFERROR(INDEX('Detalle Costos'!$AA$5:$AA$158,MATCH(Resumen!AA7,'Detalle Costos'!$C$5:$C$158,0))*AG7,0) -> 1207.3128 | AG7: =AB7*G7 -> 7088.4 | AH7: 3.16 | AI7: =+AJ7/AH7 -> 1842.697 | AJ7: 5822.9227 | AK7: =P7-AG7 -> 1759.6 | AL7: =AK7/P7 -> 0.1988698 | AM7: =R7 -> 544.5 | AN7: =1500/26*G7 -> 228.46154 | AO7: =SUM(AM7:AN7) -> 772.96154 | AP7: =60070/248*G7 -> 959.18226 | AQ7: =S7*0.03 -> 249.105 | AR7: =AK7-AO7-AP7+AQ7 -> 276.5612 | AS7: =AR7/P7 -> 0.031256917 | AT7: =131251/248*G7 -> 2095.7821 | AU7: =AR7-AT7 -> -1819.2209 | AV7: =AU7/P7 -> -0.20560815 | AW7: =123530/248*G7 -> 1972.4952 | AX7: =AR7+AW7 -> 2249.0564 | AY7: =AX7/P7 -> 0.25418811 | BA7: =P7/$G7 -> 2234.3434 | BB7: =-AC7/$G7 -> -1162.7196 | BC7: =-AD7/$G7 -> -306.77225 | BD7: =-AE7/$G7 -> -15.631193 | BE7: =-AF7/$G7 -> -304.87696 | BF7: =-AG7/$G7 -> -1790 | BG7: =AK7/$G7 -> 444.34343 | BH7: =-AM7/$G7 -> -137.5 | BI7: =-AN7/$G7 -> -57.692308 | BJ7: =-AO7/$G7 -> -195.19231 | BK7: =-AP7/$G7 -> -242.21774 | BL7: =AQ7/$G7 -> 62.905303 | BM7: =AR7/$G7 -> 69.838688 | BN7: =-AT7/$G7 -> -529.2379 | BO7: =AU7/$G7 -> -459.39922 | BP7: =AW7/$G7 -> 498.10484 | BQ7: =AX7/$G7 -> 567.94353
B8: ENERO | C8: =B8 -> ENERO | D8: 129-2025 | E8: 45982 | F8: 46031 | G8: 24 | H8: POTA CONOS | I8: Conos | K8: Tailandia | L8: Bangkok | M8: TSUJINO | N8: Jose | O8: 2100 | P8: 50400 | Q8: 1962.5 | R8: 3300 | S8: =P8-R8 -> 47100 | T8: 1 | U8: ECO MARIN 26002S | V8: 6440924270 | W8: COSCO | X8: PAITA | Y8: 10007969 | Z8: Compensación | AA8: =B8&Y8&Z8 -> ENERO10007969Compensación | AB8: =INDEX('Detalle Costos'!$L$5:$L$158,MATCH(Resumen!AA8,'Detalle Costos'!$C$5:$C$158,0))*1000 -> 1640 | AC8: =IFERROR(INDEX('Detalle Costos'!$X$5:$X$158,MATCH(Resumen!AA8,'Detalle Costos'!$C$5:$C$158,0))*AG8,0) -> 30431.619 | AD8: =IFERROR(INDEX('Detalle Costos'!$Z$5:$Z$158,MATCH(Resumen!AA8,'Detalle Costos'!$C$5:$C$158,0))*AG8,0) -> 5331.8121 | AE8: =IFERROR(INDEX('Detalle Costos'!$Y$5:$Y$158,MATCH(Resumen!AA8,'Detalle Costos'!$C$5:$C$158,0))*AG8,0) -> 403.53077 | AF8: =IFERROR(INDEX('Detalle Costos'!$AA$5:$AA$158,MATCH(Resumen!AA8,'Detalle Costos'!$C$5:$C$158,0))*AG8,0) -> 3193.0382 | AG8: =AB8*G8 -> 39360 | AH8: 24 | AI8: =+AJ8/AH8 -> 1644.3167 | AJ8: 39463.6 | AK8: =P8-AG8 -> 11040 | AL8: =AK8/P8 -> 0.21904762 | AM8: =R8 -> 3300 | AN8: =1500/26*G8 -> 1384.6154 | AO8: =SUM(AM8:AN8) -> 4684.6154 | AP8: =60070/248*G8 -> 5813.2258 | AQ8: =S8*0.03 -> 1413 | AR8: =AK8-AO8-AP8+AQ8 -> 1955.1588 | AS8: =AR8/P8 -> 0.038792834 | AT8: =131251/248*G8 -> 12701.71 | AU8: =AR8-AT8 -> -10746.551 | AV8: =AU8/P8 -> -0.21322522 | AW8: =123530/248*G8 -> 11954.516 | AX8: =AR8+AW8 -> 13909.675 | AY8: =AX8/P8 -> 0.27598561 | BA8: =P8/$G8 -> 2100 | BB8: =-AC8/$G8 -> -1267.9841 | BC8: =-AD8/$G8 -> -222.15884 | BD8: =-AE8/$G8 -> -16.813782 | BE8: =-AF8/$G8 -> -133.04326 | BF8: =-AG8/$G8 -> -1640 | BG8: =AK8/$G8 -> 460 | BH8: =-AM8/$G8 -> -137.5 | BI8: =-AN8/$G8 -> -57.692308 | BJ8: =-AO8/$G8 -> -195.19231 | BK8: =-AP8/$G8 -> -242.21774 | BL8: =AQ8/$G8 -> 58.875 | BM8: =AR8/$G8 -> 81.46495 | BN8: =-AT8/$G8 -> -529.2379 | BO8: =AU8/$G8 -> -447.77295 | BP8: =AW8/$G8 -> 498.10484 | BQ8: =AX8/$G8 -> 579.56979
B9: ENERO | C9: =B9 -> ENERO | D9: 137-2025 | E9: 46000 | F9: 46043 | G9: 24 | H9: POTA FILETE CONGELADO | I9: Filete | J9: 2 - 4 kg | K9: Taiwan | L9: KAOHSIUNG | M9: TSUJINO | N9: Jose | O9: =P9/G9 -> 1966.6667 | P9: =48000*0+47200 -> 47200 | Q9: =S9/G9 -> 1841.5417 | R9: 3003 | S9: =P9-R9 -> 44197 | T9: 1 | U9: ECO MARIN 25052N | V9: LIMF26385300 | W9: ONE | X9: PAITA | Y9: 10005721 | Z9: Compensación | AA9: =B9&Y9&Z9 -> ENERO10005721Compensación | AB9: =INDEX('Detalle Costos'!$L$5:$L$158,MATCH(Resumen!AA9,'Detalle Costos'!$C$5:$C$158,0))*1000 -> 1860 | AC9: =IFERROR(INDEX('Detalle Costos'!$X$5:$X$158,MATCH(Resumen!AA9,'Detalle Costos'!$C$5:$C$158,0))*AG9,0) -> 27074.763 | AD9: =IFERROR(INDEX('Detalle Costos'!$Z$5:$Z$158,MATCH(Resumen!AA9,'Detalle Costos'!$C$5:$C$158,0))*AG9,0) -> 9821.5948 | AE9: =IFERROR(INDEX('Detalle Costos'!$Y$5:$Y$158,MATCH(Resumen!AA9,'Detalle Costos'!$C$5:$C$158,0))*AG9,0) -> 427.38655 | AF9: =IFERROR(INDEX('Detalle Costos'!$AA$5:$AA$158,MATCH(Resumen!AA9,'Detalle Costos'!$C$5:$C$158,0))*AG9,0) -> 7316.2554 | AG9: =AB9*G9 -> 44640 | AH9: 23.7 | AI9: =+AJ9/AH9 -> 1889.3859 | AJ9: 44778.445 | AK9: =P9-AG9 -> 2560 | AL9: =AK9/P9 -> 0.054237288 | AM9: =R9 -> 3003 | AN9: =1500/26*G9 -> 1384.6154 | AO9: =SUM(AM9:AN9) -> 4387.6154 | AP9: =60070/248*G9 -> 5813.2258 | AQ9: =S9*0.03 -> 1325.91 | AR9: =AK9-AO9-AP9+AQ9 -> -6314.9312 | AS9: =AR9/P9 -> -0.13379092 | AT9: =131251/248*G9 -> 12701.71 | AU9: =AR9-AT9 -> -19016.641 | AV9: =AU9/P9 -> -0.40289493 | AW9: =123530/248*G9 -> 11954.516 | AX9: =AR9+AW9 -> 5639.5849 | AY9: =AX9/P9 -> 0.11948273 | BA9: =P9/$G9 -> 1966.6667 | BB9: =-AC9/$G9 -> -1128.1151 | BC9: =-AD9/$G9 -> -409.23312 | BD9: =-AE9/$G9 -> -17.807773 | BE9: =-AF9/$G9 -> -304.84398 | BF9: =-AG9/$G9 -> -1860 | BG9: =AK9/$G9 -> 106.66667 | BH9: =-AM9/$G9 -> -125.125 | BI9: =-AN9/$G9 -> -57.692308 | BJ9: =-AO9/$G9 -> -182.81731 | BK9: =-AP9/$G9 -> -242.21774 | BL9: =AQ9/$G9 -> 55.24625 | BM9: =AR9/$G9 -> -263.12213 | BN9: =-AT9/$G9 -> -529.2379 | BO9: =AU9/$G9 -> -792.36004 | BP9: =AW9/$G9 -> 498.10484 | BQ9: =AX9/$G9 -> 234.98271
B10: ENERO | C10: =B10 -> ENERO | D10: 140-2025 | E10: 347 | F10: 46038 | G10: 24 | H10: POTA FILETE CONGELADO | I10: Filete | J10: 2-4kg | K10: Japón | L10: Sendai | M10: TSUJINO | N10: Jose | O10: =P10/G10 -> 1983.3333 | P10: =48000*0+47600 -> 47600 | Q10: =S10/G10 -> 1845.7083 | R10: 3303 | S10: =P10-R10 -> 44297 | T10: 1 | U10: ECO SIROCCO 26003S | V10: LIMG00358300 | W10: ONE | X10: PAITA | Y10: 10005721 | Z10: Compensación | AA10: =B10&Y10&Z10 -> ENERO10005721Compensación | AB10: =INDEX('Detalle Costos'!$L$5:$L$158,MATCH(Resumen!AA10,'Detalle Costos'!$C$5:$C$158,0))*1000 -> 1860 | AC10: =IFERROR(INDEX('Detalle Costos'!$X$5:$X$158,MATCH(Resumen!AA10,'Detalle Costos'!$C$5:$C$158,0))*AG10,0) -> 27074.763 | AD10: =IFERROR(INDEX('Detalle Costos'!$Z$5:$Z$158,MATCH(Resumen!AA10,'Detalle Costos'!$C$5:$C$158,0))*AG10,0) -> 9821.5948 | AE10: =IFERROR(INDEX('Detalle Costos'!$Y$5:$Y$158,MATCH(Resumen!AA10,'Detalle Costos'!$C$5:$C$158,0))*AG10,0) -> 427.38655 | AF10: =IFERROR(INDEX('Detalle Costos'!$AA$5:$AA$158,MATCH(Resumen!AA10,'Detalle Costos'!$C$5:$C$158,0))*AG10,0) -> 7316.2554 | AG10: =AB10*G10 -> 44640 | AH10: 23.7 | AI10: =+AJ10/AH10 -> 1889.3859 | AJ10: 44778.445 | AK10: =P10-AG10 -> 2960 | AL10: =AK10/P10 -> 0.062184874 | AM10: =R10 -> 3303 | AN10: =1500/26*G10 -> 1384.6154 | AO10: =SUM(AM10:AN10) -> 4687.6154 | AP10: =60070/248*G10 -> 5813.2258 | AQ10: =S10*0.03 -> 1328.91 | AR10: =AK10-AO10-AP10+AQ10 -> -6211.9312 | AS10: =AR10/P10 -> -0.13050276 | AT10: =131251/248*G10 -> 12701.71 | AU10: =AR10-AT10 -> -18913.641 | AV10: =AU10/P10 -> -0.3973454 | AW10: =123530/248*G10 -> 11954.516 | AX10: =AR10+AW10 -> 5742.5849 | AY10: =AX10/P10 -> 0.12064254 | BA10: =P10/$G10 -> 1983.3333 | BB10: =-AC10/$G10 -> -1128.1151 | BC10: =-AD10/$G10 -> -409.23312 | BD10: =-AE10/$G10 -> -17.807773 | BE10: =-AF10/$G10 -> -304.84398 | BF10: =-AG10/$G10 -> -1860 | BG10: =AK10/$G10 -> 123.33333 | BH10: =-AM10/$G10 -> -137.625 | BI10: =-AN10/$G10 -> -57.692308 | BJ10: =-AO10/$G10 -> -195.31731 | BK10: =-AP10/$G10 -> -242.21774 | BL10: =AQ10/$G10 -> 55.37125 | BM10: =AR10/$G10 -> -258.83047 | BN10: =-AT10/$G10 -> -529.2379 | BO10: =AU10/$G10 -> -788.06837 | BP10: =AW10/$G10 -> 498.10484 | BQ10: =AX10/$G10 -> 239.27437
B11: ENERO | C11: =B11 -> ENERO | D11: 145-2025 | E11: 46020 | F11: 46041 | G11: 54 | H11: POTA REJOS CONGELADOS | I11: Rejos | J11: 500-1 / 1-2 | K11: España | L11: Vigo | M11: GLOBAL OCEAN | N11: Jorge | O11: 2600 | P11: 140400 | Q11: 2430.963 | R11: 9128 | S11: =P11-R11 -> 131272 | T11: 2 | U11: IZMIT EXPRESS 604N | V11: 28952064 | W11: HAPAG | X11: PAITA | Y11: 10007162 | Z11: Compensación | AA11: =B11&Y11&Z11 -> ENERO10007162Compensación | AB11: =INDEX('Detalle Costos'!$L$5:$L$158,MATCH(Resumen!AA11,'Detalle Costos'!$C$5:$C$158,0))*1000 -> 1790 | AC11: =IFERROR(INDEX('Detalle Costos'!$X$5:$X$158,MATCH(Resumen!AA11,'Detalle Costos'!$C$5:$C$158,0))*AG11,0) -> 62786.858 | AD11: =IFERROR(INDEX('Detalle Costos'!$Z$5:$Z$158,MATCH(Resumen!AA11,'Detalle Costos'!$C$5:$C$158,0))*AG11,0) -> 16565.702 | AE11: =IFERROR(INDEX('Detalle Costos'!$Y$5:$Y$158,MATCH(Resumen!AA11,'Detalle Costos'!$C$5:$C$158,0))*AG11,0) -> 844.0844 | AF11: =IFERROR(INDEX('Detalle Costos'!$AA$5:$AA$158,MATCH(Resumen!AA11,'Detalle Costos'!$C$5:$C$158,0))*AG11,0) -> 16463.356 | AG11: =AB11*G11 -> 96660 | AH11: 54 | AI11: =+AJ11/AH11 -> 1842.697 | AJ11: 99505.64 | AK11: =P11-AG11 -> 43740 | AL11: =AK11/P11 -> 0.31153846 | AM11: =R11 -> 9128 | AN11: =1500/26*G11 -> 3115.3846 | AO11: =SUM(AM11:AN11) -> 12243.385 | AP11: =60070/248*G11 -> 13079.758 | AQ11: =S11*0.03 -> 3938.16 | AR11: =AK11-AO11-AP11+AQ11 -> 22355.017 | AS11: =AR11/P11 -> 0.15922377 | AT11: =131251/248*G11 -> 28578.847 | AU11: =AR11-AT11 -> -6223.8295 | AV11: =AU11/P11 -> -0.04432927 | AW11: =123530/248*G11 -> 26897.661 | AX11: =AR11+AW11 -> 49252.679 | AY11: =AX11/P11 -> 0.35080255 | BA11: =P11/$G11 -> 2600 | BB11: =-AC11/$G11 -> -1162.7196 | BC11: =-AD11/$G11 -> -306.77225 | BD11: =-AE11/$G11 -> -15.631193 | BE11: =-AF11/$G11 -> -304.87696 | BF11: =-AG11/$G11 -> -1790 | BG11: =AK11/$G11 -> 810 | BH11: =-AM11/$G11 -> -169.03704 | BI11: =-AN11/$G11 -> -57.692308 | BJ11: =-AO11/$G11 -> -226.72934 | BK11: =-AP11/$G11 -> -242.21774 | BL11: =AQ11/$G11 -> 72.928889 | BM11: =AR11/$G11 -> 413.9818 | BN11: =-AT11/$G11 -> -529.2379 | BO11: =AU11/$G11 -> -115.2561 | BP11: =AW11/$G11 -> 498.10484 | BQ11: =AX11/$G11 -> 912.08664
B12: FEBRERO | C12: =B12 -> FEBRERO | D12: 146-2026 | E12: 46027 | F12: 46059 | G12: 10 | H12: POTA CONOS | I12: Conos | J12: 10 cm - up | K12: Tailandia | L12: Lat Krabang | M12: TSUJINO | N12: Jose | O12: 2100 | P12: 21000 | Q12: 2100 | R12: =3500/24*G12 -> 1458.3333 | S12: =P12-R12 -> 19541.667 | T12: 1 | U12: ECO MARIN 26006S | V12: 6444023300 | W12: COSCO | X12: PAITA | Y12: 10007969 | Z12: Compensación | AA12: =B12&Y12&Z12 -> FEBRERO10007969Compensación | AB12: =INDEX('Detalle Costos'!$L$5:$L$158,MATCH(Resumen!AA12,'Detalle Costos'!$C$5:$C$158,0))*1000*0+AI12 -> 1397.2773 | AC12: =IFERROR(INDEX('Detalle Costos'!$X$5:$X$158,MATCH(Resumen!AA12,'Detalle Costos'!$C$5:$C$158,0))*AG12,0) -> 11301.832 | AD12: =IFERROR(INDEX('Detalle Costos'!$Z$5:$Z$158,MATCH(Resumen!AA12,'Detalle Costos'!$C$5:$C$158,0))*AG12,0) -> 2127.4653 | AE12: =IFERROR(INDEX('Detalle Costos'!$Y$5:$Y$158,MATCH(Resumen!AA12,'Detalle Costos'!$C$5:$C$158,0))*AG12,0) -> 166.83162 | AF12: =IFERROR(INDEX('Detalle Costos'!$AA$5:$AA$158,MATCH(Resumen!AA12,'Detalle Costos'!$C$5:$C$158,0))*AG12,0) -> 376.64454 | AG12: =AB12*G12 -> 13972.773 | AH12: =+G12 -> 10 | AI12: 1397.2773 | AJ12: =+AI12*AH12 -> 13972.773 | AK12: =P12-AG12 -> 7027.2269 | AL12: =AK12/P12 -> 0.33462985 | AM12: =R12 -> 1458.3333 | AN12: =1500/26*G12 -> 576.92308 | AO12: =SUM(AM12:AN12) -> 2035.2564 | AP12: =65590/1634.3*G12 -> 401.3339 | AQ12: =S12*0.03 -> 586.25 | AR12: =AK12-AO12-AP12+AQ12 -> 5176.8866 | AS12: =AR12/P12 -> 0.24651841 | AT12: =148498/1634.3*G12 -> 908.63367 | AU12: =AR12-AT12 -> 4268.2529 | AV12: =AU12/P12 -> 0.20325014 | AW12: =123484.35/1634.3*G12 -> 755.57945 | AX12: =AR12+AW12 -> 5932.4661 | AY12: =AX12/P12 -> 0.28249838 | BA12: =P12/$G12 -> 2100 | BB12: =-AC12/$G12 -> -1130.1832 | BC12: =-AD12/$G12 -> -212.74653 | BD12: =-AE12/$G12 -> -16.683162 | BE12: =-AF12/$G12 -> -37.664454 | BF12: =-AG12/$G12 -> -1397.2773 | BG12: =AK12/$G12 -> 702.72269 | BH12: =-AM12/$G12 -> -145.83333 | BI12: =-AN12/$G12 -> -57.692308 | BJ12: =-AO12/$G12 -> -203.52564 | BK12: =-AP12/$G12 -> -40.13339 | BL12: =AQ12/$G12 -> 58.625 | BM12: =AR12/$G12 -> 517.68866 | BN12: =-AT12/$G12 -> -90.863367 | BO12: =AU12/$G12 -> 426.82529 | BP12: =AW12/$G12 -> 75.557945 | BQ12: =AX12/$G12 -> 593.24661
B13: FEBRERO | C13: =B13 -> FEBRERO | D13: 146-2026 | E13: 46027 | F13: 46059 | G13: 14 | H13: POTA NUCAS | I13: Nucas | J13: 500-up | K13: Tailandia | L13: Lat Krabang | M13: TSUJINO | N13: Jose | O13: 1700 | P13: =23800-344 -> 23456 | Q13: 1700 | R13: =3500/24*G13 -> 2041.6667 | S13: =P13-R13 -> 21414.333 | T13: 0 | Y13: 10005779 | Z13: Compensación | AA13: =B13&Y13&Z13 -> FEBRERO10005779Compensación | AB13: =INDEX('Detalle Costos'!$L$5:$L$158,MATCH(Resumen!AA13,'Detalle Costos'!$C$5:$C$158,0))*1000*0+AI13 -> 1859.7145 | AC13: =IFERROR(INDEX('Detalle Costos'!$X$5:$X$158,MATCH(Resumen!AA13,'Detalle Costos'!$C$5:$C$158,0))*AG13,0) -> 15847.871 | AD13: =IFERROR(INDEX('Detalle Costos'!$Z$5:$Z$158,MATCH(Resumen!AA13,'Detalle Costos'!$C$5:$C$158,0))*AG13,0) -> 5732.4075 | AE13: =IFERROR(INDEX('Detalle Costos'!$Y$5:$Y$158,MATCH(Resumen!AA13,'Detalle Costos'!$C$5:$C$158,0))*AG13,0) -> 189.9202 | AF13: =IFERROR(INDEX('Detalle Costos'!$AA$5:$AA$158,MATCH(Resumen!AA13,'Detalle Costos'!$C$5:$C$158,0))*AG13,0) -> 4265.8048 | AG13: =AB13*G13 -> 26036.003 | AH13: 14.849 | AI13: 1859.7145 | AJ13: =AI13*AH13 -> 27614.901 | AK13: =P13-AG13 -> -2580.0034 | AL13: =AK13/P13 -> -0.10999332 | AM13: =R13 -> 2041.6667 | AN13: =1500/26*G13 -> 807.69231 | AO13: =SUM(AM13:AN13) -> 2849.359 | AP13: =65590/1634.3*G13 -> 561.86747 | AQ13: =S13*0.03 -> 642.43 | AR13: =AK13-AO13-AP13+AQ13 -> -5348.7998 | AS13: =AR13/P13 -> -0.22803546 | AT13: =148498/1634.3*G13 -> 1272.0871 | AU13: =AR13-AT13 -> -6620.887 | AV13: =AU13/P13 -> -0.28226837 | AW13: =123484.35/1634.3*G13 -> 1057.8112 | AX13: =AR13+AW13 -> -4290.9886 | AY13: =AX13/P13 -> -0.18293778 | BA13: =P13/$G13 -> 1675.4286 | BB13: =-AC13/$G13 -> -1131.9908 | BC13: =-AD13/$G13 -> -409.45768 | BD13: =-AE13/$G13 -> -13.565729 | BE13: =-AF13/$G13 -> -304.70034 | BF13: =-AG13/$G13 -> -1859.7145 | BG13: =AK13/$G13 -> -184.28596 | BH13: =-AM13/$G13 -> -145.83333 | BI13: =-AN13/$G13 -> -57.692308 | BJ13: =-AO13/$G13 -> -203.52564 | BK13: =-AP13/$G13 -> -40.13339 | BL13: =AQ13/$G13 -> 45.887857 | BM13: =AR13/$G13 -> -382.05713 | BN13: =-AT13/$G13 -> -90.863367 | BO13: =AU13/$G13 -> -472.9205 | BP13: =AW13/$G13 -> 75.557945 | BQ13: =AX13/$G13 -> -306.49919
B14: ENERO | C14: =B14 -> ENERO | D14: 147-2026 | E14: 46032 | F14: 46050 | G14: 72 | H14: POTA ALAS CONGELADAS | I14: Alas | J14: 1 - 2 KGS. | K14: Tailandia | L14: Bangkok | M14: TSUJINO | N14: Jose | O14: =P14/G14 -> 1887.7083 | P14: =140400*0+135915 -> 135915 | Q14: =S14/G14 -> 1754.25 | R14: 9609 | S14: =P14-R14 -> 126306 | T14: 3 | U14: ECO MARIN 26004N | V14: LIMG01524600 | W14: ONE | X14: PAITA | Y14: 10006720 | Z14: Compensación | AA14: =B14&Y14&Z14 -> ENERO10006720Compensación | AB14: =INDEX('Detalle Costos'!$L$5:$L$158,MATCH(Resumen!AA14,'Detalle Costos'!$C$5:$C$158,0))*1000 -> 1720 | AC14: =IFERROR(INDEX('Detalle Costos'!$X$5:$X$158,MATCH(Resumen!AA14,'Detalle Costos'!$C$5:$C$158,0))*AG14,0) -> 81764.361 | AD14: =IFERROR(INDEX('Detalle Costos'!$Z$5:$Z$158,MATCH(Resumen!AA14,'Detalle Costos'!$C$5:$C$158,0))*AG14,0) -> 18919.258 | AE14: =IFERROR(INDEX('Detalle Costos'!$Y$5:$Y$158,MATCH(Resumen!AA14,'Detalle Costos'!$C$5:$C$158,0))*AG14,0) -> 1185.8374 | AF14: =IFERROR(INDEX('Detalle Costos'!$AA$5:$AA$158,MATCH(Resumen!AA14,'Detalle Costos'!$C$5:$C$158,0))*AG14,0) -> 21970.544 | AG14: =AB14*G14 -> 123840 | AH14: 69.7 | AI14: =+AJ14/AH14 -> 1723.916 | AJ14: 120156.94 | AK14: =P14-AG14 -> 12075 | AL14: =AK14/P14 -> 0.088842291 | AM14: =R14 -> 9609 | AN14: =1500/26*G14 -> 4153.8462 | AO14: =SUM(AM14:AN14) -> 13762.846 | AP14: =60070/248*G14 -> 17439.677 | AQ14: =S14*0.03 -> 3789.18 | AR14: =AK14-AO14-AP14+AQ14 -> -15338.344 | AS14: =AR14/P14 -> -0.11285247 | AT14: =131251/248*G14 -> 38105.129 | AU14: =AR14-AT14 -> -53443.473 | AV14: =AU14/P14 -> -0.39321247 | AW14: =123530/248*G14 -> 35863.548 | AX14: =AR14+AW14 -> 20525.205 | AY14: =AX14/P14 -> 0.15101501 | BA14: =P14/$G14 -> 1887.7083 | BB14: =-AC14/$G14 -> -1135.6161 | BC14: =-AD14/$G14 -> -262.76747 | BD14: =-AE14/$G14 -> -16.469963 | BE14: =-AF14/$G14 -> -305.14645 | BF14: =-AG14/$G14 -> -1720 | BG14: =AK14/$G14 -> 167.70833 | BH14: =-AM14/$G14 -> -133.45833 | BI14: =-AN14/$G14 -> -57.692308 | BJ14: =-AO14/$G14 -> -191.15064 | BK14: =-AP14/$G14 -> -242.21774 | BL14: =AQ14/$G14 -> 52.6275 | BM14: =AR14/$G14 -> -213.03255 | BN14: =-AT14/$G14 -> -529.2379 | BO14: =AU14/$G14 -> -742.27045 | BP14: =AW14/$G14 -> 498.10484 | BQ14: =AX14/$G14 -> 285.07229
B15: ENERO | C15: =B15 -> ENERO | E15: 46053 | F15: 46053 | G15: 0 | H15: RESIDUOS DE POTA | I15: Residuos | J15: Residuos | K15: Residuos | L15: Residuos | M15: PROVEEDORA DE PRODUCTOS MARINOS | O15: 0 | P15: 24314.28 | Q15: 0 | R15: 0 | S15: =P15-R15 -> 24314.28 | AB15: 0 | AC15: =IFERROR(INDEX('Detalle Costos'!$X$5:$X$158,MATCH(Resumen!AA15,'Detalle Costos'!$C$5:$C$158,0))*AG15,0) -> 0 | AD15: =IFERROR(INDEX('Detalle Costos'!$Z$5:$Z$158,MATCH(Resumen!AA15,'Detalle Costos'!$C$5:$C$158,0))*AG15,0) -> 0 | AE15: =IFERROR(INDEX('Detalle Costos'!$Y$5:$Y$158,MATCH(Resumen!AA15,'Detalle Costos'!$C$5:$C$158,0))*AG15,0) -> 0 | AF15: =IFERROR(INDEX('Detalle Costos'!$AA$5:$AA$158,MATCH(Resumen!AA15,'Detalle Costos'!$C$5:$C$158,0))*AG15,0) -> 0 | AG15: =AB15*G15 -> 0 | AK15: =P15-AG15 -> 24314.28 | AL15: =AK15/P15 -> 1 | AM15: =R15 -> 0 | AN15: =1500/26*G15 -> 0 | AO15: =SUM(AM15:AN15) -> 0 | AP15: =60070/248*G15 -> 0 | AQ15: 0 | AR15: =AK15-AO15-AP15+AQ15 -> 24314.28 | AS15: =AR15/P15 -> 1 | AT15: =131251/248*G15 -> 0 | AU15: =AR15-AT15 -> 24314.28 | AV15: =AU15/P15 -> 1 | AW15: =123530/248*G15 -> 0 | AX15: =AR15+AW15 -> 24314.28 | AY15: =AX15/P15 -> 1 | BA15: 0 | BB15: 0 | BC15: 0 | BD15: 0 | BE15: 0 | BF15: 0 | BG15: 0 | BH15: 0 | BI15: 0 | BJ15: 0 | BK15: 0 | BL15: 0 | BM15: 0 | BN15: 0 | BO15: 0 | BP15: 0 | BQ15: 0
B16: FEBRERO | C16: =B16 -> FEBRERO | D16: 148-2026 | E16: 15 | F16: 46055 | G16: 135 | H16: POTA FILETE CONGELADO | I16: Filete | J16: 2-4 (B) | K16: España | L16: Vigo | M16: FOOD & BEVERAGES TRADERS | N16: Jorge | O16: 1650 | P16: 222750 | Q16: 1480.963 | R16: 22820 | S16: =P16-R16 -> 199930 | T16: 5 | U16: ODYSSEUS 606N | V16: 59582082 | W16: HAPAG | X16: PAITA | Y16: 10005721 | Z16: Compensación | AA16: =B16&Y16&Z16 -> FEBRERO10005721Compensación | AB16: =INDEX('Detalle Costos'!$L$5:$L$158,MATCH(Resumen!AA16,'Detalle Costos'!$C$5:$C$158,0))*1000*0+AI16 -> 1861.4473 | AC16: =IFERROR(INDEX('Detalle Costos'!$X$5:$X$158,MATCH(Resumen!AA16,'Detalle Costos'!$C$5:$C$158,0))*AG16,0) -> 152495.08 | AD16: =IFERROR(INDEX('Detalle Costos'!$Z$5:$Z$158,MATCH(Resumen!AA16,'Detalle Costos'!$C$5:$C$158,0))*AG16,0) -> 50378.669 | AE16: =IFERROR(INDEX('Detalle Costos'!$Y$5:$Y$158,MATCH(Resumen!AA16,'Detalle Costos'!$C$5:$C$158,0))*AG16,0) -> 2680.0174 | AF16: =IFERROR(INDEX('Detalle Costos'!$AA$5:$AA$158,MATCH(Resumen!AA16,'Detalle Costos'!$C$5:$C$158,0))*AG16,0) -> 45741.622 | AG16: =AB16*G16 -> 251295.39 | AH16: =+G16 -> 135 | AI16: =AJ16/AH16 -> 1861.4473 | AJ16: 251295.39 | AK16: =P16-AG16 -> -28545.39 | AL16: =AK16/P16 -> -0.1281499 | AM16: =R16 -> 22820 | AN16: =1500/26*G16 -> 7788.4615 | AO16: =SUM(AM16:AN16) -> 30608.462 | AP16: =65590/1634.3*G16 -> 5418.0077 | AQ16: =S16*0.03 -> 5997.9 | AR16: =AK16-AO16-AP16+AQ16 -> -58573.959 | AS16: =AR16/P16 -> -0.26295829 | AT16: =148498/1634.3*G16 -> 12266.554 | AU16: =AR16-AT16 -> -70840.514 | AV16: =AU16/P16 -> -0.318027 | AW16: =124162.35/1634.3*G16 -> 10256.328 | AX16: =AR16+AW16 -> -48317.631 | AY16: =AX16/P16 -> -0.21691417 | BA16: =P16/$G16 -> 1650 | BB16: =-AC16/$G16 -> -1129.5932 | BC16: =-AD16/$G16 -> -373.17533 | BD16: =-AE16/$G16 -> -19.85198 | BE16: =-AF16/$G16 -> -338.82683 | BF16: =-AG16/$G16 -> -1861.4473 | BG16: =AK16/$G16 -> -211.44733 | BH16: =-AM16/$G16 -> -169.03704 | BI16: =-AN16/$G16 -> -57.692308 | BJ16: =-AO16/$G16 -> -226.72934 | BK16: =-AP16/$G16 -> -40.13339 | BL16: =AQ16/$G16 -> 44.428889 | BM16: =AR16/$G16 -> -433.88118 | BN16: =-AT16/$G16 -> -90.863367 | BO16: =AU16/$G16 -> -524.74455 | BP16: =AW16/$G16 -> 75.972802 | BQ16: =AX16/$G16 -> -357.90838
B17: FEBRERO | C17: =B17 -> FEBRERO | D17: 149-2026 | E17: 16 | F17: 46055 | G17: 27 | H17: POTA REPRODUCTORES | I17: Rejos | K17: España | L17: Vigo | M17: GLOBAL OCEAN | N17: Jorge | O17: =P17/G17 -> 2873.5185 | P17: =79650*0+77585 -> 77585 | Q17: =S17/G17 -> 2711.8889 | R17: 4364 | S17: =P17-R17 -> 73221 | T17: 1 | Y17: 10007567 | Z17: Entradas | AA17: =B17&Y17&Z17 -> FEBRERO10007567Entradas | AB17: =INDEX('Detalle Costos'!$L$5:$L$158,MATCH(Resumen!AA17,'Detalle Costos'!$C$5:$C$158,0))*1000*0+AI17 -> 1829.8235 | AC17: =IFERROR(INDEX('Detalle Costos'!$X$5:$X$158,MATCH(Resumen!AA17,'Detalle Costos'!$C$5:$C$158,0))*AG17,0) -> 30498.569 | AD17: =IFERROR(INDEX('Detalle Costos'!$Z$5:$Z$158,MATCH(Resumen!AA17,'Detalle Costos'!$C$5:$C$158,0))*AG17,0) -> 8738.5729 | AE17: =IFERROR(INDEX('Detalle Costos'!$Y$5:$Y$158,MATCH(Resumen!AA17,'Detalle Costos'!$C$5:$C$158,0))*AG17,0) -> 554.46203 | AF17: =IFERROR(INDEX('Detalle Costos'!$AA$5:$AA$158,MATCH(Resumen!AA17,'Detalle Costos'!$C$5:$C$158,0))*AG17,0) -> 9613.63 | AG17: =AB17*G17 -> 49405.233 | AH17: 26.302 | AI17: =+AI4 -> 1829.8235 | AJ17: 48129 | AK17: =P17-AG17 -> 28179.767 | AL17: =AK17/P17 -> 0.36321153 | AM17: =R17 -> 4364 | AN17: =1500/26*G17 -> 1557.6923 | AO17: =SUM(AM17:AN17) -> 5921.6923 | AP17: =65590/1634.3*G17 -> 1083.6015 | AQ17: =S17*0.03 -> 2196.63 | AR17: =AK17-AO17-AP17+AQ17 -> 23371.103 | AS17: =AR17/P17 -> 0.30123223 | AT17: =148498/1634.3*G17 -> 2453.3109 | AU17: =AR17-AT17 -> 20917.792 | AV17: =AU17/P17 -> 0.26961129 | AW17: =124162.35/1634.3*G17 -> 2051.2656 | AX17: =AR17+AW17 -> 25422.368 | AY17: =AX17/P17 -> 0.32767118 | BA17: =P17/$G17 -> 2873.5185 | BB17: =-AC17/$G17 -> -1129.5766 | BC17: =-AD17/$G17 -> -323.65085 | BD17: =-AE17/$G17 -> -20.535631 | BE17: =-AF17/$G17 -> -356.06037 | BF17: =-AG17/$G17 -> -1829.8235 | BG17: =AK17/$G17 -> 1043.6951 | BH17: =-AM17/$G17 -> -161.62963 | BI17: =-AN17/$G17 -> -57.692308 | BJ17: =-AO17/$G17 -> -219.32194 | BK17: =-AP17/$G17 -> -40.13339 | BL17: =AQ17/$G17 -> 81.356667 | BM17: =AR17/$G17 -> 865.5964 | BN17: =-AT17/$G17 -> -90.863367 | BO17: =AU17/$G17 -> 774.73303 | BP17: =AW17/$G17 -> 75.972802 | BQ17: =AX17/$G17 -> 941.5692
B18: FEBRERO | C18: =B18 -> FEBRERO | D18: 150-2026A | E18: 325 | F18: 46069 | G18: 26 | H18: POTA REJOS CONGELADOS | I18: Rejos | J18: 1-2 KG | K18: España | L18: Vigo | M18: OVERSEA | N18: Avelino | O18: 2600 | P18: 67600 | Q18: 2432.1538 | R18: 4364 | S18: =P18-R18 -> 63236 | T18: 1 | U18: CAPE SPENCER 608N | V18: 11400418 | W18: HAPAG | X18: PAITA | Y18: 10007162 | Z18: Compensación | AA18: =B18&Y18&Z18 -> FEBRERO10007162Compensación | AB18: =INDEX('Detalle Costos'!$L$5:$L$158,MATCH(Resumen!AA18,'Detalle Costos'!$C$5:$C$158,0))*1000*0+AI18 -> 1715.2908 | AC18: =IFERROR(INDEX('Detalle Costos'!$X$5:$X$158,MATCH(Resumen!AA18,'Detalle Costos'!$C$5:$C$158,0))*AG18,0) -> 27996.818 | AD18: =IFERROR(INDEX('Detalle Costos'!$Z$5:$Z$158,MATCH(Resumen!AA18,'Detalle Costos'!$C$5:$C$158,0))*AG18,0) -> 7988.6675 | AE18: =IFERROR(INDEX('Detalle Costos'!$Y$5:$Y$158,MATCH(Resumen!AA18,'Detalle Costos'!$C$5:$C$158,0))*AG18,0) -> 415.9275 | AF18: =IFERROR(INDEX('Detalle Costos'!$AA$5:$AA$158,MATCH(Resumen!AA18,'Detalle Costos'!$C$5:$C$158,0))*AG18,0) -> 8196.1487 | AG18: =AB18*G18 -> 44597.561 | AH18: =+G18 -> 26 | AI18: 1715.2908 | AJ18: =AI18*AH18 -> 44597.561 | AK18: =P18-AG18 -> 23002.439 | AL18: =AK18/P18 -> 0.34027276 | AM18: =R18 -> 4364 | AN18: =1500/26*G18 -> 1500 | AO18: =SUM(AM18:AN18) -> 5864 | AP18: =65590/1634.3*G18 -> 1043.4682 | AQ18: =S18*0.03 -> 1897.08 | AR18: =AK18-AO18-AP18+AQ18 -> 17992.051 | AS18: =AR18/P18 -> 0.26615459 | AT18: =148498/1634.3*G18 -> 2362.4475 | AU18: =AR18-AT18 -> 15629.603 | AV18: =AU18/P18 -> 0.23120715 | AW18: =124162.35/1634.3*G18 -> 1975.2928 | AX18: =AR18+AW18 -> 19967.343 | AY18: =AX18/P18 -> 0.2953749 | BA18: =P18/$G18 -> 2600 | BB18: =-AC18/$G18 -> -1076.8007 | BC18: =-AD18/$G18 -> -307.25644 | BD18: =-AE18/$G18 -> -15.997212 | BE18: =-AF18/$G18 -> -315.23649 | BF18: =-AG18/$G18 -> -1715.2908 | BG18: =AK18/$G18 -> 884.70918 | BH18: =-AM18/$G18 -> -167.84615 | BI18: =-AN18/$G18 -> -57.692308 | BJ18: =-AO18/$G18 -> -225.53846 | BK18: =-AP18/$G18 -> -40.13339 | BL18: =AQ18/$G18 -> 72.964615 | BM18: =AR18/$G18 -> 692.00195 | BN18: =-AT18/$G18 -> -90.863367 | BO18: =AU18/$G18 -> 601.13858 | BP18: =AW18/$G18 -> 75.972802 | BQ18: =AX18/$G18 -> 767.97475
B19: FEBRERO | C19: =B19 -> FEBRERO | D19: 151-2025 | E19: 26 | F19: 46080 | G19: 27 | H19: POTA MEMBRANA PRECOCIDA | I19: Membrana | K19: China | L19: Qingdao | M19: Hunan Jinyueyang | O19: =P19/G19 -> 1429.8611 | P19: =39150*0+38606.25 -> 38606.25 | Q19: =S19/G19 -> 1322.4537 | R19: 2900 | S19: =P19-R19 -> 35706.25 | T19: 1 | U19: ECO SIROCCO 26009S | V19: 6445502950 | W19: COSCO | X19: PAITA | Y19: 10009332 | Z19: Entradas | AA19: =B19&Y19&Z19 -> FEBRERO10009332Entradas | AB19: =AI19 -> 1529.9065 | AC19: =IFERROR(INDEX('Detalle Costos'!$X$5:$X$158,MATCH(Resumen!AA19,'Detalle Costos'!$C$5:$C$158,0))*AG19,0) -> 34256.34 | AD19: =IFERROR(INDEX('Detalle Costos'!$Z$5:$Z$158,MATCH(Resumen!AA19,'Detalle Costos'!$C$5:$C$158,0))*AG19,0) -> 6268.5858 | AE19: =IFERROR(INDEX('Detalle Costos'!$Y$5:$Y$158,MATCH(Resumen!AA19,'Detalle Costos'!$C$5:$C$158,0))*AG19,0) -> 633.18765 | AF19: =IFERROR(INDEX('Detalle Costos'!$AA$5:$AA$158,MATCH(Resumen!AA19,'Detalle Costos'!$C$5:$C$158,0))*AG19,0) -> 149.36167 | AG19: =AB19*G19 -> 41307.475 | AH19: 26.625 | AI19: =AJ19/AH19 -> 1529.9065 | AJ19: 40733.76 | AK19: =P19-AG19 -> -2701.2249 | AL19: =AK19/P19 -> -0.069968591 | AM19: =R19 -> 2900 | AN19: =1500/26*G19 -> 1557.6923 | AO19: =SUM(AM19:AN19) -> 4457.6923 | AP19: =65590/1634.3*G19 -> 1083.6015 | AQ19: =S19*0.03 -> 1071.1875 | AR19: =AK19-AO19-AP19+AQ19 -> -7171.3313 | AS19: =AR19/P19 -> -0.18575571 | AT19: =148498/1634.3*G19 -> 2453.3109 | AU19: =AR19-AT19 -> -9624.6422 | AV19: =AU19/P19 -> -0.2493027 | AW19: =124162.35/1634.3*G19 -> 2051.2656 | AX19: =AR19+AW19 -> -5120.0656 | AY19: =AX19/P19 -> -0.13262271 | BA19: =P19/$G19 -> 1429.8611 | BB19: =-AC19/$G19 -> -1268.7533 | BC19: =-AD19/$G19 -> -232.16984 | BD19: =-AE19/$G19 -> -23.451395 | BE19: =-AF19/$G19 -> -5.5319137 | BF19: =-AG19/$G19 -> -1529.9065 | BG19: =AK19/$G19 -> -100.04537 | BH19: =-AM19/$G19 -> -107.40741 | BI19: =-AN19/$G19 -> -57.692308 | BJ19: =-AO19/$G19 -> -165.09972 | BK19: =-AP19/$G19 -> -40.13339 | BL19: =AQ19/$G19 -> 39.673611 | BM19: =AR19/$G19 -> -265.60486 | BN19: =-AT19/$G19 -> -90.863367 | BO19: =AU19/$G19 -> -356.46823 | BP19: =AW19/$G19 -> 75.972802 | BQ19: =AX19/$G19 -> -189.63206
B20: FEBRERO | C20: =B20 -> FEBRERO | D20: 151-2025 | E20: 26 | F20: 46080 | G20: 27 | H20: POTA TELILLA PRECOCIDA | I20: Telilla | K20: China | L20: Qingdao | M20: Hunan Jinyueyang | O20: =P20/G20 -> 1429.8611 | P20: =39150*0+38606.25 -> 38606.25 | Q20: =S20/G20 -> 1322.4537 | R20: 2900 | S20: =P20-R20 -> 35706.25 | T20: 1 | U20: ECO SIROCCO 26009S | V20: 6445502950 | W20: COSCO | X20: PAITA | Y20: 10009332 | Z20: Compensación | AA20: =B20&Y20&Z20 -> FEBRERO10009332Compensación | AB20: =INDEX('Detalle Costos'!$L$5:$L$158,MATCH(Resumen!AA20,'Detalle Costos'!$C$5:$C$158,0))*1000*0+AI20 -> 1515.6443 | AC20: =IFERROR(INDEX('Detalle Costos'!$X$5:$X$158,MATCH(Resumen!AA20,'Detalle Costos'!$C$5:$C$158,0))*AG20,0) -> 33289.301 | AD20: =IFERROR(INDEX('Detalle Costos'!$Z$5:$Z$158,MATCH(Resumen!AA20,'Detalle Costos'!$C$5:$C$158,0))*AG20,0) -> 5812.6541 | AE20: =IFERROR(INDEX('Detalle Costos'!$Y$5:$Y$158,MATCH(Resumen!AA20,'Detalle Costos'!$C$5:$C$158,0))*AG20,0) -> 581.72151 | AF20: =IFERROR(INDEX('Detalle Costos'!$AA$5:$AA$158,MATCH(Resumen!AA20,'Detalle Costos'!$C$5:$C$158,0))*AG20,0) -> 1238.72 | AG20: =AB20*G20 -> 40922.397 | AH20: 26.625 | AI20: =AJ20/AH20 -> 1515.6443 | AJ20: 40354.03 | AK20: =P20-AG20 -> -2316.1466 | AL20: =AK20/P20 -> -0.059994084 | AM20: =R20 -> 2900 | AN20: =1500/26*G20 -> 1557.6923 | AO20: =SUM(AM20:AN20) -> 4457.6923 | AP20: =65590/1634.3*G20 -> 1083.6015 | AQ20: =S20*0.03 -> 1071.1875 | AR20: =AK20-AO20-AP20+AQ20 -> -6786.253 | AS20: =AR20/P20 -> -0.1757812 | AT20: =148498/1634.3*G20 -> 2453.3109 | AU20: =AR20-AT20 -> -9239.5639 | AV20: =AU20/P20 -> -0.23932819 | AW20: =124162.35/1634.3*G20 -> 2051.2656 | AX20: =AR20+AW20 -> -4734.9873 | AY20: =AX20/P20 -> -0.12264821 | BA20: =P20/$G20 -> 1429.8611 | BB20: =-AC20/$G20 -> -1232.9371 | BC20: =-AD20/$G20 -> -215.28349 | BD20: =-AE20/$G20 -> -21.545241 | BE20: =-AF20/$G20 -> -45.878519 | BF20: =-AG20/$G20 -> -1515.6443 | BG20: =AK20/$G20 -> -85.783208 | BH20: =-AM20/$G20 -> -107.40741 | BI20: =-AN20/$G20 -> -57.692308 | BJ20: =-AO20/$G20 -> -165.09972 | BK20: =-AP20/$G20 -> -40.13339 | BL20: =AQ20/$G20 -> 39.673611 | BM20: =AR20/$G20 -> -251.3427 | BN20: =-AT20/$G20 -> -90.863367 | BO20: =AU20/$G20 -> -342.20607 | BP20: =AW20/$G20 -> 75.972802 | BQ20: =AX20/$G20 -> -175.3699
B21: FEBRERO | C21: =B21 -> FEBRERO | D21: 152-2026 | E21: 26 | F21: 46062 | G21: 27 | H21: POTA REJOS CONGELADOS | I21: Rejos | J21: 2-UP KG | K21: España | L21: Vigo | M21: OVERSEA | N21: Avelino | O21: =P21/G21 -> 2781.2963 | P21: =75600*0+75095 -> 75095 | Q21: =S21/G21 -> 2619.6667 | R21: 4364 | S21: =P21-R21 -> 70731 | T21: 1 | U21: GEMLIK EXPRESS 607N | V21: 24312444 | W21: HAPAG | X21: PAITA | Y21: 10007162 | Z21: Compensación | AA21: =B21&Y21&Z21 -> FEBRERO10007162Compensación | AB21: =INDEX('Detalle Costos'!$L$5:$L$158,MATCH(Resumen!AA21,'Detalle Costos'!$C$5:$C$158,0))*1000*0+AI21 -> 1751.1868 | AC21: =IFERROR(INDEX('Detalle Costos'!$X$5:$X$158,MATCH(Resumen!AA21,'Detalle Costos'!$C$5:$C$158,0))*AG21,0) -> 29682.043 | AD21: =IFERROR(INDEX('Detalle Costos'!$Z$5:$Z$158,MATCH(Resumen!AA21,'Detalle Costos'!$C$5:$C$158,0))*AG21,0) -> 8469.5332 | AE21: =IFERROR(INDEX('Detalle Costos'!$Y$5:$Y$158,MATCH(Resumen!AA21,'Detalle Costos'!$C$5:$C$158,0))*AG21,0) -> 440.96362 | AF21: =IFERROR(INDEX('Detalle Costos'!$AA$5:$AA$158,MATCH(Resumen!AA21,'Detalle Costos'!$C$5:$C$158,0))*AG21,0) -> 8689.5035 | AG21: =AB21*G21 -> 47282.044 | AH21: =+G21 -> 27 | AI21: =1.75118680089485*1000 -> 1751.1868 | AJ21: =AI21*AH21 -> 47282.044 | AK21: =P21-AG21 -> 27812.956 | AL21: =AK21/P21 -> 0.37037028 | AM21: =R21 -> 4364 | AN21: =1500/26*G21 -> 1557.6923 | AO21: =SUM(AM21:AN21) -> 5921.6923 | AP21: =65590/1634.3*G21 -> 1083.6015 | AQ21: =S21*0.03 -> 2121.93 | AR21: =AK21-AO21-AP21+AQ21 -> 22929.593 | AS21: =AR21/P21 -> 0.30534113 | AT21: =148498/1634.3*G21 -> 2453.3109 | AU21: =AR21-AT21 -> 20476.282 | AV21: =AU21/P21 -> 0.2726717 | AW21: =124162.35/1634.3*G21 -> 2051.2656 | AX21: =AR21+AW21 -> 24980.858 | AY21: =AX21/P21 -> 0.33265674 | BA21: =P21/$G21 -> 2781.2963 | BB21: =-AC21/$G21 -> -1099.3349 | BC21: =-AD21/$G21 -> -313.68641 | BD21: =-AE21/$G21 -> -16.331986 | BE21: =-AF21/$G21 -> -321.83346 | BF21: =-AG21/$G21 -> -1751.1868 | BG21: =AK21/$G21 -> 1030.1095 | BH21: =-AM21/$G21 -> -161.62963 | BI21: =-AN21/$G21 -> -57.692308 | BJ21: =-AO21/$G21 -> -219.32194 | BK21: =-AP21/$G21 -> -40.13339 | BL21: =AQ21/$G21 -> 78.59 | BM21: =AR21/$G21 -> 849.24417 | BN21: =-AT21/$G21 -> -90.863367 | BO21: =AU21/$G21 -> 758.3808 | BP21: =AW21/$G21 -> 75.972802 | BQ21: =AX21/$G21 -> 925.21697
B22: FEBRERO | C22: =B22 -> FEBRERO | D22: 156-2026A | E22: 27 | F22: 46062 | G22: 54 | H22: POTA FILETE CONGELADO | I22: Filete | J22: 2-4 kg 100% blanco, No polyphosphate,no medicine | K22: China | L22: Qingdao | M22: Longkou Yunfeng Aquatic | O22: 1650 | P22: 89100 | Q22: 1534.963 | R22: 6212 | S22: =P22-R22 -> 82888 | T22: 2 | U22: CMA CGM IMAGINATION / 0DVITN1MA | V22: LMM0571149 | W22: CMA CGM | X22: PAITA | Y22: 10005721 | Z22: Compensación | AA22: =B22&Y22&Z22 -> FEBRERO10005721Compensación | AB22: =INDEX('Detalle Costos'!$L$5:$L$158,MATCH(Resumen!AA22,'Detalle Costos'!$C$5:$C$158,0))*1000*0+AI22 -> 1740.7827 | AC22: =IFERROR(INDEX('Detalle Costos'!$X$5:$X$158,MATCH(Resumen!AA22,'Detalle Costos'!$C$5:$C$158,0))*AG22,0) -> 57043.957 | AD22: =IFERROR(INDEX('Detalle Costos'!$Z$5:$Z$158,MATCH(Resumen!AA22,'Detalle Costos'!$C$5:$C$158,0))*AG22,0) -> 18845.189 | AE22: =IFERROR(INDEX('Detalle Costos'!$Y$5:$Y$158,MATCH(Resumen!AA22,'Detalle Costos'!$C$5:$C$158,0))*AG22,0) -> 1002.5162 | AF22: =IFERROR(INDEX('Detalle Costos'!$AA$5:$AA$158,MATCH(Resumen!AA22,'Detalle Costos'!$C$5:$C$158,0))*AG22,0) -> 17110.605 | AG22: =AB22*G22 -> 94002.267 | AH22: =+G22 -> 54 | AI22: =1.7407827151654*1000 -> 1740.7827 | AJ22: =+AI22*AH22 -> 94002.267 | AK22: =P22-AG22 -> -4902.2666 | AL22: =AK22/P22 -> -0.055019827 | AM22: =R22 -> 6212 | AN22: =1500/26*G22 -> 3115.3846 | AO22: =SUM(AM22:AN22) -> 9327.3846 | AP22: =65590/1634.3*G22 -> 2167.2031 | AQ22: =S22*0.03 -> 2486.64 | AR22: =AK22-AO22-AP22+AQ22 -> -13910.214 | AS22: =AR22/P22 -> -0.15611913 | AT22: =148498/1634.3*G22 -> 4906.6218 | AU22: =AR22-AT22 -> -18816.836 | AV22: =AU22/P22 -> -0.21118784 | AW22: =124162.35/1634.3*G22 -> 4102.5313 | AX22: =AR22+AW22 -> -9807.683 | AY22: =AX22/P22 -> -0.11007501 | BA22: =P22/$G22 -> 1650 | BB22: =-AC22/$G22 -> -1056.3696 | BC22: =-AD22/$G22 -> -348.98498 | BD22: =-AE22/$G22 -> -18.565115 | BE22: =-AF22/$G22 -> -316.86305 | BF22: =-AG22/$G22 -> -1740.7827 | BG22: =AK22/$G22 -> -90.782715 | BH22: =-AM22/$G22 -> -115.03704 | BI22: =-AN22/$G22 -> -57.692308 | BJ22: =-AO22/$G22 -> -172.72934 | BK22: =-AP22/$G22 -> -40.13339 | BL22: =AQ22/$G22 -> 46.048889 | BM22: =AR22/$G22 -> -257.59656 | BN22: =-AT22/$G22 -> -90.863367 | BO22: =AU22/$G22 -> -348.45993 | BP22: =AW22/$G22 -> 75.972802 | BQ22: =AX22/$G22 -> -181.62376
B23: FEBRERO | C23: =B23 -> FEBRERO | D23: 156-2026B | E23: 27 | F23: 46071 | G23: 81 | H23: POTA FILETE CONGELADO | I23: Filete | J23: 2-4 kg 100% blanco, No polyphosphate,no medicine | K23: China | L23: Qingdao | M23: Longkou Yunfeng Aquatic | O23: 1650 | P23: 133650 | Q23: 1534.963 | R23: 9318 | S23: =P23-R23 -> 124332 | T23: 3 | U23: CMA CGM EXCELLENCE 0DVNNN1MA | V23: LMM0571699 | W23: CMA CGM | X23: PAITA | Y23: 10005721 | Z23: Compensación | AA23: =B23&Y23&Z23 -> FEBRERO10005721Compensación | AB23: =INDEX('Detalle Costos'!$L$5:$L$158,MATCH(Resumen!AA23,'Detalle Costos'!$C$5:$C$158,0))*1000*0+AI23 -> 1740.7827 | AC23: =IFERROR(INDEX('Detalle Costos'!$X$5:$X$158,MATCH(Resumen!AA23,'Detalle Costos'!$C$5:$C$158,0))*AG23,0) -> 85565.935 | AD23: =IFERROR(INDEX('Detalle Costos'!$Z$5:$Z$158,MATCH(Resumen!AA23,'Detalle Costos'!$C$5:$C$158,0))*AG23,0) -> 28267.783 | AE23: =IFERROR(INDEX('Detalle Costos'!$Y$5:$Y$158,MATCH(Resumen!AA23,'Detalle Costos'!$C$5:$C$158,0))*AG23,0) -> 1503.7743 | AF23: =IFERROR(INDEX('Detalle Costos'!$AA$5:$AA$158,MATCH(Resumen!AA23,'Detalle Costos'!$C$5:$C$158,0))*AG23,0) -> 25665.907 | AG23: =AB23*G23 -> 141003.4 | AH23: =+G23 -> 81 | AI23: =1.7407827151654*1000 -> 1740.7827 | AJ23: =+AI23*AH23 -> 141003.4 | AK23: =P23-AG23 -> -7353.3999 | AL23: =AK23/P23 -> -0.055019827 | AM23: =R23 -> 9318 | AN23: =1500/26*G23 -> 4673.0769 | AO23: =SUM(AM23:AN23) -> 13991.077 | AP23: =65590/1634.3*G23 -> 3250.8046 | AQ23: =S23*0.03 -> 3729.96 | AR23: =AK23-AO23-AP23+AQ23 -> -20865.321 | AS23: =AR23/P23 -> -0.15611913 | AT23: =148498/1634.3*G23 -> 7359.9327 | AU23: =AR23-AT23 -> -28225.254 | AV23: =AU23/P23 -> -0.21118784 | AW23: =124162.35/1634.3*G23 -> 6153.7969 | AX23: =AR23+AW23 -> -14711.525 | AY23: =AX23/P23 -> -0.11007501 | BA23: =P23/$G23 -> 1650 | BB23: =-AC23/$G23 -> -1056.3696 | BC23: =-AD23/$G23 -> -348.98498 | BD23: =-AE23/$G23 -> -18.565115 | BE23: =-AF23/$G23 -> -316.86305 | BF23: =-AG23/$G23 -> -1740.7827 | BG23: =AK23/$G23 -> -90.782715 | BH23: =-AM23/$G23 -> -115.03704 | BI23: =-AN23/$G23 -> -57.692308 | BJ23: =-AO23/$G23 -> -172.72934 | BK23: =-AP23/$G23 -> -40.13339 | BL23: =AQ23/$G23 -> 46.048889 | BM23: =AR23/$G23 -> -257.59656 | BN23: =-AT23/$G23 -> -90.863367 | BO23: =AU23/$G23 -> -348.45993 | BP23: =AW23/$G23 -> 75.972802 | BQ23: =AX23/$G23 -> -181.62376
B24: FEBRERO | C24: =B24 -> FEBRERO | D24: 157-2026 | E24: 28 | F24: 46066 | G24: 24 | H24: POTA CONOS | I24: Conos | K24: Tailandia | L24: Lat Krabang | M24: TSUJINO | N24: Jose | O24: 2000 | P24: 48000 | Q24: 1854.1667 | R24: 3500 | S24: =P24-R24 -> 44500 | T24: 1 | U24: ECO SIROCCO 26007S | V24: 6445030580 | W24: COSCO | X24: PAITA | Y24: 10007969 | Z24: Compensación | AA24: =B24&Y24&Z24 -> FEBRERO10007969Compensación | AB24: =INDEX('Detalle Costos'!$L$5:$L$158,MATCH(Resumen!AA24,'Detalle Costos'!$C$5:$C$158,0))*1000*0+AI24 -> 1397.2773 | AC24: =IFERROR(INDEX('Detalle Costos'!$X$5:$X$158,MATCH(Resumen!AA24,'Detalle Costos'!$C$5:$C$158,0))*AG24,0) -> 27124.396 | AD24: =IFERROR(INDEX('Detalle Costos'!$Z$5:$Z$158,MATCH(Resumen!AA24,'Detalle Costos'!$C$5:$C$158,0))*AG24,0) -> 5105.9167 | AE24: =IFERROR(INDEX('Detalle Costos'!$Y$5:$Y$158,MATCH(Resumen!AA24,'Detalle Costos'!$C$5:$C$158,0))*AG24,0) -> 400.3959 | AF24: =IFERROR(INDEX('Detalle Costos'!$AA$5:$AA$158,MATCH(Resumen!AA24,'Detalle Costos'!$C$5:$C$158,0))*AG24,0) -> 903.94689 | AG24: =AB24*G24 -> 33534.655 | AH24: 23.14 | AI24: 1397.2773 | AJ24: =+AI24*AH24 -> 32332.997 | AK24: =P24-AG24 -> 14465.345 | AL24: =AK24/P24 -> 0.30136135 | AM24: =R24 -> 3500 | AN24: =1500/26*G24 -> 1384.6154 | AO24: =SUM(AM24:AN24) -> 4884.6154 | AP24: =65590/1634.3*G24 -> 963.20137 | AQ24: =S24*0.03 -> 1335 | AR24: =AK24-AO24-AP24+AQ24 -> 9952.5278 | AS24: =AR24/P24 -> 0.20734433 | AT24: =148498/1634.3*G24 -> 2180.7208 | AU24: =AR24-AT24 -> 7771.807 | AV24: =AU24/P24 -> 0.16191265 | AW24: =124162.35/1634.3*G24 -> 1823.3472 | AX24: =AR24+AW24 -> 11775.875 | AY24: =AX24/P24 -> 0.24533073 | BA24: =P24/$G24 -> 2000 | BB24: =-AC24/$G24 -> -1130.1832 | BC24: =-AD24/$G24 -> -212.74653 | BD24: =-AE24/$G24 -> -16.683162 | BE24: =-AF24/$G24 -> -37.664454 | BF24: =-AG24/$G24 -> -1397.2773 | BG24: =AK24/$G24 -> 602.72269 | BH24: =-AM24/$G24 -> -145.83333 | BI24: =-AN24/$G24 -> -57.692308 | BJ24: =-AO24/$G24 -> -203.52564 | BK24: =-AP24/$G24 -> -40.13339 | BL24: =AQ24/$G24 -> 55.625 | BM24: =AR24/$G24 -> 414.68866 | BN24: =-AT24/$G24 -> -90.863367 | BO24: =AU24/$G24 -> 323.82529 | BP24: =AW24/$G24 -> 75.972802 | BQ24: =AX24/$G24 -> 490.66146
B25: FEBRERO | C25: =B25 -> FEBRERO | D25: 160-2026 | E25: 30 | F25: 46066 | G25: 108 | H25: POTA ALAS CONGELADAS | I25: Alas | K25: China | L25: Qingdao | M25: TSUJINO | N25: Jose | O25: 1600 | P25: 172800 | Q25: 1492.5926 | R25: 11600 | S25: =P25-R25 -> 161200 | T25: 4 | U25: ECO SIROCCO 26007S | V25: 6445031110 | W25: COSCO | X25: PAITA | Y25: 10006720 | Z25: Compensación | AA25: =B25&Y25&Z25 -> FEBRERO10006720Compensación | AB25: =INDEX('Detalle Costos'!$L$5:$L$158,MATCH(Resumen!AA25,'Detalle Costos'!$C$5:$C$158,0))*1000*0+AI25 -> 1639.7682 | AC25: =IFERROR(INDEX('Detalle Costos'!$X$5:$X$158,MATCH(Resumen!AA25,'Detalle Costos'!$C$5:$C$158,0))*AG25,0) -> 114801.8 | AD25: =IFERROR(INDEX('Detalle Costos'!$Z$5:$Z$158,MATCH(Resumen!AA25,'Detalle Costos'!$C$5:$C$158,0))*AG25,0) -> 26268.814 | AE25: =IFERROR(INDEX('Detalle Costos'!$Y$5:$Y$158,MATCH(Resumen!AA25,'Detalle Costos'!$C$5:$C$158,0))*AG25,0) -> 1720.5907 | AF25: =IFERROR(INDEX('Detalle Costos'!$AA$5:$AA$158,MATCH(Resumen!AA25,'Detalle Costos'!$C$5:$C$158,0))*AG25,0) -> 34303.76 | AG25: =AB25*G25 -> 177094.96 | AH25: =+G25 -> 108 | AI25: =1.63976816895275*1000 -> 1639.7682 | AJ25: =+AI25*AH25 -> 177094.96 | AK25: =P25-AG25 -> -4294.9622 | AL25: =AK25/P25 -> -0.024855106 | AM25: =R25 -> 11600 | AN25: =1500/26*G25 -> 6230.7692 | AO25: =SUM(AM25:AN25) -> 17830.769 | AP25: =65590/1634.3*G25 -> 4334.4062 | AQ25: =S25*0.03 -> 4836 | AR25: =AK25-AO25-AP25+AQ25 -> -21624.138 | AS25: =AR25/P25 -> -0.12513969 | AT25: =148498/1634.3*G25 -> 9813.2436 | AU25: =AR25-AT25 -> -31437.381 | AV25: =AU25/P25 -> -0.18192929 | AW25: =124162.35/1634.3*G25 -> 8205.0626 | AX25: =AR25+AW25 -> -13419.075 | AY25: =AX25/P25 -> -0.077656684 | BA25: =P25/$G25 -> 1600 | BB25: =-AC25/$G25 -> -1062.9796 | BC25: =-AD25/$G25 -> -243.22976 | BD25: =-AE25/$G25 -> -15.931396 | BE25: =-AF25/$G25 -> -317.62741 | BF25: =-AG25/$G25 -> -1639.7682 | BG25: =AK25/$G25 -> -39.768169 | BH25: =-AM25/$G25 -> -107.40741 | BI25: =-AN25/$G25 -> -57.692308 | BJ25: =-AO25/$G25 -> -165.09972 | BK25: =-AP25/$G25 -> -40.13339 | BL25: =AQ25/$G25 -> 44.777778 | BM25: =AR25/$G25 -> -200.2235 | BN25: =-AT25/$G25 -> -90.863367 | BO25: =AU25/$G25 -> -291.08686 | BP25: =AW25/$G25 -> 75.972802 | BQ25: =AX25/$G25 -> -124.25069
